Workbook

Sheet BS
A1: FAIR FIELD CO-OPERATIVE HOUSING SOCIETY LTD.
A2: ( Regd. No. MUM/WP/HSG/PC/9693/97-98 )
A3: 68, Marve Road, Orlem, Malad (West), Mumbai, Maharshtra - 400064
A4: Balance Sheet as at 31st March, 2026
H5: (Amt. in Rs.)
A6: 45747 | B6: LIABILITIES | D6: 46112 | E6: =A6 -> 45747 | F6: ASSETS | H6: =D6 -> 46112
B7: Authorised Share Capital | F7: Cash and Bank Balances:
A8: 600000 | B8: (12,000 Share of ₹ 50/- each ) | D8: 600000 | E8: 1854 | F8: Cash in Hand | G8: 1570
E9: 11775 | F9: Mumbai District Central Co-op Bank | G9: 11775
B10: Issued, Subscribed and Paid-up Share Capital: | E10: 485220.61 | F10: The Saraswat Co-op Bank | G10: =BRS!D4 -> 426209.01 | H10: =SUM(G8:G10) -> 439554.01
A11: 9000 | B11: (180 Shares of ₹ 50/- each) | D11: 9000
F12: Investments (As per Sch I)
B13: RESERVE & SURPLUS | E13: 1825894 | F13: Fixed Deposits with Banks | G13: ='Sch I - FD'!C33 -> 1425496
B14: (i) General Reserves Fund | E14: 86863 | F14: Accrued Interest on Fixed Deposits | G14: ='Sch I - FD'!D33 -> 62482 | H14: =SUM(G13:G14) -> 1487978
A15: 116352 | B15: Bal as per last year | C15: =A15+A17+A18+A16 -> 210509.75
A16: 1400 | B16: Add: Additions during the year | C16: 28100
A17: 45066.75 | B17: Add: 25% of Surplus | C17: =IE!D47 -> 11434.1 | F17: Other Current Assets
A18: 47691 | B18: Add: Interest earned during the year | C18: =-IE!G22 -> 60268 | D18: =SUM(C15:C18) -> 310311.85 | E18: 18359 | F18: Dues from Member's (As per Sch - II) | G18: ='Sch II,III & IV '!D7 -> 10551
B19: (ii) Sinking Fund | E19: 11068.54 | F19: Deposit with Adani Electricity | G19: 11068.54
A20: 533282 | B20: Bal as per last year | C20: =A20+A21+A22+A23 -> 581422 | E20: 24000 | F20: Advance to Vendor - RK Water proofing | G20: 39000
A21: 12792 | B21: Add: Additions during the year | C21: 12792 | E21: 25250 | F21: TDS Receivables | G21: 35280 | H21: =SUM(G18:G21) -> 95899.54
A22: 35348 | B22: Add: Interest earned during the year on FD | C22: =-IE!G23 -> 954
A23: 0 | B23: Add: Interest earned during the year on RD | C23: 0 | D23: =SUM(C20:C23) -> 595168 | F23: Fixed Assets:
B24: (iii) Repair Fund | E24: 12040000 | F24: (i) Land and Building | H24: 12040000
A25: 391684.7 | B25: Bal as per last year | C25: =A25+A26+A27+A28 -> 450886.7
A26: 38376 | B26: Add: Additions during the year | C26: 38376 | F26: (ii) Furniture and Fixture
A27: 20826 | B27: Add: Interest earned during the year on RD | C27: =-IE!G24 -> 22293 | E27: 1376 | F27: Opening Balance | G27: 1706
A28: 0 | B28: Less: Major Repair Expenses for the year | C28: -131037 | D28: =SUM(C25:C28) -> 380518.7 | E28: 520 | F28: Add: Additional during the year | G28: 0
B29: (iv) Building Development Fund | G29: =SUM(G27:G28) -> 1706
A30: 370593 | B30: Bal as per last year | C30: =A30+A31+A32 -> 565159 | E30: -190 | F30: Less: Depreciation @ 10% | G30: =-ROUND(G29*10%,0) -> -171 | H30: =G29+G30 -> 1535
A31: 180624 | B31: Add: Additions during the year | C31: 180624
A32: 13942 | B32: Add: Interest earned during the year on FD | C32: =-IE!G26 -> 14486 | F32: (iii) Borewell Pump
A33: 0 | B33: Less: Major Repair Expenses for the year | C33: -760269 | D33: =SUM(C30:C33) -> 0 | E33: 260 | F33: Opening Balance | G33: =E33+E34 -> 221
B34: (v) Education and Training Fund | E34: -39 | F34: Less: Depreciation @ 15% | G34: =-ROUND(G33*15%,0) -> -33 | H34: =SUM(G33:G34) -> 188
A35: 22627 | B35: Bal as per last year | C35: =A35+A36+A38 -> 26392
A36: 2160 | B36: Add: Additions during the year | C36: =18*10*12 -> 2160 | F36: (iv) CCTV Systems
A37: 0 | B37: Less : Utilisation during the year | C37: 1770 | E37: 56255.6 | F37: Opening Balance | G37: 51855.6
A38: 1605 | B38: Add: Interest earned during the year on FD | C38: =-IE!G25 -> 1686 | D38: =SUM(C35:C36)-C37+C38 -> 28468 | E38: 4366 | F38: Add: Additional during the year | G38: 18000
G39: =SUM(G37:G38) -> 69855.6
B40: Members Contribution : | E40: -8766 | F40: Less: Depreciation @ 15% | G40: =-ROUND((G37*15%)+(G38*15%)/2,0) -> -9128 | H40: =G39+G40 -> 60727.6
...

Sheet IE
A1: =BS!A1 -> FAIR FIELD CO-OPERATIVE HOUSING SOCIETY LTD.
A2: ( Regd. No. MUM/WP/HSG/PC/9693/97-98 )
A3: =BS!A3 -> 68, Marve Road, Orlem, Malad (West), Mumbai, Maharshtra - 400064
A4: Income and Expenditure Account for the year ended March 31, 2026
H5: =BS!H5 -> (Amt. in Rs.)
A6: =BS!A6 -> 45747 | B6: EXPENDITURE | D6: =BS!D6 -> 46112 | E6: =A6 -> 45747 | F6: INCOME | H6: =D6 -> 46112
F7: By Members Contribution Towards :
A8: 167292 | B8: Municipal Taxes | D8: 212060 | E8: 167292 | F8: Municipal Taxes | G8: =197156+15300 -> 212456
E9: 614736 | F9: Maintenance Charges | G9: 614736
A10: 103730 | B10: To Common Electricity Charges | D10: 108540 | E10: 70416 | F10: Electricity Charges | G10: 70416
E11: 19050 | F11: Parking Charges | G11: =3100+41800+4800+2850 -> 52550
A12: 6927 | B12: Insurance Expense | D12: 10838 | E12: 6996 | F12: Insurance Charges | G12: 6996
B13: To Water Expenses | E13: 2837 | F13: Interest on Delayed Payments | G13: 1986
A14: 26642 | B14: Water Expenses | C14: 27154 | E14: 28080 | F14: Water Charges | G14: 28080
A15: 3200 | B15: Water Tank Cleaning Expense | C15: 3500 | E15: 3170 | F15: Non Occupancy Charges | G15: =2219+1585 -> 3804
A16: 0 | B16: Water Pump Repair Charges | C16: 10475 | D16: =C14+C15+C16 -> 41129 | E16: 0 | F16: Other Charges | G16: 21000
B17: To Repair and Maintenance Expenses | E17: 17000 | F17: Guest Parking Charges | G17: 0 | H17: =SUM(G8:G17) -> 1012024
A18: 16486 | B18: AMC - Lift | C18: 16811
A19: 18880 | B19: R&M - Lift | C19: 0 | F19: By Interest Income
A20: 14458 | B20: R&M - Garden | C20: 16000 | E20: 16907 | F20: Interest Income from Savings Deposits | H20: 12449
A21: 6515 | B21: R&M - Plumbing | C21: 2085 | E21: 120019 | F21: Interest Income from Fixed Deposits | G21: 100295
A22: 67846 | B22: R&M - Electrical | C22: 26129 | E22: -47691 | F22: Less: trf. to Reserve Fund | G22: =-60269+1 -> -60268
A23: 4870 | B23: R&M - Others | C23: 21604.88 | E23: -35348 | F23: Less: trf. to Sinking Fund | G23: =-956+2 -> -954
A24: 6903 | B24: R&M - Fire Fighting | C24: 6903 | E24: -20826 | F24: Less: trf. to Repair Fund | G24: -22293
A25: 2600 | B25: R&M - CCTV | C25: 0 | D25: =SUM(C18:C25) -> 89532.88 | E25: -1605 | F25: Less: trf. to Education and Train. Fund | G25: -1686
B26: To Service Charges | E26: -13942 | F26: Less: trf. to Building Develop. Fund | G26: -14486 | H26: =SUM(G21:G26) -> 608
A27: 245886 | B27: Salary Expenses | C27: 264213
A28: 18625 | B28: Bonus | C28: 16250 | F28: By Other Income
A29: 826 | B29: Subscription Federation | C29: 826 | E29: 0 | F29: Legal Charges | G29: 12400 | H29: =SUM(G29) -> 12400
A30: 2000 | B30: Audit Fees | C30: 3800
A31: 2249 | B31: Housekeeping Expense | C31: 2188
A32: 11448 | B32: Accounting Charges | C32: 12592
A33: 8199 | B33: Pest Control Expense | C33: 8107
A34: 95 | B34: Printing and Stationary | C34: 1577
A35: 18500 | B35: Professional Fees | C35: 0
A36: 752 | B36: Bank Charges | C36: 1075.72
A37: 1180 | B37: Conveyance Charges | C37: 0
A38: 0 | B38: Garbage Disposal | C38: 5200
A39: 10715 | B39: Depreciation on Fixed Assets | C39: 10794
A40: 0 | B40: Miscelleneous Charges | C40: 400
...

Sheet Sch I - FD
A1: =BS!A1 -> FAIR FIELD CO-OPERATIVE HOUSING SOCIETY LTD.
A3: Schedule 1: Details of Fixed Deposits as on 31st March 2026
H4: (Amt. in Rs.)
A5: Certificate No. | B5: Date | C5: Amount Invested | D5: Accrued Int 25-26 | E5: Total Amt | F5: Maturity Date | G5: Maturity Value | H5: Interest % | I5: Bank
A6: Sinking Fund
A7: TD1001240592 | B7: 26.06.2025 | C7: 13661 | D7: =702-70 -> 632 | E7: =SUM(C7:D7) -> 14293 | F7: 26.06.2026 | G7: 14583 | H7: 0.066 | I7: SCB
C8: =SUM(C7:C7) -> 13661 | D8: =SUM(D7:D7) -> 632 | E8: =SUM(E7:E7) -> 14293 | G8: =SUM(G7:G7) -> 14583
A10: Repair Fund
A11: TD1000855869_02 | B11: 15.09.2025 | C11: 269800 | D11: =10108-1010 -> 9098 | E11: =SUM(C11:D11) -> 278898 | F11: 15.10.2026 | G11: 290175 | H11: 0.068 | I11: SCB
A12: TD1001240642 | B12: 26.06.2025 | C12: 52542 | D12: =2698-270 -> 2428 | E12: =SUM(C12:D12) -> 54970 | F12: 26.06.2026 | G12: 56088 | H12: 0.066 | I12: SCB
C13: =SUM(C11:C12) -> 322342 | D13: =SUM(D11:D12) -> 11526 | E13: =SUM(E11:E12) -> 333868 | G13: =SUM(G11:G12) -> 346263
A15: Building Development Fund
A16: TD1000855895_08 | B16: 15.09.2025 | C16: 208951 | D16: =7828-783 -> 7045 | E16: =SUM(C16:D16) -> 215996 | F16: 15.10.2026 | G16: 224731 | H16: 0.068 | I16: SCB
C17: =SUM(C16) -> 208951 | D17: =SUM(D15:D16) -> 7045 | E17: =SUM(E16) -> 215996 | G17: =SUM(G16) -> 224731
A19: Share Capital
A20: TD0000400923 | B20: 29.03.2024 | C20: 9000 | D20: 0 | E20: =SUM(C20:D20) -> 9000 | F20: 29.03.2029 | G20: 9000 | H20: 0.0675 | I20: SCB
C21: =SUM(C20) -> 9000 | D21: =SUM(D19:D20) -> 0 | E21: =SUM(E20) -> 9000 | G21: =SUM(G20) -> 9000
A23: General Fund
A24: TD1000855858_02 | B24: 15.09.2025 | C24: 45920 | D24: =1720-172 -> 1548 | E24: =SUM(C24:D24) -> 47468 | F24: 15.10.2026 | G24: 49388 | H24: 0.068 | I24: SCB
A25: TD1001227336 | B25: 14.06.2025 | C25: 801296 | D25: =45572-4679 -> 40893 | E25: =SUM(C25:D25) -> 842189 | F25: 14.06.2026 | G25: 858712 | H25: 0.07 | I25: SCB
C26: =SUM(C24:C25) -> 847216 | D26: =SUM(D24:D25) -> 42441 | E26: =SUM(E24:E25) -> 889657 | G26: =SUM(G24:G25) -> 908100
A28: Education & Training Fund
A29: TD1000855877_02 | B29: 15.09.2025 | C29: 22961 | D29: =860-86 -> 774 | E29: =SUM(C29:D29) -> 23735 | F29: 15.10.2026 | G29: 24695 | H29: 0.068 | I29: SCB
A30: TD1001240638_01 | B30: 26.06.2025 | C30: 1365 | D30: =70-6 -> 64 | E30: =SUM(C30:D30) -> 1429 | F30: 26.06.2026 | G30: 1457 | H30: 0.066 | I30: SCB
C31: =SUM(C29:C30) -> 24326 | D31: =SUM(D29:D30) -> 838 | E31: =SUM(E29:E30) -> 25164 | G31: =SUM(G29:G30) -> 26152
A33: Grand Total | C33: =C8+C13+C17+C21+C26+C31 -> 1425496 | D33: =D8+D13+D17+D21+D26+D31 -> 62482 | E33: =E8+E13+E17+E21+E26+E31 -> 1487978 | G33: =G8+G13+G17+G21+G26+G31 -> 1528829

Sheet Sch II,III & IV 
A1: =BS!A1 -> FAIR FIELD CO-OPERATIVE HOUSING SOCIETY LTD.
B3: Schedule II : Dues from Members as no 31 March 2026
B4: Flat no | C4: Member Name | D4: Amt
B5: 303 | C5: Ms. Maureen Rodrigues | D5: 9826
B6: 401 | C6: Mr. Allwyn Sequeira | D6: 725
B7: Total | D7: =SUM(D5:D6) -> 10551
B9: Schedule III : Advance from Members as no 31 March 2026
B10: Flat no | C10: Member Name | D10: Amt
B11: 301 | C11: Ms. Bernadette D'Souza | D11: 408
B12: 501 | C12: Ms. Linda Pereira | D12: 6373
B13: 601 | C13: Mr. Fletcher Martins | D13: 12800
B14: Total | D14: =SUM(D11:D13) -> 19581
A17: Schedule IV : Current Liabilities and Provisions as no 31 March 2026
A18: Sr.no | B18: FY 2024-25 | C18: Particular | D18: FY 2025-26
A19: 1 | B19: 8950 | C19: Adani Electricity | D19: 9110
A20: 2 | B20: 1000 | C20: Gardener | D20: 1000
A21: 3 | B21: 19750 | C21: Watchman | D21: 20250
A22: 4 | B22: 4500 | C22: Professional Fees | D22: 1500
A23: 5 | B23: 4000 | C23: Audit Fees | D23: 6000
A24: 6 | B24: 3491 | C24: Water Charges | D24: 3923
A25: 9 | B25: 0 | C25: Savita | D25: 2130
A26: 10 | B26: 101814 | C26: Property Tax BMC | D26: =6613+101814 -> 108427
A27: 11 | B27: 6600 | C27: Income Tax | D27: 6600
A28: 12 | B28: 0 | C28: TDS Payable | D28: 11490
B29: =SUM(B19:B28) -> 150105 | C29: Total | D29: =SUM(D19:D28) -> 170430

Sheet BRS
A1: Fair Field CHS
A2: Saraswat Bank Reconciliation Statement as on 31.03.2026
D3: Amount
B4: Balance as per System (Book Balance) | D4: 426209.01
A6: Less: | B6: Cheque issued but not presented (Outflow) | D6: =I6 -> 0
A8: Add: | B8: Amount credited in Bank but not entered in the system (Deposit) | D8: 0
D10: 0
B12: Balance as per Bank Passbook | D12: 426209.01
D13: =D4-D12 -> 0
A15: Fair Field CHS
A16: MDCC Reconciliation Statement as on 31.03.2026
D17: Amount
B18: Balance as per System (Book Balance) | D18: 11775
A20: Add: | B20: Cheque deposited but not cleared (Inflow) | D20: 0
A22: Less: | B22: Amount Debited by Bank but not entered in the system (Issued) | D22: 0
D23: =D18-D20-D22 -> 11775
B25: Balance as per Bank Passbook | D25: 11775
D26: =D23-D25 -> 0

Sheet Workings
B2: Note: Workings Page is not the be printed
B4: Water Expense
B6: Period | D6: Days | E6: Amount
B7: 45698 | C7: 46059 | D7: =C7-B7 -> 361 | E7: =20109+6613 -> 26722
B8: =C7 -> 46059 | C8: 46112 | D8: =C8-B8 -> 53 | E8: =E7*D8/D7 -> 3923.1745 | F8: Provision
B10: Lift Maintenance AMC
B11: Period | D11: Days | E11: Amount
B12: 46023 | C12: 46387 | D12: =C12-B12+1 -> 365 | E12: 17700
B13: 46113 | C13: 46387 | D13: =C13-B13+1 -> 275 | E13: =E12*D13/D12 -> 13335.616 | F13: Prepaid
B15: Insurance
B16: Period | D16: Days | E16: Amount
B17: 45961 | C17: 46325 | D17: =C17-B17+1 -> 365 | E17: 16302
B18: 46113 | C18: 46325 | D18: =C18-B18+1 -> 213 | E18: =E17*D18/D17 -> 9513.2219 | F18: Prepaid
B20: Pest Control
B21: Period | D21: Days | E21: Amount
B22: 46113 | C22: 46477 | D22: =C22-B22+1 -> 365 | E22: 5400
B23: 46113 | C23: 46477 | D23: =C23-B23+1 -> 365 | E23: =E22*D23/D22 -> 5400 | F23: Prepaid
B26: Period | D26: Days | E26: Amount
B27: 45809 | C27: 46173 | D27: =C27-B27+1 -> 365 | E27: 3200
B28: 46113 | C28: 46173 | D28: =C28-B28+1 -> 61 | E28: =E27*D28/D27 -> 534.79452 | F28: Prepaid
