Workbook

Sheet BALANCE SHEET
A1: SPARSH CO-OPERATIVE HOUSING SOCIETY LTD
A2: (Regn. No.BOM/W-P/HSG/(T.C.)/4158/88-89)
A3: BALANCE SHEET AS ON 31ST MARCH 2025
A4: MAR-2024 | B4: LIABILITIES | D4: MAR-2025 | E4: =A4 -> MAR-2024 | F4: ASSETS | H4: =D4 -> MAR-2025
A5: 5000 | B5: Share Capital | C5: 5000 | F5: CASH & BANK BALANCES :
A6: 0 | B6: Add: Additional 5 shares from old members | C6: =250*20 -> 5000 | E6: 5650 | F6: Cash in hand | G6: 1488
B7: Add: Additional 10 shares from new members | C7: =500*32 -> 16000 | D7: =SUM(C5:C7) -> 26000 | E7: 180376.41 | F7: Saraswat Bank | G7: =BRS!C6 -> 1057355.6
E8: 68660.08 | F8: Jankalyan Bank | G8: =BRS!C18 -> 489668.24 | H8: =SUM(G6:G8) -> 1548511.9
B9: Reserve Fund :
A10: 1982157.6 | B10: Balance B/f | C10: =1982157.6+25000 -> 2007157.6
A11: 25000 | B11: Add: Addition during the year | C11: 54800
A12: 0 | B12: Less: Refund back to old Member | C12: =-1610486-113000-113000-113000-57671.6 -> -2007157.6 | F12: INVESTMENTS :
A13: 0 | B13: Add: 25% Surplus | C13: ='INCOME & EXP'!C63 -> 171714 | D13: =SUM(C10:C13) -> 226514 | E13: 533805.5 | F13: FDR with Janalalyan Bank | G13: 0
B14: Sinking Fund : | E14: 1891954 | F14: FDR with Saraswat Bank | G14: 0
A15: 0 | B15: Balance B/f | C15: 0 | E15: 500 | F15: Shares of JKN Coop Hsg Fed | G15: 500
B16: Add: Addition during the year | C16: 214428 | D16: =SUM(C15:C16) -> 214428 | E16: 1000 | F16: Share of MDCC Bank | G16: 1000
B17: Redevelopment Deposit : | E17: 16754 | F17: Security Deposit with Adani | G17: 25722 | H17: =SUM(G13:G17) -> 27222
A18: 548324 | B18: Balance B/f | C18: =548324-11810 -> 536514
A19: -11810 | B19: Less: Expenses Paid by Society | C19: ='INCOME & EXP'!C12+'INCOME & EXP'!C21-C33 -> -347511 | D19: =SUM(C18:C19) -> 189003 | E19: 0 | F19: Fixed Asset Sch-I | H19: ='FA Sch-I'!H9 -> 78894
B20: Repair Fund :
A21: 0 | B21: Balance B/f | C21: 0 | F21: Other Current Assets:
A22: 0 | B22: Add: Addition during the year | C22: 643524 | E22: 0 | F22: Member Receivables (Sch-II) | G22: ='Sch-II & III'!D11 -> 232041
B23: Less: Refund back to old Member | C23: =-26842.4-113000 -> -139842.4 | D23: =SUM(C21:C23) -> 503681.6 | E23: 10623 | F23: TDS Receivables FY 24-25 | G23: 2581
A24: 10830 | B24: Education & Training Fund : | C24: 10830 | E24: 0 | F24: Prepaid Expense (Sch-III) | G24: ='Sch-II & III'!D24 -> 210234 | H24: =SUM(G22:G24) -> 444856
A25: 0 | B25: Add: Addition during the year | C25: =10*52*12 -> 6240 | D25: =SUM(C24:C25) -> 17070
A27: 0 | B27: Payables & Provisions (Sch-IV) | D27: ='Sch-IV & V'!D23 -> 277744
A29: 0 | B29: Advance Members (Sch-V) | D29: ='Sch-IV & V'!D30 -> 11258
B31: Income & Expenditure A/c :
A32: 145377.39 | B32: Balance B/f | C32: =145377.39+4444 -> 149821.39
A33: 0 | B33: Add: Builder Period Electricity adjst agst EMD | C33: 20340
A34: 0 | B34: Less: Excess Provision write off | C34: -51517 | J34: Pre-matured closure of FDR by society
A35: 4444 | B35: Add: Surplus during the year | C35: ='INCOME & EXP'!C62 -> 515140.9 | D35: =SUM(C32:C35) -> 633785.29
A37: =SUM(A5:A36) -> 2709323 | B37: TOTAL | D37: =SUM(D5:D36) -> 2099483.9 | E37: =SUM(E5:E36) -> 2709323 | F37: TOTAL | H37: =SUM(H5:H36) -> 2099483.9
A39: As per my report of even date | I39: =A37-E37 -> 0
F40: FOR SPARSH CO-OPERATIVE HOUSING SOCIETY LTD
I42: =A37-E37 -> 0 | J42: =D37-H37 -> 0
A44: Shri. Bharat C. Boridkar
A45: Govt. Certified Panel Auditor | F45: Chairman Secretary Treasurer
A46: [Panel No.: Mumbai-4/B2/1011404]
A47: 45892

Sheet INCOME & EXP
A1: SPARSH CO-OPERATIVE HOUSING SOCIETY LTD
A2: (Regn. No.BOM/W-P/HSG/(T.C.)/4158/88-89)
A3: STATEMENT OF INCOME & EXPENDITURE A/C FOR THE YEAR ENDED 31ST MARCH 2025
A4: MAR-2024 | B4: EXPENDITURE | D4: MAR-2025 | E4: =A4 -> MAR-2024 | F4: INCOME | H4: =D4 -> MAR-2025
B5: Salary Expense | F5: Members Contribution Towards:
A6: 0 | B6: Gardener | C6: =5000*11 -> 55000 | E6: 0 | F6: Insurance Charges | G6: 29952
A7: 0 | B7: Housekeeper | C7: =21000+80000 -> 101000 | E7: 0 | F7: Electricity Charges | G7: 571584
A8: 0 | B8: Manager | C8: =72000+6000 -> 78000 | E8: 0 | F8: Water Charges | G8: 149952
A9: 0 | B9: Bonus | C9: 4000 | D9: =SUM(C6:C9) -> 238000 | E9: 0 | F9: Service Charges | G9: 1730976
E10: 0 | F10: Non Occupancy Charge | G10: =73431+111 -> 73542
A11: 0 | B11: Property Tax | C11: 226871 | E11: 0 | F11: Late Payment Interest | G11: 22487
A12: 0 | B12: Less: Builder's liability trfd to EMD | C12: -226871 | D12: =SUM(C11:C12) -> 0 | E12: 48000 | F12: Sub-lettee Shifting Charges | G12: 60000
E13: 0 | F13: Penalty | G13: 2000 | H13: =SUM(G6:G13) -> 2640493
A14: 0 | B14: Electricity Expenses | D14: 357584
A16: 0 | B16: Water Expenses | D16: =Workings!F21+Workings!F22 -> 142800
B17: (Includes Provision Rs.1,19,000)
B19: AMC's Expenses | F19: Income from other sources:
A20: 0 | B20: Lift | C20: 139404 | E20: 10154 | F20: Saving Bank Interest | G20: 39949
B21: Less: Builder's liability trfd to EMD | C21: -100300 | E21: 134974 | F21: Fixed Deposit Interest | G21: 32784
A22: 0 | B22: Intercom | C22: 5601 | E22: 0 | F22: Interest on IT Refund | G22: 367
A23: 0 | B23: Bird Net | C23: 1365 | E23: 0 | F23: Miscellaneous Income | G23: 3.08
A24: 0 | B24: CCTV | C24: 4073 | D24: =SUM(C20:C24) -> 50143 | E24: 9440 | F24: Income Tax refund received | G24: 0 | H24: =SUM(G20:G24) -> 73103.08
B26: Repairs & Maintenance Expense
A27: 0 | B27: Garden Maintenance | C27: 38889
A28: 161625 | B28: Bird-net Expenses | C28: 0
A29: 0 | B29: Gym Expense | C29: 31050
A30: 0 | B30: Electrical Expenses | C30: 10443
A31: 990 | B31: Other Expenses | C31: 23966
B32: Pest Control | C32: 44800 | D32: =SUM(C27:C32) -> 149148
B34: Monthly Expenses
A35: 6000 | B35: Accounting Charges | C35: 53790
A36: 0 | B36: Security Expenses | C36: 753445
A37: 0 | B37: House Keeping Expenses | C37: 64446
A38: 0 | B38: House Keeping Materials | C38: 9810
A39: 0 | B39: Subscription Charges of Security App | C39: 12000 | D39: =SUM(C35:C39) -> 893491
B42: Administrative & Other Expenses
A43: 3850 | B43: Subscription Federation | C43: =6250+2478 -> 8728
A44: 0 | B44: Income Tax Expense | C44: 9500
A45: 4981 | B45: Conveyance | C45: 2453
A46: 0 | B46: Legal Fees | C46: 21000
...

Sheet FA Sch-I
A1: =+'INCOME & EXP'!A1:H1 -> SPARSH CO-OPERATIVE HOUSING SOCIETY LTD
A2: Sch I - Fixed Assets as on 31.03.2025
A3: Particulars | B3: Rate % | C3: Opening W.D.V. as on 01.04.2024 | D3: Additions during the year before 30.09.2024 | E3: Additions during the year after 30.09.2024 | F3: Gross Block (at cost) as on 31.03.2025 | G3: Depreciation for the year | H3: Closing W.D.V. as on 31.03.2025
A4: Ladder | B4: 0.1 | C4: 0 | D4: 0 | E4: 17000 | F4: =C4+D4+E4 -> 17000 | G4: =ROUND(((D4+C4)*B4)+(E4*B4)/2,0) -> 850 | H4: =F4-G4 -> 16150
A5: Mobile | B5: 0.15 | C5: 0 | D5: 10010 | E5: 0 | F5: =C5+D5+E5 -> 10010 | G5: =ROUND(((D5+C5)*B5)+(E5*B5)/2,0) -> 1502 | H5: =F5-G5 -> 8508
A6: Fan | B6: 0.15 | C6: 0 | D6: 4750 | E6: 0 | F6: =C6+D6+E6 -> 4750 | G6: =ROUND(((D6+C6)*B6)+(E6*B6)/2,0) -> 713 | H6: =F6-G6 -> 4037
A7: Computer & Printer | B7: 0.4 | C7: 0 | D7: 55165 | E7: 0 | F7: =C7+D7+E7 -> 55165 | G7: =ROUND(((D7+C7)*B7)+(E7*B7)/2,0) -> 22066 | H7: =F7-G7 -> 33099
A8: Furniture | B8: 0.1 | C8: 0 | D8: 0 | E8: =15000+3000 -> 18000 | F8: =C8+D8+E8 -> 18000 | G8: =ROUND(((D8+C8)*B8)+(E8*B8)/2,0) -> 900 | H8: =F8-G8 -> 17100
A9: Total | C9: =SUM(C4:C8) -> 0 | D9: =SUM(D4:D8) -> 69925 | E9: =SUM(E4:E8) -> 35000 | F9: =SUM(F4:F8) -> 104925 | G9: =SUM(G4:G8) -> 26031 | H9: =SUM(H4:H8) -> 78894
A14: Lift
A15: Machanical Stack
A16: Water Pump
A17: Fire Equipments
A18: CCTV/ Intercom
A19: Gym Equipments
A20: Bird Nets
A21: Gate
A22: Air Conditioner
A23: Land & Builder Cost | B23: to be shown in BS

Sheet Sch-II & III
A2: Schedule-II
A3: =+'FA Sch-I'!A1:H1 -> SPARSH CO-OPERATIVE HOUSING SOCIETY LTD
A4: Member's Receivable as on 31st March 2025
A5: Sr. no. | B5: Flat no. | C5: Name of Member | D5: Amount
A6: 1 | B6: 0102 | C6: Ms. Shamal Shetty and Mr. Saurabh Santosh Shukla | D6: 6903
A7: 2 | B7: 0801 | C7: Mr. Sumit Nair & Mr. Rahul Nair | D7: 17689
A8: 3 | B8: 1003 | C8: Mr. Balkrishna Kisan Chaudhari and Jayashri B Chaudhari | D8: 67384
A9: 4 | B9: 1004 | C9: Mr. Balkrishna Kisan Chaudhari and Jayashri B Chaudhari | D9: 62334
A10: 5 | B10: 1302 | C10: Mrs. Sitabai Bhagwandas Vagh and Mrs. Renuka Subhash Asar | D10: 77731
A11: Total | D11: =SUM(D6:D10) -> 232041
A15: Schedule-III
A16: =+A3 -> SPARSH CO-OPERATIVE HOUSING SOCIETY LTD
A17: Prepaid Expense as on 31st March 2025
A18: Sr. no. | B18: Vendor | C18: Account Head | D18: Amount
A19: 1 | B19: Schindler | C19: Lift AMC - From 01.04.2025 to 29.10.2025 | D19: 161496
A20: 2 | B20: Electronic India | C20: Intercom AMC - From 01.04.2025 to 31.12.2025 | D20: 17114
A21: 3 | B21: Supreme Care | C21: Bird Net AMC - From 01.04.2025 to 04.05.2027 | D21: 2775
A22: 4 | B22: Electronic India | C22: CCTV AMC - From 01.04.2025 to 31.12.2025 | D22: 12447
A23: 5 | B23: ICICI Lombard | C23: Insurance - From 01.04.2025 to 27.01.2026 | D23: =Workings!F26 -> 16402
A24: Total | D24: =SUM(D19:D23) -> 210234

Sheet Sch-IV & V
A2: Schedule-IV
A3: =+'Sch-II & III'!A3:D3 -> SPARSH CO-OPERATIVE HOUSING SOCIETY LTD
A4: Payables as on 31st March 2025
A5: Sr. no. | B5: Vendor | C5: Remarks | D5: Amount
A6: 1 | B6: Manager | C6: Cavin Rodrigues - March 2025 Salary | D6: 12000
A7: 2 | B7: Adani | C7: Electricity charges - March 2025 | D7: 28840
A8: 3 | B8: Gardener | C8: Sunil Sah - March 2025 Salary | D8: 5000
A9: 4 | B9: Housekeeper | C9: Sheela Savda - March 2025 Salary | D9: 10000
A10: 5 | B10: Ivan Rosario | C10: Accounting charges - March 2025 | D10: 5310
A11: 6 | B11: MCGM | C11: Water charges - Period 16.04.2024 to 16.05.2024 | D11: 11900
A12: 7 | B12: Nelumbo Enterprises | C12: Security charges - March 2025 | D12: 14845
A13: 8 | B13: Team Armor Four | C13: Security charges - March 2025 | D13: 53671
A14: 9 | B14: MDCHF | C14: Subscription Federation - FY 24-25 with Arrear | D14: 2478
A15: Total (A) | D15: =SUM(D6:D14) -> 144044
A17: Provision as on 31st March 2025
A18: Sr. no. | B18: Vendor | C18: Remarks | D18: Amount
A19: 1 | B19: Auditor | C19: Audit fee - FY 2024-25 | D19: 5200
A20: 2 | B20: Gardener | C20: Water Expense - Jun 2024 to Mar 2025 | D20: 119000
A21: 3 | B21: - | C21: Income Tax - FY 2024-25 | D21: 9500
A22: Total (B) | D22: =SUM(D19:D21) -> 133700
A23: C = (A+B) | D23: =D15+D22 -> 277744
A25: Schedule-V
A26: Members Advance as of 31st March 2025
A27: Sr. no. | B27: Flat no. | C27: Name of Members | D27: Amount
A28: 1 | B28: 0101 | C28: Mr. Unnikrishnan Ashokan Mannel & Ashokan Bhaskaran | D28: 6000
A29: 2 | B29: 1103 | C29: Mr. Flavius Augustine Chettiar and Mrs. Elenka Rodrigues | D29: 5258
A30: Total | D30: =SUM(D28:D29) -> 11258

Sheet BRS
A2: SPARSH CO-OPERATIVE HOUSING SOCIETY LTD
B4: Saraswat Bank reconciliation statement as on 31st March 2025 | E4: Date | F4: Deposit | G4: Issued | H4: Instru. No. | I4: Vendor/ flat | J4: Comments | K4: Cleared on
C5: Amount | E5: 27.03.2025 | G5: 226871 | H5: 173128 | I5: BMC | J5: Property Tax | K5: 03.04.2025
B6: Balance as per System | C6: 1057355.6 | E6: 30.03.2025 | F6: 5258 | H6: SZP010987065 | I6: 1103 | J6: Maintenance | K6: 03.04.2025
F7: =SUM(F5:F6) -> 5258 | G7: =SUM(G5:G6) -> 226871
A8: Add: | B8: Chq issued but not cleared as on 31.03.2024 | C8: =G7 -> 226871
A10: Less: | B10: Chq deposited but not cleared as on 31.03.2024 | C10: =F7 -> 5258
C12: =C6+C8-C10+C11 -> 1278968.6
B13: Balance as per Pass Book | C13: 1278968.6
C14: =C12-C13 -> 0
B16: Janakalyan Bank reconciliation statement as on 31st March 2025
C17: Amount
B18: Balance as per System | C18: 489668.24
B20: Balance as per Pass Book | C20: 489668.24
C21: =C18-C20 -> 0

Sheet Workings
C1: Period | E1: No. of Days / month
B2: Account Head | C2: From | D2: To | F2: Amount
K3: Income Tax Provision
A4: 1 | B4: Lift AMC | K4: Income from Savings A/c. | M4: ='INCOME & EXP'!G20 -> 39949
C5: 45565 | D5: 45959 | E5: =D5-C5+1 -> 395 | F5: 300900 | K5: Income from Fixed Deposit | M5: ='INCOME & EXP'!G21 -> 32784
C6: 45748 | D6: 45959 | E6: =D6-C6+1 -> 212 | F6: =ROUND(E6*F5/E5,0) -> 161496 | G6: Prepaid | K6: Benefit of 80p2d | M6: =-M5 -> -32784
K7: Interest on IT Refund | M7: ='INCOME & EXP'!G22 -> 367
A8: 2 | B8: Intercom AMC | K8: Sale of scrap & Promotional | M8: =[1]IE!I29 -> 0
C9: 45658 | D9: 46022 | E9: =D9-C9+1 -> 365 | F9: 22715 | K9: Net Taxable Income | M9: =SUM(M4:M8) -> 40316
C10: 45748 | D10: 46022 | E10: =D10-C10+1 -> 275 | F10: =ROUND(E10*F9/E9,0) -> 17114 | G10: Prepaid | K10: 0-10000 | L10: 0.1 | M10: 1000
K11: 10000-20000 | L11: 0.2 | M11: 2000
A12: 3 | B12: Bird Net AMC | K12: 20000 or More | L12: 0.3 | M12: =ROUND((M9-20000)*30%,0) -> 6095
C13: 45417 | D13: 46511 | E13: =D13-C13+1 -> 1095 | F13: 4140 | K13: Tax | M13: =SUM(M10:M12) -> 9095
C14: 45778 | D14: 46511 | E14: =D14-C14+1 -> 734 | F14: =ROUND(E14*F13/E13,0) -> 2775 | G14: Prepaid | K14: Education cess | L14: 0.04 | M14: =M13*4% -> 363.8
K15: Total Tax | M15: =M13+M14 -> 9458.8
A16: 4 | B16: CCTV AMC | K16: Say | M16: =ROUND(M15,-2) -> 9500
C17: 45658 | D17: 46022 | E17: =D17-C17+1 -> 365 | F17: 16520
C18: 45748 | D18: 46022 | E18: =D18-C18+1 -> 275 | F18: =ROUND(E18*F17/E17,0) -> 12447 | G18: Prepaid
A20: 5 | B20: Water Charges
C21: 45383 | D21: 45413 | E21: 2 | F21: =11900+11900 -> 23800
C22: 45444 | D22: 45717 | E22: 10 | F22: =E22*F21/E21 -> 119000 | G22: Provision
A24: 6 | B24: Insurance
C25: 45685 | D25: 46049 | E25: =D25-C25+1 -> 365 | F25: 19824
C26: 45748 | D26: =D25 -> 46049 | E26: =D26-C26+1 -> 302 | F26: =ROUND(E26*F25/E25,0) -> 16402 | G26: Prepaid
F29: Adani | G29: Deposit
F30: Ac-153587768 | G30: 3120
F31: Ac-153544448 | G31: 400
F32: Ac-153563364 | G32: 720
F33: Ac-153454115 | G33: 16842
F34: Ac-153457629 | G34: 4640
G35: =SUM(G30:G34) -> 25722

Sheet Notes
B3: Notes
A4: 1 | B4: Provision for 1 member payable to Res.F A5 -1003/1004 | C4: Sch
A5: 2 | B5: Land & building to be shown in BS
D11: 492099.5
D12: 73245
D14: FD | E14: Principle | F14: Int-Accrued
D15: =+E15+F15 -> 1891954 | E15: 1860415 | F15: 31539
D16: =+E16+F16 -> 533805.5 | E16: 492099.5 | F16: =73245-31539 -> 41706
