Workbook

Sheet BALANCE SHEET
A1: SPARSH CO-OPERATIVE HOUSING SOCIETY LTD
A2: (Regn. No.BOM/W-P/HSG/(T.C.)/4158/88-89)
A3: BALANCE SHEET AS ON 31ST MARCH 2026
A4: MAR-2025 | B4: LIABILITIES | D4: MAR-2026 | E4: =A4 -> MAR-2025 | F4: ASSETS | H4: =D4 -> MAR-2026
A5: 5000 | B5: Share Capital | C5: 5000 | F5: CASH & BANK BALANCES :
A6: 5000 | B6: Add: Additional 5 shares from old members | C6: =250*20 -> 5000 | E6: 1488 | F6: Cash in hand | G6: 2629
A7: 16000 | B7: Add: Additional 10 shares from new members | C7: =500*32 -> 16000 | D7: =SUM(C5:C7) -> 26000 | E7: 1057355.6 | F7: Saraswat Bank | G7: =BRS!C6 -> 187598.36
E8: 489668.24 | F8: Jankalyan Bank | G8: =BRS!C15 -> 99229.5 | H8: =SUM(G6:G8) -> 289456.86
B9: Reserve Fund :
A10: 2007157.6 | B10: Balance B/f | C10: 226514 | F10: INVESTMENTS :
A11: 54800 | B11: Add: Addition during the year | C11: 51900 | E11: 0 | F11: Fixed Deposit (Sch-I) | G11: ='FDR Sch-I'!D33 -> 1588907
A12: 0 | B12: Add: Interest earned/accrued during the year | C12: =-'INCOME & EXP'!G23 -> 3931 | E12: 0 | F12: Accrued Interest on FDR | G12: ='FDR Sch-I'!E33 -> 57227
A13: -2007157.6 | B13: Less: Refund back to old Member | C13: 0 | E13: 500 | F13: Shares of JKN Coop Hsg Fed | G13: 500
A14: 171714 | B14: Add: 25% Surplus | C14: ='INCOME & EXP'!C67 -> 0 | D14: =SUM(C10:C14) -> 282345 | E14: 1000 | F14: Share of MDCC Bank | G14: 1000
E15: 25722 | F15: Security Deposit with Adani | G15: =2390+720+400+17825.09+4953.2 -> 26288.29 | H15: =SUM(G11:G15) -> 1673922.3
B16: Sinking Fund :
A17: 0 | B17: Balance B/f | C17: 214428 | E17: 78894 | F17: Fixed Asset Sch-II | H17: ='FA Sch-II'!H16 -> 307695
A18: 214428 | B18: Add: Addition during the year | C18: 214428
A19: 0 | B19: Add: Interest earned/accrued during the year | C19: =-'INCOME & EXP'!G20 -> 14368 | D19: =SUM(C17:C19) -> 443224 | F19: Other Current Assets:
E20: 232041 | F20: Member Receivables (Sch-III) | G20: ='Sch-III & IV'!D14 -> 504126
B21: Redevelopment Deposit : | F21: TDS Receivables
A22: 536514 | B22: Balance B/f | C22: 189003 | E22: 2581 | F22: FY 2024-25 | G22: 0
A23: -347511 | B23: Add: Expenses Paid by Society | C23: =100300+226871 -> 327171 | E23: 0 | F23: FY 2025-26 | G23: 8940
A24: 0 | B24: Add: Interest earned/accrued during the year | C24: =-'INCOME & EXP'!G24 -> 276 | D24: =SUM(C22:C24) -> 516450 | E24: 210234 | F24: Prepaid Expense (Sch-IV) | G24: ='Sch-III & IV'!D29 -> 246966 | H24: =SUM(G20:G24) -> 760032
B26: Repair Fund :
A27: 0 | B27: Balance B/f | C27: 503681.6
A28: 643524 | B28: Add: Addition during the year | C28: 643524
A29: 0 | B29: Add: Interest earned/accrued during the year | C29: =-'INCOME & EXP'!G21 -> 42179
A30: -139842.4 | B30: Less: Refundable to old member (1003/1004) | C30: =-D41 -> -113000 | D30: =SUM(C27:C30) -> 1076384.6
B32: Education & Training Fund :
A33: 10830 | B33: Balance B/f | C33: 17070
A34: 6240 | B34: Add: Addition during the year | C34: =10*52*12 -> 6240
A35: 0 | B35: Add: Interest earned/accrued during the year | C35: =-'INCOME & EXP'!G22 -> 1128 | D35: =SUM(C32:C35) -> 24438
A37: 277744 | B37: Payables & Provisions (Sch-V) | D37: ='Sch-V & VI'!D23 -> 475938
A39: 11258 | B39: Advance Members (Sch-VI) | D39: ='Sch-V & VI'!D32 -> 11614
A41: 0 | B41: Statutory Fund Payable to Flat 1003/1004 | D41: 113000
B43: Income & Expenditure A/c :
A44: 149821.39 | B44: Balance B/f | C44: =149821.39+20340-51517+515140.9 -> 633785.29
A45: 20340 | B45: Less: Builder Period Expense adjst agst EMD | C45: 0
A46: -51517 | B46: Less: Pre-matured closure of FDR by society | C46: 0
...

Sheet INCOME & EXP
A1: SPARSH CO-OPERATIVE HOUSING SOCIETY LTD
A2: (Regn. No.BOM/W-P/HSG/(T.C.)/4158/88-89)
A3: STATEMENT OF INCOME & EXPENDITURE A/C FOR THE YEAR ENDED 31ST MARCH 2026
A4: MAR-2025 | B4: EXPENDITURE | D4: MAR-2026 | E4: =A4 -> MAR-2025 | F4: INCOME | H4: =D4 -> MAR-2026
B5: Salary Expense | F5: Members Contribution Towards:
A6: 55000 | B6: Gardener | C6: =5000*12 -> 60000 | E6: 29952 | F6: Insurance Charges | G6: 13550
A7: 101000 | B7: Housekeeper | C7: =(10000*7)+(11000*5) -> 125000 | E7: 571584 | F7: Electricity Charges | G7: 571584
A8: 78000 | B8: Manager | C8: =(12000*11)+(16000) -> 148000 | E8: 149952 | F8: Water Charges | G8: 149952
A9: 0 | B9: Valet Driver | C9: 144500 | E9: 1730976 | F9: Service Charges | G9: 1730976
A10: 4000 | B10: Bonus | C10: =5000+10000+12000+22000+22000+15000+15000+500 -> 101500 | D10: =SUM(C6:C10) -> 579000 | E10: 73542 | F10: Non Occupancy Charge | G10: 79704
E11: 22487 | F11: Late Payment Interest | G11: 62225
A12: 226871 | B12: Property Tax | C12: 291969 | E12: 60000 | F12: Sub-lettee Shifting Charges | G12: 12000
A13: -226871 | B13: Less: Builder's liability trfd to EMD | C13: 0 | D13: =SUM(C12:C13) -> 291969 | E13: 0 | F13: Other Charges | G13: 1000
E14: 2000 | F14: Penalty | G14: 0 | H14: =SUM(G6:G14) -> 2620991
A15: 357584 | B15: Electricity Expenses | D15: 387509.71
A17: 142800 | B17: Water Expenses | D17: =+Workings!F23 -> 142800 | F17: Income from other sources:
B18: (Includes Provision Rs.1,19,000) | E18: 39949 | F18: Saving Bank Interest | G18: 29922
E19: 32784 | F19: Fixed Deposit Interest | G19: 63586
B20: AMC's Expenses | E20: 0 | F20: Less: Trfd to Sinking Fund | G20: -14368
A21: 139404 | B21: Lift | C21: 388751 | E21: 0 | F21: Less: Trfd to Repair Fund | G21: -42179
A22: -100300 | B22: Less: Builder's liability trfd to EMD | C22: 0 | E22: 0 | F22: Less: Trfd to Education Fund | G22: -1128
A23: 5601 | B23: Intercom | C23: 22715 | E23: 0 | F23: Less: Trfd to Reserv Fund | G23: -3931
A24: 1365 | B24: Bird Net | C24: 1380 | E24: 0 | F24: Less: Redevelopment Fund | G24: -276
A25: 0 | B25: Fire Fighting | C25: 46512 | E25: 367 | F25: Interest on IT Refund | G25: 0
A26: 0 | B26: Stack Parking | C26: 87517 | E26: 3.08 | F26: Miscellaneous Income | G26: 3001
A27: 0 | B27: AC | C27: 2000 | E27: 0 | F27: Income Tax refund received | G27: 0 | H27: =SUM(G18:G27) -> 34627
A28: 44800 | B28: Pest Control | C28: 44800
A29: 4073 | B29: CCTV | C29: 17248 | D29: =SUM(C21:C29) -> 610923
B31: Repairs & Maintenance Expense
A32: 38889 | B32: Garden Maintenance | C32: =2500+900+1000+7100+3000 -> 14500
A33: 0 | B33: Water Tank Cleaning | C33: 12500
A34: 31050 | B34: Gym Expense | C34: 0
A35: 10443 | B35: Electrical Expenses | C35: 42966
A36: 23966 | B36: Other Expenses | C36: =42020+8000 -> 50020
B37: Plumbing Expense | C37: 4400
A38: 0 | B38: Fire Fighting | C38: 7080 | D38: =SUM(C32:C38) -> 131466
B40: Monthly Expenses
A41: 53790 | B41: Accounting Charges | C41: 63720
A42: 753445 | B42: Security Expenses | C42: 860258
A43: 64446 | B43: House Keeping Expenses | C43: 0
...

Sheet FDR Sch-I
A1: SPARSH CO-OPERATIVE HOUSING SOCIETY LTD
A3: Schedule I - Details of Fixed Deposits with Banks as on 31st March 2026
A5: Sr No. | B5: Certificate No. | C5: Date | D5: Amount Invested | E5: Accrued Int. 2025-26 | F5: Total | G5: Maturity Date | H5: Maturity Value | I5: Interest % | J5: Bank
B6: General Reserve Fund
A7: 1 | B7: TD1001647777 | C7: 15.05.2025 | D7: 55000 | E7: =3605-360 -> 3245 | F7: =SUM(D7:E7) -> 58245 | G7: 15.05.2027 | H7: 63562 | I7: 0.073 | J7: SCB
A8: 2 | B8: TD1002067987 | C8: 24.03.2026 | D8: 223214 | E8: =326-33 -> 293 | F8: =SUM(D8:E8) -> 223507 | G8: 24.07.2027 | H8: 244201 | I8: 0.068 | J8: SCB
D9: =SUM(D7:D8) -> 278214 | E9: =SUM(E7:E8) -> 3538 | F9: =SUM(F7:F8) -> 281752 | H9: =SUM(H7:H8) -> 307763
B11: Sinking Fund
A12: 3 | B12: TD1001647782 | C12: 15.05.2025 | D12: 214428 | E12: =14054-1406 -> 12648 | F12: =SUM(D12:E12) -> 227076 | G12: 15.05.2027 | H12: 247809 | I12: 0.073 | J12: SCB
A13: 4 | B13: TD1002068054 | C13: 24.03.2026 | D13: 214428 | E13: =314-31 -> 283 | F13: =SUM(D13:E13) -> 214711 | G13: 24.07.2027 | H13: 234589 | I13: 0.068 | J13: SCB
D14: =SUM(D12:D13) -> 428856 | E14: =SUM(E12:E13) -> 12931 | F14: =SUM(F12:F13) -> 441787 | H14: =SUM(H12:H13) -> 482398
B16: Repair Fund
A17: 5 | B17: TD1001647789 | C17: 15.05.2025 | D17: 643524 | E17: =42179-4218 -> 37961 | F17: =SUM(D17:E17) -> 681485 | G17: 15.05.2027 | H17: 743704 | I17: 0.073 | J17: SCB
D18: =SUM(D17:D17) -> 643524 | E18: =SUM(E17:E17) -> 37961 | F18: =SUM(F17:F17) -> 681485 | H18: =SUM(H17:H17) -> 743704
B20: Edu. & Trng. Fund
A21: 6 | B21: TD1001647797 | C21: 15.05.2025 | D21: 17070 | E21: =1119-111 -> 1008 | F21: =SUM(D21:E21) -> 18078 | G21: 15.05.2027 | H21: 19727 | I21: 0.073 | J21: SCB
A22: 7 | B22: TD1002068160 | C22: 24.03.2026 | D22: 6240 | E22: =9-1 -> 8 | F22: =SUM(D22:E22) -> 6248 | G22: 24.07.2027 | H22: 6827 | I22: 0.068 | J22: SCB
D23: =SUM(D21:D22) -> 23310 | E23: =SUM(E21:E22) -> 1016 | F23: =SUM(F21:F22) -> 24326 | H23: =SUM(H21:H22) -> 26554
B25: Share Capital
A26: 8 | B26: TD1001647766 | C26: 15.05.2025 | D26: 26000 | E26: =1704-171 -> 1533 | F26: =SUM(D26:E26) -> 27533 | G26: 15.05.2027 | H26: 30048 | I26: 0.073 | J26: SCB
D27: =SUM(D26:D26) -> 26000 | E27: =SUM(E26:E26) -> 1533 | F27: =SUM(F26:F26) -> 27533 | H27: =SUM(H26:H26) -> 30048
B29: Redevelopment Fund
A30: 9 | B30: TD1002068222 | C30: 24.03.2026 | D30: 189003 | E30: =276-28 -> 248 | F30: =SUM(D30:E30) -> 189251 | G30: 24.07.2027 | H30: 206773 | I30: 0.068 | J30: SCB
D31: =SUM(D30:D30) -> 189003 | E31: =SUM(E30:E30) -> 248 | F31: =SUM(F30:F30) -> 189251 | H31: =SUM(H30:H30) -> 206773
B33: GRAND TOTAL | D33: =D9+D14+D18+D23+D27+D31 -> 1588907 | E33: =E9+E14+E18+E23+E27+E31 -> 57227 | F33: =F9+F14+F18+F23+F27+F31 -> 1646134 | H33: =H9+H14+H18+H23+H27+H31 -> 1797240

Sheet FA Sch-II
A1: SPARSH CO-OPERATIVE HOUSING SOCIETY LTD
A2: Sch II - Fixed Assets as on 31.03.2026
A3: Particulars | B3: Rate % | C3: Opening W.D.V. as on 01.04.2025 | D3: Additions during the year before 30.09.2025 | E3: Additions during the year after 30.09.2025 | F3: Gross Block (at cost) as on 31.03.2026 | G3: Depreciation for the year | H3: Closing W.D.V. as on 31.03.2026
A4: Ladder | B4: 0.1 | C4: 16150 | D4: 0 | E4: 0 | F4: =C4+D4+E4 -> 16150 | G4: =ROUND(((D4+C4)*B4)+(E4*B4)/2,0) -> 1615 | H4: =F4-G4 -> 14535
A5: Mobile | B5: 0.15 | C5: 8508 | D5: 0 | E5: 0 | F5: =C5+D5+E5 -> 8508 | G5: =ROUND(((D5+C5)*B5)+(E5*B5)/2,0) -> 1276 | H5: =F5-G5 -> 7232
A6: Fan | B6: 0.15 | C6: 4037 | D6: 0 | E6: 0 | F6: =C6+D6+E6 -> 4037 | G6: =ROUND(((D6+C6)*B6)+(E6*B6)/2,0) -> 606 | H6: =F6-G6 -> 3431
A7: Computer & Printer | B7: 0.4 | C7: 33099 | D7: 0 | E7: 0 | F7: =C7+D7+E7 -> 33099 | G7: =ROUND(((D7+C7)*B7)+(E7*B7)/2,0) -> 13240 | H7: =F7-G7 -> 19859
A8: Furniture | B8: 0.1 | C8: 17100 | D8: 0 | E8: 0 | F8: =C8+D8+E8 -> 17100 | G8: =ROUND(((D8+C8)*B8)+(E8*B8)/2,0) -> 1710 | H8: =F8-G8 -> 15390
A9: Water Pump | B9: 0.15 | C9: 0 | D9: 59000 | E9: 0 | F9: =C9+D9+E9 -> 59000 | G9: =ROUND(((D9+C9)*B9)+(E9*B9)/2,0) -> 8850 | H9: =F9-G9 -> 50150
A10: Society Name Board | B10: 0.1 | C10: 0 | D10: 0 | E10: 13960 | F10: =C10+D10+E10 -> 13960 | G10: =ROUND(((D10+C10)*B10)+(E10*B10)/2,0) -> 698 | H10: =F10-G10 -> 13262
A11: Parking Control Box | B11: 0.15 | C11: 0 | D11: 0 | E11: 20000 | F11: =C11+D11+E11 -> 20000 | G11: =ROUND(((D11+C11)*B11)+(E11*B11)/2,0) -> 1500 | H11: =F11-G11 -> 18500
A12: Dustbin Cabin Room | B12: 0.1 | C12: 0 | D12: 0 | E12: 36000 | F12: =C12+D12+E12 -> 36000 | G12: =ROUND(((D12+C12)*B12)+(E12*B12)/2,0) -> 1800 | H12: =F12-G12 -> 34200
A13: Safety Door | B13: 0.1 | C13: 0 | D13: 0 | E13: 39780 | F13: =C13+D13+E13 -> 39780 | G13: =ROUND(((D13+C13)*B13)+(E13*B13)/2,0) -> 1989 | H13: =F13-G13 -> 37791
A14: Boundry Grill | B14: 0.1 | C14: 0 | D14: 0 | E14: =64500+15200 -> 79700 | F14: =C14+D14+E14 -> 79700 | G14: =ROUND(((D14+C14)*B14)+(E14*B14)/2,0) -> 3985 | H14: =F14-G14 -> 75715
A15: Canteliver Lock | B15: 0.15 | C15: 0 | D15: 0 | E15: =7000+12060 -> 19060 | F15: =C15+D15+E15 -> 19060 | G15: =ROUND(((D15+C15)*B15)+(E15*B15)/2,0) -> 1430 | H15: =F15-G15 -> 17630
A16: Total | C16: =SUM(C4:C15) -> 78894 | D16: =SUM(D4:D15) -> 59000 | E16: =SUM(E4:E15) -> 208500 | F16: =SUM(F4:F15) -> 346394 | G16: =SUM(G4:G15) -> 38699 | H16: =SUM(H4:H15) -> 307695
A21: Lift
A22: Machanical Stack
A23: Water Pump
A24: Fire Equipments
A25: CCTV/ Intercom
A26: Gym Equipments
A27: Bird Nets
A28: Gate
A29: Air Conditioner
A30: Land & Builder Cost | B30: to be shown in BS

Sheet Sch-III & IV
A2: Schedule-III
A3: SPARSH CO-OPERATIVE HOUSING SOCIETY LTD
B4: Member's Receivable as on 31st March 2026
A5: Sr. no. | B5: Flat no. | C5: Name of Member | D5: Amount
A6: 1 | B6: 0502 | C6: Mrs. Hema Sanjay Sawant and Mr. Sanjay Sawant | D6: 5319
A7: 2 | B7: 0801 | C7: Mr. Sumit Nair & Mr. Rahul Nair | D7: =5872+600 -> 6472
A8: 3 | B8: 1003 | C8: Mr. Balkrishna Kisan Chaudhari and Jayashri B Chaudhari | D8: 148883
A9: 4 | B9: 1004 | C9: Mr. Balkrishna Kisan Chaudhari and Jayashri B Chaudhari | D9: 137723
A10: 5 | B10: 1203 | C10: Mr. Sanjeev Rajendra Prasad Singh | D10: 17348
A11: 6 | B11: 1204 | C11: Mr. Sanjeev Rajendra Prasad Singh | D11: 16125
A12: 7 | B12: 1302 | C12: Mrs. Sitabai Bhagwandas Vagh and Mrs. Renuka Subhash Asar | D12: 171656
A13: 8 | B13: 1403 | C13: Mrs. Bhakti V. Ladhani | D13: 600
A14: Total | D14: =SUM(D6:D13) -> 504126
A18: Schedule-IV
A19: SPARSH CO-OPERATIVE HOUSING SOCIETY LTD
B20: Prepaid Expense as on 31st March 2026
A21: Sr. no. | B21: Vendor | C21: Account Head | D21: Amount
A22: 1 | B22: Schindler | C22: Lift AMC - From 01.04.2026 to 28.10.2026 | D22: =Workings!F6 -> 173945
A23: 2 | B23: Electronic India | C23: Intercom AMC - From 01.04.2026 to 31.12.2026 | D23: =Workings!F10 -> 17114
A24: 3 | B24: Amrita Plumarch | C24: Fire Fighting AMC - From 01.04.2026 to 30.04.2026 | D24: =Workings!F31 -> 4228
A25: 4 | B25: Supreme Care | C25: Bird Net AMC - From 01.04.2026 to 04.05.2027 | D25: =Workings!F14-Workings!F15 -> 1395
A26: 5 | B26: Electronic India | C26: CCTV AMC - From 01.04.2026 to 31.12.2026 | D26: =Workings!F19 -> 14669
A27: 6 | B27: ICICI Lombard | C27: Insurance - From 01.04.2026 to 27.01.2027 | D27: =Workings!F27 -> 18112
A28: 7 | B28: Shubham Elevators | C28: Stack AMC - From 01.04.2026 to 30.04.2026 | D28: =Workings!F35 -> 17503
A29: Total | D29: =SUM(D22:D28) -> 246966

Sheet Sch-V & VI
A2: Schedule-V
A3: SPARSH CO-OPERATIVE HOUSING SOCIETY LTD
B4: Payables as on 31st March 2026
A5: Sr. No. | B5: Vendor | C5: Remarks | D5: Amount
A6: 1 | B6: Manager | C6: Cavin Rodrigues - March 2026 Salary | D6: 16000
A7: 2 | B7: Adani | C7: Electricity charges - March 2026 | D7: 33330
A8: 3 | B8: Gardener | C8: Sunil Sah - March 2026 Salary | D8: 5000
A9: 4 | B9: Housekeeper | C9: Sheela Savda - March 2026 Salary | D9: 11000
A10: 6 | B10: MCGM | C10: Water charges - Period 16.04.2024 to 16.05.2024 | D10: 11900
A11: 7 | B11: Nelumbo Enterprises | C11: Security charges - March 2026 | D11: 73160
A12: 8 | B12: MDCHF | C12: Subscription Federation - FY 24-25 with Arrear | D12: 2478
A13: 9 | B13: Amrita Plumarch | C13: Fire Fighting AMC - 50% | D13: 25370
A14: 10 | B14: Valet Parking | C14: Sunil Sah & Santosh - March 2026 | D14: =7000+7000 -> 14000
A15: Total (A) | D15: =SUM(D6:D14) -> 192238
B17: Provision as on 31st March 2026
A18: Sr. No. | B18: Vendor | C18: Remarks | D18: Amount
A19: 1 | B19: Auditor | C19: Audit fee - FY 2025-26 | D19: 5200
A20: 2 | B20: BMC | C20: Water Expense - Jun 2024 to Mar 2026 | D20: =119000+142800 -> 261800
A21: 3 | B21: - | C21: Income Tax - FY 2024-25 | D21: =9500+7200 -> 16700
A22: Total (B) | D22: =SUM(D19:D21) -> 283700
A23: C = (A+B) | D23: =D15+D22 -> 475938
A26: Schedule-VI
A27: Members Advance as of 31st March 2026
A28: Sr. No. | B28: Flat no. | C28: Name of Members | D28: Amount
A29: 1 | B29: 0101 | C29: Mr. Unnikrishnan Ashokan Mannel & Ashokan Bhaskaran | D29: 6172
A30: 2 | B30: 0703 | C30: Mrs. Sharon Gonsalves and Mr. Dallon Gonsalves | D30: 5258
A31: 3 | B31: 1002 | C31: Mrs. Theresa Fernandes | D31: 184
A32: Total | D32: =SUM(D29:D31) -> 11614

Sheet BRS
A2: SPARSH CO-OPERATIVE HOUSING SOCIETY LTD
B4: Saraswat Bank reconciliation statement as on 31st March 2026 | E4: Date | F4: Deposit | G4: Issued | H4: Instru. No. | I4: Vendor/ flat | J4: Comments | K4: Cleared on
C5: Amount | E5: 29.03.2026 | G5: 3250 | H5: 1443 | I5: Jank. Nag. Co-op Hsg Fed. | J5: Jankalyan Fed. | K5: 20.04.2026
B6: Balance as per System | C6: 187598.36 | E6: 31.03.2026 | G6: 12060 | H6: 1444 | I6: Imran A.G. Ansari | J6: Cantilever lock, Coil socket | K6: 10.04.2026
F7: =SUM(F5:F6) -> 0 | G7: =SUM(G5:G6) -> 15310
A8: Add: | B8: Chq issued but not cleared as on 31.03.2026 | C8: =G7 -> 15310
B10: Balance as per Pass Book | C10: =C6+C8 -> 202908.36
B13: Janakalyan Bank reconciliation statement as on 31st March 2026
C14: Amount
B15: Balance as per System | C15: 99229.5
B17: Balance as per Pass Book | C17: 99229.5
C18: =C15-C17 -> 0

Sheet Workings
C1: Period | E1: No. of Days / month
B2: Account Head | C2: From | D2: To | F2: Amount
K3: Income Tax Provision
A4: 1 | B4: Lift AMC | K4: Income from Savings A/c. | M4: ='INCOME & EXP'!G18 -> 29922
C5: 45959 | D5: 46323 | E5: =D5-C5+1 -> 365 | F5: 300900 | K5: Income from Fixed Deposit | M5: ='INCOME & EXP'!G19 -> 63586
C6: 46113 | D6: =D5 -> 46323 | E6: =D6-C6+1 -> 211 | F6: =ROUND(E6*F5/E5,0) -> 173945 | G6: Prepaid | K6: Benefit of 80p2d | M6: =-M5 -> -63586
K7: Interest on IT Refund | M7: ='INCOME & EXP'!G25 -> 0
A8: 2 | B8: Intercom AMC | K8: Sale of scrap & Promotional | M8: ='INCOME & EXP'!G26 -> 3001
C9: 46023 | D9: 46387 | E9: =D9-C9+1 -> 365 | F9: 22715 | K9: Net Taxable Income | M9: =SUM(M4:M8) -> 32923
C10: 46113 | D10: =D9 -> 46387 | E10: =D10-C10+1 -> 275 | F10: =ROUND(E10*F9/E9,0) -> 17114 | G10: Prepaid | K10: 0-10000 | L10: 0.1 | M10: 1000
K11: 10000-20000 | L11: 0.2 | M11: 2000
A12: 3 | B12: Bird Net AMC | K12: 20000 or More | L12: 0.3 | M12: =ROUND((M9-20000)*30%,0) -> 3877
C13: 45417 | D13: 46511 | E13: =D13-C13+1 -> 1095 | F13: 4140 | K13: Tax | M13: =SUM(M10:M12) -> 6877
C14: 45748 | D14: 46511 | E14: =D14-C14+1 -> 764 | F14: 2775 | G14: Prepaid | K14: Education cess | L14: 0.04 | M14: =M13*4% -> 275.08
C15: 45748 | D15: 46112 | E15: =D15-C15+1 -> 365 | F15: =ROUND(F13*E15/E13,0) -> 1380 | G15: Prepaid | K15: Total Tax | M15: =M13+M14 -> 7152.08
K16: Say | M16: =ROUND(M15,-2) -> 7200
A17: 4 | B17: CCTV AMC
C18: 46023 | D18: 46387 | E18: =D18-C18+1 -> 365 | F18: 19470
C19: 46113 | D19: =D18 -> 46387 | E19: =D19-C19+1 -> 275 | F19: =ROUND(E19*F18/E18,0) -> 14669 | G19: Prepaid
A21: 5 | B21: Water Charges
C22: 45383 | D22: 45747 | E22: 12 | F22: =11900*12 -> 142800
C23: 45748 | D23: 46112 | E23: 12 | F23: =11900*12 -> 142800 | G23: Provision
A25: 6 | B25: Insurance
C26: 46050 | D26: 46414 | E26: =D26-C26+1 -> 365 | F26: 21890
C27: 46113 | D27: =D26 -> 46414 | E27: =D27-C27+1 -> 302 | F27: =ROUND(E27*F26/E26,0) -> 18112 | G27: Prepaid
A29: 7 | B29: Fire Fighting AMC
C30: 45778 | D30: 46142 | E30: 12 | F30: 50740
C31: 46113 | D31: =D30 -> 46142 | E31: 1 | F31: =ROUND(E31*F30/E30,0) -> 4228 | G31: Prepaid
A33: 8 | B33: Stack Parking AMC
C34: 45778 | D34: 46142 | E34: 12 | F34: 210040
C35: 46113 | D35: =D34 -> 46142 | E35: 1 | F35: =ROUND(E35*F34/E34,0) -> 17503 | G35: Prepaid
F37: Adani | G37: Deposit
F38: Ac-153587768 | G38: 2390 | H38: to change
F39: Ac-153544448 | G39: 400 | H39: to change
F40: Ac-153563364 | G40: 720 | H40: to change
F41: Ac-153454115 | G41: 17825.09 | H41: to change
F42: Ac-153457629 | G42: =4953.2 -> 4953.2 | H42: to change
G43: =SUM(G38:G42) -> 26288.29

Sheet Notes
B3: Notes
A4: 1 | B4: Provision for 1 member payable to Res.F A5 -1003/1004 | C4: Sch
A5: 2 | B5: Land & building to be shown in BS
