Workbook

Sheet Balance Sheet
A1: VASANT VIEW CO-OP HOUSING SOCIETY LTD. | J1: VASANT VIEW CO-OP HOUSING SOCIETY LTD.
A2: D'Monte Lane, Orlem, Malad - West, Mumbai - 400 064
A3: Balance Sheet as at 31st March 2026
H4: (Amt. in Rs.)
A5: Previous Year 2024-25 | B5: Liabilities | D5: Current Year 2025-26 | E5: =A5 -> Previous Year 2024-25 | F5: Assets | H5: =D5 -> Current Year 2025-26
B6: Authorised Share Capital
A7: 1000000 | B7: Authorised Share Captial | D7: 1000000 | F7: Cash & Bank Balance :
E8: 55466.86 | F8: Cash in hand | G8: =53001-2218.14 -> 50782.86
B9: Issued, Subscribed and Paid Up Share | E9: 9802 | F9: MDCC Bank (Repair and Painting A/c) | G9: 62758.02
A10: =24500+3750 -> 28250 | B10: Share Capital | C10: 28250 | E10: 532643.65 | F10: Saraswat Bank | G10: 1165792.3
B11: Add: Additions during the year | C11: =15*250 -> 3750 | D11: =SUM(C10:C11) -> 32000 | E11: 5724 | F11: Corporation Bank | G11: 5724
E12: 81474.19 | F12: C Wing Saraswat Bank | G12: 0
B13: General Reserve & Other Funds | E13: 60383.02 | F13: MDCC Bank (0006100600857) | G13: 10109
B14: Entrance Fees | E14: 0 | F14: Deemed Conv (Saraswat Bank) 069534 | G14: 5000
A15: 6105 | B15: As per last Balance Sheet | C15: =SUM(A15:A16) -> 6405 | E15: 0 | F15: C Wing Repair (Saraswat Bank) 69488 | G15: 5000 | H15: =SUM(G8:G15) -> 1305166.2
A16: 300 | B16: Add: Additions during the year | C16: =200+100 -> 300 | D16: =SUM(C15:C16) -> 6705
B17: Transfer Fees : | F17: Investments & Deposits :
A18: 17090 | B18: As per last Balance Sheet | C18: =SUM(A18:A19) -> 18590 | E18: 1074978 | F18: Fixed Deposits (As per Schedule) | G18: ='FD Schedule'!D41 -> 1129778
A19: 1500 | B19: Add: Additions during the year | C19: 500 | D19: =SUM(C18:C19) -> 19090 | E19: 43989 | F19: Accrued Interest on Fixed Deposits | G19: ='FD Schedule'!E41+'FD Schedule'!F41 -> 41174 | H19: =G18+G19 -> 1170952
B20: Transfer Premium :
A21: 250000 | B21: As per last Balance Sheet | C21: =SUM(A21:A22) -> 275000 | F21: Deposits
A22: 25000 | B22: Add: Additions during the year | C22: 25000 | D22: =SUM(C21:C22) -> 300000 | E22: 1000 | F22: Share (MDCC) | G22: 1000
B23: Reserve Fund : | E23: 77 | F23: Share (MDHF) | G23: 77
A24: 94261 | B24: As per last Balance Sheet | C24: =SUM(A24:A25) -> 121076 | E24: 9390 | F24: Security Deposit (Electricity) | G24: 9390 | H24: =SUM(G22:G24) -> 10467
A25: 26815 | B25: Add: Accrued/Earned Interest | C25: ='I&E'!G30 -> 27018 | D25: =C24+C25 -> 148094
B26: Common Amenity Fund : | F26: Fixed Assets ( Schedule - E )
A27: 755161.5 | B27: As per last Balance Sheet | D27: 755161.5 | E27: =21800100+5117000 -> 26917100 | F27: Land and Building Account | G27: ='Fixed Assets'!H6 -> 26917100
B28: Sinking Fund : | E28: 3326 | F28: Borewell Account | G28: ='Fixed Assets'!H7 -> 2827
A29: 261770 | B29: As per last Balance Sheet | C29: =SUM(A29:A31) -> 291225 | E29: 1577 | F29: Furniture and Fixtures | G29: ='Fixed Assets'!H8 -> 1419
A30: 11700 | B30: Add: Contributions of Members | C30: 11700 | E30: 1685 | F30: Fencing | G30: ='Fixed Assets'!H9 -> 1516
A31: 17755 | B31: Add: Accrued/Earned Interest | C31: ='I&E'!G28 -> 20619 | D31: =SUM(C29:C31) -> 323544 | E31: 3689 | F31: Water Pump | G31: ='Fixed Assets'!H10 -> 3136
B32: Repair Fund : | E32: 69088 | F32: CCTV | G32: ='Fixed Assets'!H11 -> 58725
A33: 268893 | B33: As per last Balance Sheet | C33: =SUM(A33:A35) -> 308019 | E33: 98438 | F33: Lift (Enhancement) | G33: ='Fixed Assets'!H12 -> 83672
A34: 24264 | B34: Add: Contributions of Members | C34: =18198+6066 -> 24264 | E34: 1249 | F34: Fan | G34: ='Fixed Assets'!H14 -> 1062
A35: 14862 | B35: Add: Accrued/Earned Interest | C35: ='I&E'!G31 -> 15503 | D35: =SUM(C33:C35) -> 347786 | E35: 625 | F35: Printer | G35: ='Fixed Assets'!H15 -> 375
A36: 0 | B36: Major Repair Fund | E36: 26308 | F36: Intercom | G36: ='Fixed Assets'!H13 -> 66014
A37: 0 | B37: Add: Contributions of Members | C37: 165774 | D37: =SUM(C37) -> 165774 | E37: 0 | F37: Ladder | G37: 5180
B38: Corpus Fund : | E38: 0 | F38: Computers | G38: 28360 | H38: =SUM(G27:G38) -> 27169386
A39: 78864 | B39: As per last Balance Sheet | C39: =SUM(A39:A40) -> 157728
A40: 78864 | B40: Add: Contributions of Members | C40: 19716 | D40: =SUM(C39:C40) -> 177444
...

Sheet I&E
A1: ='Balance Sheet'!A1:H1 -> VASANT VIEW CO-OP HOUSING SOCIETY LTD.
A2: D'Monte Lane, Orlem, Malad - West, Mumbai - 400 064
A3: Income and Expenditure A/c. for the year ended 31st March 2026
H4: (Amt. in Rs.)
A5: ='Balance Sheet'!A5 -> Previous Year 2024-25 | B5: Expenditure | D5: ='Balance Sheet'!D5 -> Current Year 2025-26 | E5: =A5 -> Previous Year 2024-25 | F5: Income | H5: =D5 -> Current Year 2025-26
B6: To Property & N.A Tax : | F6: By Contribution towards Maintenance : | AN6: Account Heads | AO6: Income | AP6: Expenses | AQ6: Surplus/ (Deficit) | AT6: Service Charges
A7: 149661 | B7: Property Tax | D7: 212284 | E7: =137740+0 -> 137740 | F7: Property Tax | G7: =175294+12518 -> 187812 | AN7: Property Tax | AO7: =G7+G8+G9 -> 210184 | AP7: =D7 -> 212284 | AQ7: =AO7-AP7 -> -2100 | AT7: Sweeper Salary | AU7: 108000
E8: 5880 | F8: Property Tax Common area | G8: =964+60 -> 1024 | AN8: Service Charges | AO8: =G10 -> 1082102 | AP8: =D17+D29+D37+D50-C36 -> 1214539.5 | AQ8: =AO8-AP8 -> -132437.54 | AT8: Gardner Salary | AU8: 36000
A9: 143966 | B9: To Electricity Expenses | D9: 171767 | E9: 15024 | F9: Garage Charges (Property Tax) | G9: 21348 | AN9: Insurance | AO9: =G13 -> 39504 | AP9: =C36 -> 18518 | AQ9: =AO9-AP9 -> 20986 | AT9: Bonus | AU9: 12000
E10: 1052226 | F10: Maintenance Charges | G10: 1082102 | AN10: Electricity | AO10: =G12 -> 157959 | AP10: =D9 -> 171767 | AQ10: =AO10-AP10 -> -13808 | AT10: Water Pump Repair | AU10: 300
B11: To Water Expenses | E11: 130200 | F11: Water Charges | G11: 141990 | AN11: Water | AO11: =G11 -> 141990 | AP11: =D13 -> 110855 | AQ11: =AO11-AP11 -> 31135 | AT11: Water tank & Sewage system | AU11: 7730
A12: 148180 | B12: Water Expenses | C12: 106455 | E12: 73500 | F12: Common Electricity Charges | G12: 157959 | AN12: (A) | AO12: =SUM(AO7:AO11) -> 1631739 | AP12: =SUM(AP7:AP11) -> 1727963.5 | AQ12: =SUM(AQ7:AQ11) -> -96224.54 | AT12: R&M / AMC - Lift | AU12: 53845
A13: 0 | B13: Water tank & Sewage system | C13: 4400 | D13: =SUM(C12:C13) -> 110855 | E13: 34752 | F13: Insurance Charges | G13: 39504 | AN13: Parking | AO13: =G15 -> 152200 | AP13: 0 | AQ13: =AO13-AP13 -> 152200 | AT13: Garden Maintenance Expenses | AU13: 7420
E14: 44945 | F14: Non Occupancy Charges | G14: =49403+166 -> 49569 | AN14: NOC | AO14: =G14 -> 49569 | AP14: 0 | AQ14: =AO14-AP14 -> 49569 | AT14: Pest Control Expenses | AU14: 8214
B15: To Salary Expenses : | E15: 119050 | F15: Parking Charges | G15: =102000+38400+4900+6900 -> 152200 | AN15: Fines & Penalties | AO15: =G18 -> 0 | AP15: 0 | AQ15: =AO15-AP15 -> 0 | AT15: Plumbing Repair Maintenance | AU15: 1320
A16: 141200 | B16: Salary | C16: 211500 | E16: 0 | F16: Garden Maintenance | G16: 19005 | AN16: Late Payment | AO16: =G21 -> 12145 | AP16: 0 | AQ16: =AO16-AP16 -> 12145 | AT16: Electrical Repair Maintenance | AU16: 15216
A17: 19600 | B17: Bonus | C17: 30000 | D17: =SUM(C16:C17) -> 241500 | E17: 0 | F17: CCTV & Intercom Charges | G17: 51360 | AN17: Interest Income | AO17: =SUM(H24:H31) -> 33066 | AP17: 0 | AQ17: =AO17-AP17 -> 33066 | AT17: General Repairs (Civil & Carpentry) | AU17: 950
E18: 3500 | F18: Fines & Penalties | G18: 0 | AN18: Other Income | AO18: =#REF! -> #REF! | AP18: 0 | AQ18: =AO18-AP18 -> #REF! | AT18: Staircase Railing | AU18: 21299
B19: To Repair & Maintenance : | E19: 5000 | F19: Other Charges | G19: 0 | AN19: (B) | AO19: =SUM(AO13:AO18) -> #REF! | AP19: =SUM(AP13:AP18) -> 0 | AQ19: =SUM(AQ13:AQ18) -> #REF! | AT19: Housekeeping Consumables | AU19: 6170
A20: 2000 | B20: Water Pump Repair | C20: 0 | E20: 150 | F20: Cheque Bounce Charges | G20: 0 | AT20: R&M - Fire Fighting | AU20: 4900
A21: 52234 | B21: R&M / AMC - Lift | C21: =14400+20773 -> 35173 | E21: 24298 | F21: Late Payment Interest | G21: 12145 | H21: =SUM(G7:G21) -> 1916018 | AN21: (C ) | AO21: =AO12+AO19 -> #REF! | AP21: =AP12+AP19 -> 1727963.5 | AQ21: =AQ12+AQ19 -> #REF! | AT21: R&M - CCTV & Intercom | AU21: 2741
A22: 59800 | B22: Garden Maintenance Expenses | C22: 65000 | AT22: Security Expenses | AU22: 485000
A23: 12020 | B23: Pest Control Expenses | C23: 26792 | F23: By Interest Income : | AT23: Depreciation | AU23: 42920
A24: 2550 | B24: Plumbing Repair Maintenance | C24: 1940 | E24: 8572 | F24: Interest Income - Savings A/c | H24: 19320 | AT24: Audit Fees | AU24: 4900
A25: 11501 | B25: Electrical Repair Maintenance | C25: 21490 | E25: 210 | F25: Interest on IT Refund | H25: 0 | AT25: Accounting Charges | AU25: 23520
A26: 104656.5 | B26: Repair & Maintenance Other | C26: 37243 | E26: 77934 | F26: Interest on Fixed Deposits : | G26: 80873 | AT26: Printing and Stationary | AU26: 3617
A27: 6321 | B27: Housekeeping & Consumables | C27: 8623 | F27: Less: Transfer to: | AT27: Income Tax Expenses | AU27: 5024
A28: 7050 | B28: R&M - Fire Fighting | C28: 4000 | E28: -17755 | F28: Sinking Fund | G28: 20619 | AT28: Legal & Professional Fees | AU28: 8500
A29: 3050 | B29: R&M - CCTV & Intercom | C29: 11000 | D29: =SUM(C20:C29) -> 211261 | E29: -3758 | F29: Education & Training Fund | G29: 3987 | AT29: Meeting Expenses | AU29: 2011
E30: -26815 | F30: Reserve Fund | G30: 27018 | AT30: Postage/ Telephone/ Internet Exp. | AU30: 38
B31: To Service Charges : | E31: -14862 | F31: Repair Fund | G31: 15503 | H31: =G26-SUM(G28:G31) -> 13746 | AT31: Festival Expenses | AU31: 12245
A32: 596100 | B32: Security Expenses | C32: 543000 | AT32: Miscellaneous Expenses | AU32: 4323
A33: 36443 | B33: Depreciation on Fixed Assets | C33: ='Fixed Assets'!G18 -> 46104 | F33: Other Income : | AT33: Bank Charges | AU33: 68.3
A34: 0 | B34: Subscription Fedration | C34: 3304 | E34: 80300 | F34: Gate Opening Charges | G34: 15075 | AT34: Conveyance | AU34: 200
A35: 0 | B35: Election Charges | C35: 15000 | E35: 12500 | F35: Shifting Charges | G35: 22500 | H35: =SUM(G34:G35) -> 37575 | AU35: =SUM(AU7:AU34) -> 878471.3
A36: 55313 | B36: Insurance Expenses | C36: 18518
A37: 8000 | B37: Audit Fees | C37: =25960+6400 -> 32360 | D37: =SUM(C32:C37) -> 658286
B39: To Office Expenses :
A40: 36784 | B40: Accounting Charges | C40: 33792
A41: 2464 | B41: Printing and Stationary | C41: 11369
...

Sheet FD Schedule
B1: VASANT VIEW CO-OP. HOUSING SOCIETY LIMITED.
B2: Details of Fixed Deposits as on 31st March 2026
A3: Sr. No. | C3: Date | D3: Amount Invested | E3: Accrued Int. 2024-25 | F3: Accrued Int. 2025-26 | G3: Total | H3: Maturity Date | I3: Maturity Value | J3: Interest % | K3: Bank
B4: Sinking Fund
A5: 1 | B5: 1020813-4 5400011040_1 | C5: 18.02.2025 | D5: 16287 | E5: 132 | F5: =1212 -> 1212 | G5: =SUM(D5:F5) -> 17631 | H5: 18.08.2026 | I5: 18127 | J5: 7.2 | K5: MDCC | N5: Investment to be made as of 31.03.2026
A6: 2 | B6: 1020814-4 5400011041_1 | C6: 18.02.2025 | D6: 38321 | E6: 312 | F6: =2855 -> 2855 | G6: =SUM(D6:F6) -> 41488 | H6: 18.08.2026 | I6: 38321 | J6: 7.2 | K6: MDCC | O6: Liability | P6: Asset | Q6: (FD Short)
A7: 3 | B7: 1076328-6 5400011514_2 | C7: 11.10.2025 | D7: 32583 | E7: 0 | F7: =1058 -> 1058 | G7: =SUM(D7:F7) -> 33641 | H7: 11.10.2026 | I7: 34856 | J7: 6.8 | K7: MDCC | O7: Funds | P7: Investments | Q7: FD Excess
A8: 4 | B8: TD0000411008-3 | C8: 30.07.2025 | D8: 129197 | E8: 0 | F8: =6163-617 -> 5546 | G8: =SUM(D8:F8) -> 134743 | H8: 30.08.2026 | I8: 139283 | J8: 7 | K8: SCB | N8: Sinking Fund | O8: ='Balance Sheet'!D31 -> 323544 | P8: =G12 -> 273739 | Q8: =O8-P8 -> 49805
A9: 5 | B9: TD1000280978-2 | C9: 22.03.2025 | D9: 10836 | E9: 0 | F9: 0 | G9: =SUM(D9:F9) -> 10836 | H9: 22.03.2028 | I9: 10836 | J9: 6.8 | K9: SCB | N9: Repair Fund | O9: ='Balance Sheet'!D35 -> 347786 | P9: =G18 -> 228429 | Q9: =O9-P9 -> 119357
A10: 6 | B10: TD1000719245_1 | C10: 24.03.2025 | D10: 12977 | E10: =20-2 -> 18 | F10: =966-95 -> 871 | G10: =SUM(D10:F10) -> 13866 | H10: 24.03.2027 | I10: 14974 | J10: 7.25 | K10: SCB | N10: Reserve Fund | O10: ='Balance Sheet'!D16+'Balance Sheet'!D19+'Balance Sheet'!D22+'Balance Sheet'!D25 -> 473889 | P10: =G24 -> 384388 | Q10: =O10-P10 -> 89501
A11: 7 | B11: TD1001134251 | C11: 26.06.2025 | D11: 20528 | E11: 0 | F11: =1119-113 -> 1006 | G11: =SUM(D11:F11) -> 21534 | H11: 26.09.2026 | I11: 22384 | J11: 7 | K11: SCB | N11: Education & Training | O11: ='Balance Sheet'!D44 -> 84606 | P11: =G34 -> 57372 | Q11: =O11-P11 -> 27234
D12: =SUM(D5:D11) -> 260729 | E12: =SUM(E5:E11) -> 462 | F12: =SUM(F5:F11) -> 12548 | G12: =SUM(G5:G11) -> 273739 | I12: =SUM(I5:I11) -> 278781 | N12: Common Amenity Fund | O12: ='Balance Sheet'!D27 -> 755161.5 | P12: =G39 -> 202524 | Q12: =O12-P12 -> 552637.5
N13: Share Capital | O13: ='Balance Sheet'!D11 -> 32000 | P13: =G29 -> 24500 | Q13: =O13-P13 -> 7500
B14: Repair Fund | N14: Major Repair Fund | O14: ='Balance Sheet'!D37 -> 165774 | P14: 0 | Q14: =-O14-P14 -> -165774
A15: 8 | B15: TD0000411007-3 | C15: 30.07.2025 | D15: 153028 | E15: 0 | F15: =7299-730 -> 6569 | G15: =SUM(D15:F15) -> 159597 | H15: 30.08.2026 | I15: 164975 | J15: 7 | K15: SCB | N15: Corpus Fund | O15: ='Balance Sheet'!D40 -> 177444 | P15: 0 | Q15: =-O15-P15 -> -177444
A16: 9 | B16: TD1000281021-2 | C16: 22.03.2026 | D16: 21672 | E16: 0 | F16: 0 | G16: =SUM(D16:F16) -> 21672 | H16: 22.03.2028 | I16: 21672 | J16: 6.8 | K16: SCB | N16: TOTAL | O16: =SUM(O8:O15) -> 2360204.5 | P16: =SUM(P8:P15) -> 1170952 | Q16: =SUM(Q8:Q15) -> 502816.5
A17: 10 | B17: TD1001134388_1 | C17: 26.06.2025 | D17: 44954 | E17: 0 | F17: =2451-245 -> 2206 | G17: =SUM(D17:F17) -> 47160 | H17: 26.09.2026 | I17: 49017 | J17: 7 | K17: SCB
D18: =SUM(D15:D17) -> 219654 | E18: =SUM(E15:E17) -> 0 | F18: =SUM(F15:F17) -> 8775 | G18: =SUM(G15:G17) -> 228429 | I18: =SUM(I15:I17) -> 235664
B20: Reserve Fund
A21: 11 | B21: TD1000281015_2 | C21: 22.03.2026 | D21: 272382 | G21: =SUM(D21:F21) -> 272382 | H21: 22.03.2028 | I21: 272382 | J21: 6.8 | K21: SCB
A22: 12 | B22: TD1000719459_1 | C22: 24.03.2025 | D22: 31668 | E22: =49-5 -> 44 | F22: =2356-235 -> 2121 | G22: =SUM(D22:F22) -> 33833 | H22: 24.03.2027 | I22: 36542 | J22: 7.25 | K22: SCB
A23: 13 | B23: TD1001134370_1 | C23: 26.06.2025 | D23: 74516 | E23: 0 | F23: =4062-405 -> 3657 | G23: =SUM(D23:F23) -> 78173 | H23: 26.09.2026 | I23: 81252 | J23: 7 | K23: SCB
D24: =SUM(D21:D23) -> 378566 | E24: =SUM(E21:E23) -> 44 | F24: =SUM(F21:F23) -> 5778 | G24: =SUM(G21:G23) -> 384388 | I24: =SUM(I21:I23) -> 390176
B26: Share Capital
A27: 14 | B27: TD0000400794-2 | C27: 30.07.2025 | D27: 12250 | E27: 0 | G27: =SUM(D27:F27) -> 12250 | H27: 30.08.2026 | I27: 12250 | J27: 7 | K27: SCB
A28: 15 | B28: TD1000281044-2 | C28: 22.03.2026 | D28: 12250 | E28: 0 | G28: =SUM(D28:F28) -> 12250 | H28: 22.03.2028 | I28: 12250 | J28: 6.8 | K28: SCB
D29: =SUM(D27:D28) -> 24500 | E29: =SUM(E27:E28) -> 0 | G29: =SUM(G27:G28) -> 24500 | I29: =SUM(I27:I28) -> 24500
B31: Edu. & Trng. Fund
A32: 16 | B32: TD100719487 | C32: 24.03.2025 | D32: 47406 | E32: =74-7 -> 67 | F32: =3527-352 -> 3175 | G32: =SUM(D32:F32) -> 50648 | H32: 24.03.2027 | I32: 54702 | J32: 7.25 | K32: SCB
A33: 17 | B33: TD1001134406 | C33: 26.06.2025 | D33: 6410 | E33: 0 | F33: =349-35 -> 314 | G33: =SUM(D33:F33) -> 6724 | H33: 26.09.2026 | I33: 6989 | J33: 7 | K33: SCB
D34: =SUM(D32:D33) -> 53816 | E34: =SUM(E32:E33) -> 67 | F34: =SUM(F32:F33) -> 3489 | G34: =SUM(G32:G33) -> 57372 | I34: =SUM(I32:I33) -> 61691
B36: Comm. Amen. Fund
A37: 18 | B37: TD1001134417 | C37: 26.06.2025 | D37: 54456 | E37: 0 | F37: =2969-298 -> 2671 | G37: =SUM(D37:F37) -> 57127 | H37: 26.09.2026 | I37: 59378 | J37: 7 | K37: SCB
A38: 19 | B38: TD0000413196_1 | C38: 17.06.2025 | D38: 138057 | E38: 0 | F38: =8112-772 -> 7340 | G38: =SUM(D38:F38) -> 145397 | H38: 17.07.2026 | I38: 149280 | J38: 7.3 | K38: SCB
D39: =SUM(D37:D38) -> 192513 | E39: =SUM(E37:E38) -> 0 | F39: =SUM(F37:F38) -> 10011 | G39: =SUM(G37:G38) -> 202524 | I39: =SUM(I37:I38) -> 208658
B41: Grand Total | D41: =D12+D18+D24+D29+D34+D39 -> 1129778 | E41: =E12+E18+E24+E29+E34+E39 -> 573 | F41: =F12+F18+F24+F29+F34+F39 -> 40601 | G41: =G12+G18+G24+G29+G34+G39 -> 1170952 | I41: =I12+I18+I24+I29+I34+I39 -> 1199470

Sheet Fixed Assets
A1: VASANT VIEW CO-OP. HSG. SOC. LTD. (A&B Wing)
A2: Schedule - E
A3: Fixed Assets as at 31st March 2026
A5: Particulars | B5: Rate % | C5: Opening W.D.V. as on 01.04.2025 | D5: Additions during the year before 30.09.2025 | E5: Additions during the year after 30.09.2025 | F5: Gross Block (at cost) as on 31.03.2026 | G5: Depreciation for the year | H5: Closing W.D.V. as on 31.03.2026
A6: Land & Building Account | B6: 0 | C6: =21800100+5117000 -> 26917100 | D6: 0 | E6: 0 | F6: =SUM(C6:E6) -> 26917100 | G6: =ROUND(((C6+D6)*B6)+(E6*B6)/2,0) -> 0 | H6: =F6-G6 -> 26917100
A7: Borewell Account | B7: 0.15 | C7: 3326 | D7: 0 | E7: 0 | F7: =SUM(C7:E7) -> 3326 | G7: =ROUND(((C7+D7)*B7)+(E7*B7)/2,0) -> 499 | H7: =F7-G7 -> 2827
A8: Furniture & Fixtures | B8: 0.1 | C8: 1577 | D8: 0 | E8: 0 | F8: =SUM(C8:E8) -> 1577 | G8: =ROUND(((C8+D8)*B8)+(E8*B8)/2,0) -> 158 | H8: =F8-G8 -> 1419
A9: Fencing | B9: 0.1 | C9: 1685 | D9: 0 | E9: 0 | F9: =SUM(C9:E9) -> 1685 | G9: =ROUND(((C9+D9)*B9)+(E9*B9)/2,0) -> 169 | H9: =F9-G9 -> 1516
A10: Water Pump | B10: 0.15 | C10: 3689 | D10: 0 | E10: 0 | F10: =SUM(C10:E10) -> 3689 | G10: =ROUND(((C10+D10)*B10)+(E10*B10)/2,0) -> 553 | H10: =F10-G10 -> 3136
A11: CCTV | B11: 0.15 | C11: 69088 | D11: 0 | E11: 0 | F11: =SUM(C11:E11) -> 69088 | G11: =ROUND(((C11+D11)*B11)+(E11*B11)/2,0) -> 10363 | H11: =F11-G11 -> 58725
A12: Lift | B12: 0.15 | C12: 98438 | D12: 0 | E12: 0 | F12: =SUM(C12:E12) -> 98438 | G12: =ROUND(((C12+D12)*B12)+(E12*B12)/2,0) -> 14766 | H12: =F12-G12 -> 83672
A13: Intercom | B13: 0.15 | C13: 26308 | D13: 51355 | E13: 0 | F13: =SUM(C13:E13) -> 77663 | G13: =ROUND(((C13+D13)*B13)+(E13*B13)/2,0) -> 11649 | H13: =F13-G13 -> 66014
A14: Fan | B14: 0.15 | C14: 1249 | D14: 0 | E14: 0 | F14: =SUM(C14:E14) -> 1249 | G14: =ROUND(((C14+D14)*B14)+(E14*B14)/2,0) -> 187 | H14: =F14-G14 -> 1062
A15: Printer | B15: 0.4 | C15: 625 | D15: 0 | E15: 0 | F15: =SUM(C15:E15) -> 625 | G15: =ROUND(((D15+C15)*B15)+(E15*B15)/2,0) -> 250 | H15: =F15-G15 -> 375
A16: Ladder | B16: 0.15 | C16: 0 | D16: 0 | E16: 5600 | F16: =SUM(C16:E16) -> 5600 | G16: =ROUND(((D16+C16)*B16)+(E16*B16)/2,0) -> 420 | H16: =F16-G16 -> 5180
A17: Computer | B17: 0.4 | C17: 0 | D17: 0 | E17: =26000+9450 -> 35450 | F17: =SUM(C17:E17) -> 35450 | G17: =ROUND(((D17+C17)*B17)+(E17*B17)/2,0) -> 7090 | H17: =F17-G17 -> 28360
A18: Total | C18: =SUM(C6:C17) -> 27123085 | D18: =SUM(D6:D17) -> 51355 | E18: =SUM(E6:E17) -> 41050 | F18: =SUM(F6:F17) -> 27215490 | G18: =SUM(G6:G17) -> 46104 | H18: =SUM(H6:H17) -> 27169386

Sheet Members Dues n Advances
A1: Vasant View Co-op. Housing Society Ltd.
D2: Schedule - A
A3: Members Dues as on 31-03-2026
A4: Sl.No | B4: Block | C4: Flat | D4: Name of the Member | E4: Total
A5: 1 | B5: A | C5: 301 | D5: Mrs. Sunitha Nelson Mendonca & Mr. Nelson A. Mendonca | E5: 23982
A6: 2 | B6: A | C6: 302 | D6: Mrs. Gloria S. Fernandes | E6: 5413
A7: 3 | B7: B | C7: 502 | D7: Mr. Devendra D. Sukhathankar | E7: 300
A8: 4 | B8: B | C8: 701 | D8: Mr. Anthony Hanson Fernandes | E8: 17951
A9: 5 | B9: B | C9: 702 | D9: Mr. Anthony Hanson Fernandes | E9: 14868
A10: 6 | B10: B | C10: 704 | D10: Mr. Sidharth K. Sabharwal | E10: 7658
A11: 7 | B11: C | C11: 303 | D11: Ms. Claudia N. Mahe | E11: 100
A12: 8 | B12: Utility A | C12: 301 | D12: Mrs. Sunitha Nelson Mendonca & Mr. Nelson A. Mendonca | E12: 2657
A13: 9 | B13: Utility A | C13: 303 | D13: Mr. Benedict S. Soares | E13: 2657
A14: 10 | B14: Utility B | C14: 304 | D14: Mr. Namdev A. Mhatre & Mrs. Madhavi N. Mhatre | E14: 2657
A15: 11 | B15: Utility B | C15: 701 | D15: Mr. Anthony Hanson Fernandes | E15: 2657
A16: 12 | B16: Utility B | C16: 702 | D16: Mr. Anthony Hanson Fernandes | E16: 2657
A17: 13 | B17: Utility C | C17: 402 | D17: Mrs. Carmina Fernandes | E17: 14195
A18: Total | E18: =SUM(E5:E17) -> 97752
D20: Schedule - B
A21: Advance from Members as at 31-03-2026
A22: Sl.No | B22: Block | C22: Flat | D22: Name | E22: Amount
A23: 1 | B23: A | C23: 103 | D23: Ms. Anita Mendonca | E23: 507
A24: 2 | B24: A | C24: 401 | D24: Mr. Joaquim Fernandes & Fenny B. Fernandes | E24: 21656
A25: 3 | B25: A | C25: 403 | D25: Mr. Joseph D. Collaco | E25: 20814
A26: 4 | B26: A | C26: 501 | D26: Mr. Merwyn Mascarenhas | E26: 115
A27: 5 | B27: A | C27: 502 | D27: Mrs. Carol Mascarenhas & Mr. Merwyn Mascarenhas | E27: 985
A28: 6 | B28: A | C28: 503 | D28: Argentina M. Cardozo and Michelle Cardozo | E28: 51271
A29: 7 | B29: A | C29: 603 | D29: Ms. Jennifred C Luiz | E29: 11568
A30: 8 | B30: B | C30: 101 | D30: Ms. Carmina Fernandes | E30: 14
A31: 9 | B31: B | C31: 204 | D31: Mr. Clevy Rosario | E31: 10563
A32: 10 | B32: B | C32: 301 | D32: Mr. Gleeson Rozario | E32: 20224
A33: 11 | B33: B | C33: 603 | D33: Mr. Shriram P. Singh & Mrs. Gyanmati S. Singh | E33: 263
A34: 12 | B34: B | C34: 703 | D34: Mr. Paul Tony Menezes | E34: 4887
... A40: 18 | B40: Utility B | C40: 204 | D40: Mr. Clevy Rosario | E40: 2657
A41: Total | E41: =SUM(E23:E40) -> 219608

Sheet Vendors - Paya. & Adv.
A1: Vasant View Co-op. Hsg. Soc. Ltd.
C3: Schedule - C
A4: Vendor Payables & Provisions as on 31-03-2026
A5: Sl.No | B5: FY 2024-25 | C5: Vendors Name | D5: FY 2025-26
A6: 1 | B6: 4520 | C6: Adani Electricity Mumbai Ltd | D6: 3470
A7: 2 | B7: 0 | C7: Reliable Pest Control | D7: 17200
A8: 3 | B8: 5000 | C8: Dharmendra Shinde | D8: 0
A9: 4 | B9: 3000 | C9: Gardener | D9: 0
A10: 5 | B10: 8100 | C10: Krishna Saple | D10: 0
A11: 6 | B11: 100 | C11: Sachin
A12: 7 | B12: 5000 | C12: Shrey Sanjay Shah | D12: 0
A13: 8 | B13: 14100 | C13: Sweeper | D13: 8000
A14: 9 | B14: 39600 | C14: Swordsman Protection Service | D14: 0
A15: 10 | B15: 19126 | C15: Tata Power | D15: 0
A16: 11 | B16: 5000 | C16: Vasant view C Wing | D16: 5000
A17: 12 | B17: 4782 | C17: Vidhya Accounts Consultants | D17: 54
A18: 13 | B18: 2000 | C18: Irene Rosario | D18: 0
B19: =SUM(B6:B18) -> 110328 | C19: TOTAL | D19: =SUM(D6:D18) -> 33724
C21: Schedule - D
A22: Provision for Expenses
A23: Sl.No | B23: =B5 -> FY 2024-25 | C23: Particulars | D23: =D5 -> FY 2025-26
A24: 1 | B24: 21200 | C24: Audit Fees | D24: =14800+6400 -> 21200
A25: 2 | B25: 74408 | C25: Water Charges | D25: 43009
A26: 3 | B26: 1500 | C26: Gardenr Salary - C | D26: 0
A27: 4 | B27: 9000 | C27: Security Charges - C | D27: 0
A28: 5 | B28: 6663 | C28: Property Tax - C | D28: 6663
A29: 6 | B29: 5000 | C29: Professional Fees | D29: 4500
A30: 7 | B30: 23294 | C30: Lift AMC | D30: 0
A31: 8 | B31: 670 | C31: TDS Payable | D31: 770
A32: 9 | B32: 0 | C32: Income Tax Provision | D32: 3150
A33: 10 | B33: 78864 | C33: Provision N.A. Tax | D33: 78864
B34: =SUM(B24:B33) -> 220599 | C34: TOTAL | D34: =SUM(D24:D33) -> 158156
A36: Schedule - F
A37: Advance to Vendors as on 31-03-2026
A38: Sl.No | B38: =B5 -> FY 2024-25 | C38: VendorsName | D38: =D5 -> FY 2025-26
A39: 1 | B39: 6000 | C39: Krishna Saple | D39: 0
A40: 2 | B40: =200-100 -> 100 | C40: Sachin | D40: =200-100 -> 100
B41: =SUM(B40:B40) -> 100 | C41: TOTAL | D41: =SUM(D39:D40) -> 100

Sheet BRS
A1: VASANT VIEW A & B CHS LTD
A2: Saraswat Bank Reconciliation Statement as on 31.03.2026
D3: Amount
B4: Balance as per System (Book Balance) | D4: 1165792.3 | G4: Posted Date | H4: Inflow | I4: Outflow | J4: Ledger | K4: Instr No | L4: Reconciled Date
G5: 46054 | H5: 0 | I5: 7000 | J5: Sweeper | K5: 212183 | L5: 46129
A6: Add: | B6: Cheque issued but not presented (Outflow) | D6: =I12 -> 77120 | G6: 46112 | H6: 6239 | I6: 0 | J6: B 602 | K6: 609419200362 | L6: 46116
G7: 46112 | H7: 0 | I7: 6000 | J7: Gardener | K7: 213505 | L7: 46119
A8: Less: | B8: Cheque deposited but not cleared (Inflow) | D8: =H12 -> 6239 | G8: 46112 | H8: 0 | I8: 7000 | J8: Sweeper | K8: 213507 | L8: 46121
G9: 46112 | H9: 0 | I9: 5600 | J9: Ladder | K9: 213502 | L9: 46114
A10: Less: | B10: Amount Debited by Bank but not entered in the system (Issued) | D10: ='[1]Saraswat Attachment'!C152 -> 0 | G10: 46112 | H10: 0 | I10: 47520 | J10: Swordsman Protection Service | K10: 213504 | L10: 46119
G11: 46112 | H11: 0 | I11: 4000 | J11: Manager | K11: 213508 | L11: 46114
A12: Add: | B12: Amount credited in Bank but not entered in the system (Deposit) | D12: 0 | H12: =SUM(H5:H11) -> 6239 | I12: =SUM(I5:I11) -> 77120
D14: =D4+D6-D8-D10+D12 -> 1236673.3
B16: Balance as per Bank Passbook | D16: 1236673.3
C17: Difference | D17: =D14-D16 -> 0
A19: VASANT VIEW C CHS LTD
A20: Saraswat Bank Reconciliation Statement as on 30.07.2025 - 152200100912972
D21: Amount
B22: Balance as per System (Book Balance) | D22: 0
B24: Balance as per Bank Passbook | D24: 0 | E24: A/c closed
C25: Difference | D25: =D22-D24 -> 0
A27: VASANT VIEW A & B CHS LTD
A28: MDCC Rep & Paint. Bank Reconciliation Statement as on 31.03.2026 A/c. 1286
D29: Amount
B30: Balance as per System (Book Balance) | D30: 10109
B32: Balance as per Bank Passbook | D32: 10109
C33: Difference | D33: =D30-D32 -> 0
A36: VASANT VIEW A & B CHS LTD
A37: MDCC Rep & Paint. Bank Reconciliation Statement as on 31.03.2026 A/c. 0061006000857
D38: Amount
B39: Balance as per System (Book Balance) | D39: 62758.02
B41: Balance as per Bank Passbook | D41: 62758.02
C42: Difference | D42: =D39-D41 -> 0
A45: VASANT VIEW C CHS LTD
A46: Saraswat Deemd Conv. Bank Reconciliation Statement as on 31.03.2026 - 610000000069534
D47: Amount
B48: Balance as per System (Book Balance) | D48: 5000
B50: Balance as per Bank Passbook | D50: 5000
C51: Difference | D51: =D48-D50 -> 0
A54: VASANT VIEW C CHS LTD
...

Sheet Meeting on 11th July 2020
A1: Meeting with Allwyn/Joshi/Jerome on 11th July at 8 pm
A2: 1. Rs.200 cash deposit on 23rd Aug 2019 | C2: Rs.100 each deposited in MDCC accounts
A3: 2. C wing toilet expenses 10th Jan 2020 | C3: Done and provided Rs.2500 - Dec to Mar20 | E3: 425 | F3: Aug
A4: 3. Drive Rs.35,400 move to expense | C4: Done | E4: 425 | F4: Sept
A5: 4. CCTV figures to be taken from Jerome | C5: Jerome to give figures | E5: 625 | F5: Oct
A6: 5. 87000 - Rs.23,400 = 63600 | C6: Done | E6: 625 | F6: Nov
A7: 6. Garden maintenance - to move bonus here | C7: Done
A8: 7. Rs.2400 garden maintenance | C8: This is correct. | E8: =SUM(E3:E7) -> 2100
A9: 8. Rs.500 to move lift to Intercomm asset | C9: done
A10: 9. Meter Rs.14925+17675 (electric refurbishing to merge | C10: Done | E10: Provision
A11: 10. Office renovation - Rs.7251 + 3600 from Major | C11: Done | E11: =625*4 -> 2500 | F11: Dec to Mar 2020
A12: 11. Rs.157349 to plumbing | C12: Done
A13: 12. Advance schedule
A14: 13. Ch # 031693 - Rs.90,690 to check | C14: Major Repair payment made to RCC
A15: 14. Ch. 034316 - Rs.8160 breakup | C15: PDF file sent to Allwyn
A16: 15. Rs.1980 + 9137 to move others from pumbling | C16: Done
A17: 16. LED bulbs from electric to lift maint - Rs.2000 | C17: Done
A18: 17. Rs.750 office renovation | C18: Done
A19: 18. Ch. 031722 to electrical - Rs.1400 | C19: Rs.750 for office renovation and Rs.650 plumbing are correct entries.
A20: 19. salary ledger to be sent
A21: 20. Billing summary of FY 19-20 | C21: Done

Sheet Worksheet
A1: Vasant View - Provisions & Prepaid workings for FY 2024-25
A2: Sr. No. | B2: Particular | D2: Days | E2: Amount | F2: Amount
A3: 1 | B3: Water Expenses
B4: PN0001222
B5: 45665 | C5: 45846 | D5: =C5-B5+1 -> 182 | E5: =6239+6185+6282+6595-6259 -> 19042
B6: =C5 -> 45846 | C6: 46112 | D6: =C6-B6+1 -> 267 | E6: =ROUND(E5*D6/D5,0) -> 27935 | F6: Provision
B8: PNK8460006
B9: 45573 | C9: 46030 | D9: =C9-B9+1 -> 458 | E9: =44341-15548 -> 28793
B10: =C9 -> 46030 | C10: 46112 | D10: =C10-B10+1 -> 83 | E10: =ROUND(E9*D10/D9,0) -> 5218 | F10: Provision
B12: PNK9380006
B13: 45573 | C13: 46030 | D13: =C13-B13+1 -> 458 | E13: =68212-13828 -> 54384
B14: =C13 -> 46030 | C14: 46112 | D14: =C14-B14+1 -> 83 | E14: =ROUND(E13*D14/D13,0) -> 9856 | F14: Provision
A16: 2 | B16: Lift - AMC
B18: 45870 | C18: 46234 | D18: =C18-B18+1 -> 365 | E18: 35400
B19: 46113 | C19: =C18 -> 46234 | D19: =C19-B19+1 -> 122 | E19: =ROUND(D19*E18/D18,0) -> 11832
E20: =SUM(E18:E19) -> 47232
A23: 2 | B23: Pest Control Expenses
B24: 45930 | C24: 46660 | D24: =C24-B24+1 -> 731 | E24: 34400
B25: 46113 | C25: =C24 -> 46660 | D25: =C25-B25+1 -> 548 | E25: =ROUND(D25*E24/D24,0) -> 25788
A27: 3 | B27: Insurance Expenses
B29: 45970 | C29: 46334 | D29: =C29-B29+1 -> 365 | E29: 24295
B30: 46113 | C30: =C29 -> 46334 | D30: =C30-B30+1 -> 222 | E30: =ROUND(D30*E29/D29,0) -> 14777
A33: 4 | B33: Provision for Income Tax
B34: Income from Savings A/c. | F34: ='I&E'!H24 -> 19320
B35: Income from Sweep A/c. | F35: 0
B36: Income from Fixed Deposit | F36: ='I&E'!G26 -> 80873
B37: Gross Total Income | F37: =SUM(F34:F36) -> 100193
A38: Less: | B38: Deduction u/s 80P | F38: =-(+F35+F36) -> -80873
B39: Net Taxable Income | F39: =SUM(F37:F38) -> 19320
B40: 0-10000 | D40: 0.1 | F40: 1000
B41: 10000-20000 | D41: 0.2 | F41: 2000
B42: 20000 or More | D42: 0.3 | F42: 0
B43: Tax | F43: =SUM(F40:F42) -> 3000
A44: Add: | B44: Education cess | D44: 0.04 | F44: =ROUND(F43*D44,0) -> 120
B45: Total Tax | F45: =SUM(F43:F44) -> 3120
F46: 3150 | G46: Round off

Sheet Note
A2: 1 | B2: Manager Salary Not booked in Jan-25 | C2: Salary Expenses
A3: 2 | B3: Sachin Salary not booked in Jan-25, Feb-25 & Mar-25 | C3: Salary Expenses
A4: 3 | B4: Property Tax A/C No. PN1805870430000 Bill booked for period FY2022 to 2025 Amount Rs.2,478, please check
A5: 4 | B5: Tata Power Electricity Bill CA No.9000 0034 7794 Jan-25 bill not booked
A6: 5 | B6: Tata Power Electricity Bill CA No.9000 0034 7826 Jan-25 bill not booked
A7: 6 | B7: Tata Power Electricity Bill CA No.9000 0034 7860 Jan-25 bill not booked
A8: 7 | B8: Tata Power Electricity Bill CA No.9000 0034 7874 Jan-25 bill not booked
A9: 8 | B9: Tata Power Electricity Bill CA No.9000 0034 7891 Jan-25 bill not booked
A10: 9 | B10: Lift AMC provision made for 01.08.23 to 31.03.24 Rs.9.333/- but bill not booked in FY2024-25 of provision period
A11: 10 | B11: Krishna Saple - garden maintenace Exp. Charges not booked of Mar-25 Rs.1,500/-
A12: 11 | B12: Krishna Saple - Security Expe. Double bill booked in Sep-24 Paid in cash
A13: 12 | B13: Krishna Saple - Jan-24 Security bill not booked
A14: 13 | B14: Please check Insurance period
A15: 14 | B15: Irene Rosario Accounting charges bill of Jan-Mar-25 bill not booked
... A20: 19 | B20: FD Schedule maturity date, value & interest detail not updated FY2024-25, mark in red colour

Sheet Refundable Deposit
B2: Refundable Deposit
B3: Flat No. | C3: Amount
B4: C-202 | C4: 5000
B5: C-203 | C5: 5000
B6: C-302 | C6: 5000
B7: C-304 | C7: 5000
B8: Opening | C8: 5000
B9: Total | C9: =SUM(C4:C8) -> 25000 | D9: Trfd to I&E a/c
