Workbook

Sheet BS 25-26
A1: SUNRISE ORLEM TOWER 2B CO OPERATIVE HOUSING SOCIETY
A2: Regn.No.MUM/SRA/HSG/(TC)/13509/2024 Dt.13/03/2024
A3: As on 31st March 2026
A4: Previous Year Rs. | B4: LIABILITIES | G4: Current Year Rs. | I4: Previous Year Rs. | J4: ASSETS | P4: Current Year Rs.
C5: Share Capital | K5: Cash & Bank Balance
C6: Authorised Share Capital | I6: 3000 | K6: Cash in Hand | O6: 2452
A7: 50000 | C7: 1000 shares of Rs.50/- each | G7: =1000*50 -> 50000 | I7: 0 | K7: MDCC Bank A/c | O7: =BRS!D24 -> 6401
C8: Issued,Subscribed & Paidup | I8: 0 | K8: Saraswat Bank | O8: =BRS!D16 -> 212558.15 | Q8: 32439501 | R8: =+Q8-#REF! -> #REF!
A9: 21000 | C9: 420 shares of Rs.50/- each | G9: =420*50 -> 21000 | I9: 911944 | K9: HDFC Bank | O9: =BRS!D5 -> 218208.75 | P9: =SUM(O6:O9) -> 439619.9
C11: Reserve Fund & Others | K11: Investments Sch-I
C12: Reserve Fund | I12: 200000 | K12: Fixed Deposits - Reserve Fund | O12: ='Fixed Deposit'!D23 -> 1393766.3
A13: 0 | C13: As per last B/s. | F13: =SUM(A13:A16) -> 361766.26 | I13: 0 | K13: Fixed Deposits - Sinking Fund | O13: ='Fixed Deposit'!D7 -> 362880
A14: 329166.26 | C14: Add: Surplus of I&E account | F14: ='I&E 25-26'!G59 -> 1019372 | I14: 0 | K14: Fixed Deposits - Repair Fund | O14: ='Fixed Deposit'!D12 -> 1088640
A15: 7600 | C15: Add: Admission Fees | F15: ='I&E 25-26'!G56 -> 0 | I15: 0 | K15: Fixed Deposits - Education & Training Fund | O15: ='Fixed Deposit'!D28 -> 5040
A16: 25000 | C16: Add: Share Transfer Premium | F16: =+'I&E 25-26'!G55 -> 0 | I16: 0 | K16: Fixed Deposits - Share Capital | O16: ='Fixed Deposit'!D32 -> 21000
A17: 0 | C17: Add: Interest during the year | F17: =-'I&E 25-26'!O39 -> 50018 | G17: =SUM(F13:F17) -> 1431156.3 | I17: 0 | K17: Sweep A/c - Saraswat bank | O17: 1450000
I18: 5087 | K18: Accrued Interest on FD | O18: ='Fixed Deposit'!G34 -> 82677 | P18: =SUM(O12:O18) -> 4404003.3
C19: Sinking Fund
A20: 0 | C20: As per last B/s. | F20: =SUM(A20:A21) -> 181440 | K20: Advances & Deposits
A21: 181440 | C21: Add:Addition during the year | F21: =+'I&E 25-26'!G52 -> 181440 | I21: 10800 | K21: Deposits Electricity | O21: 10800
A22: 0 | C22: Add: Interest during the year | F22: ='Fixed Deposit'!E7 -> 12528 | G22: =SUM(F20:F22) -> 375408 | I22: 43661 | K22: Security Deposit with (BMC-Water) | O22: 43661
I23: 0 | K23: Self Assessment Tax Paid | O23: 530
C24: Repair Fund | I24: 0 | K24: TDS Receivable | O24: 10579 | P24: =SUM(O21:O24) -> 65570
A25: 0 | C25: As per last B/s. | F25: =SUM(A25:A26) -> 544320
A26: 544320 | C26: Add:Addition during the year | F26: =+'I&E 25-26'!G53 -> 544320
A27: 0 | C27: Add: Interest during the year | F27: ='Fixed Deposit'!E12 -> 37585 | G27: =SUM(F25:F27) -> 1126225 | I27: 37562.6 | K27: Fixed Assets (Sch-II) | P27: =+'Assets '!I11+0.1 -> 85735.73
C29: Training & Education Fund | K29: Sundry Debtors
A30: 0 | C30: As per last B/s. | F30: =SUM(A30:A33) -> 5040 | I30: 70364.25 | K30: Dues from Members (Sch-III) | P30: ='Mem os'!D9 -> 15452
A31: 5040 | C31: Add:Addition during the year | F31: ='I&E 25-26'!G54 -> 5040 | I31: 0 | K31: Receivable Dhawal Housing | P31: =9600-'Builder Ac'!D12 -> 1800
A32: 0 | C32: Add: Interest during the year | F32: ='Fixed Deposit'!E28 -> 207 | I32: 1373364 | K32: Builder A/c | P32: =(1373364-23200-22200-1000000-250000+25500)*0 -> 0
A33: 0 | C33: Less:Expenses during the year | F33: 5947 | G33: =SUM(F30:F32)-F33 -> 4340
K34: Prepaid Expenses
C35: Current Liabilities | I35: 27878 | K35: Insurance | P35: 24671
A36: 59982 | C36: Expenses incurred by Members | G36: =+F36 -> 0 | I36: 0 | K36: Lift AMC | P36: 30987
I37: 0 | K37: Adda Subscription Charges | P37: 6064
C38: Member Payable | I38: 0 | K38: Pest Control AMC | P38: =1721+38321 -> 40042
A39: 0 | C39: Advance from members (Sch-IV) | G39: ='Mem os'!D20 -> 52771
A41: 522613.72 | C41: Provisions & Payables (Sch-V) | G41: =Sch!D20 -> 566495
A43: 0 | C43: Payable to Builder (Sch-VI) | G43: =-'Builder Ac'!E32 -> 602324
C45: Income & Expenditure Account
...

Sheet I&E 25-26
A1: SUNRISE ORLEM TOWER 2B CO OPERATIVE HOUSING SOCIETY
A2: Regn.No.MUM/SRA/HSG/(TC)/13509/2024 Dt.13/03/2024
A3: For the year ended on 31st March 2026
A4: Previous Year Rs. | B4: EXPENDITURE | H4: Current Year Rs. | J4: Previous Year Rs. | K4: INCOME | P4: Current Year Rs.
C5: Property Expenses | L5: Members Contribution Towards
A6: 18280 | C6: Municipal Taxes | G6: 20102 | J6: 3608640 | L6: Maintenance Charges | O6: 1208592
A7: 514814 | C7: Common Electricity Charges | G7: 631730 | J7: 0 | L7: Electricity Charges | O7: 576072
A8: 33690 | C8: Alternate Fire Fighting Electricity Charges | G8: 0 | J8: 0 | L8: Water Charges | O8: 105336
A9: 29500 | C9: Water Tanker Charges | G9: 36000 | J9: 0 | L9: Service Charges | O9: 838656
A10: 59568 | C10: Water Charges | G10: 58451 | J10: 70364.25 | L10: Non Occupancy Charges | O10: 65160
A11: 0 | C11: Water Tank Cleaning Expenses | G11: 8500 | J11: 181440 | L11: Sinking Fund | O11: 181440
A12: 354000 | C12: Lift Maintenance | G12: =346023+12931.2 -> 358954.2 | J12: 544320 | L12: Repair Fund | O12: 544320
A13: 0 | C13: Electrical Repair Maintenance | G13: 10549 | J13: 0 | L13: Contribution Towards Cultural Expenses | O13: 63000
A14: 22000 | C14: Other Repairs & Maintenance | G14: 48822 | J14: 0 | L14: Other Charges - Stilt Area | O14: 9600
A15: 0 | C15: Intercom Repair & Maintenance | G15: 2360 | J15: 5040 | L15: Training & Education | O15: 5040
A16: 0 | C16: Water Pump Repair charges | G16: 58290 | J16: 0 | L16: Late Payment Interest | O16: =11158+2 -> 11160
A17: 0 | C17: Plumbing Repair & Maintenance | G17: 26213 | J17: 0 | L17: Insurance Charges | O17: 22428
A18: 38000 | C18: Fire Fighting AMC | G18: 0 | J18: 0 | L18: Property Tax | O18: =1620+7308 -> 8928
A19: 28206.72 | C19: Pest Control Charges | G19: 31336.2 | J19: 0 | L19: Parking charges/ Stilt Area | O19: =9000+3780 -> 12780
A20: 371500 | C20: Security Charges | G20: 350311.2 | J20: 0 | L20: Federation Electricity - Tower Parking/GYM | O20: 65016
A21: 10401 | C21: House Keeping Material | G21: 9638 | J21: 0 | L21: Federation Service Charges | O21: 541296
A22: 118399 | C22: House Keeping Charges | G22: 273650.79 | J22: 0 | L22: Federation Property Tax - Common area / gym | O22: 36288
A23: 16948 | C23: Insurance Charges | G23: 41203 | J23: 0 | L23: Federation Charges | O23: 642600 | P23: =SUM(O6:O23) -> 4937712
A24: 4500 | C24: Audit Fees | G24: 4500
A25: 4670 | C25: Printing & Stationery | G25: 18529 | L25: Receipt on Flat Transfer
A26: 179 | C26: Postage & Courier Charges | G26: 175 | J26: 25000 | L26: Share Transfer Premium | P26: 0
A27: 8000 | C27: Accounting Charges | G27: 34280 | J27: 7600 | L27: Admission Fees | P27: 0
A28: 888 | C28: Meeting Expenses | G28: 9021
A29: 6500 | C29: Professional Fees | G29: 24000 | L29: Other Income
A30: 0 | C30: Conveyance charges | G30: 550 | J30: 3000 | L30: Rent Income | P30: 0
A31: 0 | C31: Bank Charges | G31: 3.85
A32: 26062 | C32: Festival Expenses | G32: 90147 | L32: Interest Income
A33: 0 | C33: Adda Subscription Charges | G33: 563 | J33: 0 | L33: Interest - Saving Account | O33: 3983
A34: 12150 | C34: Fire Extinguisher | G34: 12150 | J34: 0 | L34: Interest - Sweep Account | O34: 13957
A35: 28320 | C35: My Gate | G35: 0 | J35: 5087 | L35: Interest - Fixed Deposit | O35: 100356
A36: 3925.5 | C36: Deprepciation | G36: ='Assets '!H11 -> 19457 | H36: =SUM(G6:G36) -> 2179486.2 | J36: 0 | L36: Less: Interest on Sinking Fund | O36: =-'Fixed Deposit'!E7 -> -12528
J37: 0 | L37: Less: Interest on Repair Fund | O37: =-'Fixed Deposit'!E12 -> -37585
C38: Federation Expense | J38: 0 | L38: Less: Interest on Education Fund | O38: =-'Fixed Deposit'!E28 -> -207
A39: 44247 | C39: GYM Electricity | G39: =55359+6926 -> 62285 | J39: 0 | L39: Less: Interest on Reserve Fund | O39: =-'Fixed Deposit'!E23-'Fixed Deposit'!E15 -> -50018 | P39: =SUM(O33:O39) -> 17958
A40: 0 | C40: GYM R & M | G40: =1000+125 -> 1125
...

Sheet Fixed Deposit
B1: SUNRISE ORLEM TOWER 2B CO OPERATIVE HOUSING SOCIETY
B2: Schedule I - Details of Fixed Deposits as on 31st March 2026
A3: Sr. no. | B3: Certificate No. | C3: Date | D3: Amount Invested | E3: Accrued Int. 25-26 | F3: TDS | G3: Total Accrued Interest | H3: Total Value as on 31.03.2026 | I3: Maturity Date | J3: Maturity Value | K3: Interest % | L3: Bank | P3: Assets | Q3: Liabilities | R3: (Shortfall)
B4: Sinking Fund | P4: Investments | Q4: Funds | R4: Excess
A5: 1 | B5: TD1001809298 | C5: 03.09.2025 | D5: 181440 | E5: 7457 | F5: 746 | G5: =SUM(E5:E5)-F5 -> 6711 | H5: =D5+G5 -> 188151 | I5: 02.09.2027 | J5: 208453 | K5: 7 | L5: SCB | O5: Sinking Fund | P5: =H7 -> 374155 | Q5: ='BS 25-26'!G22 -> 375408 | R5: =P5-Q5 -> -1253
A6: 2 | B6: TD1001902668 | C6: 04.11.2025 | D6: 181440 | E6: 5071 | F6: 507 | G6: =SUM(E6:E6)-F6 -> 4564 | H6: =D6+G6 -> 186004 | I6: 04.11.2027 | J6: 207635 | K6: 6.8 | L6: SCB | O6: Repair Fund | P6: =H12 -> 1122466 | Q6: ='BS 25-26'!G27 -> 1126225 | R6: =P6-Q6 -> -3759
D7: =SUM(D5:D6) -> 362880 | E7: =SUM(E5:E6) -> 12528 | F7: =SUM(F5:F6) -> 1253 | G7: =SUM(G5:G6) -> 11275 | H7: =SUM(H5:H6) -> 374155 | J7: =SUM(J5:J6) -> 416088 | O7: Reserve Fund | P7: =H23 -> 1431156.3 | Q7: ='BS 25-26'!G17 -> 1431156.3 | R7: =P7-Q7 -> 0 | S7: 1019372
O8: Share Capital | P8: =H32 -> 21000 | Q8: ='BS 25-26'!G9 -> 21000 | R8: =P8-Q8 -> 0
B9: Repair Fund | P9: =SUM(P5:P8) -> 2948777.3 | Q9: =SUM(Q5:Q8) -> 2953789.3 | R9: =SUM(R5:R8) -> -5012
A10: 3 | B10: TD1001809347 | C10: 03.09.2025 | D10: 544320 | E10: 22371 | F10: 2237 | G10: =SUM(E10:E10)-F10 -> 20134 | H10: =D10+G10 -> 564454 | I10: 02.09.2027 | J10: 625097 | K10: 7 | L10: SCB
A11: 4 | B11: TD1001902699 | C11: 04.11.2025 | D11: 544320 | E11: 15214 | F11: 1522 | G11: =SUM(E11:E11)-F11 -> 13692 | H11: =D11+G11 -> 558012 | I11: 04.11.2027 | J11: 622905 | K11: 6.8 | L11: SCB
D12: =SUM(D10:D11) -> 1088640 | E12: =SUM(E10:E11) -> 37585 | F12: =SUM(F10:F11) -> 3759 | G12: =SUM(G10:G11) -> 33826 | H12: =SUM(H10:H11) -> 1122466 | J12: =SUM(J10:J11) -> 1248002
B14: Reserve Fund
B15: 50301067120830 | C15: 01.04.2025 | D15: 200000 | E15: 8477 | G15: =SUM(E15:E15)-F15 -> 8477 | H15: =D15+G15 -> 208477 | L15: HDFC
A17: 5 | B17: 6605300019841 | C17: 27.03.2026 | D17: 32000 | E17: 28 | F17: 0 | G17: =SUM(E17:E17)-F17 -> 28 | H17: =D17+G17 -> 32028 | I17: 27.03.2031 | J17: 44173 | K17: 6.5 | L17: MDCC
A18: 6 | B18: TD1001812588 | C18: 05.09.2025 | D18: 361766.26 | E18: 14658 | F18: 1466 | G18: =SUM(E18:E18)-F18 -> 13192 | H18: =D18+G18 -> 374958.26 | I18: 05.09.2027 | J18: 415626.26 | K18: 7 | L18: SCB
A19: 7 | B19: TD1001820321 | C19: 07.09.2025 | D19: 250000 | E19: 9984 | F19: 998 | G19: =SUM(E19:E19)-F19 -> 8986 | H19: =D19+G19 -> 258986 | I19: 08.09.2027 | J19: 287220 | K19: 7 | L19: SCB
A20: 8 | B20: TD1001820341 | C20: 07.09.2025 | D20: 250000 | E20: 9984 | F20: 998 | G20: =SUM(E20:E20)-F20 -> 8986 | H20: =D20+G20 -> 258986 | I20: 08.09.2027 | J20: 287220 | K20: 7 | L20: SCB
A21: 9 | B21: TD1001913684 | C21: 04.11.2025 | D21: 200000 | E21: 5516 | F21: 552 | G21: =SUM(E21:E21)-F21 -> 4964 | H21: =D21+G21 -> 204964 | I21: 06.12.2026 | J21: 215147 | K21: 6.8 | L21: SCB
A22: 10 | B22: TD1002054962 | C22: 07.03.2026 | D22: 300000 | E22: 1371 | F22: 137 | G22: =SUM(E22:E22)-F22 -> 1234 | H22: =D22+G22 -> 301234 | I22: 07.03.2028 | J22: 343312 | K22: 6.8 | L22: SCB
D23: =SUM(D17:D22) -> 1393766.3 | E23: =SUM(E17:E22) -> 41541 | F23: =SUM(F17:F22) -> 4151 | G23: =SUM(G17:G22) -> 37390 | H23: =SUM(H17:H22) -> 1431156.3 | J23: =SUM(J17:J22) -> 1592698.3
B25: Education & Training Fund
A27: 11 | B27: TD1001809417 | C27: 03.09.2025 | D27: 5040 | E27: 207 | F27: 21 | G27: =SUM(E27:E27)-F27 -> 186 | H27: =D27+G27 -> 5226 | I27: 22.10.2026 | J27: 5433 | K27: 7 | L27: SCB
D28: =SUM(D27) -> 5040 | E28: =SUM(E27) -> 207 | F28: =SUM(F27) -> 21 | G28: =SUM(G27) -> 186 | H28: =SUM(H27) -> 5226 | J28: =SUM(J27) -> 5433
B30: Share Capital
A31: 12 | B31: 006601200007701 | C31: 27.03.2026 | D31: 21000 | E31: 0 | F31: 0 | G31: 0 | H31: =D31+G31 -> 21000 | I31: 27.03.2031 | J31: 21000 | K31: 6.5 | L31: MDCC
D32: =SUM(D31) -> 21000 | E32: =SUM(E31) -> 0 | F32: =SUM(F31) -> 0 | G32: =SUM(G31) -> 0 | H32: =SUM(H31) -> 21000 | J32: =SUM(J31) -> 21000
B34: GRAND TOTALS | D34: =D7+D23+D12+D32+D28 -> 2871326.3 | E34: =E7+E23+E12+E32+E28+F46 -> 91879 | F34: =F7+F23+F12+F32+F28+G46 -> 9184 | G34: =G7+G23+G12+G32+G28 -> 82677 | H34: =H7+H23+H12+H32+H28 -> 2954003.3 | J34: =J7+J23+J12+J32+J28 -> 3283221.3
B36: Note : | C36: Renewed on 06.06.18 - Not reflected in Bank certiciate Accrued Interest provided for these Fd as under
C37: 31.03.18 | D37: Accrued Int | H37: Accrued Int | I37: Date of renewal | J37: Amount Renewed
B38: 1017085 | C38: 28242 | D38: =+#REF!-C38 -> #REF! | H38: =+#REF!*#REF! -> #REF! | I38: 06.06.18 | J38: 30476 | K38: =+J38-#REF! -> #REF! | L38: 10.3.18 to 06.06.18
B39: 1017317 | C39: 81142 | D39: =+#REF!-C39 -> #REF! | H39: =+#REF!*#REF! -> #REF! | I39: 06.06.18 | J39: 87647 | K39: =+J39-#REF! -> #REF! | L39: 23.03.18 to 06.06.18
B40: 1017316 | C40: 271014 | D40: =+#REF!-C40 -> #REF! | H40: =+#REF!*#REF! -> #REF! | I40: 06.06.18 | J40: 292735 | K40: =+J40-#REF! -> #REF! | L40: 23.03.18 to 06.06.18
E46: =B31 -> 006601200007701 | F46: 18 | I46: Credited in bank
E47: HDFC BK | F47: =E15 -> 8477 | G47: =F15 -> 0 | H47: 8477 | I47: 0
E48: MDCC BK | F48: =F46+E17 -> 46 | G48: =G46+F17 -> 0 | H48: =18+28 -> 46 | I48: 0
E49: SCB SWEEP | F49: 13957 | G49: 1395
E50: SCB FD | F50: =SUM(E5:E6,E10:E11,E18:E22,E27) -> 91833 | G50: =SUM(F5:F6,F10:F11,F18:F22,F27) -> 9184
E51: SCB TOTAL | F51: =SUM(F49:F50) -> 105790 | G51: =SUM(G49:G50) -> 10579 | H51: 105790 | I51: 10579

Sheet Assets 
A1: SUNRISE ORLEM TOWER 2B CO OPERATIVE HOUSING SOCIETY
A2: SCHEDULES FORMING PART OF BALANCE SHEET AS ON 31.03.2026
A3: FIXED ASSETS
A4: Schedule (II)
A5: SR.NO. | B5: PARTICULARS | C5: RATE OF DEPN. % | D5: OPENING BALANCE AS ON 01.04.2025 | E5: ADDITIONS DURING THE YEAR | F5: DELETIONS DURING THE YEAR | G5: Total | H5: Depreciation | I5: CLOSING BALNCE AS ON 31.03.2026
D6: A | E6: B | G6: C | H6: D | I6: (C - D)
A7: 1 | B7: Furniture & Fixtures | C7: 10 | D7: 27690.5 | E7: 4990 | F7: 0 | G7: =D7+E7-F7 -> 32680.5 | H7: =ROUND((D7+E7-F7)*C7%,0) -> 3268 | I7: =G7-H7 -> 29412.5
A8: 2 | B8: Computer & Printer | C8: 40 | D8: 9872 | E8: 0 | F8: 0 | G8: =D8+E8-F8 -> 9872 | H8: =ROUND((D8+E8-F8)*C8%,0) -> 3949 | I8: =G8-H8 -> 5923
A9: 3 | B9: Pump | C9: 15 | D9: 0 | E9: =17000+9250+25016 -> 51266 | G9: =D9+E9-F9 -> 51266 | H9: =ROUND((D9+E9-F9)*C9%,0) -> 7690 | I9: =G9-H9 -> 43576
A10: 4 | B10: Mobile | C10: 40 | D10: 0 | E10: 11374.13 | G10: =D10+E10-F10 -> 11374.13 | H10: =ROUND((D10+E10-F10)*C10%,0) -> 4550 | I10: =G10-H10 -> 6824.13
B11: TOTAL Rs. | D11: =SUM(D7:D10) -> 37562.5 | E11: =SUM(E7:E10) -> 67630.13 | F11: =SUM(F7:F10) -> 0 | G11: =SUM(G7:G10) -> 105192.63 | H11: =SUM(H7:H10) -> 19457 | I11: =SUM(I7:I10) -> 85735.63

Sheet Mem os
A3: Sch-III
A4: Sunrise Orlem Tower 2B Co Operative Housing Society Limited
A5: Receivable - Members as of 31st March 2026
A6: Sl.No | B6: Unit | C6: Primary Contact | D6: Receivable Amount
A7: 1 | B7: 0101 | C7: MR.SAHEBRAO ABAJI BHISE & MRS. REKHA SAHEBRAO BHISE & MRS. KOMAL PRAVIN NERKAR ALIAS MS. KOMAL SAHEBRAO BHISE | D7: 15436
A8: 2 | B8: 1502 | C8: MR. EVERTON JOHN PEREIRA & MRS. ALICE PEREIRA | D8: 16
C9: TOTAL | D9: =SUM(D7:D8) -> 15452
A14: Sch-IV
A15: Sunrise Orlem Tower 2B Co Operative Housing Society Limited
A16: Advance-Members as of 31st March 2026
A17: Sl.No | B17: Unit | C17: Primary Contact | D17: Advance Amount
A18: 1 | B18: 1801 | C18: MRS. VANDANA GIRDHARILAL NAVANI & MR. NITIN GIRDHARILAL NAVANI | D18: 43521
A19: 2 | B19: 2001 | C19: MR. NELSON GEORGE DSOUZA & MRS. ROSHANI DSOUZA | D19: 9250
C20: TOTAL | D20: =SUM(D18:D19) -> 52771

Sheet Sch
A2: Sch-V
A3: Sunrise Orlem Tower 2B Co Operative Housing Society Limited
A4: Vendor payables & Provision as of 31st March 2026
A6: Current Liabilities/Provisions
A7: Sr. No | B7: Particulars | C7: 2024-25 | D7: 2025-26
A8: 1 | B8: Audit Fees | C8: 4500 | D8: 4500
A9: 2 | B9: Pest Control | C9: 28206.72 | D9: 0
A10: 3 | B10: House Keeping Charges | C10: 23180 | D10: 20234
B11: Security Charges - Shera Security | C11: 0 | D11: 66221
A12: 4 | B12: Security Charges - Ashtabhuja | C12: 83661 | D12: 68279
A13: 5 | B13: Professional fees | C13: 5500 | D13: 0
A14: 6 | B14: Accounting Charges | C14: 8000 | D14: 0
A15: 7 | B15: Electricity Charges - Adani | C15: 55030 | D15: =50590+3830 -> 54420
A16: 8 | B16: Water Tanker Charges | C16: 12000 | D16: 0
A17: 9 | B17: Water Charges | C17: 14892 | D17: 28530
A18: 10 | B18: TDS Payable | C18: 4977 | D18: 354
A19: 11 | B19: Federation Expenses Payable | C19: 282667 | D19: =977064-833647+180540 -> 323957
A20: Total | C20: =SUM(C8:C19) -> 522613.72 | D20: =SUM(D8:D19) -> 566495

Sheet BRS
B2: SUNRISE Orlem Tower 2B CHS LTD
B3: HDFC Bank Reconciliation Statement as on 31.03.2026
D4: Amt | F4: Date | G4: Deposit | H4: Issued | I4: Instru. No. | J4: Remarks | K4: Cleared on
B5: Balance as per Book Balance (System) | D5: 218208.75 | F5: 06.03.2026 | G5: 0 | H5: 29500 | I5: 000041 | J5: PCI Pest Control | K5: 02.04.2026
F6: 31.03.2026 | G6: 9250 | H6: 0 | I6: SOZ013147542 | J6: Flat 2001 - Maintenance | K6: 02.04.2026
A7: Add: | B7: Cheques issued but not cleared | D7: =H8 -> 33000 | F7: 31.03.2026 | G7: 0 | H7: 3500 | I7: 000046 | J7: Pump Care Services | K7: 07.04.2026
G8: =SUM(G5:G7) -> 9250 | H8: =SUM(H5:H7) -> 33000
A9: Less: | B9: Cheques deposited but not cleared | D9: =G8 -> 9250
B11: Balance as per Bank Passbook | D11: =D5+D7-D9 -> 241958.75
B14: Saraswat Bank Reconciliation Statement as on 31.03.2026
D15: Amt
B16: Balance as per Book Balance (System) | D16: 212558.15
B18: Balance as per Bank Passbook | D18: =D16 -> 212558.15
B22: MDCC Bank Reconciliation Statement as on 31.03.2026
D23: Amt
B24: Balance as per Book Balance (System) | D24: 6401
B26: Balance as per Bank Passbook | D26: =D24 -> 6401
B30: MDCC Promotors a/c Reconciliation Statement as on 06.01.26
D31: Amt
B32: Balance as per Book Balance (System) | D32: 0
B34: Balance as per Bank Passbook | D34: 0 | E34: A/c closed

Sheet Builder Ac
C3: Sch-VI
B4: Builder Account Statement
B5: Date | C5: Particular | D5: Debit | E5: Credit
B6: 01.04.2025 | C6: Opening Balance as of 01.04.2025
B7: 01.04.2025 | C7: Receivable from Builder | D7: 1373364 | G7: Share Money | H7: =21000+7600 -> 28600
B8: 01.04.2025 | C8: Transfer Premium of 602 & Share money received from Builder & initail deposit | E8: =H10 -> 50400 | G8: 602 Transfer Premium | H8: 25000
B9: 07.04.2025 | C9: Amount received from Dhaval Housing | E9: 1000000 | G9: Total receipt from member | H9: =SUM(H7:H8) -> 53600
B10: 16.05.2025 | C10: Amount received from Dhaval Housing | E10: 250000 | G10: Actual received from Builder | H10: =22200+23200+5000 -> 50400 | I10: (Partially paid & initial deposit)
C11: Debit Notes | H11: =H9-H10 -> 3200 | I11: Still receivable agst share money
B12: 29.01.2026 | C12: Parking charges from Dhaval DN no.1 | D12: 7800
B13: 29.01.2026 | C13: Purchase of 2 cupboard & installation of grills window as per DN no.2 | D13: 31500
B14: 29.01.2026 | C14: Towards civil works - Dr. Note . 3 | D14: 25500
B15: 16.03.2026 | C15: Electrical work done on terrace as per DN no.4 | D15: 10200
C16: Provision for Federation
B17: 01-04-2025 | C17: Being provision towards Federation Insurance Tower Parking for FY 2024-25 | E17: 16061
B18: 01-04-2025 | C18: Being provision towards Federation Property Tax CA for FY 2024-25 | E18: =51644+7108 -> 58752
B19: 01-04-2025 | C19: Being provision towards Federation electricity tower parking account 153461716 & 153461715 for FY 2024-25 | E19: =24737+4737 -> 29474
B20: 01-04-2025 | C20: Being provision towards Federation electricity tower parking account 153461716 & 153461715 for FY 2024-25 | E20: =36204+3390 -> 39594
B21: 01-04-2025 | C21: Being provision towards Federation Electricity car wash for FY 2024-25 | E21: 4375
B22: 31-03-2026 | C22: Being provision towards Federation electricity tower parking account 153461716 & 153461715 for FY 2025-26 | E22: 27092
B23: 31-03-2026 | C23: Being provision towards Federation Insurance Tower Parking for FY 2025-26 | E23: =26871+3362 -> 30233
B24: 31-03-2026 | C24: Being provision towards Federation Property Tax CA for FY 2025-26 | E24: 56811
B25: 31-03-2026 | C25: Being provision towards Federation Electricity car wash for FY 2025-26 | E25: =7623+954 -> 8577
B26: 31-03-2026 | C26: Being provision towards Federation Gym electricity for FY 2025-26 | E26: =55359+6926 -> 62285
B27: 31-03-2026 | C27: Being provision towards Federation electricity tower parking account 153461716 & 153461715 for FY 2025-26 | E27: 37858
B28: 31-03-2026 | C28: Being provision towards Federation stack parking operator for FY 2025-26 | E28: =176004+22020 -> 198024
B29: 31-03-2026 | C29: Being provision towards Federation Gym R & M for FY 2025-26 | E29: =1000+125 -> 1125
B30: 31-03-2026 | C30: Being provision towards Federation Gym Trainer operator for FY 2025-26 | E30: =160008+20019 -> 180027
C31: Total | D31: =SUM(D7:D30) -> 1448364 | E31: =SUM(E7:E30) -> 2050688
C32: Net Payable to Builder | E32: =D31-E31 -> -602324

Sheet working
A1: MCGM WATER CHARGES
A2: PN 0061354 | B2: 45751 | C2: 45845 | D2: =C2-B2 -> 94 | E2: 15177 | F2: paid
B3: =C2 -> 45845 | C3: 45936 | D3: =C3-B3 -> 91 | E3: 14812 | F3: paid
D4: =SUM(D2:D3) -> 185 | E4: =SUM(E2:E3) -> 29989 | I4: Posted Date | J4: Comments | K4: Debit | L4: Credit | M4: FY 2024-25
B5: =C3 -> 45936 | C5: 46112 | D5: =C5-B5 -> 176 | E5: =ROUND(E4/D4*D5,0) -> 28530 | F5: PROVISION | I5: 01-04-2025 | J5: Opening Balance | K5: 0 | L5: 282667
I6: 01-04-2025 | J6: Being provision towards Federation Insurance Tower Parking for FY 2024-25 | L6: 16061
I7: 01-04-2025 | J7: Being prov for Security Exp - Federation reversed | K7: 52000
I8: 01-04-2025 | J8: Being prov for Security exp - Federation for FY 2024-25 reversed | K8: 100000
A9: LIFT AMC | B9: 45778 | C9: 46142 | D9: =C9-B9+1 -> 365 | E9: 377010 | I9: 01-04-2025 | J9: Being provision towards Federation Property Tax CA for FY 2024-25 | L9: 51644
B10: 46113 | C10: =C9 -> 46142 | D10: =C10-B10+1 -> 30 | E10: =ROUND(E9/D9*D10,0) -> 30987 | F10: prepaid | I10: 01-04-2025 | J10: Being provision towards Federation electricity tower parking account 153461716 & 153461715 for FY 2024-25 | L10: 24737
I11: 01-04-2025 | J11: Being provision towards Federation electricity tower parking account 153461716 & 153461715 for FY 2024-25 | L11: 36204
A12: ADDA Subscription | B12: 46082 | C12: 46446 | D12: =C12-B12+1 -> 365 | E12: 6627 | I12: 01-04-2025 | J12: Being provision towards Federation Electricity car wash for FY 2024-25 | L12: 4375
B13: 46113 | C13: =C12 -> 46446 | D13: =C13-B13+1 -> 334 | E13: =ROUND(E12/D12*D13,0) -> 6064 | F13: prepaid | I13: 31-03-2026 | J13: Being provision towards Federation electricity tower parking account 153461716 & 153461715 for FY 2025-26 | L13: 27092
I14: 31-03-2026 | J14: Being provision towards Federation Insurance Tower Parking for FY 2025-26 | L14: 26871
A15: Insurance | B15: 45985 | C15: 46349 | D15: =C15-B15+1 -> 365 | E15: 37996 | I15: 31-03-2026 | J15: Being provision towards Federation Property Tax CA for FY 2025-26 | L15: 56811
B16: 46113 | C16: =C15 -> 46349 | D16: =C16-B16+1 -> 237 | E16: =ROUND(E15/D15*D16,0) -> 24671 | F16: prepaid | I16: 31-03-2026 | J16: Being provision towards Federation Electricity car wash for FY 2025-26 | L16: 7623
I17: 31-03-2026 | J17: Being provision towards Federation Gym electricity for FY 2025-26 | L17: 55359
A18: Pest Control | B18: 45763 | C18: 46127 | D18: =C18-B18+1 -> 365 | E18: 41878.2 | I18: 31-03-2026 | J18: Being provision towards Federation electricity tower parking account 153461716 & 153461715 for FY 2025-26 | L18: 37858
B19: 46113 | C19: =C18 -> 46127 | D19: =C19-B19+1 -> 15 | E19: =ROUND(E18/D18*D19,0) -> 1721 | F19: prepaid | I19: 31-03-2026 | J19: Being provision towards Federation stack parking operator for FY 2025-26 | L19: 176004
I20: 31-03-2026 | J20: Being provision towards Federation Gym R & M for FY 2025-26 | L20: 1000
A21: Pest Control | B21: 46082 | C21: 46446 | D21: =C21-B21+1 -> 365 | E21: 41878.2 | I21: 31-03-2026 | J21: Being provision towards Federation Gym Trainer operator for FY 2025-26 | L21: 160008
B22: 46113 | C22: =C21 -> 46446 | D22: =C22-B22+1 -> 334 | E22: =ROUND(E21/D21*D22,0) -> 38321 | F22: prepaid | K22: =SUM(K5:K21) -> 152000 | L22: =SUM(L5:L21) -> 964314 | M22: =L22-K22 -> 812314

Sheet Assets
A1: DHRUV PARK (ATT)CO.OP.HSG.SOCIETY LTD.
A2: SCHEDULE - B FIXED ASSETS
A3: SR.NO. | B3: PARTICULARS | C3: RATE OF DEPN. % | D3: OPENING BALANCE AS ON 01.04.2023 | E3: ADDITIONS DURING THE YEAR | F3: Total | G3: Depreciation | H3: CLOSING BALNCE AS ON 31.03.2024
D4: A | E4: B | F4: C | G4: D | H4: (C - D)
A5: 1 | B5: LAND & BUILDING | C5: 0 | E5: =531916093 -> 531916093 | F5: =D5+E5 -> 531916093 | G5: =F5*0% -> 0 | H5: =F5-G5 -> 531916093
A6: 2 | B6: FURNITURE & FIXTURE | C6: 10 | D6: 87543 | E6: 0 | F6: =D6+E6 -> 87543 | G6: =+(D6+E6)*C6% -> 8754.3 | H6: =F6-G6 -> 78788.7
A7: 3 | B7: CYCLE STAND & COMPOUND GATE | C7: 10 | D7: 78354 | E7: 0 | F7: =D7+E7 -> 78354 | G7: =+(D7+E7)*C7% -> 7835.4 | H7: =F7-G7 -> 70518.6
A8: 4 | B8: Water Pump | C8: 15 | D8: 55853 | E8: 0 | F8: =D8+E8 -> 55853 | G8: =+(D8+E8)*C8% -> 8377.95 | H8: =F8-G8 -> 47475.05
A9: 5 | B9: CCTV | C9: 20 | D9: 34134 | E9: =407990+30236+21500 -> 459726 | F9: =D9+E9 -> 493860 | G9: =+(D9+E9)*C9% -> 98772 | H9: =F9-G9 -> 395088
A10: 6 | B10: Fire Fighting Equipments | C10: 10 | D10: 115437 | E10: 0 | F10: =D10+E10 -> 115437 | G10: =+(D10+E10)*C10% -> 11543.7 | H10: =F10-G10 -> 103893.3 | K10: Water Connection
A11: 7 | B11: BOREWELL & WATER HARVESTING | C11: 15 | D11: 73977 | E11: 0 | F11: =D11+E11 -> 73977 | G11: =+(D11+E11)*C11% -> 11096.55 | H11: =F11-G11 -> 62880.45 | K11: Before 3 Oct | L11: 250000 | M11: =+L11*15% -> 37500
A12: 8 | B12: Water Meter | C12: 15 | D12: 30035 | E12: 0 | F12: =D12+E12 -> 30035 | G12: =+(D12+E12)*C12% -> 4505.25 | H12: =F12-G12 -> 25529.75 | K12: After 3 Oct | L12: =250000+71880+50500 -> 372380 | M12: =+L12*15%/2 -> 27928.5
A13: 9 | B13: SPORTS EQUIPMENTS | C13: 10 | D13: 2202 | E13: 0 | F13: =D13+E13 -> 2202 | G13: =+(D13+E13)*C13% -> 220.2 | H13: =F13-G13 -> 1981.8 | M13: =SUM(M11:M12) -> 65428.5
A14: 10 | B14: COMPUTER & PRINTER | C14: 40 | D14: 13055 | E14: 0 | F14: =D14+E14 -> 13055 | G14: =+(D14+E14)*C14% -> 5222 | H14: =F14-G14 -> 7833
A15: 11 | B15: SOUND SYSTEM | C15: 10 | D15: 5843 | E15: 0 | F15: =D15+E15 -> 5843 | G15: =+(D15+E15)*C15% -> 584.3 | H15: =F15-G15 -> 5258.7
A16: 12 | B16: TOOLS & EQUIPMENTS | C16: 10 | D16: 6313 | E16: 0 | F16: =D16+E16 -> 6313 | G16: =+(D16+E16)*C16% -> 631.3 | H16: =F16-G16 -> 5681.7
A17: 13 | B17: GENERATOR | C17: 10 | D17: 29637 | E17: 0 | F17: =D17+E17 -> 29637 | G17: =+(D17+E17)*C17% -> 2963.7 | H17: =F17-G17 -> 26673.3
A18: 14 | B18: FOGGING MACHINE | C18: 15 | D18: 10440 | E18: 0 | F18: =D18+E18 -> 10440 | G18: =+(D18+E18)*C18% -> 1566 | H18: =F18-G18 -> 8874
A19: 15 | B19: Water Connection | C19: 15 | D19: 0 | E19: =622380-46880+86600 -> 662100 | F19: =D19+E19 -> 662100 | G19: =+(250000*15%)+(412100*7.5%) -> 68407.5 | H19: =F19-G19 -> 593692.5
B20: TOTAL Rs. | D20: =SUM(D5:D19) -> 542823 | E20: =SUM(E5:E19) -> 533037919 | F20: =SUM(F5:F19) -> 533580742 | G20: =SUM(G5:G19) -> 230480.15 | H20: =SUM(H5:H19) -> 5.3335026e+08

Sheet Sheet2
H10: ok | I10: agm fine
H11: ok | I11: Misc Income
H12: ok | I12: Accounting charges
H13: ok | I13: Insuarnce prepaid calculation
H15: 10k adjust aginst misc | I15: Fetival Day
H17: ok | I17: W-off anuual day against common aminties fund
H21: ok | I21: shares,
I22: Davi sir
G23: sahakar bharti | H23: ok | I23: training and education
G24: agm resolution | H24: next yr | I24: Discard related to subregistrat
I26: 5k o/s- whre to put
I27: 137K

Sheet Sheet1
A3: 1 | C3: 2 | D3: 3 | E3: 4
A4: F0201 Mrs. Flavia Fernandes | B4: Mrs. Flavia Fernandes | C4: F0201 | D4: 5000
A5: F0202 Mr. Sanjay Kumar & Smt. Kante Prasad | B5: Mr. Sanjay Kumar & Smt. Kante Prasad | C5: F0202 | D5: 5000
A6: F0203 - Mrs. Malini Karmancherry | B6: Mrs. Malini Karmancherry | C6: F0203 | E6: 12211
A7: F0204 Mr. T.K. Ananthakrishnan | B7: Mr. T.K. Ananthakrishnan | C7: F0204 | D7: 5000
A8: F0303 - Mr. Jerome Henery Fernandes | B8: Mr. Jerome Henery Fernandes | C8: F0303 | E8: 370
A9: F0405 - Mr. Alex Crasta & Mrs. Theresa Crasta | B9: Mr. Alex Crasta & Mrs. Theresa Crasta | C9: F0405 | D9: 5000
A10: F0504 - Mrs. Margaret Mascarenhas | B10: Mrs. Margaret Mascarenhas | C10: F0504 | E10: 10
A11: F0505 - Mr. Jiju George | B11: Mr. Jiju George | C11: F0505 | D11: 5000
A12: F0601 Mr. Linus P.D.'Souza & Mr. Lawrence P.D'Souza | B12: Mr. Linus P.D.'Souza & Mr. Lawrence P.D'Souza | C12: F0601 | D12: 5000
A13: F0602 - Mr. Mohammed Shaikh & Pakeeza Shaikh | B13: Mr. Mohammed Shaikh & Pakeeza Shaikh | C13: F0602 | D13: 5240
A14: F0605 - Mr. Jayendra T. Acharekar | B14: Mr. Jayendra T. Acharekar | C14: F0605 | E14: 1496
A15: F0705 - Mr. Lenzon & Mrs. Immelda Mendes | B15: Mr. Lenzon & Mrs. Immelda Mendes | C15: F0705 | E15: 0.5
A16: F0706 - Mr. Dhruv P.Dave | B16: Mr. Dhruv P.Dave | C16: F0706 | D16: 180
A17: F0901 -Mr. Wilbur Almeida & Mrs. Mrs. Dolly Almeida | B17: Mr. Wilbur Almeida & Mrs. Mrs. Dolly Almeida | C17: F0901 | D17: 6000
A18: F0906 - Mr. Atit Kamlesh Shah | B18: Mr. Atit Kamlesh Shah | C18: F0906 | D18: 5000
A19: F1002 - Ms. Karen Stephen | B19: Ms. Karen Stephen | C19: F1002 | E19: 516.5
A20: F1005 - Mrs. Tannvi Tapan Jagtap | B20: Mrs. Tannvi Tapan Jagtap | C20: F1005 | D20: 5000
A21: F1101 - Mr. Bharat R. Sharma | B21: Mr. Bharat R. Sharma | C21: F1101 | D21: 4978
A22: F1203 - Mr. Glenn Garfield Croning | B22: Mr. Glenn Garfield Croning | C22: F1203 | D22: 73299
A23: F1204 - Mrs. Avencia P. Cordeiro/Mrs. Daniella Gay | B23: Mrs. Avencia P. Cordeiro/Mrs. Daniella Gay | C23: F1204 | D23: 17
A24: F1206 - Mrs. Deepika N. & Mr. Naresh M. Vaswani | B24: Mrs. Deepika N. & Mr. Naresh M. Vaswani | C24: F1206 | D24: 305
A25: F1305 - Mrs. Madhurni Aggarwal | B25: Mrs. Madhurni Aggarwal | C25: F1305 | D25: 5000
A26: F1306 - Mrs. Flavia Fernandes/ Mr. Jerson Fernandes | B26: Mrs. Flavia Fernandes/ Mr. Jerson Fernandes | C26: F1306 | D26: 5000
A27: F1401 - Mr. Deepak Joshi | B27: Mr. Deepak Joshi | C27: F1401 | E27: 1
A28: F1405 - Mrs. Cynthia Machado | B28: Mrs. Cynthia Machado | C28: F1405 | D28: 5000
A29: F1502 -Mr. Anthony S. Chetty & Mr. Devraj S. Chetty | B29: Mr. Anthony S. Chetty & Mr. Devraj S. Chetty | C29: F1502 | E29: 6520
A30: F1505 - Mr. Marlon Silva Lobo | B30: Mr. Marlon Silva Lobo | C30: F1505 | D30: 5308
A31: F1702 - Mr. Kalpesh Shah/Mrs. Neha Shah/Anila Shah | B31: Mr. Kalpesh Shah/Mrs. Neha Shah/Anila Shah | C31: F1702 | D31: 5000
A32: F1705 - Mrs. Nitya Chatterjee | B32: Mrs. Nitya Chatterjee | C32: F1705 | D32: 5000
A33: F1803 - Mrs. Leena D'Souza | B33: Mrs. Leena D'Souza | C33: F1803 | D33: 5000
A34: F1804 - Mr. Alex Chetty | B34: Mr. Alex Chetty | C34: F1804 | E34: 48
A35: F1902-Mrs. Gail M. Fernandes/Mr. Fritz A. Fernandes | B35: Mrs. Gail M. Fernandes/Mr. Fritz A. Fernandes | C35: F1902 | D35: 5000
A36: F1903 - Mr. Satyandra Yadav | B36: Mr. Satyandra Yadav | C36: F1903 | D36: 17382
A37: F1904 - Mrs. Madhumita / Mr. Prashantkumar Lata | B37: Mrs. Madhumita / Mr. Prashantkumar Lata | C37: F1904 | D37: 5000
A38: F2002 - Mr. Nirbhay R. Desai | B38: Mr. Nirbhay R. Desai | C38: F2002 | D38: 5000
A39: F2101 - Mr. Rajeev M. Sherry | B39: Mr. Rajeev M. Sherry | C39: F2101 | D39: 5000
A40: F2102 - Rati Pandey | B40: Rati Pandey | C40: F2102 | D40: 5000
A41: F2105-Mr. Merrill G. & Mrs. Anuja M.Mascarenhas | B41: Mr. Merrill G. & Mrs. Anuja M.Mascarenhas | C41: F2105 | E41: 42635
A42: F2201 - Mr. Rufus Cardoza & Mrs. Philomena Cardoza | B42: Mr. Rufus Cardoza & Mrs. Philomena Cardoza | C42: F2201 | D42: 4997.5
...

Sheet Interest
B1: Interest Income
B2: DHRUV PARK (A.T.T) CO-OP HSG. SOC.LTD.
A3: Particulars | B3: 1-Apr-23 to 31-Mar-24
B4: Closing Balance
B5: Debit | C5: Credit | E5: NET | F5: TDS | G5: Gross
A6: Accrued Int. CAFD 466702 | C6: 3720 | D6: Common Amenity Fund | E6: =4133-413 -> 3720 | F6: =+E6/90*10 -> 413.33333 | G6: =+E6+F6 -> 4133.3333
A7: Accrued Interest FD-17889- MDCC | C7: 16605 | D7: Repair Fund | E7: =18450-1845 -> 16605 | F7: =+E7/90*10 -> 1845 | G7: =+E7+F7 -> 18450
A8: Accrued Interest on FD-14735 (MDCC) | C8: 1908 | D8: Sinking Fund | E8: =2120-212 -> 1908 | F8: =+E8/90*10 -> 212 | G8: =+E8+F8 -> 2120
A9: Interest Received on SFFD-14735 (MDCC Bank) | C9: 8655 | D9: Sinking Fund | E9: =9617-962 -> 8655 | F9: =+E9/90*10 -> 961.66667 | G9: =+E9+F9 -> 9616.6667
A10: Accrued Interest on FD-14951-MDCC | C10: 29106 | D10: Sinking Fund | E10: =32340-3234 -> 29106 | F10: =+E10/90*10 -> 3234 | G10: =+E10+F10 -> 32340
A11: Accrued Interest on FD-18266 (MDCC) | C11: 754 | D11: Share Capital | E11: =838-84 -> 754 | F11: =+E11/90*10 -> 83.777778 | G11: =+E11+F11 -> 837.77778
A12: Accrued Interest on FD-18267 | C12: 1771 | D12: Repair Fund | E12: =1968-196 -> 1772 | F12: =+E12/90*10 -> 196.88889 | G12: =+E12+F12 -> 1968.8889
A13: Accrued Interest on FD-731037 | C13: 53645 | D13: Reserve Fund | E13: =59606-5961 -> 53645 | F13: =+E13/90*10 -> 5960.5556 | G13: =+E13+F13 -> 59605.556
A14: Accrued Interest on FD-801981 | C14: 12151 | D14: Repair Fund | E14: =13503-1352 -> 12151 | F14: =+E14/90*10 -> 1350.1111 | G14: =+E14+F14 -> 13501.111
A15: Accrued Interest on FD-801989 | C15: 19659 | D15: Reserve Fund | E15: =21841-2182 -> 19659 | F15: =+E15/90*10 -> 2184.3333 | G15: =+E15+F15 -> 21843.333
A16: Accrued Interest on FD-802027 | C16: 9995 | D16: Sinking Fund | E16: =11106-1111 -> 9995 | F16: =+E16/90*10 -> 1110.5556 | G16: =+E16+F16 -> 11105.556
A17: Accrued Interest on Property TAXFD-1001112822-MDCC | C17: 3812 | D17: General Prop | E17: =4236-424 -> 3812 | F17: =+E17/90*10 -> 423.55556 | G17: =+E17+F17 -> 4235.5556
A18: Accrued Int on LFFD 678753 | C18: 81562 | D18: Legal Fund | E18: =90625-9063 -> 81562 | F18: =+E18/90*10 -> 9062.4444 | G18: =+E18+F18 -> 90624.444
A19: Accrued Int. on Reserve FD 414106 | C19: 43811 | D19: Reserve Fund | E19: =48678-4867 -> 43811 | F19: =+E19/90*10 -> 4867.8889 | G19: =+E19+F19 -> 48678.889
A20: Accrued Int. on RFFD 414104 | C20: 7342 | D20: Repair Fund | E20: =8156-814 -> 7342 | F20: =+E20/90*10 -> 815.77778 | G20: =+E20+F20 -> 8157.7778
A21: Accrued Int. on RFFD 414123 | C21: 11391 | D21: Repair Fund | E21: =12657-1266 -> 11391 | F21: =+E21/90*10 -> 1265.6667 | G21: =+E21+F21 -> 12656.667
A22: Accrued Int. on RFFD 629155 | C22: 34342 | D22: Repair Fund | E22: =38158-3816 -> 34342 | F22: =+E22/90*10 -> 3815.7778 | G22: =+E22+F22 -> 38157.778
A23: Accrued Int. on RFFD 667528 | C23: 9675 | D23: Repair Fund | E23: =10749-1074 -> 9675 | F23: =+E23/90*10 -> 1075 | G23: =+E23+F23 -> 10750
A24: Accrued Int. Reserve FD 414124 | C24: 15705 | D24: Reserve Fund | E24: =17451-1747 -> 15704 | F24: =+E24/90*10 -> 1744.8889 | G24: =+E24+F24 -> 17448.889
A25: Accrued Int. T&EFD 16241 | C25: 1712 | D25: Training | E25: =1749+153-190 -> 1712 | F25: =+E25/90*10 -> 190.22222 | G25: =+E25+F25 -> 1902.2222
A26: Interest on Bank | C26: 28300 | D26: =21630+6670 -> 28300 | G26: 28300
A27: Interest Received FD-13536-MDCC | C27: 7485 | D27: Sinking Fund | E27: =8317-832 -> 7485 | F27: =+E27/90*10 -> 831.66667 | G27: =+E27+F27 -> 8316.6667 | H27: Closed
A28: Interest Received on FD-125944 | C28: 4147 | D28: Common Amenity Fund | E28: =4608-461 -> 4147 | F28: =+E28/90*10 -> 460.77778 | G28: =+E28+F28 -> 4607.7778 | H28: Closed
A29: Interest Received on FD-16373(MDCC) | C29: 3163 | D29: Repair Fund | E29: =3163-316 -> 2847 | F29: =+E29/90*10 -> 316.33333 | G29: =+E29+F29 -> 3163.3333 | H29: Closed
A30: Interest Received on FD - 304939 | C30: 1675 | D30: Reserve Fund | E30: =1861-186 -> 1675 | F30: =+E30/90*10 -> 186.11111 | G30: =+E30+F30 -> 1861.1111 | H30: Closed
A31: Interest Received on FD-414104 | C31: 58 | D31: Repair Fund | E31: =65-7 -> 58 | F31: =+E31/90*10 -> 6.4444444 | G31: =+E31+F31 -> 64.444444
A32: Interest Received on FD-414106 | C32: 349 | D32: Reserve Fund | E32: =387-38 -> 349 | F32: =+E32/90*10 -> 38.777778 | G32: =+E32+F32 -> 387.77778
A33: Interest Received on FD-414103 | C33: 105 | D33: Repair Fund | E33: =116-11 -> 105 | F33: =+E33/90*10 -> 11.666667 | G33: =+E33+F33 -> 116.66667 | H33: Closed
A34: Interest Received on FD-41434 | C34: 1883 | D34: Share Capital | E34: =2092-209 -> 1883 | F34: =+E34/90*10 -> 209.22222 | G34: =+E34+F34 -> 2092.2222
A35: Interest Received on FD-466702 | C35: 2657 | D35: Common Amenity Fund | E35: =2953-296 -> 2657 | F35: =+E35/90*10 -> 295.22222 | G35: =+E35+F35 -> 2952.2222
A36: Interest Received on FD - 563 | C36: 1123 | D36: Repair Fund | E36: =1248-125 -> 1123 | F36: =+E36/90*10 -> 124.77778 | G36: =+E36+F36 -> 1247.7778 | H36: =1248-125 -> 1123
A37: Interest Received on FD - 698962 | C37: 703 | D37: Reserve Fund | E37: =781-78 -> 703 | F37: =+E37/90*10 -> 78.111111 | G37: =+E37+F37 -> 781.11111
A38: Interest Received on FD-TD1001005266 | C38: 2676 | D38: General Prop | E38: =2973-297 -> 2676 | F38: =+E38/90*10 -> 297.33333 | G38: =+E38+F38 -> 2973.3333
A39: Interest Received on RFFD - 400559 | C39: 11249 | D39: Repair Fund | E39: =10878+1622-1089-162 -> 11249 | F39: =+E39/90*10 -> 1249.8889 | G39: =+E39+F39 -> 12498.889 | H39: =10878+1622-1089-162 -> 11249
A40: Interest Received on RFFD - 400560 | C40: 12543 | D40: Repair Fund | E40: =12128+1809-1213-181 -> 12543 | F40: =+E40/90*10 -> 1393.6667 | G40: =+E40+F40 -> 13936.667 | H40: =12128+1809-1213-181 -> 12543
...
