Workbook

Sheet BS
A1: NINAAD CO-OPERATIVE HOUSING SOCIETY LTD.
A2: Link Road, Side of Apna Sahari Bank Ltd., Mith Chowki, Malad West, Mumbai, Maharashtra - 400064
A3: Society Reg No : BOM/HSG/P/8537 of 1981, Dated:22/9/1981
A4: Balance Sheet as at March 31, 2026
A5: March 31, 2025 | B5: LIABILITIES | D5: March 31, 2026 | E5: =A5 -> March 31, 2025 | F5: ASSETS | H5: =D5 -> March 31, 2026
B6: Authorised Share Capital | F6: Cash and Bank Balances:
A7: 100000 | B7: 2000 Shares of ₹ 50/- each | D7: 100000 | E7: 375952.3 | F7: MDCC Bank | G7: =BRS!D14 -> 377615.3
E8: 77796.52 | F8: Apna Sahakari Bank | G8: =BRS!D5 -> 53786.12
B9: Issues, Subscribed and Paid Up | E9: 4191.25 | F9: Cash in Hand | G9: 484.75 | H9: =SUM(G7:G9) -> 431886.17
A10: 12500 | B10: 250 Shares of of ₹ 50/- each | D10: 12500
F11: Investments (Sch I)
B12: Reserves and Surplus (Sch V) | E12: 479845 | F12: Sinking Fund | G12: ='Sch I'!F14 -> 604713
A13: 568444 | B13: Reserve Fund | C13: ='Sch V'!D9 -> 641195 | E13: 1075885 | F13: Repair Fund | G13: ='Sch I'!F25 -> 1442643
A14: 528691.16 | B14: Sinking Fund | C14: ='Sch V'!D15 -> 608367.16 | E14: 460125 | F14: Common Benefit Fund | G14: ='Sch I'!F31 -> 492873
A15: 1239191.2 | B15: Repair and Maintenance Fund | C15: ='Sch V'!D21 -> 1450875.2 | E15: 173551 | F15: Reserve Fund | G15: ='Sch I'!F36 -> 185780 | H15: =SUM(G12:G15) -> 2726009
A16: 610000 | B16: Common Benefit Fund | C16: ='Sch V'!D26 -> 610000
A17: 15474 | B17: Education and Training Fund | C17: ='Sch V'!D31 -> 17754 | D17: =SUM(C13:C17) -> 3328191.4 | E17: 94533601 | F17: Fixed Assets (Sch II) | H17: ='Sch II'!H10 -> 94443212
B19: Current Liabilities: | F19: Deposits:
A20: 11888 | B20: Advance from Members (Sch VI) | C20: ='Sch VI & VII'!D6 -> 5783 | E20: 11720.08 | F20: Security Deposit - Reliance | G20: 11720.08
A21: 91636 | B21: Payables & Provisions (Sch VII) | C21: ='Sch VI & VII'!D29 -> 110361 | D21: =SUM(C20:C21) -> 116144 | E21: 1100 | F21: Security Deposit - BMC | G21: 1100 | H21: =SUM(G20:G21) -> 12820.08
B23: Contribution from Members Towards: | F23: Other Current Assets:
A24: 93912100 | B24: Land and Building | D24: 93912100 | E24: 818505 | F24: Member Receivable (Sch III) | G24: ='Sch III & IV'!D8 -> 845120
E25: 0 | F25: Advance to Vendors (Sweeper) | G25: 2000
E26: 14267 | F26: TDS Receivable - FY 24-25 | G26: 14267
B27: Income and Expenditure Account | E27: 0 | F27: TDS Receivable - FY 25-26 | G27: 16884 | H27: =SUM(G24:G27) -> 878271
A28: 784665.14 | B28: Retained Earnings | C28: =SUM(A28:A30) -> 1071327.7
A29: 15635 | B29: Add: Exp w/off of prior years | C29: 0 | E29: 34713 | F29: Prepaid Expenses (Sch IV) | H29: ='Sch III & IV'!D20 -> 16393
A30: 271027.6 | B30: Surplus/(Deficit) for the year | C30: =IE!D40 -> 68328.1 | D30: =SUM(C28:C30) -> 1139655.8
A31: =SUM(A10:A30) -> 98061252 | B31: Total | D31: =SUM(D10:D30) -> 98508591 | E31: =SUM(E6:E30) -> 98061252 | F31: Total | H31: =SUM(H7:H30) -> 98508591
A33: As per my report of even date | E33: FOR NINAAD CO-OPERATIVE HOUSING SOCIETY LTD.
J35: =D31-H31 -> 0
A37: Shri. Bharat C. Boridkar
A38: Govt. Certified Panel Auditor
A39: [Panel No.: Mumbai-4/C1/1011404] | E39: ( SECRETARY CHAIRMAN TREASURER )
A40: 46262

Sheet IE
A1: =BS!A1 -> NINAAD CO-OPERATIVE HOUSING SOCIETY LTD.
A2: Link Road, Side of Apna Sahari Bank Ltd., Mith Chowki, Malad West, Mumbai, Maharashtra - 400064
A3: Society Reg No : BOM/HSG/P/8537 of 1981, Dated:22/9/1981
A4: Income and Expenditure Account for the year ended March 31, 2026
A5: =BS!A5 -> March 31, 2025 | B5: EXPENDITURE | D5: =BS!D5 -> March 31, 2026 | E5: =A5 -> March 31, 2025 | F5: INCOME | H5: =D5 -> March 31, 2026
F6: Maintenance Income
A7: 186916 | B7: Property Tax | D7: 21458 | E7: 176840 | F7: Property Tax | G7: 21660
E8: 787020 | F8: Service Charges | G8: 787020
A9: 160698 | B9: Electricity Expenses | D9: 185300 | E9: 8729 | F9: Non Occupancy Charges | G9: 9933
E10: 249576 | F10: Parking Charges | G10: =12300+1550 -> 13850
B11: Water Expenses | E11: 113681 | F11: Late Payment Interest | G11: 138514
A12: 37538 | B12: Water Expenses | C12: 47752 | E12: 0 | F12: Penalty | G12: 8000 | H12: =SUM(G7:G12) -> 978977
A13: 0 | B13: Water Expenses - Arrears | C13: 33117
A14: 5500 | B14: Water Tank Cleaning Expense | C14: 0 | D14: =SUM(C12:C14) -> 80869
F15: Interest Income
A16: 151418 | B16: Repair and Maintenance (Sch VIII) | D16: ='Sch VIII'!D16 -> 201292.5 | E16: 456 | F16: Interest Income - IT Refund | H16: 251
E17: 13640 | F17: Interest Income - Savings Account | H17: 15262
B18: Service Charges | E18: 142601 | F18: Interest Income - Fixed Deposit | G18: 168811
A19: 45387 | B19: Salary Expenses | C19: =43900+3500 -> 47400 | E19: -33140 | F19: Less: trf to Reserve Fund | G19: -49975
A20: 227307 | B20: Security Expenses | C20: 216000 | E20: -29146 | F20: Less: trf to Sinking Fund | G20: -36536
A21: 16400 | B21: Insurance Expense | C21: 16405 | E21: -80315 | F21: Less: trf to Repair Fund | G21: -82300 | H21: =SUM(G18:G21) -> 0
A22: 0 | B22: Subscription Federation | C22: 1652
A23: 2000 | B23: Audit Fees | C23: 2500 | F23: Other Income
A24: 16395 | B24: Accounting Charges | C24: 16052 | D24: =SUM(C19:C24) -> 300009 | E24: 6000 | F24: Sale of Scrap | G24: 0 | H24: =SUM(G24:G24) -> 0
B25: Office Expenses
A26: 2714 | B26: Printing and Stationary | C26: 4157
A27: 73 | B27: Postage and Courier | C27: 0
A28: 3770 | B28: Meeting Expense | C28: 1692
A29: 1838 | B29: Conveyance Expense | C29: 3365
A30: 0 | B30: Professional Fees | C30: 3000
A31: 12000 | B31: Election Expenses | C31: 0
A32: 109001 | B32: Depreciation | C32: ='Sch II'!G10 -> 92895
A33: 507.4 | B33: Bank Charges | C33: 507.4
A34: 10384 | B34: Misc. Expenses | C34: =2280+2177+3600+288+495 -> 8840
A35: 336 | B35: Income Tax | C35: -4949
A36: 4390 | B36: Festival Expenses | C36: 4950 | D36: =SUM(C26:C36) -> 114457.4
B38: Excess of Income over Expenditure:
A39: 90342 | B39: 25% trf to Reserve Fund | D39: =ROUND((H41-SUM(D7:D38))*25%,0) -> 22776
A40: 271027.6 | B40: Surplus for the year | D40: =H41-SUM(D6:D39) -> 68328.1
A41: =SUM(A6:A40) -> 1355942 | B41: Total | D41: =SUM(D7:D40) -> 994490 | E41: =SUM(E7:E40) -> 1355942 | F41: Total | H41: =SUM(H6:H40) -> 994490
...

Sheet Sch I
B1: NINAAD CO-OPERATIVE HOUSING SOCIETY LTD.
B2: Sch I: Details of Fixed Deposits as on 31st March 2026
A3: Sr. | B3: Certificate No. | C3: Date | D3: Amount Invested | E3: Accd Int. 25-26 | F3: Total | G3: Maturity Date | H3: Maturity Value | I3: Interest % | J3: Bank | M3: rend int | N3: rend tds | O3: accd int | P3: accd tds | Q3: net int | R3: net tds
B4: Sinking Fund | Q4: =+M4+O4 -> 0 | R4: =+N4+P4 -> 0
A5: 1 | B5: 6605400013062 | C5: 12.11.2025 | D5: 66792 | E5: =1758-175 -> 1583 | F5: =SUM(D5:E5) -> 68375 | G5: 12.11.2026 | H5: 71451 | I5: 0.068 | J5: MDCC | L5: =SUM(E5:E5) -> 1583 | M5: 3080 | N5: 308 | O5: 1758 | P5: 175 | Q5: =+M5+O5 -> 4838 | R5: =+N5+P5 -> 483 | S5: =RIGHT(B5,5) -> 13062
A6: =+A5+1 -> 2 | B6: 6605400012666 | C6: 10.04.2025 | D6: 66286 | E6: =5097-510 -> 4587 | F6: =SUM(D6:E6) -> 70873 | G6: 10.04.2026 | H6: 71539 | I6: 0.077 | J6: MDCC | L6: =SUM(E6:E6) -> 4587 | M6: 136 | N6: 14 | O6: 5097 | P6: 510 | Q6: =+M6+O6 -> 5233 | R6: =+N6+P6 -> 524 | S6: =RIGHT(B6,5) -> 12666
A7: =+A6+1 -> 3 | B7: 6605400013948 | C7: 08.09.2025 | D7: 57554 | E7: =2225-223 -> 2002 | F7: =SUM(D7:E7) -> 59556 | G7: 08.09.2026 | H7: 61569 | I7: 0.068 | J7: MDCC | L7: =SUM(E7:E7) -> 2002 | M7: 1793 | N7: 179 | O7: 2225 | P7: 223 | Q7: =+M7+O7 -> 4018 | R7: =+N7+P7 -> 402 | S7: =RIGHT(B7,5) -> 13948
A8: =+A7+1 -> 4 | B8: 6605400013949 | C8: 08.09.2025 | D8: 95923 | E8: =3709-371 -> 3338 | F8: =SUM(D8:E8) -> 99261 | G8: 08.09.2026 | H8: 102614 | I8: 0.068 | J8: MDCC | L8: =SUM(E8:E8) -> 3338 | M8: 2988 | N8: 299 | O8: 3709 | P8: 371 | Q8: =+M8+O8 -> 6697 | R8: =+N8+P8 -> 670 | S8: =RIGHT(B8,5) -> 13949
A9: =+A8+1 -> 5 | B9: 6605400014147 | C9: 03.03.2026 | D9: 57463 | E9: =303-30 -> 273 | F9: =SUM(D9:E9) -> 57736 | G9: 03.03.2027 | H9: 61381 | I9: 0.0665 | J9: MDCC | L9: =SUM(E9:E9) -> 273 | M9: 3923 | N9: 393 | O9: 303 | P9: 30 | Q9: =+M9+O9 -> 4226 | R9: =+N9+P9 -> 423 | S9: =RIGHT(B9,5) -> 14147
A10: =+A9+1 -> 6 | B10: 6605400014457 | C10: 05.03.2026 | D10: 54691 | E10: =269-27 -> 242 | F10: =SUM(D10:E10) -> 54933 | G10: 05.03.2027 | H10: 58420 | I10: 0.0665 | J10: MDCC | L10: =SUM(E10:E10) -> 242 | M10: 3756 | N10: 375 | O10: 269 | P10: 27 | Q10: =+M10+O10 -> 4025 | R10: =+N10+P10 -> 402 | S10: =RIGHT(B10,5) -> 14457
A11: =+A10+1 -> 7 | B11: 6605400014742 | C11: 10.02.2026 | D11: 52177 | E11: =469-47 -> 422 | F11: =SUM(D11:E11) -> 52599 | G11: 10.02.2027 | H11: 55734 | I11: 0.0665 | J11: MDCC | L11: =SUM(E11:E11) -> 422 | M11: 3353 | N11: 336 | O11: 469 | P11: 47 | Q11: =+M11+O11 -> 3822 | R11: =+N11+P11 -> 383 | S11: =RIGHT(B11,5) -> 14742
A12: =+A11+1 -> 8 | B12: 6605400015331 | C12: 26.03.2026 | D12: 49315 | E12: =53-5 -> 48 | F12: =SUM(D12:E12) -> 49363 | G12: 26.03.2027 | H12: 52677 | I12: 0.0665 | J12: MDCC | L12: =SUM(E12:E12) -> 48 | M12: 3590 | N12: 359 | O12: 53 | P12: 5 | Q12: =+M12+O12 -> 3643 | R12: =+N12+P12 -> 364 | S12: =RIGHT(B12,5) -> 15331
A13: =+A12+1 -> 9 | B13: 6605400016209 | D13: 91986 | E13: =O13-P13 -> 31 | F13: =SUM(D13:E13) -> 92017 | H13: 0 | J13: MDCC | L13: =SUM(E13:E13) -> 31 | M13: 0 | N13: 0 | O13: 34 | P13: 3 | Q13: =+M13+O13 -> 34 | R13: =+N13+P13 -> 3 | S13: =RIGHT(B13,5) -> 16209
D14: =SUM(D5:D13) -> 592187 | E14: =SUM(E5:E13) -> 12526 | F14: =SUM(F5:F13) -> 604713 | H14: =SUM(H5:H13) -> 535385 | L14: 0 | Q14: =+M14+O14 -> 0 | R14: =+N14+P14 -> 0 | S14: =RIGHT(B14,5)
L15: =SUM(E15:E15) -> 0 | Q15: =+M15+O15 -> 0 | R15: =+N15+P15 -> 0 | S15: =RIGHT(B15,5)
B16: Repair Fund | L16: =SUM(E16:E16) -> 0 | Q16: =+M16+O16 -> 0 | R16: =+N16+P16 -> 0 | S16: =RIGHT(B16,5) -> Fund
A17: =+A13+1 -> 10 | B17: 6605300015265 | C17: 12.11.2025 | D17: 200312 | E17: =5277-527 -> 4750 | F17: =SUM(D17:E17) -> 205062 | G17: 12.11.2026 | H17: 214285 | I17: 0.068 | J17: MDCC | L17: =SUM(E17:E17) -> 4750 | M17: 9235 | N17: 924 | O17: 5277 | P17: 527 | Q17: =+M17+O17 -> 14512 | R17: =+N17+P17 -> 1451 | S17: =RIGHT(B17,5) -> 15265
A18: =+A17+1 -> 11 | B18: 6605300015266 | C18: 12.11.2025 | D18: 200312 | E18: =5277-527 -> 4750 | F18: =SUM(D18:E18) -> 205062 | G18: 12.11.2026 | H18: 214285 | I18: 0.068 | J18: MDCC | L18: =SUM(E18:E18) -> 4750 | M18: 9235 | N18: 924 | O18: 5277 | P18: 527 | Q18: =+M18+O18 -> 14512 | R18: =+N18+P18 -> 1451 | S18: =RIGHT(B18,5) -> 15266
A19: =+A18+1 -> 12 | B19: 6605300014655 | C19: 13.04.2025 | D19: 76822 | E19: =5855-586 -> 5269 | F19: =SUM(D19:E19) -> 82091 | G19: 13.04.2026 | H19: 82910 | I19: 0.077 | J19: MDCC | L19: =SUM(E19:E19) -> 5269 | M19: 201 | N19: 20 | O19: 5855 | P19: 586 | Q19: =+M19+O19 -> 6056 | R19: =+N19+P19 -> 606 | S19: =RIGHT(B19,5) -> 14655
A20: =+A19+1 -> 13 | B20: 6605300016491 | C20: 08.09.2025 | D20: 172616 | E20: =6674-668 -> 6006 | F20: =SUM(D20:E20) -> 178622 | G20: 08.09.2026 | H20: 184657 | I20: 0.068 | J20: MDCC | L20: =SUM(E20:E20) -> 6006 | M20: 5376 | N20: 538 | O20: 6674 | P20: 668 | Q20: =+M20+O20 -> 12050 | R20: =+N20+P20 -> 1206 | S20: =RIGHT(B20,5) -> 16491
A21: =+A20+1 -> 14 | B21: 6605300016739 | C21: 03.03.2026 | D21: 172340 | E21: =910-91 -> 819 | F21: =SUM(D21:E21) -> 173159 | G21: 03.03.2027 | H21: 184090 | I21: 0.0665 | J21: MDCC | L21: =SUM(E21:E21) -> 819 | M21: 11765 | N21: 1176 | O21: 910 | P21: 91 | Q21: =+M21+O21 -> 12675 | R21: =+N21+P21 -> 1267 | S21: =RIGHT(B21,5) -> 16739
A22: =+A21+1 -> 15 | B22: 6605400017683 | C22: 08.02.2026 | D22: 156492 | E22: =1465-147 -> 1318 | F22: =SUM(D22:E22) -> 157810 | G22: 08.02.2027 | H22: 156492 | I22: 0.0665 | J22: MDCC | L22: =SUM(E22:E22) -> 1318 | M22: 9993 | N22: 1000 | O22: 1465 | P22: 147 | Q22: =+M22+O22 -> 11458 | R22: =+N22+P22 -> 1147 | S22: =RIGHT(B22,5) -> 17683
A23: =+A22+1 -> 16 | B23: 6605300018486 | C23: 26.03.2026 | D23: 147904 | E23: =161-16 -> 145 | F23: =SUM(D23:E23) -> 148049 | G23: 26.03.2027 | H23: 157988 | I23: 0.0665 | J23: MDCC | L23: =SUM(E23:E23) -> 145 | M23: 10767 | N23: 1077 | O23: 161 | P23: 16 | Q23: =+M23+O23 -> 10928 | R23: =+N23+P23 -> 1093 | S23: =RIGHT(B23,5) -> 18486
A24: =+A23+1 -> 17 | B24: 6605300019862 | C24: 30.03.2026 | D24: 292690 | E24: =O24-P24 -> 98 | F24: =SUM(D24:E24) -> 292788 | H24: 0 | J24: MDCC | L24: =SUM(E24:E24) -> 98 | O24: 109 | P24: 11 | Q24: =+M24+O24 -> 109 | R24: =+N24+P24 -> 11 | S24: =RIGHT(B24,5) -> 19862
D25: =SUM(D17:D24) -> 1419488 | E25: =SUM(E17:E24) -> 23155 | F25: =SUM(F17:F24) -> 1442643 | H25: =SUM(H17:H24) -> 1194707 | L25: 0 | Q25: =+M25+O25 -> 0 | R25: =+N25+P25 -> 0 | S25: =RIGHT(B25,5)
L26: =SUM(E26:E26) -> 0 | Q26: =+M26+O26 -> 0 | R26: =+N26+P26 -> 0 | S26: =RIGHT(B26,5)
B27: Common Benefit Fund | L27: =SUM(E27:E27) -> 0 | Q27: =+M27+O27 -> 0 | R27: =+N27+P27 -> 0 | S27: =RIGHT(B27,5) -> Fund
A28: =+A24+1 -> 18 | B28: 6605300014636 | C28: 10.04.2025 | D28: 153656 | E28: =11817-1182 -> 10635 | F28: =SUM(D28:E28) -> 164291 | G28: 10.04.2026 | H28: 165834 | I28: 0.077 | J28: MDCC | L28: =SUM(E28:E28) -> 10635 | M28: 312 | N28: 31 | O28: 11817 | P28: 1182 | Q28: =+M28+O28 -> 12129 | R28: =+N28+P28 -> 1213 | S28: =RIGHT(B28,5) -> 14636
A29: =+A28+1 -> 19 | B29: 6605300014637 | C29: 10.04.2025 | D29: 153656 | E29: =11817-1182 -> 10635 | F29: =SUM(D29:E29) -> 164291 | J29: MDCC | L29: =SUM(E29:E29) -> 10635 | M29: 312 | N29: 31 | O29: 11817 | P29: 1182 | Q29: =+M29+O29 -> 12129 | R29: =+N29+P29 -> 1213 | S29: =RIGHT(B29,5) -> 14637
A30: =+A29+1 -> 20 | B30: 6605300014639 | C30: 10.04.2025 | D30: 153656 | E30: =11817-1182 -> 10635 | F30: =SUM(D30:E30) -> 164291 | G30: 10.04.2026 | H30: 165834 | I30: 0.077 | J30: MDCC | L30: =SUM(E30:E30) -> 10635 | M30: 312 | N30: 31 | O30: 11817 | P30: 1182 | Q30: =+M30+O30 -> 12129 | R30: =+N30+P30 -> 1213 | S30: =RIGHT(B30,5) -> 14639
D31: =SUM(D28:D30) -> 460968 | E31: =SUM(E28:E30) -> 31905 | F31: =SUM(F28:F30) -> 492873 | H31: =SUM(H28:H30) -> 331668 | L31: =SUM(E31:E31) -> 31905 | Q31: =+M31+O31 -> 0 | R31: =+N31+P31 -> 0 | S31: =RIGHT(B31,5)
L32: =SUM(E32:E32) -> 0 | Q32: =+M32+O32 -> 0 | R32: =+N32+P32 -> 0 | S32: =RIGHT(B32,5)
B33: General Reserve Fund | L33: =SUM(E33:E33) -> 0 | Q33: =+M33+O33 -> 0 | R33: =+N33+P33 -> 0 | S33: =RIGHT(B33,5) -> Fund
A34: =+A30+1 -> 21 | B34: 006605400015714 | C34: 28.02.2026 | D34: 46216 | E34: =264-26 -> 238 | F34: =SUM(D34:E34) -> 46454 | G34: 28.02.2027 | H34: 49367 | I34: 0.0665 | J34: MDCC | L34: =SUM(E34:E34) -> 238 | M34: 3134 | N34: 314 | O34: 264 | P34: 26 | Q34: =+M34+O34 -> 3398 | R34: =+N34+P34 -> 340 | S34: =RIGHT(B34,5) -> 15714
A35: =+A34+1 -> 22 | B35: 006605300019095 | C35: 28.02.2026 | D35: 138612 | E35: =793-79 -> 714 | F35: =SUM(D35:E35) -> 139326 | G35: 28.02.2027 | H35: 148062 | I35: 0.0665 | J35: MDCC | L35: =SUM(E35:E35) -> 714 | M35: 9397 | N35: 940 | O35: 793 | P35: 79 | Q35: =+M35+O35 -> 10190 | R35: =+N35+P35 -> 1019 | S35: =RIGHT(B35,5) -> 19095
D36: =SUM(D34:D35) -> 184828 | E36: =SUM(E34:E35) -> 952 | F36: =SUM(F34:F35) -> 185780 | H36: =SUM(H34:H35) -> 197429 | L36: =SUM(E36:E36) -> 952
B39: Grand Total | D39: =D14+D25+D31+D36 -> 2657471 | E39: =E14+E25+E31+E36 -> 68538 | F39: =F14+F25+F31+F36 -> 2726009 | H39: =H14+H25+H31+H36 -> 2259189 | M39: =SUM(M4:M38) -> 92658 | N39: =SUM(N4:N38) -> 9269 | O39: =SUM(O4:O38) -> 76153 | P39: =SUM(P4:P38) -> 7615 | Q39: =SUM(Q4:Q38) -> 168811 | R39: =SUM(R4:R38) -> 16884
E41: =SUM(E39:E39) -> 68538
E42: =+O39-P39 -> 68538

Sheet Sch II
A1: NINAAD CO-OPERATIVE HOUSING SOCIETY LTD.
A2: Sch II: Details of Fixed Assets as on 31st March 20296
A3: Particulars | B3: Rate % | C3: Opening W.D.V. as of 01.04.2025 | D3: Additions during the year before 30.09.2025 | E3: Additions during the year after 30.09.2025 | F3: Gross Block (at cost) as on 31.03.2026 | G3: Depreciation for the year | H3: Closing W.D.V. as of 31.03.2026
A4: Land & Building | B4: 0 | C4: 93912100 | D4: 0 | E4: 0 | F4: =C4+D4+E4 -> 93912100 | G4: =ROUND((SUM(C4:D4)*B4)+E4*B4/2,) -> 0 | H4: =F4-G4 -> 93912100
A5: CCTV | B5: 0.15 | C5: 49616 | D5: 0 | E5: 2506 | F5: =C5+D5+E5 -> 52122 | G5: =ROUND((SUM(C5:D5)*B5)+E5*B5/2,) -> 7630 | H5: =F5-G5 -> 44492
A6: Fan | B6: 0.15 | C6: 1238 | D6: 0 | E6: 0 | F6: =C6+D6+E6 -> 1238 | G6: =ROUND((SUM(C6:D6)*B6)+E6*B6/2,) -> 186 | H6: =F6-G6 -> 1052
A7: Furniture | B7: 0.1 | C7: 10354 | D7: 0 | E7: 0 | F7: =C7+D7+E7 -> 10354 | G7: =ROUND((SUM(C7:D7)*B7)+E7*B7/2,) -> 1035 | H7: =F7-G7 -> 9319
A8: Intercom | B8: 0.15 | C8: 9918 | D8: 0 | E8: 0 | F8: =C8+D8+E8 -> 9918 | G8: =ROUND((SUM(C8:D8)*B8)+E8*B8/2,) -> 1488 | H8: =F8-G8 -> 8430
A9: Stack Parking | B9: 0.15 | C9: 550375 | D9: 0 | F9: =C9+D9+E9 -> 550375 | G9: =ROUND((SUM(C9:D9)*B9)+E9*B9/2,) -> 82556 | H9: =F9-G9 -> 467819
A10: Total | C10: =SUM(C4:C9) -> 94533601 | D10: =SUM(D4:D9) -> 0 | E10: =SUM(E4:E9) -> 2506 | F10: =SUM(F4:F9) -> 94536107 | G10: =SUM(G4:G9) -> 92895 | H10: =SUM(H4:H9) -> 94443212

Sheet Sch III & IV
A1: NINAAD CO-OPERATIVE HOUSING SOCIETY LTD.
A2: Sch III: Member Receivable as on 31.03.2026
A3: Sl.No | B3: Flat | C3: Name | D3: Amount
A4: 1 | B4: 00G1 | C4: MR. MANOJ SAMANI | D4: 153355
A5: 2 | B5: 2 | C5: MR. SANJAY SAMANI | D5: 77853
A6: 3 | B6: 202 | C6: MS. ALICIA FERNANDES | D6: 8342
A7: 4 | B7: 1001 | C7: MR. TEJAS RAJA | D7: 605570
B8: Total | D8: =SUM(D4:D7) -> 845120
B12: NINAAD CO-OPERATIVE HOUSING SOCIETY LTD.
B13: Sch IV: Prepaid Expense as on 31.03.2026
B14: FY 2024-25 | C14: Particulars | D14: FY 2025-26
B15: 0 | C15: Pest Control | D15: 1800
B16: 18248 | C16: Insurance | D16: 1843
B17: 0 | C17: Lift AMC | D17: 6000
B18: 7818 | C18: Fire Fighting AMC | D18: =Workings!E21 -> 6750
B19: 8647 | C19: CCTV AMC | D19: 0
B20: =SUM(B15:B19) -> 34713 | C20: Total | D20: =SUM(D15:D19) -> 16393

Sheet Sch V
B1: NINAAD CO-OPERATIVE HOUSING SOCIETY LTD.
B2: Sch V : Reserve and Surplus
B3: FY 2024-25 | C3: Particulars | D3: FY 2025-26
C4: Reserve Fund
B5: 418662 | C5: As per last balance sheet | D5: =B9 -> 568444
B6: 26300 | C6: Add: Collections during the year | D6: 0
B7: 33140 | C7: Add: Interest earned during the year | D7: =-IE!G19 -> 49975
B8: 90342 | C8: Add: 25% Surplus trf from I&E Account | D8: =IE!D39 -> 22776
B9: =SUM(B5:B8) -> 568444 | C9: Total | D9: =SUM(D5:D8) -> 641195
C11: Sinking Fund
B12: 456405.16 | C12: As per last balance sheet | D12: =B15 -> 528691.16
B13: 43140 | C13: Add: Collections during the year | D13: 43140
B14: 29146 | C14: Add: Interest earned during the year | D14: =-IE!G20 -> 36536
B15: =SUM(B12:B14) -> 528691.16 | C15: Total | D15: =SUM(D12:D14) -> 608367.16
C17: Repair and Maintenance Fund
B18: 1029492.2 | C18: As per last balance sheet | D18: =B21 -> 1239191.2
B19: 129384 | C19: Add: Collections during the year | D19: 129384
B20: 80315 | C20: Add: Interest earned during the year | D20: =-IE!G21 -> 82300
B21: =SUM(B18:B20) -> 1239191.2 | C21: Total | D21: =SUM(D18:D20) -> 1450875.2
C23: Common Benefit Fund
B24: 500000 | C24: Corpus Fund | D24: 500000
B25: 110000 | C25: Donation Fund | D25: 110000
B26: =SUM(B24:B25) -> 610000 | C26: Total | D26: =SUM(D24:D25) -> 610000
C28: Education and Training Fund
B29: 13194 | C29: As per last balance sheet | D29: =B31 -> 15474
B30: 2280 | C30: Add: Collections during the year | D30: 2280
B31: =SUM(B29:B30) -> 15474 | C31: Total | D31: =SUM(D29:D30) -> 17754

Sheet Sch VIII
B1: NINAAD CO-OPERATIVE HOUSING SOCIETY LTD.
B2: Sch VIII : Repair and Maintenance Expenses
B3: FY 2024-25 | C3: Particulars | D3: FY 2025-26
B4: 5900 | C4: Electrical Repair Maintenance | D4: 16840
B5: 19840 | C5: Other Repair Maintenance | D5: 25002.5
B6: 12605 | C6: Plumbing Repair Maintenance | D6: 0
B7: 5200 | C7: CCTV Repair Maintenance | D7: 3000
B8: 11009 | C8: Fire Fighting Repair Maintenance | D8: 21600
B9: 5450 | C9: Lift Repair and Maintenance | D9: 25000
B10: 52000 | C10: Lift AMC | D10: 62000
B11: 2156 | C11: Intercom AMC | D11: 0
B12: 4790 | C12: CCTV AMC | D12: 8647
B13: 21668 | C13: Fire Fighting AMC | D13: 30203
B14: 10800 | C14: Pest Control Expenses | D14: 9000
B15: 0 | C15: Garden Maintenance Expense | D15: 0
B16: =SUM(B4:B15) -> 151418 | C16: Total | D16: =SUM(D4:D15) -> 201292.5

Sheet Sch VI & VII
A1: NINAAD CO-OPERATIVE HOUSING SOCIETY LTD.
A2: Sch VI: Advance from Members as on 31.03.2026
A3: Sl.No | B3: Flat | C3: Name | D3: Amount
A4: 1 | B4: 601 | C4: MR. RAJESH K. SINHA | D4: 229
A5: 2 | B5: 602 | C5: MRS. JACINTHA LOBO | D5: 5554
B6: Total | D6: =SUM(D4:D5) -> 5783
B10: NINAAD CO-OPERATIVE HOUSING SOCIETY LTD.
B11: Sch VII: Payables and Provisions as on 31.03.2026
B12: Sl.No | C12: Payables | D12: Amount
B13: 1 | C13: BMC | D13: 46111
B14: 2 | C14: Deepa Fire Service | D14: 2385
B15: 3 | C15: Irene Rosario | D15: 343
B16: 4 | C16: MDCHFL | D16: 826
B17: 5 | C17: Sweeper | D17: 2000
B18: 6 | C18: Mintu Kumar Singh | D18: 11307
B19: 7 | C19: Roshan Security Services | D19: 18000
B20: Total (A) | D20: =SUM(D13:D19) -> 80972
B22: Sl.No | C22: Provisions | D22: Amount
B23: 1 | C23: Water Charges Payable | D23: 6719
B24: 2 | C24: Electricity Charges Payable | D24: 14470
B25: 3 | C25: Audit Fees Payable | D25: 6000
B26: 4 | C26: Income Tax Payable | D26: 2200
B27: Total (B) | D27: =SUM(D23:D26) -> 29389
C29: Total A+B | D29: =D20+D27 -> 110361

Sheet BRS
A2: NINAAD CO-OPERATIVE HOUSING SOCIETY LIMITED
A3: Apna Sahakari Bank Reconciliation Statement as on 31st March 2026 | G3: Date | H3: Inflow | I3: Outflow | J3: Intr. No. | K3: Remarks | L3: Reconciled Date
D4: Amount | G4: 29.03.2026 | I4: 1600 | J4: 100512 | K4: Irene Rosario | L4: 30.04.2026
B5: Balance as per System | D5: 53786.12
A7: Add: | B7: Cheque issued but not cleared | D7: =I4 -> 1600
B8: Balance as per Bank Statement | D8: =D5+D7 -> 55386.12
A11: NINAAD CO-OPERATIVE HOUSING SOCIETY LIMITED
A12: MDCC Bank Reconciliation Statement as on 31st March 2026
D13: Amount
B14: Balance as per System | D14: 377615.3
A16: Add: | B16: Cheque issued but not cleared
B17: Balance as per Bank Statement | D17: =D14+D16 -> 377615.3

Sheet Workings
B2: Note: Workings Page is not the be printed
B4: Water Charges
B5: 45695 | C5: 46059 | D5: =C5-B5 -> 364 | E5: 46143
B6: =C5 -> 46059 | C6: 46112 | D6: =C6-B6 -> 53 | E6: =ROUND(E5*D6/D5,0) -> 6719 | F6: Provision
B9: CCTV AMC
B10: 45646 | C10: 46010 | D10: =+C10-B10+1 -> 365 | E10: 12000
B11: 45748 | C11: 46010 | D11: =+C11-B11+1 -> 263 | E11: =ROUND(E10*D11/D10,0) -> 8647 | F11: prepaid
B13: Insurance
B14: 45748 | C14: 46153 | D14: =+C14-B14+1 -> 406 | E14: 18248
B15: 46113 | C15: 46153 | D15: =+C15-B15+1 -> 41 | E15: =ROUND(E14*D15/D14,0) -> 1843 | F15: prepaid
B18: Fire Fighting AMC
B19: 46023 | C19: 46203 | D19: 6 | E19: 13500
B20: 46023 | C20: 46112 | D20: 3 | E20: =ROUND(E19*D20/D19,0) -> 6750
E21: =E19-E20 -> 6750 | F21: prepaid
B23: Lift Amc
B24: 46054 | C24: 46113 | D24: 3 | E24: 18000
B25: 46113 | C25: 46113 | D25: =C25-B25+1 -> 1 | E25: =ROUND(E24*D25/D24,0) -> 6000 | F25: prepaid
I32: to pass depre in system
I33: to pass int trf entries in system
I34: to pass inc.tax entry
