Workbook

Sheet BS
A1: HELENA VILLA CO-OPERATIVE HOUSING SOCIETY LIMITED
A2: (Regd. No MUM/WP/HSG/TC/12195 DATED 19-09-2003)
A4: BALANCE SHEET AS ON 31ST MARCH 2024
H5: (Amt. in Rs.)
A6: Previous Year | B6: LIABILITIES | D6: Current Year | E6: Previous Year | F6: ASSETS | H6: Current Year
A7: 2022-23 | D7: 2023-24 | E7: =A7 -> 2022-23 | H7: =D7 -> 2023-24
B8: Authorised Share Capital | F8: Cash & Bank Balance
A9: 1500000 | B9: (30000 Shares of Rs. 50 each) | D9: 1500000 | E9: 149 | F9: Cash in hand | G9: 150
E10: 22096.53 | F10: Citizen Credit Bank | G10: 21076.85
B11: Issued, Subscribed and Paid Up Share Capital | E11: 2226 | F11: MDCC Bank | G11: 2363 | H11: =SUM(G9:G11) -> 23589.85
A12: 3500 | B12: (70 shares of Rs. 50/- each ) | D12: 3500
F13: Deposits
A14: 1483590 | B14: Gen. Reserve and Surplus Fund - (Sch III) | D14: ='Sch III - R&S'!D35 -> 608474 | E14: 1894.88 | F14: Security Deposit with Adani | H14: 1894.88
B16: New Water Pipeline Fund | F16: Investments
A17: 6663 | B17: As per last Balance Sheet | C17: =A17+A18 -> 5664 | E17: 1000 | F17: Share with MDCC | G17: 1000
A18: -999 | B18: Less: Depreciation 15% | C18: -850 | D18: =SUM(C17:C18) -> 4814 | E18: 100 | F18: 1 share of MDHF | G18: 100
E19: 1474404 | F19: Fixed Deposits - (Sch I) | G19: ='Sch I - FD'!C21 -> 853701
B20: Lift Upgradation Fund | E20: 320920 | F20: Accrued Interest - (Sch I) | G20: ='Sch I - FD'!D21 -> 5334 | H20: =SUM(G17:G20) -> 860135
A21: 190300 | B21: As per last Balance Sheet | C21: =A21+A22 -> 161755
A22: -28545 | B22: Less: Depreciation 15% | C22: =-'Sch II - FA'!G12 -> -24263 | D22: =SUM(C21:C22) -> 137492 | E22: 204682 | F22: Fixed Assets - (Sch II) | H22: ='Sch II - FA'!H13 -> 174208
B24: Current Liabilities & Provisions : | F24: Other Current Assets:
A25: 2000 | B25: Audit Fees | C25: 4000 | E25: =6954+8859+9093 -> 24906 | F25: TDS Receivables | H25: 5407
A26: 3735 | B26: Electricity Charges | C26: 3381.23
A27: 0 | B27: Professional Fees | C27: 3000 | F27: Prepaid Expenses:
A28: 0 | B28: Income tax | C28: 1160 | E28: 950 | F28: Pest Control | G28: 967
A29: 2489 | B29: Water Charges | C29: 2475 | D29: =SUM(C25:C29) -> 14016.23 | E29: 19470 | F29: Lift AMC | G29: 19470
E30: 5841 | F30: CCTV AMC | G30: 5841
A31: 35314 | B31: Advance from Members - (Sch IV) | D31: ='Sch IV - Mem. Adv'!D8 -> 25905 | E31: 3894 | F31: Intercom AMC | G31: 3894
E32: 6846 | F32: Building Insurance Charges | G32: 6827 | H32: =SUM(G28:G32) -> 36999
A33: 0 | B33: Retention Sejal Construction | D33: 80300
B35: Income & Expenditure Account
A36: 382413.15 | B36: As per last Balance Sheet | C36: =A36+A37 -> 391332.41
A37: 8919.26 | B37: Less: Excess of Expenditure over Income | C37: =IE!H30 -> 163599.91 | D37: =C36-C37 -> 227732.5 | J37: =A39-E39 -> 0
A39: =SUM(A12:A37) -> 2089379.4 | B39: Total | D39: =SUM(D11:D37) -> 1102233.7 | E39: =SUM(E8:E37) -> 2089379.4 | F39: Total | H39: =SUM(H9:H37) -> 1102233.7 | I39: =D39-H39 -> 0
A41: As per my report of even date | E41: For HELENA VILLA CO-OP. HOUSING SOCIETY LTD.
A45: (Shankar D. Gawde)
A46: Govt. Certified Auditor - Panel No. 14428 | E46: Chairman | F46: Secretary | G46: Treasurer
A47: Place : Mumbai
A48: Date : 12.07.2024

Sheet IE
A1: HELENA VILLA CO-OPERATIVE HOUSING SOCIETY LIMITED
A2: (Regd. No MUM/WP/HSG/TC/12195 DATED 19-09-2003)
A4: INCOME & EXPENDITURE ACCOUNT FOR THE YEAR ENDED 31ST MARCH 2024
H5: (Amt. in Rs.)
A6: Previous Year | B6: EXPENDITURE | D6: Current Year | E6: Previous Year | F6: INCOME | H6: Current Year
A7: 2022-23 | D7: 2023-24 | E7: =A7 -> 2022-23 | H7: =D7 -> 2023-24
F8: Members Contribution Towards
A9: 154710 | B9: Property Tax | D9: 154710 | E9: 172104 | F9: Property Tax | G9: =161244+4704 -> 165948
E10: 5040 | F10: Garage Tax | G10: 0
A11: 30698 | B11: Water Expenses | D11: 36517 | E11: 390600 | F11: Maintenance Charges | G11: 413280
E12: 2400 | F12: Parking Charges | G12: 3600
A13: 23352 | B13: Building Insurance | D13: 23371 | E13: 147 | F13: Late Payment Interest | G13: 16
E14: 14000 | F14: Non Occupancy Charges | G14: 13750 | H14: =SUM(G9:G14) -> 596594
A15: 44590.62 | B15: Electricity Charges | D15: 43048.61
F16: Interest Income
A17: ='Sch V -R&M'!A12 -> 82560 | B17: Repair & Maintenance - (Sch V) | D17: ='Sch V -R&M'!C12 -> 181194 | E17: 4002 | F17: Interest on Saving A/C | H17: 8631
E18: 71484 | F18: Interest on Fixed Deposits | G18: 67191
B19: Service Charges | E19: 0 | F19: Less: Trfd to Painting Fund | G19: -15571
A20: 2000 | B20: Audit Fees | C20: 2000 | E20: 0 | F20: Less: Trfd to Sinking Fund | G20: -15737 | H20: =SUM(G18:G20) -> 35883
A21: 24038 | B21: Salaries | C21: 24252
A22: 0 | B22: Bonus | C22: 12335.5 | E22: 154.88 | F22: Interest on Security Deposit | G22: 0
A23: 251501 | B23: Security Charges | C23: 253200 | E23: 0 | F23: Interest on IT refund | G23: 646 | H23: =SUM(G22:G23) -> 646
A24: 826 | B24: Subscription Charges | C24: 826
A25: 6277 | B25: Depreciation | C25: ='Sch II - FA'!G16 -> 5361 | F25: Other Income
A26: 18712 | B26: Accounting Charges | C26: 18000 | E26: 0 | F26: Sale of Scrap | G26: 1100
A27: 2000 | B27: Professional Fees | C27: =18000+3000 -> 21000 | E27: 0 | F27: Dividend | G27: 51 | H27: =SUM(G26:G27) -> 1151
A28: 993 | B28: Miscellaneous Expense | C28: 2699
A29: 0 | B29: Bank Charges | C29: 70.8
A30: 1032 | B30: Printing and Stationery | C30: 1370 | F30: By Excess of Expenditure over Income | H30: 163599.91
A31: 0 | B31: Income tax Expense | C31: =9607+1160 -> 10767
A32: 4750 | B32: Pest Control Expense | C32: 15783 | D32: =SUM(C20:C32) -> 367664.3
A34: 0 | B34: Major Repair Expenses | C34: 888140
A35: 0 | B35: Less : Trfd to liability | C35: ='Sch III - R&S'!D27-348864 -> -888140 | D35: =SUM(C34:C35) -> 0
A37: 2973 | B37: 25% of Surplus trfd to Reserves
A38: 8919.26 | B38: Excess of Expenditure over Income | D38: =H40-SUM(D8:D37) -> 0
I39: =D40-H40 -> 0 | J39: 41037
A40: =SUM(A8:A38) -> 659931.88 | B40: Total | D40: =SUM(D8:D38) -> 806504.91 | E40: =SUM(E8:E29) -> 659931.88 | F40: Total | H40: =SUM(H9:H38) -> 806504.91
A42: As per my report of even date | E42: For HELENA VILLA CO-OP HOUSING SOCIETY LTD.
J43: 5
A46: =BS!A45 -> (Shankar D. Gawde)
...

Sheet Sch I - FD
A1: Helena Villa C.H.S. Ltd.
A3: Schedule I : Details of Fixed Deposits as on 31st March 2024
H4: (Amt in Rs.)
A5: FDR No. | B5: Date | C5: Amount Invested | D5: Accrued Int. 2023-24 | E5: Total | F5: Maturity Date | G5: Maturity Value | H5: Interest % | I5: Bank
A6: Sinking Fund
A7: 15320 | B7: 22.03.2024 | C7: 8368 | D7: 18 | E7: =SUM(C7:D7) -> 8386 | F7: 22.03.2026 | G7: 9756 | H7: 7.75 | I7: MDCC
A8: 15318 | B8: 22.03.2024 | C8: 256718 | D8: 545 | E8: =SUM(C8:D8) -> 257263 | F8: 22.03.2026 | G8: 299315 | H8: 7.75 | I8: MDCC
A9: 3542476 | B9: 17.03.2024 | C9: 38615 | D9: =107-10 -> 97 | E9: =SUM(C9:D9) -> 38712 | I9: CCB
A10: Total | C10: =SUM(C7:C9) -> 303701 | D10: =SUM(D7:D9) -> 660 | E10: =SUM(E7:E9) -> 304361 | G10: =SUM(G7:G9) -> 309071
A12: General Fund
A13: 1003921 | B13: 12.02.2024 | C13: 100000 | D13: =982-71 -> 911 | E13: =SUM(C13:D13) -> 100911 | I13: CCB
A14: 1003938 | B14: 12.02.2024 | C14: 100000 | D14: =982-71 -> 911 | E14: =SUM(C14:D14) -> 100911 | I14: CCB
A15: 1003941 | B15: 12.02.2024 | C15: 100000 | D15: =982-71 -> 911 | E15: =SUM(C15:D15) -> 100911 | I15: CCB
A16: 1003957 | B16: 12.02.2024 | C16: 100000 | D16: =982-71 -> 911 | E16: =SUM(C16:D16) -> 100911 | I16: CCB
A17: 1003962 | B17: 12.02.2024 | C17: 100000 | D17: =982-71 -> 911 | E17: =SUM(C17:D17) -> 100911 | I17: CCB
A18: 1004194 | B18: 18.03.2024 | C18: 50000 | D18: =129-10 -> 119 | E18: =SUM(C18:D18) -> 50119 | I18: CCB
A19: Total | C19: =SUM(C13:C18) -> 550000 | D19: =SUM(D13:D18) -> 4674 | E19: =SUM(E13:E18) -> 554674 | G19: =SUM(G13:G18) -> 0
A21: Grand Total | C21: =+C10+C19 -> 853701 | D21: =+D10+D19 -> 5334 | E21: =+E10+E19 -> 859035 | G21: =+G10+G19 -> 309071

Sheet Sch II - FA
A2: Helena Villa CHS Ltd
A4: Sch II -Fixed Assets as on 31st March 2024
A6: Particulars | B6: Rate % | C6: Opening W.D.V. as on 01.04.2023 | D6: Additions during the year before 30.09.2023 | E6: Additions during the year after 30.09.2023 | F6: Gross Block (at cost) as on 31.03.2024 | G6: Depreciation for the year | H6: Closing W.D.V. as on 31.03.2024
A7: Letter Box | B7: 0.1 | C7: 3951 | D7: 0 | E7: 0 | F7: =C7+D7+E7 -> 3951 | G7: =ROUND(((D7+C7)*B7)+(E7*B7)/2,0) -> 395 | H7: =F7-G7 -> 3556
A8: Cupboard | B8: 0.1 | C8: 613 | D8: 0 | E8: 0 | F8: =C8+D8+E8 -> 613 | G8: =ROUND(((D8+C8)*B8)+(E8*B8)/2,0) -> 61 | H8: =F8-G8 -> 552
A9: Intercom | B9: 0.15 | C9: 7901 | D9: 0 | E9: 0 | F9: =C9+D9+E9 -> 7901 | G9: =ROUND(((D9+C9)*B9)+(E9*B9)/2,0) -> 1185 | H9: =F9-G9 -> 6716
A10: CCTV | B10: 0.15 | C10: 24798 | D10: 0 | E10: 0 | F10: =C10+D10+E10 -> 24798 | G10: =ROUND(((D10+C10)*B10)+(E10*B10)/2,0) -> 3720 | H10: =F10-G10 -> 21078
A11: Water pipe Enlargement | B11: 0.15 | C11: 5664 | D11: 0 | E11: 0 | F11: =C11+D11+E11 -> 5664 | G11: =ROUND(((D11+C11)*B11)+(E11*B11)/2,0) -> 850 | H11: =F11-G11 -> 4814
A12: Lift | B12: 0.15 | C12: 161755 | D12: 0 | E12: 0 | F12: =C12+D12+E12 -> 161755 | G12: =ROUND(((D12+C12)*B12)+(E12*B12)/2,0) -> 24263 | H12: =F12-G12 -> 137492
A13: Total | C13: =SUM(C7:C12) -> 204682 | D13: =SUM(D7:D12) -> 0 | E13: =SUM(E7:E12) -> 0 | F13: =SUM(F7:F12) -> 204682 | G13: =SUM(G7:G12) -> 30474 | H13: =SUM(H7:H12) -> 174208
G14: =-G11 -> -850 | H14: Less trfd to fund
G15: =-G12 -> -24263 | H15: Less trfd to fund
G16: =G13+G14+G15 -> 5361 | H16: Total Depreciation for FY 23-24

Sheet Sch III - R&S
B1: Helena Villa C.H.S. Ltd
B3: Schedule - III Reserve and Surplus Fund as on 31st March 2024
B5: FY 2022-23 | C5: General Fund | D5: FY 2023-24
B6: 297472 | C6: As per Last year Balance Sheet | D6: =B9 -> 300445
B7: 0 | C7: Add: Addition during the year | D7: 100
B8: 2973 | C8: Add: 25% of Surplus
B9: =SUM(B6:B8) -> 300445 | C9: Total (a) | D9: =SUM(D6:D8) -> 300545
C11: Sinking Fund
B12: 261677 | C12: As per last year Balance Sheet | D12: =B15 -> 282196
B13: 6636 | C13: Add: Addition during the year | D13: 6636
B14: 13883 | C14: Add: Interest on FD earned/accrued | D14: 15737
B15: =SUM(B11:B14) -> 282196 | C15: Total (b) | D15: =SUM(D11:D14) -> 304569
C17: Repair & Maintenance Fund
B18: 367080 | C18: As per last Balance Sheet | D18: =B21 -> 403788
B19: 36708 | C19: Add: Addition during the year | D19: 36708
C20: Less: Major Repair Expense | D20: =-348864-91632 -> -440496
B21: =SUM(B16:B19) -> 403788 | C21: Total (c) | D21: =SUM(D17:D20) -> 0
C23: Repairs & Painting Fund
B24: 448459 | C24: As per last Balance Sheet | D24: =B28 -> 495481
B25: 28224 | C25: Add: Addition during the year | D25: 28224
B26: 18798 | C26: Add: Interest on FD earned/accrued | D26: 15571
B27: 0 | C27: Less: Major Repair Expense | D27: -539276
B28: =SUM(B23:B27) -> 495481 | C28: Total (d) | D28: =SUM(D23:D27) -> 0
C30: Education & Training Fund
B31: 0 | C31: As per last Balance Sheet | D31: =B33 -> 1680
B32: 1680 | C32: Add: Addition during the year | D32: 1680
B33: =SUM(B29:B32) -> 1680 | C33: Total (e) | D33: =SUM(D29:D32) -> 3360
B35: =B9+B15+B21+B28+B33 -> 1483590 | C35: Total (a+b+c+d+e) | D35: =D9+D15+D21+D28+D33 -> 608474
B38: Schedule IV -Members Advance as on 31st March 2024
B40: Flat No. | C40: Member's Name | D40: Amount (Rs.)
B41: 102 | C41: MR. ERIC LEWIS & MR.MAXIE LEWIS | D41: 949
B42: 301 | C42: MR. PAUL J. D'SOUZA & MRS. VIRGINIA M. D'SOUZA | D42: 42
B43: 501 | C43: MR. MALCOLM J. FERNANDES | D43: 7952
B44: 702 | C44: MR. JIBU VARGHESE THETHAYIL | D44: 16962
B45: Total | D45: =SUM(D41:D44) -> 25905
B48: Schedule V - Repair and Maintenance Expenses
B50: FY 22-23 | C50: Particulars | D50: FY 23-24
B51: 23200 | C51: R&M - Others | D51: =179666-91632 -> 88034
B52: 2465 | C52: R&M - Electrical | D52: 54220
B53: 8182 | C53: R&M - Water Pump | D53: 0
...

Sheet Sch IV - Mem. Adv
A1: Helena Villa CHS Ltd
A2: Schedule IV -Members Advance as on 31st March 2024
A3: Sl.No | B3: Flat No. | C3: Member's Names | D3: Amount
A4: 1 | B4: 102 | C4: MR. ERIC LEWIS & MR.MAXIE LEWIS | D4: 949
A5: 2 | B5: 301 | C5: MR. PAUL J. D'SOUZA & MRS. VIRGINIA M. D'SOUZA | D5: 42
A6: 3 | B6: 501 | C6: MR. MALCOLM J. FERNANDES | D6: 7952
A7: 4 | B7: 702 | C7: MR. JIBU VARGHESE THETHAYIL | D7: 16962
A8: Total | D8: =SUM(D4:D7) -> 25905

Sheet Sch V -R&M
A1: Helena Villa Chs Ltd
A2: Schedule V - Repair and Maintenance Expense
A3: FY 22-23 | B3: Particulars | C3: FY 23-24
A4: 23200 | B4: R&M - Others | C4: =179666-91632 -> 88034
A5: 2465 | B5: R&M - Electrical | C5: 54220
A6: 8182 | B6: R&M - Water Pump | C6: 0
A7: 6500 | B7: R&M - Garden | C7: 0
A8: 25518 | B8: AMC - Lift | C8: 25960
A9: 4838 | B9: AMC - Intercom | C9: 5192
A10: 7257 | B10: AMC - CCTV | C10: 7788
A11: 4600 | B11: Water Tank Cleaning Charges | C11: 0
A12: =SUM(A4:A11) -> 82560 | B12: Total | C12: =SUM(C4:C11) -> 181194

Sheet BRS
A2: Helena Villa CHS Ltd.
A3: Citizen Credit Bank reconciliation statement as on 31st March 2024 | E3: Date | F3: Amount | G3: Chq no | H3: Comment | I3: Cleared on
B4: Amount | E4: 31.03.2024 | F4: 2071 | G4: 955166 | H4: Sweeper salary | I4: 15.04.2024
A5: Balance as per System | B5: 21076.85 | E5: 31.03.2024 | F5: 10357 | G5: 955165 | H5: Gangadhar | I5: 02.04.2024
A6: Add: Cheques issued but not cleared as on 31.03.24 | B6: =F7 -> 23671 | E6: 31.03.2024 | F6: 11243 | G6: 955164 | H6: Sumanji | I6: 02.04.2024
F7: =SUM(F4:F6) -> 23671
A8: Balance as per Pass Book | B8: 44747.85
B9: =B5+B6-B8 -> 0
A11: Helena Villa CHS Ltd.
A12: MDCC Bank reconciliation statement as on 31st March 2024
B13: Amount
A14: Balance as per System | B14: 2363
A16: Balance as per Pass Book | B16: 2363
B17: =B14-B16 -> 0

Sheet Workings
A2: Water | B2: Period | D2: Days | E2: Amount
B3: 45265 | C3: 45356 | D3: =C3-B3 -> 91 | E3: 9008
B4: 45357 | C4: 45382 | D4: =C4-B4 -> 25 | E4: =ROUND(E3*D4/D3,0) -> 2475 | F4: Prov
A7: Lift AMC | B7: Period | D7: Months | E7: Amount
B8: 45292 | C8: 45627 | D8: 12 | E8: 25960
B9: 45383 | C9: 45627 | D9: 9 | E9: =ROUND(E8*D9/D8,0) -> 19470 | F9: Prepaid
A12: Intercom AMC | B12: Period | D12: Months | E12: Amount
B13: 45292 | C13: 45627 | D13: 12 | E13: 5192
B14: 45383 | C14: 45627 | D14: 9 | E14: =ROUND(E13*D14/D13,0) -> 3894 | F14: Prepaid
A17: CCTV AMC | B17: Period | D17: Months | E17: Amount
B18: 45292 | C18: 45627 | D18: 12 | E18: 7788
B19: 45383 | C19: 45627 | D19: 9 | E19: =ROUND(E18*D19/D18,0) -> 5841 | F19: Prepaid
A22: Pest Control | B22: Period | D22: Months | E22: Amount
B23: 45078 | C23: 45413 | D23: 12 | E23: 5800
B24: 45383 | C24: 45413 | D24: 2 | E24: =ROUND(E23*D24/D23,0) -> 967 | F24: Prepaid
A27: Insurance | B27: Period | D27: Days | E27: Amount
B28: 45124 | C28: 45489 | D28: =C28-B28+1 -> 366 | E28: =1431+21921 -> 23352
B29: 45383 | C29: 45489 | D29: =C29-B29+1 -> 107 | E29: =ROUND(E28*D29/D28,0) -> 6827 | F29: Prepaid
A32: Income tax
B33: =IE!G26+IE!G23+IE!H17 -> 10377
B34: 1000
B35: =(B33-10000)*30% -> 113.1
B36: =B34+B35 -> 1113.1
B37: =B36*4% -> 44.524
B38: =B36+B37 -> 1157.624
B39: =1160 -> 1160

Sheet Sheet1
A1: Helena Villa CHS - Income - Non Members > Interest Income - Fixed Deposit ( 306002 ) <br>Transactions From 01-04-2023 to 31-03-2024
A2: Journal No. | B2: Posted Date | C2: Comments | D2: Credit
A3: JE-2023-0000015 | B3: 15-04-2023 | C3: Being FD 47507 redeemed on maturity - GF | D3: 63 | E3: GF | G3: 35883 | H3: GF
A4: JE-2023-0000016 | B4: 24-04-2023 | C4: Being FD 47539 redeemed on maturity - GF | D4: 357 | E4: GF | G4: 15571 | H4: PF
A5: JE-2023-0000017 | B5: 24-04-2023 | C5: Being FD 47540 redeemed on maturity - GF | D5: 357 | E5: GF | G5: 15737 | H5: SF
A6: JE-2023-0000018 | B6: 24-04-2023 | C6: Being FD 47541 redeemed on maturity - GF | D6: 357 | E6: GF | G6: =SUM(G3:G5) -> 67191
A7: JE-2023-0000019 | B7: 24-04-2023 | C7: Being FD 47542 redeemed on maturity - GF | D7: 357 | E7: GF
A8: JE-2023-0000109 | B8: 30-06-2023 | C8: Being interest recd on FD 1000459 PF CCB | D8: 561 | E8: PF
A9: JE-2023-0000110 | B9: 30-09-2023 | C9: Being interest recd on FD 1000459 PF CCB | D9: 567 | E9: PF
A10: JE-2023-0000093 | B10: 13-10-2023 | C10: Being FD 1001025 redeemed on maturity GF CCB | D10: 5870 | E10: GF
A11: JE-2023-0000111 | B11: 22-10-2023 | C11: Being interest recd on FD 1000459 PF CCB | D11: 129 | E11: PF
A12: JE-2023-0000112 | B12: 23-10-2023 | C12: Being FD 1000459 redeemed on maturity PF CCB | D12: 12 | E12: PF
A13: JE-2023-0000094 | B13: 23-10-2023 | C13: Being FD 21001097 redeemed on maturity GF CCB | D13: 23483 | E13: GF
A14: JE-2023-0000089 | B14: 25-10-2023 | C14: Being FD 30524 R06 redeemed on maturity PF CCB | D14: 1353 | E14: PF
A15: JE-2023-0000090 | B15: 20-11-2023 | C15: Being FD 3053697 R01 redeemed on maturity PF CCB | D15: 901 | E15: PF
A16: JE-2023-0000095 | B16: 26-12-2023 | C16: Being FD 21000911 redeemed on maturity PF CCB | D16: 1534 | E16: PF
A17: JE-2023-0000096 | B17: 10-01-2024 | C17: Being FD 3051949 R04 redeemed on maturity PF CCB | D17: 1433 | E17: PF
A18: JE-2023-0000104 | B18: 20-02-2024 | C18: Being FD 825414 3052448 R03 redeemed on maturity PF CCB | D18: 1523 | E18: PF
... A51: JE-2023-0000097 | B51: 31-03-2024 | C51: Being interest accrued on FD 1003921 GF CCB | D51: 982 | E51: GF
