Workbook

Sheet BS
A1: FARRY APARTMENT CO-OPERATIVE HOUSING SOCIETY LTD.
A2: (Regd No : BOM/WP/HSG/TC/8669 of 1993-94)
A3: Opp. Bank of Baroda, Marve Road, Orlem, Malad(West), Mumbai, Maharashtra-400064
A4: Balance Sheet as at March 31, 2026
A5: 45747 | B5: LIABILITIES | D5: 46112 | E5: =+A5 -> 45747 | F5: ASSETS | H5: =+D5 -> 46112
B6: Authorised Share Capital | F6: Cash and Bank Balances:
A7: 1200000 | B7: 24,000 shares of ₹50/- each | D7: 1200000 | E7: 288 | F7: Cash Balance | G7: 107
E8: 110575.29 | F8: Saraswat Bank - Saving Account | G8: =BRS!D5 -> 246018.67
B9: Issued, Subscribed and Paid-Up | E9: 0 | F9: Saraswat Bank - Sweep Account | G9: 50000
A10: 14500 | B10: 290 shares of ₹50/- each | D10: 14500 | E10: 26652 | F10: MDCC Bank | G10: 29158 | H10: =SUM(G7:G10) -> 325283.67
B11: Reserve Fund and Others:
B12: Reserve Fund | F12: Investments:
A13: 928711 | B13: As per last balance sheet | C13: =SUM(A13:A16) -> 1202968 | E13: 100 | F13: 1 Share of MDHF | G13: 100
A14: 17594 | B14: Add: 25% Surplus transferd from I&E | C14: =+IE!C47 -> 35449.845 | E14: 1000 | F14: 10 Shares of MDCC Bank | G14: 1000
A15: 26400 | B15: Add: Additions during the year | C15: =1500+600+75000 -> 77100 | E15: 5564421 | F15: Fixed Deposits (As per Schedule I) | G15: ='FD-Sch'!D33 -> 6002500
A16: 230263 | B16: Add: Interest earned during the year | C16: =IE!G27 -> 316041 | D16: =SUM(C13:C16) -> 1631558.8 | E16: 382990 | F16: Accrued Interest on Fixed Deposits | G16: 433409
B17: Sinking Fund | E17: 0 | F17: Accrued Interest on Recurring Deposits | G17: 0 | H17: =SUM(G13:G17) -> 6437009
A18: 1574492.9 | B18: As per last balance sheet | C18: =SUM(A18:A20) -> 1645023.9
A19: 45456 | B19: Add: Additions during the year | C19: 45456 | E19: 18213609 | F19: Fixed Assets (As per Schedule II) | H19: ='FA-Sh'!I12 -> 18204522
A20: 25075 | B20: Add: Interest earned during the year | C20: =IE!G25 -> 26799 | D20: =SUM(C18:C20) -> 1717278.9
B21: Repair Fund | F21: Other Current Assets
A22: 1194134 | B22: As per last balance sheet | C22: =SUM(A22:A25) -> 1428275 | E22: 14044 | F22: Member's Receivable (Sch - 3) | G22: ='Member Receivable & Advances'!D7 -> 35637
A23: 249641 | B23: Add: Additions during the year | C23: 0 | E23: 7500 | F23: Advance to Vendor - (Sch - 6) | G23: ='Vendor Payable & Adavnce'!C19 -> 32600
A24: 0 | B24: Add: Interest earned during the year | C24: =IE!G26 -> 88443 | E24: 54023 | F24: TDS Receivable | G24: 61308
A25: -15500 | B25: Less:Repair expenses incurred | C25: 0 | D25: =SUM(C22:C25) -> 1516718 | E25: 8884 | F25: Prepaid Insurance Charges | G25: 13520
B26: Education & Training Fund | E26: 9779 | F26: Prepaid Intercom AMC | G26: 9779
A27: 30514 | B27: As per last balance sheet | C27: =SUM(A27:A29) -> 33754 | E27: 8530 | F27: Security Deposit with Tata Power | G27: 8530 | H27: =SUM(G22:G27) -> 161374
A28: 3240 | B28: Add: Additions during the year | C28: 3240
A29: 0 | B29: Add: Interest earned during the year | C29: 0 | D29: =SUM(C27:C29) -> 36994
B31: Current Liabilities and Provisions:
A32: 300 | B32: TDS Payable | C32: 1792
A33: 15978 | B33: Adavnce From Member - (Sch - 4) | C33: ='Member Receivable & Advances'!D19 -> 25525
A34: 65073 | B34: Payable to vendor - (Sch - 5) | C34: ='Vendor Payable & Adavnce'!C11 -> 73966
A35: 0 | B35: Retention Monery(R. Reddy) | C35: 0
A36: 0 | B36: Retention Monery(Jessica) | C36: 0 | D36: =SUM(C32:C36) -> 101283
B37: Provision
A38: 2900 | B38: Audit Fee Payable | C38: 3200
A39: 2000 | B39: Professional Fee Payable | C39: 0
A40: 6669 | B40: Water Charges Payable | C40: 15970
A41: 500 | B41: TDS Reimbursement to Irene Rosario | C41: 0
...

Sheet IE
A1: =BS!A1 -> FARRY APARTMENT CO-OPERATIVE HOUSING SOCIETY LTD.
A2: (Regd No : BOM/WP/HSG/TC/8669 of 1993-94)
A3: Opp. Bank of Baroda, Marve Road, Orlem, Malad(West), Mumbai, Maharashtra-400064
A4: Income and Expenditure Account for the year ended March 31, 2026
A5: =+BS!E5 -> 45747 | B5: EXPENDITURE | D5: =BS!D5 -> 46112 | E5: =+A5 -> 45747 | F5: INCOME | H5: =+D5 -> 46112
B6: Property Expenses | F6: By Contribution from member towards:-
A7: 426284 | B7: Property Tax | D7: 550328 | E7: 418824 | F7: Property Tax | G7: =54792+495558 -> 550350
A8: 0 | B8: Arrears Property Tax | D8: 0 | E8: 111600 | F8: Electricity Charges | G8: 111600
A9: 113939 | B9: Electricity Expenses | D9: 133169 | E9: 47500 | F9: Water Charges | G9: 60000
A10: 77447 | B10: Water Expenses | D10: =73416+5400 -> 78816 | E10: 601400 | F10: Maintenance Charges | G10: 660300
B11: To Repair and Maintenance Expenses | E11: 66400 | F11: Parking Charges | G11: =43600+20200+1500+450 -> 65750
A12: 36576 | B12: R&M - Lift AMC | C12: =34692+200 -> 34892 | E12: 9200 | F12: Non Occupancy Charges | G12: 7210
A13: 110 | B13: R&M - Plumbing | C13: 1680 | E13: 197064 | F13: Other Charges | G13: =197064 -> 197064
A14: 15210 | B14: R&M - Electrical | C14: 6215 | E14: 2413 | F14: Late Payment Interest | G14: 4408
A15: 59673 | B15: R&M - Other | C15: 52000 | E15: 1000 | F15: Shifting Charges | G15: 4000
A16: 12936 | B16: R&M - Intercom AMC | C16: 12980 | E16: 0 | F16: Cheque Return Charges | G16: 300
A17: 8250 | B17: R&M - Water Tank Cleaning | C17: 0 | E17: 0 | F17: Penalty | G17: 1000
A18: 7570 | B18: R&M - Garden Expenses | C18: 10350 | E18: 0 | F18: Legal Charges | G18: 2000 | H18: =SUM(G7:G18) -> 1663982
A19: 15500 | B19: R&M - Building | C19: 35000
A20: -15500 | B20: Less: trf to Repair Fund | C20: 0 | D20: =SUM(C12:C20) -> 153117 | F20: Interest Income
B21: Service Expenses | E21: 4735 | F21: Interest income - Savings Account | H21: 6094
A22: 357345 | B22: Security charges | C22: 359339 | E22: 3744 | F22: Interest income - Sweep Deposit | H22: 1381
A23: 17414 | B23: Depreciation on Fixed Assets | C23: 15990 | E23: 1131 | F23: Interest on Income Tax Refund | H23: 1966
A24: 29708 | B24: Insurance Expenses | C24: 19554 | E24: 357269 | F24: Interest Income - Fixed Deposit | G24: 432443
A25: 826 | B25: Subscription Federation | C25: 0 | E25: -25075 | F25: Less: trf to Sinking Fund | G25: 26799
B26: Pest Control Charges | C26: 2450 | E26: -100731 | F26: Less: trf to Repair Fund | G26: 88443
A27: 6685 | B27: Housekeeping Expenses | C27: 7208 | E27: -230263 | F27: Less: trf to Reserve Fund | G27: 316041 | H27: =G24-G25-G26-G27 -> 1160
A28: 2900 | B28: Audit Fees | C28: 5500 | D28: =SUM(C22:C28) -> 410041
B29: Office Expenses
A30: 84000 | B30: Salaries | C30: 89250 | F30: Other Income
A31: 62 | B31: Interest on TDS | C31: 0 | E31: 1742 | F31: Scrap Sale | G31: 0
A32: 18532 | B32: Accounting Charges | C32: 18532 | E32: 0 | F32: Miscellaneous Income | G32: 725 | H32: =SUM(G31:G32) -> 725
A33: 1393 | B33: Printing and Stationary | C33: 3059
A34: 200 | B34: Meeting Expenses | C34: 0
A35: 2700 | B35: Professional Fees | C35: 6500
A36: 137.26 | B36: Bank Charges | C36: 182.62
A37: 44406 | B37: Bank charges of prematured FD Penalty | C37: 0
A38: 3574 | B38: Misc. Expenses | C38: 4954
A39: 69676 | B39: Festival Expenses | C39: 63895
A40: 0 | B40: Election Expenses | C40: 0
...

Sheet FD-Sch
A1: FARRY APARTMENTS CO-OP.HSG.SOC.LTD
A2: Schedule 1: Details of Fixed Deposits as on 31.03.2026
A3: Sr. | B3: Certificate No. | C3: Date | D3: Amount Invested | E3: Accrued Int 23-24 | F3: Accrued Int 24-25 | G3: Accrued Int 25-26 | H3: Total Amount Invested | I3: Maturity Date | J3: Maturity Value | K3: Int % | L3: Bank
B4: Sinking Fund
A5: 1 | B5: 102101040040150 | C5: 23.09.2024 | D5: 36829 | E5: 0 | F5: =1340-782 -> 558 | G5: =649+666+683+689-69 -> 2618 | H5: =SUM(D5:G5) -> 40005 | I5: 0 | J5: 0 | K5: 0 | L5: SVC
A6: 2 | B6: 300001000468048 | C6: 28.01.2026 | D6: 346591 | E6: 0 | F6: 0 | G6: 0 | H6: =SUM(D6:G6) -> 346591 | I6: 28.01.2026 | J6: 348454 | K6: 0.0725 | L6: SVC
A7: Total :- | D7: =SUM(D5:D6) -> 383420 | E7: =SUM(E5:E6) -> 0 | F7: =SUM(F5:F6) -> 558 | G7: =SUM(G5:G6) -> 2618 | H7: =SUM(H5:H6) -> 386596 | J7: =SUM(J5:J6) -> 348454
B8: Repair Fund
A9: 3 | B9: TD0000412514_03 | C9: 21.09.2025 | D9: 283439 | E9: 0 | F9: 0 | G9: =10298-1030 -> 9268 | H9: =SUM(D9:G9) -> 292707 | L9: SCB
A10: 4 | B10: TD0000412515_03 | C10: 21.09.2025 | D10: 283327 | E10: 0 | F10: 0 | G10: =10294-1029 -> 9265 | H10: =SUM(D10:G10) -> 292592 | L10: SCB
A11: 5 | B11: TD1000855564_01 | C11: 15.07.2025 | D11: 341459 | E11: 0 | F11: 0 | G11: =17282-1728 -> 15554 | H11: =SUM(D11:G11) -> 357013 | L11: SCB
A12: 6 | B12: TD1000854263_1 | C12: 14.07.2025 | D12: 341457 | E12: 0 | F12: 0 | G12: =17348-1735 -> 15613 | H12: =SUM(D12:G12) -> 357070 | L12: SCB
A13: 7 | B13: TD1002022122 | C13: 13.02.2026 | D13: 100000 | E13: 0 | F13: 0 | G13: =914-92 -> 822 | H13: =SUM(D13:G13) -> 100822 | I13: 13.02.2028 | J13: 114437 | K13: 0.068 | L13: SCB
A14: 8 | B14: 300000100148176 | C14: 12.07.2024 | D14: 200000 | E14: 0 | F14: =10239-1024 -> 9215 | G14: =15034-386 -> 14648 | H14: =SUM(D14:G14) -> 223863
A15: 9 | B15: 300001000184534 | C15: 24.09.2024 | D15: 150000 | E15: 0 | F15: =5524-553 -> 4971 | G15: =11136-285 -> 10851 | H15: =SUM(D15:G15) -> 165822
A16: Total :- | D16: =SUM(D9:D15) -> 1699682 | E16: =SUM(E9:E15) -> 0 | F16: =SUM(F9:F15) -> 14186 | G16: =SUM(G9:G15) -> 76021 | H16: =SUM(H9:H15) -> 1789889 | J16: =SUM(J9:J15) -> 114437
B17: Share Capital
A18: 10 | B18: 1200007559 | C18: 01.01.2026 | D18: 15500 | E18: 0 | F18: 0 | H18: =SUM(D18:F18) -> 15500 | I18: 01.01.2028 | J18: 15500 | K18: 0.0775 | L18: MDCC
A19: Total :- | D19: =SUM(D18) -> 15500 | E19: =SUM(E18) -> 0 | F19: =SUM(F18) -> 0 | G19: =SUM(G18) -> 0 | H19: =SUM(H18) -> 15500 | J19: =SUM(J18) -> 15500
B20: General Reserve Fund
A21: 11 | B21: TD0000412510_04 | C21: 26.05.2025 | D21: 314543 | E21: 0 | F21: 0 | G21: =17147-1715 -> 15432 | H21: =SUM(D21:G21) -> 329975 | L21: SCB
A22: 12 | B22: TD0000412511_04 | C22: 26.05.2025 | D22: 314542 | E22: 0 | F22: 0 | G22: =17147-1714 -> 15433 | H22: =SUM(D22:G22) -> 329975 | L22: SCB
A23: 13 | B23: TD0000412508_04 | C23: 14.05.2025 | D23: 583355 | E23: 0 | F23: 0 | G23: =38356-3835 -> 34521 | H23: =SUM(D23:G23) -> 617876 | L23: SCB
A24: 14 | B24: TD1000854262_01 | C24: 17.07.2025 | D24: 341458 | E24: 0 | F24: 0 | G24: =17349-1735 -> 15614 | H24: =SUM(D24:G24) -> 357072 | L24: SCB
A25: 15 | B25: TD1001264532 | C25: 12.07.2024 | D25: 600000 | E25: 0 | F25: =30750-2153 -> 28597 | G25: =45052-4506 -> 40546 | H25: =SUM(D25:G25) -> 669143 | L25: SCB
A26: 16 | B26: TD1001264534 | C26: 12.07.2024 | D26: 500000 | E26: 0 | F26: =25625-1795 -> 23830 | G26: =37543-3755 -> 33788 | H26: =SUM(D26:G26) -> 557618 | L26: SCB
A27: 17 | B27: TD1001264542 | C27: 12.07.2024 | D27: 500000 | E27: 0 | F27: =25608-2274 -> 23334 | G27: =37508-3750 -> 33758 | H27: =SUM(D27:G27) -> 557092 | L27: SCB
A28: 18 | B28: TD1001264563 | C28: 12.07.2024 | D28: 500000 | E28: 0 | F28: =25598-2559 -> 23039 | G28: =37486-3749 -> 33737 | H28: =SUM(D28:G28) -> 556776 | L28: SCB
A29: 19 | B29: TD1001538948 | C29: 17.02.2025 | D29: 150000 | E29: 0 | F29: =1345-135 -> 1210 | G29: =11234-1124 -> 10110 | H29: =SUM(D29:G29) -> 161320 | L29: SCB
A30: 20 | B30: TD1001575057 | C30: 24.03.2025 | D30: 100000 | E30: 0 | F30: =161-16 -> 145 | G30: =7703-771 -> 6932 | H30: =SUM(D30:G30) -> 107077 | L30: SCB
A31: Total :- | D31: =SUM(D21:D30) -> 3903898 | E31: =SUM(E21:E30) -> 0 | F31: =SUM(F21:F30) -> 100155 | G31: =SUM(G21:G30) -> 239871 | H31: =SUM(H21:H30) -> 4243924 | J31: =SUM(J21:J30) -> 0
A33: Grand Total | D33: =D7+D16+D19+D31 -> 6002500 | E33: =E7+E16+E19+E31 -> 0 | F33: =F7+F16+F19+F31 -> 114899 | G33: =G7+G16+G19+G31 -> 318510 | H33: =H7+H16+H19+H31 -> 6435909 | J33: =J7+J16+J19+J31 -> 478391

Sheet FA-Sh
A1: FARRY APARTMENTS CO-OP.HSG.SOC.LTD
B2: Schedule 2: Details of Fixed Assets as on 31.03.2026
A3: Sr.No | B3: Particulars | C3: Rate % | D3: Opening W.D.V. as of 01.04.2025 | E3: Additions during the year before 30.09.25 | F3: Additions during the year after 30.09.25 | G3: Gross Block (at cost) as of 31.03.26 | H3: Depreciation for the year | I3: Closing W.D.V. as of 31.03.2026
A4: 1 | B4: Land and Building | C4: 0 | D4: 18080000 | E4: 0 | F4: 0 | G4: =D4+E4+F4 -> 18080000 | H4: =ROUND(G4*C4,) -> 0 | I4: =G4-H4 -> 18080000
A5: 2 | B5: Office Premises | C5: 0 | D5: 23225 | E5: 0 | F5: 0 | G5: =D5+E5+F5 -> 23225 | H5: =ROUND(G5*C5,) -> 0 | I5: =G5-H5 -> 23225
A6: 3 | B6: Furniture and Fixtures | C6: 0.1 | D6: 14997 | E6: 0 | F6: 0 | G6: =D6+E6+F6 -> 14997 | H6: =ROUND(G6*C6,) -> 1500 | I6: =G6-H6 -> 13497
A7: 4 | B7: Borewell | C7: 0.15 | D7: 26619 | E7: 0 | F7: 0 | G7: =D7+E7+F7 -> 26619 | H7: =ROUND(G7*C7,) -> 3993 | I7: =G7-H7 -> 22626
A8: 5 | B8: Intercome System | C8: 0.15 | D8: 5341 | E8: 0 | F8: 0 | G8: =D8+E8+F8 -> 5341 | H8: =ROUND(G8*C8,) -> 801 | I8: =G8-H8 -> 4540
A9: 6 | B9: CCTV | C9: 0.15 | D9: 49637 | E9: 6903 | F9: 0 | G9: =D9+E9+F9 -> 56540 | H9: =ROUND(G9*C9,) -> 8481 | I9: =G9-H9 -> 48059
A10: 7 | B10: Garden Equipment | C10: 0.15 | D10: 2411 | E10: 0 | F10: 0 | G10: =D10+E10+F10 -> 2411 | H10: =ROUND(G10*C10,) -> 362 | I10: =G10-H10 -> 2049
A11: 8 | B11: Fogging Machine | C11: 0.15 | D11: 11379 | E11: 0 | F11: 0 | G11: =D11+E11+F11 -> 11379 | H11: =ROUND(G11*C11/2,) -> 853 | I11: =G11-H11 -> 10526
B12: Total :- | D12: =SUM(D4:D11) -> 18213609 | E12: =SUM(E4:E11) -> 6903 | F12: =SUM(F4:F11) -> 0 | G12: =SUM(G4:G11) -> 18220512 | H12: =SUM(H4:H11) -> 15990 | I12: =SUM(I4:I11) -> 18204522

Sheet Member Receivable & Advances
A1: =+BS!A1 -> FARRY APARTMENT CO-OPERATIVE HOUSING SOCIETY LTD.
A2: Schedule 3 : Member's Receivable as on 31.03.2026
A3: Sl.No | B3: Unit | C3: Name The Member | D3: Amount
A4: 1 | B4: 301 | C4: Ms. Sheila Seth | D4: 12297
A5: 2 | B5: 103 | C5: Mr. K. K. Francis & Mrs. Kumari Francis | D5: 4407
A6: 3 | B6: 201 | C6: Ms. Asha Arun Kala & Mrs. Namita Sandeep Chabra | D6: 18933
A7: Total | D7: =SUM(D4:D6) -> 35637
A11: Schedule 4 : Member's Adavances as on 31.03.2026
A12: Sl.No | B12: Unit | C12: Name | D12: Amount
A13: 1 | B13: 203 | C13: Ms. Zita Arthur Rodrigues & Mr. Arthur J. Rodrigues | D13: 11869
A14: 2 | B14: 402 | C14: Mrs Nerissa Aaguiar | D14: 3703
A15: 3 | B15: 501 | C15: Mr. Prakash Godwin Rodrigues & Mrs. Nancy Rodrigues | D15: 3684
A16: 4 | B16: 502 | C16: Mr. Sydney Joe Lobo & Mrs. Karen Maria Rodrigues | D16: 6197
A17: 5 | B17: 503 | C17: Ms. Charmaine E. Lobo & Mrs. Agnes N. Lobo | D17: 22
A18: 6 | B18: G001 | C18: Mr. Valerian J Henriques | D18: 50
A19: Total | D19: =SUM(D13:D18) -> 25525
B22: Schedule 5 : Vendor Payable as on 31.03.2026
B23: Sl.No | C23: Name The Vendor | D23: Amount
B24: 1 | C24: BMC Water Tax | D24: 15970
B25: 2 | C25: BMC Property Tax | D25: 7450
B26: 3 | C26: Chitra Parmar | D26: 5000
B27: 4 | C27: Deepak Security Service | D27: 31581
B28: 5 | C28: Gardner | D28: 1250
B29: 7 | C29: Shantaram Kulkar | D29: 2500
B30: 8 | C30: TATA Power | D30: 10215
B31: Total | D31: =SUM(D24:D30) -> 73966
B34: Schedule 6 : Advance to Vendor as on 31.03.2026
B35: Sl.No | C35: Name The Vendor | D35: Amount
B36: 1 | C36: Shankar Majhi | D36: 7500
B37: 2 | C37: Ivan Rosario | D37: 100
B38: 3 | C38: Wise Construction | D38: 25000
B39: Total | D39: =SUM(D36:D38) -> 32600

Sheet Vendor Payable & Adavnce
A2: Schedule 5 : Vendor Payable as on 31.03.2026
A3: Sl.No | B3: Name The Vendor | C3: Amount
A4: 1 | B4: BMC Water Tax | C4: 15970
A5: 2 | B5: BMC Property Tax | C5: 7450
A6: 3 | B6: Chitra Parmar | C6: 5000
A7: 4 | B7: Deepak Security Service | C7: 31581
A8: 5 | B8: Gardner | C8: 1250
A9: 7 | B9: Shantaram Kulkar | C9: 2500
A10: 8 | B10: TATA Power | C10: 10215
A11: Total | C11: =SUM(C4:C10) -> 73966
A14: Schedule 6 : Advance to Vendor as on 31.03.2026
A15: Sl.No | B15: Name The Vendor | C15: Amount
A16: 1 | B16: Shankar Majhi | C16: 7500
A17: 2 | B17: Ivan Rosario | C17: 100
A18: 3 | B18: Wise Construction | C18: 25000
A19: Total | C19: =SUM(C16:C18) -> 32600

Sheet BRS
A1: FARRY APARTMENTS CO-OP.HSG.SOC.LTD
A3: Saraswat Bank Reconciliation Statement as on 31.03.2026
D4: Amount
A5: Balance as per system (Book Balance) | D5: 246018.67
A6: Add | B6: Cheque deposited but not cleared in Adda | D6: 0
A7: Add | B7: Cheque issued but not cleared in Adda | D7: 2000
A8: Add | B8: Amount Reconciled in FY2025-26 | D8: 0
A9: Add | B9: Amount not enter in Adda
A10: Balance as per passbook | D10: =D5+D6+D7+D8+D9 -> 248018.67
A12: MDCC Bank Reconciliation Statement as on 31.03.2026
D13: Amount
A14: Balance as per system (Book Balance) | D14: 29158
A15: Add | B15: Cheque deposited but not cleared in Adda
A16: Less | B16: Cheque issued but not cleared in Adda | D16: 0
A17: Add | B17: Amount in Adda but not reconciled in Adda | D17: 0
A19: Balance as per passbook | D19: =D14+D15-D16+D17 -> 29158

Sheet Workings
A1: Note: Workings Page is not the be printed
B4: Water Charges
B5: 45968 | C5: 46059 | D5: =+C5-B5 -> 91 | E5: 9764 | J5: Income Tax Provision
B6: 46059 | C6: 46112 | D6: =+C6-B6 -> 53 | E6: =ROUND(+E5*D6/D5,0) -> 5687 | F6: Provision | J6: Interest on Saving | K6: =IE!H22 -> 1381
J7: Interest on Sweep | K7: =IE!H23 -> 1966
B8: 45968 | C8: 46059 | D8: =+C8-B8 -> 91 | E8: 6206 | J8: Interest on IT refund | K8: 1131
B9: 46059 | C9: 46112 | D9: =+C9-B9 -> 53 | E9: =ROUND(+E8*D9/D8,0) -> 3614 | F9: Provision | J9: Interest on FD/RD | K9: =IE!G24 -> 432443
J10: 80P2D Benefit | K10: =-K9-K6-K7 -> -435790
J11: Total | K11: =SUM(K6:K10) -> 1131
B12: Insurance Charges | J12: 0 To 10000 | K12: =ROUND(K11*L12,0) -> 113 | L12: 0.1
B13: 45952 | C13: 46316 | D13: =C13-B13+1 -> 365 | E13: 24190 | J13: 10001 To 20000 | K13: 0 | L13: 0.2
B14: 46113 | C14: =+C13 -> 46316 | D14: =C14-B14+1 -> 204 | E14: =ROUND(+E13*D14/D13,0) -> 13520 | F14: Prepaid | J14: 20001 Or more | K14: 0 | L14: 0.3
J15: Education Cess | K15: =ROUND(SUM(K12:K14)*L15,0) -> 5 | L15: 0.04
J16: Total Tax | K16: =SUM(K12:K15) -> 118
J17: Rounded Off | K17: =ROUND(K16,-1) -> 120
J18: Provision already made | K18: 201 | L18: FY 2023-24
B20: Intercom Expenses
B21: 46023 | C21: 46387 | D21: =C21-B21+1 -> 365 | E21: 12980
B22: 46113 | C22: =+C21 -> 46387 | D22: =C22-B22+1 -> 275 | E22: =ROUND(+E21*D22/D21,0) -> 9779 | F22: Prepaid
B24: TDS Filing
B25: 45383 | C25: 45473 | D25: =C25-B25+1 -> 91 | E25: 1874
B26: 45474 | C26: 45565 | D26: =C26-B26+1 -> 92 | E26: 1900
D27: =SUM(D25:D26) -> 183 | E27: =SUM(E25:E26) -> 3774
B28: 45566 | C28: 45747 | D28: =C28-B28+1 -> 182 | E28: =ROUND(+E27*D28/D27,0) -> 3753 | F28: Provision
B30: Audit Fees
