Workbook

Sheet BS
A1: DIAGO CO-OPERATIVE HOUSING SOCIETY LIMITED
A2: 186-A, Baudi Cross Lane, Orlem, Malad (West), Mumbai, Maharashtra - 400064
A3: Society Reg No : BOM/(WP)/HSG(TC) 1007/84-85 dated.13/07/1984
A4: Balance Sheet as at March 31, 2026
A5: March 31, 2025 | B5: LIABILITIES | D5: March 31, 2026 | E5: =+A5 -> March 31, 2025 | F5: ASSETS | H5: =+D5 -> March 31, 2026
B6: Authorised Share Capital | F6: Cash and Bank Balances:
A7: =4460*50 -> 223000 | B7: 4460 Share of ₹ 50/- each | D7: 223000 | E7: 2056 | F7: Cash in Hand | G7: 950
E8: 257877.75 | F8: Saraswat Co-op Bank | G8: 203659.25
B9: Issued, Subscribed and Fully Paid-up: | E9: 2777.86 | F9: Mumbai District Central Co-op Bank | G9: 2862.86
A10: 18000 | B10: 360 Shares of ₹ 50/- each | D10: 18000 | E10: 3441.85 | F10: Bank of Baroda | G10: 3381.35 | H10: =SUM(G7:G10) -> 210853.46
A12: ='Fund Sch_1'!A42 -> 1260442 | B12: Reserves and Surplus: | F12: Investments:
B13: (Refer Schedule 1) | D13: ='Fund Sch_1'!D42 -> 1486441 | E13: 1000 | F13: Share of MDCC Bank | G13: 1000
E14: 1228170 | F14: Fixed Deposits: (Refer Schedule 2) | G14: ='FD Sch_2'!D81 -> 1523053
B15: Members Contributions Towards | E15: 67712 | F15: Accrued Interest | G15: ='FD Sch_2'!G81 -> 76526 | H15: =SUM(G13:G15) -> 1600579
A16: 2227750 | B16: Land and Building | D16: 2227750
F17: Deposits:
B18: Current Liabilities: | E18: 33319 | F18: Deposit with BMC | G18: 33319
A19: 31930 | B19: Advance from Members (Sch 5) | C19: ='Advance n Refundable Sch 4 to 7'!E12 -> 21383 | E19: 4430 | F19: Deposit with Tata Power | G19: 4430 | H19: =SUM(G18:G19) -> 37749
A20: 20000 | B20: Refundable Deposit (Sch 6) | C20: ='Advance n Refundable Sch 4 to 7'!E28 -> 24000 | D20: =SUM(C19:C20) -> 45383
B22: Provisions: | F22: Sundry Debtors:
A23: 3600 | B23: Audit Fees Payable | C23: 3600 | E23: 6921 | F23: Member's Due (Refer Schedule 4) | H23: ='Advance n Refundable Sch 4 to 7'!E5 -> 3982
A24: 18026 | B24: Water Charges Payable | C24: 18771
A25: 0 | B25: Membership & Subscription | C25: 826 | F25: Prepaid Expenses:
A26: 5310 | B26: Professional Fee Payable | C26: 3540 | E26: 7269 | F26: Insurance Charges | G26: 7269
A27: 9694 | B27: Payables (Refer Schedule 7) | C27: ='Advance n Refundable Sch 4 to 7'!J8 -> 33044 | E27: 9802 | F27: Pest Control Charges | G27: 3332 | H27: =+G26+G27 -> 10601
A28: 54400 | B28: Retention - Ecotech Exterior and Interior | C28: 54400 | D28: =SUM(C23:C28) -> 114181 | F28: Income tax refund receivables | H28: 6321
E29: 6995 | F29: TDS Receivable | H29: 8597
B30: Income and Expenditure Account:
A31: 236930.74 | B31: Balance as per last balance sheet | C31: =A31+A32+A34 -> 269629.46 | F31: Fixed Assets
A32: 1770 | B32: Add: Excess Prof. Fees Prov. written back | C32: 0 | E32: 2287010 | F32: (Refer Schedule 3) | H32: ='FA Sch_3'!H10 -> 2283328
A33: 0 | B33: Add: Excess provision fire fighting System. Writte back | C33: 1300
A34: =E35-SUM(A10:A32) -> 30928.72 | B34: Add: Surplus/(Defecit) for the year | C34: =-IE!H50 -> -674 | D34: =SUM(C31:C34) -> 270255.46
A35: =SUM(A10:A34) -> 3918781.5 | B35: Total | D35: =SUM(D10:D34) -> 4162010.5 | E35: =SUM(E6:E34) -> 3918781.5 | F35: Total | H35: =SUM(H6:H34) -> 4162010.5
G36: =A35-E35 -> 0 | H36: =H35-D35 -> 0
A37: As per my report of even date | E37: FOR DIAGO CO-OPERATIVE HOUSING SOCIETY LIMITED
A41: Shri. Bharat C. Boridkar
A42: Govt. Certified Panel Auditor | E42: Chairman Secretary Treasurer
A43: [Panel No.: Mumbai-4/C1/1011404]
A44: 46234

Sheet IE
A1: =BS!A1 -> DIAGO CO-OPERATIVE HOUSING SOCIETY LIMITED
A2: =BS!A2 -> 186-A, Baudi Cross Lane, Orlem, Malad (West), Mumbai, Maharashtra - 400064
A3: =BS!A3 -> Society Reg No : BOM/(WP)/HSG(TC) 1007/84-85 dated.13/07/1984
A4: Income and Expenditure Account for the year ended March 31, 2026
A5: March 31, 2025 | B5: EXPENDITURE | D5: March 31, 2026 | E5: =+A5 -> March 31, 2025 | F5: INCOME | H5: =+D5 -> March 31, 2026
B6: Property Tax | F6: Maintenance Income
A7: 13333 | B7: Property Tax | D7: 13654 | E7: 13330 | F7: Property Tax | G7: 13656
B8: Water Expenses | E8: 226080 | F8: Maintenance Charges | G8: 226080
A9: 76693 | B9: Water Expenses | C9: 78473 | E9: 55008 | F9: Electricity Charges | G9: 55008
A10: 4000 | B10: Water Tank Cleaning Expenses | C10: 0 | D10: =SUM(C9:C10) -> 78473 | E10: 75312 | F10: Water Charges | G10: 75312
E11: =9589+83 -> 9672 | F11: Non Occupancy Charges | G11: =11408+83 -> 11491
A12: 75021 | B12: Common Electricity Charges | D12: 76274 | E12: =12200+15200+1600 -> 29000 | F12: Parking Charges | G12: =7450+16100+50 -> 23600
E13: 781 | F13: Interest on Delayed Payments | G13: 2287
A14: 40500 | B14: Salary Expenses | D14: 52000 | E14: 13172 | F14: Insurance Charges | G14: 13172
B15: Repair and Maintenance Expenses | E15: 200 | F15: Fines | G15: 1300
A16: 8240 | B16: Electrical Repairs | C16: 4800 | E16: 2925 | F16: Guest Parking Charges | G16: 250 | H16: =SUM(G7:G16) -> 422156
A17: 47219 | B17: Plumbing Repairs | C17: 0
A18: 58875 | B18: Other Repairs | C18: 116000 | F18: Interest Income
A19: 2510 | B19: CCTV AMC Expense | C19: 3304 | E19: 6310 | F19: Interest Income from Savings Deposits | G19: 7174
A20: 1300 | B20: Fire Fighting Expenses | C20: 0 | E20: 751 | F20: Interest on Income Tax Refund | G20: 0
A21: 0 | B21: Major Repair Expenses | C21: 18000 | D21: =SUM(C16:C21) -> 142104 | E21: 84529 | F21: Interest Income from Fixed Deposits | G21: 101559 | H21: =SUM(G19:G21) -> 108733
B22: Service Charges
A23: 7780 | B23: Insurance Expense | C23: 7781 | F23: Other Income
A24: 3600 | B24: Audit Fees | C24: 3600 | E24: 7 | F24: Miscellaneous Income | G24: 0
A25: 826 | B25: Subscription Federation | C25: 826 | F25: Dividend Income | H25: 0
A26: 20392 | B26: Accounting Charges | C26: 22432 | D26: =SUM(C23:C26) -> 34639
B27: Other Expenses
A28: 4314 | B28: Depreciation | C28: ='FA Sch_3'!G10 -> 3682
A29: 998 | B29: Printing and Stationary | C29: =3420+4 -> 3424
A30: 10406 | B30: Meeting Expenses | C30: 8824
A31: 4751 | B31: Conveyance Expense | C31: 5534
A32: 7080 | B32: Professional Fees | C32: 3540
A33: 2500 | B33: Legal Fees | C33: 12000
A34: 403.28 | B34: Bank Charges | C34: 733
A35: 36 | B35: Income Tax | C35: 674
A36: 3000 | B36: Misc. Expenses | C36: 0
A37: 0 | B37: Postage & Courier | C37: 99 | D37: =SUM(C28:C37) -> 38510
B39: Transfer of Funds
A40: 10936 | B40: Less: trf to Sinking Fund | C40: 13233
A41: 9156 | B41: Less: trf to Painting Fund | C41: =9923+2055 -> 11978
...

Sheet Fund Sch_1
A1: DIAGO CO-OP HOUSING SOCIETY LIMITED.
A2: Schedule 1 - Liability - Funds as at 31st March 2026
A3: FY 24-25 | B3: Particulars | D3: FY 25-26
B4: General Fund
A5: 116266 | B5: As per last Balance Sheet | C5: =SUM(A5:A8) -> 193456
A6: 54200 | B6: Add: Addition during the year | C6: 78700
A7: 10309 | B7: Add: 25% surplus trfd from Income/Expend. | C7: 0
A8: 12681 | B8: Add: Accrued interest | C8: 17232 | D8: =SUM(C5:C8) -> 289388
B10: Common Amenity Fund
A11: 128875 | B11: As per last Balance Sheet | C11: =SUM(A11:A12) -> 138034
A12: 9159 | B12: Add: Accrued interest | C12: 9900 | D12: =SUM(C11:C12) -> 147934
B14: Redevelopment Fund
A15: 133117 | B15: As per last Balance Sheet | C15: =SUM(A15:A16) -> 143212
A16: 10095 | B16: Add: Interest received/accrued | C16: 10760 | D16: =SUM(C15:C16) -> 153972
B18: Sinking Fund
A19: 165556 | B19: As per last Balance Sheet | C19: =SUM(A19:A21) -> 184476
A20: 7984 | B20: Add: Additions during the year | C20: 7984
A21: 10936 | B21: Add: Interest received/accrued | C21: 13233 | D21: =SUM(C19:C21) -> 205693
B23: Painting Fund
A24: 133411 | B24: As per last Balance Sheet | C24: =SUM(A24:A26) -> 166523
A25: 23956 | B25: Add: Additions during the year | C25: 23956
A26: 9156 | B26: Add: Interest received/accrued | C26: 11978 | D26: =SUM(C24:C26) -> 202457
B28: Pest Control Fund
A29: 136380 | B29: As per last Balance Sheet | C29: =SUM(A29:A31) -> 137847
A30: -9028 | B30: Less: Expenses incurred for the year | C30: -6470
A31: 10495 | B31: Add: Interest received/accrued | C31: 11451 | D31: =SUM(C29:C31) -> 142828
B33: Legal Fund
A34: 221813 | B34: As per last Balance Sheet | C34: =SUM(A34:A36) -> 260748
A35: 21600 | B35: Add: Additions during the year | C35: 21600
A36: 17335 | B36: Add: Interest received/accrued | C36: 18595 | D36: =+SUM(C34:C36) -> 300943
B38: Education & Training Fund
A39: 29621 | B39: As per last Balance Sheet | C39: =SUM(A39:A41) -> 36146
A40: 4320 | B40: Add: Additions during the year | C40: 4320
A41: 2205 | B41: Add: Interest received/accrued | C41: 2760 | D41: =SUM(C39:C41) -> 43226
A42: =SUM(A5:A41) -> 1260442 | B42: Total | D42: =SUM(D5:D41) -> 1486441

Sheet FD Sch_2
A1: =BS!A1 -> DIAGO CO-OPERATIVE HOUSING SOCIETY LIMITED
A2: Schedule 2 - Details of Fixed Deposits as on 31st March 2026
A3: Sr. | B3: Certificate No. | C3: Date | D3: Amount Invested | E3: Accrued Int 24-25 | F3: Accrued Int 25-26 | G3: Total Accrued Int | H3: Total | I3: Maturity Date | J3: Maturity Value | K3: Interest % | L3: Bank
B4: Sinking Fund
A5: 1 | B5: TD1000182883_01 | C5: 04.12.24 | D5: 13194 | E5: =302-30 -> 272 | F5: =965-96 -> 869 | G5: =+E5+F5 -> 1141 | H5: =D5+G5 -> 14335 | I5: 04.12.27 | J5: 16248 | K5: 0.07 | L5: SCB
A6: 2 | B6: TD0000415687_02 | C6: 05.06.24 | D6: 7366 | E6: =432-44 -> 388 | F6: =556-56 -> 500 | G6: =+E6+F6 -> 888 | H6: =D6+G6 -> 8254 | I6: 05.06.27 | J6: 9071 | K6: 0.07 | L6: SCB
A7: 3 | B7: TD0000415693_02 | C7: 25.06.24 | D7: 7281 | E7: =398-39 -> 359 | F7: =548-55 -> 493 | G7: =+E7+F7 -> 852 | H7: =D7+G7 -> 8133 | I7: 25.06.27 | J7: 8966 | K7: 0.07 | L7: SCB
A8: 4 | B8: TD0000415690_02 | C8: 22.06.24 | D8: 19266 | E8: =1065-107 -> 958 | F8: =1450-143 -> 1307 | G8: =+E8+F8 -> 2265 | H8: =D8+G8 -> 21531 | I8: 22.06.27 | J8: 23725 | K8: 0.07 | L8: SCB
A9: 5 | B9: TD1001583749 | C9: 28.03.25 | D9: 11492 | E9: =9-1 -> 8 | F9: =885-89 -> 796 | G9: =+E9+F9 -> 804 | H9: =D9+G9 -> 12296 | I9: 28.07.26 | J9: 12688 | K9: 0.075 | L9: SCB
A10: 6 | B10: TD1001583745 | C10: 28.03.25 | D10: 26590 | E10: =21-3 -> 18 | F10: =2047-204 -> 1843 | G10: =+E10+F10 -> 1861 | H10: =D10+G10 -> 28451 | I10: 28.07.26 | J10: 29358 | K10: 0.075 | L10: SCB
A11: 7 | B11: TD0000415655_01 | C11: 28.03.25 | D11: 3663 | E11: =3-0 -> 3 | F11: =282-27 -> 255 | G11: =+E11+F11 -> 258 | H11: =D11+G11 -> 3921 | I11: 28.07.26 | J11: 4044 | K11: 0.075 | L11: SCB
A12: 8 | B12: TD1000106181_01 | C12: 08.09.24 | D12: 6063 | E12: =242-25 -> 217 | F12: =450-45 -> 405 | G12: =+E12+F12 -> 622 | H12: =D12+G12 -> 6685 | I12: 08.09.27 | J12: 7466 | K12: 0.07 | L12: SCB
A13: 9 | B13: TD1001583757 | C13: 28.03.25 | D13: 3345 | E13: =3-1 -> 2 | F13: =257-24 -> 233 | G13: =+E13+F13 -> 235 | H13: =D13+G13 -> 3580 | I13: 28.07.26 | J13: 3693 | K13: 0.075 | L13: SCB
A14: 10 | B14: TD1001583325 | C14: 28.03.25 | D14: 8879 | E14: =7-1 -> 6 | F14: =684-68 -> 616 | G14: =+E14+F14 -> 622 | H14: =D14+G14 -> 9501 | I14: 28.07.26 | J14: 9803 | K14: 0.075 | L14: SCB
A15: 11 | B15: TD1002072829 | C15: 27.03.26 | D15: 53839 | E15: 0 | F15: =49-5 -> 44 | G15: =+E15+F15 -> 44 | H15: =D15+G15 -> 53883 | I15: 27.03.28 | J15: 61612 | K15: 0.068 | L15: SCB
A16: 12 | B16: TD1001713033 | C16: 27.06.25 | D16: 32675 | E16: 0 | F16: =1781-178 -> 1603 | G16: =+E16+F16 -> 1603 | H16: =D16+G16 -> 34278 | I16: 26.06.27 | J16: 37540 | K16: 0.07 | L16: SCB
D17: =SUM(D5:D16) -> 193653 | E17: =SUM(E5:E16) -> 2231 | F17: =SUM(F5:F16) -> 8964 | G17: =SUM(G5:G16) -> 11195 | H17: =SUM(H5:H16) -> 204848 | J17: =SUM(J5:J16) -> 224214
B18: General Fund
A19: 13 | B19: 6605300013705_02 | C19: 02.05.25 | D19: 66724 | E19: 0 | F19: 4505 | G19: =E19+F19 -> 4505 | H19: =D19+G19 -> 71229 | I19: 02.08.26 | J19: 72949 | K19: 0.072 | L19: MDCC
A20: 14 | B20: TD1000784123_01 | C20: 09.05.25 | D20: 85428 | E20: 0 | F20: =5705-571 -> 5134 | G20: =E20+F20 -> 5134 | H20: =D20+G20 -> 90562 | I20: 09.05.27 | J20: 98727 | K20: 0.073 | L20: SCB
A21: 15 | B21: TD1001126359_01 | C21: 19.06.25 | D21: 29862 | E21: 0 | F21: =1742-174 -> 1568 | G21: =E21+F21 -> 1568 | H21: =D21+G21 -> 31430 | I21: 19.09.26 | J21: 32688 | K21: 0.073 | L21: SCB
A22: 16 | B22: TD1001583375 | C22: 28.03.25 | D22: 2528 | E22: =2-0 -> 2 | F22: =195-20 -> 175 | G22: =E22+F22 -> 177 | H22: =D22+G22 -> 2705 | I22: 28.07.26 | J22: 2791 | K22: 0.075 | L22: SCB
A23: 17 | B23: TD1001713094 | C23: 26.06.25 | D23: 10309 | E23: 0 | F23: =562-57 -> 505 | G23: =E23+F23 -> 505 | H23: =D23+G23 -> 10814 | I23: 26.06.27 | J23: 11844 | K23: 0.07 | L23: SCB
A24: 18 | B24: TD1001713102 | C24: 26.06.25 | D24: 54200 | E24: 0 | F24: =2955-296 -> 2659 | G24: =E24+F24 -> 2659 | H24: =D24+G24 -> 56859 | I24: 26.06.27 | J24: 62269 | K24: 0.07 | L24: SCB
A25: 19 | B25: TD1002073005 | C25: 27.03.26 | D25: 27023 | E25: 0 | F25: =25-3 -> 22 | G25: =E25+F25 -> 22 | H25: =D25+G25 -> 27045 | I25: 27.03.28 | J25: 30924 | K25: 0.068 | L25: SCB
D26: =SUM(D19:D25) -> 276074 | E26: =SUM(E19:E25) -> 2 | F26: =SUM(F19:F25) -> 14568 | G26: =SUM(G19:G25) -> 14570 | H26: =SUM(H19:H25) -> 290644 | J26: =SUM(J19:J25) -> 312192
B27: Pest Control Fund
A28: 20 | B28: TD1001583788 | C28: 28.03.25 | D28: 10374 | E28: =8-1 -> 7 | F28: =799-80 -> 719 | G28: =E28+F28 -> 726 | H28: =D28+G28 -> 11100 | I28: 28.07.26 | J28: 11454 | K28: 0.075 | L28: SCB
A29: 21 | B29: 6605300016121_03 | C29: 27.11.25 | D29: 147432 | E29: 0 | F29: 3466 | G29: =E29+F29 -> 3466 | H29: =D29+G29 -> 150898 | I29: 27.11.26 | J29: 157716 | K29: 0.068 | L29: MDCC
D30: =SUM(D28:D29) -> 157806 | E30: =SUM(E28:E29) -> 7 | F30: =SUM(F28:F29) -> 4185 | G30: =SUM(G28:G29) -> 4192 | H30: =SUM(H28:H29) -> 161998 | J30: =SUM(J28:J29) -> 169170
B31: Painting Fund
A32: 22 | B32: TD0000415696_02 | C32: 05.06.24 | D32: 22099 | E32: =1296-130 -> 1166 | F32: =1668-167 -> 1501 | G32: =E32+F32 -> 2667 | H32: =D32+G32 -> 24766 | I32: 05.06.27 | J32: 27214 | K32: 0.07 | L32: SCB
A33: 23 | B33: TD0000415681_02 | C33: 04.12.24 | D33: 10790 | E33: =247-25 -> 222 | F33: =789-79 -> 710 | G33: =E33+F33 -> 932 | H33: =D33+G33 -> 11722 | I33: 04.12.27 | J33: 13287 | K33: 0.07 | L33: SCB
A34: 24 | B34: TD1000106202_01 | C34: 08.09.24 | D34: 18192 | E34: =727-73 -> 654 | F34: =1350-137 -> 1213 | G34: =E34+F34 -> 1867 | H34: =D34+G34 -> 20059 | I34: 08.09.27 | J34: 22402 | K34: 0.07 | L34: SCB
A35: 25 | B35: TD1001583354 | C35: 28.03.25 | D35: 27774 | E35: =22-2 -> 20 | F35: =2138-214 -> 1924 | G35: =E35+F35 -> 1944 | H35: =D35+G35 -> 29718 | I35: 28.07.26 | J35: 30665 | K35: 0.075 | L35: SCB
D36: =SUM(D32:D35) -> 78855 | E36: =SUM(E32:E35) -> 2062 | F36: =SUM(F32:F35) -> 5348 | G36: =SUM(G32:G35) -> 7410 | H36: =SUM(H32:H35) -> 86265 | J36: =SUM(J32:J35) -> 93568
B37: Share Capital
A38: 26 | B38: TD0000400904_02 | C38: 21.01.24 | D38: 9000 | E38: 0 | F38: 0 | G38: =E38+F38 -> 0 | H38: =D38+G38 -> 9000 | I38: 21.01.28 | J38: 9000 | K38: 0.07 | L38: SCB
A39: 27 | B39: TD1000225977_01 | C39: 24.01.24 | D39: 9000 | E39: 0 | F39: 0 | G39: =E39+F39 -> 0 | H39: =D39+G39 -> 9000 | I39: 24.01.28 | J39: 9000 | K39: 0.07 | L39: SCB
D40: =SUM(D38:D39) -> 18000 | E40: =SUM(E38:E39) -> 0 | F40: =SUM(F38:F39) -> 0 | G40: =SUM(G38:G39) -> 0 | H40: =SUM(H38:H39) -> 18000 | J40: =SUM(J38:J39) -> 18000
...

Sheet FA Sch_3
A1: =BS!A1 -> DIAGO CO-OPERATIVE HOUSING SOCIETY LIMITED
A2: Schedule 3 - Details of Fixed Assets as on 31st March 2026
A3: Particulars | B3: Rate % | C3: Opening W.D.V as on 01.04.2025 | D3: Additions during the year before 30.09.2025 | E3: Additions during the year after 30.09.2025 | F3: Gross Block (at cost) as on 31.03.2026 | G3: Depreciation for the year | H3: Closing W.D.V as on 31.03.2026
A4: Land and Building | B4: 0 | C4: 45000 | D4: 0 | E4: 0 | F4: =+C4+D4+E4 -> 45000 | G4: =ROUND((C4*B4)+(D4*B4)+(E4*B4/2),0) -> 0 | H4: =F4-G4 -> 45000
A5: Building | B5: 0 | C5: 2182750 | D5: 0 | E5: 0 | F5: =+C5+D5+E5 -> 2182750 | G5: =ROUND((C5*B5)+(D5*B5)+(E5*B5/2),0) -> 0 | H5: =F5-G5 -> 2182750
A6: Office Premises | B6: 0 | C6: 33797 | D6: 0 | E6: 0 | F6: =+C6+D6+E6 -> 33797 | G6: =ROUND((C6*B6)+(D6*B6)+(E6*B6/2),0) -> 0 | H6: =F6-G6 -> 33797
A7: Furniture and Fixture | B7: 0.1 | C7: 2739 | D7: 0 | E7: 0 | F7: =+C7+D7+E7 -> 2739 | G7: =ROUND((C7*B7)+(D7*B7)+(E7*B7/2),0) -> 274 | H7: =F7-G7 -> 2465
A8: Water Pump | B8: 0.15 | C8: 2549 | D8: 0 | E8: 0 | F8: =+C8+D8+E8 -> 2549 | G8: =ROUND((C8*B8)+(D8*B8)+(E8*B8/2),0) -> 382 | H8: =F8-G8 -> 2167
A9: CCTV | B9: 0.15 | C9: 20175 | D9: 0 | E9: 0 | F9: =+C9+D9+E9 -> 20175 | G9: =ROUND((C9*B9)+(D9*B9)+(E9*B9/2),0) -> 3026 | H9: =F9-G9 -> 17149
A10: Total :- | C10: =SUM(C4:C9) -> 2287010 | D10: =SUM(D4:D9) -> 0 | E10: =SUM(E4:E9) -> 0 | F10: =SUM(F4:F9) -> 2287010 | G10: =SUM(G4:G9) -> 3682 | H10: =SUM(H4:H9) -> 2283328
C13: =+C10-C5 -> 104260
H14: =+H10-H5 -> 100578

Sheet Advance n Refundable Sch 4 to 7
A1: =BS!A1 -> DIAGO CO-OPERATIVE HOUSING SOCIETY LIMITED
A2: Schedule 4: Member's Due as on 31st March 2026 | G2: Schedule 7: Payables as on 31st March 2026
A3: Sr | B3: Wing | C3: Flat | D3: Name of Member | E3: Amount | G3: Sl.No | H3: Vendor | I3: Expense Head | J3: Amt
A4: 1 | B4: A | C4: 002 | D4: Ms. Valentine D'Souza | E4: =6912-2930 -> 3982 | G4: 1 | H4: Ecotech Exteriror & Interior Co. | I4: Major Repairs | J4: 5000
A5: Total | E5: =SUM(E4:E4) -> 3982 | G5: 2 | H5: Tata Power | I5: Electricity Expenses | J5: 6651
G6: 3 | H6: BMC | I6: Water Expenses | J6: 19623
A7: Schedule 5: Advance from Members as on 31st March 2026 | G7: 4 | H7: Ivan Rosario | I7: Professional Fees | J7: 1770
A8: Sr | B8: Wing | C8: Flat | D8: Name of Member | E8: Amount | G8: Total | J8: =SUM(J4:J7) -> 33044
A9: 1 | B9: A | C9: 102 | D9: Mrs. Rita D'Souza | E9: 10883
A10: 2 | B10: B | C10: 303 | D10: Mr. Sydney Joe Lobo | E10: 8989
A11: 3 | B11: B | C11: 402 | D11: Mr. Francis Pais | E11: 1511
A12: Total | E12: =SUM(E9:E11) -> 21383
A14: Schedule 6: Refundable Deposit as on 31st March 2026
A15: Sr | B15: Wing | C15: Flat | D15: Name of Member | E15: Amount
A16: 1 | B16: B | C16: 1 | D16: Mr. Lovette Remedios | E16: 2000
A17: 2 | B17: C | C17: 1 | D17: Mr. Nigel P. A. Rodrigues | E17: 2000
A18: 3 | B18: B | C18: 3 | D18: Mr. John V. Rodrigues | E18: 2000
A19: 4 | B19: A | C19: 101 | D19: Mr. Simon P. Pereira | E19: 2000
A20: 5 | B20: A | C20: 102 | D20: Ms. Rita H. D'Souza | E20: 2000
A21: 6 | B21: A | C21: 202 | D21: Mr. Gladston Leo D'souza | E21: 2000
A22: 7 | B22: A | C22: 203 | D22: Mr. Robert D'Souza | E22: 2000
A23: 8 | B23: B | C23: 301 | D23: Mrs. Fatima A. Mascarenhas | E23: 2000
A24: 9 | B24: A | C24: 301 | D24: Mr. Sheldon C. D'Silva | E24: 2000
A25: 10 | B25: A | C25: 303 | D25: Mrs. Chinnamma Joseph | E25: 2000
A26: 11 | B26: B | C26: 303 | D26: Mr. Sydney Joe Lobo | E26: 2000
A27: 12 | B27: A | C27: 403 | D27: Suzie Rupesh Dlima & Rupesh Kaitan Dlima | E27: 2000
D28: Total | E28: =SUM(E16:E27) -> 24000

Sheet Sheet1
