Workbook

Sheet BS
A1: LA SERENA CO-OP.HOUSING SOCIETY LTD.
A2: PLOT No.7&8,SUNDER LANE,ORLEM,MALAD WEST,MUMBAI 400 064.
A3: BOM/HSG/3758 of 1972 Dated-16/9/1972.
A4: BALANCE SHEET AS ON 31st MARCH 2026
A5: FY 2024-25 | B5: LIABILITIES | D5: FY 2025-26 | E5: =A5 -> FY 2024-25 | F5: ASSETS | H5: =D5 -> FY 2025-26
B7: Share Capital | F7: Cash and Bank Balance
B8: Authorised Share Capital | E8: 97 | F8: Cash Account | G8: -4268
A9: 10000 | B9: 200 shares of Rs.50/-each | D9: 10000 | E9: 72489.6 | F9: Citizen Credit Bank (459) | G9: =BRS!C4 -> 67689.6
E10: 819015.53 | F10: SVC Bank (631) | G10: =BRS!C14 -> 1747041.5 | H10: =SUM(G8:G10) -> 1810463.1
B11: Issued,Subscribed & Paidup
A12: 21500 | B12: 430 shares of Rs.50/-each | D12: 21500 | F12: Investments
B13: Reserve Fund & Others | E13: 100 | F13: 1 share of MDHF | G13: 100
A14: 27956 | B14: Opening Balance | C14: =27956+1200+330+2170 -> 31656 | E14: 1342632 | F14: Fixed Deposits with Banks (Sch-I) | G14: ='Sch-I FD'!D30 -> 1577151
A15: 1200 | B15: Add: Addition during the year | C15: 25700 | E15: 31988 | F15: Accrued Interest - FD | G15: ='Sch-I FD'!E30+'Sch-I FD'!F30+'Sch-I FD'!G30-'Sch-I FD'!G16-'Sch-I FD'!G21-'Sch-I FD'!G27 -> 62799
A16: 330 | B16: Add: Interest on FD | C16: =IE!G25 -> 498 | E16: 13461 | F16: Accrued Interest - RD | G16: ='Sch-I FD'!G16+'Sch-I FD'!G21+'Sch-I FD'!G27 -> 15668 | H16: =SUM(G13:G16) -> 1655718
A17: 2170 | B17: Add: 25% Surplus | C17: =IE!C58 -> 50376 | D17: =SUM(C14:C17) -> 108230
B18: Sinking Fund | F18: Security Deposits
A19: 152852 | B19: Opening Balance | C19: =152852+169992+7025 -> 329869 | E19: 34740 | F19: Tata Power | H19: 34740
A20: 169992 | B20: Add: Addition during the year | C20: 169956
A21: 7025 | B21: Add: Interest on FD/RD | C21: =IE!G26 -> 13072 | D21: =SUM(C19:C21) -> 512897 | F21: Other Current Assets
B22: Repair Fund | E22: 13233 | F22: Dues From Members (Sch-IV) | G22: ='Sch-III, IV & V'!D20 -> 23319
A23: 193500 | B23: Opening Balance | C23: =193500+509976+39324 -> 742800 | E23: 216192 | F23: Members Receivable | G23: 0
A24: 509976 | B24: Add: Addition during the year | C24: 509805 | E24: 4736 | F24: TDS Receivables | G24: 10928
A25: 39324 | B25: Add: Interest on FD/RD | C25: =IE!G28 -> 52724 | D25: =SUM(C23:C25) -> 1305329 | E25: 23000 | F25: Advance Payment to Vendors (Sch-V) | G25: ='Sch-III, IV & V'!D29 -> 320420
B26: Education & Training Fund | E26: 3868 | F26: Excess Maint. Receivable (Cecil D'souza) | G26: 3868 | H26: =SUM(G22:G26) -> 358535
A27: 3870 | B27: Opening Balance | C27: =3870+5160+21 -> 9051
A28: 5160 | B28: Add: Addition during the year | C28: 5160 | E28: 15453533 | F28: Fixed Assets (Sch-II) | H28: ='Sch-II FA'!I21 -> 15439046
A29: 21 | B29: Add: Interest on FD | C29: =IE!G27 -> 634 | D29: =SUM(C27:C29) -> 14845
E30: 152155 | F30: Prepaid Expenses (Sch-III) | H30: ='Sch-III, IV & V'!D12 -> 45763
B31: Members Contribution Towards
A32: 15147120 | B32: Land & Building | D32: 15147120
B34: Old Member Account
A35: 81340.53 | B35: As Per last B/s. | C35: ='Old Member Balance'!F3 -> 81340.53
A36: -61005 | B36: Less: Refunded to Members | C36: ='Old Member Balance'!E20 -> 65072 | D36: =C35-C36 -> 16268.53
B38: Current Liabilities & Provisions
A39: 116328 | B39: Advance from Members (Sch-VI) | C39: ='Sch-VI & VII'!D13 -> 125806
A40: 4084 | B40: TDS Payable | C40: 425
A41: 64003 | B41: Payables & Provision (Sch-VII) | C41: ='Sch-VI & VII'!D36 -> 246224.5 | D41: =SUM(C39:C41) -> 372455.5
B43: Income & Expenditure Account
A44: 1687985 | B44: As per last B/s | C44: =1687985+6508.6 -> 1694493.6
...

Sheet IE
A1: LA SERENA CO-OP.HOUSING SOCIETY LTD.
A2: PLOT No.7&8,SUNDER LANE,ORLEM,MALAD WEST,MUMBAI 400 064.
A3: BOM/HSG/3758 of 1972 Dated-16/9/1972.
A4: INCOME AND EXPENDITURE ACCOUNT FOR THE YEAR ENDED MARCH 31, 2026
A5: FY 2024-25 | B5: Expenditure | D5: FY 2025-26 | E5: =A5 -> FY 2024-25 | F5: Income | H5: =D5 -> FY 2025-26
B7: Salary Expenses | F7: Members Contribution Towards
A8: 129600 | B8: Salary & Wages | C8: 12000 | E8: 503760 | F8: Maintenance/AMC Charges | G8: =1135904+216000 -> 1351904
A9: 38800 | B9: Bonus | C9: 22292 | D9: =SUM(C8:C9) -> 34292 | E9: 140352 | F9: House Keeping Charges | G9: 0
E10: 237360 | F10: Electricity Charges | G10: 315792
A11: 52864 | B11: Municipal Taxes | D11: 58148 | E11: 363780 | F11: Security Charges | G11: 0
E12: 258000 | F12: Water Charges | G12: 80246
A13: 315504 | B13: Electricity Charges | D13: 282919 | E13: 34572 | F13: Accounting Charges | G13: 0
E14: 62436 | F14: Municipal Tax | G14: 58308
B15: Water Expense | E15: 99850 | F15: Parking Charges | G15: =53700+67900+21700+100 -> 143400
A16: 67468 | B16: BMC Water | C16: 87772 | E16: 25068 | F16: Insurance Charges | G16: 29985
A17: 248600 | B17: Water Tanker Expense | C17: 0 | D17: =SUM(C16:C17) -> 87772 | E17: 30705 | F17: Non Occupancy Charges | G17: 31672
E18: 16664 | F18: Interest from Members | G18: 2087
E19: 126 | F19: Misc.Charges | G19: 0 | H19: =SUM(G8:G19) -> 2013394
B20: Repair & Maintenance
A21: 59536 | B21: R & M - Others | C21: 61020.5 | F21: Interest from Bank
A22: 0 | B22: R & M - CCTV | C22: 2800 | E22: 41959 | F22: Saving Interest | G22: 45539
A23: 3000 | B23: R & M - AC | C23: 0 | E23: 33394 | F23: Fixed Deposit Interest | G23: 68684
A24: 18250 | B24: R & M - Electricals | C24: 45006 | E24: 14957 | F24: Recurring Deposit Interest | G24: 23490
A25: 95879 | B25: R & M - Plumbing | C25: 2700 | E25: -330 | F25: Less: Trfd to Reserve Fund | G25: 498
A26: 12586 | B26: R & M - Fire Fighting | C26: 0 | E26: -7025 | F26: Less: Trfd to Sinking Fund | G26: 13072
A27: 8000 | B27: Water Tank Cleaning Charges | C27: 8100 | E27: -21 | F27: Less: Trfd to Education Fund | G27: 634
A28: 23205 | B28: Water Pump Repair Charges | C28: 3179 | D28: =SUM(C21:C28) -> 122805.5 | E28: -39324 | F28: Less: Trfd to Repair Fund | G28: 52724 | H28: =G22+G23+G24-G25-G26-G27-G28 -> 70785
B30: Annual Maintenance Charges
A31: 150764 | B31: AMC - Lift | C31: 155100
A32: 3877 | B32: AMC - Intercom | C32: 5000
A33: 8333 | B33: AMC - Pest Control | C33: 10250
A34: 12500 | B34: AMC - Fire Fighting | C34: 50000
A35: 64900 | B35: AMC - Stack Parking | C35: 372074
A36: 8529 | B36: AMC - CCTV | C36: 11775 | D36: =SUM(C31:C36) -> 604199
B38: Administrative/Other Expenses
A39: 336000 | B39: Security Charges | C39: 336000
A40: 0 | B40: Housekeeping Expense | C40: 158097
A41: 35700 | B41: Accounting Charges | C41: 44400
A42: 18833 | B42: Insurance Charges | C42: 38416
A43: 1888 | B43: Meeting Expenses | C43: 8153
...

Sheet Sch-I FD
A1: Sch I | B1: La Serena CHS Ltd
B2: Fixed Deposits as at 31.03.2025
A3: Sr.No | B3: Certificate No | C3: Date | D3: Principal Amount | E3: FY 23-24 Accrued Interest | F3: FY 24-25 Accrued Interest | G3: FY 25-26 Accrued Interest | H3: Total | I3: Maturity Date | J3: Maturity Value | K3: Int % | L3: Bank
B4: Share Capital
A5: 1 | B5: 44039 | C5: 05.04.2023 | D5: 21500 | E5: 1528 | F5: =1651-165 -> 1486 | G5: =(428+436+443+449)-(42+44+44+45) -> 1581 | H5: =SUM(D5:G5) -> 26095 | I5: 05.04.2028 | J5: 30418 | K5: 7 | L5: SVC
D6: =SUM(D5:D5) -> 21500 | E6: =SUM(E5:E5) -> 1528 | F6: =SUM(F5:F5) -> 1486 | G6: =SUM(G5:G5) -> 1581 | H6: =SUM(H5:H5) -> 26095 | J6: =SUM(J5:J5) -> 30418
B8: Reserve Fund
A9: 2 | B9: 44040 | C9: 05.04.2023 | D9: 4300 | E9: 306 | F9: =330-33 -> 297 | G9: =(85+87+89+90)-(8+8+9+9) -> 317 | H9: =SUM(D9:G9) -> 5220 | I9: 05.04.2028 | J9: 6084 | K9: 7 | L9: SVC
B10: 496244 | C10: 17.03.2026 | D10: 52453 | E10: 0 | F10: 0 | G10: =147-15 -> 132 | H10: =SUM(D10:G10) -> 52585
D11: =SUM(D9:D10) -> 56753 | E11: =SUM(E9:E10) -> 306 | F11: =SUM(F9:F10) -> 297 | G11: =SUM(G9:G10) -> 449 | H11: =SUM(H9:H10) -> 57805 | J11: =SUM(J9:J10) -> 6084
B13: Repair Fund
A14: 3 | B14: 1000112701_1 | C14: 04.06.2025 | D14: 494920 | E14: 0 | F14: 0 | G14: =(2691+8992+9149+9288)-(1482+899+915+929) -> 25895 | H14: =SUM(D14:G14) -> 520815 | L14: SVC
A15: 4 | B15: 101043021003944 | C15: 19.03.2025 | D15: 236500 | E15: 0 | F15: =544-0 -> 544 | G15: =16556-0 -> 16556 | H15: =SUM(D15:G15) -> 253600 | I15: 19.03.2030 | J15: 319275 | K15: 7 | L15: CCB
A16: 5 | B16: RD-334624 | C16: 11.06.2025 | D16: 424860 | E16: 0 | F16: 0 | G16: =(164+1982+4263+6550)-(17+198+427+655) -> 11662 | H16: =SUM(D16:G16) -> 436522 | L16: SVC
D17: =SUM(D14:D16) -> 1156280 | E17: =SUM(E14:E16) -> 0 | F17: =SUM(F14:F16) -> 544 | G17: =SUM(G14:G16) -> 54113 | H17: =SUM(H14:H16) -> 1210937 | J17: =SUM(J14:J16) -> 319275
B19: Sinking Fund
A20: 6 | B20: 101043021003955 | C20: 19.03.2025 | D20: 186768 | E20: 0 | F20: =430-0 -> 430 | G20: =13072-0 -> 13072 | H20: =SUM(D20:G20) -> 200270 | I20: 19.03.2030 | J20: 252137 | K20: 7 | L20: CCB
A21: 7 | B21: RD-334596 | C21: 11.06.2025 | D21: 141660 | E21: 0 | F21: 0 | G21: =(55+661+1421+2184)-(6+66+142+218) -> 3889 | H21: =SUM(D21:G21) -> 145549 | L21: SVC
D22: =SUM(D20:D21) -> 328428 | E22: =SUM(E20:E21) -> 0 | F22: =SUM(F20:F21) -> 430 | G22: =SUM(G20:G21) -> 16961 | H22: =SUM(H20:H21) -> 345819 | J22: =SUM(J20:J21) -> 252137
B24: Education Fund
A25: 8 | B25: 101043021003939 | C25: 19.03.2025 | D25: 9030 | E25: 0 | F25: =21-0 -> 21 | G25: =632-0 -> 632 | H25: =SUM(D25:G25) -> 9683 | I25: 19.03.2030 | J25: 12191 | K25: 7 | L25: CCB
B26: 496253 | C26: 17.03.2026 | D26: 860 | E26: 0 | F26: 0 | G26: =2 -> 2 | H26: =SUM(D26:G26) -> 862 | L26: SVC
B27: RD-334630 | C27: 11.06.2025 | D27: 4300 | E27: 0 | F27: 0 | G27: =(2+20+43+66)-(1+2+4+7) -> 117 | H27: =SUM(D27:G27) -> 4417 | L27: SVC
D28: =SUM(D25:D27) -> 14190 | E28: =SUM(E25:E27) -> 0 | F28: =SUM(F25:F27) -> 21 | G28: =SUM(G25:G27) -> 751 | H28: =SUM(H25:H27) -> 14962 | J28: =SUM(J25:J27) -> 12191 | L28: SVC
B30: Total | D30: =D6+D11+D17+D22+D28 -> 1577151 | E30: =E6+E11+E17+E22+E28 -> 1834 | F30: =F6+F11+F17+F22+F28 -> 2778 | G30: =G6+G11+G17+G22+G28 -> 73855 | H30: =H6+H11+H17+H22+H28 -> 1655618 | J30: =J6+J11+J17+J22+J28 -> 620105

Sheet Sch-II FA
B2: ='Sch-I FD'!B1:L1 -> La Serena CHS Ltd
B3: Schedule - II
B4: Fixed Asset & Depreciation as on 31st March 2026
B5: Particulars | C5: ROD | D5: Opening W.D.V. as on 01.04.2025 | E5: Additions during the year before 30.09.2025 | F5: Additions during the year after 30.09.2025 | G5: Gross Block (at cost) as on 31.03.2026 | H5: Depreciation for the year | I5: Closing W.D.V. as on 31.03.2026
B6: Land & Building | C6: 0 | D6: 15147120 | E6: 0 | F6: 0 | G6: =D6+E6+F6 -> 15147120 | H6: =ROUND((D6*C6)+(E6*C6)+(F6*C6/2),0) -> 0 | I6: =G6-H6 -> 15147120
B8: Water Pump | C8: 0.15 | D8: 50575 | E8: 0 | F8: 0 | G8: =D8+E8+F8 -> 50575 | H8: =ROUND((D8*C8)+(E8*C8)+(F8*C8/2),0) -> 7586 | I8: =G8-H8 -> 42989
B10: Furniture & Fixture | C10: 0.1 | D10: 14499 | E10: 12000 | F10: 0 | G10: =D10+E10+F10 -> 26499 | H10: =ROUND((D10*C10)+(E10*C10)+(F10*C10/2),0) -> 2650 | I10: =G10-H10 -> 23849
B12: Intercom | C12: 0.15 | D12: 43350 | E12: 0 | F12: 0 | G12: =D12+E12+F12 -> 43350 | H12: =ROUND((D12*C12)+(E12*C12)+(F12*C12/2),0) -> 6503 | I12: =G12-H12 -> 36847
B14: CCTV | C14: 0.15 | D14: 114615 | E14: 0 | F14: 0 | G14: =D14+E14+F14 -> 114615 | H14: =ROUND((D14*C14)+(E14*C14)+(F14*C14/2),0) -> 17192 | I14: =G14-H14 -> 97423
B16: Water Meter | C16: 0.15 | D16: 69375 | E16: 0 | F16: 0 | G16: =D16+E16+F16 -> 69375 | H16: =ROUND((D16*C16)+(E16*C16)+(F16*C16/2),0) -> 10406 | I16: =G16-H16 -> 58969
B18: Letter Box | C18: 0.1 | D18: 0 | E18: 0 | F18: 24684 | G18: =D18+E18+F18 -> 24684 | H18: =ROUND((D18*C18)+(E18*C18)+(F18*C18/2),0) -> 1234 | I18: =G18-H18 -> 23450
B20: Computer & Printer | C20: 0.4 | D20: 13999 | E20: 0 | F20: 0 | G20: =D20+E20+F20 -> 13999 | H20: =ROUND((D20*C20)+(E20*C20)+(F20*C20/2),0) -> 5600 | I20: =G20-H20 -> 8399
B21: Total | D21: =SUM(D6:D20) -> 15453533 | E21: =SUM(E6:E20) -> 12000 | F21: =SUM(F6:F20) -> 24684 | G21: =SUM(G6:G20) -> 15490217 | H21: =SUM(H6:H20) -> 51171 | I21: =SUM(I6:I20) -> 15439046

Sheet Sch-III, IV & V
A2: La Serena CHS Ltd
A3: Sch-III
A4: Prepaid Expense as of 31.03.2026
A5: Sr. | B5: Vendor | D5: Amount (Rs.)
A6: 1 | B6: Intercom AMC | D6: =Working!F17 -> 1123
A7: 2 | B7: Fire Fighting AMC | D7: 0
A8: 3 | B8: CCTV AMC | D8: =Working!F25 -> 2696
A9: 4 | B9: Lift AMC | D9: =Working!F13 -> 27289
A10: 5 | B10: Insurance | D10: =Working!F29 -> 12938
A11: 6 | B11: Pest Control AMC | D11: =Working!F33 -> 1717
A12: Total | D12: =SUM(D6:D11) -> 45763
A15: Sch-IV
A16: Members' Receivables as at 31.03.2026
A17: Sr. | B17: Flat | C17: Name of Member | D17: Amount (Rs.)
A18: 1 | B18: 0401 | C18: Mr. John D'Souza | D18: 10946
A19: 2 | B19: 0501 | C19: Mr. Domnic G. C. Miranda | D19: 12373
A20: Total | D20: =SUM(D18:D19) -> 23319
A23: Sch-V
A24: Advance Payament to Vendors as of 31.03.2026
A25: Sr. | B25: Account | C25: Vendor | D25: Amount (Rs.)
A26: 1 | B26: Water Meter | C26: Mukesh Badge | D26: 23000
A27: 2 | B27: Solar System | C27: MNM Solar Power | D27: 293975
A28: 3 | B28: TDS | C28: Ivan Rosario | D28: 3445
A29: Total | D29: =SUM(D26:D28) -> 320420

Sheet Sch-VI & VII
A3: Sch-VI
A4: La Serena CHS Ltd
A5: Advance Members as of 31.03.2026
A6: Sr.no. | B6: Flat | C6: Name | D6: Amount
A7: 1 | B7: 0201 | C7: Mr. Jaison David & Mrs. Jefna Jaison | D7: 25185
A8: 2 | B8: 0202 | C8: Mr. Rudolph Rodrigues | D8: 7355
A9: 3 | B9: 0301 | C9: Mr. Rozario Carvalho | D9: 6745
A10: 4 | B10: 0801 | C10: Mr. Archie Fernandes & Mr. Joseph Fernandes | D10: 44446
A11: 5 | B11: 0802 | C11: Mr. Godfrey Sequeira | D11: 4119
A12: 6 | B12: 1003 | C12: Mrs. Samiksha Niraj Desai Sheth | D12: 37956
A13: Total | D13: =SUM(D7:D12) -> 125806
A16: Sch-VII
A17: Payables as of 31.03.2026
A18: Sr. | B18: Account | C18: Vendor | D18: Amount (Rs.)
A19: 1 | B19: Electricity | C19: Tata Power | D19: 452
A20: 2 | C20: Ram Kishor Bind | D20: 2000
A21: 3 | C21: Sher Ali M. Qureshi | D21: 4887.5
A22: 4 | C22: Singh Detective Service | D22: 42075
A23: 5 | C23: MCGM | D23: 65213
A24: Total (A) | D24: =SUM(D19:D23) -> 114627.5
A27: Provision as of 31.03.2026
A28: Sr. | B28: Account | C28: Vendor | D28: Amount (Rs.)
A29: 1 | B29: Audit Fees | C29: Auditor | D29: 4300
A30: 2 | B30: Water Expense | C30: BMC | D30: 33425
A31: 3 | B31: Subscription | C31: MDFH | D31: 826
A32: 4 | B32: Wohr Parking | C32: Stack AMC | D32: 69446
A33: 5 | B33: Ceasex Fire | C33: Fire Fighting AMC | D33: 12500
C34: Income Tax | D34: =Working!N17 -> 11100
A35: Total (B) | D35: =SUM(D29:D34) -> 131597
A36: Total (A+B) | D36: =D24+D35 -> 246224.5

Sheet BRS
B1: La Serena CHS Ltd.
B2: Citizen Credit Bank as of 31.03.2026
C3: Amount
B4: Balance as per System (Book Balance) | C4: 67689.6
B6: Balance as per Passbook | C6: 67689.6
B12: SVCC Bank as of 31.03.2026
C13: Amount
B14: Balance as per System (Book Balance) | C14: 1747041.5
B16: Balance as per Passbook | C16: 1747041.5

Sheet Working
A1: Sr. no. | B1: Account head | C1: Period | E1: No. of days | F1: Amount
C2: From | D2: To
J3: 8 | K3: Income Tax Provision
A4: 1 | B4: Water Expense | K4: Income from Savings A/c. | N4: =IE!G22 -> 45539
C5: 45750 | D5: 45841 | E5: =D5-C5+1 -> 92 | F5: 17983 | K5: Income from FD/RD | N5: =IE!G23+IE!G24 -> 92174
C6: =D5 -> 45841 | D6: 45933 | E6: =D6-C6+1 -> 93 | F6: 17705 | K6: Interest on IT Refund | N6: 0
C7: =D6 -> 45933 | D7: 46024 | E7: =D7-C7+1 -> 92 | F7: 18659 | K7: Sale of scrap & Promotional | N7: 0
C8: =C5 -> 45750 | D8: =D7 -> 46024 | E8: =SUM(E5:E7) -> 277 | F8: =SUM(F5:F7) -> 54347 | K8: Gross Taxable Income | N8: =SUM(N4:N7) -> 137713
C9: =D8 -> 46024 | D9: 46112 | E9: =D9-C9 -> 88 | F9: =ROUND(34185/90*E9,) -> 33425 | G9: Provision | J9: Less: | K9: Deduction U/S 80P | N9: =N5 -> 92174
K10: Net Taxable Income | N10: =N8-N9 -> 45539
A11: 2 | B11: Lift AMC | K11: 0-10000 | M11: 0.1 | N11: 1000
C12: 45992 | D12: 46173 | E12: =D12-C12+1 -> 182 | F12: =43070+38350 -> 81420 | K12: 10000-20000 | M12: 0.2 | N12: 2000
C13: 46113 | D13: =D12 -> 46173 | E13: =D13-C13+1 -> 61 | F13: =ROUND(E13*F12/E12,0) -> 27289 | G13: Prepaid | K13: 20000 or More | M13: 0.3 | N13: =ROUND((N10-20000)*M13,0) -> 7662
K14: Tax | N14: =SUM(N11:N13) -> 10662
A15: 3 | B15: Intercom AMC | J15: Add | K15: Education cess | M15: 0.04 | N15: =ROUND(N14*M15,0) -> 426
C16: 45830 | D16: 46194 | E16: =D16-C16+1 -> 365 | F16: 5000 | K16: Total Tax | N16: =SUM(N14:N15) -> 11088
C17: 46113 | D17: =D16 -> 46194 | E17: =D17-C17+1 -> 82 | F17: =ROUND(E17*F16/E16,0) -> 1123 | G17: Prepaid | K17: Say | N17: =ROUND(N16,-2) -> 11100
A19: 4 | B19: Fire Fighting AMC
C20: 45748 | D20: 45992 | E20: 9 | F20: =50000-12500 -> 37500
C21: 46023 | D21: 46082 | E21: 3 | F21: =ROUND(E21*F20/E20,0) -> 12500 | G21: Provision
A23: 5 | B23: CCTV AMC
C24: 45830 | D24: 46194 | E24: =D24-C24+1 -> 365 | F24: 12000
C25: 46113 | D25: =D24 -> 46194 | E25: =D25-C25+1 -> 82 | F25: =ROUND(E25*F24/E24,0) -> 2696 | G25: Prepaid
A27: 6 | B27: Insurance
C28: 45858 | D28: 46222 | E28: =D28-C28+1 -> 365 | F28: =36084+1649+5196 -> 42929
C29: 46113 | D29: =D28 -> 46222 | E29: =D29-C29+1 -> 110 | F29: =ROUND(E29*F28/E28,0) -> 12938 | G29: Prepaid
A31: 7 | B31: Pest Control AMC
C32: 45809 | D32: 46143 | E32: 12 | F32: 10300
C33: 46113 | D33: =D32 -> 46143 | E33: 2 | F33: =ROUND(E33*F32/E32,0) -> 1717 | G33: Prepaid

Sheet Old Member Balance
A1: La Serena CHS Ltd - Old Member Balance
A2: Sr, no. | B2: Account | C2: Posted Date | D2: Comments | E2: Debit | F2: Credit
A3: 1 | B3: Old Member Balance | C3: 01-04-2024 | D3: Opening balance as on 01.04.2024 | F3: 81340.53
A4: 2 | B4: Flat 101 | C4: 29-04-2025 | D4: Being balance amount of Flat 101 refunded vide ch. 031174 | E4: 4067
A5: 3 | B5: Flat 102 | C5: 25-10-2024 | D5: Being balance amount of Flat 102 refunded vide ch. 020030 | E5: 4067
A6: 4 | B6: Flat 202 | C6: 25-10-2024 | D6: Being balance amount of Flat 202 refunded vide ch. 026302 | E6: 4067
A7: 5 | B7: Flat 301 | C7: 25-10-2024 | D7: Being balance amount of Flat 301 refunded vide ch. 020032 | E7: 4067
A8: 6 | B8: Flat 302 | C8: 22-10-2024 | D8: Being balance amount of Flat 302 refunded vide ch. 020033 | E8: 4067
A9: 7 | B9: Flat 401 | C9: 22-10-2024 | D9: Being balance amount of Flat 401 refunded vide ch. 020034 | E9: 4067
A10: 8 | B10: flat 402 | C10: 25-10-2024 | D10: Being balance amount of Flat 402 refunded vide ch. 020035 | E10: 4067
A11: 9 | B11: Flat 502 | C11: 22-10-2024 | D11: Being balance amount of Flat 502 refunded vide ch. 020037 | E11: 4067
A12: 10 | B12: Flat 602 | C12: 25-10-2024 | D12: Being balance amount of Flat 602 refunded vide ch. 020038 | E12: 4067
A13: 11 | B13: Flat 603 | C13: 22-10-2024 | D13: Being balance amount of Flat 603 refunded vide ch. 020045 | E13: 4067
A14: 12 | B14: Flat 701 | C14: 22-10-2024 | D14: Being balance amount of Flat 701 refunded vide ch. 020039 | E14: 4067
A15: 13 | B15: Flat 702 | C15: 22-10-2024 | D15: Being balance amount of warren Monteiro refunded vide ch. 020047 | E15: 4067
... A19: 17 | B19: Flat 1001 | C19: 25-10-2024 | D19: Being balance amount of Flat 1001 refunded vide ch. 020042 | E19: 4067
E20: =SUM(E3:E19) -> 65072 | F20: =SUM(F3:F19) -> 81340.53 | G20: =F20-E20 -> 16268.53 | H20: Balance

Sheet Interest
A1: Dosti Corona ( Dosti Imperia) Co.op housing society Ltd. - Income - Non Members > Interest Income - Fixed Deposits ( 306002 ) <br>Transactions From 01-04-2022 to 30-04-2023
A2: Journal No. | B2: Posted Date | C2: Comments | D2: Debit | E2: Credit | F2: Account
A3: JE-2022-0000342 | B3: 06-07-2022 | C3: Being old FD TD0000439672 renewed vide new FD TD0000439672-1 RF SCB | E3: 6987 | F3: RF
A4: JE-2022-0000345 | B4: 29-09-2022 | C4: Being old FD TD0000439766 renewed vide new FD TD0000439766-1 GF SCB | E4: 728 | F4: Res.
A5: JE-2022-0000349 | B5: 13-11-2022 | C5: Being old FD 12458-1 renewed vide new FD 12458-2 Corp. UBI | E5: 70590 | F5: Corp
A6: JE-2022-0000347 | B6: 30-12-2022 | C6: Being FD TD0000439674 redeemed on maturity SCB - RMF | E6: 27590 | F6: RF
A7: JE-2022-0000348 | B7: 30-12-2022 | C7: Being FD TD0000439675 redeemed on maturity SCB - GF | E7: 4918 | F7: Res.
A8: JE-2022-0000343 | B8: 30-12-2022 | C8: Being old FD TD0000439673-1 renewed vide new FD TD0000439673-2 SF SCB | E8: 27594 | F8: SF
A9: JE-2022-0000344 | B9: 30-12-2022 | C9: Being old FD TD0000439676-1 renewed vide new FD TD0000439676-2 E&T SCB | E9: 808 | F9: ETF
A10: JE-2022-0000351 | B10: 19-01-2023 | C10: Being old FD 349022 renewed vide new FD 13612 SF UBI | E10: 41749 | F10: SF
A11: JE-2022-0000352 | B11: 19-01-2023 | C11: Being old FD 349023 renewed vide new FD 13613 ET UBI | E11: 2442 | F11: ETF
A12: JE-2022-0000350 | B12: 15-02-2023 | C12: Being old FD 12758-1 renewed vide new FD 16416 Corp. UBI | E12: 77702 | F12: Corp
A13: JE-2022-0000353 | B13: 31-03-2023 | C13: Being accrued int. on FD TD0000439679 SF SCB | E13: 54793 | F13: SF
A14: JE-2022-0000354 | B14: 31-03-2023 | C14: Being accrued int. on FD TD0000439673-2 SF SCB | E14: 12802 | F14: SF
... A36: JE-2022-0000377 | B36: 31-03-2023 | C36: Being accrued int. on FD 30013282 Corp. UBI | E36: 111859 | F36: Corp
A37: Balance : | B37: ₹1,081,151.00(Credit) | E37: ₹1,081,151.00
