Workbook

Sheet BS
A1: FORM N
A2: [See Rule 62(1) of the MCS Rules 1961]
A3: NIKITA CO-OPERATIVE HOUSING SOCIETY LTD.
A4: (Reg. MUM-2/WL/HSG/(TC)/8845/2002-03 Dt. 14.07.2003)
A6: Balance Sheet as at 31st March, 2026
H7: (Amt. in Rs.)
A8: Previous Year 31.03.2025 | B8: LIABILITIES | D8: Current Year 31.03.2026 | E8: =A8 -> Previous Year 31.03.2025 | F8: ASSETS | H8: =D8 -> Current Year 31.03.2026
B9: AUTHORISED SHARE CAPITAL | F9: CASH AND BANK BALANCE :
A10: =12000*50 -> 600000 | B10: ( 12,000 shares of ₹50 each) | D10: =12000*50 -> 600000 | E10: 496 | F10: Cash in Hand | G10: 430
E11: 131862.21 | F11: State Bank of India | G11: =BRS!D11 -> 1332539.9
B12: Issued, Subscribed and Paid-Up Share Capital : | E12: 39627.14 | F12: NKGSB Co-op Bank | G12: =BRS!D4 -> 17012.74
A13: 29000 | B13: ( 580 shares of ₹50 each ) | D13: =580*50 -> 29000 | E13: 46906 | F13: MDCC Bank | G13: =47282+1078 -> 48360 | H13: =SUM(G10:G13) -> 1398342.6
B15: RESERVE FUNDS AND OTHER FUNDS | F15: INVESTMENTS & DEPOSITS :
A16: 4431689.2 | B16: (Refer Schedule - I) | D16: ='Sch I'!E37 -> 5150119.2 | E16: 21000 | F16: 21 MDCC Shares | H16: 21000
E17: 100 | F17: 1 Share of Mumbai District Federation | H17: 100
B18: CURRENT LIABILITIES :
A19: 891570 | B19: (Refer Schedule - V) | D19: ='Sch V'!C32 -> 880416 | E19: 3898635 | F19: Fixed Deposits (Refer Schedule - II) | G19: ='Sch II'!D23 -> 4252088
E20: 132634 | F20: Accrued Interest on FDRs with Bank | G20: ='Sch II'!E23+'Sch II'!F23+'Sch II'!G23 -> 108297 | H20: =SUM(G19:G20) -> 4360385
A21: 155891.03 | B21: Advance from Members (Refer Schedule - III) | D21: ='Sch III, IV'!E20 -> 122401.03
E22: 27340.81 | F22: Deposit with MSDCL | G22: 27340.81
A23: 5113 | B23: Unidentified Receipts - Sch VII | D23: ='Sch III, IV'!E42 -> 5113 | E23: 5000 | F23: Election Deposit | G23: 5000 | H23: =G22+G23 -> 32340.81
B25: INCOME & EXPENDITURE ACCOUNT : | F25: Sundry Debtors :
A26: 1218687.7 | B26: Op. Balance as per Last year | C26: =SUM(A26:A27) -> 1129429.6 | E26: 616228.24 | F26: Dues from Members (Refer Schedule - IV) | G26: ='Sch III, IV'!E34 -> 1250846
A27: =-IE!E37 -> -89258.12 | B27: Less: Excess of Expense over Income | C27: =IE!D51 -> 1323598 | D27: =SUM(C26:C27) -> 2453027.6 | E27: 108027.72 | F27: NIKITA Car Parking CR | G27: 108027.72 | H27: =SUM(G26:G27) -> 1358873.7
F29: DEPOSITS & ADVANCES :
E30: 0 | F30: Advance with Savita Gagat | G30: 15000
E31: 6490 | F31: Advance with Bajaj Alianz Receivable | G31: 6490
E32: 27031 | F32: Taxes Receivable | G32: ='Sch V'!C40 -> 7934 | H32: =SUM(G30:G32) -> 29424
F34: FIXED ASSETS :
E35: 1466322.7 | F35: (Refer Schedule - VI) | H35: ='Sch VI'!H17 -> 1246691.7
F37: OTHER ASSETS:
E38: 71457 | F38: Prepaid Lift AMC | G38: 129046
E39: 16335 | F39: Prepaid CCTV AMC | G39: 18618
E40: 27200 | F40: Prepaid Insurance Expense | G40: 23356
E41: 0 | F41: Prepaid Pest Control | G41: 1839
E42: 0 | F42: Prepaid ADDA Subscription | G42: 20060 | H42: =SUM(G38:G42) -> 192919
A43: =SUM(A13:A42) -> 6642692.8 | B43: Total | D43: =SUM(D13:D42) -> 8640076.8 | E43: =SUM(E10:E42) -> 6642692.8 | F43: Total | H43: =SUM(H10:H42) -> 8640076.8
A44: =A43-E43 -> 0 | E44: =E43-A43 -> 0 | H44: =H43-D43 -> 0
A45: As per my report of even date | E45: For NIKITA CO-OPERATIVE HOUSING SOCIETY LTD.
E51: Chairperson Hon. Secretary Hon. Treasurer
...

Sheet IE
A1: FORM N
A2: [See Rule 62(1) of the MCS Rules 1961]
A3: NIKITA CO-OPERATIVE HOUSING SOCIETY LTD
A4: (Reg. MUM-2/WL/HSG/(TC)/8845/2002-03 Dt. 14.07.2003)
A6: Income and Expenditure Account for the year ended 31st March, 2026
H7: (Amt. in Rs.)
A8: Previous Year 31.03.2025 | B8: EXPENDITURE | D8: Current Year 31.03.2026 | E8: =A8 -> Previous Year 31.03.2025 | F8: INCOME | H8: =D8 -> Current Year 31.03.2026
B9: To Property Related Expenditure: | F9: By Member's Contribution Towards:
A10: 662494 | B10: Property Tax Expenses | C10: 761468 | E10: 209496 | F10: Administrative Charges | G10: 209496
A11: 631054 | B11: Water Expense | C11: 424632 | E11: 360528 | F11: Common Electricity Charges | G11: 360528
A12: 403723 | B12: Common Area Electricity Expense | C12: 461827 | E12: 149640 | F12: Employee Cost | G12: 149640
A13: 41278 | B13: Insurance Expenses | C13: 38640 | D13: =SUM(C10:C13) -> 1686567 | E13: 125280 | F13: Lift Maintenance Charges | G13: 125280
E14: 20184 | F14: Pest Control Charges | G14: 20184
B15: To Repair and Maintenance Expenses: | E15: 565848 | F15: Security Service Charges | G15: 565848
A16: 172400 | B16: Lift AMC/Repair and Maintenance | C16: 181419 | E16: 48804 | F16: Insurance Premium | G16: 45297
A17: 7698 | B17: Electrical Repair Maintenance | C17: =10191+17500-15000 -> 12691 | E17: 630383 | F17: Property Tax | G17: 756477
A18: 150504 | B18: Other Repair Maintenance | C18: =168130+10500+7000-10000-19600 -> 156030 | E18: 34050 | F18: Vehicle Washing Charges | G18: 40100
A19: 0 | B19: Garden Maintenance Expenses | C19: =9000+10000 -> 19000 | E19: 546120 | F19: Water Charges | G19: 546120
A20: 16335 | B20: CCTV Repair and Maintenance | C20: 32038 | E20: 128760 | F20: Legal & Accounting Charges | G20: 128760
A21: 9020 | B21: Water System Repair and Maintenace | C21: =10000+5000+19600 -> 34600 | E21: 94745 | F21: Non-Occupancy Charges | G21: =97860 -> 97860
A22: 7000 | B22: Water Tank Cleaning Expenses | C22: =16500-10500 -> 6000 | D22: =SUM(C16:C22) -> 441778 | E22: 0 | F22: Penalty | G22: 177
E23: 6400 | F23: Visitior Car Parking Charges | G23: 19150
B24: To Service Charges: | E24: 93200 | F24: Annual Open Parking Charges | G24: 100250
A25: 577000 | B25: Security Expenses | C25: 581393 | E25: 76232 | F25: Late Payment Charges | G25: =89169 -> 89169 | H25: =SUM(G10:G25) -> 3254336
A26: 5461 | B26: Housekeeping Expenses | C26: 11145
A27: 6000 | B27: Audit Fees | C27: 5800 | F27: By Interest Income:
A28: 17345 | B28: Software Subscription Expenses | C28: 20060 | E28: 3250 | F28: Interest Income - Savings Bank | G28: =698+1078 -> 1776
A29: 30226 | B29: Pest Control Expenses | C29: 32661 | E29: 270283 | F29: Interest Income - Fixed Deposit | G29: 289277
A30: 192000 | B30: Salary Expenses | C30: 208000 | D30: =SUM(C25:C30) -> 859059 | E30: -32640 | F30: Less: trf to Sinking Fund | G30: -40426 | H30: =SUM(G28:G30) -> 250627
B32: To Office Expenses: | F32: By Other Income:
A33: 12000 | B33: Accounting Charges | C33: 12000 | E33: 2 | F33: Misc. Income | H33: 1760
A34: 0 | B34: Election Expenses | C34: 15000
A35: 3938 | B35: Printing and Stationary | C35: 6052 | E35: 0 | F35: Recovery Charges U/s 88 | H35: =1057126.4+535540 -> 1592666.4
A36: 6209 | B36: Meeting Expenses | C36: 1237
A37: 15072 | B37: Conveyance Charges | C37: 3631 | E37: =A52-SUM(E9:E33) -> 89258.12 | F37: Excess of Expenditure over Income
A38: 18 | B38: Postage | C38: 272
A39: 79700 | B39: Legal Fees | C39: 11660
A40: 31000 | B40: Professional Fees | C40: 4328
A41: 25409 | B41: Professional Fees (Recovery Proceedings) | C41: 0
A42: 826 | B42: Federation Subscription | C42: 826
...

Sheet Sch I
A1: NIKITA CO-OP. HOUSING SOCIETY LIMITED
A3: Schedule I
A4: Reserve Funds and Other Funds as at 31st March, 2026
E5: (Amt. in Rs.)
A6: Sr. | B6: 31.03.2024 | C6: Particulars | D6: 31.03.2022 | E6: 31.03.2025
A7: 1 | C7: Sinking Fund :
B8: 997845.24 | C8: Opening balance | D8: 1591358.8 | E8: =B12 -> 1099257.2
B9: 68772 | C9: Add: Members contribution for the year | D9: 68772 | E9: 68772
B10: =-IE!E30 -> 32640 | C10: Add: Interest earned on fixed deposits | D10: =-IE!E30 -> 32640 | E10: =-IE!G30 -> 40426
B11: 0 | C11: Less: Major Repair Expenses incurred | E11: 0
B12: =SUM(B8:B11) -> 1099257.2 | C12: Closing balance (A) | D12: =SUM(D8:D10) -> 1692770.8 | E12: =SUM(E8:E11) -> 1208455.2
A14: 2 | C14: Reserve Fund :
B15: 0 | C15: Opening balance | D15: 604544 | E15: =SUM(B19) -> 26200
B16: 26200 | C16: Add: Members contribution for the year | D16: 0 | E16: =25600+25600+600 -> 51800
B17: 0 | C17: Add: 25% Surplus trf from I&E Account | D17: =IE!#REF! -> #REF! | E17: =IE!D50 -> 441200
B18: 0 | C18: Less: Major Repair Expenses incurred | E18: 0
B19: =SUM(B15:B18) -> 26200 | C19: Closing balance (B) | D19: =SUM(D15:D17) -> #REF! | E19: =SUM(E15:E18) -> 519200
A21: 3 | C21: Lift Replacement Charges :
B22: 3190000 | C22: Opening balance | E22: =B23 -> 3190000
B23: =SUM(B22:B22) -> 3190000 | C23: Closing balance (C) | D23: 3190000 | E23: =SUM(E22:E22) -> 3190000
A25: 4 | C25: Repair and Maintenance Fund :
B26: 0 | C26: Opening balance | D26: 0 | E26: =SUM(B29) -> 116232
B27: 116232 | C27: Add: Members contribution for the year | D27: 116232 | E27: 116232
B28: 0 | C28: Less: Major Repair Expenses incurred | E28: 0
B29: =SUM(B26:B28) -> 116232 | C29: Closing balance (D) | D29: =SUM(D26:D27) -> 116232 | E29: =SUM(E26:E28) -> 232464
A31: 5 | C31: Major Repair Fund :
B32: 0 | C32: Opening balance | E32: 0
B33: 0 | C33: Add: Members contribution for the year | D33: 0 | E33: 0
B34: 0 | C34: Less: Major Repair Expenses incurred | D34: 0 | E34: 0
B35: =SUM(B32:B34) -> 0 | C35: Closing balance (E) | D35: =SUM(D33:D34) -> 0 | E35: =SUM(E32:E34) -> 0
B37: =SUM(B12,B19,B23,B29,B35) -> 4431689.2 | C37: ALL Total (A + B + C + D + E ) | D37: =SUM(D12,D19,D23,D29,D35) -> #REF! | E37: =SUM(E12,E19,E23,E29,E35) -> 5150119.2

Sheet Sch II
A1: NIKITA CO-OP. HOUSING SOCIETY LIMITED
A3: Schedule II
A4: Fixed Deposit with Banks as at 31st March, 2026
K5: (Amt. in Rs.)
A6: Sr. | B6: FDR Account No. | C6: Date of Deposit | D6: Principal Amt. | E6: Accd Int FY 23-24 | F6: Accd Int FY 24-25 | G6: Accd Int FY 25-26 | H6: Total Amt Invested | I6: Date of Maturity | J6: Rate of Int | K6: Maturity Amt | L6: Bank | N6: Interest | O6: TDS
B7: (Sinking Fund)
A8: 1 | B8: 18200300006508_09 | C8: 06.02.2026 | D8: 346104 | E8: 0 | F8: 0 | G8: =3394-339 -> 3055 | H8: =SUM(D8:G8) -> 349159 | L8: NKSGB | N8: =21199+3394 -> 24593 | O8: =2121+339 -> 2460
A9: 2 | B9: 41771143809_01 | C9: 21.02.2026 | D9: 82601 | E9: 0 | F9: 0 | G9: =581-59 -> 522 | H9: =SUM(D9:G9) -> 83123 | L9: SBI | N9: =5038+522 -> 5560 | O9: 557
A10: 3 | B10: 42830019902 | C10: 27.03.2024 | D10: 68772 | E10: =66-7 -> 59 | F10: 4452 | G10: =5268-527 -> 4741 | H10: =SUM(D10:G10) -> 78024 | I10: 27.02.2027 | J10: 0.07 | K10: 84222 | L10: SBI | N10: =527+4741 -> 5268 | O10: 527
A11: 4 | B11: 43956273303 | C11: 29.03.2025 | D11: 68772 | E11: 0 | F11: 36 | G11: =4945-495 -> 4450 | H11: =SUM(D11:G11) -> 73258 | I11: 29.03.2027 | J11: 0.07 | K11: 79011 | L11: SBI | N11: =495+4450 -> 4945 | O11: 495
A12: 5 | B12: 45040546741 | D12: 68772 | E12: 0 | F12: 0 | G12: =60-6 -> 54 | H12: =SUM(D12:G12) -> 68826 | L12: SBI | N12: =6+54 -> 60 | O12: 6
A13: A | D13: =SUM(D8:D12) -> 635021 | E13: =SUM(E8:E12) -> 59 | F13: =SUM(F8:F12) -> 4488 | G13: =SUM(G8:G12) -> 12822 | H13: =SUM(H8:H12) -> 652390 | K13: =SUM(K8:K12) -> 163233 | N13: =SUM(N8:N12) -> 40426 | O13: =SUM(O8:O12) -> 4045
B14: (Lift Replacement Fund)
A15: 6 | B15: 18200300004980_09 | C15: 10.02.2026 | D15: 1380445 | E15: 0 | F15: 0 | G15: =12587-1258 -> 11329 | H15: =SUM(D15:G15) -> 1391774 | L15: NKSGB | N15: =85585+12587 -> 98172 | O15: =8558+1258 -> 9816
A16: 7 | B16: 18200300004992_08 | C16: 05.05.2025 | D16: 156801 | E16: 0 | F16: 0 | G16: =9532-954 -> 8578 | H16: =SUM(D16:G16) -> 165379 | L16: NKSGB | N16: =1920+9532 -> 11452 | O16: =192+954 -> 1146
A17: 8 | B17: 18200300004993_08 | C17: 05.05.2025 | D17: 114566 | E17: 0 | F17: 0 | G17: =6965-696 -> 6269 | H17: =SUM(D17:G17) -> 120835 | L17: NKSGB | N17: =1404+6965 -> 8369 | O17: =141+696 -> 837
A18: 9 | B18: 18200300000205_08 | C18: 21.07.2025 | D18: 241509 | E18: 0 | F18: 0 | G18: =10110-1011 -> 9099 | H18: =SUM(D18:G18) -> 250608 | L18: NKSGB | N18: =6640+10110 -> 16750 | O18: =664+1011 -> 1675
A19: 10 | B19: 42038283120_01 | C19: 07.09.2025 | D19: 574582 | E19: 0 | F19: 0 | G19: =20614-2063 -> 18551 | H19: =SUM(D19:G19) -> 593133 | L19: SBI | N19: =19485+18551 -> 38036 | O19: 3805
A20: 11 | B20: 42038283595_01 | C20: 07.09.2025 | D20: 574582 | E20: 0 | F20: 0 | G20: =20614-2063 -> 18551 | H20: =SUM(D20:G20) -> 593133 | L20: SBI | N20: =19485+18551 -> 38036 | O20: 3805
A21: 12 | B21: 42038283867_01 | C21: 07.09.2025 | D21: 574582 | E21: 0 | F21: 0 | G21: =20614-2063 -> 18551 | H21: =SUM(D21:G21) -> 593133 | L21: SBI | N21: =19485+18551 -> 38036 | O21: 3805
B22: B | D22: =SUM(D15:D21) -> 3617067 | E22: =SUM(E15:E21) -> 0 | F22: =SUM(F15:F21) -> 0 | G22: =SUM(G15:G21) -> 90928 | H22: =SUM(H15:H21) -> 3707995 | K22: =SUM(K15:K21) -> 0 | N22: =SUM(N15:N21) -> 248851 | O22: =SUM(O15:O21) -> 24889
A23: Grand Total ( A + B ) | D23: =SUM(D13,D22) -> 4252088 | E23: =SUM(E13,E22) -> 59 | F23: =SUM(F13,F22) -> 4488 | G23: =SUM(G13,G22) -> 103750 | H23: =SUM(H13,H22) -> 4360385 | K23: =SUM(K13,K22) -> 163233 | N23: =SUM(N13,N22) -> 289277 | O23: =SUM(O13,O22) -> 28934

Sheet Sch III, IV
A1: NIKITA CO-OP. HOUSING SOCIETY LIMITED
D3: Schedule - III
A4: Advance from Members as at 31st March , 2026
E5: (Amt. in Rs.)
A6: Sl.No | B6: Block | C6: Flat | D6: Name of the Member | E6: Advance Amount (Rs.)
A7: 1 | B7: A | C7: 202 | D7: Mr. Izaan Mohammed Iqbal Khan | E7: 29847
A8: 2 | B8: A | C8: 401 | D8: Mr. S. Rangarajan & Mrs. Vijayalakshmi Rangarajan | E8: 100
A9: 3 | B9: A | C9: 502 | D9: Mr. Ashok Karan John | E9: 4411
A10: 4 | B10: A | C10: 601 | D10: Mr. Asit Das & Mrs. Lopamudra Pattnaik | E10: 20292
A11: 5 | B11: A | C11: 702 | D11: Mr. Anand Anthony Pereira & Mrs. Sabita Anand Pereira | E11: 1688
A12: 6 | B12: B | C12: 101 | D12: Mr. James Aiyinikhal Raphael | E12: 960
A13: 7 | B13: B | C13: 102 | D13: Mr. Mohammed Iqbal Jainul Khan | E13: 18729
A14: 8 | B14: B | C14: 202 | D14: Mrs. Seema Vivek Bangera | E14: 3885
A15: 9 | B15: B | C15: 601 | D15: Mrs. Saba Q. Mukaddam & Dr. Qayum I. Mukaddam | E15: 4835
A16: 10 | B16: C | C16: 103 | D16: Mrs. Vanessa Noronha | E16: 12
A17: 11 | B17: C | C17: 303 | D17: Mrs. Chandrasheela Ravindra Mishra | E17: 0.03
A18: 12 | B18: C | C18: 501 | D18: Mr. M. Srinivas & Mrs. Vijayalakshmi Srinivas | E18: 6467
A19: 13 | B19: C | C19: 502 | D19: Mr. Gopakumar V. R. & Mrs. Sindhu G. Nair | E19: 31175
A20: Total | E20: =SUM(E7:E19) -> 122401.03
A22: Schedule IV
A23: Members Receivable as at March 31, 2026
A25: Sl.No | B25: Block | C25: Unit | D25: Name of the Member | E25: Receivable Amount
A26: 1 | B26: A | C26: 101 | D26: Mr. Kedar M. Bobde & Mrs. Rucha K. Bobde | E26: 8177
A27: 2 | B27: A | C27: 701 | D27: Mrs. Preeti Easwardas Nair | E27: 24
A28: 3 | B28: B | C28: 401 (2) | D28: Mrs. Sajini Anoj & Mr. Porumbumkattil Shankaran Anoj | E28: 3331
A29: 4 | B29: C | C29: 101 | D29: Mr. Purushotam Ashok Shetty | E29: 14413
A30: 5 | B30: C | C30: 102 | D30: Mr. Satyan Velayudhan Pullaniparambath | E30: 3926
A31: 6 | B31: C | C31: 204 | D31: Mr. Chandrakant Hanumant Pawar & Mrs. Vaishali C. Pawar | E31: =681895+535540 -> 1217435
A32: 7 | B32: C | C32: 601 | D32: Mr. Sushil Ratnakar Manure & Mrs. Archana Sushil Manure | E32: 3492
A33: 8 | B33: C | C33: 602 | D33: Mr. Ashok K. John & Mrs. Anne John | E33: 48
A34: Total | E34: =SUM(E26:E33) -> 1250846
A37: Schedule - VII
A38: Unidentified Collections as at March 31, 2026
A40: - Member unknown (old Balance) | E40: 3613
A41: Chq # 018877 Deposited Dt 28.05.2021 - Member unknown | E41: 1500
A42: Total | E42: =+E40+E41 -> 5113

Sheet Sch V
A1: NIKITA CO-OP. HOUSING SOCIETY LIMITED
A3: Schedule V
A4: Details of Current Liabilities as at 31st March, 2026
A6: Sr. No. | B6: Vendor Details | C6: Amount (Rs.) | D6: Remarks
A7: 1 | B7: BMC Water Charges | C7: 174281
A8: Total (A) | C8: =SUM(C7:C7) -> 174281
A10: Other Current Liabilities
A11: Sr. No. | B11: Particulars | C11: Amount (Rs.) | D11: Remarks
A12: 1 | B12: Education & Training Fund | C12: 135
A13: 2 | B13: TDS Payable | C13: 708
A14: 3 | B14: Treasurer Imprest - Inderjit Khurana | C14: 28171
A15: 4 | B15: Retension - Supreme N Force | C15: 314857 | D15: Retention Amount
A16: 5 | B16: Retension - Shofikul S. Sekh | C16: 165024 | D16: Retention Amount
A17: 6 | B17: Swapnil Sarfare | C17: 51955 | D17: Retention Amount
A18: 7 | B18: Nilesh Kamat | C18: 11597
A19: 8 | B19: Nikita Property Society Office | C19: 191
A20: Total (B) | C20: =SUM(C12:C19) -> 572638
A22: Provisions
A23: Sr. No. | B23: Particulars | C23: Amount (Rs.) | D23: Remarks
A24: 1 | B24: Accounting Charges | C24: =1500+12000 -> 13500 | D24: For FY 2022-23
A25: 2 | B25: Income Tax Provision | C25: 0 | D25: For FY 2022-23
A26: 3 | B26: Audit Fees | C26: 5800 | D26: For FY 2022-23
A27: 4 | B27: Federation Subscription Payable | C27: 826
A28: 5 | B28: Water Charges | C28: 111531 | D28: For 29.12.2022 to 31.03.2024
A29: 6 | B29: Pest Control | C29: 1840 | D29: For Mar-2024
A30: Total (C) | C30: =SUM(C24:C29) -> 133497
A32: ALL Total ( A + B + C ) | C32: =C8+C20+C30 -> 880416
A35: Income Taxes Recoverable
A36: Sr. No. | B36: Particulars | C36: Amount (Rs.)
A37: 1 | B37: Add: Advance Taxes Paid | C37: 17000
A38: 2 | B38: Add: TDS Receivable | C38: 28934
A39: 3 | B39: Less: Income Tax Provision Made | C39: -38000
B40: Net Income Taxes Receivable | C40: =SUM(C37:C39) -> 7934

Sheet Sch VI
A1: NIKITA CO-OP. HOUSING SOCIETY LIMITED
A3: Schedule VI
A4: Details of Fixed Assets as at 31st March, 2026
H5: (Amt. in Rs.)
A6: Particulars | B6: Rate % | C6: Opening W.D.V. as on 01.04.2025 | D6: Additions during the year before 30.09.2025 | E6: Additions during the year after 30.09.2025 | F6: Gross Block (at cost) as on 31.03.2026 | G6: Depreciation for the year | H6: Closing W.D.V. as on 31.03.2026
A7: CCTV Camera | B7: 0.15 | C7: 179842 | D7: 0 | E7: 0 | F7: =SUM(C7:E7) -> 179842 | G7: =ROUND(F7*B7,) -> 26976 | H7: =F7-G7 -> 152866
A8: Chair | B8: 0.1 | C8: 2489 | D8: 0 | E8: 0 | F8: =SUM(C8:E8) -> 2489 | G8: =ROUND(F8*B8,) -> 249 | H8: =F8-G8 -> 2240
A9: Electrical Installations | B9: 0.15 | C9: 10069 | D9: 0 | E9: 0 | F9: =SUM(C9:E9) -> 10069 | G9: =ROUND(F9*B9,) -> 1510 | H9: =F9-G9 -> 8559
A10: Furniture and Fixture | B10: 0.1 | C10: 3823 | D10: 0 | E10: 0 | F10: =SUM(C10:E10) -> 3823 | G10: =ROUND(F10*B10,) -> 382 | H10: =F10-G10 -> 3441
A11: Lift | B11: 0.15 | C11: 1197485 | D11: 0 | E11: 0 | F11: =SUM(C11:E11) -> 1197485 | G11: =ROUND(F11*B11,) -> 179623 | H11: =F11-G11 -> 1017862
A12: Pump Control Sensor | B12: 0.15 | C12: 19105 | D12: 0 | E12: 0 | F12: =SUM(C12:E12) -> 19105 | G12: =ROUND(F12*B12,) -> 2866 | H12: =F12-G12 -> 16239
A13: Main Gate Shade | B13: 0.15 | C13: 14616 | D13: 0 | E13: 0 | F13: =SUM(C13:E13) -> 14616 | G13: =ROUND(F13*B13,) -> 2192 | H13: =F13-G13 -> 12424
A14: Stabilizer | B14: 0.15 | C14: 9189 | D14: 0 | E14: 0 | F14: =SUM(C14:E14) -> 9189 | G14: =ROUND(F14*B14,) -> 1378 | H14: =F14-G14 -> 7811
A15: Water Pump | B15: 0.15 | C15: 13549.7 | D15: 0 | E15: 0 | F15: =SUM(C15:E15) -> 13549.7 | G15: =ROUND(F15*B15,) -> 2032 | H15: =F15-G15 -> 11517.7
A16: Fogging Machine | B16: 0.15 | C16: 16155 | D16: 0 | E16: 0 | F16: =SUM(C16:E16) -> 16155 | G16: =ROUND(F16*B16,) -> 2423 | H16: =F16-G16 -> 13732
A17: Total | C17: =SUM(C7:C16) -> 1466322.7 | D17: =SUM(D7:D16) -> 0 | E17: =SUM(E7:E16) -> 0 | F17: =SUM(F7:F16) -> 1466322.7 | G17: =SUM(G7:G16) -> 219631 | H17: =SUM(H7:H16) -> 1246691.7

Sheet Sch VII
A1: NIKITA CO-OP. HOUSING SOCIETY LIMITED
A3: Schedule VII
A4: Details of Prior Period Adjustments as at 31st March, 2025
A6: Sr. | B6: Vendor Details | C6: Amt (Rs.) | D6: Remarks
A7: 1 | B7: Flat B-101, B-201, B-502 bad debts written off | C7: 0
A8: 2 | B8: Bhandary Liability & Retention written back | C8: 0
A9: 3 | B9: Lift AMC excess created in earlier periods written back | C9: 0
A10: Total | C10: =SUM(C7:C9) -> 0

Sheet BRS
B1: NIKITA CHS LTD
A2: NKGSB Bank Reconciliation Statement as at March 31, 2026
A3: FY 2024-25 | B3: Particulars | D3: FY 2025-26 | F3: Posting | G3: Vendor | H3: Instr No. | I3: Credit Values | J3: Debit Values | K3: Clearance Dt
A4: =39627.14 -> 39627.14 | C4: Closing balance as per System | D4: 17012.74
A6: =10989 -> 10989 | B6: Add: | C6: Cheques issued but not cleared | D6: =I6 -> 0 | I6: =SUM(I3:I5) -> 0 | J6: =SUM(J3:J5) -> 0
A7: =SUM(A4:A6) -> 50616.14 | C7: Closing balance as per Bank Statement | D7: =SUM(D4:D6) -> 17012.74
A9: SBI Bank Reconciliation Statement as at March 31, 2026
A10: =A3 -> FY 2024-25 | B10: =B3 -> Particulars | D10: =D3 -> FY 2025-26 | F10: Posting | G10: Vendor | H10: Instr No. | I10: Credit Values | J10: Debit Values | K10: Clearance Dt
A11: =131862.21 -> 131862.21 | C11: Closing balance as per System | D11: 1332539.9
I12: =SUM(I11:I11) -> 0 | J12: =SUM(J11:J11) -> 0
A13: -3660 | B13: Less: | C13: Receipts recorded but not cleared | D13: =-J12 -> 0
A14: =SUM(A11:A13) -> 128202.21 | C14: Closing balance as per Bank Statement | D14: =SUM(D11:D13) -> 1332539.9

Sheet Sheet1
A1: Provision for Water Charges Calculations
D2: LX@0014146 | E2: LX@0014158
A3: 45740 | B3: 45833 | C3: =B3-A3 -> 93 | D3: 101052 | E3: 49868 | H3: Income Tax Workings
A4: =+B3 -> 45833 | B4: 45925 | C4: =B4-A4 -> 92 | D4: 54568 | E4: 49127 | H4: SB Interest | K4: 698
A5: =+B4 -> 45925 | B5: 46017 | C5: =B5-A5 -> 92 | D5: 21759 | E5: 48827 | H5: FD Interest - SBI | K5: =64521+65420 -> 129941 | M5: 13000
A6: =A3 -> 45740 | B6: =+B5 -> 46017 | C6: =SUM(C3:C5) -> 277 | D6: =SUM(D3:D5) -> 177379 | E6: =SUM(E3:E5) -> 147822 | H6: FD Interest - NKGSB | K6: 159336 | M6: 15934
A7: =+B6 -> 46017 | B7: 46112 | C7: =B7-A7 -> 95 | D7: =D6*C7/C6 -> 60833.953 | E7: =E6*C7/C6 -> 50697.076 | F7: =SUM(D7:E7) -> 111531.03 | G7: Provision | K7: =SUM(K4:K6) -> 289975 | M7: =SUM(M5:M6) -> 28934 | N7: Tds receivable
H8: Less: Chap 6 Ded | K8: =K6 -> 159336 | M8: 17000 | N8: advance tax
H9: Net Taxable Income | K9: =ROUND(K7-K8,-1) -> 130640 | M9: =SUM(M7:M8) -> 45934 | N9: Prepaid Taxes
A10: Prepaid Lift AMC Calculations: | H10: Tax | K10: =ROUND(3000+(K9-20000)*30%,) -> 36192
A11: 45931 | B11: 46295 | C11: =B11-A11+1 -> 365 | D11: 64310 | H11: Cess | K11: =ROUND(K10*4%,) -> 1448
A12: 46113 | B12: =+B11 -> 46295 | C12: =B12-A12+1 -> 183 | D12: =ROUND(D11*C12/C11,) -> 32243 | E12: Prepaid | H12: Tax Provision | K12: =SUM(K10:K11) -> 37640
A14: 45992 | B14: 46356 | C14: =B14-A14+1 -> 365 | D14: 64310
A15: 46113 | B15: =+B14 -> 46356 | C15: =B15-A15+1 -> 244 | D15: =ROUND(D14*C15/C14,) -> 42991 | E15: Prepaid
A17: 46082 | B17: 46446 | C17: =B17-A17+1 -> 365 | D17: 58806
A18: 46113 | B18: =+B17 -> 46446 | C18: =B18-A18+1 -> 334 | D18: =ROUND(D17*C18/C17,) -> 53812 | E18: Prepaid
A20: Prepaid pest control | C20: mts
A21: 45962 | B21: 46142 | C21: 6 | D21: 11033
A22: 46113 | B22: =+B21 -> 46142 | C22: 1 | D22: =ROUND(D21*C22/C21,) -> 1839 | E22: Prepaid
A24: Prepaid CCTV
A25: 45962 | B25: 46326 | C25: =B25-A25+1 -> 365 | D25: 17715
A26: 46113 | B26: =+B25 -> 46326 | C26: =B26-A26 -> 213 | D26: =ROUND(D25*C26/C25,) -> 10338 | E26: Prepaid
A28: 45931 | B28: 46295 | C28: =B28-A28+1 -> 365 | D28: 16606
A29: 46113 | B29: =+B28 -> 46295 | C29: =B29-A29 -> 182 | D29: =ROUND(D28*C29/C28,) -> 8280 | E29: Prepaid
A31: Prepaid Insurance Calculations:
A32: 45994 | B32: 46358 | C32: =B32-A32+1 -> 365 | D32: =31256+3540 -> 34796
A33: 46113 | B33: =+B32 -> 46358 | C33: =B33-A33 -> 245 | D33: =ROUND(D32*C33/C32,) -> 23356 | E33: Prepaid
