Workbook

Sheet BS
A1: LITTLE SUNFLOWER CO-OP HOUSING SOCIETY LIMITED
A2: (Regd. No. BOM/HSG/3365/1972)
A3: Plot No.19, Lourdes Colony, Orlem, Malad ( West ), Mumbai - 400 064
A4: BALANCE SHEET AS AT 31ST MARCH 2026
H5: (Amt. in Rs.)
A6: Previous Year 2024-25 | B6: LIABILITIES | D6: Current Year 2025-26 | E6: =A6 -> Previous Year 2024-25 | F6: ASSETS | H6: =D6 -> Current Year 2025-26
B7: Authorised Share Capital | F7: Cash & Bank Balance
A8: 100000 | B8: (2000 Shares of Rs.50/- each ) | D8: 100000 | E8: 764 | F8: Cash in hand | G8: 215
E9: 14409 | F9: Mumbai District Central Co-op. Bank | G9: =BRS!C17 -> 14854
B10: Issued, Subscribed and Paid Up Share Captial | E10: 5895 | F10: Saraswat Bank | G10: =BRS!C25 -> 8321 | L10: =J10-K10 -> 0
A11: 14000 | B11: (280 Shares of Rs.50/- each) | D11: 14000 | E11: 15608 | F11: Citizen Credit Bank | G11: =BRS!C33 -> 17851
E12: 236540.74 | F12: The Shamrao Vithal Co-op. Bank Ltd. | G12: =BRS!C4 -> 227840.85 | H12: =SUM(G8:G12) -> 269081.85
B13: Reserve and Surplus Fund
A14: 627286 | B14: As per last Balance Sheet | C14: =SUM(A14:A17) -> 734254 | F14: Investments & Deposits :
A15: 23174 | B15: Add: 25% Trfd from Surplus Income | C15: =IE!D46 -> 10419 | E15: 500 | F15: Share in Mah. Co-op. Hsg. Finance Soc. Ltd. | G15: 500
A16: 300 | B16: Add: Addition during the year | C16: 0 | E16: 100 | F16: Shares in Mumbai Dist. Co-op. Hsg. Fed. | G16: 100
A17: 83494 | B17: Add: Interest received/ Accrued | C17: ='FD Interest Working'!E117 -> 95399 | D17: =SUM(C14:C17) -> 840072 | E17: 2500 | F17: Shares in Mah. State Co-op. Hsg. Fed. Ltd. | G17: 2500
E18: 8108609 | F18: Fixed Deposits with Banks (As per Sch I) | G18: ='Sch I Fixed Deposits'!D99 -> 8627401
B19: Grotto Fund | E19: 576281 | F19: Accrued Interest on FDRs with Banks | G19: ='Sch I Fixed Deposits'!E99+'Sch I Fixed Deposits'!F99+'Sch I Fixed Deposits'!G99+'Sch I Fixed Deposits'!H99+'Sch I Fixed Deposits'!I99 -> 845260 | H19: =SUM(G15:G19) -> 9475761
A20: 74603 | B20: Add: Transferred from Reserve Fund | C20: =SUM(A20:A23) -> 96383
A21: 0 | B21: Less: Expense on Grotto maintenance | C21: 0 | F21: Deposits
A22: 10000 | B22: Add: Donation from Flat 404 | C22: 0 | E22: 12131.5 | F22: Security Deposit with Adani Electricity | H22: 12131.5
A23: 11780 | B23: Add: Interest received/ Accrued | C23: ='FD Interest Working'!E115 -> 7902 | D23: =SUM(C20:C23) -> 104285
F24: Fixed Assets
B25: Contingency Fund | E25: 35838000 | F25: Land and Building | H25: 35838000
A26: 1389293 | B26: As per last Balance Sheet | C26: =SUM(A26:A28) -> 1584118 | E26: 189800 | F26: Fixed Assets ( As per Sch II) | H26: ='Sch II Fixed Asset'!H10 -> 162049
A27: 103200 | B27: Add: Addition during the year | C27: 54000
A28: 91625 | B28: Add: Interest received/ Accrued | C28: ='FD Interest Working'!E114 -> 112301 | D28: =SUM(C26:C28) -> 1750419 | F28: Sundry Debtors
E29: 2870 | F29: Member's Receivables - ( As per Sch III ) | H29: ='Sch III, IV, V, VI & VII'!D9 -> 11805
B30: Sinking Fund
A31: 1069196 | B31: As per last Balance Sheet | C31: =SUM(A31:A33) -> 1203632 | F31: Prepaid Expenses :
A32: 58224 | B32: Add: Additions during the year | C32: 58224 | E32: 12286 | F32: Insurance Charges | G32: 11701
A33: 76212 | B33: Add: Interest received/ Accrued | C33: ='FD Interest Working'!E122 -> 87678 | D33: =SUM(C31:C33) -> 1349534 | E33: 4295 | F33: Pest Control Charges | G33: 4779 | H33: =SUM(G32:G33) -> 16480
B35: Repair Fund
A36: 4563998 | B36: As per last Balance Sheet | C36: =SUM(A36:A39) -> 3453942 | F36: Other Current Assets :
A37: 175056 | B37: Add: Additions during the year | C37: 175056 | E37: 50131 | F37: TDS Receivable | G37: 58567 | H37: =SUM(G37:G37) -> 58567
A38: -1489986 | B38: Less: Painting and Repair Expenses | C38: =IE!C20 -> -152099
A39: 204874 | B39: Add: Interest received/ Accrued | C39: ='FD Interest Working'!E119 -> 237133 | D39: =SUM(C36:C39) -> 3714032
B41: Building Painting Fund
A42: 719610 | B42: As per last Balance Sheet | C42: =SUM(A42:A43) -> 767792
...

Sheet IE
A1: LITTLE SUNFLOWER CO-OP HOUSING SOCIETY LIMITED
A2: =BS!A2 -> (Regd. No. BOM/HSG/3365/1972)
A3: Plot No.19, Lourdes Colony, Orlem, Malad - West, Mumbai - 400 064
A4: INCOME & EXPENDITURE ACCOUNT FOR THE YEAR ENDED 31ST MARCH 2026
H5: (Amt. in Rs.)
A6: =BS!A6 -> Previous Year 2024-25 | B6: Expenditure | D6: =BS!D6 -> Current Year 2025-26 | E6: =A6 -> Previous Year 2024-25 | F6: Income | H6: =D6 -> Current Year 2025-26
B7: To Property Tax : | F7: By Maintenance Contribution from Members:
A8: 11640 | B8: Property Tax | D8: 16296 | E8: 211200 | F8: Electricity Charges | G8: 211200
E9: 48000 | F9: Water Charges | G9: 48000
A10: 166014.75 | B10: Electricity Expenses | C10: 179811.41 | E10: 115200 | F10: Lift Maintenance Charges | G10: 115200
A11: 58634 | B11: Water Expenses | C11: =58680+4000 -> 62680 | D11: =SUM(C10:C11) -> 242491.41 | E11: 181248 | F11: Service Charges | G11: 181248
E12: 18837 | F12: Non Occupancy Charges | G12: 19251
B13: To Lift Maintenance : | E13: 31550 | F13: Parking Charges | G13: =5400+35100 -> 40500
A14: 41253 | B14: Lift AMC Expenses | C14: 41296 | E14: 2132 | F14: Late Payment Interest | G14: 1826
A15: 19140 | B15: Lift Repair and Maintenance | C15: 73240 | D15: =SUM(C14:C15) -> 114536 | E15: 240000 | F15: Security Charges | G15: 240000
E16: 6000 | F16: MoveIn -Moveout Charges | G16: 2000
B17: To Repair & Maintenance : | E17: 40452 | F17: Insurance Charges | G17: 40452
A18: 48000 | B18: Garden Maintenance | C18: 65400 | E18: 5000 | F18: Terrace Usage Charges | G18: 5000 | H18: =SUM(G8:G18) -> 904677
A19: 1503446 | B19: Repair Maintenance - Others | C19: 158834
A20: -1489986 | B20: Less: Trfd to Repair Fund | C20: -152099
A21: 11900 | B21: Repair Maintenance - Electrical | C21: 7730 | F21: By Property Tax Contribution from Members :
A22: 21150 | B22: Repair Maintenance - Plumbing | C22: 1150 | E22: 9048 | F22: Stilt Tax | H22: 9048
A23: 7788 | B23: CCTV AMC | C23: 7788
A24: 6490 | B24: Intercom AMC Expenses | C24: 6490 | D24: =SUM(C18:C24) -> 95293 | F24: By Bank Interest Income
E25: 1402 | F25: Interest Income - IT Refund | G25: 2770
B26: To Service Charges : | E26: 17385 | F26: Interest Income - Savings A/c. | G26: 12713 | H26: =SUM(G25:G26) -> 15483
A27: 264598 | B27: Security Charges | C27: 264000
A28: 5988 | B28: Pest Control Expenses | C28: 5216 | E28: 526740 | F28: By Interest Income - Fixed Deposits | G28: 612056
A29: 32553 | B29: Depreciation | C29: ='Sch II Fixed Asset'!G10 -> 27751 | E29: 0 | F29: Interest Income on FD Redeemed | G29: 0
A30: 24744 | B30: Insurance Expenses | C30: 24180 | E30: -91625 | F30: Less: Trf to Contingency Fund | G30: =-'FD Interest Working'!E114 -> -112301
A31: 826 | B31: Federation Subscription | C31: 826 | E31: -83494 | F31: Less: Trf to Reserve Fund | G31: =-'FD Interest Working'!E117 -> -95399
A32: 2800 | B32: Audit Fees | C32: 2800 | D32: =SUM(C27:C32) -> 324773 | E32: -48182 | F32: Less: Trf to Bldg. Painting Fund | G32: =-'FD Interest Working'!E116 -> -55965
E33: -204874 | F33: Less: Trf to Repair Fund | G33: =-'FD Interest Working'!E119 -> -237133
B34: To Office Expenses : | E34: -76212 | F34: Less: Trf to Sinking Fund | G34: =-'FD Interest Working'!E122 -> -87678
A35: 54000 | B35: Salary/Bonus Expenses | C35: =42000+9500 -> 51500 | E35: -11780 | F35: Less: Trf to Grotto Fund | G35: =-'FD Interest Working'!E115 -> -7902 | H35: =SUM(G28:G35) -> 15678
A36: 17808 | B36: Accounting Charges | C36: 19588
A37: 2097 | B37: Printing and Stationery | C37: 1884 | E37: 3500 | F37: Sale of Scrap | H37: 0
A38: 936 | B38: Meeting Expenses | C38: 2570
A39: 200 | B39: Conveyance | C39: 60
A40: 8000 | B40: Professional Fees | C40: 8100
...

Sheet Sch I Fixed Deposits
A1: LITTLE SUNFLOWER CO-OP HOUSING SOCIETY LIMITED
B2: Schedule I - Details of Fixed Deposits as on 31st March 2026
A3: Sr. No. | B3: Certificate No. | C3: Date | D3: Amount Invested | E3: Accrued Int. 21-22 | F3: Accrued Int. 22-23 | G3: Accrued Int. 23-24 | H3: Accrued Int. 24-25 | I3: Accrued Int. 25-26 | J3: Total | K3: Maturity Date | L3: Maturity Value | M3: Interest % | N3: Bank
B4: Sinking Fund
A5: 1 | B5: 116280 | C5: 12.05.2024 | D5: 132475 | E5: 0 | F5: 0 | G5: 0 | H5: =8371-838 -> 7533 | I5: =10035-1004 -> 9031 | J5: =SUM(D5:I5) -> 149039 | K5: 13.05.2027 | L5: 163135 | M5: 7 | N5: SVC
A6: 2 | B6: 41141_1 | C6: 10.01.2024 | D6: 123554 | E6: 0 | F6: 0 | G6: =2023-203 -> 1820 | H6: =9314-931 -> 8383 | I6: =9937-993 -> 8944 | J6: =SUM(D6:I6) -> 142701 | K6: 10.01.2027 | L6: 153275 | M6: 7.25 | N6: SVC
A7: 3 | B7: 39990_1 | C7: 04.07.2023 | D7: 105722 | E7: 0 | F7: 0 | G7: =5375-540 -> 4835 | H7: =7634-763 -> 6871 | I7: =8109-197-202-204-207 -> 7299 | J7: =SUM(D7:I7) -> 124727 | K7: 04.07.2026 | L7: 129234 | M7: 6.75 | N7: SVC
A8: 4 | B8: 41799_1 | C8: 12.04.2024 | D8: 101079 | E8: 0 | F8: 0 | G8: 0 | H8: =6257-626 -> 5631 | I8: =6811-682 -> 6129 | J8: =SUM(D8:I8) -> 112839 | K8: 12.04.2027 | L8: 121748 | M8: 6.25 | N8: SVC
A9: 5 | B9: 2090100003053386_2 | C9: 25.06.2025 | D9: 79595 | E9: 0 | F9: 0 | G9: 0 | H9: 0 | I9: =5473-1218 -> 4255 | J9: =SUM(D9:I9) -> 83850 | K9: 07.11.2026 | M9: 7 | N9: Citizen
A10: 6 | B10: 6605400011724_4 | C10: 08.11.2025 | D10: 47366 | E10: 0 | F10: 0 | G10: 0 | H10: 0 | I10: =1245-125 -> 1120 | J10: =SUM(D10:I10) -> 48486 | K10: 08.11.2027 | L10: 53992 | M10: 6.6 | N10: MDCC
A11: 7 | B11: 220743 | C11: 30.11.2024 | D11: 10000 | E11: 0 | F11: 0 | G11: 0 | H11: =238-24 -> 214 | I11: =732-74 -> 658 | J11: =SUM(D11:I11) -> 10872 | K11: 30.11.2029 | L11: 14148 | M11: 7 | N11: SVC
A12: 8 | B12: 6605400012118_3 | C12: 30.12.2025 | D12: 77337 | E12: 0 | F12: 0 | G12: 0 | H12: 0 | I12: =1314-132 -> 1182 | J12: =SUM(D12:I12) -> 78519 | K12: 30.12.2026 | L12: 82610 | M12: 6.65 | N12: MDCC
A13: 9 | B13: 6605400014443_1 | C13: 16.02.2025 | D13: 43658 | E13: 0 | F13: 0 | G13: 0 | H13: =362-36 -> 326 | I13: =3150-315 -> 2835 | J13: =SUM(D13:I13) -> 46819 | K13: 16.02.2028 | L13: 53762 | M13: 7 | N13: MDCC
A14: 10 | B14: 6605400013159_3 | C14: 08.02.2026 | D14: 89832 | E14: 0 | F14: 0 | G14: 0 | H14: 0 | I14: =840-84 -> 756 | J14: =SUM(D14:I14) -> 90588 | K14: 08.02.2027 | L14: 95956 | M14: 6.65 | N14: MDCC
A15: 11 | B15: 6605400009713_3 | C15: 28.03.2026 | D15: 26499 | E15: 0 | F15: 0 | G15: 0 | H15: 0 | I15: =19-2 -> 17 | J15: =SUM(D15:I15) -> 26516 | K15: 28.03.2027 | L15: 28306 | M15: 6.65 | N15: MDCC
A16: 12 | B16: 6605400014035_1 | C16: 01.01.2024 | D16: 67120 | E16: 0 | F16: 0 | G16: =1191-119 -> 1072 | H16: =4958-496 -> 4462 | I16: =5282-528 -> 4754 | J16: =SUM(D16:I16) -> 77408 | K16: 01.01.2027 | L16: 82898 | M16: 7.25 | N16: MDCC
A17: 13 | B17: 6605400014698 | C17: 08.12.2022 | D17: 58224 | E17: 0 | F17: =1171-117 -> 1054 | G17: =3845-384 -> 3461 | H17: =4070-408 -> 3662 | I17: =4306-430 -> 3876 | J17: =SUM(D17:I17) -> 70277 | K17: 08.12.2027 | L17: 79782 | M17: 6.35 | N17: MDCC | R17: Fund | S17: FD | T17: Diff
A18: 14 | B18: 6605400014434_1 | C18: 14.02.2025 | D18: 67192 | E18: 0 | F18: 0 | G18: 0 | H18: =584-58 -> 526 | I18: =4851-485 -> 4366 | J18: =SUM(D18:I18) -> 72084 | K18: 14.02.2026 | L18: 82743 | M18: 7 | N18: MDCC | Q18: Share Capital | R18: =BS!D11 -> 14000 | S18: =J97 -> 14000 | T18: =R18-S18 -> 0
A19: 15 | B19: 6605400015102_01 | C19: 30.11.2025 | D19: 66916 | E19: 0 | F19: 0 | G19: 0 | H19: 0 | I19: =1489-149 -> 1340 | J19: =SUM(D19:I19) -> 68256 | K19: 30.11.2027 | L19: 76276 | M19: 6.6 | N19: MDCC | Q19: =BS!B13 -> Reserve and Surplus Fund | R19: =BS!D17 -> 840072 | S19: =J47 -> 1414865 | T19: =R19-S19 -> -574793
A20: 16 | B20: 6605400015598 | C20: 30.09.2024 | D20: 58224 | E20: 0 | F20: 0 | G20: 0 | H20: =2287-229 -> 2058 | I20: =4794-480 -> 4314 | J20: =SUM(D20:I20) -> 64596 | K20: 30.09.2026 | L20: 67885 | M20: 7.75 | N20: MDCC | Q20: =BS!B19 -> Grotto Fund | R20: =BS!D23 -> 104285 | S20: =J78 -> 122767 | T20: =R20-S20 -> -18482
A21: 17 | B21: 281691 | C21: 17.03.2025 | D21: 17030 | E21: 0 | F21: 0 | G21: 0 | H21: =48-4 -> 44 | I21: =1224-124 -> 1100 | J21: =SUM(D21:I21) -> 18174 | K21: 17.03.2030 | L21: 24094 | M21: 7 | N21: SVC | Q21: =BS!B25 -> Contingency Fund | R21: =BS!D28 -> 1750419 | S21: =J68 -> 1814135 | T21: =R21-S21 -> -63716
A22: 18 | B22: 6605400016067 | C22: 16.02.2026 | D22: 65324 | E22: 0 | F22: 0 | G22: 0 | H22: 0 | I22: =499-50 -> 449 | J22: =SUM(D22:I22) -> 65773 | K22: 18.02.2029 | L22: 79852 | M22: 6.75 | N22: MDCC | Q22: =BS!B30 -> Sinking Fund | R22: =BS!D33 -> 1349534 | S22: =J23 -> 1351524 | T22: =R22-S22 -> -1990
D23: =SUM(D5:D22) -> 1237147 | E23: =SUM(E5:E22) -> 0 | F23: =SUM(F5:F22) -> 1054 | G23: =SUM(G5:G22) -> 11188 | H23: =SUM(H5:H22) -> 39710 | I23: =SUM(I5:I22) -> 62425 | J23: =SUM(J5:J22) -> 1351524 | L23: =SUM(L5:L22) -> 1389696 | Q23: =BS!B35 -> Repair Fund | R23: =BS!D39 -> 3714032 | S23: =J38 -> 3798231 | T23: =R23-S23 -> -84199
Q24: =BS!B41 -> Building Painting Fund | R24: =BS!D43 -> 823757 | S24: =J93 -> 828409 | T24: =R24-S24 -> -4652
B25: Repair Fund | Q25: =BS!B50 -> Refundable Deposit - ( As per Sch IV ) | R25: =BS!D54 -> 80000 | S25: =J85 -> 128730 | T25: =R25-S25 -> -48730
A26: 19 | B26: 116286 | C26: 12.05.2024 | D26: 397435 | E26: 0 | F26: 0 | G26: 0 | H26: =25114-2510 -> 22604 | I26: =30105-3012 -> 27093 | J26: =SUM(D26:I26) -> 447132 | K26: 13.05.2027 | L26: 498417 | M26: 7 | N26: SVC
A27: 20 | B27: 39995_1 | C27: 04.07.2023 | D27: 317235 | E27: 0 | F27: 0 | G27: =16127-1611 -> 14516 | H27: =22909-2291 -> 20618 | I27: =24332-2434 -> 21898 | J27: =SUM(D27:I27) -> 374267 | K27: 04.07.2026 | L27: 387786 | M27: 6.75 | N27: SVC | R27: =SUM(R18:R26) -> 8676099 | S27: =SUM(S18:S26) -> 9472661 | T27: =SUM(T18:T26) -> -796562
A28: 21 | B28: 41420_02 | C28: 14.04.2025 | D28: 486439 | E28: 0 | F28: 0 | G28: 0 | H28: 0 | I28: =7283+8627+8804+1+8902-728-863-880-890 -> 30256 | J28: =SUM(D28:I28) -> 516695 | K28: 14.05.2027 | L28: 562121 | M28: 7 | N28: SVC
A29: 22 | B29: 42887_1 | C29: 10.02.2025 | D29: 376597 | E29: 0 | F29: 0 | G29: 0 | H29: =3756-375 -> 3381 | I29: =27234-2723 -> 24511 | J29: =SUM(D29:I29) -> 404489 | K29: 10.02.2028 | L29: 463756 | M29: 7 | N29: SVC | R29: From | S29: To
A30: 23 | B30: 42907 | C30: 17.02.2022 | D30: 175056 | E30: =1185-119 -> 1066 | F30: =10326-1034 -> 9292 | G30: =10935-1094 -> 9841 | H30: =11447-1143 -> 10304 | I30: =12051-1205 -> 10846 | J30: =SUM(D30:I30) -> 216405 | K30: 17.02.2027 | L30: 232888 | M30: 5.75 | N30: SVC | R30: Reserve Fund | S30: Contingency
A31: 24 | B31: 43583 | C31: 06.12.2022 | D31: 175056 | E31: 0 | F31: =3767-378 -> 3389 | G31: =12349-1235 -> 11114 | H31: =13090-1311 -> 11779 | I31: =13903-1390 -> 12513 | J31: =SUM(D31:I31) -> 213851 | K31: 05.12.2027 | L31: 244641 | M31: 6.75 | N31: SVC | R31: Reserve Fund | S31: Painting Fun
A32: 25 | B32: 6605300017268_2 | C32: 16.02.2025 | D32: 262486 | E32: 0 | F32: 0 | G32: 0 | H32: =2185-219 -> 1966 | I32: =18951-1895 -> 17056 | J32: =SUM(D32:I32) -> 281508 | K32: 16.02.2028 | L32: 323236 | M32: 7 | N32: MDCC | R32: Security | S32: Sinking
A33: 26 | B33: TD0000413096_03 | C33: 28.11.2025 | D33: 282129 | E33: 0 | F33: 0 | G33: 0 | H33: 0 | I33: =6629-663 -> 5966 | J33: =SUM(D33:I33) -> 288095 | K33: 28.11.2027 | L33: 322836 | M33: 6.8 | N33: SCB
A34: 27 | B34: TD0000413488_03 | C34: 10.01.2026 | D34: 463557 | E34: 0 | F34: 0 | G34: 0 | H34: 0 | I34: =7118-712 -> 6406 | J34: =SUM(D34:I34) -> 469963 | K34: 10.01.2028 | L34: 530482 | M34: 6.8 | N34: SCB
A35: 28 | B35: 21086 | C35: 09.10.2023 | D35: 175056 | E35: 0 | F35: 0 | G35: =5908-591 -> 5317 | H35: =12927-663 -> 12264 | I35: =13761-1377 -> 12384 | J35: =SUM(D35:I35) -> 205021 | K35: 09.10.2026 | L35: 215571 | M35: 7 | N35: SVC
A36: 29 | B36: 281673 | C36: 17.03.2025 | D36: 122568 | E36: 0 | F36: 0 | G36: 0 | H36: =346-34 -> 312 | I36: =8807-882 -> 7925 | J36: =SUM(D36:I36) -> 130805 | K36: 17.03.2030 | L36: 173407 | M36: 7 | N36: SVC
A37: 30 | B37: TD1002026254 | C37: 17.02.2026 | D37: 250000 | E37: 0 | F37: 0 | G37: 0 | H37: 0 | I37: 0 | J37: =SUM(D37:I37) -> 250000 | K37: 17.02.2028 | L37: 250000 | M37: 6.8 | N37: SCB
D38: =SUM(D26:D37) -> 3483614 | E38: =SUM(E26:E37) -> 1066 | F38: =SUM(F26:F37) -> 12681 | G38: =SUM(G26:G37) -> 40788 | H38: =SUM(H26:H37) -> 83228 | I38: =SUM(I26:I37) -> 176854 | J38: =SUM(J26:J37) -> 3798231 | L38: =SUM(L26:L37) -> 4205141
B40: Reserve Fund
A41: 31 | B41: 6605300015439_3 | C41: 08.02.2026 | D41: 26872 | E41: 0 | F41: 0 | G41: 0 | H41: 0 | I41: =250-25 -> 225 | J41: =SUM(D41:I41) -> 27097 | K41: 08.02.2027 | L41: 28704 | M41: 6.65 | N41: MDCC
...

Sheet Sch II Fixed Asset
A1: LITTLE SUNFLOWER CO-OP HOUSING SOCIETY LIMITED
A2: Schedule II - Fixed Assets Details as on 31st March 2026
B3: Gross Block | F3: Depreciation | H3: Net Block
A4: Assets | B4: Cost as at 01/04/2025 | C4: Additions on or before 30/09/2025 | D4: Additions after 30/09/2025 | E4: Cost as at 31/03/2026 | F4: Rate of Dep (%) | G4: For the Year 2025-26 | H4: As at 31/03/2026
A5: Beetle Telephone | B5: 242 | C5: 0 | D5: 0 | E5: =+B5+C5+D5 -> 242 | F5: 0.15 | G5: =ROUND(((B5+C5)*F5)+(D5*F5)/2,) -> 36 | H5: =+E5-G5 -> 206
A6: Water Pump | B6: 41717 | C6: 0 | D6: 0 | E6: =+B6+C6+D6 -> 41717 | F6: 0.15 | G6: =ROUND(((B6+C6)*F6)+(D6*F6)/2,) -> 6258 | H6: =+E6-G6 -> 35459
A7: Furniture & Fixture | B7: 14405 | C7: 0 | D7: 0 | E7: =+B7+C7+D7 -> 14405 | F7: 0.1 | G7: =ROUND(((B7+C7)*F7)+(D7*F7)/2,) -> 1441 | H7: =+E7-G7 -> 12964
A8: CCTV | B8: 38892 | C8: 0 | D8: 0 | E8: =+B8+C8+D8 -> 38892 | F8: 0.15 | G8: =ROUND(((B8+C8)*F8)+(D8*F8)/2,) -> 5834 | H8: =+E8-G8 -> 33058
A9: Fire Fighting System | B9: 94544 | C9: 0 | D9: 0 | E9: =+B9+C9+D9 -> 94544 | F9: 0.15 | G9: =ROUND(((B9+C9)*F9)+(D9*F9)/2,) -> 14182 | H9: =+E9-G9 -> 80362
A10: Total | B10: =SUM(B5:B9) -> 189800 | C10: =SUM(C5:C9) -> 0 | D10: =SUM(D5:D9) -> 0 | E10: =SUM(E5:E9) -> 189800 | G10: =SUM(G5:G9) -> 27751 | H10: =SUM(H5:H9) -> 162049

Sheet Sch III, IV, V, VI & VII
A1: LITTLE SUNFLOWER CO-OP HOUSING SOCIETY LIMITED
A2: Schedule III - Members Receivable As on 31.03.2026
A3: Sl.No | B3: Flat | C3: Name | D3: Amount
A4: 1 | B4: 302 | C4: Mr. Heslyn Greg Silveira | D4: 8815
A5: 2 | B5: 104 | C5: Mr. Joslyn Pereira, Ms. Leticia Pereira | D5: 6
A6: 3 | B6: 201 | C6: Ms. Joanita Gago | D6: 2794
A7: 4 | B7: 202 | C7: Mr. Meltzer Barretto | D7: 161
A8: 5 | B8: 204 | C8: Elaine Pereira, Charmin Nazareth & Dolly Aaron | D8: 29
C9: Total | D9: =SUM(D4:D8) -> 11805
A12: Sch IV - Member Refundable Deposit as at 31.03.2026
A13: Sl.No | B13: Flat | C13: Name | D13: Amount
A14: 1 | B14: 101 | C14: Ms. Melba Figueiredo | D14: 10000
A15: 2 | B15: 203 | C15: Ms. Marceline Lasrado | D15: 10000
A16: 3 | B16: 502 | C16: Mr. Anthony Francis Silveira | D16: 10000
A17: 4 | B17: 503 | C17: Mr. Kunal Kevin Menezes | D17: 10000
A18: 5 | B18: 504 | C18: Ms. Prescilla Theresa Goveas | D18: 10000
A19: 6 | B19: 602 | C19: Ms. Chatura K. Fernandes | D19: 10000
A20: 7 | B20: 702/802 | C20: Mr. Chandresh Gawans | D20: 20000
C21: Total | D21: =SUM(D14:D20) -> 80000
A24: LITTLE SUNFLOWER CO-OP HOUSING SOCIETY LIMITED
A25: Sch V - Advance from Members as at 31.03.2026
A26: Sl.No | B26: Flat | C26: Name | D26: Amount
A27: 1 | B27: 203 | C27: Ms. Marceline Lasrado | D27: 4174
A28: 2 | B28: 102 | C28: Mr. Jude Anthony D'souza | D28: 2765
A29: 3 | B29: 403 | C29: Mr. Dominic D. Mendes, Ms. Bonita E. Mendes | D29: 2765
A30: 4 | B30: 404 | C30: Mr. Anthony Rodrigues | D30: 22273
C31: Total | D31: =SUM(D27:D30) -> 31977
A34: Sch VI - Provisions as of 31.03.2026
A35: Sl.No | B35: 2023-24 | C35: Vendor & Other Payable | D35: 2024-25
A36: 1 | B36: 381 | C36: TDS Payable | D36: =742-126 -> 616
A37: 2 | B37: 2800 | C37: Audit Fees | D37: 2800
A38: 3 | B38: 12690 | C38: Ashna Elevators | D38: 10236
A39: 4 | B39: 14590 | C39: Adani | D39: 14149.52
A40: 5 | B40: 18953 | C40: Water Charges | D40: 4195
A41: 6 | B41: 6270 | C41: V.S. Enterprises | D41: 6270
A42: 7 | B42: 0 | C42: Income Tax | D42: 199
A43: 8 | B43: 147 | C43: Irene Rosario (TDS reimbursement) | D43: 0
A44: 9 | B44: 1000 | C44: Professional Fess - TDS Returns | D44: 1000
A45: 10 | B45: 3500 | C45: Professional Fess - IT Returns | D45: 3800
A46: 11 | B46: 1500 | C46: Professional Fess - Mandatory returns | D46: 1500
...

Sheet BRS
A1: Little Sunflower CHS Ltd
A2: SVC Bank reconciliation statement as on 31st March 2026
C3: Amount
B4: Balance as per System | C4: 227840.85 | E4: Date | F4: Amount | G4: Vendor | H4: Chq no. | I4: Cleared date
E5: 31.03.2026 | F5: 14683 | G5: BMC Water | H5: 48939 | I5: 04.04.2026
A6: Add: | B6: Cheque issued but not presented | E6: 31.03.2026 | F6: 14618 | G6: BMC Water | H6: 48938 | I6: 04.04.2026
B7: a. As per statement | C7: =F10 -> 58581 | E7: 30.03.2026 | F7: 21780 | G7: Ganesh Security | H7: 48937 | I7: 06.04.2026
E8: 30.03.2026 | F8: 3500 | G8: Annamalia | H8: 48936 | I8: 04.04.2026
A9: Less: | B9: Cheques deposited but not cleared | E9: 30.03.2026 | F9: 4000 | G9: Bahadur | H9: 48935 | I9: 02.04.2026
F10: =SUM(F5:F9) -> 58581
B11: Balance as per Bank Statement | C11: =C4+C7+C10 -> 286421.85
A14: Little Sunflower CHS Ltd
A15: MDCC Bank reconciliation statement as on 31st March 2026
C16: Amount
B17: Balance as per System | C17: 14854
B19: Balance as per Bank Statement | C19: =C17 -> 14854
A22: Little Sunflower CHS Ltd
A23: Saraswat Bank reconciliation statement as on 31st March 2026
C24: Amount
B25: Balance as per System | C25: 8321
B27: Balance as per Bank Statement | C27: =C25 -> 8321
A30: Little Sunflower CHS Ltd
A31: Citizen Bank reconciliation statement as on 31st March 2026
C32: Amount
B33: Balance as per System | C33: 17851
B35: Balance as per Bank Statement | C35: =C33 -> 17851

Sheet Working
A1: Provision and Prepaid workings for FY 2025-26
A2: Sr. No. | B2: A/c. Head
A3: 1 | B3: Water Expense
B4: Period from and upto | D4: Days | E4: Amount
B5: 45995 | C5: 46086 | D5: =+C5-B5 -> 91 | E5: 14683
B6: =+C5 -> 46086 | C6: 46112 | D6: =+C6-B6 -> 26 | E6: =ROUND((E5*D6)/D5,0) -> 4195 | F6: provision
A8: 2 | B8: Pest Control
B9: 46054 | C9: 46418 | D9: =+C9-B9+1 -> 365 | E9: 5700
B10: 46113 | C10: =+C9 -> 46418 | D10: =+C10-B10+1 -> 306 | E10: =ROUND(E9*D10/D9,) -> 4779 | F10: Prepaid
A12: 3 | B12: Insurance
B13: 45929 | C13: 46293 | D13: =+C13-B13+1 -> 365 | E13: 23595
B14: 46113 | C14: =+C13 -> 46293 | D14: =+C14-B14+1 -> 181 | E14: =ROUND(E13*D14/D13,) -> 11701 | F14: Prepaid

Sheet FD Interest Working
A1: Little Sunflower C.H.S. Ltd - Income - Non Members > Interest Income - Fixed Deposit ( 306002 ) <br>Transactions From 01-04-2024 to 31-03-2025
A2: Journal No. | B2: Posted Date | C2: Comments | D2: Credit | E2: Fund
A3: JE-2025-0000034 | B3: 14-04-2025 | C3: Being FD 41420 renewed and remade SVC - RMF | D3: 1184 | E3: RMF
A4: JE-2025-0000111 | B4: 25-06-2025 | C4: Being FD 3053386 renewed and remade CIT - SF | D4: 1218 | E4: SF
A5: JE-2025-0000109 | B5: 25-06-2025 | C5: Being FD 3053384 renewed and remade CIT - CF | D5: 2358 | E5: CF
A6: JE-2025-0000001 | B6: 30-06-2025 | C6: Being Int recd on FD TD102101030043943 - SC SVC | D6: 253 | E6: SCF.
A7: JE-2025-0000073 | B7: 30-06-2025 | C7: Being int on FD 301100 CIT | D7: 438 | E7: PF
A8: JE-2025-0000113 | B8: 05-07-2025 | C8: Being FD 3053396 renewed and remade CIT - SDF | D8: 578 | E8: SDF
A9: JE-2025-0000115 | B9: 10-09-2025 | C9: Being FD 3053502 renewed and remade CIT - CF | D9: 2878 | E9: CF
A10: JE-2025-0000004 | B10: 30-09-2025 | C10: Being int on FD 102101030043943 SVC | D10: 254 | E10: SCF.
A11: JE-2025-0000074 | B11: 30-09-2025 | C11: Being int on FD 301100 CIT | D11: 438 | E11: PF
A12: JE-2025-0000080 | B12: 07-10-2025 | C12: Being FD 191583 redeeem & credited in bank SVC RET | D12: 6134 | E12: RET
A13: JE-2025-0000096 | B13: 08-11-2025 | C13: Being FD 6605400011724 renewed and remade MDCC - SF | D13: 2194 | E13: SF
A14: JE-2025-0000018 | B14: 28-11-2025 | C14: Being FD TD0000413097 renewed and remade SCB - RF | D14: 1605 | E14: CF
... A98: JE-2025-0000038 | B98: 31-03-2026 | C98: Being int accu on FD 41799 - SF - SVC | D98: 6811 | E98: SF
B99: 31.03.2026 | C99: Being int accu on FD 6605500001645 - CF - MDCC | D99: 177 | E99: CF
D100: =SUM(D3:D99) -> 612056
D104: Bank | E104: System | F104: Diff
D105: 360712 | E105: 360712 | F105: =D105-E105 -> 0 | H105: SVC
D106: 26440 | E106: 26440 | F106: =D106-E106 -> 0 | H106: CIT
D107: 107713 | E107: 107713 | F107: =D107-E107 -> 0 | H107: MDCC
D108: 117191 | E108: 117191 | F108: =D108-E108 -> 0 | H108: SCB
D109: =SUBTOTAL(9,D105:D108) -> 612056 | E109: =SUBTOTAL(9,E105:E108) -> 612056
F111: 11207 | G111: Savings Account Interest
E114: 112301 | F114: Contignecy | G114: CF
E115: 7902 | F115: GF/Grotto | G115: GF
E116: 55965 | F116: Painting | G116: PF
E117: 95399 | F117: Reserve | G117: RF
E118: 6134 | F118: Retention | G118: Ret
E119: 237133 | F119: Repair | G119: RMF
E120: 1015 | F120: Share | G120: SC
E121: 8529 | F121: Security | G121: SDF
E122: 87678 | F122: Sinking | G122: SF
E123: =SUBTOTAL(9,E114:E122) -> 612056
E124: =E114+E115+E116+E117+E119+E122 -> 596378
