Workbook

Sheet BS
A1: BETSY CO-OPERATIVE HOUSING SOCIETY LTD
A2: 68, Marve Road, Orlem, Malad (West), Mumbai, Maharshtra-400064
A3: Society Reg No : MUM/WP/HSG/TC/10340 dt. 28.04.99
A4: Balance Sheet as at March 31, 2026
A5: March 31, 2025 | B5: LIABILITIES | D5: March 31, 2026 | E5: =A5 -> March 31, 2025 | F5: ASSETS | H5: =D5 -> March 31, 2026
B6: Authorised Share Capital | F6: Cash and Bank Balances:
A7: 200000 | B7: 4000 shares of Rs. 50/- each | D7: 200000 | E7: 2030 | F7: Cash in Hand | G7: 351
E8: 700534.86 | F8: The Saraswat Co-op Bank | G8: =BRS!C4 -> 599390.71
B9: Issued, Subscribed and Paid Up | E9: 16235 | F9: MDCC Bank | G9: =BRS!C16 -> 16235 | J9: MDCC ac dormant
A10: 11000 | B10: 220 Shares of Rs. 50/- each | D10: 11000 | E10: 23690 | F10: Citizen Credit Co-op Bank | G10: =BRS!C23 -> 24714 | H10: =SUM(G7:G10) -> 640690.71
B12: Reserve & Surplus: | F12: Investments:
B13: Reserve fund | E13: 100 | F13: 1 share of MDHF | G13: 100
A14: 668294 | B14: As per last Balance Sheet | C14: =SUM(A14:A17) -> 802639 | E14: 1000 | F14: 10 share of MDCC Bank | G14: 1000
A15: 51300 | B15: Add: Addition during the year | C15: 2600 | E15: 4274179.5 | F15: Fixed Deposits (As per Schedule 1) | G15: ='FD-Sch 1'!D79 -> 4436711.5
A16: 57319 | B16: Add: 1/4 th Surplus Transferred | C16: =IE!D43 -> 38500 | E16: 204159 | F16: Accrued Interest on Investment | G16: ='FD-Sch 1'!E79+'FD-Sch 1'!F79+'FD-Sch 1'!G79+'FD-Sch 1'!H79 -> 331218 | H16: =SUM(G13:G16) -> 4769029.5
A17: 25726 | B17: Add: Accrued / Interest Earned | C17: ='FD Interest'!D85 -> 30309 | D17: =SUM(C14:C17) -> 874048
B18: Sinking Fund | F18: Deposits:
A19: 459965 | B19: As per last Balance Sheet | C19: =SUM(A19:A21) -> 498899 | E19: 16690 | F19: Security Deposit (Tata Power) | H19: 23897
A20: 9120 | B20: Add: Addition during the year | C20: 9120
A21: 29814 | B21: Add: Accrued / Interest Earned | C21: ='FD Interest'!D87 -> 32122 | D21: =SUM(C19:C21) -> 540141 | F21: Fixed Assets: (As per Schedule 2)
B22: Repair Fund | E22: 9718736 | F22: Land and Building | G22: ='FA-Sch 2'!H4 -> 9718736
A23: 831154 | B23: As per last Balance Sheet | C23: =SUM(A23:A25) -> 910701 | E23: 389 | F23: Furniture and Fixture | G23: ='FA-Sch 2'!H5 -> 350
A24: 27492 | B24: Add: Addition during the year | C24: 27492 | E24: 28567 | F24: Water Pump | G24: ='FA-Sch 2'!H6 -> 24282
A25: 52055 | B25: Add: Accrued / Interest Earned | C25: ='FD Interest'!D80 -> 64547 | D25: =SUM(C23:C25) -> 1002740 | E25: 7593 | F25: Borewell | G25: ='FA-Sch 2'!H7 -> 6454
B26: Bldg Development Fund | E26: 1062 | F26: Fan | G26: ='FA-Sch 2'!H10 -> 903
A27: 829304.75 | B27: As per last Balance Sheet | C27: =SUM(A27:A29) -> 1097760.8 | E27: 10575 | F27: LED Monitor | G27: ='FA-Sch 2'!H9 -> 8989
A28: 177528 | B28: Add: Addition during the year | C28: 177528 | E28: 41042 | F28: CCTV | G28: ='FA-Sch 2'!H8 -> 34886
A29: 90928 | B29: Add: Accrued / Interest Earned | C29: ='FD Interest'!D83 -> 105923 | E29: 0 | F29: New Pipeline | G29: ='FA-Sch 2'!H11 -> 203500 | H29: =SUM(G22:G29) -> 9998100
A30: 0 | B30: Less: Major Repair Expenses | C30: 0 | D30: =SUM(C27:C30) -> 1381211.8
B31: Parking Deposit | F31: Sundry Debtors:
A32: 51723 | B32: As per last Balance Sheet | C32: =SUM(A32:A34) -> 60020 | E32: 6624 | F32: Dues from Members (As per Schedule 3) | G32: ='Sch 3 to 6'!D6 -> 43723
A33: 8297 | B33: Add: Accrued / Interest Earned | C33: ='FD Interest'!D84 -> 12027 | D33: =SUM(C32:C33) -> 72047 | E33: 2019 | F33: Interest Receivable on Security Deposit from Tata Power | G33: 2019
B34: Education & Training Fund | H34: =SUM(G32:G33) -> 45742
A35: 24082 | B35: As per last Balance Sheet | C35: =SUM(A35:A37) -> 28432
A36: 2640 | B36: Add: Addition during the year | C36: 2640 | F36: Other Current Assets:
A37: 1710 | B37: Add: Accrued / Interest Earned | C37: ='FD Interest'!D81 -> 2123 | D37: =SUM(C35:C37) -> 33195 | E37: 55991 | F37: TDS Receivable | G37: 71718
E38: 12744 | F38: Prepaid Lift AMC | G38: 12891
B39: Current Liabilities & Provisions | E39: 29233 | F39: Prepaid Pest Control | G39: =Workings!E12 -> 29760 | H39: =SUM(G37:G39) -> 114369
A40: 20525 | B40: Advance from Member (As per schedule 4) | C40: ='Sch 3 to 6'!D14 -> 15605
A41: 60000 | B41: Refundable Deposit (As per schedule 5) | C41: ='Sch 3 to 6'!D28 -> 60000
...

Sheet IE
A1: =BS!A1 -> BETSY CO-OPERATIVE HOUSING SOCIETY LTD
A2: 68, Marve Road, Orlem, Malad (West), Mumbai, Maharshtra-400064
A3: Society Reg No : MUM/WP/HSG/TC/10340 dt. 28.04.99
A4: Income and Expenditure for the year ended 31st March 2026
A5: March 31, 2025 | B5: EXPENDITURE | D5: March 31, 2026 | E5: =A5 -> March 31, 2025 | F5: INCOME | H5: =D5 -> March 31, 2026
F6: Members ContributionTowards
A7: 155051 | B7: Property Tax | D7: 190448 | E7: 483432 | F7: Maintenance Charges | G7: 483432
E8: 136584 | F8: Electricity Charges | G8: 136584
A9: 123696 | B9: Electricity Charges | D9: 106384 | E9: 49392 | F9: Water Charges | G9: 49392
E10: 20916 | F10: Lift Maintenance Charges | G10: 20916
A11: 51322 | B11: Water Expenses | D11: 53380 | E11: 5598 | F11: Non Occupancy Charges | G11: 6220
E12: 48000 | F12: Parking Charges | G12: =19200+4400+8400+15600 -> 47600
B13: Service Charges | E13: 566 | F13: Interest on Delayed Payments | G13: 3113
A14: 192000 | B14: Security Expenses | C14: 196912 | E14: 3024 | F14: Garage Tax | G14: 4920
A15: 0 | B15: CCTV AMC | C15: 0 | E15: 444 | F15: Cheque Bounce charges | G15: 0
A16: 826 | B16: Subscription Federation | C16: 826 | E16: 142008 | F16: Municipal Tax | G16: =176760+17740 -> 194500 | H16: =SUM(G7:G16) -> 946677
A17: 15720 | B17: Depreciation | C17: ='FA-Sch 2'!G12 -> 29864
A18: 40920 | B18: Pest Control Charges | C18: 41173 | F18: Other Member Income
A19: 0 | B19: Audit Fees | C19: 2500 | D19: =SUM(C14:C19) -> 271275 | E19: 5000 | F19: Shifting Charges | G19: 5000
E20: 0 | F20: Electricity Renovation charges | G20: 4286
B21: Office Expenses | E21: 3000 | F21: Penalty | G21: 3000 | H21: =SUM(G19:G21) -> 12286
A22: 52000 | B22: Salary /Bonus Expenses | C22: =65470+5000 -> 70470
A23: 15392 | B23: Accounting Charges | C23: 15392 | F23: Interest Income
A24: 4117 | B24: Printing and Stationary | C24: 4169 | E24: 22699 | F24: Interest Income - Savings Account | H24: 20358
A25: 0 | B25: Income Tax Expenses | C25: -356 | E25: 638 | F25: Interest Income from IT Refund | H25: 287
A26: 5315 | B26: Meeting Expenses | C26: 4326 | E26: 254243 | F26: Interest Income - Fixed Deposit | G26: 320070
A27: 351.95 | B27: Bank Charges | C27: 528.15 | F27: Less: Trfd to Liabilities
A28: 3000 | B28: Professional Fees | C28: 3000 | E28: -52055 | F28: Bldg Repair Fund | G28: 64547
A29: 11876 | B29: Festival Expense | C29: 1350 | E29: -1710 | F29: Education & Training Fund | G29: 2123
A30: 1614 | B30: Conveyance Expenses | C30: 2170 | E30: -90928 | F30: Building Development Fund | G30: 105923
A31: 9450 | B31: Miscellaneous Expenses | C31: 10790 | D31: =SUM(C22:C31) -> 111839.15 | E31: -8297 | F31: Parking Deposit | G31: 12027
E32: -25726 | F32: Reserve Fund | G32: 30309
B33: Repair & Maintenance | E33: -29814 | F33: Sinking Fund | G33: 32122 | H33: =G26-SUM(G28:G33) -> 73019
A34: 9836 | B34: Lift AMC Expenses | C34: 16963
A35: 14000 | B35: Major Repair Expenses | C35: 0 | E35: 0 | F35: Dividend | H35: 0
A36: 0 | B36: Lift Repair & Maintenance | C36: 0
A37: 4071 | B37: CCTV Repair & Maintenance | C37: 8210
A38: 13135 | B38: Repair Maintenance - Electrical | C38: 75510
A39: 10546 | B39: Repair Maintenance - Other | C39: =54520+6599 -> 61119
A40: 3500 | B40: Water Tank Cleaning | C40: 3500 | D40: =SUM(C34:C40) -> 165302
...

Sheet FD-Sch 1
A1: =BS!A1 -> BETSY CO-OPERATIVE HOUSING SOCIETY LTD
B2: Scheduel 1: Details of Fixed Deposits as on 31st March 2026
A3: Sr. | B3: Certificate No. | C3: Date | D3: Amount Invested | E3: Accrued Int. 22-23 | F3: Accrued Int. 23-24 | G3: Accrued Int. 24-25 | H3: Accrued Int. 25-26 | I3: Total | J3: Maturity Date | K3: Maturity Value | L3: Interest % | M3: Bank
B4: Sinking Fund
A5: 1 | B5: 384066-R15 | C5: 19.03.2026 | D5: 86561 | E5: 0 | F5: 0 | G5: 0 | H5: 174 | I5: =SUM(D5:H5) -> 86735 | J5: 19.03.2027 | K5: 91841 | L5: 6.1 | M5: CCB
A6: 2 | B6: 476584-R15 | C6: 21.03.2026 | D6: 78695 | E6: 0 | F6: 0 | G6: 0 | H6: 132 | I6: =SUM(D6:H6) -> 78827 | J6: 21.03.2027 | K6: 83495 | L6: 6.1 | M6: CCB
A7: 3 | B7: 551598-R14 | C7: 04.08.2025 | D7: 58476 | E7: 0 | F7: 0 | G7: 0 | H7: 2430 | I7: =SUM(D7:H7) -> 60906 | J7: 04.08.2027 | K7: 65983 | L7: 6.1 | M7: CCB
A8: 4 | B8: 003141_3 | C8: 06.05.2025 | D8: 16325 | E8: 0 | F8: 0 | G8: 0 | H8: 127 | I8: =SUM(D8:H8) -> 16452 | J8: 22.10.2026 | K8: 16496 | L8: 4.25 | M8: CCB
A9: 5 | B9: 476961-R40 | C9: 28.05.2025 | D9: 21453 | E9: 0 | F9: 0 | G9: 0 | H9: 113 | I9: =SUM(D9:H9) -> 21566 | J9: 13.11.2026 | K9: 21678 | L9: 4.25 | M9: CCB
A10: 6 | B10: 477604-R40 | C10: 18.05.2025 | D10: 21073 | E10: 0 | F10: 0 | G10: 0 | H10: 136 | I10: =SUM(D10:H10) -> 21209 | J10: 03.11.2026 | K10: 21294 | L10: 4.25 | M10: CCB
A11: 7 | B11: 548311-R39 | C11: 28.01.2025 | D11: 20024 | E11: 0 | F11: 0 | G11: 0 | H11: 177 | I11: =SUM(D11:H11) -> 20201 | J11: 13.10.2026 | K11: 20234 | L11: 4.25 | M11: CCB
A12: 8 | B12: 587906-R38 | C12: 18.01.2025 | D12: 18629 | E12: 0 | F12: 0 | G12: 0 | H12: 186 | I12: =SUM(D12:H12) -> 18815 | J12: 03.10.2026 | K12: 18824 | L12: 4.25 | M12: CCB
A13: 9 | B13: 625431-R40 | C13: 29.06.2025 | D13: 17611 | E13: 0 | F13: 0 | G13: 0 | H13: 25 | I13: =SUM(D13:H13) -> 17636 | J13: 15.09.2026 | K13: 17796 | L13: 4.25 | M13: CCB
A14: 10 | B14: TD0000403571_3 | C14: 27.03.2026 | D14: 16198 | E14: 0 | F14: 0 | G14: 0 | H14: =16-2 -> 14 | I14: =SUM(D14:H14) -> 16212 | J14: 25.03.2027 | K14: 17167 | L14: 6 | M14: SCB
A15: 11 | B15: TD0000406346_03 | C15: 07.09.2025 | D15: 82092 | E15: 0 | F15: 0 | G15: 0 | H15: =3294-329 -> 2965 | I15: =SUM(D15:H15) -> 85057 | J15: 07.09.2027 | K15: 94263 | L15: 7 | M15: SCB
A16: 12 | B16: TD0000414152_02 | C16: 01.02.2025 | D16: 12933 | E16: 0 | F16: 0 | G16: =151-16 -> 135 | H16: =937-92 -> 845 | I16: =SUM(D16:H16) -> 13913 | J16: 01.02.2028 | K16: 15918 | L16: 7 | M16: SCB
A17: 13 | B17: TD0000414168_02 | C17: 14.02.2026 | D17: 30747 | E17: 0 | F17: 0 | G17: 0 | H17: =263-26 -> 237 | I17: =SUM(D17:H17) -> 30984 | J17: 14.02.2029 | K17: 37294 | L17: 6.5 | M17: SCB
A18: 14 | B18: TD0000414147_03 | C18: 27.03.2026 | D18: 14958 | E18: 0 | F18: 0 | G18: 0 | H18: =14-1 -> 13 | I18: =SUM(D18:H18) -> 14971 | J18: 27.03.2028 | K18: 17114 | L18: 6.8 | M18: SCB
A19: 15 | B19: TD1000697044-1 | C19: 10.03.2025 | D19: 3151 | E19: 0 | F19: 0 | G19: =14-1 -> 13 | H19: =235-24 -> 211 | I19: =SUM(D19:H19) -> 3375 | J19: 10.03.2027 | K19: 3638 | L19: 7.25 | M19: SCB
A20: 16 | B20: TD1001128233 | C20: 20.03.2024 | D20: 9859 | E20: 0 | F20: =23-2 -> 21 | G20: =718-71 -> 647 | H20: =766-78 -> 688 | I20: =SUM(D20:H20) -> 11215 | J20: 20.03.2027 | K20: 12176 | L20: 7.1 | M20: SCB
A21: 17 | B21: TD1001580377 | C21: 27.03.2025 | D21: 10012 | E21: 0 | F21: 0 | G21: =10-1 -> 9 | H21: =771-77 -> 694 | I21: =SUM(D21:H21) -> 10715 | J21: 27.07.2026 | K21: 11054 | L21: 7.5 | M21: SCB
D22: =SUM(D5:D21) -> 518797 | E22: =SUM(E5:E21) -> 0 | F22: =SUM(F5:F21) -> 21 | G22: =SUM(G5:G21) -> 804 | H22: =SUM(H5:H21) -> 9167 | I22: =SUM(I5:I21) -> 528789 | K22: =SUM(K5:K21) -> 566265
B23: Reserve Fund
A24: 18 | B24: 608343 - R02 | C24: 26.09.2022 | D24: 14705 | E24: 418 | F24: =850 -> 850 | G24: =898 -> 898 | H24: 947 | I24: =SUM(D24:H24) -> 17818 | J24: 26.09.2027 | K24: 19323 | L24: 5.5 | M24: CCB
A25: 19 | B25: TD0000414167_02 | C25: 01.02.2025 | D25: 162273 | E25: 0 | F25: 0 | G25: =1893-189 -> 1704 | H25: =11753-1174 -> 10579 | I25: =SUM(D25:H25) -> 174556 | J25: 01.02.2026 | K25: 199732 | L25: 7 | M25: SCB
A26: 20 | B26: TD0000414171_2 | C26: 14.02.2026 | D26: 118712 | E26: 0 | F26: 0 | G26: 0 | H26: =1016-102 -> 914 | I26: =SUM(D26:H26) -> 119626 | J26: 14.02.2026 | K26: 143990 | L26: 6.5 | M26: SCB
A27: 21 | B27: TD0000414148_1 | C27: 03.02.2024 | D27: 80487 | E27: 0 | F27: =922-92 -> 830 | G27: =5913-590 -> 5323 | H27: =6300-629 -> 5671 | I27: =SUM(D27:H27) -> 92311 | J27: 03.02.2027 | K27: 99387 | L27: 7.1 | M27: SCB
A28: 22 | B28: TD1000277843-1 | C28: 19.03.2025 | D28: 40950 | E28: 0 | F28: 0 | G28: =107-11 -> 96 | H28: =3158-315 -> 2843 | I28: =SUM(D28:H28) -> 43889 | J28: 19.03.2026 | K28: 45205 | L28: 7.5 | M28: SCB
A29: 23 | B29: TD1000697037-1 | C29: 10.03.2025 | D29: 2293 | E29: 0 | F29: 0 | G29: =10-1 -> 9 | H29: =171-18 -> 153 | I29: =SUM(D29:H29) -> 2455 | J29: 10.03.2026 | K29: 2647 | L29: 7.25 | M29: SCB
D30: =SUM(D24:D29) -> 419420 | E30: =SUM(E24:E29) -> 418 | F30: =SUM(F24:F29) -> 1680 | G30: =SUM(G24:G29) -> 8030 | H30: =SUM(H24:H29) -> 21107 | I30: =SUM(I24:I29) -> 450655 | K30: =SUM(K24:K29) -> 510284
B32: Share Capital
A33: 24 | B33: 608344- R01 | C33: 26.09.2022 | D33: 5500 | E33: 0 | F33: 0 | G33: 0 | H33: 0 | I33: =SUM(D33:H33) -> 5500 | J33: 26.09.2027 | K33: 5500 | L33: 5.5 | M33: CCB
A34: 25 | B34: TD1000277973-1 | C34: 19.03.2025 | D34: 5500 | E34: 0 | F34: 0 | G34: 0 | H34: 0 | I34: =SUM(D34:H34) -> 5500 | J34: 19.11.2027 | K34: 5500 | L34: 7.5 | M34: SCB
D35: =SUM(D33:D34) -> 11000 | E35: =SUM(E33:E34) -> 0 | F35: =SUM(F33:F34) -> 0 | G35: =SUM(G33:G34) -> 0 | H35: =SUM(H33:H34) -> 0 | I35: =SUM(I33:I34) -> 11000 | K35: =SUM(K33:K34) -> 11000
B37: Painting & Development Fund
A38: 26 | B38: TD0000406343_02 | C38: 27.03.2026 | D38: 199257 | E38: 0 | F38: 0 | G38: 0 | H38: =174-18 -> 156 | I38: =SUM(D38:H38) -> 199413 | J38: 27.03.2029 | K38: 241714 | L38: 6.5 | M38: SCB
A39: 27 | B39: TD0000406344_1 | C39: 23.08.2023 | D39: 94497 | E39: 0 | F39: =4126-413 -> 3713 | G39: =7142-715 -> 6427 | H39: =7609-761 -> 6848 | I39: =SUM(D39:H39) -> 111485 | J39: 23.08.2026 | K39: 116628 | L39: 7.1 | M39: SCB
A40: 28 | B40: TD0000414165_02 | C40: 01.02.2025 | D40: 251777 | E40: 0 | F40: 0 | G40: =2937-294 -> 2643 | H40: =18235-1824 -> 16411 | I40: =SUM(D40:H40) -> 270831 | J40: 01.02.2026 | K40: 309897 | L40: 7 | M40: SCB
A41: 29 | B41: TD0000414172_02 | C41: 01.02.2025 | D41: 406004.75 | E41: 0 | F41: 0 | G41: =4737-474 -> 4263 | H41: =29404-2939 -> 26465 | I41: =SUM(D41:H41) -> 436732.75 | J41: 01.02.2026 | K41: 499425.75 | L41: 7 | M41: SCB
A42: 30 | B42: TD0000414170_02 | C42: 01.02.2026 | D42: 349263.75 | E42: 0 | F42: 0 | G42: 0 | H42: =2990-299 -> 2691 | I42: =SUM(D42:H42) -> 351954.75 | J42: 14.02.2029 | K42: 423633.75 | L42: 6.5 | M42: SCB
...

Sheet FA-Sch 2
A1: BETSY CO-OPERATIVE HOUSING SOCIETY LIMITED
A2: Schedule 2: Fixed Assets Details as at 31st March 2026
A3: Particulars | B3: Rate % | C3: Opening W.D.V. as on 01.04.2025 | D3: Additions during the year before 30.09.2025 | E3: Additions during the year after 30.09.2025 | F3: Gross Block (at cost) as on 31.03.2026 | G3: Depreciation for the year | H3: Closing W.D.V. as on 31.03.2026
A4: Land and Building at cost | B4: 0 | C4: 9718736 | D4: 0 | E4: 0 | F4: =SUM(C4:E4) -> 9718736 | G4: =ROUND((C4+D4)*B4+(E4*B4/2),0) -> 0 | H4: =F4-G4 -> 9718736
A5: Furniture & Fixtures | B5: 0.1 | C5: 389 | D5: 0 | E5: 0 | F5: =SUM(C5:E5) -> 389 | G5: =ROUND((C5+D5)*B5+(E5*B5/2),0) -> 39 | H5: =F5-G5 -> 350
A6: Water Pump Account | B6: 0.15 | C6: 28567 | D6: 0 | E6: 0 | F6: =SUM(C6:E6) -> 28567 | G6: =ROUND((C6+D6)*B6+(E6*B6/2),0) -> 4285 | H6: =F6-G6 -> 24282
A7: Borewell Account | B7: 0.15 | C7: 7593 | D7: 0 | E7: 0 | F7: =SUM(C7:E7) -> 7593 | G7: =ROUND((C7+D7)*B7+(E7*B7/2),0) -> 1139 | H7: =F7-G7 -> 6454
A8: CCTV | B8: 0.15 | C8: 41042 | D8: 0 | E8: 0 | F8: =SUM(C8:E8) -> 41042 | G8: =ROUND((C8+D8)*B8+(E8*B8/2),0) -> 6156 | H8: =F8-G8 -> 34886
A9: LED Monitor | B9: 0.15 | C9: 10575 | D9: 0 | E9: 0 | F9: =SUM(C9:E9) -> 10575 | G9: =ROUND((C9+D9)*B9+(E9*B9/2),0) -> 1586 | H9: =F9-G9 -> 8989
A10: Fan | B10: 0.15 | C10: 1062 | D10: 0 | E10: 0 | F10: =SUM(C10:E10) -> 1062 | G10: =ROUND((C10+D10)*B10+(E10*B10/2),0) -> 159 | H10: =F10-G10 -> 903
A11: Pipeline Replacement | B11: 0.15 | D11: 0 | E11: 220000 | F11: =SUM(C11:E11) -> 220000 | G11: =ROUND((C11+D11)*B11+(E11*B11/2),0) -> 16500 | H11: =F11-G11 -> 203500
A12: Total :- | C12: =SUM(C4:C11) -> 9807964 | D12: =SUM(D4:D10) -> 0 | E12: =SUM(E4:E11) -> 220000 | F12: =SUM(F4:F11) -> 10027964 | G12: =SUM(G4:G11) -> 29864 | H12: =SUM(H4:H11) -> 9998100

Sheet Sch 3 to 6
A1: BETSY CO-OPERATIVE HOUSING SOCIETY LIMITED
A2: Sch 3: Member's Due as on 31st March 2026
A3: Sr. | B3: Flat | C3: Name | D3: Amount
A4: 1 | B4: 101 | C4: Mr. Anselm A. Desa and Mrs. Maureen A. Desa | D4: 5018
A5: 2 | B5: 602 | C5: Mr. B. M Ramchandani | D5: 38705
A6: Total | D6: =SUM(D4:D5) -> 43723
A8: Sch 4: Advance from Members as on 31st March 2026
A9: Sr. | B9: Flat | C9: Name | D9: Amount
A10: 1 | B10: 103 | C10: Mr. Llewellyn F. D'souza | D10: 2185
A11: 2 | B11: 0B1 | C11: Mrs. Veena Gotecha | D11: 8893
A12: 3 | B12: 401 | C12: Mr. Savio Joseph Lawrence Lobo | D12: 4517
A13: 4 | B13: 302 | C13: Mr. Iqbal Singh Bahadur Singh Dadial | D13: 10
A14: Total | D14: =SUM(D10:D13) -> 15605
A16: Sch 5: Refundable Deposit as on 31st March 2026
A17: Sr. | B17: Flat | C17: Name | D17: Amount
A18: 1 | B18: 0B1 | C18: Mrs. Veena Gotecha | D18: 15000
A19: 2 | B19: 101 | C19: Mr. Anselm A. Desa | D19: 5000
A20: 3 | B20: 102 | C20: Mrs. Christine Albuquerque | D20: 5000
A21: 4 | B21: 201 | C21: Mr. Bosco Joseph Britto | D21: 5000
A22: 5 | B22: 203 | C22: Mrs. Maria Dias | D22: 5000
A23: 6 | B23: 301 | C23: Mr. Fritz A. Fernandes | D23: 5000
A24: 7 | B24: 302 | C24: Mr. Iqbal Dadial | D24: 5000
A25: 8 | B25: 402 | C25: Mr. Wilbur Agnel D'Souza | D25: 5000
A26: 9 | B26: 403 | C26: Mrs. Sybil D'Souza | D26: 5000
A27: 10 | B27: 501 | C27: Mr. Christopher D'Silva | D27: 5000
A28: Total | D28: =SUM(D18:D27) -> 60000
A30: Sch 6: Provision/Payable as on 31st March 2026
B31: Sr. No. | C31: Vendor | D31: Amount
B32: 1 | C32: Bihar Security Services - Mar 25 | D32: 2100
B33: 2 | C33: Irene Rosario | D33: 1500
B34: 3 | C34: Narendra Jha | D34: 14225
B35: 4 | C35: Sweeper March 26 | D35: 8000
B36: 5 | C36: Tata Power March 2026 | D36: 4139
B37: Total | D37: =SUM(D32:D36) -> 29964

Sheet BRS
A1: BETSY CO-OPERATIVE HOUSING SOCIETY LIMITED
A2: Saraswat Bank Reconciliation Statement as on 31st March 2026
C3: Amount
B4: Balance as per System (Book Balance) | C4: 599390.71
A6: Add: | B6: Cheques Issued but not Presented | C6: 0
B7: As per schedule attached
A9: Less: | B9: Cheques Deposited but not Cleared | C9: 0
B11: Balance as per Bank Passbook | C11: =+C4+C6-C9 -> 599390.71
A14: MDCC Bank Reconciliation Statement as on 31st March 2026
C15: Amount
B16: Balance as per System (Book Balance) | C16: 16235
B18: Balance as per Bank Passbook | C18: =+C16 -> 16235
A21: Citizen Credit Bank Reconciliation Statement as on 31st March 2026
C22: Amount
B23: Balance as per System (Book Balance) | C23: 24714
B25: Balance as per Bank Passbook | C25: =+C23 -> 24714

Sheet FD Interest
A1: Betsy Co-op. Housing Society Ltd - Income - Non Members > Interest Income - Fixed Deposit ( 306002 ) <br/>Transactions From 1-04-2025 to 31-03-2026
A2: Journal No. | B2: Posted Date | C2: Comments | D2: Credit
A3: JE-2025-0000037 | B3: 31-03-2026 | C3: Being int accu on FD 406342- RDF - SCB | D3: 7162
A4: JE-2025-0000048 | B4: 31-03-2026 | C4: Being int accu on FD TD0000414149- RDF - SCB | D4: 2213
A5: JE-2025-0000066 | B5: 31-03-2026 | C5: Being int accu on FD TD1000277956 - RDF- SCB | D5: 2652
A6: JE-2025-0000058 | B6: 14-02-2026 | C6: Being FD 414170 renewed and remade SCB - PDF | D6: 20487
A7: JE-2025-0000038 | B7: 27-03-2026 | C7: Being FD TD0000406343 renewed and remade SCB - PDF | D7: 13239
A8: JE-2025-0000039 | B8: 31-03-2026 | C8: Being int accu on FD TD0000406343 - PDF - SCB | D8: 174
A9: JE-2025-0000040 | B9: 31-03-2026 | C9: Being int accu on FD TD0000406344 - PDF - SCB | D9: 7609
A10: JE-2025-0000051 | B10: 31-03-2026 | C10: Being int accu on FD TD0000414165- PDF - SCB | D10: 18235
A11: JE-2025-0000059 | B11: 31-03-2026 | C11: Being int accu on FD TD0000414170 - PDF - SCB | D11: 2990
A12: JE-2025-0000062 | B12: 31-03-2026 | C12: Being int accu on FD 414172- PDF - SCB | D12: 29404
A13: JE-2025-0000071 | B13: 31-03-2026 | C13: Being int accu on FD TD1000697085- PDF - SCB | D13: 13785
A14: JE-2025-0000049 | B14: 31-03-2026 | C14: Being int accu on FD 414150- ETF - SCB | D14: 1191
... A76: JE-2025-0000080 | B76: 31-03-2026 | C76: Being int accu on FD TD1001580383 - BRF - SCB | D76: 2441
D77: =SUM(D3:D76) -> 320070
D80: 64547 | E80: BRF
D81: 2123 | E81: ETF
D82: 72302 | E82: GF
D83: 105923 | E83: PDF
D84: 12027 | E84: RDF | F84: REFUNDABLE
D85: 30309 | E85: RF | F85: RESERVE FUND
D86: 717 | E86: SC
D87: 32122 | E87: SF
D88: =SUM(D80:D87) -> 320070 | E88: System
D90: 299227 | E90: SCB BANK
D91: 20843 | E91: CCB BANK
D92: =SUM(D90:D91) -> 320070 | G92: =D92-D86-D82 -> 247051
D93: =D88-D92 -> 0 | E93: Diff

Sheet Workings
B1: Note: Workings Page is not the be printed
B2: Water Expenses
B3: 45968 | C3: 46059 | D3: =+C3-B3 -> 91 | E3: 13336
B4: =+C3 -> 46059 | C4: 46112 | D4: =+C4-B4 -> 53 | E4: =ROUND(E3/D3*D4,0) -> 7767 | F4: provision
B6: Lift AMC
B7: 46023 | C7: 46387 | D7: =+C7-B7+1 -> 365 | E7: 17110
B8: 46113 | C8: =+C7 -> 46387 | D8: =+C8-B8+1 -> 275 | E8: =ROUND(E7*D8/D7,0) -> 12891 | F8: Prepaid
B10: Pest Control
B11: 46023 | C11: 46387 | D11: =+C11-B11+1 -> 365 | E11: 39500
B12: 46113 | C12: =+C11 -> 46387 | D12: =+C12-B12+1 -> 275 | E12: =ROUND(E11*D12/D11,0) -> 29760 | F12: Prepaid
