Workbook

Sheet BS
A1: Domonica CHS Ltd
A2: Reg. no.BOM/WKE/HSG/TC/14063/2008 Dt.10/01/2008
A3: Balance Sheet as at 31st March, 2026
A4: March 31, 2025 | B4: LIABILITIES | D4: March 31, 2026 | E4: =A4 -> March 31, 2025 | F4: ASSETS | H4: =D4 -> March 31, 2026
A5: 100000 | B5: Authorised Share Capital | D5: 100000 | F5: Savings Bank
E6: 41023.71 | F6: HDFC a/c-00601450000885 | G6: =BRS!C6 -> 42085.71
B7: Share Capital Subscribed | E7: 265828.01 | F7: Citizen a/c-2090182000006930 | G7: =BRS!C15 -> 222824.41
A8: 14000 | B8: 280 shares pf Rs.50 each | D8: 14000 | E8: 31817.5 | F8: MSC Bank a/c. | G8: =BRS!C23 -> 32799.5
E9: 178893 | F9: Yes Bank | G9: =BRS!C31 -> 26390.33 | H9: =SUM(G6:G9) -> 324099.95
B10: Reserve & Surplus
A11: 37250 | B11: Statutory Reserve Fund | C11: =SUM(A11:A13) -> 116403 | F11: Cash in Hand
A12: 0 | B12: Add: Trf from Common Amenity Fund | C12: 1787024 | E12: 2790 | F12: Petty Cash | H12: 1514
A13: 79153 | B13: Add: Accrued / Interest Earned | C13: =-IE!G25 -> 137186 | D13: =SUM(C11:C13) -> 2040613
F14: Investments
A15: 729942 | B15: Sinking Fund | C15: =SUM(A15:A18) -> 29478 | E15: 100 | F15: 1 share of Housing Federation | H15: 100
A16: 29460 | B16: Add: Addition during the year | C16: 29460
A17: -4375 | B17: Add: Accrued / Interest Earned | C17: =-IE!G23 -> 2282 | F17: Long Term Fixed Deposits
A18: -725549 | B18: Less: Major Repairs | C18: 0 | D18: =SUM(C15:C18) -> 61220 | E18: 1999742 | F18: Fixed Deposit - Schedule 1 | G18: ='FD Details'!D28 -> 2145217
E19: 31521 | F19: Accrued Interest of FD | G19: ='FD Details'!G28 -> 146066 | H19: =SUM(G18:G19) -> 2291283
A20: 0 | B20: Repair and Maintenance Fund | C20: =SUM(A20:A22) -> 98365
A21: 98304 | B21: Add: Addition during the year | C21: 98304 | F21: Loans & Advances
A22: 61 | B22: Add: Accrued / Interest Earned | C22: =-IE!G24 -> 7490 | D22: =SUM(C20:C22) -> 204159 | E22: 10258.4 | F22: Deposit with Adani (esrtwhile Reliance) | G22: =6424.05+5727.45 -> 12151.5
E23: 15000 | F23: Deposit with Active Infotech | G23: 15000
A24: 21808 | B24: Education Fund | C24: =SUM(A24:A26) -> 25168 | E24: 43550 | F24: Advance Tax | G24: 20000
A25: 3360 | B25: Add: Addition during the year | C25: 3360 | E25: 134715 | F25: Indus Tower TDS | G25: =57735+11513+14271 -> 83519
A26: 0 | B26: Less: Training expenses incurred | C26: -1770 | D26: =SUM(C24:C26) -> 26758 | E26: 7929 | F26: Citizen Bank TDS | G26: =14476+226 -> 14702
E27: 75000 | F27: Advance for Automatic Gate | G27: 0 | H27: =SUM(G22:G27) -> 145372.5
A28: 4243118 | B28: Common Amenity Fund | C28: 4243118
A29: 0 | B29: Less: Trf to Retained Earnings | C29: -2456094 | E29: 546460 | F29: Fixed Assets - Schedule 2 | H29: =FA!I21 -> 506811
A30: 0 | B30: Less: Trf to Reserve Fund | C30: -1787024 | D30: =SUM(C28:C30) -> 0
F31: Other Current Assets
B32: Current liabilities | E32: 115287 | F32: Member Receivables- Schedule 3 | G32: ='Sch 3'!G32 -> 234204
A33: 854443 | B33: Advance for Municipal Taxes Collected | D33: =A33 -> 854443 | E33: 24680 | F33: Prepaid Expense | G33: 9842 | H33: =SUM(G32:G33) -> 244046
B35: Other Liabilities | E35: 6000 | F35: Advance from Vendor - Schedule 4 | H35: 0
A36: 166000 | B36: Income Tax Payable | C36: 152000
A37: 6000 | B37: Audit Fee Payable | C37: 3000 | F37: Income and Expenditure Account:
A38: 47554 | B38: Water Charges Payable | C38: 17597 | E38: 1207698.3 | F38: As per last balance sheet | G38: =SUM(E38:E41) -> 2913979.1
A39: 0 | B39: Federation Subscription Payable | C39: 826 | E39: 0 | F39: Less: Prior Years Adjustment | G39: =-30107-4246-12000+75000 -> 28647
A40: 4246 | B40: N.A. Land Tax Payable | C40: 0 | E40: 0 | F40: Less: Trf from Common Amenity Fund | G40: -2456094
A41: 47509 | B41: Payables to Vendors | C41: ='Sch 4'!D9 -> 34508 | E41: =IE!E30 -> 1706280.8 | F41: Add: Surplus/(Deficit) for the year | G41: =IE!H30 -> -377596.83 | H41: =SUM(G38:G41) -> 108935.25
...

Sheet IE
A1: Domonica CHS Ltd
A2: Reg. no.BOM/WKE/HSG/TC/14063/2008 Dt.10/01/2008
A3: Income & Expense Statement for year ended 31st March 2026
A4: March 31, 2025 | B4: EXPENDITURE | D4: March 31, 2026 | E4: =A4 -> March 31, 2025 | F4: INCOME | H4: =D4 -> March 31, 2026
A5: 202734 | B5: Property Tax | D5: 271826 | F5: Maintenance Income
E6: 295680 | F6: Maintenance Charges | G6: 295680
B7: Manager's Remunerations | E7: 147840 | F7: Electricity Charges | G7: 147840
A8: 79125 | B8: Manager's Remuneration | C8: 79500 | E8: 162300 | F8: Water Charges | G8: 162300
A9: 6000 | B9: Bonus | C9: 14000 | D9: =SUM(C8:C9) -> 93500 | E9: 31920 | F9: Lift Maintenance Charges | G9: 31920
E10: 45869 | F10: 2W Parking Charges | G10: =33150+1147 -> 34297
A11: 123910 | B11: Common Area Electricity Expenses | D11: 130466.9 | E11: 13490 | F11: Non Occupancy Charges | G11: 13490
E12: 128936 | F12: 4W Parking Charges | G12: 143884
B13: Water Expenses | E13: 518 | F13: Other charges | G13: 0
A14: 114966 | B14: Water Expenses | C14: 115156 | E14: 24171 | F14: Late Payment Interest | G14: 30299 | H14: =SUM(G5:G14) -> 859710
A15: 7700 | B15: Water Tanker expenses | C15: 25500 | D15: =SUM(C14:C15) -> 140656
F16: Property tax
B17: Repair & Maintenance | E17: 329496 | F17: Municipal Taxes | H17: 377395
A18: 69400 | B18: Electrical Repair Maintenance | C18: 34900
A19: 130688 | B19: Other Repair Maintenance | C19: 19287 | F19: Interest Income
A20: 142480 | B20: Plumbing Repair Maintenance | C20: 5000 | E20: 20626 | F20: Interest Income Savings Account | G20: =10764+432+22 -> 11218
A21: 2635684 | B21: Major Repair Expenses | C21: 0 | E21: 2083 | F21: Interest on IT Refund | G21: 0
A22: -725549 | B22: Less: Trf to Major Repair Fund | C22: 0 | E22: 74839 | F22: Interest Income Fixed Deposit | G22: 146958
A23: 35582 | B23: Pest Control | C23: 15410 | E23: 4375 | F23: Less: Transferred to Sinking Reserve Fund | G23: -2282
A24: 7906 | B24: Fire Fighting Expenses | C24: 9440 | E24: -61 | F24: Less: Transferred to Repair Fund | G24: =-7372-118 -> -7490
A25: 0 | B25: CCTV Repair Expenses | C25: 1770 | E25: -79153 | F25: Less: Transferred to General Reserve Fund | G25: -137186 | H25: =SUM(G20:G25) -> 11218
A26: 7640 | B26: Intercom AMC Expenses | C26: 13165 | D26: =SUM(C18:C26) -> 98972
F27: Other Income
B28: Service Charges | E28: 769800 | F28: Tower Rent Income | H28: =692477.33+14271 -> 706748.33
A29: 294079 | B29: Security Expenses | C29: 301548
A30: 62513 | B30: House Keeping Expenses | C30: 73821 | E30: =A50-SUM(E6:E28) -> 1706280.8 | F30: Deficit (Surplus) for the period | H30: =D50-SUM(H6:H28) -> -377596.83
A31: 7000 | B31: Garbage Disposal Expense | C31: 1370
A32: 3000 | B32: Audit Fees | C32: 3000 | D32: =SUM(C29:C32) -> 379739
B34: Office Expenses
A35: 5000 | B35: Telephone and Internet Expenses | C35: 4740
A36: 24000 | B36: Accounting Charges | C36: 26400
A37: 3000 | B37: Professional Fees | C37: 1500
A38: 826 | B38: Subscription Federation | C38: 826
A39: 5750 | B39: Printing and Stationary | C39: 3551
A40: 17230 | B40: Meeting Expenses | C40: 23341
A41: 24518 | B41: Miscellaneous Expenses | C41: 447
...

Sheet TB
C2: Domonica CHS Ltd
C3: Trial Balance-Domonica CHS Ltd-31-Mar-2024
B4: Section | C4: GL Account | D4: Account | E4: Opening Debit | F4: Opening Credit | G4: Period Debit | H4: Period Credit | I4: Closing Debit | J4: Closing Credit
B5: Assets | C5: 101001 | D5: HDFC a/c-00601450000885 | E5: 106630.79 | F5: 0 | G5: 855232 | H5: 922045.08 | I5: 39817.71 | J5: 0 | L5: 39817.71 | N5: =I5-L5 -> 0
B6: Assets | C6: 101002 | D6: Citizen a/c - 2090182000006930 | E6: 54496.03 | F6: 0 | G6: 3060678 | H6: 2967156.6 | I6: 148017.41 | J6: 0 | L6: 148017.41 | N6: =I6-L6 -> 0
B7: Assets | C7: 101003 | D7: MSC Bank a/c | E7: 28945.5 | F7: 0 | G7: 898 | H7: 0 | I7: 29843.5 | J7: 0 | L7: 29843.5 | N7: =I7-L7 -> 0
B8: Assets | C8: 101004 | D8: Project A/c - Citizen Bank | E8: 8574 | F8: 0 | G8: 0 | H8: 0 | I8: 8574 | J8: 0 | L8: 8574 | N8: =I8-L8 -> 0
B9: Assets | C9: 101005 | D9: Yes Bank a/c - 020188700000206 | E9: 0 | F9: 0 | G9: 976241 | H9: 783270 | I9: 192971 | J9: 0 | L9: 192971 | N9: =I9-L9 -> 0
B10: Assets | C10: 102001 | D10: Petty Cash | E10: 435 | F10: 0 | G10: 40000 | H10: 38126 | I10: 2309 | J10: 0 | L10: 2309 | N10: =I10-L10 -> 0
B11: Assets | C11: 103001 | D11: 1 share of Housing Federation | E11: 100 | F11: 0 | G11: 0 | H11: 0 | I11: 100 | J11: 0 | L11: 100 | N11: =I11-L11 -> 0
B12: Assets | C12: 103008 | D12: Accrued Interest of FD | E12: 168330 | F12: 0 | G12: 97988 | H12: 165975 | I12: 100343 | J12: 0 | L12: 100343 | N12: =I12-L12 -> 0
B13: Assets | C13: 104001 | D13: 310130_R01 CCB - SF | E13: 38000 | F13: 0 | G13: 0 | H13: 38000 | I13: 0 | J13: 0 | L13: 0 | N13: =I13-L13 -> 0
B14: Assets | C14: 104002 | D14: 306357_R05 CCB - SF | E14: 100000 | F14: 0 | G14: 0 | H14: 0 | I14: 100000 | J14: 0 | L14: 100000 | N14: =I14-L14 -> 0
B15: Assets | C15: 104003 | D15: 306634596_R06 CCB - SF | E15: 88000 | F15: 0 | G15: 0 | H15: 88000 | I15: 0 | J15: 0 | L15: 0 | N15: =I15-L15 -> 0
B16: Assets | C16: 104004 | D16: 3051151_R01 CCB - SF | E16: 130099 | F16: 0 | G16: 0 | H16: 130099 | I16: 0 | J16: 0 | L16: 0 | N16: =I16-L16 -> 0
... B54: Assets | C54: 106003 | D54: Deposit with Active Infotech | E54: 15000 | F54: 0 | G54: 0 | H54: 0 | I54: 15000 | J54: 0 | L54: 15000 | N54: =I54-L54 -> 0
B55: Assets | C55: 106004 | D55: Advance Tax | E55: 62000 | F55: 0 | G55: 133000 | H55: 62000 | I55: =E55+G55-H55 -> 133000 | J55: 0 | L55: 133000 | N55: =I55-L55 -> 0
B56: Assets | C56: 106007 | D56: Advance for Automatic Gate | E56: 75000 | F56: 0 | G56: 0 | H56: 0 | I56: 75000 | J56: 0 | L56: 75000 | N56: =I56-L56 -> 0
B57: Assets | C57: 107001 | D57: Members Receivable | E57: 1579 | F57: 0 | G57: 1248 | H57: 1579 | I57: 1248 | J57: 0 | L57: 1248 | N57: =I57-L57 -> 0
B58: Assets | C58: 108002 | D58: Building Front Entrance Door | E58: 10419 | F58: 0 | G58: 0 | H58: 1042 | I58: 9377 | J58: 0 | L58: 9377 | N58: =I58-L58 -> 0
B59: Assets | C59: 108003 | D59: Bio-metric system | E59: 5179 | F59: 0 | G59: 0 | H59: 2072 | I59: 3107 | J59: 0 | L59: 3107 | N59: =I59-L59 -> 0
B60: Assets | C60: 108004 | D60: Compound Main Gate | E60: 6820 | F60: 0 | G60: 0 | H60: 682 | I60: 6138 | J60: 0 | L60: 6138 | N60: =I60-L60 -> 0
B61: Assets | C61: 108005 | D61: Cars Parking Shed | E61: 181111 | F61: 0 | G61: 0 | H61: 18111 | I61: 163000 | J61: 0 | L61: 163000 | N61: =I61-L61 -> 0
B62: Assets | C62: 108006 | D62: Bikes Parking Shed | E62: 20322 | F62: 0 | G62: 0 | H62: 2032 | I62: 18290 | J62: 0 | L62: 18290 | N62: =I62-L62 -> 0
B63: Assets | C63: 108007 | D63: Monsoon Shed on Terrace | E63: 168550 | F63: 0 | G63: 0 | H63: 16855 | I63: 151695 | J63: 0 | L63: 151695 | N63: =I63-L63 -> 0
B64: Assets | C64: 108008 | D64: Lights and Fans on Terrace | E64: 8805 | F64: 0 | G64: 0 | H64: 881 | I64: 7924 | J64: 0 | L64: 7924 | N64: =I64-L64 -> 0
B65: Assets | C65: 108009 | D65: Porta Cabin - Watchman | E65: 21218 | F65: 0 | G65: 0 | H65: 2489 | I65: 18729 | J65: 0 | L65: 18729 | N65: =I65-L65 -> 0
B66: Assets | C66: 108010 | D66: Society Office | E66: 36730 | F66: 0 | G66: 0 | H66: 3306 | I66: 33424 | J66: 0 | L66: 33424 | N66: =I66-L66 -> 0
B67: Assets | C67: 108011 | D67: Member Name Plate Board | E67: 31917 | F67: 0 | G67: 0 | H67: 3192 | I67: 28725 | J67: 0 | L67: 28725 | N67: =I67-L67 -> 0
... B79: Assets | C79: 109007 | D79: Excess paid to Zicom | E79: 11106.4 | F79: 0 | G79: 0 | H79: 0 | I79: 11106.4 | J79: 0 | L79: 11106.4 | N79: =I79-L79 -> 0
N80: =I80-L80 -> 0
B81: Assets Total | E81: 5545561.1 | F81: 0 | G81: 11763080 | H81: 11513848 | I81: 5794792.7 | J81: 0 | L81: 5794792.7 | N81: =I81-L81 -> 0
N82: =I82-L82 -> 0
B83: Liabilities | C83: 201001 | D83: Share Capital | E83: 0 | F83: 14000 | G83: 0 | H83: 0 | I83: 0 | J83: 14000 | L83: 14000 | N83: =L83-J83 -> 0
B84: Liabilities | C84: 202001 | D84: Statutory Reserve Fund | E84: 0 | F84: 35800 | G84: 0 | H84: 1450 | I84: 0 | J84: =F84+H84 -> 37250 | L84: 37250 | N84: =L84-J84 -> 0
B85: Liabilities | C85: 202002 | D85: Sinking Fund | E85: 0 | F85: 669707 | G85: 0 | H85: 60459 | I85: 0 | J85: 730166 | L85: 730166 | N85: =L85-J85 -> 0
B86: Liabilities | C86: 202003 | D86: Repair and Maintenance Fund | E86: 0 | F86: 975302.92 | G86: 0 | H86: 265004 | I86: 0 | J86: 1240306.9 | L86: 1240306.9 | N86: =L86-J86 -> 0
B87: Liabilities | C87: 202005 | D87: Common Amenity Fund | E87: 0 | F87: 4243118 | G87: 0 | H87: 0 | I87: 0 | J87: 4243118 | L87: 4243118 | N87: =L87-J87 -> 0
B88: Liabilities | C88: 203005 | D88: TDS Payable | E88: 0 | F88: 0 | G88: 0 | H88: 13049 | I88: 0 | J88: 13049 | L88: 13049 | N88: =L88-J88 -> 0
B89: Liabilities | C89: 203004 | D89: Payables | E89: 0 | F89: 28742 | G89: 2589156.7 | H89: 2606914.7 | I89: 0 | J89: 46500 | L89: 46500 | N89: =L89-J89 -> 0
...

Sheet Receipt & Payments
A1: Domonica CHS Ltd
A2: Reg. no.BOM/WKE/HSG/TC/14063/2008 Dt.10/01/2008
A3: Receipts & Payments A/C for Period 01.04.2023 to 31.03.2024
A4: Receipts | C4: Amount | D4: Payments | F4: =C4 -> Amount
A5: Bank & Cash Balance beginning of 01-04-2023 | D5: Accounting Charges | F5: 7500
A6: Opening HDFC a/c-00601450000885 | B6: 93576.33 | D6: AMC Water Pump | F6: 12000
A7: Opening Citizen a/c-2090182000006930 | B7: 28466.83 | D7: Audit Fees | F7: 5900
A8: Opening MSC Bank a/c. - | B8: 28367.5 | D8: Bank Charges | F8: 70.8
A9: Opening Project A/c - Citizen Bank | B9: 8323 | D9: Bonus | F9: 4780
A10: Opening Petty Cash | B10: 3841 | C10: =SUM(B6:B10) -> 162574.66 | D10: CCTV Rent Expense | F10: 58195.24
D11: Common Area Electricity Expenses | F11: 122850
A12: Receipts from Members | C12: 1310290.7 | D12: Conveyance Charges | F12: 690
D13: Election Expense | F13: 10000
D14: Electrical Repair Maintenance | F14: 11352
A15: Income from Non Members | D15: Fixed Asset Control A/C | F15: =6000+6000 -> 12000
A16: Tower Rent Income | C16: 173205 | D16: Garbage Disposal Expenses | F16: 6000
D17: House Keeping Expenses | F17: 57305
D18: Insurance Expenses | F18: 14344
A19: Journal Entries | C19: 408559 | D19: Intercom AMC Expenses | F19: 7650
D20: Land Rent Expense | F20: 80490
D21: Lift Repair & Maintenance | F21: 273800
D22: Meals & Refreshments | F22: 100
D23: Meeting Expenses | F23: 5886
D24: Miscellaneous Expenses | F24: 7694
D25: Other Repair Maintenance | F25: 17560
D26: Plumbing Repairs | F26: 6400
D27: Printing & Stationary | F27: 7503
D28: Professional Fees | F28: 93500
D29: Property Tax - Members | F29: 241360
D30: Salary Expenses | F30: 18000
D31: Security Expenses | F31: 271519
... D42: Journal Entries | F42: 356464
D44: Bank & Cash Balance Closing of 31-03-2024
D45: HDFC a/c-00601450000885 balance | E45: 106630.79
D46: Citizen a/c-2090182000006930 balance | E46: 55322.03
D47: MSC Bank a/c. - balance | E47: 28945.5
D48: Project A/c - Citizen Bank balance | E48: 8323
D49: Petty Cash balance | E49: 435 | F49: =SUM(E45:E49) -> 199656.32
A51: Total | C51: =SUM(C5:C50) -> 2054629.4 | D51: Total | F51: =SUM(F4:F50) -> 2054629.4

Sheet FD Details
A1: Domonica CHS Ltd
A2: Schedule 1: Fixed Deposit Details as at 31st March 2026
A4: Sr- | B4: Certificate No- | C4: Deposit Date | D4: Principal | E4: Accd Int 24-25 | F4: Accd Int 25-26 | G4: Total Accd Int | H4: Total | I4: Mat Date | J4: Mat Value | K4: ROI | L4: Bank
B5: Sinking Fund
A6: 1 | B6: 101843221001231 | C6: 45744 | D6: 29460 | E6: 18 | F6: =2208-221 -> 1987 | G6: =SUM(E6:F6) -> 2005 | H6: =SUM(D6:F6) -> 31465 | I6: 46744 | J6: 35513 | K6: 7-5% | L6: Citizencredit | N6: TDS booked as per 26AS
A7: 2 | B7: 101843221001471 | C7: 46101 | D7: 29460 | E7: 0 | F7: =56-5 -> 51 | G7: =SUM(E7:F7) -> 51 | H7: =SUM(D7:F7) -> 29511 | I7: 47101 | J7: 34585 | K7: 6-35% | L7: Citizencredit | N7: TDS booked as per 26AS
B8: Total | D8: =SUM(D6:D7) -> 58920 | E8: =SUM(E6:E7) -> 18 | F8: =SUM(F6:F7) -> 2038 | G8: =SUM(G6:G7) -> 2056 | H8: =SUM(H6:H7) -> 60976 | J8: =SUM(J6:J7) -> 70098
B10: General Funds
A11: 3 | B11: 101843051000498 | C11: 46002 | D11: 215813 | E11: 0 | F11: =4207-418 -> 3789 | G11: =SUM(E11:F11) -> 3789 | H11: =SUM(D11:F11) -> 219602 | I11: 46502 | J11: 234734 | K11: 0.064 | L11: Citizencredit
A12: 4 | B12: 2090180003051568 | C12: 45503 | D12: 122347 | E12: 2433 | F12: =8872-888 -> 7984 | G12: =SUM(E12:F12) -> 10417 | H12: =SUM(D12:F12) -> 132764 | I12: 46137 | J12: 134498 | K12: 7-25% | L12: Citizencredit
A13: 5 | B13: 2090180003051572 | C13: 45503 | D13: 122347 | E13: 2433 | F13: =8872-888 -> 7984 | G13: =SUM(E13:F13) -> 10417 | H13: =SUM(D13:F13) -> 132764 | I13: 46137 | J13: 134498 | K13: 7-25% | L13: Citizencredit
A14: 6 | B14: 2090180003051662 | C14: 45490 | D14: 462141 | E14: 10300 | F14: =33504-3350 -> 30154 | G14: =SUM(E14:F14) -> 40454 | H14: =SUM(D14:F14) -> 502595 | I14: 46124 | J14: 508039 | K14: 7-25% | L14: Citizencredit
A15: 7 | B15: 2090180003051571 | C15: 45503 | D15: 122347 | E15: 2433 | F15: =8872-888 -> 7984 | G15: =SUM(E15:F15) -> 10417 | H15: =SUM(D15:F15) -> 132764 | I15: 46137 | J15: 134498 | K15: 7-25% | L15: Citizencredit
A16: 8 | B16: 2090180003051569 | C16: 45503 | D16: 122347 | E16: 2433 | F16: =8872-888 -> 7984 | G16: =SUM(E16:F16) -> 10417 | H16: =SUM(D16:F16) -> 132764 | I16: 46137 | J16: 134498 | K16: 7-25% | L16: Citizencredit
A17: 9 | B17: 2090180003051570 | C17: 45503 | D17: 122347 | E17: 2433 | F17: =8872-888 -> 7984 | G17: =SUM(E17:F17) -> 10417 | H17: =SUM(D17:F17) -> 132764 | I17: 46137 | J17: 134498 | K17: 7-25% | L17: Citizencredit
A18: 10 | B18: 101843221001207 | C18: 45744 | D18: 200000 | E18: 110 | F18: =15000-1501 -> 13499 | G18: =SUM(E18:F18) -> 13609 | H18: =SUM(D18:F18) -> 213609 | I18: 46744 | J18: 241096 | K18: 7-5% | L18: Citizencredit
A19: 11 | B19: 101843221001219 | C19: 45744 | D19: 200000 | E19: 110 | F19: =15000-1501 -> 13499 | G19: =SUM(E19:F19) -> 13609 | H19: =SUM(D19:F19) -> 213609 | I19: 46744 | J19: 241096 | K19: 7-5% | L19: Citizencredit
A20: 12 | B20: 1018432221001221 | C20: 45744 | D20: 200000 | E20: 110 | F20: =15000-1501 -> 13499 | G20: =SUM(E20:F20) -> 13609 | H20: =SUM(D20:F20) -> 213609 | I20: 46744 | J20: 241096 | K20: 7-5% | L20: Citizencredit
B21: Total | D21: =SUM(D11:D20) -> 1889689 | E21: =SUM(E11:E20) -> 22795 | F21: =SUM(F11:F20) -> 114360 | G21: =SUM(G11:G20) -> 137155 | H21: =SUM(H11:H20) -> 2026844 | J21: =SUM(J11:J20) -> 2138551
B23: Repair Funds
A24: 13 | B24: 101843221001198 | C24: 45744 | D24: 98304 | E24: =61-7 -> 54 | F24: =7372-740 -> 6632 | G24: =SUM(E24:F24) -> 6686 | H24: =SUM(D24:F24) -> 104990 | I24: 46744 | J24: 118503 | K24: 7-5% | L24: Citizencredit
A25: 14 | B25: 101843221001499 | C25: 46101 | D25: 98304 | E25: 0 | F25: =188-19 -> 169 | G25: =SUM(E25:F25) -> 169 | H25: =SUM(D25:F25) -> 98473 | I25: 47101 | J25: 115406 | K25: 0.0635 | L25: Citizencredit
B26: Total | D26: =SUM(D24:D25) -> 196608 | E26: =SUM(E24:E25) -> 54 | F26: =SUM(F24:F25) -> 6801 | G26: =SUM(G24:G25) -> 6855 | H26: =SUM(H24:H25) -> 203463 | J26: =SUM(J24:J25) -> 233909
B28: Grand Total | D28: =+D8+D21+D26 -> 2145217 | E28: =+E8+E21+E26 -> 22867 | F28: =+F8+F21+F26 -> 123199 | G28: =+G8+G21+G26 -> 146066 | H28: =+H8+H21+H26 -> 2291283 | J28: =+J8+J21+J26 -> 2442558

Sheet FA
A1: Domonica CHS Ltd
A2: Schedule 2: Fixed Assets Details as at 31st March 2026
A3: Sr. no | B3: Particulars | C3: Rate % | D3: Opening W.D.V. as on 01.04.2025 | E3: Additions during the year before 30.09.2025 | F3: Additions during the year after 30.09.2025 | G3: Gross Block (at cost) as on 31.03.2026 | H3: Depreciation for the year | I3: Closing W.D.V. as on 31.03.2026
A4: 1 | B4: Furniture & Fixtures | C4: 0.1 | D4: 33892 | E4: 0 | F4: 0 | G4: =SUM(D4:F4) -> 33892 | H4: =ROUND((D4+E4)*C4+(F4*C4/2),0) -> 3389 | I4: =G4-H4 -> 30503
A5: 2 | B5: Water Level Indicator | C5: 0.1 | D5: 7656 | E5: 0 | F5: 0 | G5: =SUM(D5:F5) -> 7656 | H5: =ROUND((D5+E5)*C5+(F5*C5/2),0) -> 766 | I5: =G5-H5 -> 6890
A6: 3 | B6: Computer Printers | C6: 0.4 | D6: 1076 | E6: 0 | F6: 0 | G6: =SUM(D6:F6) -> 1076 | H6: =ROUND((D6+E6)*C6+(F6*C6/2),0) -> 430 | I6: =G6-H6 -> 646
A7: 4 | B7: Telecom System | C7: 0.15 | D7: 12871 | E7: 0 | F7: 0 | G7: =SUM(D7:F7) -> 12871 | H7: =ROUND((D7+E7)*C7+(F7*C7/2),0) -> 1931 | I7: =G7-H7 -> 10940
A8: 5 | B8: CCTV System | C8: 0.15 | D8: 56206 | E8: 0 | F8: 0 | G8: =SUM(D8:F8) -> 56206 | H8: =ROUND((D8+E8)*C8+(F8*C8/2),0) -> 8431 | I8: =G8-H8 -> 47775
A9: 6 | B9: Building Front Entrance Door | C9: 0.1 | D9: 8439 | E9: 0 | F9: 0 | G9: =SUM(D9:F9) -> 8439 | H9: =ROUND((D9+E9)*C9+(F9*C9/2),0) -> 844 | I9: =G9-H9 -> 7595
A10: 7 | B10: Bio-metric system | C10: 0.4 | D10: 1864 | E10: 0 | F10: 0 | G10: =SUM(D10:F10) -> 1864 | H10: =ROUND((D10+E10)*C10+(F10*C10/2),0) -> 746 | I10: =G10-H10 -> 1118
A11: 8 | B11: Compound Main Gate | C11: 0.1 | D11: 5524 | E11: 0 | F11: 0 | G11: =SUM(D11:F11) -> 5524 | H11: =ROUND((D11+E11)*C11+(F11*C11/2),0) -> 552 | I11: =G11-H11 -> 4972
A12: 9 | B12: Car Parking shed | C12: 0.1 | D12: 146700 | E12: 0 | F12: 0 | G12: =SUM(D12:F12) -> 146700 | H12: =ROUND((D12+E12)*C12+(F12*C12/2),0) -> 14670 | I12: =G12-H12 -> 132030
A13: 10 | B13: Bike Parking Shed | C13: 0.1 | D13: 16461 | E13: 0 | F13: 0 | G13: =SUM(D13:F13) -> 16461 | H13: =ROUND((D13+E13)*C13+(F13*C13/2),0) -> 1646 | I13: =G13-H13 -> 14815
A14: 11 | B14: Monsoon Shed on Terrace | C14: 0.1 | D14: 136525 | E14: 0 | F14: 0 | G14: =SUM(D14:F14) -> 136525 | H14: =ROUND((D14+E14)*C14+(F14*C14/2),0) -> 13653 | I14: =G14-H14 -> 122872
A15: 12 | B15: Lights & Fans on Terrace | C15: 0.1 | D15: 7132 | E15: 0 | F15: 0 | G15: =SUM(D15:F15) -> 7132 | H15: =ROUND((D15+E15)*C15+(F15*C15/2),0) -> 713 | I15: =G15-H15 -> 6419
... A20: 17 | B20: Lenovo Laptop | C20: 0.4 | D20: 0 | E20: 35500 | F20: 0 | G20: =SUM(D20:F20) -> 35500 | H20: =ROUND((D20+E20)*C20+(F20*C20/2),0) -> 14200 | I20: =G20-H20 -> 21300
A21: Total | D21: =SUM(D4:D20) -> 546460 | E21: =SUM(E4:E20) -> 35500 | F21: =SUM(F4:F20) -> 0 | G21: =SUM(G4:G20) -> 581960 | H21: =SUM(H4:H20) -> 75149 | I21: =SUM(I4:I20) -> 506811

Sheet Sch 4
A2: Domonica CHS Ltd
A3: Vendor Payables and Advances
A4: Sr. No. | B4: Vendor Name | C4: Advance | D4: Payables
A5: 1 | B5: Pheonix Management Serives | C5: 0 | D5: 4500
A6: 2 | B6: Sai Engineering & Electricals | C6: 0 | D6: 0
A7: 3 | B7: Sweeper Salary | C7: 0 | D7: 5500
A8: 4 | B8: Security Salary | C8: 0 | D8: 24508
A9: Total | C9: =SUM(C5:C8) -> 0 | D9: =SUM(D5:D8) -> 34508

Sheet Members Contribution
A1: Domonica CHS Ltd
A2: Flat-Wise Contibution Details for the period from 1st April 2022 to 31st March 2023
A3: Sl. No | B3: Flat | C3: Member Name | D3: Open Bal. | E3: Late Pymt Int. | F3: Maint. Chgs | G3: Elect. Chgs | H3: Water Chgs | I3: Lift Maint. Chgs | J3: 2W Park Chgs | K3: 4W Park Chgs | L3: Edu. & Trng Fund | M3: Municipal Taxes | N3: Sinking Fund | O3: Repair Fund | P3: Party Hall Income | Q3: Penalty & Other chgs | R3: Entrance Fee | S3: Share Transfer Fee | T3: Transfer Premium | U3: NOC | V3: Other Charges | W3: Total Bill | X3: Total Receipts | Y3: Interest accrued for Mar 2023 bill | Z3: Net
A4: 1 | B4: 101 | C4: MR. Jeffrey D. D''Mello | D4: 0 | E4: 0 | F4: 10560 | G4: 5280 | H4: 6072 | I4: 1140 | J4: 0 | K4: 0 | L4: 120 | M4: 11148 | N4: 1248 | O4: 4176 | P4: 0 | Q4: 0 | R4: 0 | S4: 0 | T4: 0 | U4: 1925 | V4: 0 | W4: =SUM(D4:V4) -> 41669 | X4: 41669 | Y4: 0 | Z4: =W4-X4+Y4 -> 0
A5: 2 | B5: 102 | C5: Mr. Berny Netto | D5: 0 | E5: 60 | F5: 10560 | G5: 5280 | H5: 6072 | I5: 1140 | J5: 1800 | K5: 10088 | L5: 120 | M5: 11820 | N5: 1332 | O5: 4428 | P5: 0 | Q5: 0 | R5: 0 | S5: 0 | T5: 0 | U5: 0 | V5: 0 | W5: =SUM(D5:V5) -> 52700 | X5: 52700 | Y5: 0 | Z5: =W5-X5+Y5 -> 0
A6: 3 | B6: 103 | C6: Ms. Ashleen C. Knight | D6: 0 | E6: 0 | F6: 10560 | G6: 5280 | H6: 6072 | I6: 1140 | J6: 0 | K6: 0 | L6: 120 | M6: 6444 | N6: 720 | O6: 2412 | P6: 0 | Q6: 0 | R6: 0 | S6: 0 | T6: 0 | U6: 0 | V6: 0 | W6: =SUM(D6:V6) -> 32748 | X6: 32748 | Y6: 0 | Z6: =W6-X6+Y6 -> 0
A7: 4 | B7: 201 | C7: Ms. Donna D''Mello | D7: 0 | E7: 0 | F7: 10560 | G7: 5280 | H7: 6072 | I7: 1140 | J7: 0 | K7: 0 | L7: 120 | M7: 11148 | N7: 1248 | O7: 4176 | P7: 0 | Q7: 0 | R7: 0 | S7: 0 | T7: 0 | U7: 0 | V7: 0 | W7: =SUM(D7:V7) -> 39744 | X7: 39744 | Y7: 0 | Z7: =W7-X7+Y7 -> 0
A8: 5 | B8: 202 | C8: Mr. Avellino D''Mello | D8: 0 | E8: 0 | F8: 10560 | G8: 5280 | H8: 4044 | I8: 1140 | J8: 0 | K8: 0 | L8: 120 | M8: 10008 | N8: 1128 | O8: 3756 | P8: 0 | Q8: 0 | R8: 0 | S8: 0 | T8: 0 | U8: 0 | V8: 0 | W8: =SUM(D8:V8) -> 36036 | X8: 36036 | Y8: 0 | Z8: =W8-X8+Y8 -> 0
A9: 6 | B9: 203 | C9: Ms. Albertina D''Souza | D9: -20107 | E9: 0 | F9: 10560 | G9: 5280 | H9: 6072 | I9: 1140 | J9: 300 | K9: 11528 | L9: 120 | M9: 8244 | N9: 924 | O9: 3096 | P9: 0 | Q9: 0 | R9: 0 | S9: 0 | T9: 0 | U9: 0 | V9: 0 | W9: =SUM(D9:V9) -> 27157 | X9: 53000 | Y9: 0 | Z9: =W9-X9+Y9 -> -25843
A10: 7 | B10: 301 | C10: Ms. Nereen Jeffrey Dmello | D10: 0 | E10: 0 | F10: 10560 | G10: 5280 | H10: 6072 | I10: 1140 | J10: 0 | K10: 0 | L10: 120 | M10: 11148 | N10: 1248 | O10: 4176 | P10: 0 | Q10: 0 | R10: 0 | S10: 0 | T10: 0 | U10: 0 | V10: 0 | W10: =SUM(D10:V10) -> 39744 | X10: 39744 | Y10: 0 | Z10: =W10-X10+Y10 -> 0
A11: 8 | B11: 302 | C11: Ms. Assenta D''Mello | D11: 0 | E11: 0 | F11: 10560 | G11: 5280 | H11: 4044 | I11: 1140 | J11: 0 | K11: 0 | L11: 120 | M11: 10008 | N11: 1128 | O11: 3756 | P11: 0 | Q11: 0 | R11: 0 | S11: 0 | T11: 0 | U11: 0 | V11: 0 | W11: =SUM(D11:V11) -> 36036 | X11: 36036 | Y11: 0 | Z11: =W11-X11+Y11 -> 0
A12: 9 | B12: 303 | C12: Ms. Noreen G Fernandes | D12: 0 | E12: 0 | F12: 10560 | G12: 5280 | H12: 6072 | I12: 1140 | J12: 0 | K12: 0 | L12: 120 | M12: 8244 | N12: 924 | O12: 3096 | P12: 0 | Q12: 0 | R12: 0 | S12: 0 | T12: 0 | U12: 0 | V12: 0 | W12: =SUM(D12:V12) -> 35436 | X12: 35436 | Y12: 0 | Z12: =W12-X12+Y12 -> 0
A13: 10 | B13: 401 | C13: Mr. K. A. Vincent | D13: 0 | E13: 0 | F13: 10560 | G13: 5280 | H13: 6072 | I13: 1140 | J13: 1800 | K13: 0 | L13: 120 | M13: 11148 | N13: 1248 | O13: 4176 | P13: 0 | Q13: 0 | R13: 0 | S13: 0 | T13: 0 | U13: 0 | V13: 0 | W13: =SUM(D13:V13) -> 41544 | X13: 41544 | Y13: 0 | Z13: =W13-X13+Y13 -> 0
A14: 11 | B14: 402 | C14: Mr. Bernard Spitz | D14: -30 | E14: 253 | F14: 10560 | G14: 5280 | H14: 6072 | I14: 1140 | J14: 5400 | K14: 0 | L14: 120 | M14: 11820 | N14: 1332 | O14: 4428 | P14: 0 | Q14: 0 | R14: 0 | S14: 0 | T14: 0 | U14: 0 | V14: 0 | W14: =SUM(D14:V14) -> 46375 | X14: 46375 | Y14: 0 | Z14: =W14-X14+Y14 -> 0
A15: 12 | B15: 403 | C15: Mr. Yeshwant D. Salvi | D15: 0 | E15: 456 | F15: 10560 | G15: 5280 | H15: 6072 | I15: 1140 | J15: 4050 | K15: 0 | L15: 120 | M15: 6444 | N15: 720 | O15: 2412 | P15: 0 | Q15: 0 | R15: 0 | S15: 0 | T15: 0 | U15: 1750 | V15: 0 | W15: =SUM(D15:V15) -> 39004 | X15: 39004 | Y15: 0 | Z15: =W15-X15+Y15 -> 0
... A27: 24 | B27: 803 | C27: Ms. Carral Netto | D27: 0 | E27: 90 | F27: 10560 | G27: 5280 | H27: 6072 | I27: 1140 | J27: 1350 | K27: 7792 | L27: 120 | M27: 9924 | N27: 720 | O27: 2412 | P27: 0 | Q27: 0 | R27: 0 | S27: 0 | T27: 0 | U27: 2100 | V27: 0 | W27: =SUM(D27:V27) -> 47560 | X27: 47560 | Y27: 0 | Z27: =W27-X27+Y27 -> 0
A28: 25 | B28: G001 | C28: Mr. Stanney D'Souza | D28: 25840 | E28: 8929 | F28: 10560 | G28: 5280 | H28: 6072 | I28: 1140 | J28: 1800 | K28: 10088 | L28: 120 | M28: 9732 | N28: 1092 | O28: 3648 | P28: 3000 | Q28: 0 | R28: 0 | S28: 0 | T28: 0 | U28: 0 | V28: 0 | W28: =SUM(D28:V28) -> 87301 | X28: 28000 | Y28: 1248 | Z28: =W28-X28+Y28 -> 60549
A29: 26 | B29: G002 | C29: MR. James P. D'Sa | D29: 0 | E29: 152 | F29: 10560 | G29: 5280 | H29: 6072 | I29: 1140 | J29: 1800 | K29: 18270 | L29: 120 | M29: 7536 | N29: 852 | O29: 2820 | P29: 0 | Q29: 500 | R29: 0 | S29: 0 | T29: 0 | U29: 0 | V29: 0 | W29: =SUM(D29:V29) -> 55102 | X29: 55102 | Y29: 0 | Z29: =W29-X29+Y29 -> 0
A30: 27 | B30: G002A | C30: Mr. Stanney D'Souza | D30: 38964 | E30: 7939 | F30: 10560 | G30: 5280 | H30: 2412 | I30: 1140 | J30: 0 | K30: 0 | L30: 120 | M30: 33444 | N30: 384 | O30: 1260 | P30: 0 | Q30: 0 | R30: 100 | S30: 500 | T30: 25000 | U30: 0 | V30: 0 | W30: =SUM(D30:V30) -> 127103 | X30: 121825 | Y30: 43 | Z30: =W30-X30+Y30 -> 5321
A31: 28 | B31: G003 | C31: Mr. Varghese Anthony V.K. | D31: 30 | E31: 628 | F31: 10560 | G31: 5280 | H31: 6072 | I31: 1140 | J31: 0 | K31: 0 | L31: 120 | M31: 6444 | N31: 720 | O31: 2412 | P31: 0 | Q31: 0 | R31: 0 | S31: 0 | T31: 0 | U31: 0 | V31: 0 | W31: =SUM(D31:V31) -> 33406 | X31: 59508.7 | Y31: 0 | Z31: =W31-X31+Y31 -> -26102.7
A32: Total | D32: =SUM(D4:D31) -> 45796 | E32: =SUM(E4:E31) -> 24123 | F32: =SUM(F4:F31) -> 295680 | G32: =SUM(G4:G31) -> 147840 | H32: =SUM(H4:H31) -> 162300 | I32: =SUM(I4:I31) -> 31920 | J32: =SUM(J4:J31) -> 41400 | K32: =SUM(K4:K31) -> 81610 | ... Z32: =SUM(Z4:Z31) -> 31822.3

Sheet Property Tax
A1: Domonica CHS Ltd
A2: Property Tax collected but not assessed/paid to MCGM
A3: Sr. no. | B3: Flat no. | C3: Name of Member | D3: 2013-14 | E3: 2014-15 | F3: 2015-16 | G3: 2016-17 | H3: 2017-18 | I3: 2018-19 | J3: 2019-20 | K3: 2020-21 | L3: 2021-22 | M3: 2022-23 | N3: Total
A4: 1 | B4: 101 | C4: Mr. Jeffrey D. D'mello | D4: 8118 | E4: 12300 | F4: 11148 | G4: 11148 | H4: 11148 | I4: 11148 | J4: 11148 | K4: 11148 | L4: 11148 | M4: 11148 | N4: =SUM(D4:M4) -> 109602
A5: 2 | B5: 501 | C5: Mr. Avellino D'mello | D5: 5631 | E5: 12924 | F5: 11712 | G5: 11712 | H5: 11712 | I5: 11712 | J5: 11712 | K5: 11712 | L5: 11712 | M5: 11712 | N5: =SUM(D5:M5) -> 112251
A6: 3 | B6: 601 | C6: Mr. P. S. Varghese | D6: 0 | E6: 0 | F6: 1952 | G6: 11712 | H6: 11712 | I6: 11712 | J6: 11712 | K6: 11712 | L6: 11712 | M6: 11712 | N6: =SUM(D6:M6) -> 83936
A7: 4 | B7: 602 | C7: Mr. Henry Louis Chettiar | D7: 22838 | E7: 13764 | F7: 12462 | G7: 12408 | H7: 12408 | I7: 12408 | J7: 12408 | K7: 12408 | L7: 12408 | M7: 12408 | N7: =SUM(D7:M7) -> 135920
A8: 5 | B8: 801 | C8: Mrs. Sujatha Fernandes | D8: 29064 | E8: 18948 | F8: 16356 | G8: 16356 | H8: 16356 | I8: 16356 | J8: 16356 | K8: 16356 | L8: 16356 | M8: 16356 | N8: =SUM(D8:M8) -> 178860
A9: 6 | B9: 803 | C9: Mrs. Carral Netto | D9: 16776 | E9: 10944 | F9: 9924 | G9: 9924 | H9: 9924 | I9: 9924 | J9: 9924 | K9: 9924 | L9: 9924 | M9: 9924 | N9: =SUM(D9:M9) -> 107112
A10: Total | D10: =SUM(D4:D9) -> 82427 | E10: =SUM(E4:E9) -> 68880 | F10: =SUM(F4:F9) -> 63554 | G10: =SUM(G4:G9) -> 73260 | H10: =SUM(H4:H9) -> 73260 | I10: =SUM(I4:I9) -> 73260 | J10: =SUM(J4:J9) -> 73260 | K10: =SUM(K4:K9) -> 73260 | ... N10: =SUM(N4:N9) -> 727681

Sheet Sch 3
A1: Domonica CHS Ltd - Members Account as of 31st March 2026
A2: Sl. No | B2: Unit | C2: Name of Member | D2: Carpet Area | F2: Share Capital | G2: Dues from Members | H2: Advance From Member | I2: Deposit for Internal Repair
D3: Sq. mt. | E3: Sq. ft.
A4: 1 | B4: G001 | C4: Mr. Stanney D'Souza | D4: 56.51 | E4: =D4*10.7639 -> 608.26799 | F4: 500 | G4: 31945 | H4: 0 | I4: 0
A5: 2 | B5: G002 | C5: MR. James P. D'Sa & Ms. Telma D'Sa | D5: 43.7 | E5: =D5*10.7639 -> 470.38243 | F5: 500 | G5: 0 | H5: 0 | I5: 0
A6: 3 | B6: G002A | C6: Ms. Lora John Carvalho | D6: 19.51 | E6: =D6*10.7639 -> 210.00369 | F6: 500 | G6: 164820 | H6: 0 | I6: 0
A7: 4 | B7: G003 | C7: Mr. Varghese Anthony V.K. | D7: 37.38 | E7: =D7*10.7639 -> 402.35458 | F7: 500 | G7: 0 | H7: 1004.7 | I7: 0
A8: 5 | B8: 101 | C8: MR. Jeffrey D. D'Mello | D8: 64.72 | E8: =D8*10.7639 -> 696.63961 | F8: 500 | G8: 0 | H8: 0 | I8: 0
A9: 6 | B9: 102 | C9: Mr. Berny Netto & Ms. Carral Netto | D9: 68.57 | E9: =D9*10.7639 -> 738.08062 | F9: 500 | G9: 0 | H9: 0 | I9: 0
A10: 7 | B10: 103 | C10: Ms. Ashleen C. Knight | D10: 37.38 | E10: =D10*10.7639 -> 402.35458 | F10: 500 | G10: 0 | H10: 1217 | I10: 0
A11: 8 | B11: 201 | C11: Ms. Donna D'Mello | D11: 64.72 | E11: =D11*10.7639 -> 696.63961 | F11: 500 | G11: 0 | H11: 0 | I11: 0
A12: 9 | B12: 202 | C12: Mr. Avellino D'Mello | D12: 58.07 | E12: =D12*10.7639 -> 625.05967 | F12: 500 | G12: 0 | H12: 0 | I12: 0
A13: 10 | B13: 203 | C13: Ms. Albertina D'Souza | D13: 47.88 | E13: =D13*10.7639 -> 515.37553 | F13: 500 | G13: 0 | H13: 26490 | I13: 0
A14: 11 | B14: 301 | C14: Ms. Nereen Jeffrey Dmello | D14: 64.72 | E14: =D14*10.7639 -> 696.63961 | F14: 500 | G14: 0 | H14: 0 | I14: 0
A15: 12 | B15: 302 | C15: Ms. Assenta D'Mello | D15: 58.07 | E15: =D15*10.7639 -> 625.05967 | F15: 500 | G15: 0 | H15: 0 | I15: 0
A16: 13 | B16: 303 | C16: Ms. Noreen G Fernandes | D16: 47.88 | E16: =D16*10.7639 -> 515.37553 | F16: 500 | G16: 0 | H16: 0 | I16: 0
A17: 14 | B17: 401 | C17: Mr. K. A. Vincent | D17: 64.72 | E17: =D17*10.7639 -> 696.63961 | F17: 500 | G17: 0 | H17: 0 | I17: 0
A18: 15 | B18: 402 | C18: Mr. Bernard Spitz & Ms. Scarlet B. Spitz | D18: 68.57 | E18: =D18*10.7639 -> 738.08062 | F18: 500 | G18: 0 | H18: 0 | I18: 0
A19: 16 | B19: 403 | C19: Mr. Yeshwant D. Salvi | D19: 37.38 | E19: =D19*10.7639 -> 402.35458 | F19: 500 | G19: 0 | H19: 3573 | I19: 10000
... A31: 28 | B31: 803 | C31: Ms. Carral Netto | D31: 37.38 | E31: =D31*10.7639 -> 402.35458 | F31: 500 | G31: 0 | H31: 0 | I31: 0
A32: Total | D32: =SUM(D4:D31) -> 1522.46 | E32: =SUM(E4:E31) -> 16387.607 | F32: =SUM(F4:F31) -> 14000 | G32: =SUM(G4:G31) -> 234204 | H32: =SUM(H4:H31) -> 51440.7 | I32: =SUM(I4:I31) -> 20000

Sheet BRS
A1: Domonica CHS Ltd
A3: HDFC Bank Reconciliations Statement as at 31.03.2026
A5: Particulars | C5: Amount
A6: Book balance as per system | C6: 42085.71
A8: Balance as per bank statements | C8: =SUM(C6:C7) -> 42085.71
A12: Citizen Bank Reconciliation Statement as at 31.03.2026
A14: Particulars | C14: Amount
A15: Book balance as per system | C15: 222824.41
A17: Balance as per bank statements | C17: =SUM(C15:C16) -> 222824.41
A20: MSC Bank Reconciliations Statement as at 31.03.2026
A22: Particulars | C22: Amount
A23: Book balance as per system | C23: 32799.5
A25: Balance as per bank statements | C25: =SUM(C23:C24) -> 32799.5
A28: Yes Bank Reconciliation Statement as at 31.03.2026
A30: Particulars | C30: Amount
A31: Book balance as per system | C31: 26390.33
A33: Balance as per bank statements | C33: =SUM(C31:C32) -> 26390.33

Sheet Budget
A1: DOMONICA CO-OPERATIVE HOUSING SOCIETY LIMITED
A2: BUDGET ESTIMATE FOR FY 2023-24
A4: Head of Account | B4: Actual for FY 2022-23 | F4: Estimates for FY 2023-24
B5: Income | D5: Expenditure | E5: Difference | F5: Income | H5: Expenditure | I5: Difference
A6: Municipal/ Property taxes | C6: =IE!H17 -> 377395 | D6: =IE!#REF! -> #REF! | E6: =C6-D6 -> #REF! | G6: =Estimated!D17 -> 241360 | H6: =Estimated!B36 -> 241360 | I6: =G6-H6 -> 0
A7: Water Charges | C7: =IE!G8 -> 162300 | D7: =IE!#REF! -> #REF! | E7: =C7-D7 -> #REF! | G7: =Estimated!D8 -> 130500 | H7: =Estimated!B18+Estimated!B19+Estimated!B39+Estimated!B40 -> 139000 | I7: =G7-H7 -> -8500
A8: Common Electricity Charges | C8: =IE!G7 -> 147840 | D8: =IE!D11 -> 130466.9 | E8: =C8-D8 -> 17373.1 | G8: =Estimated!D7 -> 115000 | H8: =Estimated!B35 -> 115000 | I8: =G8-H8 -> 0
A9: Lift Maintenance Expenses | C9: =IE!G9 -> 31920 | D9: =IE!#REF! -> #REF! | E9: =C9-D9 -> #REF! | G9: =Estimated!D9 -> 260000 | H9: =Estimated!B34 -> 260000 | I9: =G9-H9 -> 0
A10: Administrative & Maintenance
A11: a) Society Maint. Charges | B11: =IE!G6 -> 295680 | F11: =Estimated!D6 -> 1042268
A12: b) Other Items (Please see details below) | B12: =B46 -> #REF! | C12: =SUM(B11:B12) -> #REF! | D12: =H46 -> #REF! | E12: =C12-D12 -> #REF! | F12: =C46 -> 192450 | G12: =SUM(F11:F12) -> 1234718 | H12: =I46 -> 1047472 | I12: =G12-H12 -> 187246
C13: =SUM(C6:C12) -> #REF! | D13: =SUM(D6:D12) -> #REF! | E13: =SUM(E6:E12) -> #REF! | G13: =SUM(G6:G12) -> 1981578 | H13: =SUM(H6:H12) -> 1802832 | I13: =SUM(I6:I12) -> 178746
E14: Deficit | I14: Surplus
A17: Break-up of other Income: | D17: Break-up of other Expenditure:
A18: Particulars | B18: Actual for 2022-23 | C18: Estimates for 2023-24 | D18: Particulars | H18: Actual for 2022-23 | I18: Estimates for 2023-24
A19: Interest on Savings Account | B19: =IE!G20 -> 11218 | C19: =Estimated!D23 -> 0 | D19: Audit Fees | H19: =IE!C32 -> 3000 | I19: =Estimated!B5 -> 5900
A20: Interest on Fixed Deposit | B20: =IE!G22 -> 146958 | C20: =Estimated!D24 -> 0 | D20: Subscription for Federation | H20: =IE!C38 -> 826 | I20: =Estimated!B13 -> 826
A21: Interest on Security Deposit | B21: =IE!#REF! -> #REF! | C21: =Estimated!D25 -> 0 | D21: Security Charges | H21: =IE!C29 -> 301548 | I21: =Estimated!B26 -> 275000
A22: Late Payment Interest | B22: =IE!G14 -> 30299 | C22: =Estimated!D14 -> 0 | D22: Sweeping Charges | H22: =IE!C8 -> 79500 | I22: =Estimated!B22 -> 60000
A23: Penalty & Other Charges | B23: =IE!G13 -> 0 | C23: =Estimated!D13 -> 0 | D23: Ex-Gratia | H23: =IE!C9 -> 14000 | I23: =Estimated!B23 -> 5000
A24: 2W parking charges | B24: =IE!G10 -> 34297 | C24: =Estimated!D10 -> 0 | D24: Housekeeping Exp. | H24: =IE!C30 -> 73821 | I24: =Estimated!B24+Estimated!B20 -> 68000
A25: 4W parking charges | B25: =IE!G12 -> 143884 | C25: =Estimated!D12 -> 0 | D25: Professional Fees | H25: =IE!#REF! -> #REF! | I25: =Estimated!B25 -> 105000
A26: Non Occupancy Charges | B26: =IE!G11 -> 13490 | C26: =Estimated!D11 -> 0 | D26: Electrical Repairs & Replacements | H26: =IE!C18 -> 34900 | I26: =Estimated!B29 -> 12000
A27: Party Hall Income | B27: =IE!#REF! -> #REF! | C27: =Estimated!D20 -> 0 | D27: Plumbing Repairs | H27: =IE!C20 -> 5000 | I27: =Estimated!B30 -> 7000
A28: Tower Rent Income | B28: =IE!H28 -> 706748.33 | C28: =Estimated!D28 -> 192450 | D28: Education & Training Fund | H28: 0 | I28: =Estimated!B38 -> 3360
D29: Accounting Charges | H29: =IE!C36 -> 26400 | I29: =Estimated!B21 -> 24000
D30: Printing & Stationery Expenses | H30: =IE!C39 -> 3551 | I30: =Estimated!B12 -> 4000
D31: Garbage Disposal | H31: =IE!C31 -> 1370 | I31: =Estimated!B27 -> 6000
D32: Society Internet & WIFI | H32: =IE!C35 -> 4740 | I32: =Estimated!B11 -> 600
D33: Building Insurance | H33: =IE!C43 -> 14070 | I33: =Estimated!B37 -> 14344
D34: Depreciation | H34: =IE!C46 -> 75149 | I34: =Estimated!B9 -> 77584
D35: AMC - Intercom | H35: =IE!C26 -> 13165 | I35: =Estimated!B16 -> 4000
D36: Royalty - Car Parking Area | H36: =IE!#REF! -> #REF! | I36: =Estimated!B17 -> 80500
D37: Water Pumps AMC & Repairs | H37: =IE!#REF! -> #REF! | I37: =Estimated!B32 -> 2500
D38: Bank charges & Miscellaneous Exp. | H38: =IE!#REF!+IE!C41+IE!#REF! -> #REF! | I38: =Estimated!B6+Estimated!B8 -> 700
D39: Conveyance | H39: =IE!#REF! -> #REF! | I39: =Estimated!B7 -> 700
D40: AGM/ SGM Expenses | H40: =IE!C40 -> 23341 | I40: =Estimated!B12 -> 4000
D41: Repair & Maintenance Other | H41: =IE!C19 -> 19287 | I41: =Estimated!B31 -> 20000
D42: CCTV Rent | H42: =IE!C42 -> 45864 | I42: =Estimated!B28 -> 60000
D43: Election Expenses | H43: =IE!#REF! -> #REF!
...

Sheet Estimated
A4: EXPENDITURE | B4: Estimated | C4: INCOME | D4: Estimated
A5: Audit Fees | B5: 5900 | C5: Maintenance Income
A6: Bank Charges | B6: 600 | C6: Maintenance Charges | D6: =ROUND(SUM(B5:B32),0) -> 1042268
A7: Conveyance | B7: 700 | C7: Electricity Charges | D7: =B35 -> 115000
A8: Meals & Refreshment Expense | B8: 100 | C8: Water Charges | D8: =B39+B40 -> 130500
A9: Depreciation | B9: 77584 | C9: Lift Maintenance Charges | D9: =B34 -> 260000
A10: Income Tax expense | B10: 206458 | C10: 2W Parking Charges
A11: Internet & Communication | B11: 600 | C11: Non Occupancy Charges
A12: Meeting Expenses | B12: 4000 | C12: 4W Parking Charges
A13: Subscription Federation | B13: 826 | C13: Penalty and Other charges
A14: Postage and Courier | B14: 0 | C14: Late Payment Interest
A15: Printing & Stationery | B15: 8000
A16: Intercom | B16: 4000 | C16: Property tax
A17: Land Rent Expense | B17: 80500 | C17: Municipal Taxes | D17: =B36 -> 241360
A18: Water Pumps | B18: 2500
A19: Water Tanks Cleaning | B19: 6000 | C19: Other Member Income
A20: Housekeeping Material/ Misc. | B20: 8000 | C20: Party Hall Income
A21: Accountant | B21: 24000
A22: Salary | B22: 60000 | C22: Interest Income
A23: Bonus | B23: 5000 | C23: Interest Income Savings Account
A24: Housekeeping Expenses | B24: 60000 | C24: Interest Income Fixed Deposit
A25: Legal/Professional Fees | B25: 105000 | C25: Interest Income Security Deposit
A26: Security Expenses | B26: 275000
A27: Waste Mgmt Expenses | B27: 6000 | C27: Other Income
A28: R&M - CCTV | B28: 60000 | C28: Tower Rent Income | D28: 192450
A29: R&M - Electrial | B29: 12000
A30: R&M - Plumbing | B30: 7000 | D30: 0
A31: R&M - Others | B31: 20000
A32: R&M - Water pump | B32: 2500
A34: R&M - Lift | B34: 260000
A35: Electricity Charges | B35: 115000
A36: Property Tax | B36: 241360
A37: Insurance | B37: 14344
A38: Education & Training Fund | B38: 3360
A39: Water Charges | B39: 118000
A40: Water Tanker | B40: 12500
A42: Surplus | B42: =D43-SUM(B5:B40) -> 174746
A43: Total | B43: =SUM(B5:B42) -> 1981578 | C43: Total | D43: =SUM(D5:D42) -> 1981578

Sheet Workings
A1: Intercom AMC
B2: 45931 | C2: 46295 | D2: =C2-B2+1 -> 365 | E2: 8200
B3: 46113 | C3: =+C2 -> 46295 | D3: =C3-B3+1 -> 183 | E3: =+E2*D3/D2 -> 4111.2329 | K3: Adani AC no. | L3: Amount
K4: 151591540 | L4: 5727.45
A5: Insurance | K5: 151591541 | L5: 6424.05
B6: 45898 | C6: 46262 | D6: =C6-B6+1 -> 365 | E6: 13946 | L6: =SUM(L4:L5) -> 12151.5
B7: 46113 | C7: =+C6 -> 46262 | D7: =C7-B7+1 -> 150 | E7: =+E6*D7/D6 -> 5731.2329
A9: Water expense
B10: 45692 | C10: 46057 | D10: =C10-B10+1 -> 366 | E10: 115006
B11: 46057 | C11: 46112 | D11: =C11-B11+1 -> 56 | E11: =+E10*D11/D10 -> 17596.546
A15: Income Tax Provision for FY 25-26
C16: Gross | D16: Deduction | E16: Nett
A17: Tower Rent | C17: 692476 | D17: =ROUND(C17*30%,) -> 207743 | E17: =C17-D17 -> 484733
A18: Savings interest | C18: 11218 | D18: 0 | E18: =C18-D18 -> 11218
E19: =ROUND(SUM(E17:E18),-1) -> 495950
A20: Tax provision: | E20: =ROUND((3000+(E19-20000)*30%)*1.04,-3) -> 152000

Sheet Queries
A1: Project A/c Citizen Bank statement not avaialable
A2: MSC bank statement not available
A3: Cash is negative balance and Cash not reconcile
A4: Depreciation not charged FY 23-24 | B4: Done
A5: prepaid exp not reversal | B5: Done | C5: 1 | D5: The Oriental Insurance Company Ltd bill required | E5: DONE
A6: provisional not reverse | B6: Done | C6: 2 | D6: Lift AMC Bill Required
A7: Collection not trasnferred to reserve fund | B7: Done | C7: 3 | D7: Last yeat Royalty car parking exp booked but current exp not booekd
A8: Pls check tower rent income ledger | C8: 4 | D8: Subscipetion fees not paid FY23-24 | E8: DONE
A9: Manager provisional salary not booked | B9: Done | C9: 5 | D9: MSC Bank Statement required
A10: Property Tax bill not booked FY23-24 | B10: Done | C10: 6 | D10: Yes Bank Statement required
A11: water exp after aug bill not booked | B11: Done | C11: 7 | D11: Project A/c Citizen Bank statement not avaialable
A12: Intercom AMC prepaid not booked | B12: Done | C12: 8 | D12: Rs. 3500/- advance payment done on 18.10.23 to Pradeep Vishwakarma Bill required
A13: Pest control AMC not booked | B13: Done | C13: 9 | D13: Rs. 15000/ advance payment done on 11.08.2023 to Sagar electricals bill required
A14: Security salary not provision for the month of March | B14: Done | C14: 10 | D14: Rs. 20000/ advance payment done on 23.06.2023 to Sai Fabricators Bill required
A15: 31.12.23 in security ledger one bill booked in the name of Daya | C15: 11 | D15: Rs.6000/ advance payment done on 17.11.2022 to Sreejesh A.V bill required | E15: DONE
A16: Sweeper salary provision not booked | B16: Done | C16: 12 | D16: Required Ashna Elevataor Bill Rs. 2,45,000 dt. 24.04.2023 , Rs. 49000 dt. 17.04.2023 & Rs. 100000 dt. 28.07.2023
A17: CCTV Rental charges feb month exp not booked | C17: 13 | D17: Required J.N.Construction Bill Rs. 4,21,405.00 dt. 16.02.2024
A18: fixed asset control not transferred in fixed asset | B18: Done | C18: 14 | D18: Required Swarajya Enterprises Bill Rs. 3,57,123.00 dt. 16.02.2024
A19: Water Exp bill required | B19: Done | C19: 15 | D19: AS per 26 Sinking Fund TDS not shown in 26 AS
A20: Property Tax bill required | B20: Done
A21: The Oriental Insurance Company Ltd bill required | B21: Pending
A22: Lift AMC Bill Required | B22: Pending
A23: Last yeat Royalty car parking exp booked but current exp not booekd
A24: Subscipetion fees not paid FY23-24 | B24: Pending
A25: MSC Bank Statement required
A26: Project A/c Citizen Bank statement not avaialable
A27: Rs. 3500/- advance payment done on 18.10.23 to Pradeep Vishwakarma Bill required
A28: Rs. 15000/ advance payment done on 11.08.2023 to Sagar electricals bill required
A29: Rs. 20000/ advance payment done on 23.06.2023 to Sai Fabricators Bill required
A30: Rs.6000/ advance payment done on 17.11.2022 to Sreejesh A.V bill required

Sheet fd 1
A1: Domonica CHS Ltd
A2: Schedule 1: Fixed Deposit Details as at 31.03.2023
A4: Sr. | B4: Certificate No. | C4: Deposit Date | D4: Principal | E4: Accd Int 21-22 | F4: Accd Int 22-23 | G4: Accd Int 23-24 | H4: Total | I4: Mat Date | J4: Mat Value | K4: ROI | L4: Bank
B5: Sinking Fund
A6: 1 | B6: 2090180000310130 | C6: 30.03.2021 | D6: 38000 | E6: =1933-195 -> 1738 | F6: =2024-101 -> 1923 | G6: =242-53 -> 189 | H6: 0 | I6: 30.06.2024 | J6: 44660 | K6: 5 | L6: Citizencredit
A7: 2 | B7: 2090180000306357 | C7: 11.03.2022 | D7: 100000 | E7: 0 | F7: 0 | G7: 0 | H7: =SUM(D7:G7) -> 100000 | I7: 24.07.2023 | J7: 100000 | K7: 4.75 | L7: Citizencredit
A8: 3 | B8: 2090180003051151 | C8: 22.07.2022 | D8: 138443 | E8: 0 | F8: 0 | G8: 3251 | H8: =SUM(D8:G8) -> 141694 | I8: 04.12.2023 | J8: 138564 | K8: 4.75 | L8: Citizencredit | N8: =D8+F8 -> 138443 | O8: =138443 -> 138443 | P8: =O8-N8 -> 0 | Q8: =7424 -> 7424 | R8: 155 | S8: =Q8-P8 -> 7424
A9: 4 | B9: 2090180306634596 | C9: 26.11.2022 | D9: 88000 | E9: 0 | F9: 0 | G9: 0 | H9: 0 | I9: 09.04.2024 | J9: 88000 | K9: 5.15 | L9: Citizencredit
A10: 5 | B10: 2090180003051188 | C10: 06.10.2022 | D10: 135693 | E10: 0 | F10: 0 | G10: 1170 | H10: =SUM(D10:G10) -> 136863 | I10: 18.02.2024 | J10: 135693 | K10: 5.15 | L10: Citizencredit | N10: 129918 | O10: 135693 | P10: =O10-N10 -> 5775 | Q10: 6945 | R10: 164 | S10: =Q10-P10 -> 1170
A11: 6 | B11: 2090180003051410 | C11: 23.06.2022 | D11: 48500 | E11: 0 | F11: 0 | G11: 1469 | H11: =SUM(D11:G11) -> 49969 | I11: 05.11.2023 | J11: 48611 | K11: 4.75 | L11: Citizencredit | N11: 47294 | O11: 48500 | P11: =O11-N11 -> 1206 | Q11: 2675 | R11: 55 | S11: =Q11-P11 -> 1469 | T11: =49922-49969 -> -47
A12: 7 | B12: 101843051000483 | C12: 17.03.2023 | D12: 56023 | E12: 0 | F12: 156 | G12: 4060 | H12: =SUM(D12:G12) -> 60239 | I12: 29.07.2024 | J12: 61587 | K12: 7.25 | L12: Citizencredit
B13: Total | D13: =SUM(D6:D12) -> 604659 | E13: =SUM(E6:E12) -> 1738 | F13: =SUM(F6:F12) -> 2079 | G13: =SUM(G6:G12) -> 10139 | H13: =SUM(H6:H12) -> 488765 | J13: =SUM(J6:J12) -> 617115
B15: General Funds
A16: 8 | B16: 2090180000310127 | C16: 30.03.2021 | D16: 127200 | E16: =6469-649 -> 5820 | F16: =6776-662 -> 6114 | G16: =780-515 -> 265 | H16: 0 | I16: 30.06.2024 | J16: 149494 | K16: 5 | L16: Citizencredit
A17: 9 | B17: 2090180000310129 | C17: 30.03.2021 | D17: 600000 | E17: =30517-3054 -> 27463 | F17: =31959-3120 -> 28839 | G17: =4197-2426 -> 1771 | H17: 0 | I17: 30.06.2024 | J17: 705158 | K17: 5 | L17: Citizencredit
A18: 10 | B18: 2090180000306356 | C18: 24.07.2023 | D18: 300000 | E18: 0 | F18: 0 | H18: =SUM(D18:F18) -> 300000 | I18: 24.07.2024 | J18: 300000 | K18: 4.75 | L18: Citizencredit
A19: 11 | B19: 2090180003051190 | C19: 18.02.2024 | D19: 134826 | E19: 0 | F19: 0 | G19: =1102+10 -> 1112 | H19: =SUM(D19:G19) -> 135938 | I19: 18.02.2025 | J19: 135693 | K19: 5.15 | L19: Citizencredit | N19: 129615 | O19: 134826 | P19: =O19-N19 -> 5211 | Q19: 6928 | R19: 615 | S19: =Q19-P19-R19 -> 1102
A20: 12 | B20: 2090180003051150 | C20: 04.12.2023 | D20: 447436 | E20: 0 | F20: 0 | G20: 9916 | H20: =SUM(D20:G20) -> 457352 | I20: 04.12.2024 | J20: 450099 | K20: 4.75 | L20: Citizencredit | N20: 435195 | O20: 447436 | P20: =O20-N20 -> 12241 | Q20: 24067 | R20: 1910 | S20: =Q20-P20-R20 -> 9916
A21: 13 | B21: 2090180003051189 | C21: 18.02.2024 | D21: 134826 | E21: 0 | F21: 0 | G21: =1102+10 -> 1112 | H21: =SUM(D21:G21) -> 135938 | I21: 18.02.2025 | J21: 135693 | K21: 5.15 | L21: Citizencredit | N21: 129615 | O21: 134826 | P21: =O21-N21 -> 5211 | Q21: 6928 | R21: 615 | S21: =Q21-P21-R21 -> 1102
A22: 14 | B22: 2090180003051191 | C22: 18.02.2024 | D22: 134826 | E22: 0 | F22: 0 | G22: =1102+10 -> 1112 | H22: =SUM(D22:G22) -> 135938 | I22: 18.02.2025 | J22: 135693 | K22: 5.15 | L22: Citizencredit | N22: 129615 | O22: 134826 | P22: =O22-N22 -> 5211 | Q22: 6928 | R22: 615 | S22: =Q22-P22-R22 -> 1102
A23: 15 | B23: 2090180003051192 | C23: 18.02.2024 | D23: 134826 | E23: 0 | F23: 0 | G23: =1102+10 -> 1112 | H23: =SUM(D23:G23) -> 135938 | I23: 18.02.2025 | J23: 135693 | K23: 5.15 | L23: Citizencredit | N23: 129615 | O23: 134826 | P23: =O23-N23 -> 5211 | Q23: 6928 | R23: 615 | S23: =Q23-P23-R23 -> 1102
A24: 16 | B24: 101843051000498 | C24: 17.03.2023 | D24: 181519 | E24: 0 | F24: =505-51 -> 454 | G24: =13160-1106 -> 12054 | H24: =SUM(D24:G24) -> 194027 | I24: 29.07.2024 | J24: 199547 | K24: 7.25 | L24: Citizencredit
A25: 17 | B25: 2090180003051568 | C25: 30.07.2023 | D25: 112125 | E25: 0 | F25: 0 | G25: 4990 | H25: =SUM(D25:G25) -> 117115 | I25: 30.07.2024 | J25: 112794 | K25: 4.75 | L25: Citizencredit | N25: 110634 | O25: 112125 | P25: =O25-N25 -> 1491 | Q25: 7065 | R25: 584 | S25: =Q25-P25-R25 -> 4990
A26: 18 | B26: 2090180003051572 | C26: 30.07.2023 | D26: 112125 | E26: 0 | F26: 0 | G26: 4990 | H26: =SUM(D26:G26) -> 117115 | I26: 30.07.2024 | J26: 112794 | K26: 4.75 | L26: Citizencredit | N26: 110634 | O26: 112125 | P26: =O26-N26 -> 1491 | Q26: 7065 | R26: 584 | S26: =Q26-P26-R26 -> 4990
A27: 19 | B27: 2090180003051661 | C27: 17.07.2023 | D27: 300000 | E27: =1093-110 -> 983 | F27: =14271-1395 -> 12876 | H27: 0 | I27: 17.07.2024 | J27: 319521 | K27: 4.75 | L27: Citizencredit
A28: 20 | B28: 2090180003051662 | C28: 17.07.2023 | D28: 423514 | E28: 0 | F28: 0 | G28: 19840 | H28: =SUM(D28:G28) -> 443354 | I28: 17.07.2024 | J28: 426027 | K28: 4.75 | L28: Citizencredit | N28: 418480 | O28: 423514 | P28: =O28-N28 -> 5034 | Q28: 27106 | R28: 2232 | S28: =Q28-P28-R28 -> 19840
A29: 21 | B29: 2090180003051571 | C29: 30.07.2023 | D29: 112125 | E29: 0 | F29: 0 | G29: 4990 | H29: =SUM(D29:G29) -> 117115 | I29: 30.07.2024 | J29: 112794 | K29: 4.75 | L29: Citizencredit | N29: 110634 | O29: 112125 | P29: =O29-N29 -> 1491 | Q29: 7065 | R29: 584 | S29: =Q29-P29-R29 -> 4990
A30: 22 | B30: 2090180003051411 | C30: 05.11.2023 | D30: 155476 | E30: 0 | F30: 0 | G30: =4412-150 -> 4262 | H30: =SUM(D30:G30) -> 159738 | I30: 05.11.2024 | J30: 156546 | K30: 4.75 | L30: Citizencredit | N30: 151971 | O30: 155476 | P30: =O30-N30 -> 3505 | Q30: 8596 | R30: 679 | S30: =Q30-P30-R30 -> 4412
A31: 23 | B31: 2090180003051569 | C31: 30.07.2023 | D31: 112125 | E31: 0 | F31: 0 | G31: 4990 | H31: =SUM(D31:G31) -> 117115 | I31: 30.07.2024 | J31: 112794 | K31: 4.75 | L31: Citizencredit | N31: 110634 | O31: 112125 | P31: =O31-N31 -> 1491 | Q31: 7065 | R31: 584 | S31: =Q31-P31-R31 -> 4990
A32: 24 | B32: 2090180003051570 | C32: 30.07.2023 | D32: 112125 | E32: 0 | F32: 0 | G32: 4990 | H32: =SUM(D32:G32) -> 117115 | I32: 30.07.2024 | J32: 112794 | K32: 4.75 | L32: Citizencredit | N32: 110634 | O32: 112125 | P32: =O32-N32 -> 1491 | Q32: 7065 | R32: 584 | S32: =Q32-P32-R32 -> 4990
A33: 25 | B33: 2090180003051256 | C33: 18.01.2023 | D33: 163609 | E33: 0 | F33: 1787 | G33: =9816-825 -> 8991 | H33: =SUM(D33:G33) -> 174387 | I33: 01.06.2024 | J33: 177056 | K33: 6 | L33: Citizencredit
B34: Total | D34: =SUM(D16:D33) -> 3798683 | E34: =SUM(E16:E33) -> 34266 | F34: =SUM(F16:F33) -> 50070 | G34: =SUM(G16:G33) -> 86497 | H34: =SUM(H16:H33) -> 2858185 | J34: =SUM(J16:J33) -> 3990190
B36: Grand Total | D36: =+D13+D34 -> 4403342 | E36: =+E13+E34 -> 36004 | F36: =+F13+F34 -> 52149 | G36: =+G13+G34 -> 96636 | H36: =+H13+H34 -> 3346950 | J36: =+J13+J34 -> 4607305
