Workbook

Sheet BS
A1: JEEVAN HEIGHTS CO-OPERATIVE HOUSING SOCIETY LTD
A2: Society Address: Bandar, Pakhadi Road ,Kandivali (W), Mumbai - 400067.
A3: Society Reg No : TNA/TNA/HSG/TC/13111/Year 2021
A4: Balance Sheet as at March 31, 2025
H5: (Amounts in ₹)
A6: March 31, 2024 | B6: LIABILITIES | D6: March 31, 2025 | E6: =A6 -> March 31, 2024 | F6: ASSETS | H6: =D6 -> March 31, 2025
B7: Share Capital: | F7: Cash and Bank Balances:
A8: =4000*50 -> 200000 | B8: Authorised: 4,000 shares of ₹ 50/- each | D8: 200000 | E8: 8954 | F8: Cash in Hand | G8: 1546
E9: 52596 | F9: MDCC Bank | G9: 54399
A10: 31500 | B10: Share Application Money Pending Allotment | D10: 31500 | E10: 192784.03 | F10: ICICI Bank | G10: =BRS!C7 -> 922186.04
B11: 630 Shares of Rs. 50/- each | E11: 22158.28 | F11: Union Bank of India | G11: =BRS!C22 -> 55753.28
E12: 325712.01 | F12: ICICI Sweep Account | G12: 0 | H12: =SUM(G8:G12) -> 1033884.3
A13: =+'Sch 5'!B33 -> 3355937.1 | B13: Reserves and Surplus (Sch 5) | D13: =+'Sch 5'!E33 -> 3977417.1
E14: 3953747 | F14: Fixed Deposit (Sch 1) | H14: =+'Sch 1'!K41 -> 4604276
B15: Current Liabilities & Provision: (Sch 6)
A16: ='Sch 4,6'!B32 -> 483654 | B16: Vendors Payable | C16: ='Sch 4,6'!D32 -> 507786 | F16: Loan & Advances
A17: ='Sch 4,6'!B39 -> 99548 | B17: Statutory Dues Payable | C17: =+'Sch 4,6'!D39 -> 114401 | E17: 0 | F17: Advance Payment to Vendor | H17: ='Sch 4,6'!D51 -> 20433
A18: ='Sch 4,6'!B45 -> 59866 | B18: Provisions | C18: =+'Sch 4,6'!D45 -> 58730 | D18: =SUM(C16:C18) -> 680917
F19: Deposits
B20: Members' Payables: | E20: =73765+18798 -> 92563 | F20: Adani electricity | G20: =73765+18798 -> 92563
A21: 9160 | B21: Advance Members (Sch 7) | D21: ='Sch 3&7'!D17 -> 101874 | E21: 2721 | F21: MCGM -water | G21: 2721 | H21: =SUM(G20:G21) -> 95284
B23: Retained Earnings: | E23: ='Sch 2'!C14 -> 401831.4 | F23: Fixed Assets: (Sch 2) | H23: =+'Sch 2'!I14 -> 533313
A24: 561971.93 | B24: Retained Earnings | C24: 1259516.6
A25: 83475 | B25: Add: Prior period Adjustment | C25: -2484 | F25: Other Current Assets:
A26: -6383 | B26: Less: Advance to Vendors (TDS) | C26: 0 | E26: 42381 | F26: Member receivables (Sch 3) | G26: ='Sch 3&7'!D8 -> 65424
A27: =PL!A47 -> 620452.7 | B27: Surplus / (Deficit) for the Period | C27: =+PL!D47 -> 513449.6 | D27: =SUM(C24:C27) -> 1770482.2 | E27: 16006 | F27: Accrued interest on sweep | G27: 0
E28: 13318 | F28: Unclaimed ITC | G28: =Workings!L9 -> 22033
E29: 3010.5 | F29: Central GST | G29: 0
E30: 3010.5 | F30: State GST | G30: 0
E31: 249 | F31: Integrated GST | G31: 550
E32: =16919+1779 -> 18698 | F32: TDS receivables | G32: =26115 -> 26115
E33: 32800 | F33: Advance Income Tax | G33: =85800-32800 -> 53000 | H33: =SUM(G26:G33) -> 167122
E35: =+'Sch 4,6'!B13 -> 116642 | F35: Prepaid Expenses (Sch 4) | H35: =+'Sch 4,6'!D13 -> 107878
A37: =SUM(A10:A36) -> 5299181.7 | B37: Total | D37: =SUM(D10:D36) -> 6562190.3 | E37: =SUM(E7:E36) -> 5299181.7 | F37: Total | H37: =SUM(H7:H36) -> 6562190.3
A38: =A37-E37 -> 0
A39: As per my report of even date | E39: FOR JEEVAN HEIGHTS CO-OPERATIVE HOUSING SOCIETY LTD
A43: Shri. Bharat C. Boridkar
A44: Govt. Certified Panel Auditor | E44: Chairman Secretary Treasurer
A45: [Panel No.: Mumbai-4/B2/1011404]
A46: 45884

Sheet PL
A1: =BS!A1 -> JEEVAN HEIGHTS CO-OPERATIVE HOUSING SOCIETY LTD
A2: =BS!A2 -> Society Address: Bandar, Pakhadi Road ,Kandivali (W), Mumbai - 400067.
A3: Society Reg No : TNA/TNA/HSG/TC/13111/Year 2021
A4: Income and Expenditure Account for the year ended March 31, 2025 | M4: Account Head | N4: Income | O4: Expenses | P4: Surplus/ (Deficit)
H5: (Amounts in ₹) | M5: Common Area maintenance Charges | N5: 3575880 | O5: =D9+D21+D29-C24-C26+D44-C44 -> 3266811.4 | P5: =N5-O5 -> 309068.6
A6: =BS!A6 -> March 31, 2024 | B6: EXPENDITURE | D6: =BS!D6 -> March 31, 2025 | E6: =A6 -> March 31, 2024 | F6: INCOME | H6: =D6 -> March 31, 2025 | M6: Common Electricity Charges | N6: 1388772 | O6: =D13 -> 1595680 | P6: =N6-O6 -> -206908
B7: Salary Expenses | F7: Maintenance Income: | M7: Water Charges | N7: 401940 | O7: =D16 -> 213810 | P7: =N7-O7 -> 188130
A8: 195100 | B8: Salary Expenses | C8: 166200 | E8: 3575880 | F8: Common Area maintenance Charges | G8: 3575880 | M8: Usage charges | N8: 896988 | O8: =C24 -> 603030 | P8: =N8-O8 -> 293958
A9: 39450 | B9: Diwali Bonus | C9: =49600 -> 49600 | D9: =SUM(C8:C9) -> 215800 | E9: 1388772 | F9: Common Electricity Charges | G9: 1388772 | M9: Insurance Charges | N9: 84952 | O9: =C26 -> 77350 | P9: =N9-O9 -> 7602
B10: Property Tax | E10: 401940 | F10: Water Charges | G10: 401940 | M10: Society Welfare Charges | N10: 226800 | O10: =C44 -> 261187 | P10: =N10-O10 -> -34387
A11: 111260 | B11: Property Tax Members | D11: 111260 | E11: 45310 | F11: Non-Occupancy Charges | G11: =47280 -> 47280 | M11: Common area property Tax | N11: 47628 | O11: =D11 -> 111260 | P11: =N11-O11 -> -63632
B12: Common electricity expenses | E12: 84952 | F12: Insurance Charges | G12: 84952 | M12: Parking Property tax | N12: 65412 | O12: 0 | P12: =N12-O12 -> 65412
A13: =1439410-18798 -> 1420612 | B13: Electricity Expenses | D13: 1595680 | E13: 226800 | F13: Society Welfare Charges | G13: 226800 | M13: (A) | N13: =SUM(N5:N12) -> 6688372 | O13: =SUM(O5:O12) -> 6129128.4 | P13: =SUM(P5:P12) -> 559243.6
B14: Water Expenses | E14: 0 | F14: Late Payment Interest | G14: =24207 -> 24207 | H14: =SUM(G8:G14) -> 5749831 | M14: Non-Occupancy Charges | N14: 45310 | O14: 0 | P14: =N14-O14 -> 45310
A15: 220611 | B15: MCGM water expenses | C15: =Workings!D9 -> 186810 | M15: Function Charges (Ground /Terrace) | N15: 37500 | O15: 0 | P15: =N15-O15 -> 37500
A16: 109400 | B16: Water Tanker Expenses | C16: =47000-20000 -> 27000 | D16: =SUM(C15:C16) -> 213810 | F16: Property Tax | M16: Shifting Charges Move In And Move Out | N16: 20000 | O16: 0 | P16: =N16-O16 -> 20000
B17: Lift Maintenance | E17: 47628 | F17: Common area property Tax | G17: 47628 | M17: Interest on Savings Account | N17: 2245 | O17: 0 | P17: =N17-O17 -> 2245
A18: 600893 | B18: Lift AMC Expenses | C18: =Workings!D52+Workings!D58+Workings!D60 -> 656445 | E18: 65412 | F18: Parking Property tax | G18: 65412 | H18: =SUM(G17:G18) -> 113040 | M18: Interest on Fixed Deposits | N18: 17868 | O18: 0 | P18: =N18-O18 -> 17868
A19: -600893 | B19: Less: Trfd to Repair Fund | C19: -656445 | D19: =SUM(C18:C19) -> 0 | M19: Misc. Income | N19: 25001.7 | O19: 0 | P19: =N19-O19 -> 25001.7
B20: Repair and Maintenance Expense (Sch 8) | F20: Other Member Income | M20: (B) | N20: =SUM(N14:N19) -> 147924.7 | O20: =SUM(O14:O19) -> 0 | P20: =SUM(P14:P19) -> 147924.7
A21: ='Sch 8 & 9'!B34 -> 374025 | B21: As per schedule | D21: ='Sch 8 & 9'!D34 -> 524117 | E21: 37500 | F21: Function Charges (Ground /Terrace) | G21: =37500+5000 -> 42500 | M21: C = (A+B) | N21: =N13+N20 -> 6836296.7 | O21: =O13+O20 -> 6129128.4 | P21: =P13+P20 -> 707168.3
B22: Service Expenses: | E22: 20000 | F22: Shifting Charges Move In And Move Out | G22: 0
A23: 1513557 | B23: Security Expenses | C23: 1342948 | E23: 896988 | F23: Usage charges | G23: 896988 | H23: =SUM(G21:G23) -> 939488
A24: =541931+62092 -> 604023 | B24: Housekeeping Expenses, incl material | C24: =538285+64745 -> 603030
A25: 54288 | B25: Depreciation | C25: =+'Sch 2'!H14 -> 70170.4 | F25: Interest Income:
A26: 90844 | B26: Insurance | C26: =Workings!D34 -> 77350 | E26: 2245 | F26: Interest on Savings Account | H26: =1955+466 -> 2421
A27: 7080 | B27: Software Charges | C27: 7080 | E27: 169141 | F27: Interest on Fixed Deposits | G27: =257457 -> 257457
A28: 6300 | B28: Audit Fees | C28: 6300 | E28: -40306 | F28: Less: Trf to Reserve Fund | G28: 66446
A29: 34806 | B29: Pest Control Expense | C29: =Workings!D40 -> 49235 | D29: =SUM(C23:C29) -> 2156113.4 | E29: -46026 | F29: Less: Trf to Sinking Fund | G29: 70799
B30: General Expenses: | E30: -82539 | F30: Less: Trf to Repair Fund | G30: 99607
A31: 38495 | B31: General Expenses | C31: =6596+51304-11000 -> 46900 | E31: -22 | F31: Less: Trf to Edu & Trng Fund | G31: 1693
A32: 362375 | B32: Gym Expenses | C32: 378184 | E32: -218 | F32: Less: Trf to Common Amenities | G32: 16657
A33: 500 | B33: Telephone and Internet Expenses | C33: 3750 | E33: 17838 | F33: Interest on Sweep | G33: 3693 | H33: =G27-SUM(G28:G32)+G33 -> 5948
A34: 70509 | B34: Accounting Charges | C34: 69000
A35: 7018 | B35: Printing and Stationary | C35: 9502 | F35: Other Income:
A36: 0 | B36: Postage and Courier | C36: 80 | E36: =25000.03+0.67+1 -> 25001.7 | F36: Misc. Income | H36: 3000
A37: 24936 | B37: Meeting Expenses | C37: 53000
A38: 2090 | B38: Conveyance Charges | C38: 1350
A39: 1187 | B39: Bank Charges | C39: 1298
A40: 654 | B40: Miscellaneous Expenses | C40: 1000
...

Sheet Sch 1
A1: =BS!A1 -> JEEVAN HEIGHTS CO-OPERATIVE HOUSING SOCIETY LTD
A2: Schedule 1: Fixed Deposit Statement as at March 31, 2025
A3: Sr. | B3: FD Account No. | C3: Bank | D3: ROI % | E3: Date of Issue | F3: Principal Invested | G3: Accrued Interest 2021-22 | H3: Accrued Interest 2022-23 | I3: Accrued Interest 2023-24 | J3: Accrued Interest 2024-25 | K3: Total Amt Invested | L3: Date of Maturity | M3: Value at Maturity
B4: Sinking Fund:
A5: 1 | B5: 196013003673 | C5: ICICI | D5: 0.056 | E5: 30.03.2022 | F5: 362304 | G5: 109 | H5: 14738 | I5: 15827 | J5: =22473 -> 22473 | K5: =SUM(F5:J5) -> 415451 | L5: 31.03.2027 | M5: 371164
A6: 2 | B6: 196013004075 | C6: ICICI | D6: 0.059 | E6: 20.08.2022 | F6: 90666 | G6: 0 | H6: 3331 | I6: 5670 | J6: =6012-601 -> 5411 | K6: =SUM(F6:J6) -> 105078 | L6: 14.09.2027 | M6: 93997
A7: 3 | B7: 196013005097 | C7: ICICI | D7: 0.069 | E7: 30.03.2023 | F7: 181152 | G7: 0 | H7: 60 | I7: 12831 | J7: =13739-1374 -> 12365 | K7: =SUM(F7:J7) -> 206408 | L7: 01.05.2028 | M7: 181205
A8: 4 | B8: 196013004077 | C8: ICICI | D8: 0.059 | E8: 20.08.2022 | F8: 90666 | G8: 0 | H8: 3331 | I8: 5103 | J8: =5977-598 -> 5379 | K8: =SUM(F8:J8) -> 104479 | L8: 14.09.2027 | M8: 93997
A9: 5 | B9: 196013006861 | C9: ICICI | D9: 0.072 | E9: 27.03.2024 | F9: 296182 | G9: 0 | H9: 0 | I9: 287 | J9: =21929-2193 -> 19736 | K9: =SUM(F9:J9) -> 316205 | L9: 27.03.2026 | M9: 341618
A10: 6 | B10: 196013008007 | C10: ICICI | E10: 20.03.2025 | F10: 296316 | G10: 0 | H10: 0 | I10: 0 | J10: =669-67 -> 602 | K10: =SUM(F10:J10) -> 296918
F11: =SUM(F5:F10) -> 1317286 | G11: =SUM(G5:G10) -> 109 | H11: =SUM(H5:H10) -> 21460 | I11: =SUM(I5:I10) -> 39718 | J11: =SUM(J5:J10) -> 65966 | K11: =SUM(K5:K10) -> 1444539 | M11: =SUM(M5:M10) -> 1081981
B13: Repair Fund:
A14: 7 | B14: 195913010405 | C14: ICICI | D14: 0.056 | E14: 30.03.2022 | F14: 1086912 | G14: 327 | H14: 55959 | I14: 58839 | J14: =68741-6875 -> 61866 | K14: =SUM(F14:J14) -> 1263903 | L14: 31.03.2027 | M14: 1136981
A15: 8 | B15: 196013004076 | C15: ICICI | D15: 0.059 | E15: 20.08.2022 | F15: 271772 | G15: 0 | H15: 9985 | I15: 16995 | J15: =18020-1802 -> 16218 | K15: =SUM(F15:J15) -> 314970 | L15: 14.09.2027 | M15: 281757
A16: 9 | B16: 196013006860 | C16: ICICI | D16: 0.072 | E16: 27.03.2024 | F16: 173521 | G16: 0 | H16: 0 | I16: 151 | J16: =12846-1285 -> 11561 | K16: =SUM(F16:J16) -> 185233 | L16: 27.03.2026 | M16: 200138
F17: =SUM(F14:F16) -> 1532205 | G17: =SUM(G14:G16) -> 327 | H17: =SUM(H14:H16) -> 65944 | I17: =SUM(I14:I16) -> 75985 | J17: =SUM(J14:J16) -> 89645 | K17: =SUM(K14:K16) -> 1764106 | M17: =SUM(M14:M16) -> 1618876
B19: General Fund
A20: 10 | B20: 196013005098 | C20: ICICI | D20: 0.069 | E20: 30.03.2023 | F20: 119378 | G20: 0 | H20: 40 | I20: 7611 | J20: =8994-899 -> 8095 | K20: =SUM(F20:J20) -> 135124 | L20: 01.05.2028 | M20: 119414
A21: 11 | B21: 196013004078 | C21: ICICI | D21: 0.059 | E21: 20.08.2022 | F21: 271772 | G21: 0 | H21: 9985 | I21: 15295 | J21: =17918-1792 -> 16126 | K21: =SUM(F21:J21) -> 313178 | L21: 14.09.2027 | M21: 281757
A22: 12 | B22: 196013005107 | C22: ICICI | D22: 0.071 | E22: 31.03.2023 | F22: 100000 | G22: 0 | H22: 20 | I22: 6563 | J22: =7867-534 -> 7333 | K22: =SUM(F22:J22) -> 113916 | L22: 31.07.2024 | M22: 100020
A23: 13 | B23: 196013005108 | C23: ICICI | D23: 0.071 | E23: 31.03.2023 | F23: 100000 | G23: 0 | H23: 20 | I23: 6563 | J23: =7867-4185 -> 3682 | K23: =SUM(F23:J23) -> 110265 | L23: 31.07.2024 | M23: 100020
A24: 14 | B24: 196013006862 | C24: ICICI | D24: 0.072 | E24: 27.03.2024 | F24: 280115 | G24: 0 | H24: 0 | I24: 244 | J24: =20737-2073 -> 18664 | K24: =SUM(F24:J24) -> 299023 | L24: 27.03.2026 | M24: 323082
A25: 15 | B25: 196013007647 | C25: ICICI | E25: 14.11.2024 | F25: 110000 | G25: 0 | H25: 0 | I25: 0 | J25: =3063 -> 3063 | K25: =SUM(F25:J25) -> 113063
F26: =SUM(F20:F25) -> 981265 | G26: =SUM(G20:G25) -> 0 | H26: =SUM(H20:H25) -> 10065 | I26: =SUM(I20:I25) -> 36276 | J26: =SUM(J20:J25) -> 56963 | K26: =SUM(K20:K25) -> 1084569 | M26: =SUM(M20:M25) -> 924293
B28: Share Capital
A29: 16 | B29: 196010002984 | C29: ICICI | D29: 0.072 | E29: 27.03.2024 | F29: 31500 | G29: 0 | H29: 0 | I29: 27 | J29: 0 | K29: =SUM(F29:J29) -> 31527 | L29: 27.03.2026 | M29: 31500
F30: =SUM(F29) -> 31500 | G30: =SUM(G29) -> 0 | H30: =SUM(H29) -> 0 | I30: =SUM(I29) -> 27 | J30: =SUM(J29) -> 0 | K30: =SUM(K29) -> 31527 | M30: =SUM(M29) -> 31500
B32: Education & Training Fund
A33: 17 | B33: 196013006863 | C33: ICICI | D33: 0.072 | E33: 27.03.2024 | F33: 22680 | G33: 0 | H33: 0 | I33: 20 | J33: =1679-168 -> 1511 | K33: =SUM(F33:J33) -> 24211 | L33: 27.03.2026 | M33: 26159
A34: 18 | B34: 196013008039 | C34: ICICI | E34: 27.03.2025 | F34: 15124 | G34: 0 | H34: 0 | I34: 0 | J34: =14-2 -> 12 | K34: =SUM(F34:J34) -> 15136
F35: =SUM(F33:F34) -> 37804 | G35: =SUM(G33:G34) -> 0 | H35: =SUM(H33:H34) -> 0 | I35: =SUM(I33:I34) -> 20 | J35: =SUM(J33:J34) -> 1523 | K35: =SUM(K33:K34) -> 39347 | M35: =SUM(M33:M34) -> 26159
B37: Common Amenities Fund
A38: 19 | B38: 196013006864 | C38: ICICI | D38: 0.072 | E38: 27.03.2024 | F38: 225000 | G38: 0 | H38: 0 | I38: 196 | J38: =16657-1665 -> 14992 | K38: =SUM(F38:J38) -> 240188 | L38: 27.03.2026 | M38: 259513
F39: =SUM(F38) -> 225000 | G39: =SUM(G38) -> 0 | H39: =SUM(H38) -> 0 | I39: =SUM(I38) -> 196 | J39: =SUM(J38) -> 14992 | K39: =SUM(K38) -> 240188 | M39: =SUM(M38) -> 259513
A41: Total :- | F41: =F11+F17+F26+F30+F35+F39 -> 4125060 | G41: =G11+G17+G26+G30+G35+G39 -> 436 | H41: =H11+H17+H26+H30+H35+H39 -> 97469 | I41: =I11+I17+I26+I30+I35+I39 -> 152222 | J41: =J11+J17+J26+J30+J35+J39 -> 229089 | K41: =K11+K17+K26+K30+K35+K39 -> 4604276 | M41: =M11+M17+M26+M30+M35+M39 -> 3942322

Sheet Sch 2
A1: =BS!A1 -> JEEVAN HEIGHTS CO-OPERATIVE HOUSING SOCIETY LTD
A3: Schedule 2: Fixed Assets Details as at March 31, 2025
A4: Sr. | B4: Assets | C4: Gross Blosk | G4: Depreciation | I4: Net Block
C5: Opening Balance 01.04.2024 | D5: Additions during the year before 30.09.2024 | E5: Additions during the year after 30.09.2024 | F5: Cost at 31.03.2025 | G5: Rate of Dep. (%) | H5: Charged for the Year
A6: 1 | B6: Computer | C6: 29549 | D6: 0 | E6: 0 | F6: =C6+D6+E6 -> 29549 | G6: 0.4 | H6: =ROUND(SUM(C6:D6,E6/2)*G6,) -> 11820 | I6: =F6-H6 -> 17729
A7: 2 | B7: Telephone | C7: 2617 | D7: 0 | E7: 0 | F7: =C7+D7+E7 -> 2617 | G7: 0.15 | H7: =ROUND(SUM(C7:D7,E7/2)*G7,) -> 393 | I7: =F7-H7 -> 2224
A8: 3 | B8: CCTV System | C8: 39175 | D8: 0 | E8: =22250+27500 -> 49750 | F8: =C8+D8+E8 -> 88925 | G8: 0.15 | H8: =ROUND(SUM(C8:D8,E8/2)*G8,) -> 9608 | I8: =F8-H8 -> 79317
A9: 4 | B9: Battery | C9: 10536 | D9: 0 | E9: 0 | F9: =C9+D9+E9 -> 10536 | G9: 0.15 | H9: =ROUND(SUM(C9:D9,E9/2)*G9,) -> 1580 | I9: =F9-H9 -> 8956
A10: 5 | B10: Fan | C10: 41866 | D10: 0 | E10: 0 | F10: =C10+D10+E10 -> 41866 | G10: 0.15 | H10: =ROUND(SUM(C10:D10,E10/2)*G10,) -> 6280 | I10: =F10-H10 -> 35586
A11: 6 | B11: Submersible Pump | C11: 17587 | D11: 0 | E11: 0 | F11: =C11+D11+E11 -> 17587 | G11: 0.15 | H11: =ROUND(SUM(C11:D11,E11/2)*G11,) -> 2638 | I11: =F11-H11 -> 14949
A12: 7 | B12: Sound System | C12: 33415 | D12: 0 | E12: 0 | F12: =C12+D12+E12 -> 33415 | G12: 0.15 | H12: =ROUND(SUM(C12:D12,E12/2)*G12,) -> 5012 | I12: =F12-H12 -> 28403
A13: 8 | B13: Furniture and Fixtures | C13: 227086.4 | D13: =15500+35212 -> 50712 | E13: =54690+46500 -> 101190 | F13: =C13+D13+E13 -> 378988.4 | G13: 0.1 | H13: =ROUND(SUM(C13:D13,E13/2)*G13,)+0.4 -> 32839.4 | I13: =F13-H13 -> 346149
A14: Total | C14: =SUM(C6:C13) -> 401831.4 | D14: =SUM(D6:D13) -> 50712 | E14: =SUM(E6:E13) -> 150940 | F14: =SUM(F6:F13) -> 603483.4 | H14: =SUM(H6:H13) -> 70170.4 | I14: =SUM(I6:I13) -> 533313

Sheet Sch 3&7
A1: =BS!A1 -> JEEVAN HEIGHTS CO-OPERATIVE HOUSING SOCIETY LTD
A2: Schedule 3: Members Receivables March 31, 2025
A3: Block | B3: Flat | C3: Members Name | D3: Amount
A4: Block | B4: 2001 | C4: Mrs.Sneha Ashok Rathod | D4: 57606
A5: Block | B5: 2602 | C5: Mrs. Saroj Girish Kanakia, Mr. Ankit Girishbhai Kanakia & Mrs. Chanika Ankit Kanakia | D5: 2950
A6: Utility | B6: 2001 | C6: Mrs.Sneha Ashok Rathod | D6: 3975
A7: Utility | B7: 3002 | C7: Mr.Vipul Pravinbhai Kapasi Mrs. Vaishali Vipul Kapasi & Mr.Priyansh Vipul Kapasi | D7: 893
C8: Total | D8: =SUM(D4:D7) -> 65424
A12: Schedule 7 : Advance from Members March 31, 2025
A13: Sr. No. | B13: Flat | C13: Members Name | D13: Amount
A14: 1 | B14: 402 | C14: Mrs.Khyati Namit Turakhia & Mr.Namit Mahendra Turakhia | D14: 85224
A15: 2 | B15: U - 402 | C15: Mrs.Khyati Namit Turakhia & Mr.Namit Mahendra Turakhia | D15: 11925
A16: 4 | B16: U - 3402 | C16: Mr.Manoj Kanaiyalal Kanakia & Mrs.Nisha Manoj Kanakia | D16: 4725
C17: Total | D17: =SUM(D14:D16) -> 101874

Sheet Sch 4,6
A1: =BS!A1 -> JEEVAN HEIGHTS CO-OPERATIVE HOUSING SOCIETY LTD
A2: Schedule 4: Prepaid Expenses
A3: Sr. No. | B3: FY 2023-24 | C3: Expenses | D3: FY 2024-25
A4: 1 | B4: 7080 | C4: Software | D4: 0
A5: 2 | B5: 6821 | C5: Pest Control | D5: =-Workings!D39 -> 14071
A6: 3 | B6: 3552 | C6: Intercome/CCTV | D6: =-Workings!D27 -> 4110
A7: 4 | B7: 10738 | C7: Gym Equipments | D7: =-Workings!D21 -> 0
A8: 5 | B8: 10000 | C8: DG Set | D8: =-Workings!D45 -> 15000
A9: 6 | B9: 12649 | C9: Insurance | D9: =-Workings!D33 -> 10749
A10: 7 | B10: 46962 | C10: Lift AMC | D10: =-Workings!D51-Workings!D57 -> 49437
A11: 8 | B11: 4455 | C11: AC AMC | D11: =-Workings!D15 -> 4011
A12: 9 | B12: 14385 | C12: Fire Fighting System AMC | D12: =-Workings!D66 -> 10500
B13: =SUM(B4:B12) -> 116642 | C13: Total | D13: =SUM(D4:D12) -> 107878
A15: Schedule 6: Payable to Vendors March 31, 2025
A16: Sr. No. | B16: =B3 -> FY 2023-24 | C16: A - Vendor Payables | D16: =D3 -> FY 2024-25
A17: 1 | B17: 24000 | C17: Mahavir Enterprises | D17: 0
A18: 2 | B18: 128500 | C18: Adani Electricity | D18: 139200
A19: 3 | B19: 110076 | C19: Ashtabhuja Security Guard | D19: 101970
A20: 4 | B20: 0 | C20: Dhanji Solanki | D20: 5500
A21: 5 | B21: 0 | C21: Flow Chem Pumps Pvt. Ltd. | D21: 11886
A22: 6 | B22: 80642 | C22: Hitachi Lift India Private Limited | D22: 86955
A23: 7 | B23: 5175 | C23: Irene Rosario | D23: =5175+5558 -> 10733
A24: 8 | B24: 5000 | C24: Rajesh Soni | D24: 0
A25: 9 | B25: 21000 | C25: Soneji Water Tanker | D25: 0
A26: 10 | B26: 24360 | C26: Vision Fire & Safety Engineers | D26: 24360
A27: 11 | B27: 0 | C27: Sakshi Bhosle | D27: 8350
A28: 12 | C28: Shivant Hardare | D28: 10725
A29: 13 | B29: 0 | C29: Shreeji Water Pump & Services | D29: 24681
A30: 14 | B30: 53592 | C30: Sparkling Cleaning Services | D30: 52746
A31: 15 | B31: 31309 | C31: Yashwant Kamble | D31: =30996-316 -> 30680
B32: =SUM(B17:B31) -> 483654 | C32: Total (a) | D32: =SUM(D17:D31) -> 507786
A34: Sr. No. | B34: =B3 -> FY 2023-24 | C34: B - Statutory Dues Payable | D34: =D3 -> FY 2024-25
A35: 1 | B35: 9002 | C35: TDS Payable | D35: 4879
A36: 2 | B36: 41526 | C36: GST Payable - RCM | D36: 18397
A37: 3 | B37: 0 | C37: GST Payable - Regular | D37: =5562.5*2 -> 11125
A38: 4 | B38: 49020 | C38: Income Tax Payable | D38: =Workings!D83-710 -> 80000
B39: =SUM(B35:B38) -> 99548 | C39: Total (b) | D39: =SUM(D35:D38) -> 114401
A41: Sr. No. | B41: =B3 -> FY 2023-24 | C41: C - Provisions | D41: =D3 -> FY 2024-25
A42: 1 | B42: 6300 | C42: Audit Fees | D42: 6300
A43: 2 | B43: 53566 | C43: Water Charges payable | D43: =Workings!D8 -> 42992
...

Sheet Sch 5
A1: =+'Sch 3&7'!A1:D1 -> JEEVAN HEIGHTS CO-OPERATIVE HOUSING SOCIETY LTD
A2: Schedule - 5 : Reserves and Surplus as on 31.03.2025
A3: Sr. No. | B3: FY 2023-24 | C3: Account Head | E3: FY 2024-25
A4: 1 | C4: Reserve Fund
B5: 280115 | C5: As per last year BS | D5: 527238
B6: 0 | C6: Add: Transfer Premium | D6: 0
B7: 0 | C7: Add: Entrance Fees | D7: 200
B8: 0 | C8: Add: Share Transfer Fees | D8: 500
B9: =PL!A46 -> 206817 | C9: Add: 25% of Surplus | D9: =PL!D46 -> 171150
B10: =-PL!E28 -> 40306 | C10: Add: Int. acc./recd during the year | D10: =PL!G28 -> 66446 | E10: =SUM(D5:D10) -> 765534 | G10: =E10-'Sch 1'!K26 -> -319035 | H10: FD Excess
A12: 2 | C12: Sinking Fund
B13: 752531 | C13: As per last year BS | D13: 1088565
B14: 290008 | C14: Add: Collection during the year | D14: 290008
B15: =-PL!E29 -> 46026 | C15: Add: Int. acc./recd during the year | D15: =PL!G29 -> 70799 | E15: =SUM(D13:D15) -> 1449372 | G15: =E15-'Sch 1'!K11 -> 4833 | H15: FD Short
A17: 3 | C17: Repair and Maintenance Fund
B18: =1324774.09+82517 -> 1407291.1 | C18: As per last year BS | D18: 1492214.1
B19: 869892 | C19: Add: Collection during the year | D19: 869892
B20: =PL!A19+'Sch 8 & 9'!B25+'Sch 8 & 9'!B28 -> -867508 | C20: Less: Spent during the year | D20: =PL!C19+'Sch 8 & 9'!D25+'Sch 8 & 9'!D28 -> -973032
B21: =-PL!E30 -> 82539 | C21: Add: Int. acc./recd during the year | D21: =PL!G30 -> 99607 | E21: =SUM(D18:D21) -> 1488681.1 | G21: =E21-'Sch 1'!K17 -> -275424.91 | H21: FD Excess
A23: 4 | C23: Education Training Fund
B24: 15120 | C24: As per last year BS | D24: =SUM(B24:B27) -> 22702
B25: 7560 | C25: Add: Collection during the year | D25: 7560
B26: =-PL!E31 -> 22 | C26: Add: Int. acc./recd during the year | D26: =PL!G31 -> 1693
B27: 0 | C27: Less : Expenses incurred during the year | D27: 0 | E27: =SUM(D24:D27) -> 31955 | G27: =E27-'Sch 1'!K35 -> -7392 | H27: FD Excess
C29: Common Amenities Fund
B30: 225000 | C30: As per last year BS | D30: =SUM(B30:B31) -> 225218
B31: =-PL!E32 -> 218 | C31: Add: Int. acc./recd during the year | D31: =PL!G32 -> 16657 | E31: =SUM(D30:D31) -> 241875 | G31: =E31-'Sch 1'!K39 -> 1687 | H31: FD Short
B33: =SUM(B4:B32) -> 3355937.1 | C33: TOTAL | E33: =SUM(E4:E32) -> 3977417.1 | H33: =+E33+31500 -> 4008917.1

Sheet Sch 8 & 9
A1: =BS!A1 -> JEEVAN HEIGHTS CO-OPERATIVE HOUSING SOCIETY LTD
A2: Schedule 8 : R & M Expenses for the year ended March 31, 2025
A3: Sr. No | B3: ='Sch 4,6'!B3 -> FY 2023-24 | C3: Expenses | D3: ='Sch 4,6'!D3 -> FY 2024-25
A4: 1 | B4: 0 | C4: Repair and Maintenance Lift | D4: =11341+3875 -> 15216
A5: 2 | B5: 29500 | C5: Water Tank Cleaning Expenses | D5: =6000+20000 -> 26000
A6: 3 | B6: 69525 | C6: Water Pump Repair Charges | D6: 71483
A7: 4 | B7: 500 | C7: Garden Maintenance Expenses | D7: 0
A8: 5 | B8: 13900 | C8: AC Repair and Maintenance | D8: 8800
A9: 6 | B9: 0 | C9: Repair and Maintenance Gym | D9: 850
A10: 7 | B10: 26722 | C10: Repair and Maintenance Electrical | D10: =72508+599 -> 73107
A11: 8 | B11: 6880 | C11: Other Repair Maintenance | D11: =118471+9089 -> 127560
A12: 9 | B12: 72520 | C12: Repair and Maintenance Plumbing | D12: 61370
A13: 10 | B13: 6500 | C13: Repair and Maintenance (Intercom/CCTV) | D13: 2450
A14: 11 | B14: 26055 | C14: DG Set Repair and Maintenance Expenses | D14: =28407+5000 -> 33407
A15: 12 | B15: 900 | C15: Fire Fighting System Repairs and Maintenance | D15: 0
B16: =SUM(B4:B15) -> 253002 | C16: Total (a) | D16: =SUM(D4:D15) -> 420243
A18: AMC Expenses for the year ended March 31, 2025
A19: Sr. No | B19: =B3 -> FY 2023-24 | C19: Expenses | D19: =D3 -> FY 2024-25
A20: 1 | B20: 545 | C20: AMC - AC | D20: =Workings!D16 -> 6444
A21: 2 | B21: 10929 | C21: AMC - Gym Equipment | D21: =Workings!D22 -> 10738
A22: 3 | B22: 9448 | C22: AMC - Intercom | D22: =Workings!D28 -> 14442
A24: 4 | B24: 117615 | C24: AMC - Fire Fighting System | D24: =Workings!D67 -> 129885
B25: -117615 | C25: Less: Trfd to Repair Fund | D25: =-D24 -> -129885
A27: 5 | B27: 184101 | C27: AMC - Stack Parking | D27: =45686+45686+37653+48239+Workings!D92 -> 186702
B28: -149000 | C28: Less: Trfd to Repair Fund | D28: -186702
A30: 6 | B30: 45000 | C30: AMC - CCTV | D30: =23625*2 -> 47250
A31: 7 | B31: 20000 | C31: AMC - DG | D31: =Workings!D46 -> 25000
B32: =SUM(B20:B31) -> 121023 | C32: Total (b) | D32: =SUM(D20:D31) -> 103874
B34: =B16+B32 -> 374025 | C34: Total ( C) | D34: =D16+D32 -> 524117

Sheet BRS
A1: =BS!A1 -> JEEVAN HEIGHTS CO-OPERATIVE HOUSING SOCIETY LTD
A3: ICICI Bank Reconciliation Statement as at March 31, 2025 | E3: Sr | F3: Vendor | G3: Issue Date | H3: Instr No. | I3: Outflow | J3: Inflow | K3: Clearing Date | N3: Amount cleared by the bank but not entered in the system
E4: 1 | F4: Soneji Water Tanker | G4: 07.01.2025 | H4: 879 | I4: 1500 | J4: 0 | K4: 03.06.2025 | M4: Sr. No. | N4: Date | O4: Deposit | P4: Issued | Q4: Instr.no | R4: Remarks
A5: Particulars | C5: Amount | E5: 2 | F5: Maharashtra Plywood | G5: 08.03.2025 | H5: 825 | I5: 79713 | J5: 0 | K5: 30.04.2025 | M5: 1 | N5: 09.04.2024 | O5: 2950 | Q5: DDD2292856
E6: 3 | F6: Ramdev Enterprises | G6: 11.03.2025 | H6: 827 | I6: 2800 | J6: 0 | K6: 29.04.2025 | M6: 2 | N6: 23.07.2024 | P6: 15000 | Q6: 420516260238 | R6: 15th Aug Catering
A7: Closing book balance (as per system) | C7: 922186.04 | E7: 4 | F7: Kajal Catering | G7: 30.03.2025 | H7: 916 | I7: 18000 | J7: 0 | K7: 08.05.2025 | M7: 3 | N7: 13.08.2024 | P7: 10000 | Q7: 422616257456 | R7: Sadhan Catering
E8: 5 | F8: Himanshu Agarwal | G8: 30.03.2025 | H8: 917 | I8: 23000 | J8: 0 | K8: 08.05.2025 | M8: 4 | N8: 20.08.2024 | P8: 28000 | Q8: 423311708126 | R8: Sadhan Catering
A9: Add: | B9: Cheques issued and presented for payment | C9: =I11 -> 125013 | M9: 5 | N9: 22-08-2024 | P9: 6151 | Q9: 423519916224 | R9: Garage Bag
B10: but not cleared | M10: 6 | N10: 10.09.2024 | P10: 7000 | Q10: 425419583184
I11: =SUM(I4:I10) -> 125013 | J11: =SUM(J4:J10) -> 0 | M11: 7 | N11: 10.09.2024 | P11: 11000 | Q11: 425419606720
A12: Less: | B12: Cheques collected and deposited but not | C12: =-J11 -> 0 | M12: 8 | N12: 01.10.2024 | P12: 40000 | Q12: 427519911428 | R12: MMT/IMPS/427519911428/GANPATIDECOR/NIAHANT/BARB0MA
B13: cleared | M13: 9 | N13: 10.10.2024 | O13: 29500 | Q13: 037909985891 | R13: INF/INFT/037909985891/43253953/MUMBAI SPACER
M14: 10 | N14: 12.10.2024 | P14: 7800 | Q14: 428619230968 | R14: MMT/IMPS/428619230968/WAFFELDUSSERA/WAFFELPRIY/BKI
A15: Closing bank balance (as per bank) | C15: =SUM(C7:C14) -> 1047199 | M15: 11 | N15: 18.10.2024 | P15: 25000 | Q15: 429221038015 | R15: MMT/IMPS/429221038015/NAVRATRICATERIN/KAJALCATER/C
M16: 12 | N16: 14.11.2024 | P16: 110000 | Q16: 196013007647 | R16: Funding
M17: 13 | N17: 26.12.2024 | O17: 5900 | Q17: 047422 | R17: Vipul
A18: Union Bank Reconciliation Statement as at March 31, 2025 | M18: 14 | N18: 27.01.25 | P18: 20800 | Q18: 502710621242 | R18: Sudhakar do
M19: 15 | N19: 27.01.25 | P19: 1 | Q19: 502709532027 | R19: IMPS
A20: Particulars | C20: Amount | M20: 16 | N20: 06.03.2025 | P20: 4670 | Q20: 506509096201 | R20: Holigulal
M21: 17 | N21: 06.03.2025 | P21: 2500 | Q21: 506509095408 | R21: virendra
A22: Closing book balance (as per system) | C22: 55753.28
A24: Add: | B24: Cheques issued and presented for payment | C24: =I26 -> 0
B25: but not cleared
A27: Less: | B27: Cheques collected and deposited but not | C27: =-J26 -> 0
B28: cleared
A30: Closing bank balance (as per bank) | C30: =SUM(C22:C29) -> 55753.28

Sheet Workings
A2: Sr. No. | B2: Particulars | C2: Days/ Months | D2: Amount | G2: Unclaimed ITC
G3: Vendor | H3: Date | I3: Basic | J3: CGST | K3: SGST | L3: Total Tax | M3: Total | O3: 04.01.2024 to 04.04.2024 | P3: =27+29+31+4 -> 91 | Q3: 0
A4: 1 | B4: Water Expenses | G4: Bajaj Allianz | H4: 30-07-2024 | I4: =ROUND(J4*100/9,) -> 75450 | J4: =L4/2 -> 6790.5 | K4: =L4/2 -> 6790.5 | L4: 13581 | M4: =I4+L4 -> 89031 | O4: 04.01.2024 to 31.03.2024 | P4: =27+29+31 -> 87 | Q4: =ROUND(P4*Q3/P3,0) -> 0
B5: 04.01.2024 to 06.01.2025 | C5: =27+29+31+4+91+97+89 -> 368 | D5: 197384 | G5: Manoj Electricals | H5: 03-04-2024 | I5: =ROUND(J5*100/9,) -> 3500 | J5: =L5/2 -> 315 | K5: =L5/2 -> 315 | L5: =630 -> 630 | M5: =I5+L5 -> 4130
A6: Less: | B6: 05.01.2024 to 31.03.2024 | C6: =-(27+29+31) -> -87 | D6: -53566 | G6: Manoj Electricals | H6: 05-08-2024 | I6: =ROUND(J6*100/9,) -> 4528 | J6: =L6/2 -> 407.5 | K6: =L6/2 -> 407.5 | L6: 815 | M6: =I6+L6 -> 5343
B7: 01.04.2024 to 06.01.2025 | C7: =SUM(C5:C6) -> 281 | D7: =SUM(D5:D6) -> 143818 | G7: Manoj Electricals | H7: 01-12-2024 | I7: =ROUND(J7*100/9,) -> 7928 | J7: =L7/2 -> 713.5 | K7: =L7/2 -> 713.5 | L7: 1427 | M7: =I7+L7 -> 9355
A8: Add: | B8: 07.01.2025 to 31.03.2025 | C8: =25+28+31 -> 84 | D8: =ROUND(C8*D7/C7,0) -> 42992 | G8: HVT Interiors | H8: 31-03-2025 | I8: =ROUND(J8*100/6,) -> 46500 | J8: =L8/2 -> 2790 | K8: =L8/2 -> 2790 | L8: 5580 | M8: =I8+L8 -> 52080
B9: 01.04.2023 to 31.03.2024 | C9: =SUM(C7:C8) -> 365 | D9: =SUM(D7:D8) -> 186810 | I9: =SUM(I4:I8) -> 137906 | J9: =SUM(J4:J8) -> 11016.5 | K9: =SUM(K4:K8) -> 11016.5 | L9: =SUM(L4:L8) -> 22033 | M9: =SUM(M4:M8) -> 159939
A12: 2 | B12: AC AMC | G12: Account No. | I12: Deposit
B13: 01.04.2024 to 21.02.2025 | C13: 367 | D13: 4455 | G13: 153245551 | I13: 92562.72 | O13: Insurance
B14: 01.12.2025 to 30.11.2026 | C14: 365 | D14: 6000 | O14: Prepaid
A15: Less: | B15: 01.04.2025 to 30.11.2026 | C15: =-(30+31+30+31+31+30+31+30) -> -244 | D15: =ROUND(D14*C15/C14,0) -> -4011 | E15: Prepaid | G15: 153243268 | I15: 0 | O15: Income tax Provision
B16: 01.04.2025 to 30.11.2026 | C16: =SUM(C13:C15) -> 488 | D16: =SUM(D13:D15) -> 6444 | I16: =SUM(I13:I15) -> 92562.72 | O16: Income tax expenses
I17: 73765
A18: 3 | B18: Gym Equipment AMC | I18: =I16-I17 -> 18797.72
B19: 01.04.2024 to 18.12.2024 | C19: =(30+31+30+31+31+30+31+30+18) -> 262 | D19: 10738
B20: 19.12.2023 to 18.12.2024 | C20: 0 | D20: 0
A21: Less: | B21: 01.04.2024 to 18.12.2024 | C21: 0 | D21: 0 | E21: Prepaid
C22: =SUM(C19:C21) -> 262 | D22: =SUM(D19:D21) -> 10738
A24: 4 | B24: Intercom AMC Exp
B25: 01.04.2024 to 09.07.2024 | C25: =(30+31+30+9) -> 100 | D25: 3552
B26: 10.07.2024 to 09.07.2025 | C26: 365 | D26: 15000
A27: Less: | B27: 01.04.2025 to 09.07.2025 | C27: =-(30+31+30+9) -> -100 | D27: =ROUND(D26*C27/C26,0) -> -4110 | E27: Prepaid
B28: 01.04.2024 to 31.03.2025 | C28: =SUM(C25:C27) -> 365 | D28: =SUM(D25:D27) -> 14442
A30: 5 | B30: Insurance Expenses
B31: 01.04.2024 to 22.05.2024 | C31: =30+22 -> 52 | D31: 12649
B32: 23.05.2024 to 22.05.2025 | C32: 365 | D32: 75450
A33: Less: | B33: 01.04.2025 to 22.05.2025 | C33: =-(30+22) -> -52 | D33: =ROUND(D32*C33/C32,0) -> -10749 | E33: Prepaid
B34: 01.04.2024 to 31.03.2025 | C34: =SUM(C31:C33) -> 365 | D34: =SUM(D31:D33) -> 77350
A36: 6 | B36: Pest Control AMC
B37: 01.04.2024 to 30.06.2024 | C37: 3 | D37: =6821+200 -> 7021
B38: 01.07.2024 to 30.06.2025 | C38: 12 | D38: =27285+29000 -> 56285
A39: Less: | B39: 01.04.2025 to 30.06.2025 | C39: -3 | D39: =ROUND(D38*C39/C38,0) -> -14071 | E39: Prepaid
B40: 01.04.2024 to 31.03.2025 | C40: =SUM(C37:C39) -> 12 | D40: =SUM(D37:D39) -> 49235
A42: 7 | B42: DG Set AMC
B43: 01.04.2024 to 30.09.2024 | C43: 6 | D43: 10000
B44: 01.10.2024 to 30.09.2025 | C44: 12 | D44: 30000
A45: Less: | B45: 01.04.2025 to 30.09.2025 | C45: -6 | D45: =ROUND(D44*C45/C44,0) -> -15000 | E45: Prepaid
B46: 01.04.2024 to 31.03.2025 | C46: =SUM(C43:C45) -> 12 | D46: =SUM(D43:D45) -> 25000
A48: 8 | B48: Lift AMC | D48: PL-01
...

Sheet Fd int Working
A1: FD No | B1: Int | C1: TDS | D1: Acc | E1: Type
A2: 5669 | B2: 11 | C2: 0 | D2: =+B2-C2 -> 11 | E2: Sweep | L2: Income Tax | N2: Old Regime | P2: New Regime
A3: 5669 | B3: 9 | C3: 0 | D3: =+B3-C3 -> 9 | E3: Sweep | L3: Income from Savings A/c. | N3: 2245 | P3: 2245
A4: 5669 | B4: 25 | C4: 0 | D4: =+B4-C4 -> 25 | E4: Sweep | L4: Income from FD & Sweep | N4: 186979 | P4: 186979
A5: 5669 | B5: 8 | C5: 0 | D5: =+B5-C5 -> 8 | E5: Sweep | L5: Scrap Sales & Promotional | N5: 25001.7 | P5: 25001.7
A6: 4076 | B6: 16995 | C6: 0 | D6: =+B6-C6 -> 16995 | E6: RF | L6: Net Taxable Income | N6: =SUM(N3:N5) -> 214225.7 | P6: =SUM(P3:P5) -> 214225.7
A7: 4075 | B7: 5670 | C7: 0 | D7: =+B7-C7 -> 5670 | E7: SF | L7: 0-10000 | M7: 0.1 | N7: 1000
A8: 5097 | B8: 12831 | C8: 0 | D8: =+B8-C8 -> 12831 | E8: SF | L8: 10000-20000 | M8: 0.2 | N8: 2000
A9: 6861 | B9: 287 | C9: 0 | D9: =+B9-C9 -> 287 | E9: SF | L9: 20000 or More | M9: 0.3 | N9: 58268 | O9: 0.22 | P9: 47130
A10: 3673 | B10: 21568 | C10: 5741 | D10: =+B10-C10 -> 15827 | E10: SF | L10: Tax | N10: =SUM(N7:N9) -> 61268 | P10: =SUM(P7:P9) -> 47130
A11: 6860 | B11: 168 | C11: 17 | D11: =+B11-C11 -> 151 | E11: RF | L11: Surcharge | M11: 0.1 | N11: 0 | P11: =ROUND(P10*10%,0) -> 4713
A12: 5098 | B12: 8456 | C12: 845 | D12: =+B12-C12 -> 7611 | E12: GF | N12: =SUM(N10:N11) -> 61268 | P12: =SUM(P10:P11) -> 51843
A13: 6862 | B13: 271 | C13: 27 | D13: =+B13-C13 -> 244 | E13: GF | L13: Education cess | M13: 0.04 | N13: =ROUND(N12*4%,0) -> 2451 | O13: 0.04 | P13: =ROUND(P12*4%,0) -> 2074
A14: 4077 | B14: 5670 | C14: 567 | D14: =+B14-C14 -> 5103 | E14: SF | L14: Total Tax | N14: =SUM(N12:N13) -> 63719 | P14: =SUM(P12:P13) -> 53917
A15: 6864 | B15: 218 | C15: 22 | D15: =+B15-C15 -> 196 | E15: CA Fund | L15: Say | N15: =ROUND(N14,-1) -> 63720 | P15: =ROUND(P14,-1) -> 53920
A16: 4078 | B16: 16995 | C16: 1700 | D16: =+B16-C16 -> 15295 | E16: GF | K16: Less: | L16: TDS Receivables | N16: 18698 | P16: 18698
A17: 5107 | B17: 7292 | C17: 729 | D17: =+B17-C17 -> 6563 | E17: GF | K17: Less: | L17: Advance Taxes paid | N17: 32800 | P17: 32800
A18: 6863 | B18: 22 | C18: 2 | D18: =+B18-C18 -> 20 | E18: Edu | N18: =SUM(N16:N17) -> 51498 | P18: =SUM(P16:P17) -> 51498
A19: 5108 | B19: 7292 | C19: 729 | D19: =+B19-C19 -> 6563 | E19: GF | L19: Net Payable/ (Refund) | N19: =N15-N18 -> 12222 | P19: =P15-P18 -> 2422
A20: 5669 | B20: 17785 | C20: 1779 | D20: =+B20-C20 -> 16006 | E20: Sweep
A21: 2984 | B21: 30 | C21: 3 | D21: =+B21-C21 -> 27 | E21: SC
A22: 405 | B22: 65376 | C22: 6537 | D22: =+B22-C22 -> 58839 | E22: RF
A23: Total | B23: =SUM(B2:B22) -> 186979 | C23: =SUM(C2:C22) -> 18698 | D23: =SUM(D2:D22) -> 168281
