Workbook

Sheet BS
A1: JEEVAN HEIGHTS CO-OPERATIVE HOUSING SOCIETY LTD
A2: Society Address: Bandar, Pakhadi Road ,Kandivali (W), Mumbai - 400067.
A3: Society Reg No : TNA/TNA/HSG/TC/13111/Year 2021
A4: Balance Sheet as at March 31, 2026
H5: (Amounts in ₹)
A6: March 31, 2025 | B6: LIABILITIES | D6: March 31, 2026 | E6: =A6 -> March 31, 2025 | F6: ASSETS | H6: =D6 -> March 31, 2026
B7: Share Capital: | F7: Cash and Bank Balances:
A8: =4000*50 -> 200000 | B8: Authorised: 4,000 shares of ₹ 50/- each | D8: 200000 | E8: 1546 | F8: Cash in Hand | G8: =4121 -> 4121
E9: =BRS!A36 -> 54399 | F9: MDCC Bank | G9: =BRS!D36 -> 6956
A10: 31500 | B10: Share Application Money Pending Allotment | D10: 31500 | E10: =BRS!A7 -> 922186.04 | F10: ICICI Bank | G10: =BRS!D7 -> 866516.04
B11: 630 Shares of Rs. 50/- each | E11: =BRS!A22 -> 55753.28 | F11: Union Bank of India | G11: =BRS!D22 -> 57533.28 | H11: =SUM(G8:G11) -> 935126.32
A13: =+'Sch 5'!B32 -> 3977417.1 | B13: Reserves and Surplus (Sch 5) | D13: =+'Sch 5'!E32 -> 4575563.1 | E13: =4604276 -> 4604276 | F13: Fixed Deposit (Sch 1) | H13: =+'Sch 1'!M42 -> 5206674
B15: Current Liabilities & Provision: (Sch 6) | F15: Loan & Advances
A16: ='Sch 4,6'!B32 -> 507786 | B16: Vendors Payable | C16: ='Sch 4,6'!D32 -> 299406 | E16: ='Sch 4,6'!B54 -> 20433 | F16: Advance Payment to Vendor | H16: ='Sch 4,6'!D54 -> 35000
A17: ='Sch 4,6'!B39 -> 114401 | B17: Statutory Dues Payable | C17: =+'Sch 4,6'!D39 -> 173317
A18: ='Sch 4,6'!B47 -> 58730 | B18: Provisions | C18: =+'Sch 4,6'!D47 -> 126019 | D18: =SUM(C16:C18) -> 598742 | F18: Deposits
E19: =73765+18798 -> 92563 | F19: Adani electricity | G19: =73765+18798 -> 92563
B20: Members' Payables: | E20: 2721 | F20: MCGM -water | G20: 2721 | H20: =SUM(G19:G20) -> 95284
A21: 101874 | B21: Advance Members (Sch 7) | D21: ='Sch 3&7'!D22 -> 100381
E22: ='Sch 2'!C15 -> 533313 | F22: Fixed Assets: (Sch 2) | H22: =+'Sch 2'!I15 -> 864792
B23: Retained Earnings:
A24: 1259516.6 | B24: Retained Earnings | C24: =1770482.23 -> 1770482.2 | F24: Other Current Assets:
A25: -2484 | B25: Add: Prior period Adjustment | C25: 0 | E25: 65424 | F25: Member receivables (Sch 3) | G25: ='Sch 3&7'!D13 -> 233214
A26: =PL!A48 -> 513449.6 | B26: Surplus / (Deficit) for the Period | C26: =+PL!D48 -> 548593 | D26: =SUM(C24:C26) -> 2319075.2 | E26: 0 | F26: Shirke Recreation Enterprise | G26: -
E27: 22033 | F27: Unclaimed ITC | G27: 0
E28: 550 | F28: Integrated GST | G28: 8303
E29: 26115 | F29: TDS receivables | G29: =56943-26115 -> 30828
E30: 53000 | F30: Self Assessment & Advance Tax paid | G30: =125000-53000 -> 72000 | H30: =SUM(G25:G30) -> 344345
E32: =+'Sch 4,6'!B13 -> 107878 | F32: Prepaid Expenses (Sch 4) | H32: =+'Sch 4,6'!D13 -> 144040
A34: =SUM(A10:A33) -> 6562190.3 | B34: Total | D34: =SUM(D10:D33) -> 7625261.3 | E34: =SUM(E7:E33) -> 6562190.3 | F34: Total | H34: =SUM(H7:H33) -> 7625261.3
G35: =A34-E34 -> 0 | H35: =H34-D34 -> 0
A36: As per my report of even date | E36: FOR JEEVAN HEIGHTS CO-OPERATIVE HOUSING SOCIETY LTD
A40: Shri. Bharat C. Boridkar
A41: Govt. Certified Panel Auditor | E41: Chairman Secretary Treasurer
A42: [Panel No.: Mumbai-4/C1/1011404]
A43: 46221

Sheet PL
A1: =BS!A1 -> JEEVAN HEIGHTS CO-OPERATIVE HOUSING SOCIETY LTD
A2: =BS!A2 -> Society Address: Bandar, Pakhadi Road ,Kandivali (W), Mumbai - 400067.
A3: Society Reg No : TNA/TNA/HSG/TC/13111/Year 2021
A4: Income and Expenditure Account for the year ended March 31, 2026 | M4: Account Head | N4: Income | O4: Expenses | P4: Surplus/ (Deficit)
H5: (Amounts in ₹) | M5: Common Area maintenance Charges | N5: 3575880 | O5: =D9+D22+D30-C25-C27+D45-C45 -> 3134026 | P5: =N5-O5 -> 441854
A6: =BS!A6 -> March 31, 2025 | B6: EXPENDITURE | D6: =BS!D6 -> March 31, 2026 | E6: =A6 -> March 31, 2025 | F6: INCOME | H6: =D6 -> March 31, 2026 | M6: Common Electricity Charges | N6: 1388772 | O6: =D13 -> 1702520 | P6: =N6-O6 -> -313748
B7: Salary Expenses | F7: Maintenance Income: | M7: Water Charges | N7: 401940 | O7: =D16 -> 147921 | P7: =N7-O7 -> 254019
A8: 166200 | B8: Salary Expenses | C8: =243250 -> 243250 | E8: 3575880 | F8: Common Area maintenance Charges | G8: 3575880 | M8: Usage charges | N8: 896988 | O8: =C25 -> 635404 | P8: =N8-O8 -> 261584
A9: 49600 | B9: Diwali Bonus | C9: =2500+47000 -> 49500 | D9: =SUM(C8:C9) -> 292750 | E9: 1388772 | F9: Common Electricity Charges | G9: 1388772 | M9: Insurance Charges | N9: 84952 | O9: =C27 -> 67777 | P9: =N9-O9 -> 17175
B10: Property Tax | E10: 401940 | F10: Water Charges | G10: 401940 | M10: Society Welfare Charges | N10: 226800 | O10: =C45 -> 330009 | P10: =N10-O10 -> -103209
A11: 111260 | B11: Property Tax Members | D11: =130988 -> 130988 | E11: 47280 | F11: Non-Occupancy Charges | G11: =47280 -> 47280 | M11: Common area property Tax | N11: 47628 | O11: =D11 -> 130988 | P11: =N11-O11 -> -83360
B12: Common electricity expenses | E12: 84952 | F12: Insurance Charges | G12: 84952 | M12: Parking Property tax | N12: 65412 | O12: 0 | P12: =N12-O12 -> 65412
A13: =1595680 -> 1595680 | B13: Electricity Expenses | D13: =1702520 -> 1702520 | E13: 226800 | F13: Society Welfare Charges | G13: 226800 | M13: (A) | N13: =SUM(N5:N12) -> 6688372 | O13: =SUM(O5:O12) -> 6148645 | P13: =SUM(P5:P12) -> 539727
B14: Water Expenses | E14: 24207 | F14: Late Payment Interest | G14: =29466 -> 29466 | H14: =SUM(G8:G14) -> 5755090 | M14: Non-Occupancy Charges | N14: 45310 | O14: 0 | P14: =N14-O14 -> 45310
A15: =186810 -> 186810 | B15: MCGM water expenses | C15: =Workings!D9 -> 140421 | M15: Function Charges (Ground /Terrace) | N15: 37500 | O15: 0 | P15: =N15-O15 -> 37500
A16: =47000-20000 -> 27000 | B16: Water Tanker Expenses | C16: =7500 -> 7500 | D16: =SUM(C15:C16) -> 147921 | F16: Property Tax | M16: Shifting Charges Move In And Move Out | N16: 20000 | O16: 0 | P16: =N16-O16 -> 20000
B17: Lift Maintenance | E17: 47628 | F17: Common area property Tax | G17: =3591+58401 -> 61992 | M17: Interest on Savings Account | N17: 2245 | O17: 0 | P17: =N17-O17 -> 2245
A18: =656445 -> 656445 | B18: Lift AMC Expenses | C18: =Workings!D61 -> 698739 | E18: 65412 | F18: Parking Property tax | G18: =948+68256 -> 69204 | H18: =SUM(G17:G18) -> 131196 | M18: Interest on Fixed Deposits | N18: 17868 | O18: 0 | P18: =N18-O18 -> 17868
A19: =-A18 -> -656445 | B19: Less: Trfd to Repair Fund | C19: =-C18 -> -698739 | D19: =SUM(C18:C19) -> 0 | M19: Misc. Income | N19: 25001.7 | O19: 0 | P19: =N19-O19 -> 25001.7
F20: Other Member Income | M20: (B) | N20: =SUM(N14:N19) -> 147924.7 | O20: =SUM(O14:O19) -> 0 | P20: =SUM(P14:P19) -> 147924.7
B21: Repair and Maintenance Expense (Sch 8) | E21: =37500+5000 -> 42500 | F21: Function Charges (Ground /Terrace) | G21: =20000+5000 -> 25000 | M21: C = (A+B) | N21: =N13+N20 -> 6836296.7 | O21: =O13+O20 -> 6148645 | P21: =P13+P20 -> 687651.7
A22: ='Sch 8 & 9'!B34 -> 524117 | B22: As per schedule | D22: ='Sch 8 & 9'!D34 -> 532719 | E22: 0 | F22: Shifting Charges Move In And Move Out | G22: =10000 -> 10000
B23: Service Expenses: | E23: 896988 | F23: Usage charges | G23: 896988 | H23: =SUM(G21:G23) -> 931988
A24: 1342948 | B24: Security Expenses | C24: 1068130
A25: =538285+64745 -> 603030 | B25: Housekeeping Expenses, incl material | C25: =540480+15622+79302 -> 635404 | F25: Interest Income:
A26: ='Sch 2'!K15 -> 70170.4 | B26: Depreciation | C26: =+'Sch 2'!H15 -> 100773 | E26: 2421 | F26: Interest on Savings Account | H26: =2337 -> 2337
A27: 77350 | B27: Insurance | C27: =Workings!D32 -> 67777 | E27: =257457 -> 257457 | F27: Interest on Fixed Deposits | G27: =308272+3149 -> 311421
A28: 7080 | B28: Software Charges | C28: 0 | E28: -66446 | F28: Less: Trf to Reserve Fund | G28: 74652
A29: 6300 | B29: Audit Fees | C29: 6300 | E29: -70799 | F29: Less: Trf to Sinking Fund | G29: =105827+3149 -> 108976
A30: 49235 | B30: Pest Control Expense | C30: =Workings!D38 -> 34775 | D30: =SUM(C24:C30) -> 1913159 | E30: -99607 | F30: Less: Trf to Repair Fund | G30: 104952
B31: General Expenses: | E31: -1693 | F31: Less: Trf to Edu & Trng Fund | G31: 2854
A32: =6596+51304-11000 -> 46900 | B32: General Expenses | C32: =6143+33248 -> 39391 | E32: -16657 | F32: Less: Trf to Common Amenities | G32: 17733
A33: 378184 | B33: Gym Expenses | C33: =407766 -> 407766 | E33: 3693 | F33: Interest on Sweep | G33: 0 | H33: =G27-SUM(G28:G32)+G33 -> 2254
A34: 3750 | B34: Telephone and Internet Expenses | C34: =1260 -> 1260
A35: 69000 | B35: Accounting Charges | C35: =72456 -> 72456 | F35: Other Income:
A36: 9502 | B36: Printing and Stationary | C36: =10032 -> 10032 | E36: 3000 | F36: Misc. Income | H36: =17500 -> 17500
A37: 80 | B37: Postage and Courier | C37: 0 | E37: 0 | F37: NR Paid Ads | H37: 39738
A38: 53000 | B38: Meeting Expenses | C38: =43000 -> 43000
A39: 1350 | B39: Conveyance Charges | C39: =6800 -> 6800
A40: 1298 | B40: Bank Charges | C40: =59 -> 59
...

Sheet Sch 1
A1: =BS!A1 -> JEEVAN HEIGHTS CO-OPERATIVE HOUSING SOCIETY LTD
A2: Schedule 1: Fixed Deposit Statement as at March 31, 2026
A3: Sr. | B3: FD Account No. | C3: Bank | D3: ROI % | E3: Date of Issue | F3: Principal Invested | G3: Accrued Interest 2021-22 | H3: Accrued Interest 2022-23 | I3: Accrued Interest 2023-24 | J3: Accrued Interest 2024-25 | K3: Accrued Interest 2025-26 | L3: Total Accrued Interest | M3: Total Amt Invested | N3: Date of Maturity | O3: Value at Maturity
B4: Sinking Fund:
A5: 1 | B5: 196013003673 | C5: ICICI | D5: 0.056 | E5: 30.03.2022 | F5: 362304 | G5: 109 | H5: 14738 | I5: 15827 | J5: =22473 -> 22473 | K5: =23758-2376 -> 21382 | L5: =SUM(G5:K5) -> 74529 | M5: =F5+L5 -> 436833 | N5: 31.03.2027 | O5: 475851
A6: 2 | B6: 196013004075 | C6: ICICI | D6: 0.059 | E6: 20.08.2022 | F6: 90666 | G6: 0 | H6: 3331 | I6: 5670 | J6: =6012-601 -> 5411 | K6: =6338-634 -> 5704 | L6: =SUM(G6:K6) -> 20116 | M6: =F6+L6 -> 110782 | N6: 14.09.2027 | O6: 121856
A7: 3 | B7: 196013005097 | C7: ICICI | D7: 0.069 | E7: 30.03.2023 | F7: 181152 | G7: 0 | H7: 60 | I7: 12831 | J7: =13739-1374 -> 12365 | K7: =14615-1462 -> 13153 | L7: =SUM(G7:K7) -> 38409 | M7: =F7+L7 -> 219561 | N7: 01.05.2028 | O7: =256027 -> 256027
A8: 4 | B8: 196013004077 | C8: ICICI | D8: 0.059 | E8: 20.08.2022 | F8: 90666 | G8: 0 | H8: 3331 | I8: 5103 | J8: =5977-598 -> 5379 | K8: =6302-631 -> 5671 | L8: =SUM(G8:K8) -> 19484 | M8: =F8+L8 -> 110150 | N8: 14.09.2027 | O8: 121729
A9: 5 | B9: 196013006861-1 | C9: ICICI | D9: 0.063 | E9: 27.03.2026 | F9: 334942 | G9: 0 | H9: 0 | I9: 0 | J9: 0 | K9: =284-29 -> 255 | L9: =SUM(G9:K9) -> 255 | M9: =F9+L9 -> 335197 | N9: 27.03.2028 | O9: 379542
A10: 6 | B10: 196013008007 | C10: ICICI | D10: 0.07 | E10: 20.03.2025 | F10: 296316 | G10: 0 | H10: 0 | I10: 0 | J10: =669-67 -> 602 | K10: =21336-2134 -> 19202 | L10: =SUM(G10:K10) -> 19804 | M10: =F10+L10 -> 316120 | N10: 20.03.2030 | O10: 418517
A11: 7 | B11: 196013008668 | C11: ICICI | D11: 0.066 | E11: 26.09.2025 | F11: 294841 | G11: 0 | H11: 0 | I11: 0 | J11: 0 | K11: =10134-1013 -> 9121 | L11: =SUM(G11:K11) -> 9121 | M11: =F11+L11 -> 303962 | N11: 27.09.2030 | O11: 408740
A12: 8 | B12: 15605300009900 | C12: MDCC | D12: 0.072 | E12: 20.06.2025 | F12: 55000 | G12: 0 | H12: 0 | I12: 0 | J12: 0 | K12: =3149 -> 3149 | L12: =SUM(G12:K12) -> 3149 | M12: =F12+L12 -> 58149 | N12: 20.03.2027 | O12: 62316
A13: Total :- | F13: =SUM(F5:F12) -> 1705887 | G13: =SUM(G5:G12) -> 109 | H13: =SUM(H5:H12) -> 21460 | I13: =SUM(I5:I12) -> 39431 | J13: =SUM(J5:J12) -> 46230 | K13: =SUM(K5:K12) -> 77637 | L13: =SUM(L5:L12) -> 184867 | M13: =SUM(M5:M12) -> 1890754 | O13: =SUM(O5:O12) -> 2244578
B15: Repair Fund:
A16: 9 | B16: 195913010405 | C16: ICICI | D16: 0.056 | E16: 30.03.2022 | F16: 1086912 | G16: 327 | H16: 55959 | I16: 58839 | J16: =68741-6875 -> 61866 | K16: =72278-7228 -> 65050 | L16: =SUM(G16:K16) -> 242041 | M16: =F16+L16 -> 1328953 | N16: 31.03.2027 | O16: 1431602
A17: 10 | B17: 196013004076 | C17: ICICI | D17: 0.059 | E17: 20.08.2022 | F17: 271772 | G17: 0 | H17: 9985 | I17: 16995 | J17: =18020-1802 -> 16218 | K17: =18998-1900 -> 17098 | L17: =SUM(G17:K17) -> 60296 | M17: =F17+L17 -> 332068 | N17: 14.09.2027 | O17: =365263 -> 365263
A18: 11 | B18: 196013006860-1 | C18: ICICI | D18: 0.063 | E18: 27.03.2026 | F18: 197391 | G18: 0 | H18: 0 | I18: 0 | J18: 0 | K18: =167-16 -> 151 | L18: =SUM(G18:K18) -> 151 | M18: =F18+L18 -> 197542 | N18: 27.03.2028 | O18: 223675
A19: Total :- | F19: =SUM(F16:F18) -> 1556075 | G19: =SUM(G16:G18) -> 327 | H19: =SUM(H16:H18) -> 65944 | I19: =SUM(I16:I18) -> 75834 | J19: =SUM(J16:J18) -> 78084 | K19: =SUM(K13:K18) -> 159936 | L19: =SUM(L13:L18) -> 487355 | M19: =SUM(M16:M18) -> 1858563 | O19: =SUM(O16:O18) -> 2020540
B21: General Fund
A22: 12 | B22: 196013005098 | C22: ICICI | D22: 0.069 | E22: 30.03.2023 | F22: 119378 | G22: 0 | H22: 40 | I22: 7611 | J22: =8994-899 -> 8095 | K22: =9567-956 -> 8611 | L22: =SUM(G22:K22) -> 24357 | M22: =F22+L22 -> 143735 | N22: 01.05.2028 | O22: 168451
A23: 13 | B23: 196013004078 | C23: ICICI | D23: 0.059 | E23: 20.08.2022 | F23: 271772 | G23: 0 | H23: 9985 | I23: 15295 | J23: =17918-1792 -> 16126 | K23: =18890-1889 -> 17001 | L23: =SUM(G23:K23) -> 58407 | M23: =F23+L23 -> 330179 | N23: 14.09.2027 | O23: =364885 -> 364885
A24: 14 | B24: 196013005107-1 | C24: ICICI | D24: 0.0625 | E24: 30.11.2025 | F24: 119433 | G24: 0 | H24: 0 | I24: 0 | J24: 0 | K24: =2539-253 -> 2286 | L24: =SUM(G24:K24) -> 2286 | M24: =F24+L24 -> 121719 | N24: 30.03.2027 | O24: 129707
A25: 15 | B25: 196013005108-1 | C25: ICICI | D25: 0.0625 | E25: 30.11.2025 | F25: 115605 | G25: 0 | H25: 0 | I25: 0 | J25: 0 | K25: =2457-246 -> 2211 | L25: =SUM(G25:K25) -> 2211 | M25: =F25+L25 -> 117816 | N25: 30.03.2027 | O25: 125549
A26: 16 | B26: 196013006862-1 | C26: ICICI | D26: 0.063 | E26: 27.03.2026 | F26: 318650 | G26: 0 | H26: 0 | I26: 0 | J26: 0 | K26: =270-27 -> 243 | L26: =SUM(G26:K26) -> 243 | M26: =F26+L26 -> 318893 | N26: 27.03.2028 | O26: 361081
A27: 17 | B27: 196013007647-1 | C27: ICICI | D27: 0.0625 | E27: 14.02.2026 | F27: 120336 | G27: 0 | H27: 0 | I27: 0 | J27: 0 | K27: =991-99 -> 892 | L27: =SUM(G27:K27) -> 892 | M27: =F27+L27 -> 121228 | N27: 14.05.2027 | O27: 130029
A28: Total :- | F28: =SUM(F22:F27) -> 1065174 | G28: =SUM(G22:G27) -> 0 | H28: =SUM(H22:H27) -> 10025 | I28: =SUM(I22:I27) -> 22906 | J28: =SUM(J22:J27) -> 24221 | K28: =SUM(K22:K27) -> 31244 | L28: =SUM(L22:L27) -> 88396 | M28: =SUM(M22:M27) -> 1153570 | O28: =SUM(O22:O27) -> 1279702
B30: Share Capital
A31: 18 | B31: 196010002984 | C31: ICICI | D31: 0.063 | E31: 27.03.2026 | F31: 31500 | G31: 0 | H31: 0 | I31: 0 | J31: 0 | K31: =27-3 -> 24 | L31: =SUM(G31:K31) -> 24 | M31: =F31+L31 -> 31524 | N31: 27.03.2028 | O31: 31500
A32: Total :- | F32: =SUM(F31) -> 31500 | G32: =SUM(G31) -> 0 | H32: =SUM(H31) -> 0 | I32: =SUM(I31) -> 0 | J32: =SUM(J31) -> 0 | K32: =SUM(K26:K31) -> 32403 | L32: =SUM(L26:L31) -> 89555 | M32: =SUM(M31) -> 31524 | O32: =SUM(O31) -> 31500
B34: Education & Training Fund
A35: 19 | B35: 196013008039 | C35: ICICI | D35: 0.07 | E35: 27.03.2025 | F35: 15124 | G35: 0 | H35: 0 | I35: 0 | J35: =14-2 -> 12 | K35: =1088-109 -> 979 | L35: =SUM(G35:K35) -> 991 | M35: =F35+L35 -> 16115 | N35: 27.03.3030 | O35: 21362
A36: Total :- | F36: =SUM(F35:F35) -> 15124 | G36: =SUM(G35:G35) -> 0 | H36: =SUM(H35:H35) -> 0 | I36: =SUM(I35:I35) -> 0 | J36: =SUM(J35:J35) -> 12 | K36: =SUM(K31:K35) -> 33406 | L36: =SUM(L31:L35) -> 90570 | M36: =SUM(M35:M35) -> 16115 | O36: =SUM(O35:O35) -> 21362
B38: Common Amenities Fund
A39: 20 | B39: 196013006864-1 | C39: ICICI | D39: 0.063 | E39: 27.03.2026 | F39: 255952 | G39: 0 | H39: 0 | I39: 0 | J39: 0 | K39: =217-21 -> 196 | L39: =SUM(G39:K39) -> 196 | M39: =F39+L39 -> 256148 | N39: 27.03.2028 | O39: 290034
A40: Total :- | F40: =SUM(F39) -> 255952 | G40: =SUM(G39) -> 0 | H40: =SUM(H39) -> 0 | I40: =SUM(I39) -> 0 | J40: =SUM(J39) -> 0 | K40: =SUM(K35:K39) -> 34581 | L40: =SUM(L35:L39) -> 91757 | M40: =SUM(M39) -> 256148 | O40: =SUM(O39) -> 290034
A42: Total :- | F42: =F13+F19+F28+F32+F36+F40 -> 4629712 | G42: =G13+G19+G28+G32+G36+G40 -> 436 | H42: =H13+H19+H28+H32+H36+H40 -> 97429 | I42: =I13+I19+I28+I32+I36+I40 -> 138171 | J42: =J13+J19+J28+J32+J36+J40 -> 148547 | K42: =K13+K19+K28+K32+K36+K40 -> 369207 | L42: =L13+L19+L28+L32+L36+L40 -> 1032500 | M42: =M13+M19+M28+M32+M36+M40 -> 5206674 | O42: =O13+O19+O28+O32+O36+O40 -> 5887716

Sheet Sch 2
A1: =BS!A1 -> JEEVAN HEIGHTS CO-OPERATIVE HOUSING SOCIETY LTD
A3: Schedule 2: Fixed Assets Details as at March 31, 2026
A4: Sr. | B4: Assets | C4: Gross Blosk | G4: Depreciation | I4: Net Block
C5: Opening Balance 01.04.2024 | D5: Additions during the year before 30.09.2025 | E5: Additions during the year after 30.09.2025 | F5: Cost at 31.03.2026 | G5: Rate of Dep. (%) | H5: FY 2025-26 | K5: FY 2024-25
A6: 1 | B6: Computer | C6: 17729 | D6: 0 | E6: =11653 -> 11653 | F6: =C6+D6+E6 -> 29382 | G6: 0.4 | H6: =ROUND(SUM(C6:D6,E6/2)*G6,) -> 9422 | I6: =F6-H6 -> 19960 | K6: 11820
A7: 2 | B7: Intercom System | C7: 2224 | D7: 0 | E7: =53389 -> 53389 | F7: =C7+D7+E7 -> 55613 | G7: 0.15 | H7: =ROUND(SUM(C7:D7,E7/2)*G7,) -> 4338 | I7: =F7-H7 -> 51275 | K7: 393
A8: 3 | B8: CCTV System | C8: 79317 | D8: 0 | E8: =5160+7250+66550 -> 78960 | F8: =C8+D8+E8 -> 158277 | G8: 0.15 | H8: =ROUND(SUM(C8:D8,E8/2)*G8,) -> 17820 | I8: =F8-H8 -> 140457 | K8: 9608
A9: 4 | B9: Battery | C9: 8956 | D9: 0 | E9: 0 | F9: =C9+D9+E9 -> 8956 | G9: 0.15 | H9: =ROUND(SUM(C9:D9,E9/2)*G9,) -> 1343 | I9: =F9-H9 -> 7613 | K9: 1580
A10: 5 | B10: Fan | C10: 35586 | D10: =8950 -> 8950 | E10: 0 | F10: =C10+D10+E10 -> 44536 | G10: 0.15 | H10: =ROUND(SUM(C10:D10,E10/2)*G10,) -> 6680 | I10: =F10-H10 -> 37856 | K10: 6280
A11: 6 | B11: Submersible Pump | C11: 14949 | D11: 0 | E11: 0 | F11: =C11+D11+E11 -> 14949 | G11: 0.15 | H11: =ROUND(SUM(C11:D11,E11/2)*G11,) -> 2242 | I11: =F11-H11 -> 12707 | K11: 2638
A12: 7 | B12: Sound System | C12: 28403 | D12: 0 | E12: 0 | F12: =C12+D12+E12 -> 28403 | G12: 0.15 | H12: =ROUND(SUM(C12:D12,E12/2)*G12,) -> 4260 | I12: =F12-H12 -> 24143 | K12: 5012
A13: 8 | B13: Furniture and Fixtures | C13: 346149 | D13: 0 | E13: =35800 -> 35800 | F13: =C13+D13+E13 -> 381949 | G13: 0.1 | H13: =ROUND(SUM(C13:D13,E13/2)*G13,) -> 36405 | I13: =F13-H13 -> 345544 | K13: 32839.4
A14: 9 | B14: Boom Barrier Automated Gate | C14: 0 | D14: 0 | E14: =168500+75000 -> 243500 | F14: =C14+D14+E14 -> 243500 | G14: 0.15 | H14: =ROUND(SUM(C14:D14,E14/2)*G14,) -> 18263 | I14: =F14-H14 -> 225237 | K14: 32839.4
A15: Total | C15: =SUM(C6:C14) -> 533313 | D15: =SUM(D6:D14) -> 8950 | E15: =SUM(E6:E14) -> 423302 | F15: =SUM(F6:F14) -> 965565 | H15: =SUM(H6:H14) -> 100773 | I15: =SUM(I6:I14) -> 864792 | K15: =SUM(K6:K13) -> 70170.4

Sheet Sch 3&7
A1: =BS!A1 -> JEEVAN HEIGHTS CO-OPERATIVE HOUSING SOCIETY LTD
A3: Schedule 3: Members Receivables March 31, 2026
A4: Block | B4: Flat | C4: Members Name | D4: Amount
A5: Block | B5: 1701 | C5: Mrs.Rajashri Jayesh Shah & Mr. Utsav Jayesh Shah | D5: 2950
A6: Block | B6: 2001 | C6: Mrs.Sneha Ashok Rathod | D6: 151487
A7: Block | B7: 3402 | C7: Mr.Manoj Kanaiyalal Kanakia & Mrs.Nisha Manoj Kanakia | D7: 61155
A8: Utility | B8: 1102 | C8: Mr. Ketan Mahendrakumar Shah & Mrs Alpa Ketan Shah | D8: 1025
A9: Utility | B9: 1302 | C9: Mr.Bharat Jadavji Valia & Mrs. Meena Bharat Valia | D9: 45
A10: Utility | B10: 2001 | C10: Mrs.Sneha Ashok Rathod | D10: 8075
A11: Utility | B11: 2701 | C11: Mr.Hemant Vamanrai Mathuria & Mrs. Kiran Hemant Mathuria | D11: 289
A12: Utility | B12: 3402 | C12: Mr.Manoj Kanaiyalal Kanakia & Mrs.Nisha Manoj Kanakia | D12: 8188
C13: Total | D13: =SUM(D5:D12) -> 233214
A17: Schedule 7 : Advance from Members March 31, 2026
A18: Sr. No. | B18: Flat | C18: Members Name | D18: Amount
A19: 1 | B19: 402 | C19: Mrs.Khyati Namit Turakhia & Mr.Namit Mahendra Turakhia | D19: =85500 -> 85500
A20: 2 | B20: 2402 | C20: Mrs.Ila Ashok Sanghavi Mr. Ashok Vrajlal Sanghavi | D20: 2950
A21: 3 | B21: U - 402 | C21: Mrs.Khyati Namit Turakhia & Mr.Namit Mahendra Turakhia | D21: 11931
C22: Total | D22: =SUM(D19:D21) -> 100381

Sheet Sch 4,6
A1: =BS!A1 -> JEEVAN HEIGHTS CO-OPERATIVE HOUSING SOCIETY LTD
A3: Schedule 4: Prepaid Expenses
A4: Sr. No. | B4: FY 2024-25 | C4: Expenses | D4: FY 2025-26
A5: 2 | B5: 14071 | C5: Pest Control | D5: =-Workings!D37 -> 6821
A6: 3 | B6: 4110 | C6: Intercome/CCTV | D6: 0
A7: 4 | B7: 0 | C7: Stack Parking AMC | D7: =-Workings!D94 -> 41191
A8: 5 | B8: 15000 | C8: DG Set | D8: 0
A9: 6 | B9: 10749 | C9: Insurance | D9: =-Workings!D31 -> 27932
A10: 7 | B10: 49437 | C10: Lift AMC | D10: =-Workings!D57 -> 52596
A11: 8 | B11: 4011 | C11: AC AMC | D11: =-Workings!D15 -> 5000
A12: 9 | B12: 10500 | C12: Fire Fighting System AMC | D12: =-Workings!D66 -> 10500
B13: =SUM(B5:B12) -> 107878 | C13: Total | D13: =SUM(D5:D12) -> 144040
A15: Schedule 6: Payable to Vendors March 31, 2026
A16: Sr. No. | B16: =B4 -> FY 2024-25 | C16: A - Vendor Payables | D16: =D4 -> FY 2025-26
A17: 1 | B17: 0 | C17: Bindu Subhash Singh Yadav | D17: 1860
A18: 2 | B18: 139200 | C18: Adani Electricity | D18: 149320
A19: 3 | B19: 101970 | C19: Ashtabhuja Security Guard | D19: 31029
A20: 4 | B20: 5500 | C20: Dhanji Solanki | D20: 6000
A21: 5 | B21: 11886 | C21: Flow Chem Pumps Pvt. Ltd. | D21: 0
A22: 6 | B22: 86955 | C22: Hitachi Lift India Private Limited | D22: 0
A23: 7 | B23: 10733 | C23: Irene Rosario | D23: 5434
A24: 8 | B24: 0 | C24: Rishabh R Tripathi | D24: 11421
A25: 9 | B25: 0 | C25: Supriya | D25: 2000
A26: 10 | B26: 24360 | C26: Vision Fire & Safety Engineers | D26: 0
A27: 11 | B27: 8350 | C27: Sakshi Bhosle | D27: 8750
A28: 12 | B28: 10725 | C28: Shivant Hardare | D28: 0
... A31: 15 | B31: 30680 | C31: Yashwant Kamble | D31: 33660
B32: =SUM(B17:B31) -> 507786 | C32: Total (a) | D32: =SUM(D17:D31) -> 299406
A34: Sr. No. | B34: =B4 -> FY 2024-25 | C34: B - Statutory Dues Payable | D34: =D4 -> FY 2025-26
A35: 1 | B35: 4879 | C35: TDS Payable | D35: 4816
A36: 2 | B36: 18397 | C36: GST Payable - RCM | D36: 12881
A37: 3 | B37: 11125 | C37: GST Payable - Regular | D37: 42990
A38: 4 | B38: 80000 | C38: Income Tax Payable | D38: 112630
B39: =SUM(B35:B38) -> 114401 | C39: Total (b) | D39: =SUM(D35:D38) -> 173317
A41: Sr. No. | B41: =B4 -> FY 2024-25 | C41: C - Provisions | D41: =D4 -> FY 2025-26
A42: 1 | B42: 6300 | C42: Audit Fees | D42: 6300
A43: 2 | B43: 42992 | C43: Water Charges payable | D43: =Workings!D8 -> 102719
A44: 3 | B44: 0 | C44: DG Set AMC | D44: 11000
A45: 4 | B45: 0 | C45: Fire Fighting AMC | D45: 6000
A46: 5 | B46: 9438 | C46: Stack Parking AMC | D46: 0
...

Sheet Sch 5
A1: =+'Sch 3&7'!A1:D1 -> JEEVAN HEIGHTS CO-OPERATIVE HOUSING SOCIETY LTD
A2: Schedule - 5 : Reserves and Surplus as on 31.03.2026
A3: Sr. No. | B3: FY 2024-25 | C3: Account Head | E3: FY 2025-26
A4: 1 | C4: Reserve Fund
B5: 527238 | C5: As per last year BS | D5: 765534
B6: 200 | C6: Add: Entrance Fees | D6: =300 -> 300
B7: 500 | C7: Add: Share Transfer Fees | D7: =1500 -> 1500
B8: =PL!A47 -> 171150 | C8: Add: 25% of Surplus | D8: =PL!D47 -> 182865
B9: =-PL!E28 -> 66446 | C9: Add: Int. acc./recd during the year | D9: =PL!G28 -> 74652 | E9: =SUM(D5:D9) -> 1024851 | G9: =E9-'Sch 1'!M28 -> -128719 | H9: FD Excess
A11: 2 | C11: Sinking Fund
B12: 1088565 | C12: As per last year BS | D12: =1449372 -> 1449372
B13: 290008 | C13: Add: Collection during the year | D13: 290008
B14: =-PL!E29 -> 70799 | C14: Add: Int. acc./recd during the year | D14: =PL!G29 -> 108976 | E14: =SUM(D12:D14) -> 1848356 | G14: =E14-'Sch 1'!M13 -> -42398 | H14: FD Short
A16: 3 | C16: Repair and Maintenance Fund
B17: 1492214.1 | C17: As per last year BS | D17: 1488681.1
B18: 869892 | C18: Add: Collection during the year | D18: 869892
B19: =PL!A19+'Sch 8 & 9'!B25+'Sch 8 & 9'!B28 -> -973032 | C19: Less: Spent during the year | D19: =PL!C19+'Sch 8 & 9'!D25+'Sch 8 & 9'!D28 -> -1063146
B20: =-PL!E30 -> 99607 | C20: Add: Int. acc./recd during the year | D20: =PL!G30 -> 104952 | E20: =SUM(D17:D20) -> 1400379.1 | G20: =E20-'Sch 1'!M19 -> -458183.91 | H20: FD Excess
A22: 4 | C22: Education Training Fund
B23: 22702 | C23: As per last year BS | D23: =SUM(B23:B26) -> 31955
B24: 7560 | C24: Add: Collection during the year | D24: 7560
B25: =-PL!E31 -> 1693 | C25: Add: Int. acc./recd during the year | D25: =PL!G31 -> 2854
B26: 0 | C26: Less : Expenses incurred during the year | D26: 0 | E26: =SUM(D23:D26) -> 42369 | G26: =E26-'Sch 1'!M36 -> 26254 | H26: FD Short
C28: Common Amenities Fund
B29: 225218 | C29: As per last year BS | D29: =SUM(B29:B30) -> 241875
B30: =-PL!E32 -> 16657 | C30: Add: Int. acc./recd during the year | D30: =PL!G32 -> 17733 | E30: =SUM(D29:D30) -> 259608 | G30: =E30-'Sch 1'!M40 -> 3460 | H30: FD Short
B32: =SUM(B4:B31) -> 3977417.1 | C32: TOTAL | E32: =SUM(E4:E31) -> 4575563.1
E34: =E32-D8 -> 4392698.1

Sheet Sch 8 & 9
A1: =BS!A1 -> JEEVAN HEIGHTS CO-OPERATIVE HOUSING SOCIETY LTD
A3: Schedule 8 : R & M Expenses for the year ended March 31, 2026
A4: Sr. No | B4: ='Sch 4,6'!B4 -> FY 2024-25 | C4: Expenses | D4: ='Sch 4,6'!D4 -> FY 2025-26
A5: 1 | B5: =11341+3875 -> 15216 | C5: Repair and Maintenance Lift | D5: =11562 -> 11562
A6: 2 | B6: =6000+20000 -> 26000 | C6: Water Tank Cleaning Expenses | D6: =15000 -> 15000
A7: 3 | B7: 71483 | C7: Water Pump Repair Charges | D7: 0
A8: 5 | B8: 8800 | C8: AC Repair and Maintenance | D8: 0
A9: 6 | B9: 850 | C9: Repair and Maintenance Gym | D9: =8357 -> 8357
A10: 7 | B10: =72508+599 -> 73107 | C10: Repair and Maintenance Electrical | D10: =195877 -> 195877
A11: 8 | B11: =118471+9089 -> 127560 | C11: Other Repair Maintenance | D11: =93777 -> 93777
A12: 9 | B12: 61370 | C12: Repair and Maintenance Plumbing | D12: =26880 -> 26880
A13: 10 | B13: 2450 | C13: Repair and Maintenance (Intercom/CCTV) | D13: =29581+1314+1000 -> 31895
A14: 11 | B14: =28407+5000 -> 33407 | C14: DG Set Repair and Maintenance Expenses | D14: 4750
A15: 12 | B15: 0 | C15: Fire Fighting System Repairs and Maintenance | D15: 36800
B16: =SUM(B5:B15) -> 420243 | C16: Total (a) | D16: =SUM(D5:D15) -> 424898
A18: AMC Expenses for the year ended March 31, 2026
A19: Sr. No | B19: =B4 -> FY 2024-25 | C19: Expenses | D19: =D4 -> FY 2025-26
A20: 1 | B20: 6444 | C20: AMC - AC | D20: =Workings!D16 -> 5011
A21: 2 | B21: 10738 | C21: AMC - Gym Equipment | D21: =Workings!D21 -> 11250
A22: 3 | B22: 14442 | C22: AMC - Intercom | D22: =Workings!D26 -> 18310
A24: 4 | B24: =129885 -> 129885 | C24: AMC - Fire Fighting System | D24: =Workings!D67 -> 132000
B25: =-B24 -> -129885 | C25: Less: Trfd to Repair Fund | D25: =-D24 -> -132000
A27: 5 | B27: =186702 -> 186702 | C27: AMC - Stack Parking | D27: =Workings!D98 -> 232407
B28: =-B27 -> -186702 | C28: Less: Trfd to Repair Fund | D28: =-D27 -> -232407
A30: 6 | B30: =23625*2 -> 47250 | C30: AMC - CCTV | D30: =23625*2 -> 47250
A31: 7 | B31: =25000 -> 25000 | C31: AMC - DG | D31: =Workings!D43 -> 26000
B32: =SUM(B20:B31) -> 103874 | C32: Total (b) | D32: =SUM(D20:D31) -> 107821
B34: =B16+B32 -> 524117 | C34: Total ( C) | D34: =D16+D32 -> 532719

Sheet BRS
B1: =BS!A1 -> JEEVAN HEIGHTS CO-OPERATIVE HOUSING SOCIETY LTD
A3: ICICI Bank Reconciliation Statement as at March 31, 2026 | F3: Sr | G3: Vendor | H3: Issue Date | I3: Instr No. | J3: Outflow | K3: Inflow | L3: Clearing Date | O3: Amount cleared by the bank but not entered in the system
F4: 1 | G4: Shree Dev Super Market | H4: 26.03.2026 | I4: 1086 | J4: 880 | K4: 0 | L4: 13.04.2026 | N4: Sr. No. | O4: Date | P4: Deposit | Q4: Issued | R4: Instr.no | S4: Remarks
A5: FY 2024-25 | B5: Particulars | D5: FY 2025-26 | F5: 2 | G5: Vision Fire & Safety Engineers | H5: 28.03.2026 | I5: 1090 | J5: 24360 | K5: 0 | L5: 03.04.2026 | N5: 1 | O5: 09.04.2024 | P5: 2950 | R5: DDD2292856
N6: 2 | O6: 23.07.2024 | Q6: 15000 | R6: 420516260238 | S6: 15th Aug Catering
A7: 922186.04 | B7: Closing book balance (as per system) | D7: =866516.04 -> 866516.04 | N7: 3 | O7: 13.08.2024 | Q7: 10000 | R7: 422616257456 | S7: Sadhan Catering
N8: 4 | O8: 20.08.2024 | Q8: 28000 | R8: 423311708126 | S8: Sadhan Catering
A9: 125013 | B9: Add: | C9: Cheques issued and presented for payment | D9: =J11 -> 25240 | N9: 5 | O9: 22-08-2024 | Q9: 6151 | R9: 423519916224 | S9: Garage Bag
C10: but not cleared | N10: 6 | O10: 10.09.2024 | Q10: 7000 | R10: 425419583184
J11: =SUM(J4:J10) -> 25240 | K11: =SUM(K4:K10) -> 0 | N11: 7 | O11: 10.09.2024 | Q11: 11000 | R11: 425419606720
A12: 0 | B12: Less: | C12: Cheques collected and deposited but not | D12: =-K11 -> 0 | N12: 8 | O12: 01.10.2024 | Q12: 40000 | R12: 427519911428 | S12: MMT/IMPS/427519911428/GANPATIDECOR/NIAHANT/BARB0MA
C13: cleared | N13: 9 | O13: 10.10.2024 | P13: 29500 | R13: 037909985891 | S13: INF/INFT/037909985891/43253953/MUMBAI SPACER
N14: 10 | O14: 12.10.2024 | Q14: 7800 | R14: 428619230968 | S14: MMT/IMPS/428619230968/WAFFELDUSSERA/WAFFELPRIY/BKI
A15: =SUM(A7:A14) -> 1047199 | B15: Closing bank balance (as per bank) | D15: =SUM(D7:D14) -> 891756.04 | N15: 11 | O15: 18.10.2024 | Q15: 25000 | R15: 429221038015 | S15: MMT/IMPS/429221038015/NAVRATRICATERIN/KAJALCATER/C
N16: 12 | O16: 14.11.2024 | Q16: 110000 | R16: 196013007647 | S16: Funding
N17: 13 | O17: 26.12.2024 | P17: 5900 | R17: 047422 | S17: Vipul
A18: Union Bank Reconciliation Statement as at March 31, 2026 | N18: 14 | O18: 27.01.25 | Q18: 20800 | R18: 502710621242 | S18: Sudhakar do
N19: 15 | O19: 27.01.25 | Q19: 1 | R19: 502709532027 | S19: IMPS
A20: =A5 -> FY 2024-25 | B20: Particulars | D20: =D5 -> FY 2025-26 | N20: 16 | O20: 06.03.2025 | Q20: 4670 | R20: 506509096201 | S20: Holigulal
N21: 17 | O21: 06.03.2025 | Q21: 2500 | R21: 506509095408 | S21: virendra
A22: 55753.28 | B22: Closing book balance (as per system) | D22: 57533.28
A24: 0 | B24: Add: | C24: Cheques issued and presented for payment | D24: =J26 -> 0
C25: but not cleared
A27: 0 | B27: Less: | C27: Cheques collected and deposited but not | D27: -352
C28: cleared
A30: =SUM(A22:A29) -> 55753.28 | B30: Closing bank balance (as per bank) | D30: =SUM(D22:D29) -> 57181.28
A32: MDCC Bank Reconciliation Statement as at March 31, 2026
A34: =A5 -> FY 2024-25 | B34: Particulars | D34: =D5 -> FY 2025-26
A36: 54399 | B36: Closing book balance (as per system) | D36: 6956
A38: 0 | B38: Add: | C38: Cheques issued and presented for payment | D38: =J40 -> 0
C39: but not cleared
A41: 0 | B41: Less: | C41: Cheques collected and deposited but not | D41: 0
C42: cleared
A44: =SUM(A36:A43) -> 54399 | B44: Closing bank balance (as per bank) | D44: =SUM(D36:D43) -> 6956

Sheet Workings
A2: Sr. No. | B2: Particulars | C2: Days/ Months | D2: Amount | G2: Unclaimed ITC | N2: Quarter | O2: Vendor | P2: Invoice No | Q2: Invoice/Posted Date | R2: SGST | S2: CGST | T2: Total Tax | U2: ITC Rule 42/43 | V2: Trfd to Respective | X2: Sum of Trfd to Respective | Y2: Column Labels
G3: Vendor | H3: Date | I3: Basic | J3: CGST | K3: SGST | L3: Total Tax | M3: Total | N3: 1 | O3: HITACHI LIFT INDIA PRIVATE LIMITED | P3: MT2725260014 | Q3: 17/04/2025 | R3: 6632.2 | S3: 6632.2 | T3: =SUM(R3:S3) -> 13264.4 | U3: =100%-16.04% -> 0.8396 | V3: =ROUND(T3*U3,0) -> 11137 | X3: Row Labels | Y3: 1 | Z3: 2 | AA3: 3 | AB3: 4 | AC3: Grand Total
A4: 1 | B4: Water Expenses | G4: Bajaj Allianz | H4: 30-07-2024 | I4: =ROUND(J4*100/9,) -> 75450 | J4: =L4/2 -> 6790.5 | K4: =L4/2 -> 6790.5 | L4: 13581 | M4: =I4+L4 -> 89031 | N4: 1 | O4: RAM RATNA INFRASTRUCTURE PVT LTD | P4: 272511000575 | Q4: 23/06/2025 | R4: 4341.49 | S4: 4341.49 | T4: =SUM(R4:S4) -> 8682.98 | U4: =100%-16.04% -> 0.8396 | V4: =ROUND(T4*U4,0) -> 7290 | X4: HITACHI LIFT INDIA PRIVATE LIMITED | Y4: 22274 | Z4: 22240 | AB4: 47044 | AC4: 91558
B5: 06.01.2025 to 07.07.2025 | C5: =25+28+31+30+31+30+7 -> 182 | D5: =80694 -> 80694 | G5: Manoj Electricals | H5: 03-04-2024 | I5: =ROUND(J5*100/9,) -> 3500 | J5: =L5/2 -> 315 | K5: =L5/2 -> 315 | L5: =630 -> 630 | M5: =I5+L5 -> 4130 | N5: 1 | O5: RAM RATNA INFRASTRUCTURE PVT LTD | P5: 272511000017 | Q5: 08/04/2025 | R5: 4341.49 | S5: 4341.49 | T5: =SUM(R5:S5) -> 8682.98 | U5: =100%-16.04% -> 0.8396 | V5: =ROUND(T5*U5,0) -> 7290 | X5: RAM RATNA INFRASTRUCTURE PVT LTD | Y5: 14580 | Z5: 7279 | AA5: 7602 | AB5: 7551 | AC5: 37012
A6: Less: | B6: 07.01.2025 to 31.03.2025 | C6: =-(25+28+31) -> -84 | D6: -42992 | G6: Manoj Electricals | H6: 05-08-2024 | I6: =ROUND(J6*100/9,) -> 4528 | J6: =L6/2 -> 407.5 | K6: =L6/2 -> 407.5 | L6: 815 | M6: =I6+L6 -> 5343 | N6: 1 | O6: HITACHI LIFT INDIA PRIVATE LIMITED | P6: MT2725260052 | Q6: 16/05/2025 | R6: 6632.2 | S6: 6632.2 | T6: =SUM(R6:S6) -> 13264.4 | U6: =100%-16.04% -> 0.8396 | V6: =ROUND(T6*U6,0) -> 11137 | X6: Grand Total | Y6: 36854 | Z6: 29519 | AA6: 7602 | AB6: 54595 | AC6: 128570
B7: 01.04.2025 to 07.07.2025 | C7: =SUM(C5:C6) -> 98 | D7: =SUM(D5:D6) -> 37702 | G7: Manoj Electricals | H7: 01-12-2024 | I7: =ROUND(J7*100/9,) -> 7928 | J7: =L7/2 -> 713.5 | K7: =L7/2 -> 713.5 | L7: 1427 | M7: =I7+L7 -> 9355 | N7: 2 | O7: HITACHI LIFT INDIA PRIVATE LIMITED | P7: MT2725260199 | Q7: 13/08/2025 | R7: 6632.2 | S7: 6632.2 | T7: =SUM(R7:S7) -> 13264.4 | U7: =100%-16.17% -> 0.8383 | V7: =ROUND(T7*U7,0) -> 11120
A8: Add: | B8: 08.08.2025 to 31.03.2026 | C8: =24+31+30+31+30+31+31+28+31 -> 267 | D8: =ROUND(C8*D7/C7,0) -> 102719 | E8: Provision | G8: HVT Interiors | H8: 31-03-2025 | I8: =ROUND(J8*100/6,) -> 46500 | J8: =L8/2 -> 2790 | K8: =L8/2 -> 2790 | L8: 5580 | M8: =I8+L8 -> 52080 | N8: 2 | O8: HITACHI LIFT INDIA PRIVATE LIMITED | P8: MT2725260136 | Q8: 09/07/2025 | R8: 6632.2 | S8: 6632.2 | T8: =SUM(R8:S8) -> 13264.4 | U8: =100%-16.17% -> 0.8383 | V8: =ROUND(T8*U8,0) -> 11120
B9: 01.04.2025 to 31.03.2026 | C9: =SUM(C7:C8) -> 365 | D9: =SUM(D7:D8) -> 140421 | I9: =SUM(I4:I8) -> 137906 | J9: =SUM(J4:J8) -> 11016.5 | K9: =SUM(K4:K8) -> 11016.5 | L9: =SUM(L4:L8) -> 22033 | M9: =SUM(M4:M8) -> 159939 | N9: 2 | O9: RAM RATNA INFRASTRUCTURE PVT LTD | P9: 272511001269 | Q9: 20/09/2025 | R9: 4341.49 | S9: 4341.49 | T9: =SUM(R9:S9) -> 8682.98 | U9: =100%-16.17% -> 0.8383 | V9: =ROUND(T9*U9,0) -> 7279
N10: 3 | O10: RAM RATNA INFRASTRUCTURE PVT LTD | P10: 272511002065 | Q10: 29/12/2025 | R10: 4558.84 | S10: 4558.84 | T10: =SUM(R10:S10) -> 9117.68 | U10: =100%-16.62% -> 0.8338 | V10: =ROUND(T10*U10,0) -> 7602
N11: 4 | O11: HITACHI LIFT INDIA PRIVATE LIMITED | P11: MT2725260412 | Q11: 14/01/2026 | R11: 14200.88 | S11: 14200.88 | T11: =SUM(R11:S11) -> 28401.76 | U11: =100%-17.18% -> 0.8282 | V11: =ROUND(T11*U11,0) -> 23522
A12: 2 | B12: AC AMC | G12: Account No. | I12: Deposit | N12: 4 | O12: RAM RATNA INFRASTRUCTURE PVT LTD | P12: 272511002686 | Q12: 20/03/2026 | R12: 4558.84 | S12: 4558.84 | T12: =SUM(R12:S12) -> 9117.68 | U12: =100%-17.18% -> 0.8282 | V12: =ROUND(T12*U12,0) -> 7551
B13: 01.04.2025 to 31.12.2025 | C13: 9 | D13: 4011 | G13: 153245551 | I13: 92562.72 | N13: 4 | O13: HITACHI LIFT INDIA PRIVATE LIMITED | P13: MT2725260480 | Q13: 06/02/2026 | R13: 14200.88 | S13: 14200.88 | T13: =SUM(R13:S13) -> 28401.76 | U13: =100%-17.18% -> 0.8282 | V13: =ROUND(T13*U13,0) -> 23522
B14: 01.02.2026 to 31.01.2027 | C14: 12 | D14: 6000 | T14: =SUM(T3:T13) -> 154145.42 | V14: =SUM(V3:V13) -> 128570
A15: Less: | B15: 01.04.2026 to 31.01.2027 | C15: -10 | D15: =ROUND(D14*C15/C14,0) -> -5000 | E15: Prepaid | G15: 153243268 | I15: 0
B16: 01.04.2025 to 31.03.2026 | C16: =SUM(C13:C15) -> 11 | D16: =SUM(D13:D15) -> 5011 | I16: =SUM(I13:I15) -> 92562.72
I17: 73765
A18: 3 | B18: Gym Equipment AMC | I18: =I16-I17 -> 18797.72
B19: 01.07.2025 to 31.03.2026 | C19: 9 | D19: 11250
C20: 0 | D20: 0
C21: =SUM(C19:C20) -> 9 | D21: =SUM(D19:D20) -> 11250
N22: Sr.No | O22: Name of Committee Members/ Invitees | P22: Flat No | Q22: Designation
A23: 4 | B23: Intercom AMC Exp | N23: 1 | O23: Mr. Rakesh Mehta | P23: 2902 | Q23: Chairman
B24: 01.04.2025 to 09.07.2025 | C24: =(30+31+30+9) -> 100 | D24: 4110 | N24: 2 | O24: Mr. Ankit kanakia | P24: 2602 | Q24: Secretary
B25: 01.08.2025 to 31.03.2026 | C25: 8 | D25: =12000+2200 -> 14200 | N25: 3 | O25: Mr. Vinod Bhatia | P25: 3302 | Q25: Treasurer
B26: 01.04.2025 to 31.03.2026 | C26: =SUM(C24:C25) -> 108 | D26: =SUM(D24:D25) -> 18310 | N26: 4 | O26: Mr. Prashant Shah | P26: 3202 | Q26: MC Member
N27: 5 | O27: Smt Anjani Parekh | P27: 1502 | Q27: MC Member
A28: 5 | B28: Insurance Expenses | N28: 6 | O28: Mrs. Rajashri Shah | P28: 1701 | Q28: MC Member
B29: 01.04.2025 to 22.05.2025 | C29: =30+22 -> 52 | D29: 10749 | N29: 7 | O29: Mr. Jinkal Shah | P29: 3102 | Q29: MC Member
B30: 30.07.2025 to 29.07.2026 | C30: 365 | D30: =84960 -> 84960 | N30: 8 | O30: Mr. Vipul kapasi | P30: 3002 | Q30: MC Member
A31: Less: | B31: 01.04.2026 to 29.07.2026 | C31: =-(30+31+30+29) -> -120 | D31: =ROUND(D30*C31/C30,0) -> -27932 | E31: Prepaid
B32: 01.04.2025 to 31.03.2026 | C32: =SUM(C29:C31) -> 297 | D32: =SUM(D29:D31) -> 67777
A34: 6 | B34: Pest Control AMC
B35: 01.04.2025 to 30.06.2025 | C35: 3 | D35: =14071+240 -> 14311
B36: 01.07.2025 to 30.06.2026 | C36: 12 | D36: 27285
A37: Less: | B37: 01.04.2026 to 30.06.2026 | C37: -3 | D37: =ROUND(D36*C37/C36,0) -> -6821 | E37: Prepaid
B38: 01.04.2025 to 31.03.2026 | C38: =SUM(C35:C37) -> 12 | D38: =SUM(D35:D37) -> 34775
A40: 7 | B40: DG Set AMC
B41: 01.04.2025 to 30.09.2025 | C41: 6 | D41: 15000
A42: Add: | B42: 01.10.2025 to 31.03.2026 | C42: 6 | D42: 11000 | E42: Provision
B43: 01.04.2025 to 31.03.2026 | C43: =SUM(C41:C42) -> 12 | D43: =SUM(D41:D42) -> 26000
...

Sheet Fd int Working
A1: FD No | B1: Int | C1: TDS | D1: Acc | E1: Type
A2: 5669 | B2: 11 | C2: 0 | D2: =+B2-C2 -> 11 | E2: Sweep | L2: Income Tax | N2: Old Regime | P2: New Regime
A3: 5669 | B3: 9 | C3: 0 | D3: =+B3-C3 -> 9 | E3: Sweep | L3: Income from Savings A/c. | N3: 2245 | P3: 2245
A4: 5669 | B4: 25 | C4: 0 | D4: =+B4-C4 -> 25 | E4: Sweep | L4: Income from FD & Sweep | N4: 186979 | P4: 186979
A5: 5669 | B5: 8 | C5: 0 | D5: =+B5-C5 -> 8 | E5: Sweep | L5: Scrap Sales & Promotional | N5: 25001.7 | P5: 25001.7
A6: 4076 | B6: 16995 | C6: 0 | D6: =+B6-C6 -> 16995 | E6: RF | L6: Net Taxable Income | N6: =SUM(N3:N5) -> 214225.7 | P6: =SUM(P3:P5) -> 214225.7
A7: 4075 | B7: 5670 | C7: 0 | D7: =+B7-C7 -> 5670 | E7: SF | L7: 0-10000 | M7: 0.1 | N7: 1000
A8: 5097 | B8: 12831 | C8: 0 | D8: =+B8-C8 -> 12831 | E8: SF | L8: 10000-20000 | M8: 0.2 | N8: 2000
A9: 6861 | B9: 287 | C9: 0 | D9: =+B9-C9 -> 287 | E9: SF | L9: 20000 or More | M9: 0.3 | N9: 58268 | O9: 0.22 | P9: 47130
A10: 3673 | B10: 21568 | C10: 5741 | D10: =+B10-C10 -> 15827 | E10: SF | L10: Tax | N10: =SUM(N7:N9) -> 61268 | P10: =SUM(P7:P9) -> 47130
A11: 6860 | B11: 168 | C11: 17 | D11: =+B11-C11 -> 151 | E11: RF | L11: Surcharge | M11: 0.1 | N11: 0 | P11: =ROUND(P10*10%,0) -> 4713
A12: 5098 | B12: 8456 | C12: 845 | D12: =+B12-C12 -> 7611 | E12: GF | N12: =SUM(N10:N11) -> 61268 | P12: =SUM(P10:P11) -> 51843
A13: 6862 | B13: 271 | C13: 27 | D13: =+B13-C13 -> 244 | E13: GF | L13: Education cess | M13: 0.04 | N13: =ROUND(N12*4%,0) -> 2451 | O13: 0.04 | P13: =ROUND(P12*4%,0) -> 2074
A14: 4077 | B14: 5670 | C14: 567 | D14: =+B14-C14 -> 5103 | E14: SF | L14: Total Tax | N14: =SUM(N12:N13) -> 63719 | P14: =SUM(P12:P13) -> 53917
A15: 6864 | B15: 218 | C15: 22 | D15: =+B15-C15 -> 196 | E15: CA Fund | L15: Say | N15: =ROUND(N14,-1) -> 63720 | P15: =ROUND(P14,-1) -> 53920
A16: 4078 | B16: 16995 | C16: 1700 | D16: =+B16-C16 -> 15295 | E16: GF | K16: Less: | L16: TDS Receivables | N16: 18698 | P16: 18698
A17: 5107 | B17: 7292 | C17: 729 | D17: =+B17-C17 -> 6563 | E17: GF | K17: Less: | L17: Advance Taxes paid | N17: 32800 | P17: 32800
A18: 6863 | B18: 22 | C18: 2 | D18: =+B18-C18 -> 20 | E18: Edu | N18: =SUM(N16:N17) -> 51498 | P18: =SUM(P16:P17) -> 51498
A19: 5108 | B19: 7292 | C19: 729 | D19: =+B19-C19 -> 6563 | E19: GF | L19: Net Payable/ (Refund) | N19: =N15-N18 -> 12222 | P19: =P15-P18 -> 2422
A20: 5669 | B20: 17785 | C20: 1779 | D20: =+B20-C20 -> 16006 | E20: Sweep
A21: 2984 | B21: 30 | C21: 3 | D21: =+B21-C21 -> 27 | E21: SC
A22: 405 | B22: 65376 | C22: 6537 | D22: =+B22-C22 -> 58839 | E22: RF
A23: Total | B23: =SUM(B2:B22) -> 186979 | C23: =SUM(C2:C22) -> 18698 | D23: =SUM(D2:D22) -> 168281
