Workbook

Sheet BS
A1: WADHWA CO-OP. HOUSING SOCIETY LTD.
A2: Regd. No. BOM / HSG / 1848 dated 04.10.1968
A3: Vijay Bhavan, 68, St. Sebastian Road, Bandra (West), Mumbai - 400050
A4: Balance Sheet as at 31st March 2026
H5: (Amt. in Rs.)
A6: March 31, 2025 | B6: Liabilities | D6: March 31, 2026 | E6: =A6 -> March 31, 2025 | F6: Assets | H6: =D6 -> March 31, 2026
B7: Authorised Share Capital | F7: Cash & Bank Balance
A8: 725000 | B8: (14,500 Shares of Rs.50/- each) | D8: 725000 | E8: 3243 | F8: Union Bank A/c. 79923 | G8: ='Bank Reco'!E4 -> 3421
B9: Issued, Subscribed and Paid Up | E9: 8149.22 | F9: Union Bank A/c. 79931 | G9: ='Bank Reco'!E14 -> 8599.22
A10: =5500+6000 -> 11500 | B10: 230 Shares of Rs.50/- each | D10: 11500 | E10: 25106.7 | F10: Maharashtra State Co-op Bank | G10: ='Bank Reco'!E38 -> 25885.7
B11: (21 Individuals and 1 corporate) | E11: 7892.7 | F11: Citizen Credit Co-op Bank | G11: ='Bank Reco'!E24 -> 172952.3 | H11: =SUM(G8:G11) -> 210858.22
B12: General Reserve & Other Funds
A13: 165020 | B13: Bal as per last Balance Sheet | C13: =SUM(A13:A19) -> 209355 | F13: Investments & Deposits
A14: 100 | B14: Nomination Fees | C14: 0 | E14: 1000 | F14: Share of MSCB Ltd. | G14: 1000 | I14: =SUM(BS!G223876) -> 0
A15: 400 | B15: Entrance Fees | C15: 0 | E15: 100 | F15: Share with MDHF | G15: 100
A16: 1500 | B16: Share Transfer Fees | C16: 0 | E16: 1033588 | F16: Fixed Deposits (as per schedule I ) | G16: ='Sch I - FD'!D39 -> 1126072
A17: 25000 | B17: Transfer Premium | C17: 0 | E17: 61770 | F17: Accrued Interest on Investment | G17: ='Sch I - FD'!E39+'Sch I - FD'!F39+'Sch I - FD'!G39 -> 46383 | H17: =SUM(G14:G17) -> 1173555
A18: 0 | B18: 25% surplus trfd to General Reserve | C18: ='I&E'!D42 -> 10697
A19: 17335 | B19: Add: Interest received during the year | C19: =-'I&E'!G22 -> 18265 | D19: =SUM(C13:C19) -> 238317 | E19: 4580 | F19: Deposit - Tata Power | G19: 5800
B20: Sinking Fund | E20: 3890 | F20: Security Deposit with BSES | G20: 3890 | H20: =G19+G20 -> 9690
A21: 1047105.3 | B21: Bal as per last Balance Sheet | C21: =SUM(A21:A23) -> 1109884.3
A22: 10152 | B22: Add: Additions during the year | C22: 10152
A23: 52627 | B23: Add: Interest received during the year | C23: =-'I&E'!G23 -> 54444 | D23: =SUM(C21:C23) -> 1174480.3 | F23: Sundry Debtors
B24: Repair Fund | E24: 0 | F24: Member Receivables - Sch - II | H24: ='Sch II & III - Mem. Rec & Adv'!E7 -> 153
A25: 533666 | B25: Bal as per last Balance Sheet | C25: =SUM(A25:A27) -> 559367
A26: 21168 | B26: Add: Additions during the year | C26: 21168 | E26: 489853.6 | F26: Fixed Assets | H26: ='Fixed assest'!I14 -> 477258.6
A27: 4533 | B27: Add: Interest received during the year | C27: =-'I&E'!G26 -> 4859 | D27: =SUM(C25:C27) -> 585394
B28: Painting Fund | E28: 12904 | F28: TDS receivable | H28: 26273
A29: 14058 | B29: Bal as per last Balance Sheet | C29: =SUM(A29:A30) -> 15773
A30: 1715 | B30: Add: Interest received during the year | C30: =-'I&E'!G24 -> 1827 | D30: =SUM(C29:C30) -> 17600 | F30: Income & Expenditure A/c
B31: Education & Training Fund | E31: 631436.25 | F31: Retained Earnings | G31: =SUM(E31:E35) -> 714558.05
A32: 18480 | B32: As per last year Balance Sheet | C32: =SUM(A32:A34) -> 22613 | E32: 0 | F32: Add: 50% Penalty Waived Off | G32: 0
A33: 2640 | B33: Add: Additions during the year | C33: 2640 | E33: 0 | F33: Less: Excess provision written back | G33: 0
A34: 1493 | B34: Add: Interest received during the year | C34: =-'I&E'!G25 -> 1566 | D34: =SUM(C32:C34) -> 26819 | E34: 0 | F34: Less: Diff in interest of prior period | G34: 0
E35: 83121.8 | F35: Less: Income over Expenditure | G35: =-'I&E'!D43 -> -32091.6 | H35: =SUM(G31:G35) -> 682466.45
B36: Contribution from Members Towards
A37: 408812 | B37: Cost of Building | D37: 408812
B39: Current liabilities
A40: 7357 | B40: Advance Members - Sch III | C40: ='Sch II & III - Mem. Rec & Adv'!E16 -> 719
A41: 15814 | B41: Payables/ Provisions - Sch V | C41: ='Sch IV & V - Adv & Prov'!C24 -> 110453 | D41: =SUM(C40:C41) -> 111172
...

Sheet I&E
A1: =BS!A1 -> WADHWA CO-OP. HOUSING SOCIETY LTD.
A2: =BS!A2 -> Regd. No. BOM / HSG / 1848 dated 04.10.1968
A3: =BS!A3 -> Vijay Bhavan, 68, St. Sebastian Road, Bandra (West), Mumbai - 400050
A4: Income and Expenditure Account for the year ended March 31, 2026
H5: =BS!H5 -> (Amt. in Rs.)
A6: =BS!A6 -> March 31, 2025 | B6: Expenditure | D6: =BS!D6 -> March 31, 2026 | E6: =A6 -> March 31, 2025 | F6: Income | H6: =D6 -> March 31, 2026
A7: 41242 | B7: To Electricity Expenses | D7: 43878 | F7: By Maintenance Income
E8: 29040 | F8: Common Electricity Charges | G8: 29040
B9: To Property Tax | E9: 50952 | F9: Water Charges | G9: 50952
A10: 1988 | B10: Property Tax | D10: 2542 | E10: 1848 | F10: Property Tax | G10: 1848
B11: To Water Expenses | E11: 365376 | F11: Service Charges | G11: 502392
A12: 44580 | B12: Water Expenses | C12: 74762 | E12: 1792 | F12: Non Occupancy Charges | G12: 2416
A13: 7500 | B13: Water Tank Cleaning Expenses | C13: 3500 | D13: =SUM(C12:C13) -> 78262 | E13: 12000 | F13: Other charges | G13: 0
B14: To Repair & Maintenance | E14: 1708 | F14: Late Payment Interest | G14: 1621
A15: 18000 | B15: Garden Maintenance | C15: 15000 | E15: 6528 | F15: Insurance Charges | G15: 6528
A16: 18975 | B16: Other R & M Expenses | C16: 4390 | E16: 18300 | F16: 4W Parking Charges | G16: 39000
A17: 4590 | B17: Electrical R & M Expenses | C17: 1100 | E17: 37200 | F17: 2W Parking Charges | G17: 19950 | H17: =SUM(G8:G17) -> 653747
A18: 12590 | B18: Plumbing R & M Expenses | C18: 20880
A19: 11000 | B19: CCTV Repair & Maintenance | C19: =6000+6000 -> 12000 | D19: =SUM(C15:C19) -> 53370 | F19: By Interest Income
B20: To Service Charges | E20: 3796 | F20: Interest Income - Savings Account | G20: 4219
A21: 222000 | B21: Security Expenses | C21: =18000*12 -> 216000 | E21: 78631 | F21: Interest Income - Fixed Deposit | G21: =66846+15088 -> 81934
A22: 43800 | B22: Sweeper Salary | C22: 45100 | E22: -17335 | F22: Less: Trfd to General Fund | G22: -18265
A23: 12812 | B23: Depreciation on Fixed Assets | C23: ='Fixed assest'!H14 -> 12595 | E23: -52627 | F23: Less: Trfd to Sinking Fund | G23: -54444
A24: 2800 | B24: Insurance Expenses | C24: 3200 | E24: -1715 | F24: Less: Trfd to Painting Fund | G24: -1827
A25: 0 | B25: House Keeping Expenses | C25: 1335 | E25: -1493 | F25: Less: Trfd to Educ. & Trng Fund | G25: -1566
A26: 826 | B26: Subscription Federation | C26: 826 | E26: -4533 | F26: Less: Trfd to Repair Fund | G26: -4859 | H26: =SUM(G20:G26) -> 5192
A27: 2200 | B27: Audit Fees | C27: 2800 | D27: =SUM(C21:C27) -> 281856
B28: To Office Expenses | E28: 0 | F28: Miscelleneous Income | H28: 8532
A29: 97500 | B29: Manager Salary | C29: =8500*12 -> 102000
A30: 17000 | B30: Bonus | C30: 12000
A31: 16000 | B31: Accounting Charges | C31: 16000 | E31: =A44-SUM(E7:E27) -> 83121.8 | F31: By Excess of Expenditure over Income | H31: 0
A32: 5813 | B32: Printing & Stationery | C32: 1527
A33: 6000 | B33: Conveyance Charges | C33: 11000
A34: 500 | B34: Postage & Courier | C34: 0
A35: 4775 | B35: Meeting Expenses | C35: 5170
A36: 13667 | B36: Pest Control & Fogging Charges | C36: 3500
A37: 1380 | B37: Misc. Expenses | C37: 9365
A38: 1051.8 | B38: Bank charges | C38: 212.4
A39: 4000 | B39: Legal & Professional Fees | C39: =1500+2500 -> 4000
A40: 0 | B40: Income Tax Expenses | C40: 0 | D40: =SUM(C29:C40) -> 164774.4
...

Sheet Sch I - FD
B1: WADHWA CO-OP HOUSING SOCIETY LIMITED.
B2: Schedule - I
B3: Details of Fixed Deposits as on 31st March 2026
B4: Certificate No. | C4: Date | D4: Amount Invested | E4: Accrued Int 23-24 | F4: Accrued Int 24-25 | G4: Accrued Int 25-26 | H4: Total | I4: Maturity Date | J4: Maturity Value | K4: Interest % | L4: Bank
B5: Sinking Fund
B6: 6100017/5 | C6: 30.08.2025 | D6: 94457 | E6: 0 | F6: 0 | G6: =4681-936 -> 3745 | H6: =D6+E6+F6+G6 -> 98202 | I6: 30.08.2026 | J6: 100550 | K6: 0.063 | L6: MSC | N6: 181939
B7: 6100019/5 | C7: 30.08.2025 | D7: 59517 | E7: 0 | F7: 0 | G7: =2950-590 -> 2360 | H7: =D7+E7+F7+G7 -> 61877 | I7: 30.08.2026 | J7: 63356 | K7: 0.063 | L7: MSC | N7: 2033
B8: 6100018/5 | C8: 30.08.2025 | D8: 108636 | E8: 0 | F8: 0 | G8: =5385-1077 -> 4308 | H8: =D8+E8+F8+G8 -> 112944 | I8: 30.08.2026 | J8: 115643 | K8: 0.063 | L8: MSC | O8: 160745
B9: 6100020/5 | C9: 30.08.2025 | D9: 95307 | E9: 0 | F9: 0 | G9: =4723-945 -> 3778 | H9: =D9+E9+F9+G9 -> 99085 | I9: 30.08.2026 | J9: 101455 | K9: 0.063 | L9: MSC | O9: 10386
B10: 6500076 | C10: 27.03.2026 | D10: 338952 | E10: 0 | F10: 0 | G10: =6422-1284 -> 5138 | H10: =D10+E10+F10+G10 -> 344090 | I10: 27.03.2028 | J10: 379950 | K10: 0.0575 | L10: MSC | O10: 10167
B11: 2244/6601030 | C11: 21.03.2025 | D11: 10152 | E11: 0 | F11: =24-5 -> 19 | G11: =812-163 -> 649 | H11: =D11+E11+F11+G11 -> 10820 | I11: 21.02.2028 | J11: 12721 | K11: 0.078 | L11: MSC | O11: 2674
B12: 1000553 | C12: 01.06.2023 | D12: 46102 | E12: =256+811+825+840 -> 2732 | F12: 3510 | G12: 3761 | H12: =D12+E12+F12+G12 -> 56105 | I12: 01.06.2026 | J12: 56772 | K12: 0.07 | L12: CIT | N12: =SUM(N6:N11) -> 183972 | O12: =SUM(O8:O11) -> 183972 | P12: =N12-O12 -> 0
B13: TOTAL:- | D13: =SUM(D6:D12) -> 753123 | E13: =SUM(E6:E12) -> 2732 | F13: =SUM(F6:F12) -> 3529 | G13: =SUM(G6:G12) -> 23739 | H13: =SUM(H6:H12) -> 783123 | J13: =SUM(J6:J12) -> 830447
B15: Painting Fund
B16: 310425_R10 | C16: 19.03.2026 | D16: 17790 | E16: 0 | F16: 0 | G16: 34 | H16: =D16+E16+F16+G16 -> 17824 | I16: 19.03.2027 | J16: 18854 | K16: 0.0585 | L16: CIT
B17: 310426_R10 | C17: 19.03.2026 | D17: 9556 | E17: 0 | F17: 0 | G17: 18 | H17: =D17+E17+F17+G17 -> 9574 | I17: 19.03.2027 | J17: 10127 | K17: 0.0585 | L17: CIT
B18: TOTAL:- | D18: =SUM(D16:D17) -> 27346 | E18: =SUM(E16:E17) -> 0 | F18: =SUM(F16:F17) -> 0 | G18: =SUM(G16:G17) -> 52 | H18: =SUM(H16:H17) -> 27398 | J18: =SUM(J16:J17) -> 28981
B20: General Fund
B21: 303472_R09 | C21: 20.03.2026 | D21: 17543 | E21: 0 | F21: 0 | G21: 32 | H21: =D21+E21+F21+G21 -> 17575 | I21: 20.03.2027 | J21: 18613 | K21: 0.071 | L21: CIT
B22: 303473_R09 | C22: 20.03.2026 | D22: 35088 | E22: 0 | F22: 0 | G22: 65 | H22: =D22+E22+F22+G22 -> 35153 | I22: 20.03.2027 | J22: 37228 | K22: 0.061 | L22: CIT
B23: 303474_R09 | C23: 20.03.2026 | D23: 17543 | E23: 0 | F23: 0 | G23: 32 | H23: =D23+E23+F23+G23 -> 17575 | I23: 20.03.2027 | J23: 18613 | K23: 0.061 | L23: CIT
B24: 6500079/1 | C24: 28.03.2026 | D24: 181939 | E24: 0 | F24: 0 | G24: =3457-691 -> 2766 | H24: =D24+E24+F24+G24 -> 184705 | I24: 28.03.2028 | J24: 203945 | K24: 0.0575 | L24: MSC
B25: TOTAL:- | D25: =SUM(D21:D24) -> 252113 | E25: =SUM(E21:E24) -> 0 | F25: =SUM(F21:F24) -> 0 | G25: =SUM(G21:G24) -> 2895 | H25: =SUM(H21:H24) -> 255008 | J25: =SUM(J21:J24) -> 278399
B27: Repair Fund
B28: 1000565 | C28: 01.06.2023 | D28: 59560 | E28: =331+1048+1066+1085 -> 3530 | F28: 4533 | G28: 4859 | H28: =D28+E28+F28+G28 -> 72482 | I28: 01.06.2026 | J28: 73345 | K28: 0.07 | L28: CIT
B29: TOTAL:- | D29: =SUM(D28) -> 59560 | E29: =SUM(E28) -> 3530 | F29: =SUM(F28) -> 4533 | G29: =SUM(G28) -> 4859 | H29: =SUM(H28) -> 72482 | J29: =SUM(J28) -> 73345
B31: Education Fund
B32: 6500078/1 | C32: 28.03.2026 | D32: 20917 | E32: 0 | F32: 0 | G32: =397-79 -> 318 | H32: =D32+E32+F32+G32 -> 21235 | I32: 28.03.2028 | J32: 23447 | K32: 0.0575 | L32: MSC
B33: TOTAL:- | D33: =SUM(D32) -> 20917 | E33: =SUM(E32) -> 0 | F33: =SUM(F32) -> 0 | G33: =SUM(G32) -> 318 | H33: =SUM(H32) -> 21235 | J33: =SUM(J32) -> 23447
B35: Share Capital
B36: 6500077/1 | C36: 28.03.2026 | D36: 13013 | E36: 0 | F36: 0 | G36: =246-50 -> 196 | H36: =D36+E36+F36+G36 -> 13209 | I36: 28.03.2028 | J36: 14587 | K36: 0.0575 | L36: MSC
B37: TOTAL:- | D37: =SUM(D36) -> 13013 | E37: =SUM(E36) -> 0 | F37: =SUM(F36) -> 0 | G37: =SUM(G36) -> 196 | H37: =SUM(H36) -> 13209 | J37: =SUM(J36) -> 14587
B39: GRAND TOTAL:- | D39: =D13+D18+D25+D29+D33+D37 -> 1126072 | E39: =E13+E18+E25+E29+E33+E37 -> 6262 | F39: =F13+F18+F25+F29+F33+F37 -> 8062 | G39: =G13+G18+G25+G29+G33+G37 -> 32059 | H39: =H25+H18+H13+H29+H33+H37 -> 1172455 | J39: =J25+J18+J13+J29+J33+J37 -> 1249206

Sheet Sch II & III - Mem. Rec & Adv
A1: WADHWA CO-OP HOUSING SOCIETY LIMITED.
A2: SCHEDULE - II
A3: Members Receivable as on 31.03.2026
A5: Sl.No | B5: Block | C5: Flat No. | D5: Name of the Members | E5: Amount (Rs.)
A6: 1 | B6: B | C6: 03 | D6: Mr. Sunil John Macwan | E6: 153
A7: Total | E7: =SUM(E6:E6) -> 153
A9: SCHEDULE - III
A10: Members Advance as on 31.03.2026
A12: Sl.No | B12: Block | C12: Flat No. | D12: Name of the Members | E12: Amount (Rs.)
A13: 1 | B13: B | C13: 08 | D13: Mr. Shakir G Baig | E13: 416
A14: 2 | B14: B | C14: 13 | D14: Mr. Rizwan Rashid Khan | E14: 3
A15: 3 | B15: B | C15: 15 | D15: Mrs. Pratibha Agale & Mr. Vijay Agale | E15: 300
A16: Total | E16: =SUM(E13:E15) -> 719
C18: SCHEDULE - V
C19: Provisions as on 31.03.2026
E20: (Amt. in Rs.)
C21: FY 24-25 | D21: Particulars | E21: FY 25-26
C22: 2200 | D22: Audit Fee Payable | E22: 2500
C23: 1650 | D23: Water Charges Payable | E23: 4140
C24: 1500 | D24: Professional Fees Payable | E24: 2500
C25: 3868 | D25: Income Tax Payable | E25: =3900-32 -> 3868
C26: =SUM(C22:C25) -> 9218 | D26: Total | E26: =SUM(E22:E25) -> 13008
C28: Payables as on 31.03.2026
C29: FY 24-25 | D29: Particulars | E29: FY 25-26
C30: 2174 | D30: Apartment Management Services | E30: =3674-1500 -> 2174
C31: 3800 | D31: Sweeper | E31: 3800
C32: 622 | D32: Tata Power | E32: 3701
C33: 0 | D33: Santan Electrical | E33: 5880
C34: 0 | D34: Watchman | E34: 20000
C35: 0 | D35: Fracis Rebello | E35: 9000
C36: 0 | D36: MCGM | E36: 52890
C37: =SUM(C30:C36) -> 6596 | D37: Total | E37: =SUM(E30:E36) -> 97445
C39: =C26+C37 -> 15814 | D39: Total | E39: =E26+E37 -> 110453

Sheet Fixed assest
A2: WADHWA CO-OP HOUSING SOCIETY LIMITED.
A3: : Details of Fixed Assets as at March 31, 2026
I4: (Amt. in Rs.)
A5: Sr.No. | B5: Assets | C5: Rate % | D5: Cost as on 01.04.2025 | E5: Additions on or before 30.09.2025 | F5: Additions after 30.09.2025 | G5: Gross Block (as Cost) as on 31.03.2026 | H5: Depreciation for the year | I5: Net Block as on 31.03.2026
A6: 1 | B6: Building | C6: 0 | D6: 401812 | E6: 0 | F6: 0 | G6: =+D6+E6+F6 -> 401812 | H6: =ROUND((D6+E6+(F6/2))*C6,) -> 0 | I6: =+G6-H6 -> 401812
A7: 2 | B7: Compound Patty | C7: 0.15 | D7: 10919.6 | E7: 0 | F7: 0 | G7: =+D7+E7+F7 -> 10919.6 | H7: =ROUND((D7+E7+(F7/2))*C7,) -> 1638 | I7: =+G7-H7 -> 9281.6
A8: 3 | B8: Compound Gate | C8: 0.15 | D8: 103 | E8: 0 | F8: 0 | G8: =+D8+E8+F8 -> 103 | H8: =ROUND((D8+E8+(F8/2))*C8,) -> 15 | I8: =+G8-H8 -> 88
A9: 4 | B9: Furniture and Fixtures | C9: 0.1 | D9: 1034 | E9: 0 | F9: 0 | G9: =+D9+E9+F9 -> 1034 | H9: =ROUND((D9+E9+(F9/2))*C9,) -> 103 | I9: =+G9-H9 -> 931
A10: 5 | B10: Terrace Gate Grills | C10: 0.15 | D10: 79 | E10: 0 | F10: 0 | G10: =+D10+E10+F10 -> 79 | H10: =ROUND((D10+E10+(F10/2))*C10,) -> 12 | I10: =+G10-H10 -> 67 | T10: =650*10% -> 65
A11: 6 | B11: Water Pump | C11: 0.15 | D11: 13732 | E11: 0 | F11: 0 | G11: =+D11+E11+F11 -> 13732 | H11: =ROUND((D11+E11+(F11/2))*C11,) -> 2060 | I11: =+G11-H11 -> 11672
A12: 7 | B12: Garden Bench | C12: 0.1 | D12: 11174 | E12: 0 | F12: 0 | G12: =+D12+E12+F12 -> 11174 | H12: =ROUND((D12+E12+(F12/2))*C12,) -> 1117 | I12: =+G12-H12 -> 10057
A13: 8 | B13: CCTV camera | C13: 0.15 | D13: 51000 | E13: 0 | F13: 0 | G13: =+D13+E13+F13 -> 51000 | H13: =ROUND((D13+E13+(F13/2))*C13,) -> 7650 | I13: =+G13-H13 -> 43350
B14: Total | D14: =SUM(D6:D13) -> 489853.6 | E14: =SUM(E6:E13) -> 0 | F14: =SUM(F6:F13) -> 0 | G14: =SUM(G6:G13) -> 489853.6 | H14: =SUM(H6:H13) -> 12595 | I14: =SUM(I6:I13) -> 477258.6

Sheet Sch IV & V  - Adv & Prov
A1: Wadhwa Co-op. Housing Society Ltd.
A3: SCHEDULE - V
A4: Provisions as on 31.03.2026
C5: (Amt. in Rs.)
A6: FY 24-25 | B6: Particulars | C6: FY 25-26
A7: 2200 | B7: Audit Fee Payable | C7: 2500
A8: 1650 | B8: Water Charges Payable | C8: =Workings!E9 -> 4140
A9: 1500 | B9: Professional Fees Payable | C9: 2500
A10: 3868 | B10: Income Tax Payable | C10: =3900-32 -> 3868
A11: =SUM(A7:A10) -> 9218 | B11: Total | C11: =SUM(C7:C10) -> 13008
A13: Payables as on 31.03.2026
A14: FY 24-25 | B14: Particulars | C14: FY 25-26
A15: 2174 | B15: Apartment Management Services | C15: =3674-1500 -> 2174
A16: 3800 | B16: Sweeper | C16: 3800
A17: 622 | B17: Tata Power | C17: 3701
A18: 0 | B18: Santan Electrical | C18: 5880
A19: 0 | B19: Watchman | C19: 20000
A20: 0 | B20: Fracis Rebello | C20: 9000
A21: 0 | B21: MCGM | C21: 52890
A22: =SUM(A15:A21) -> 6596 | B22: Total | C22: =SUM(C15:C21) -> 97445
A24: =A11+A22 -> 15814 | B24: Total | C24: =C11+C22 -> 110453

Sheet Bank Reco
B1: Wadhwa Chs Ltd.
B2: Corporation Bank (79923) Reconciliation Statement as on 31.03.2026
E3: Amount
B4: Balance as per system | E4: 3421
B6: Add: | C6: Cheque issued but not cleared | E6: 0
B8: Less : | C8: Cheque deposited but not cleared | E8: 0
B10: Balance as per Bank Pass Book | E10: =E4+E6-E8 -> 3421
B12: Corporation Bank (79931) Reconciliation Statement as on 31.03.2026
E13: Amount
B14: Balance as per system | E14: 8599.22
B16: Add: | C16: Cheque issued but not cleared | E16: 0
B18: Less : | C18: Cheque deposited but not cleared | E18: 0
B20: Balance as per Bank Pass Book | E20: =E14+E16-E18 -> 8599.22
B22: Citizen Credit Bank Reconciliation Statement as on 31.03.2026
E23: Amount
B24: Balance as per system | E24: =187952.3-15000 -> 172952.3
B26: Add: | C26: Cheque issued but not cleared
C27: Ref Annexure attached
B29: Less: | C29: Cheque issued and cleared but not updated | E29: 0
C30: Chq # 807014 - Santan dated 29.09.2025
B32: Less : | C32: Cheque deposited but not cleared | E32: 0
C33: Ref Annexure attached
B34: Balance as per Bank Pass Book | E34: =E24-E29-E32 -> 172952.3
B36: Maharashtra State Co-op Bank Reconciliation Statement as on 31.03.2026
E37: Amount
B38: Balance as per system | E38: 25885.7
B40: Add: | C40: Cheque issued but not cleared | E40: 0
B42: Less : | C42: Cheque deposited but not cleared | E42: 0
B44: Balance as per Bank Pass Book | E44: =E38+E40-E42 -> 25885.7

Sheet Workings
A1: *Working Sheet not to be printed for Balance Sheet
A3: 1 | B3: Water Expenses:
B4: 45724 | C4: 45817 | D4: =+C4-B4 -> 93 | E4: 14120
B5: =C4 -> 45817 | C5: 45909 | D5: =+C5-B5 -> 92 | E5: 15020
B6: =+C5 -> 45909 | C6: 46000 | D6: =+C6-B6 -> 91 | E6: 15252
B7: =+C6 -> 46000 | C7: 46090 | D7: =+C7-B7 -> 90 | E7: 21493
D8: =SUM(D4:D7) -> 366 | E8: =SUM(E4:E7) -> 65885
B9: =+C7 -> 46090 | C9: 46112 | D9: =+C9-B9+1 -> 23 | E9: =ROUND(D9*E8/D8,0) -> 4140 | F9: Provision

Sheet Queries
B1: 1. MSC bank has deducted 20% TDS and the renewed amount doesn’t match with the balance, hence we have taken the balance amount in Misc. Income.
B2: 2. CCTV AMC period & bill required
B3: 3. Miscelleneous expense breakup required dated 01.07.2025 & bills missing
B4: 4. Sweeper Sunny Lohat Dec 2025 how much Bonus is given? Mar 2026 salary voucher is missing
B5: 5. Tata Power Mar 2026 voucher missing.
B6: 6. Insurance period & bill required
B7: 7. Income tax payable will set off after checking it on IT portal.
B8: 8. Kindly refer Sch I - FD details required - maturity date, amount, ROI (FD copies if possible)
B9: 9. Santan Electrical Rs. 5880 is paid? or should we write it off.
