Workbook

Sheet BS
A1: PARK ROSE CO-OPERATIVE HOUSING SOCIETY LTD.
A2: ( Regd No : BOM/W-P/HSG/TC/4208/1974 DT. 11.06.1974 )
A3: DOMINIC COLONY ROAD NO. 2, ORLEM, MALAD (WEST), MUMBAI - 400064
A4: Balance Sheet as at 31st March 2026
H5: (Amt. in Rs.)
A6: March 31, 2025 | B6: LIABILITIES | D6: March 31, 2026 | E6: =A6 -> March 31, 2025 | F6: ASSETS | H6: =D6 -> March 31, 2026
B7: Authorised Share Capital | F7: Cash and Bank Balances:
A8: 100000 | B8: ( 2,000 Share of ₹ 50/- each ) | D8: 100000 | E8: 72 | F8: Cash Balance | G8: 1143
E9: 31330.73 | F9: Model Co-op Bank | G9: =BRS!D16 -> 12373.19
B10: Issues, Subscribed and Paid Up Share Capital | E10: 150063.77 | F10: Citizencredit Co-op Bank | G10: =BRS!D6 -> 89069.55 | H10: =SUM(G8:G10) -> 102585.74
A11: 17000 | B11: ( 340 Shares of ₹ 50/- each ) | D11: 17000
B12: Reserves and other Funds: | E12: 100 | F12: Share with MDCC Bank | H12: 100
B13: (i) General Reserve Fund
A14: 149173 | B14: As per last balance sheet | C14: 190162 | E14: 1368664 | F14: Fixed Deposits - Sch I | G14: ='Sch I - FD'!F41 -> 2353314
A15: 3700 | B15: Add: Member's contribution for the year | C15: =25000+500+200 -> 25700 | E15: 44076 | F15: Accrued Interest on FDRs with Bank | G15: ='Sch I - FD'!I41 -> 74689 | H15: =SUM(G12:G15) -> 2428003
A16: 7171 | B16: Add: Interest earned during the year | C16: =IE!G29 -> 9473
A17: 30118 | B17: ` | C17: =IE!D50 -> 42015 | D17: =SUM(C14:C17) -> 267350 | E17: 27.98 | F17: Member's Receivables - Sch III | H17: 0
B18: (ii) Sinking Fund
A19: 116623 | B19: As per last balance sheet | C19: =A19+A20+A21 -> 257478 | F19: Other Current Assets:
A20: 125856 | B20: Add: Member's contribution for the year | C20: 125856 | E20: 151098 | F20: Prepaid Expenses - Sch IV | G20: ='Sch II to IV - Vendors & Mem.'!D44 -> 156943
A21: 14999 | B21: Add: Interest earned during the year | C21: =IE!G25 -> 25739 | D21: =SUM(C19:C21) -> 409073 | E21: 7214 | F21: TDS Receivables FY 2024-25 | G21: =7214 -> 7214
B22: (iii) Repair Fund | E22: 0 | F22: TDS Receivables FY 2025-26 | G22: =10183 -> 10183
A23: 350534 | B23: As per last balance sheet | C23: =A23+A24+A25 -> 761795 | E23: 13210 | F23: Security Deposit with Adani Energy | G23: 13210 | H23: =SUM(G20:G23) -> 187550
A24: 377316 | B24: Add: Member's contribution for the year | C24: 377316
A25: 33945 | B25: Add: Interest earned during the year | C25: =IE!G26 -> 74672 | D25: =SUM(C23:C25) -> 1213783 | F25: Fixed Assets:
B26: (iv) Lift Repair Fund | E26: 5202 | F26: (i) CCTV Monitor: | G26: 5202
A27: 117524 | B27: As per last balance sheet | C27: =A27+A28+A29 -> 257538 | E27: 0 | F27: Add: Purchases during the year | G27: 0
A28: 125856 | B28: Add: Member's contribution for the year | C28: 125856 | E28: 0 | F28: Less: Depreciation @ 15% | G28: =ROUND((+G27+G26)*0.15,0) -> 780 | H28: =G26+G27-G28 -> 4422
A29: 14158 | B29: Add: Interest earned during the year | C29: =IE!G28 -> 15754 | D29: =SUM(C27:C29) -> 399148
B30: (v) Education Fund | E30: 23640 | F30: (ii) Terrace Fencing Cost: | G30: 23640
A31: 3747 | B31: As per last balance sheet | C31: =A31+A33+A34 -> 8100 | E31: 0 | F31: Add: Purchases during the year | G31: 0
A32: 0 | B32: Less: Spent During the year | C32: -8260 | E32: 0 | F32: Less: Depreciation @ 10% | G32: =ROUND((+G31+G30)*0.1,0) -> 2364 | H32: =G30+G31-G32 -> 21276
A33: 4080 | B33: Add: Member's contribution for the year | C33: 4080
A34: 273 | B34: Add: Interest earned during the year | C34: =IE!G27 -> 573 | D34: =SUM(C31:C34) -> 4493 | E34: 6480 | F34: (iii)Furniture & Fixtures | G34: 6480
E35: 0 | F35: Add: Purchases during the year | G35: 0
B36: Current Liabilities and Provisions: | E36: 0 | F36: Less: Depreciation @ 10% | G36: =ROUND((+G35+G34)*0.1,0) -> 648 | H36: =G34+G35-G36 -> 5832
A37: 25352 | B37: Vendor Payables - Sch II | C37: ='Sch II to IV - Vendors & Mem.'!D11 -> 33311
A38: 650 | B38: TDS Payable | C38: 0 | E38: 0 | F38: (iv)Fabricated Collapsible Security Gate | G38: 0
A39: 10000 | B39: Refundable Deposit - Flat No. 704 | C39: 10000 | E39: 0 | F39: Add: Purchases during the year | G39: 27500
A40: ='Sch II to IV - Vendors & Mem.'!B19 -> 12041 | B40: Provisions - Sch II | C40: ='Sch II to IV - Vendors & Mem.'!D19 -> 29450 | D40: =SUM(C37:C40) -> 72761 | E40: 0 | F40: Less: Depreciation @ 10% | G40: =ROUND((+G39+G38)*0.1,0) -> 2750 | H40: =G38+G39-G40 -> 24750
...

Sheet IE
A1: PARK ROSE CO-OPERATIVE HOUSING SOCIETY LTD.
A2: ( Regd No : BOM/W-P/HSG/TC/4208/1974 DT. 11.06.1974 )
A3: DOMINIC COLONY ROAD NO. 2, ORLEM, MALAD (WEST), MUMBAI - 400064
A4: Income and Expenditure Account for the year ended 31st March 2026
H5: (Amt. in Rs.)
A6: =BS!A6 -> March 31, 2025 | B6: EXPENDITURE | D6: =BS!D6 -> March 31, 2026 | E6: =A6 -> March 31, 2025 | F6: INCOME | H6: =D6 -> March 31, 2026
B7: To Property Related Expenses: | F7: By Maintenance Incomes :
A8: 27324 | B8: Property Taxes - Parking | C8: 30148 | E8: 27216 | F8: Property Tax Parking | G8: 27216
A9: 1032 | B9: Property Taxes - Common Area | C9: =1032 -> 1032 | E9: 1224 | F9: Property Tax Common Area | G9: 1224
A10: 190560 | B10: Electricity Expenses | C10: =205730 -> 205730 | E10: 179928 | F10: Electricity Charges | G10: =179928 -> 179928
A11: 67725 | B11: Water Expenses | C11: =Workings!D10 -> 68650 | E11: 75480 | F11: Water Charges | G11: =81600-6120 -> 75480
A12: 18588 | B12: Insurance Expense | C12: =Workings!D47 -> 19218 | D12: =SUM(C8:C12) -> 324778 | E12: 20040 | F12: Insurance Charges | G12: =27516-7476 -> 20040
B13: To Repairs & Maintenance: | E13: 212784 | F13: Parking Charges | G13: =207984+8000+200 -> 216184
A14: 5900 | B14: Water Tank Cleaning Expenses | C14: 0 | E14: 983246 | F14: Service Charges | G14: =34*12*2410 -> 983280
A15: 11600 | B15: R&M - Garden | C15: 0 | E15: 22130 | F15: Non Occupancy Charges | G15: 23940
A16: 0 | B16: R&M - CCTV | C16: 6000 | E16: 0 | F16: Other charges | G16: =8020+50 -> 8070
A17: 0 | B17: ` | C17: =1425+730 -> 2155 | E17: 357 | F17: Late Payment Interest | G17: 506 | H17: =SUM(G8:G17) -> 1535868
A18: 6160 | B18: R&M - Lifts | C18: 300
A19: 31535 | B19: R&M - Electrical | C19: =18346.76+2750 -> 21096.76 | F19: By Other Incomes from Members:
A20: 57555 | B20: R&M - Others | C20: =40335.24-1500 -> 38835.24 | E20: 5000 | F20: Shifting Charge | H20: =SUM(G20:G20) -> 0
A21: 7550 | B21: R&M - Plumbing | C21: 10500
A22: 6700 | B22: R&M - Fire Fighting | C22: 0 | F22: By Interest Incomes :
A23: 109647 | B23: AMC - Lift | C23: =Workings!D16 -> 119816 | E23: 6866 | F23: Interest - Savings Deposits | H23: 8000
A24: =6344+6678 -> 13022 | B24: AMC - CCTV and Intercom | C24: =Workings!D22+Workings!D40 -> 12237 | E24: 72051 | F24: Interest - Fixed Deposits | G24: =101736+26448 -> 128184
A25: 35700 | B25: AMC - Fire Fighting Sytem | C25: =Workings!D28 -> 14744 | E25: -14999 | F25: Less: trf to Sinking Fund | G25: =25739 -> 25739
A26: 64412 | B26: AMC - Stack Parking | C26: =Workings!D34 -> 74336 | D26: =SUM(C14:C26) -> 300020 | E26: -33945 | F26: Less: trf to Repair Fund | G26: =74672 -> 74672
B27: To Service Charges: | E27: -273 | F27: Less: trf to Education Fund | G27: =573 -> 573
A28: 300000 | B28: Security Expenses | C28: =305000+5000 -> 310000 | E28: -14158 | F28: Less: trf to Lift Repair Fund | G28: =15754 -> 15754
A29: 93200 | B29: Housekeeping Expenses | C29: =86000+8000 -> 94000 | E29: -7171 | F29: Less: trf to Reserve Fund | G29: =9473 -> 9473 | H29: =G24-SUM(G25:G29) -> 1973
A30: 6363 | B30: Housekeeping Materials | C30: 3682
A31: 120000 | B31: Stack-Parking Staff Salary | C31: 115500 | F31: By Other Incomes
A32: 23288 | B32: Pest Control Expenses | C32: 22488 | D32: =SUM(C28:C32) -> 545670 | E32: 451 | F32: Misc. Incomes | H32: =SUM(G32:G32) -> 0
B33: To Administrative Expenses:
A34: 4265 | B34: Depreciation | C34: =BS!G28+BS!G32+BS!G36+BS!G40+BS!G44 -> 6542
A35: 120000 | B35: Salaries Expense | C35: 120000
A36: 36000 | B36: Accounting Charges | C36: 39600
A37: 3400 | B37: Audit Fees | C37: 3400
A38: 826 | B38: Federation Subscription | C38: 826
A39: 6705 | B39: Printing and Stationery | C39: 2328
A40: 8323 | B40: Meeting Expense | C40: 8024
...

Sheet Sch I - FD
B1: PARK ROSE CO-OPERATIVE HOUSING SOCIETY LTD
A2: ( Regd No : BOM/W-P/HSG/TC/4208/1974 DT. 11.06.1974 )
A3: Schedule I : Details of Fixed Deposits as at March 31, 2026 | U3: 4998 | V3: Extra
L4: (Amt. in Rs.)
A5: Sr. | B5: Certificate No. | C5: Int | D5: Bank | E5: Date of Issue | F5: Amount Deposited | G5: Accrued Int for FY 24-25 | H5: Accrued Int for FY 25-26 | I5: Total Accrued Int | J5: Total Amt | K5: Maturity Date | L5: Maturity Value
B6: Share Capital FD
A7: 1 | B7: 1010431002233 | C7: 0.061 | D7: Citizen | E7: 24.03.2026 | F7: 17000 | G7: 0 | H7: 0 | I7: =SUM(G7:H7) -> 0 | J7: =F7+I7 -> 17000 | K7: 24.03.2027 | L7: 17000 | P7: =18099 -> 18099 | Q7: =18130 -> 18130 | R7: =Q7-P7 -> 31 | S7: =ROUND(R7/90%,0) -> 34 | T7: =S7-R7 -> 3
F8: =SUM(F7) -> 17000 | G8: =SUM(G7) -> 0 | H8: =SUM(H7) -> 0 | I8: =SUM(I7) -> 0 | J8: =SUM(J7) -> 17000 | L8: =SUM(L7) -> 17000 | S8: =1221-S7 -> 1187 | T8: =T7-124 -> -121 | V8: 6992 | W8: 701
B9: Sinking Fund FD | V9: =V8-W21 -> 1154 | W9: =W8-V17 -> 117 | X9: =V9-W9 -> 1037
A10: 2 | B10: 101043101002934/2 | C10: 0.06 | D10: Citizen | E10: 12.12.2025 | F10: 85162 | G10: 0 | H10: =1548-157 -> 1391 | I10: =SUM(G10:H10) -> 1391 | J10: =F10+I10 -> 86553 | K10: 12.12.2026 | L10: 90388 | P10: 80004 | Q10: 81530 | R10: =Q10-P10 -> 1526 | S10: =ROUND(R10/90%,0) -> 1696 | T10: =S10-R10 -> 170
A11: 3 | B11: 101043101003739/1 | C11: 0.0585 | D11: Citizen | E11: 18.01.2026 | F11: 45393 | G11: 0 | H11: =533-50 -> 483 | I11: =SUM(G11:H11) -> 483 | J11: =F11+I11 -> 45876 | K11: 18.01.2027 | L11: 48107 | S11: =5490-S10 -> 3794 | T11: =T10-550 -> -380
A12: 4 | B12: 101043031003664/1 | C12: 0.066 | D12: Citizen | E12: 04.07.2025 | F12: 134058 | G12: 0 | H12: =6522-648 -> 5874 | I12: =SUM(G12:H12) -> 5874 | J12: =F12+I12 -> 139932 | K12: 04.07.2026 | L12: 142906
A13: 5 | B13: 163971 | C13: 0.0725 | D13: Model | E13: 10.09.2025 | F13: 126000 | G13: 0 | H13: 5180 | I13: =SUM(G13:H13) -> 5180 | J13: =F13+I13 -> 131180 | K13: 10.09.2026 | L13: 135386
F14: =SUM(F10:F13) -> 390613 | G14: =SUM(G10:G13) -> 0 | H14: =SUM(H10:H13) -> 12928 | I14: =SUM(I10:I13) -> 12928 | J14: =SUM(J10:J13) -> 403541 | L14: =SUM(L10:L13) -> 416787
B15: Repair Fund FD | X15: Accru.
A16: 6 | B16: 101043101004292/2 | C16: 0.0585 | D16: Citizen | E16: 21.03.2026 | F16: 136004 | G16: 0 | H16: =221-25 -> 196 | I16: =SUM(G16:H16) -> 196 | J16: =F16+I16 -> 136200 | K16: 21.03.2027 | L16: 144136 | P16: 127766 | Q16: 127986 | R16: =Q16-P16 -> 220 | S16: =ROUND(R16/90%,0) -> 244 | T16: =S16-R16 -> 24 | V16: 106388 | X16: =Y16-V16 -> 1037 | Y16: 107425
A17: 7 | B17: ` | C17: 0.061 | D17: Citizen | E17: 01.12.2025 | F17: =256700 -> 256700 | G17: 0 | H17: =5220-524 -> 4696 | I17: =SUM(G17:H17) -> 4696 | J17: =F17+I17 -> 261396 | K17: 01.12.2027 | L17: 289741 | S17: =8617-S16 -> 8373 | T17: =861-T16 -> 837 | V17: 584
A18: 8 | B18: 101043101006109 | C18: 0.0725 | D18: Citizen | E18: 27.11.2024 | F18: 277000 | G18: =6946-696 -> 6250 | H18: =21044-2106 -> 18938 | I18: =SUM(G18:H18) -> 25188 | J18: =F18+I18 -> 302188 | K18: 27.10.2027 | L18: 341592 | W18: 100000
A19: 9 | B19: 101043031005079/1 | C19: 0.061 | D19: Citizen | E19: 27.01.2026 | F19: 106388 | G19: 0 | H19: =1154-117 -> 1037 | I19: =SUM(G19:H19) -> 1037 | J19: =F19+I19 -> 107425 | K19: 27.01.2026 | L19: 112878 | W19: 1134
A20: 10 | B20: 163734 | C20: 0.0725 | D20: Model | E20: 08.07.2025 | F20: 377000 | G20: 0 | H20: 20233 | I20: =SUM(G20:H20) -> 20233 | J20: =F20+I20 -> 397233 | K20: 08.07.2026 | L20: 405085
F21: =SUM(F16:F20) -> 1153092 | G21: =SUM(G16:G20) -> 6250 | H21: =SUM(H16:H20) -> 45100 | I21: =SUM(I16:I20) -> 51350 | J21: =SUM(J16:J20) -> 1204442 | L21: =SUM(L16:L20) -> 1293432 | W21: 5838
B22: Education Fund FD
A23: 11 | B23: 156876 | C23: 0.0685 | D23: Model | E23: 25.02.2026 | F23: 4100 | G23: 0 | H23: 27 | I23: =SUM(G23:H23) -> 27 | J23: =F23+I23 -> 4127 | K23: 25.02.2027 | L23: 4388
F24: =SUM(F23:F23) -> 4100 | G24: =SUM(G23:G23) -> 0 | H24: =SUM(H23:H23) -> 27 | I24: =SUM(I23:I23) -> 27 | J24: =SUM(J23:J23) -> 4127 | L24: =SUM(L23:L23) -> 4388 | S24: =263-#REF! -> #REF! | T24: =28-#REF! -> #REF! | X24: =#REF!/90% -> #REF!
B25: Lift Repair Fund FD
A26: 12 | B26: 101043101002923/2 | C26: 0.06 | D26: Citizen | E26: 12.12.2025 | F26: 85162 | G26: 0 | H26: =1548-157 -> 1391 | I26: =SUM(G26:H26) -> 1391 | J26: =F26+I26 -> 86553 | K26: 12.12.2026 | L26: 90388
A27: 13 | B27: 10143031003865/1 | C27: 0.0635 | D27: Citizen | E27: 06.08.2025 | F27: 132988 | G27: 0 | H27: =5481-550 -> 4931 | I27: =SUM(G27:H27) -> 4931 | J27: =F27+I27 -> 137919 | K27: 06.08.2026 | L27: 141433
A28: 14 | B28: 101043101003729/2 | C28: 0.0585 | D28: Citizen | E28: 18.01.2026 | F28: 45393 | G28: 0 | H28: =533-50 -> 483 | I28: =SUM(G28:H28) -> 483 | J28: =F28+I28 -> 45876 | K28: 18.01.2027 | L28: 48107 | P28: =42640 -> 42640 | Q28: =43183 -> 43183 | R28: =Q28-P28 -> 543 | S28: =ROUND(R28/90%,0) -> 603 | T28: =S28-R28 -> 60
A29: 15 | B29: 101043031007357 | C29: 0.0625 | D29: Citizen | E29: 13.01.2026 | F29: 126000 | G29: 0 | H29: =1701-171 -> 1530 | I29: =SUM(G29:H29) -> 1530 | J29: =F29+I29 -> 127530 | K29: 13.01.2027 | L29: 133875
F30: =SUM(F26:F29) -> 389543 | G30: =SUM(G26:G29) -> 0 | H30: =SUM(H26:H29) -> 8335 | I30: =SUM(I26:I29) -> 8335 | J30: =SUM(J26:J29) -> 397878 | L30: =SUM(L26:L29) -> 413803 | S30: =2907-S28 -> 2304 | T30: =290-T28 -> 230
B31: Reserve Fund FD
A32: 16 | B32: 101043101004522/2 | C32: 0.0558 | D32: Citizen | E32: 28.03.2026 | F32: 113321 | G32: 0 | H32: =55-7 -> 48 | I32: =SUM(G32:H32) -> 48 | J32: =F32+I32 -> 113369 | K32: 28.03.2027 | L32: 120097 | P32: 106456 | Q32: 106510 | R32: =Q32-P32 -> 54 | S32: =ROUND(R32/90%,0) -> 60 | T32: =S32-R32 -> 6
A33: 17 | B33: 101043021004998 | C33: 0.0625 | D33: Citizen | E33: 16.09.2025 | F33: 25000 | G33: 0 | H33: =842-87 -> 755 | I33: =SUM(G33:H33) -> 755 | J33: =F33+I33 -> 25755 | K33: 16.09.2026 | L33: 26563
A34: 18 | B34: 156982 | C34: 0.0685 | D34: Model | E34: 23.03.2026 | F34: 130000 | G34: 0 | H34: 220 | I34: =SUM(G34:H34) -> 220 | J34: =F34+I34 -> 130220 | K34: 23.03.2027 | L34: 139136
A35: 19 | B35: 156877 | C35: 0.0685 | D35: Model | E35: 25.02.2026 | F35: 120000 | G35: 0 | H35: 788 | I35: =SUM(G35:H35) -> 788 | J35: =F35+I35 -> 120788 | K35: 25.02.2027 | L35: 128434
F36: =SUM(F32:F35) -> 388321 | G36: =SUM(G32:G35) -> 0 | H36: =SUM(H32:H35) -> 1811 | I36: =SUM(I32:I35) -> 1811 | J36: =SUM(J32:J35) -> 390132 | L36: =SUM(L32:L35) -> 414230 | S36: =7171-S32 -> 7111 | T36: =719-T32 -> 713
B37: Security Deposit FD
A38: 20 | B38: 101043031004566/1 | C38: 0.0625 | D38: Citizen | E38: 07.11.2025 | F38: 10645 | G38: 0 | H38: =258-20 -> 238 | I38: =SUM(G38:H38) -> 238 | J38: =F38+I38 -> 10883 | K38: 07.11.2026 | L38: 11310
F39: =SUM(F38) -> 10645 | G39: =SUM(G38) -> 0 | H39: =SUM(H38) -> 238 | I39: =SUM(I38) -> 238 | J39: =SUM(J38) -> 10883 | L39: =SUM(L38) -> 11310
B41: Total | F41: =SUM(F8,F14,F21,F24,F30,F36,F39) -> 2353314 | G41: =SUM(G8,G14,G21,G24,G30,G36,G39) -> 6250 | H41: =SUM(H8,H14,H21,H24,H30,H36,H39) -> 68439 | I41: =SUM(I8,I14,I21,I24,I30,I36,I39) -> 74689 | J41: =SUM(J8,J14,J21,J24,J30,J36,J39) -> 2428003 | L41: =SUM(L8,L14,L21,L24,L30,L36,L39) -> 2570950

Sheet Sch II to IV - Vendors & Mem.
A1: PARK ROSE CO-OPERATIVE HOUSING SOCIETY LTD
A2: ( Regd No : BOM/W-P/HSG/TC/4208/1974 DT. 11.06.1974 )
A3: Schedule II
A5: Vendor Payables as of 31st March 2026
A6: Sr | B6: FY 2024-25 | C6: Vendor Name | D6: FY 2025-26
A7: 1 | B7: 0 | C7: BMC Water Bill | D7: 17061
A8: 2 | B8: 102 | C8: Irene Rosario | D8: 0
A9: 3 | B9: 15250 | C9: Adani Electrcity | D9: =530+15720 -> 16250
A10: 4 | B10: 10000 | C10: Angad Singh | D10: 0
B11: =SUM(B7:B10) -> 25352 | C11: Total :- | D11: =SUM(D7:D10) -> 33311
A13: Provisions as of 31st March 2026
A14: Sr | B14: =B6 -> FY 2024-25 | C14: Expense Heads | D14: =D6 -> FY 2025-26
A15: 1 | B15: 3400 | C15: Audit Fee Payable | D15: 3400
A16: 2 | B16: 4561 | C16: Water Charges Payable | D16: =Workings!D9 -> 4890
A17: 3 | B17: ` | C17: Ex-Gratia to Security & HK Staff | D17: =5000+8000 -> 13000
A18: 4 | B18: 4080 | C18: Advance Locality Maintenance FY 2024-25 | D18: =4080*2 -> 8160
B19: =SUM(B15:B18) -> 12041 | C19: Total :- | D19: =SUM(D15:D18) -> 29450
A21: Schedule III
A24: Member's Advance Maintenance as of 31st March 2026
A25: Sr. | B25: Flat | C25: Member's Name | D25: Amount
A26: 1 | B26: 204 | C26: MRS. ANNA PEREIRA | D26: 5828
A27: 2 | B27: 301 | C27: MR. SHELDON JUDE FERNS & MRS. CHANTELLE OLIVE FERNS | D27: 14477
A28: 3 | B28: 504 | C28: MR.ALLEN DSOUZA & MRS. OLIVA D''SOUZA | D28: 11287
A29: 4 | B29: 705 | C29: MRS. RUMY BAVL | D29: 12376
A30: Total :- | D30: =SUM(D26:D29) -> 43968
A33: Schedule IV
A35: Prepaid Expenses as of 31st March 2026
A36: Sr | B36: FY 2024-25 | C36: Expense Head | D36: FY 2025-26 | E36: Period
A37: 1 | B37: 2844 | C37: Pest Control | D37: 0
A38: 2 | B38: 24477 | C38: Stack-Parking AMC | D38: =Workings!D33 -> 37113 | E38: 01.04.2026 to 25.09.2026
A39: 3 | B39: 8463 | C39: Fire-Fighting AMC | D39: =Workings!D27 -> 2269 | E39: 01.04.2026 to 28.04.2026
A40: 4 | B40: 3952 | C40: Intercom AMC | D40: =Workings!D21 -> 3373 | E40: 01.04.2026 to 14.11.2026
A41: 5 | B41: 79958 | C41: Lift AMC | D41: =Workings!D15 -> 93949 | E41: 01.04.2026 to 31.12.2026
A42: 6 | B42: 15251 | C42: Insurance Premium | D42: =Workings!D45 -> 16741 | E42: 01.04.2026 to 05.02.2027
A43: 7 | B43: 4098 | C43: CCTV AMC | D43: =Workings!D39 -> 3498 | E43: 01.04.2026 to 14.11.2026
B44: =SUM(B37:B43) -> 139043 | C44: Total :- | D44: =SUM(D37:D43) -> 156943

Sheet BRS
B2: PARK ROSE CO-OPERATIVE HOUSING SOCIETY LTD
F3: Sr. No. | G3: Posted Date | H3: Flat | I3: Instr No | J3: Debit | K3: Credit | L3: Reconciled Date
B4: Citizencredit Bank Reconciliation Statement as on 31st March 2026 | F4: 1 | G4: 46084 | H4: Abhay Rai | I4: 948491 | J4: 0 | K4: 5000
D5: Amount | F5: 2 | G5: 46105 | H5: Gulam Kadir | I5: 948498 | J5: 0 | K5: 5000 | L5: 46117
B6: Bank balance as per system (Book Balance) | D6: 89069.55 | F6: 3 | G6: 46109 | H6: Society123 Support Services Pvt Ltd | I6: 948503 | J6: 0 | K6: 3300 | L6: 46119
F7: 4 | G7: 46109 | H7: Anshuman Security Services | I7: 948501 | J7: 0 | K7: 34650 | L7: 46116
B8: Add: | C8: Cheques issued but not cleared | D8: =K12 -> 75303 | F8: 5 | G8: 46109 | H8: Asha - Housekeeping | I8: 948502 | J8: 0 | K8: 8000 | L8: 46115
F9: 6 | G9: 46109 | H9: Manager | I9: 948504 | J9: 0 | K9: 10000 | L9: 46114
B10: Less: | C10: Cheques deposited but not cleared | D10: =-J12 -> 0 | F10: 7 | G10: 46109 | H10: Ivan Rosario | I10: 948505 | J10: 0 | K10: 353 | L10: 46119
F11: 8 | G11: 46110 | H11: Unassigned | I11: 948500 | J11: 0 | K11: 9000 | L11: 46132
B12: Bank balance as per Passbook | D12: =SUM(D6:D11) -> 164372.55 | J12: =SUM(J4:J11) -> 0 | K12: =SUM(K4:K11) -> 75303
B14: Model Bank Reconciliation Statement as on 31st March 2026
D15: Amount
B16: Bank balance as per system (Book Balance) | D16: 12373.19
B18: Add: | C18: Chequed issued and presented but not cleared | D18: =K22 -> 0
B20: Less: | C20: Cheques deposited but not cleared | D20: =-J22 -> 0
B23: Bank balance as per Passbook | D23: =+D16+D18 -> 12373.19

Sheet Workings
A1: 1. Water expenses provisions
A2: 45723 | B2: 45813 | C2: =B2-A2 -> 90 | D2: 17105 | I2: 07.03.2025 to 05.06.2025 | J2: 90 | K2: 17105
A3: 45723 | B3: 45747 | C3: =B3-A3 -> 24 | D3: =ROUND(C3*D2/C2,0) -> 4561 | I3: 07.03.2025 to 31.03.2025 | J3: 24 | K3: =ROUND(J3*K2/J2,0) -> 4561
A4: 45748 | B4: 45813 | C4: =C2-C3 -> 66 | D4: =D2-D3 -> 12544
A5: =B4 -> 45813 | B5: 45904 | C5: =B5-A5 -> 91 | D5: 17029
A6: =B5 -> 45904 | B6: 45995 | C6: =B6-A6 -> 91 | D6: 17126
A7: =B6 -> 45995 | B7: 46086 | C7: =B7-A7 -> 91 | D7: 17061
C8: =C4+C5+C6+C7 -> 339 | D8: =D4+D5+D6+D7 -> 63760
A9: =B7 -> 46086 | B9: 46112 | C9: =B9-A9 -> 26 | D9: =ROUND(C9*D8/C8,0) -> 4890 | E9: Provision
C10: =C8+C9 -> 365 | D10: =D8+D9 -> 68650
A12: 2. Lift AMC
A13: 45748 | B13: 46022 | C13: =B13-A13+1 -> 275 | D13: 89069
A14: 46023 | B14: 46387 | C14: =B14-A14+1 -> 365 | D14: 124696
A15: 46113 | B15: 46387 | C15: =B15-A15+1 -> 275 | D15: =ROUND(C15*D14/C14,0) -> 93949 | E15: Prepaid
A16: 45748 | B16: 46112 | C16: =C13+C14-C15 -> 365 | D16: =D13+D14-D15 -> 119816
A18: 3. Intercom AMC
A19: 45748 | B19: 45975 | C19: =B19-A19+1 -> 228 | D19: 3980
A20: 45976 | B20: 46340 | C20: =B20-A20+1 -> 365 | D20: 5400
A21: 46113 | B21: 46340 | C21: =B21-A21+1 -> 228 | D21: =ROUND(C21*D20/C20,0) -> 3373 | E21: Prepaid
A22: 45748 | B22: 46112 | C22: =C19+C20-C21 -> 365 | D22: =D19+D20-D21 -> 6007
A24: 4. Fire Fighting AMC
A25: 45748 | B25: 45775 | C25: =B25-A25+1 -> 28 | D25: 2263
A26: 45959 | B26: 46140 | C26: =B26-A26+1 -> 182 | D26: 14750
A27: 46113 | B27: 46140 | C27: =B27-A27+1 -> 28 | D27: =ROUND(C27*D26/C26,0) -> 2269 | E27: Prepaid
A28: 45748 | B28: 46112 | C28: =C25+C26-C27 -> 182 | D28: =D25+D26-D27 -> 14744
A30: 5. Stack Parking AMC
A31: 45748 | B31: 45925 | C31: =B31-A31+1 -> 178 | D31: 35347
A32: 45926 | B32: 46290 | C32: =B32-A32+1 -> 365 | D32: 76102
A33: 46113 | B33: 46290 | C33: =B33-A33+1 -> 178 | D33: =ROUND(C33*D32/C32,0) -> 37113 | E33: Prepaid
A34: 45748 | B34: 46112 | C34: =C31+C32-C33 -> 365 | D34: =D31+D32-D33 -> 74336
A36: 6. CCTV AMC
A37: 45748 | B37: 45975 | C37: =B37-A37+1 -> 228 | D37: 4128
A38: 45976 | B38: 46340 | C38: =B38-A38+1 -> 365 | D38: =5600 -> 5600
A39: 46113 | B39: 46340 | C39: =B39-A39+1 -> 228 | D39: =ROUND(C39*D38/C38,0) -> 3498 | E39: Prepaid
A40: 45748 | B40: 46112 | C40: =C37+C38-C39 -> 365 | D40: =D37+D38-D39 -> 6230
A42: 7. Insurance Expenses
A43: 45748 | B43: 46050 | C43: =B43-A43+1 -> 303 | D43: 16311
A44: 46059 | B44: 46423 | C44: =B44-A44+1 -> 365 | D44: 19648
A45: 46113 | B45: 46423 | C45: =B45-A45+1 -> 311 | D45: =ROUND(C45*D44/C44,0) -> 16741 | E45: Prepaid
A46: 46059 | B46: 46112 | C46: =C44-C45 -> 54 | D46: =D44-D45 -> 2907
...

Sheet Interest on FD
A1: Park Rose CHS Ltd - Income - Non Members > Interest Income - Fixed Deposit ( 306002 ) <br/>Transactions From 01-04-2025 to 31-03-2026
A2: Journal No. | B2: Posted Date | C2: Comments | D2: Credit | E2: Fund | F2: Bank
A3: JE-2025-0000056 | B3: 04-07-2025 | C3: Being old FD 101043031003664 renewed vide new FD 101043031003664 1 SF CCB | D3: 2351 | E3: SF | F3: Citizen | H3: Sum of Credit | I3: Column Labels
A4: JE-2025-0000067 | B4: 08-07-2025 | C4: Being accrued interest on FD 163734 RMF Model | D4: 20233 | E4: RMF | F4: Model | H4: Row Labels | I4: Citizen | J4: Model | K4: Grand Total
A5: JE-2025-0000055 | B5: 06-08-2025 | C5: Being old FD 101043031003865 renewed vide new FD 101043031003865 1 SF CCB | D5: 3114 | E5: SF | F5: Citizen | H5: ETF | I5: 546 | J5: 27 | K5: 573
A6: JE-2025-0000068 | B6: 10-09-2025 | C6: Being accrued interest on FD 163971 SF Model | D6: 5180 | E6: SF | F6: Model | H6: GRF | I6: 8465 | J6: 1008 | K6: 9473
A7: JE-2025-0000057 | B7: 07-11-2025 | C7: Being old FD 101043031004566 renewed vide new FD 101043031004566 1 SDF CCB | D7: 433 | E7: SDF | F7: Citizen | H7: LRF | I7: 15754 | K7: 15754
A8: JE-2025-0000050 | B8: 01-12-2025 | C8: Being old FD 101043101002793 renewed vide new FD 101043101002793 1 RF CCB | D8: 12053 | E8: RMF | F8: Citizen | H8: RMF | I8: 54439 | J8: 20233 | K8: 74672
A9: JE-2025-0000051 | B9: 12-12-2025 | C9: Being old FD 101043101002934 1 renewed vide new FD 101043101002934 2 SF CCB | D9: 4035 | E9: SF | F9: Citizen | H9: SC | I9: 1282 | K9: 1282
A10: JE-2025-0000052 | B10: 12-12-2025 | C10: Being old FD 101043101002923 1 renewed vide new FD 101043101002923 2 LRF CCB | D10: 4035 | E10: LRF | F10: Citizen | H10: SDF | I10: 691 | K10: 691
A11: JE-2025-0000053 | B11: 18-01-2026 | C11: Being old FD 101043101003729 1 renewed vide new FD 101043101003729 2 LRF CCB | D11: 2456 | E11: LRF | F11: Citizen | H11: SF | I11: 20559 | J11: 5180 | K11: 25739
A12: JE-2025-0000054 | B12: 18-01-2026 | C12: Being old FD 101043101003739 1 renewed vide new FD 101043101003739 2 SF CCB | D12: 2456 | E12: SF | F12: Citizen | H12: Grand Total | I12: 101736 | J12: 26448 | K12: 128184
A13: JE-2025-0000063 | B13: 27-01-2026 | C13: Being old FD 101043031005079 renewed vide new FD 101043031005079 1 RMF CCB | D13: 5838 | E13: RMF | F13: Citizen
A14: JE-2025-0000065 | B14: 25-02-2026 | C14: Being accrued interest on FD 156877 GRF Model | D14: 788 | E14: GRF | F14: Model
A15: JE-2025-0000064 | B15: 25-02-2026 | C15: Being accrued interest on FD 156876 ETF Model | D15: 27 | E15: ETF | F15: Model
A16: JE-2025-0000059 | B16: 21-03-2026 | C16: Being old FD 101043101004292 1 renewed vide new FD 10104310100429 2 RMF CCB | D16: 8909 | E16: RMF | F16: Citizen
A17: JE-2025-0000066 | B17: 23-03-2026 | C17: Being accrued interest on FD 156982 GRF Model | D17: 220 | E17: GRF | F17: Model
A18: JE-2025-0000040 | B18: 23-03-2026 | C18: Being FD 101043021003929 redeemed on maturity - ETF CCB | D18: 276 | E18: ETF | F18: Citizen
A19: JE-2025-0000041 | B19: 23-03-2026 | C19: Being FD 101043021002118 redeemed on maturity - ETF CCB | D19: 270 | E19: ETF | F19: Citizen
A20: JE-2025-0000042 | B20: 24-03-2026 | C20: Being FD 101043101004287 redeemed on maturity - SC CCB | D20: 1262 | E20: SC | F20: Citizen
A21: JE-2025-0000060 | B21: 28-03-2026 | C21: Being old FD 101043101004522 1 renewed vide new FD 101043101004522 2 GRF CCB | D21: 7568 | E21: GRF | F21: Citizen
A22: JE-2025-0000088 | B22: 31-03-2026 | C22: Being accrued int. on FD 101043031004566 1 SDF CCB | D22: 258 | E22: SDF | F22: Citizen
A23: JE-2025-0000087 | B23: 31-03-2026 | C23: Being accrued int. on FD 101043021004998 GRF CCB | D23: 842 | E23: GRF | F23: Citizen
A24: JE-2025-0000086 | B24: 31-03-2026 | C24: Being accrued int. on FD 101043101004522 2 GRF CCB | D24: 55 | E24: GRF | F24: Citizen
... A36: JE-2025-0000039 | B36: 31-03-2026 | C36: Being interest on Fixed Deposit 101043041002233 SC CCB | D36: 20 | E36: SC | F36: Citizen

Sheet Sch I - FD (2)
B1: PARK ROSE CO-OPERATIVE HOUSING SOCIETY LTD
A2: ( Regd No : BOM/W-P/HSG/TC/4208/1974 DT. 11.06.1974 )
A3: Schedule I : Details of Fixed Deposits as at March 31, 2026
L4: (Amt. in Rs.)
A5: Sr. | B5: Certificate No. | C5: Int | D5: Bank | E5: Date of Issue | F5: Amount Deposited | G5: Accrued Int for FY 24-25 | H5: Accrued Int for FY 25-26 | I5: Total Accrued Int | J5: Total Amt | K5: Maturity Date | L5: Maturity Value | O5: Remark
A6: 1 | B6: 1010431002233 | C6: 0.061 | D6: Citizen | E6: 24.03.2026 | F6: 17000 | G6: 0 | H6: 0 | I6: =SUM(G6:H6) -> 0 | J6: =F6+I6 -> 17000 | K6: 24.03.2027 | L6: 17000 | O6: Share Cap
A7: 2 | B7: 101043101002934/2 | C7: 0.06 | D7: Citizen | E7: 12.12.2025 | F7: 85162 | G7: 0 | H7: =1548-157 -> 1391 | I7: =SUM(G7:H7) -> 1391 | J7: =F7+I7 -> 86553 | K7: 12.12.2026 | L7: 90388 | O7: Sinking Fund FD
A8: 3 | B8: 101043101003739/1 | C8: 0.0585 | D8: Citizen | E8: 18.01.2026 | F8: 45393 | G8: 0 | H8: =533-50 -> 483 | I8: =SUM(G8:H8) -> 483 | J8: =F8+I8 -> 45876 | K8: 18.01.2027 | L8: 48107 | O8: Sinking Fund FD
A9: 4 | B9: 101043031003664/1 | C9: 0.066 | D9: Citizen | E9: 04.07.2025 | F9: 134058 | G9: 0 | H9: =6522-648 -> 5874 | I9: =SUM(G9:H9) -> 5874 | J9: =F9+I9 -> 139932 | K9: 04.07.2026 | L9: 142906 | O9: Sinking Fund FD
A10: 5 | B10: 101043101004292/2 | C10: 0.0585 | D10: Citizen | E10: 21.03.2026 | F10: 136004 | G10: 0 | H10: =221-25 -> 196 | I10: =SUM(G10:H10) -> 196 | J10: =F10+I10 -> 136200 | K10: 21.03.2027 | L10: 144136 | O10: Repair Fund FD
A11: 6 | B11: 101043101002793/1 | C11: 0.061 | D11: Citizen | E11: 01.12.2025 | F11: =256700 -> 256700 | G11: 0 | H11: =5220-524 -> 4696 | I11: =SUM(G11:H11) -> 4696 | J11: =F11+I11 -> 261396 | K11: 01.12.2027 | L11: 289741 | O11: Repair Fund FD
A12: 7 | B12: 101043101006109 | C12: 0.0725 | D12: Citizen | E12: 27.11.2024 | F12: 277000 | G12: =6946-696 -> 6250 | H12: =21044-2106 -> 18938 | I12: =SUM(G12:H12) -> 25188 | J12: =F12+I12 -> 302188 | K12: 27.10.2027 | L12: 341592 | O12: Repair Fund FD
A13: 8 | B13: 101043031005079/1 | C13: 0.061 | D13: Citizen | E13: 27.01.2026 | F13: 106388 | G13: 0 | H13: =1154-117 -> 1037 | I13: =SUM(G13:H13) -> 1037 | J13: =F13+I13 -> 107425 | K13: 27.01.2026 | L13: 112878 | O13: Repair Fund FD
A14: 9 | B14: 101043101002923/2 | C14: 0.06 | D14: Citizen | E14: 12.12.2025 | F14: 85162 | G14: 0 | H14: =1548-157 -> 1391 | I14: =SUM(G14:H14) -> 1391 | J14: =F14+I14 -> 86553 | K14: 12.12.2026 | L14: 90388 | O14: Lift Repair Fund FD
A15: 10 | B15: 10143031003865/1 | C15: 0.0635 | D15: Citizen | E15: 06.08.2025 | F15: 132988 | G15: 0 | H15: =5481-550 -> 4931 | I15: =SUM(G15:H15) -> 4931 | J15: =F15+I15 -> 137919 | K15: 06.08.2026 | L15: 141433 | O15: Lift Repair Fund FD
A16: 11 | B16: 101043101003729/2 | C16: 0.0585 | D16: Citizen | E16: 18.01.2026 | F16: 45393 | G16: 0 | H16: =533-50 -> 483 | I16: =SUM(G16:H16) -> 483 | J16: =F16+I16 -> 45876 | K16: 18.01.2027 | L16: 48107 | O16: Lift Repair Fund FD
A17: 12 | B17: 101043031007357 | C17: 0.0625 | D17: Citizen | E17: 13.01.2026 | F17: 126000 | G17: 0 | H17: =1701-171 -> 1530 | I17: =SUM(G17:H17) -> 1530 | J17: =F17+I17 -> 127530 | K17: 13.01.2027 | L17: 133875 | O17: Lift Repair Fund FD
A18: 13 | B18: 101043101004522/2 | C18: 0.0558 | D18: Citizen | E18: 28.03.2026 | F18: 113321 | G18: 0 | H18: =55-7 -> 48 | I18: =SUM(G18:H18) -> 48 | J18: =F18+I18 -> 113369 | K18: 28.03.2027 | L18: 120097 | O18: Reserve Fund FD
A19: 14 | B19: 101043021004998 | C19: 0.0625 | D19: Citizen | E19: 16.09.2025 | F19: 25000 | G19: 0 | H19: =842-87 -> 755 | I19: =SUM(G19:H19) -> 755 | J19: =F19+I19 -> 25755 | K19: 16.09.2026 | L19: 26563 | O19: Reserve Fund FD
A20: 15 | B20: 101043031004566/1 | C20: 0.0625 | D20: Citizen | E20: 07.11.2025 | F20: 10645 | G20: 0 | H20: =258-20 -> 238 | I20: =SUM(G20:H20) -> 238 | J20: =F20+I20 -> 10883 | K20: 07.11.2026 | L20: 11310 | O20: Security Deposit FD
F21: =SUM(F6:F20) -> 1596214 | G21: =SUM(G6:G20) -> 6250 | H21: =SUM(H6:H20) -> 41991 | I21: =SUM(I6:I20) -> 48241 | J21: =SUM(J6:J20) -> 1644455 | K21: =SUM(K6:K20) -> 0 | L21: =SUM(L6:L20) -> 1758521
A22: 16 | B22: 163971 | C22: 0.0725 | D22: Model | E22: 10.09.2025 | F22: 126000 | G22: 0 | H22: 5180 | I22: =SUM(G22:H22) -> 5180 | J22: =F22+I22 -> 131180 | K22: 10.09.2026 | L22: 135386 | O22: Sinking Fund FD
A23: 17 | B23: 163734 | C23: 0.0725 | D23: Model | E23: 08.07.2025 | F23: 377000 | G23: 0 | H23: 20233 | I23: =SUM(G23:H23) -> 20233 | J23: =F23+I23 -> 397233 | K23: 08.07.2026 | L23: 405085 | O23: Repair Fund FD
A24: 18 | B24: 156876 | C24: 0.0685 | D24: Model | E24: 25.02.2026 | F24: 4100 | G24: 0 | H24: 27 | I24: =SUM(G24:H24) -> 27 | J24: =F24+I24 -> 4127 | K24: 25.02.2027 | L24: 4388 | O24: Education Fund FD
A25: 19 | B25: 156982 | C25: 0.0685 | D25: Model | E25: 23.03.2026 | F25: 130000 | G25: 0 | H25: 220 | I25: =SUM(G25:H25) -> 220 | J25: =F25+I25 -> 130220 | K25: 23.03.2027 | L25: 139136 | O25: Reserve Fund FD
A26: 20 | B26: 156877 | C26: 0.0685 | D26: Model | E26: 25.02.2026 | F26: 120000 | G26: 0 | H26: 788 | I26: =SUM(G26:H26) -> 788 | J26: =F26+I26 -> 120788 | K26: 25.02.2027 | L26: 128434 | O26: Reserve Fund FD
F27: =SUM(F22:F26) -> 757100 | G27: =SUM(G22:G26) -> 0 | H27: =SUM(H22:H26) -> 26448 | I27: =SUM(I22:I26) -> 26448 | J27: =SUM(J22:J26) -> 783548 | K27: =SUM(K22:K26) -> 0 | L27: =SUM(L22:L26) -> 812429
