Workbook

Sheet TIT
A1: CONTROL SHEET — master inputs for the entire audit report (yellow cells = confirm / edit)
A2: Name | D2: AKSHITA AVENUE CO-OPERATIVE HOUSING SOCIETY LTD.
A3: Registration No. | D3: BOM (WR) / HSG (TC) 10502-99-2000
A4: Date of Registration | D4: 36383
A5: Area of operation | D5: Mumbai - Suburban
A6: Address | D6: Akshita Avenue, Holy Cross Road, I. C. Colony, Borivali West, Mumbai - 400 103
A7: Accounting Year | B7: from | D7: 1st April, 2025
B8: to | D8: 31st March, 2026
A9: Auditor | B9: Name | D9: Shri. Bharat C. Boridkar | F9: Govt. Certified Panel Auditor
A10: Panel No. | D10: Mumbai-4/C1/1011404
B11: Address | D11: Boridkar House, Pandurang Bhoir Road, Dahisar - West, Mumbai - 400 068
A12: Place & Date of Report | D12: 46282
A13: Sr.No. of the audit memo | D13: -
A14: Date of commencement | D14: 46272
A15: Date of completion | D15: 46282
A16: Audit memo submitted | D16: 46282
A17: Annual General Meeting | F17: AGM held during FY 2025-26
A18: Special General Meeting
A19: M C Meetings
A20: Rectification of Reports: | D20: Not submitted
A21: Date of submission | D21: Not applicable
A22: Audit Fees | B22: Amt | D22: 7300
B23: Period | D23: 01/04/2024 to 31/03/2025
B24: Paid on
A25: Secretary | B25: Name | D25: Mr. Prakash Kamath
A26: Pay drawn: | D26: Nil
A27: Cash verification | B27: Amt
B28: Date
B29: Name | D29: =+D25 -> Mr. Prakash Kamath
B30: Designation | D30: Hon. Secretary
A31: AGBM of appointment | F31: AGM at which auditor was appointed for FY 2025-26
A32: Audit Classification | D32: B | F32: Auditor to confirm — see Part-B conclusion
A33: Classification last 3 audits | D33: B / B / B
A34: No. of members | D34: 64
A35: Flats / Shops | D35: 52 Flats & 12 Shops
A38: LEGEND
A39: Yellow fill + blue text = input cell. Confirm or edit before issuing the report.
A40: Black text = formula or standing text. Do not overtype.
A41: Every other sheet pulls the society name, address, registration no., period, dates,
A42: auditor details, classification and meeting counts from THIS sheet. Edit here only.
...

Sheet FirstPage
A3: STATUTORY AUDIT REPORT
A15: =+TIT!D2 -> AKSHITA AVENUE CO-OPERATIVE HOUSING SOCIETY LTD.
A17: =+TIT!D3 -> BOM (WR) / HSG (TC) 10502-99-2000
A18: =+TIT!D6 -> Akshita Avenue, Holy Cross Road, I. C. Colony, Borivali West, Mumbai - 400 103
A21: ="STATEMENT OF AUDIT REPORTS & ACCOUNTS STATEMENTS FOR THE YEAR ENDED "&UPPER(TIT!D8) -> STATEMENT OF AUDIT REPORTS & ACCOUNTS STATEMENTS FOR THE YEAR ENDED 31ST MARCH, 2026
A34: =REPT("=",79) -> ===============================================================================
A35: =+TIT!D9 -> Shri. Bharat C. Boridkar
A36: =+TIT!F9 -> Govt. Certified Panel Auditor
A37: =+TIT!D11 -> Boridkar House, Pandurang Bhoir Road, Dahisar - West, Mumbai - 400 068
A39: =REPT("=",79) -> ===============================================================================

Sheet Sheet1
B2: =+TIT!D9 -> Shri. Bharat C. Boridkar
B3: =+TIT!F9 -> Govt. Certified Panel Auditor
B4: =+TIT!D11 -> Boridkar House, Pandurang Bhoir Road, Dahisar - West, Mumbai - 400 068
B7: To,
B8: The Chairman, Members
B9: =+TIT!D2 -> AKSHITA AVENUE CO-OPERATIVE HOUSING SOCIETY LTD.
B10: =+TIT!D6 -> Akshita Avenue, Holy Cross Road, I. C. Colony, Borivali West, Mumbai - 400 103
B12: ="Sub :- Statutory audit of your society for the Financial Year ended on "&TEXT(DATE(2026,3,31),"dd-mmm-yyyy") -> Sub :- Statutory audit of your society for the Financial Year ended on 31-Mar-2026
B15: Enclosed please find 3 [Three only] sets of duly audited, signed and sealed report comprising Audit Report in Form N-2, Form-1 along with Schedules 1 to 6, Form-28, General Remarks, Balance Sheet, Income and Expenditure Account along with Schedules forming an integral part of the same, and Audit Report [Executive Summary] for the Financial Year ended on 31-Mar-2026, for the record of the Society.
B17: It is advised that one set be submitted to The Dy. Registrar, Co-Operative Societies, R/North Ward, 2nd floor, C wing, Municipal Godown Bldg, Nr. St. Lawrence School, 90 feet Road, Sanskruti Complex, Kandivali East, Mumbai - 400 101 under the Society’s covering letter at your earliest.
B19: You are requested to upload the mandatory returns prescribed u/s 79 of the MCS Act, i.e. 1] Annual Report of Activities, 2] Abridged Audit Report, 3] Balance Sheet, 4] Income and Expenditure Account, 5] Plan for Surplus Distribution, 6] List of Amendments to Bye-Laws, if any, 7] Date of holding AGBM and Election, and 8] Name of Auditor, for the year ended 31-03-2026, together with the Return Consent, on "www.mahasahakar.maharashtra.gov.in" within the time prescribed.
B21: I am also enclosing the Invoice for audit fees with a request to settle the same at your earliest.
B23: Please note that the Audit Rectification Report in Form "O", duly approved by the Managing Committee, is to be submitted to the Registering Authority within the time permitted, i.e. 3 months from the date of the audit report, under Section 82 of the MCS Act. Please ensure that an authenticated copy of the same, along with a soft copy, is provided to me for my comments thereon and for uploading thereafter on "www.mahasahakar.maharashtra.gov.in".
B25: In case any further information is required, please feel free to contact me at your convenience.
B27: Inconvenience, if any, is regretted.
B29: Thanks a lot.
B31: Yours faithfully,
B35: =+TIT!D9 -> Shri. Bharat C. Boridkar
B36: =+TIT!F9 -> Govt. Certified Panel Auditor
B37: Co-op Soc Empanelment Number : A-2 / 13395
B38: ="Co-op Soc Empanelment Number : "&TIT!D10 -> Co-op Soc Empanelment Number : Mumbai-4/C1/1011404
B40: =+TIT!D12 -> 46282
B42: Encl: | C42: 1] 3 [three only] sets as above
C43: 2] Original Invoice of Audit Fees

Sheet AR (2)
B2: =+TIT!D9 -> Shri. Bharat C. Boridkar
B3: =+TIT!F9 -> Govt. Certified Panel Auditor
B4: =+TIT!D11&", 9769556665" -> Boridkar House, Pandurang Bhoir Road, Dahisar - West, Mumbai - 400 068, 9769556665
B7: INDEPENDENT AUDITOR'S REPORT
B8: [As prescribed under section 81 of the Maharashtra Co-operative Societies Act, 1960 and rule 69 (3) of the Maharashtra Co-op. Societies Rules, 1961.]
B10: To,
B11: The Chairman, Members
B12: =+TIT!D2 -> AKSHITA AVENUE CO-OPERATIVE HOUSING SOCIETY LTD.
B13: =+TIT!D6 -> Akshita Avenue, Holy Cross Road, I. C. Colony, Borivali West, Mumbai - 400 103
B16: ="Sub :- Statutory audit of your society for the Financial Year ended on "&TEXT(DATE(2026,3,31),"dd-mmm-yyyy") -> Sub :- Statutory audit of your society for the Financial Year ended on 31-Mar-2026
C18: Report on the Financial Statements as a Statutory Auditor
B20: 1. | C20: We have audited the accompanying financial statements of AKSHITA AVENUE CO-OPERATIVE HOUSING SOCIETY LIMITED, which comprise the Balance Sheet as at 31st MARCH, 2026 and the Statement of Income and Expenditure for the year ended on that date, and a summary of significant accounting policies and other explanatory information incorporated in these financial statements of the Society audited by us for the period 1st April 2025 to 31st March 2026.
C22: Management’s Responsibility for the Financial Statements
B23: 2. | C23: Management is responsible for the preparation of these financial statements that give a true and fair view of the financial position and financial performance of the Society in accordance with the accounting principles generally accepted in India, the Maharashtra Co-operative Societies Act, 1960 and the Rules there under. This responsibility includes maintenance of adequate accounting records in accordance with the provisions of the Act for safeguarding the assets of the Society and for preventing and detecting frauds and other irregularities; selection and application of appropriate accounting policies; making judgments and estimates that are reasonable and prudent; and design, implementation and maintenance of adequate internal financial controls, that were operating effectively for ensuring the accuracy and completeness of the accounting records, relevant to the preparation and presentation of the financial statements that give a true and fair view and are free from material misstatement, whether due to fraud or error.
C25: Auditor’s Responsibility
B26: 3. | C26: Our responsibility is to express an opinion on these financial statements based on our audit. We have taken into account the provisions of the Act, the accounting and auditing standards and matters which are required to be included in the audit report under the provisions of the Act and Rules made there under. We have conducted our audit in accordance with the applicable standards issued by the Institute of Chartered Accountants of India and under the Maharashtra Co-operative Societies (MCS) Act, 1960. Those standards require that we comply with ethical requirements and plan and perform the audit to obtain reasonable assurance about whether the financial statements are free from material misstatement.
B28: 4. | C28: An audit involves performing procedures to obtain audit evidence about the amounts and disclosures in the financial statements. The procedures selected depend on the auditor’s judgment, including the assessment of the risks of material misstatement of the financial statements, whether due to fraud or error. In making those risk assessments, the auditor considers internal control relevant to the Society’s preparation and fair presentation of the financial statements in order to design audit procedures that are appropriate in the circumstances, but not for the purpose of expressing an opinion on the effectiveness of the Society’s internal control. An audit also includes evaluating the appropriateness of accounting policies used and the reasonableness of the accounting estimates made by management, as well as evaluating the overall presentation of the financial statements.
B30: 5. | C30: We believe that the audit evidence we have obtained is sufficient and appropriate to provide a basis for our audit opinion on the financial statements.
C32: Emphasis of Matter
B33: 6. | C33: We invite attention to the following matters, in respect of which our opinion is not modified: (a) interest recoverable from members aggregating Rs. 6,61,348/- has been written off during the year by debit directly to the accumulated balance of the Income and Expenditure Account instead of being routed through the Income and Expenditure Account for the year; (b) the balance with The Catholic Syrian Bank has been carried in the Balance Sheet at Rs. 5,88,837.80 being the balance as per the bank pass book, as against the balance as per the books of Rs. 4,09,500.80 shown by the Bank Reconciliation Statement of even date; and (c) expenditure of Rs. 14,92,029/- on terrace shed roofing has been charged wholly to revenue as against recovery of Rs. 10,00,320/- from members, without any transfer from the Building Repair Fund. These matters are more fully described in the General Remarks forming part of this report.
C35: Opinion
B36: 7. | C36: In our opinion and to the best of our information and according to the explanations given to us, the said financial statements together with the notes thereon give the information required as per the Maharashtra Co-operative Societies Act, 1960 and the Maharashtra Co-operative Societies Rules, 1961, and any other applicable Acts, and/or circulars issued by the Registrar, in the manner so required and give a true and fair view in conformity with the accounting principles generally accepted in India:
C38: i. | D38: In the case of the Balance Sheet, of the state of affairs of the Society as at 31st MARCH, 2026; and
C40: ii. | D40: In the case of the Statement of Income and Expenditure, of the Excess of Expenditure over Income of the Society for the year ended on that date.
C43: Report on Other Legal and Regulatory Matters
C44: As required by the Maharashtra Co-operative Societies Act, 1960 and the Rules made there under, and in terms of Circular No. 976/2014 dated 28/10/2014, we give in Parts A, B & C a statement on the matters specified in the said parts, to the extent applicable.
B45: 8. | C45: The Balance Sheet and the Income and Expenditure Account have been drawn up in accordance with the provisions of the Maharashtra State Co-operative Societies Act, 1960.
B47: 9. | C47: We report that :
C48: (a) | D48: We have obtained all the information and explanations which to the best of our knowledge and belief were necessary for the purpose of our audit and have found them to be satisfactory, except for balance confirmations from members and from the Municipal Corporation / Electricity Supply Company in respect of deposits, which were not made available to us.
C50: (b) | D50: The transactions of the Society, which have come to our notice, have been within the powers of the Society, save for the write-off of interest recoverable from members referred to in paragraph 6(a) above, for which the sanction of the General Body was not produced before us.
C52: (c) | D52: The returns received from the office of the Society have been found adequate for the purposes of our audit.
B54: 10. | C54: In our opinion, the Balance Sheet and the Income and Expenditure Account comply with the applicable Accounting Standards.
B56: 11. | C56: We further report that :
C57: i. | D57: The Balance Sheet and the Income and Expenditure Account dealt with by this report are in agreement with the books of account and the returns, and give a true and fair view of the state of affairs, subject to our observation in paragraph 6(b) above regarding the bank balance carried in the Balance Sheet.
C59: ii. | D59: In our opinion, proper books of account as required by law have been kept by the Society so far as appears from our examination of those books.
B61: Audit Classification:-
C62: ="The Society has been awarded "&CHAR(34)&TIT!D32&CHAR(34)&" Audit Classification for the Co-operative financial year 2025-2026." -> The Society has been awarded "B" Audit Classification for the Co-operative financial year 2025-2026.
C69: =+TIT!D9 -> Shri. Bharat C. Boridkar
C70: =+TIT!F9 -> Govt. Certified Panel Auditor
C71: Co-op Soc Empanelment Number : A-2 / 13395
...

Sheet SCHAR (2)
A1: =+TIT!D2 -> AKSHITA AVENUE CO-OPERATIVE HOUSING SOCIETY LTD.
A2: =+TIT!D3 -> BOM (WR) / HSG (TC) 10502-99-2000
A3: =+TIT!D6 -> Akshita Avenue, Holy Cross Road, I. C. Colony, Borivali West, Mumbai - 400 103
A4: Period:- 01.04.2025 To 31.03.2026
A7: Schedules attached to and forming part of the Audit Report dated :- | J7: =+TIT!D12 -> 46282
A8: Statutory Report as required u/s 81 (2)
A10: SCHEDULE - I
C11: Transactions involving infringement of the provisions of the Act, the Rules & the Bye-laws
D12: - Refer to Form No. 1 item 10, General Remarks Part-A item 7 and Part-C.
A14: SCHEDULE - II
C15: Particulars of sums which ought to have been but have not been brought into account.
D16: - Contribution to the Education and Training Fund u/s 24A; Tax Deducted at Source of Rs. 5,697/- on fixed deposit interest for the year; and interest recoverable from members on arrears, not charged during the year.
A18: SCHEDULE - III
C19: Material impropriety or irregularity in the expenditure or in the realisation of moneys due to the Society
D20: - Interest recoverable from members of Rs. 6,61,348/- written off against the accumulated balance of the Income and Expenditure Account without the sanction of the General Body being produced. Refer to General Remarks.
A22: SCHEDULE - III-A
C23: Irregularities in the realisation of money
D24: - Refer to General Remarks Part-B and Part-C.
C26: List of doubtful & bad debts
D27: - NIL
A28: SCHEDULE - V
C29: List of the movable & immovable properties & other assets considered doubtful of realisation
D30: - NIL
A32: SCHEDULE - VI
C33: Personal Expenditure debited to revenue
D34: - NIL
C42: =+TIT!D9 -> Shri. Bharat C. Boridkar
C43: ="[Panel No.: "&TIT!D10&"]" -> [Panel No.: Mumbai-4/C1/1011404]
C44: =+TIT!F9 -> Govt. Certified Panel Auditor
C45: =+TIT!D12 -> 46282

Sheet F-1
A1: FORM NO. 1
A2: Audit Memo (For all types of Co-op. Societies)
A3: Part-I
A5: Name of the Society | I5: =+TIT!D2 -> AKSHITA AVENUE CO-OPERATIVE HOUSING SOCIETY LTD.
A7: Sr. No. of the audit memo as per audit register | I7: =+TIT!D13 -> -
A8: Full registered address | I8: =+TIT!D6 -> Akshita Avenue, Holy Cross Road, I. C. Colony, Borivali West, Mumbai - 400 103
A10: District | I10: Mumbai Suburban District
A11: Registration No. | I11: =+TIT!D3 -> BOM (WR) / HSG (TC) 10502-99-2000
A12: Date of Registration | I12: =+TIT!D4 -> 36383
A13: Area of operation | I13: Borivali - West
A14: No. of branches, depots and shops (Give separate figures) | I14: NA
A16: (i) | B16: Audit classification | I16: ="‘"&TIT!D32&"’" -> ‘B’
A17: (ii) | B17: Audit classification given during the last three audits | I17: =+TIT!D33 -> B / B / B
A18: 1 | B18: Audit information:
B19: (1) | C19: Full name, designation and head quarters of auditing officer. | I19: =+TIT!D9 -> Shri. Bharat C. Boridkar | K19: =+TIT!F9 -> Govt. Certified Panel Auditor
I20: ="Address: "&TIT!D11 -> Address: Boridkar House, Pandurang Bhoir Road, Dahisar - West, Mumbai - 400 068
B22: (2) | C22: Period covered during the present audit. | I22: =+TIT!D7&" to "&TIT!D8 -> 1st April, 2025 to 31st March, 2026
B23: (3) Dates on which | D23: (1) Audit was commenced and continued. | I23: =+TIT!D14 -> 46272 | J23: to | K23: =+TIT!D15 -> 46282
D24: (2) Audit was completed | I24: =+K23 -> 46282
D25: (3) Audit memo was submitted. | I25: =+TIT!D16 -> 46282
A26: 2 | B26: Membership:
B27: (i) | C27: No. of Members: | E27: (a) Individual: | F27: (I) Ordinary | J27: =+TIT!D34 -> 64
F28: (ii) Nominal | J28: 0
F29: (iii) Sympathiser | J29: 0
E30: (b) Societies. | J30: 0
E31: (c) Others | J31: 0
E32: Give details of the other members, if any
E33: Total | J33: =SUM(J27:J32) -> 64
B34: (ii) | C34: Have new members been duly admitted? | I34: Yes
C35: Have they paid entrance fees? | I35: Yes
B36: (iii) | C36: Are their written applications in order and are they filed properly? | I36: Yes
B38: (iv) | C38: Is the members' register kept in Form 'I' prescribed under Rules 32 and 65(I) of the M.C.S. Rules, 1961? | I38: Maintained, but not updated
B41: (v) | C41: Is a list of members kept in Form 'J' under Rule 33 of the M.C.S. Rules, 1961? | I41: =+I38 -> Maintained, but not updated
B43: (vi) | C43: Have due remarks been passed against names of the deceased, dismissed, or resigned members in the members' register? | I43: NA
B46: (vii) | C46: Are resignations in order and are they duly accepted? | I46: Yes
B48: (viii) | C48: Have nominations made under Rule 25 of the M.C.S. Rules, 1961 been duly entered in the member's register under Rule 26? | I48: Nominations not fully received. Please see General Remarks.
A51: 3 | B51: Shares:
B52: (i) | C52: Are applications for shares in order? | I52: Yes
B53: (ii) | C53: Is share register written up-to-date? | I53: =+I41 -> Maintained, but not updated
B54: (iii) | C54: Do the entries in share register tally with the entries in the cash book? | I54: Yes
...

Sheet F-28
A1: =+TIT!D2 -> AKSHITA AVENUE CO-OPERATIVE HOUSING SOCIETY LTD.
A2: FORM NO. 28
A3: Audit Memo (Co-operative Housing Societies)
A4: Part - II
A5: 1. | B5: Borrowings :-
B6: (i) | C6: State the loans obtained by the Society for various purposes from Government and other agencies
A7: Agency Sanctioning loan | E7: Purpose for which the loan is sanctioned | G7: Amount of loan sanctioned | I7: Maximum amount drawn | J7: Repayment made | K7: Outstanding | L7: Amount overdue, if any | M7: Remarks
A10: 1 | E10: 2 | G10: 3 | I10: 4 | J10: 5 | K10: 6 | L10: 7 | M10: 8
A12: Not Applicable — the Society has not obtained any loan.
B14: (ii) | C14: Are repayments of loans punctual? | I14: Not Applicable
B15: (iii) | C15: Are all conditions laid down for grant of various loans and credits observed? Note breaches, if any. | I15: Not Applicable
B17: (iv) | C17: Are necessary documents executed in favour of the authority sanctioning the loan? | I17: Not Applicable
A19: 2. | B19: Government Financial Assistance :-
B20: (i) | C20: What is the amount of Government subsidy sanctioned and received by the society? | I20: Not Applicable
B22: (ii) | C22: Has Government sanctioned any amount for land development? If so, state the amount. Have development expenses exceeded the said amount? | I22: Not Applicable
A25: 3. | B25: Membership :-
B26: (i) | C26: State whether in case of backward class co-operative housing societies, certificates from the social welfare officers are obtained for their eligibility to membership and obtaining of financial assistance? | I26: Not Applicable
B30: (ii) | C30: State whether certificates are obtained from officers of the concerned industry in case of the subsidised industrial housing scheme. | I30: Not Applicable
B33: (iii) | C33: Have declarations been obtained from members that they and their family members do not own lands or houses in the area of operation of the society as per provisions in the bye-laws? | I33: Not Applicable
A37: 4. | B37: Lands and their development :-
B38: (i) | C38: State whether lands for construction of houses have been secured, purchased or obtained on lease. Give details of the lands, stating total area, survey Nos. and C.R.S. Nos. if any, price for which purchased, lease rent etc. | I38: =+TIT!D6 -> Akshita Avenue, Holy Cross Road, I. C. Colony, Borivali West, Mumbai - 400 103
B43: (ii) | C43: See the title deeds and ascertain whether they are properly executed in favour of the Society? | I43: Conveyance is not executed in favour of the Society.
B45: (iii) | C45: State how the land has been utilised for:-
B46: (a) | C46: Construction of houses. | I46: Yes
B47: (b) | C47: Construction of roads. | I47: -
B48: (c) | C48: Open spaces. | I48: -
B49: (d) | C49: Other purposes. (give details) | I49: -
B50: (iv) | C50: Have the layouts and plans for development been approved by the Municipal authorities before actual commencement of the work? | I50: Yes
B53: (v) | C53: Have completion certificates been obtained from appropriate authorities for drainage, water supply, roads, etc. before construction work of buildings is commenced? | I53: Yes
A57: 5. | B57: Construction of Buildings :-
B58: (i) | C58: (a) Have building constructions commenced? | I58: Already Constructed
C59: (b) State the No. of houses or flats constructed and under construction. | I59: =+TIT!D35 -> 52 Flats & 12 Shops
C61: (c) Have the completed houses and flats been allotted to members? | I61: Yes
B63: (ii) | C63: Are buildings constructed on contract basis? See the terms and conditions of contracts and state whether they have been properly observed. Note breaches, if any. | I63: Already Constructed
B67: (iii) | C67: Are these contracts properly sanctioned by the competent authority as per bye-laws of the society? | I67: Already Constructed
B69: (iv) | C69: Have tenders or quotations been called after giving due advertisements in local newspapers? If the works are not given to the contractors quoting the lowest figures, see whether reasons for the same are recorded. | I69: In respect of the terrace shed roofing work of Rs. 14,92,029/-, comparative quotations were produced; the Managing Committee resolution approving the award of the work was not made available to me.
B73: (v) | C73: Are contractors paid after necessary work progress certificates are obtained from the Architects? Are running and final bills obtained before payments are made to the contractors? | I73: Bills of the contractor were produced. Architect’s / Engineer’s work progress certificates were not made available to me.
B77: (vi) | C77: See the terms on which the architects are employed. Are there any breaches? | I77: Already Constructed
B79: (vii) | C79: See whether completion certificates have been obtained from the qualified engineers and architects, stating that the constructions have been completed according to approved plans, specifications and other terms of contracts. | I79: Already Constructed
B84: (viii) | C84: Is a property register kept in proper form? | I84: No
...

Sheet GR
A1: =+TIT!D2 -> AKSHITA AVENUE CO-OPERATIVE HOUSING SOCIETY LTD.
A2: ="General Remarks and Observations attached to and forming part of the audit report dated "&TEXT(TIT!D12,"dd-mmm-yyyy") -> General Remarks and Observations attached to and forming part of the audit report dated 17-Sep-2026
A4: INTRODUCTION
A6: 1 | B6: Name of the society | F6: :- | G6: =+TIT!D2 -> AKSHITA AVENUE CO-OPERATIVE HOUSING SOCIETY LTD.
A7: 2 | B7: Registered Address | F7: :- | G7: =+TIT!D6 -> Akshita Avenue, Holy Cross Road, I. C. Colony, Borivali West, Mumbai - 400 103
A8: 3 | B8: Reg. No. & date | F8: :- | G8: =+TIT!D3 -> BOM (WR) / HSG (TC) 10502-99-2000
A9: 4 | B9: Period of audit | F9: :- | G9: ="01-Apr-2025 To 31-Mar-2026" -> 01-Apr-2025 To 31-Mar-2026
A10: 5 | B10: Audit classification | F10: :- | G10: =CHAR(34)&TIT!D32&CHAR(34) -> "B"
A12: GENERAL REMARKS (PART-A)
A13: The following are the major discrepancies found during the audit.
A15: Sr no | B15: Particulars | E15: Instances / Examples which require reporting | L15: Auditor’s remarks
A16: 1 | B16: Fraud | E16: 1) Debiting excess amount than the voucher amount / bill amount. | L16: During the year under audit, I have not found any such instance.
E17: 2) Withdrawing the amount from bank but not crediting in cash book. | L17: During the year under audit, I have not found any such instance.
E18: 3) Debiting the bank account without depositing the amount in bank. | L18: During the year under audit, I have not found any such instance.
E19: 4) Disbursing loans without sanction / without security / without loan documents / using forged documents. | L19: Not applicable. The Society is a Co-operative Housing Society and does not disburse loans.
E20: 5) Any other transaction with the intention to defraud the society by any person. | L20: On the basis of verification of the records made available to me, I have not found any such instance.
A21: 2 | B21: Mis-utilisation of funds and properties | E21: 1) Purchasing / constructing building without inviting tenders. | L21: Terrace shed roofing work of Rs. 14,92,029/- was carried out during the year. Comparative quotations were produced; the Managing Committee resolution awarding the work was not recorded in the minutes.
E22: 2) Purchasing the computers / fixed assets without inviting tenders. | L22: Additions to fixed assets of Rs. 2,58,037/- were made during the year, mainly CCTV cameras of Rs. 1,92,617/-. Quotations were produced; the approving resolution was not recorded in the minutes.
E23: 3) Selling the movable / immovable properties without inviting bids. | L23: During the year under audit, I have not found any such instance.
E24: 4) Selling the movable / immovable properties below Reserve Price (Upset price). | L24: During the year under audit, I have not found any such instance.
A25: 3 | B25: Misapplication of funds | E25: 1) Use of sinking fund for day to day maintenance without passing the required resolution in the General Body. | L25: No amount has been withdrawn from the Sinking Fund during the year.
E26: 2) Use of revenue reserve / general reserve for creating Reserve for Bad and Doubtful Debts. | L26: Interest recoverable from members of Rs. 6,61,348/- has been written off by debit directly to the accumulated balance of the Income and Expenditure Account, instead of being routed through the Income and Expenditure Account for the year. The sanction of the General Body for the write-off was not produced before me.
A27: 4 | B27: Manipulation of accounts | L27: I have not found any manipulation of accounts during the year under audit.
A28: 5 | B28: Falsification of accounts | L28: I have not found any falsification of accounts during the year under audit.
A29: 6 | B29: Shortfall in various provisions | L29: Contribution to the Education and Training Fund under Section 24A has not been provided for. Tax deducted at source of Rs. 5,697/- on fixed deposit interest for the year has not been recorded in the books. Except as aforesaid, there is no material shortfall in the recognition of liabilities for outstanding expenses / provisions.
A31: 7. Infringement of the M.C.S. Act, 1960, the M.C.S. Rules, 1961 and the Bye-Laws of the Society
B33: Sr. | C33: Act | D33: Rules | E33: Bye-laws | G33: Description
B34: 1 | C34: 70 | D34: 54, 55 | E34: 15 | G34: Investment of Funds — Sinking Fund, Building Repair Fund, Reserve Fund, Common Amenity Fund and Share Capital are not fully invested. Shortfall as at 31.03.2026 is Rs. 10,54,527/-.
B35: 2 | E35: 20 | G35: A sub-lettee / licensee has not applied for Nominal Membership of the Society.
B36: 3 | C36: 26(1) | E36: 22 (b) | G36: Minimum contribution of a member to the share capital — 260 shares are subscribed against 64 members, as against the minimum of 10 shares per member.
B37: 4 | E37: 160 | G37: The Managing Committee did not meet once in every month.
B38: 5 | E38: 127(i) | G38: Nominations not fully received from members.
B39: 6 | D39: 26 | E39: 32 | G39: Payments made by means other than crossed account payee cheque.
B40: 7 | C40: 81 | D40: 107-D | E40: 145 | G40: Co-operative education and training not organised for members and committee members.
B41: 8 | C41: 24A | G41: Contribution to the Education and Training Fund not paid; mandatory annual returns not filed / uploaded and not received by the AGM from the committee.
B42: 9 | C42: 75(2) | E42: 95(g) & 146(b) | G42: Audit rectification report in Form "O" not placed before the Managing Committee and not submitted to the Registering Authority and to the auditor for comments.
B43: 10 | C43: 82 | D43: 73 | E43: 153(a) | G43: Conveyance of the property has not been executed in favour of the Society.
B44: 11 | C44: 79 | E44: 142 | G44: Statutory registers — Form I, Form J, Share Register, Nomination Register and Property Register — are not written up to date.
A46: Sr no | B46: Particulars | E46: Instances / Examples which require reporting | L46: Auditor’s remarks
A47: 8 | B47: Personal expenses debited to the Income and Expenditure Account. | L47: During the year under audit, I have not found any such instance.
...

Sheet SCH (2)
A1: =+TIT!D2 -> AKSHITA AVENUE CO-OPERATIVE HOUSING SOCIETY LTD.
A2: Schedules attached to and forming part of the Annual Accounts for the year ended 31st March, 2026
A4: A | B4: Accounting Conventions:
B5: 1
D6: The financial statements have been prepared under the historical cost convention, in accordance with generally accepted accounting policies and the provisions of the Maharashtra Co-operative Societies Act, 1960 and the Rules framed there under and the registered Bye-laws of the Society, and the same, unless specifically referred to otherwise, are adopted consistently by the Society.
B10: 2 | C10: Recognition of Income and Expenditure:
D11: The Society generally follows the accrual system of accounting and recognises significant items of income and expenditure on accrual basis, except contributions by members towards Property Tax and Non-Agricultural Tax and their payment, and the annual contribution towards the education and training fund of the State federal society. During the year under audit, interest on delayed payment of members’ dues has not been charged.
B15: 3 | C15: Fixed Assets:
D16: Fixed assets are stated at cost less depreciation. Cost comprises the cost of acquisition and any attributable cost of bringing the asset to the condition for its intended use.
B19: 4 | C19: Depreciation:
D20: Depreciation is provided on the written down value (WDV) method at the rates prescribed under the Income Tax Act, 1961. During the year under audit, full-year depreciation has been charged on additions to fixed assets irrespective of the date of their being put to use.
B24: 5 | C24: Investments:
D25: Investments are stated at cost. Interest accrued on fixed deposits is accounted separately under Current Assets.
B27: 6 | C27: Contingent Liabilities:
D28: Contingent liabilities are not provided for and, if any, the same are disclosed by way of note.
A30: B | B30: Notes on Accounts:
B31: 1 | C31: Previous year figures:
D32: Previous year figures have been re-worked, re-grouped, re-arranged and re-classified wherever necessary to facilitate comparison with the current year figures.
B34: 2 | C34: Confirmations:
D35: The dues from members, the credit balances and the security deposits with MCGM and Adani Electricity are subject to confirmation.
B36: 3 | C36: Bank balance:
D37: The balance with The Catholic Syrian Bank has been carried at the balance as per the bank pass book. The balance as per the books of account, as per the Bank Reconciliation Statement as at 31.03.2026, is Rs. 4,09,500.80.
B38: 4 | C38: Interest written off:
D39: Interest recoverable from members of Rs. 6,61,348/- has been written off during the year by debit to the accumulated balance of the Income and Expenditure Account.
B40: 5 | C40: Other assets:
D41: In the opinion of the Managing Committee, the value of other assets is as stated in the financial statements, if realised in the ordinary course of the operations of the Society.
H43: ="For "&TIT!D2 -> For AKSHITA AVENUE CO-OPERATIVE HOUSING SOCIETY LTD.
D44: =+TIT!D9 -> Shri. Bharat C. Boridkar
D45: ="[Panel No.: "&TIT!D10&"]" -> [Panel No.: Mumbai-4/C1/1011404]
D46: =+TIT!F9 -> Govt. Certified Panel Auditor
D47: =+TIT!D12 -> 46282 | H47: Chairman Secretary Treasurer

Sheet INDEX
A2: =+TIT!D9 -> Shri. Bharat C. Boridkar
A3: =+TIT!F9 -> Govt. Certified Panel Auditor
A4: =+TIT!D11 -> Boridkar House, Pandurang Bhoir Road, Dahisar - West, Mumbai - 400 068
A9: =+TIT!D2 -> AKSHITA AVENUE CO-OPERATIVE HOUSING SOCIETY LTD.
A10: =+TIT!D6 -> Akshita Avenue, Holy Cross Road, I. C. Colony, Borivali West, Mumbai - 400 103
A12: STATUTORY AUDIT REPORT
A13: ="Financial Year : "&2025&"-"&2026 -> Financial Year : 2025-2026
A14: INDEX
B16: Sr. No. | C16: Particulars | I16: Page No.
B17: 1 | C17: Letter to Society | I17: 2
B18: 2 | C18: Auditor's Report | I18: 3 - 4
B19: 3 | C19: Schedules attached to and forming part of the Audit Report | I19: 5
B20: 4 | C20: Form No. 1 | I20: 6 - 9
B21: 5 | C21: Form No. 28 | I21: 10 - 12
B22: 6 | C22: Accounting Policies | I22: 13
B23: 7 | C23: General Remarks - part A, B, C | I23: 14 - 20
B24: 8 | C24: Statement of Accounts with Schedule | I24: 21 - 23

Sheet mEETINGS
C1: Meeting-1 | D1: Meeting-2 | E1: Meeting-3 | F1: Meeting-4 | G1: Meeting-5 | H1: Meeting-6 | I1: Meeting-7 | J1: Meeting-8 | K1: Meeting-9 | L1: Meeting-10 | M1: Meeting-11 | N1: Meeting-12
A2: Name of the Member | B2: Designation
B3: Chairman
B4: Secretary
B5: Treasurer
B6: Member
B7: Member
B8: Member
B9: Member
B10: Member
B11: Member
A13: Attendance | C13: =COUNTIF(C3:C11,"P") -> 0 | D13: =COUNTIF(D3:D11,"P") -> 0 | E13: =COUNTIF(E3:E11,"P") -> 0 | F13: =COUNTIF(F3:F11,"P") -> 0 | G13: =COUNTIF(G3:G11,"P") -> 0 | H13: =COUNTIF(H3:H11,"P") -> 0 | I13: =COUNTIF(I3:I11,"P") -> 0 | J13: =COUNTIF(J3:J11,"P") -> 0 | ... N13: =COUNTIF(N3:N11,"P") -> 0
A16: MC meeting dates (text, feeds TIT D19 count and General Remarks)
A19: AGM held during the year | C19: =+TIT!D17 -> 0
A20: SGM held during the year | C20: =+TIT!D18 -> 0
A22: Register observations
A23: Form I, Form J and Nomination Register to be updated
A24: Share Register to be updated
A25: Property Register not maintained
A26: Blank pages left between minutes of two meetings

Sheet Sheet2
A1: The audit report for FY 2025‑26 is ready, built on your standard 11‑sheet template (TIT → FirstPage → Sheet1 → AR → SCHAR → F‑1 → F‑28 → GR → SCH → INDEX → mEETINGS), with all financial figures pulled from the Society's accounts and every formula verified error‑free.
A3: Headline finding: the Society has swung from a surplus of ₹8,37,371 (FY24‑25) to a deficit of ₹5,65,589 this year — driven mainly by the terrace shed roofing cost (₹14,92,029 expensed against only ₹10,00,320 recovered from members, with nothing drawn from the Building Repair Fund) and interest on members' dues (₹3,40,955 last year, nil this year).
A5: Two things worth flagging before you sign off:
A7: Fixed Asset schedule casting error — the Society's own schedule sub‑totals (Additions ₹2,49,787, Total ₹4,60,349) omit the Fan addition of ₹8,250; correct figures are ₹2,58,037 and ₹4,68,599. Depreciation and closing WDV carried to the Balance Sheet are unaffected — I've noted this in GR.
A8: Source accounts header mismatch — the Income & Expenditure and Balance Sheet page headers in the accounts PDF still read "31st March 2025," while the FD and Fixed Asset schedules correctly say 2026. I've treated the data as FY25‑26 throughout (per your note), but the Society should correct the stale header on its own statements.
A10: Needs your input — the TIT sheet is the control sheet everything else pulls from; its yellow cells (audit commencement/completion/submission dates, AGM date, MC meeting dates/count, AGBM‑of‑appointment date, and the audit classification) are left blank or defaulted since I don't have that data — fill those in and the rest of the report (GR, F‑1, meeting tables) updates automatically.
A12: Also caught and folded into GR: interest recoverable of ₹6,61,348 written off directly against accumulated I&E balance rather than routed through the year's account, and TDS of ₹5,697 on FD interest not yet recorded in the books.
