Workbook

Sheet BS
A1: MINJAL CO-OPERATIVE HOUSING SOCIETY LTD
A2: D'Monte Lane, Off Marve Road, Orlem, Malad (West) ,Mumbai,Maharashtra-400064
A3: Society Reg No : BOM/WP/HSG/TC/1710/1985-86 dt. 9.12.1985
A4: Balance Sheet as at March 31, 2026
A5: March 31, 2025 | B5: LIABILITIES | D5: March 31, 2026 | E5: =A5 -> March 31, 2025 | F5: ASSETS | H5: =D5 -> March 31, 2026
B6: Authorised Share Capital | F6: Cash and Bank Balance
A7: 100000 | B7: 2000 Share of ₹ 50/- each | D7: 100000 | E7: 2294 | F7: Cash in Hand | G7: 732
E8: 335080.16 | F8: Model Co-op Bank | G8: =BRS!D15 -> 598161.16
B9: Issues, Subscribed and Paid Up | E9: 616980.19 | F9: Mumbai Disctrict Central Co-op Bank | G9: =BRS!D6 -> 297391.19 | H9: =SUM(G7:G9) -> 896284.35
A10: =4500+3750 -> 8250 | B10: 165 Shares of ₹ 50/- each | D10: 8250
B11: Reserves and Surplus: | F11: Investments
B12: Reserve Fund | E12: 1000 | F12: Share with MDCC Bank | G12: 1000
A13: 214933.12 | B13: As per last balance sheet | C13: =SUM(A13:A16) -> 230878.12 | E13: 3288058 | F13: Fixed Deposits - Sch I | G13: ='Sch I'!F42 -> 3819656
A14: 0 | B14: Add: 25% of Surplus transferred | C14: =IE!D41 -> 10235 | E14: 24579 | F14: Accrued Interest | G14: 52268 | H14: =SUM(G12:G14) -> 3872924
A15: 1200 | B15: Add: Additions during the year | C15: 500
A16: 14745 | B16: Add: Interest earned during the year | C16: =-IE!G26 -> 17034 | D16: =SUM(C13:C16) -> 258647.12 | F16: Fixed Assets - Sch II
B17: Common Amenity Fund | E17: 1997350 | F17: Land and Building | G17: ='Sch II'!H5 -> 1997350
A18: 151844 | B18: As per last balance sheet | C18: =SUM(A18:A19) -> 163097 | E18: 659.94 | F18: Furniture and Fixture | G18: ='Sch II'!H6 -> 593.94
A19: 11253 | B19: Add: Interest earned during the year | C19: =-IE!G31 -> 12806 | D19: =SUM(C18:C19) -> 175903 | E19: 19206 | F19: Water Pump | G19: ='Sch II'!H7 -> 16325
B20: Sinking Fund | E20: 13492 | F20: CCTV | G20: ='Sch II'!H8 -> 11468 | H20: =SUM(G17:G20) -> 2025736.9
A21: 2485034.4 | B21: As per last balance sheet | C21: =SUM(A21:A23) -> 2680079.4
A22: 5232 | B22: Add: Additions during the year | C22: 5232 | E22: 24497 | F22: Member's Receivable - Sch III | H22: ='Sch III to V'!D8 -> 6608
A23: 189813 | B23: Add: Interest earned during the year | C23: =-IE!G27 -> 214552 | D23: =SUM(C21:C23) -> 2899863.4
B24: Repair Fund | F24: Other Current Assets:
A25: 91645.62 | B25: As per last balance sheet | C25: =A25+A27+A28 -> 118998.62 | E25: 2224.53 | F25: Security Deposit with Adani Energy Ltd | G25: 2224.53
A26: =315000+90000-308010 -> 96990 | B26: Add: Deemed Conveyance transferred | C26: =315000+90000-308010 -> 96990 | E26: 20601 | F26: TDS Receivable | G26: 42692
A27: 15696 | B27: Add: Additions during the year | C27: 15696 | E27: 0 | F27: Advance to Legal Ace | G27: 0
A28: 11657 | B28: Add: Interest earned during the year | C28: =-IE!G28 -> 13521 | D28: =SUM(C25:C28) -> 245205.62 | E28: 0 | F28: Advance to Camos Consultants | G28: 0 | H28: =SUM(G25:G28) -> 44916.53
B29: Education and Training Fund
A30: 13883 | B30: As per last balance sheet | C30: =SUM(A30:A33) -> 16664 | F30: Prepaid Expenses:
A31: 1800 | B31: Add: Additions during the year | C31: 1800 | E31: 3521 | F31: Pest Control | G31: =Workings!E17 -> 3773
A32: 981 | B32: Add: Interest earned during the year | C32: =-IE!G30 -> 1287 | E32: 4906 | F32: Insurance | G32: =Workings!E21 -> 4906 | H32: =SUM(G31:G32) -> 8679
A33: 0 | B33: Less: Expenses during the year | C33: -1770 | D33: =SUM(C30:C33) -> 17981
B34: Major Repair Fund
A35: 90000 | B35: As per last balance sheet | C35: =SUM(A35:A37) -> 90000
B36: Add: Additions during the year | C36: 180000
A37: 0 | B37: Add: Interest earned during the year | C37: =-IE!G29 -> 98 | D37: =SUM(C35:C37) -> 270098
A39: 20901 | B39: Current Liabilities and Provision - Sch IV | D39: ='Sch III to V'!J13 -> 15195
A41: 18715 | B41: Advance from Members - Sch V | D41: ='Sch III to V'!D20 -> 37707
B43: Contribution from Members:
...

Sheet IE
A1: MINJAL CO-OPERATIVE HOUSING SOCIETY LTD
A2: =BS!A2 -> D'Monte Lane, Off Marve Road, Orlem, Malad (West) ,Mumbai,Maharashtra-400064
A3: =BS!A3 -> Society Reg No : BOM/WP/HSG/TC/1710/1985-86 dt. 9.12.1985
A4: Income and Expenditure Account for the year ended March 31, 2026
A5: March 31, 2025 | B5: EXPENDITURE | D5: March 31, 2026 | E5: =A5 -> March 31, 2025 | F5: INCOME | H5: =D5 -> March 31, 2026
F6: Maintenance Income
A7: 47826 | B7: Property Tax | D7: 65152 | E7: 34698 | F7: Property Tax | G7: =59372+5776 -> 65148
E8: 105480 | F8: Maintenance Charges | G8: 105480
A9: 21082 | B9: Common Area Electricity Charges | D9: 26000 | E9: 19800 | F9: Common Electricity Charges | G9: 19800
E10: 25560 | F10: Water Charges | G10: 25560
A11: 33140 | B11: Water Expenses | D11: 32687 | E11: 4200 | F11: Non Occupancy Charges | G11: =5250+118 -> 5368
E12: 55900 | F12: Parking Charges | G12: =26250+28000+3500 -> 57750
B13: Salary Expenses | E13: 7344 | F13: Insurance Charges | G13: 7344
A14: 22800 | B14: Salary Expenses | C14: 24000 | E14: 1947 | F14: Late Payment Interest | G14: 2589 | H14: =SUM(G7:G14) -> 289039
A15: 3100 | B15: Bonus | C15: 2000 | D15: =SUM(C14:C15) -> 26000
B16: Repair and Maintenance | F16: Other Member Income
A17: 1320 | B17: Electrical Repairs | C17: 550 | E17: 0 | F17: Prior Period Refund Received AY 2020-21 | G17: 7580
A18: 1416 | B18: Fire Fighing Expenses | C18: 1416 | E18: 0 | F18: Less: Transfer to Fund | G18: 0 | H18: =SUM(G17:G18) -> 7580
A19: 3890 | B19: Other Repair Maintenance | C19: =19000+620 -> 19620
A20: 1525.26 | B20: House keeping expense | C20: 1740 | F20: Interest Income
A21: 2700 | B21: Water Tank Cleaning | C21: 0 | E21: 0 | F21: Interest on Security Deposits | G21: 0
A22: 32530 | B22: Water pump charges | C22: 14300 | D22: =SUM(C17:C22) -> 37626 | E22: 557 | F22: Interest on IT Refunds | G22: 0
B23: Service Charges | E23: 24108 | F23: Interest on Savings Deposit | G23: 33043 | H23: =SUM(G21:G23) -> 33043
A24: 4190 | B24: Pest Control | C24: 4248
A25: 9512 | B25: Insurance Expense | C25: 9525 | E25: 240311 | F25: Interest on Fixed Deposits | G25: 259931
A26: 826 | B26: Subscription Federation | C26: 0 | E26: -14745 | F26: Less: Trf to Reserve Fund | G26: -17034
A27: 2000 | B27: Audit Fees | C27: 2000 | E27: -189813 | F27: Less: Trf to Sinking Fund | G27: =-214552 -> -214552
A28: 5664 | B28: Income Tax Expenses | C28: 0 | E28: -11657 | F28: Less: Trf to Repair Fund | G28: -13521
A29: 29000 | B29: Professional/Legal Fees | C29: =3000+48000 -> 51000 | E29: 0 | F29: Less: Trf to Major Repair Fund | G29: -98
A30: 5843 | B30: Depreciation | C30: ='Sch II'!G9 -> 4971 | D30: =SUM(C24:C30) -> 71744 | E30: -981 | F30: Less: Trf to Education Fund | G30: -1287
E31: -11253 | F31: Less: Trf to Comm. Amenity Fund | G31: -12806 | H31: =SUM(G25:G31) -> 633
A32: 308010 | B32: Deemed Conveyance | C32: 0
A33: -308010 | B33: Less: Expense adjsted from Liability | C33: 0 | D33: =SUM(C32:C33) -> 0 | F33: Other Income
B34: Office Charges | F34: Dividend Income | H34: 0
A35: 10496 | B35: Accounting Charges | C35: 10496
A36: 4252 | B36: Printing and Stationery | C36: 15886
A37: 1949 | B37: Conveyance Charges | C37: 2576
A38: 0 | B38: Meeting Expense | C38: 1190 | D38: =SUM(C35:C38) -> 30148
B40: ="Excess of "&IF(D42>0,"Income over Expenditure","Expenditure over Income")&":" -> Excess of Income over Expenditure:
A41: 0 | B41: 25% Transferred to Reserve Fund | D41: =ROUND((H43-SUM(D6:D40))*25%,) -> 10235
...

Sheet Sch I
B1: MINJAL CO-OPERATIVE HOUSING SOCIETY LTD
B2: Schedule 1: Details of Fixed Deposits as at March 31, 2026
A3: Sr. | B3: Certificate No. | C3: Int | D3: Bank | E3: Date of Issue | F3: Amount Deposited | G3: Accrued Int for FY 24-25 | H3: Accrued Int for FY 25-26 | I3: Total Amt | J3: Maturity Value | K3: Maturity Date | M3: int | N3: tds
B4: Sinking Fund
A5: 1 | B5: 09402_03 | C5: 0.0665 | D5: MDCC | E5: 02.03.2026 | F5: 36754 | G5: 0 | H5: =200-20 -> 180 | I5: =F5+G5+H5 -> 36934 | J5: 39260 | K5: 02.03.2027 | M5: 2502 | N5: 200 | P5: =271-251 -> 20
A6: 2 | B6: 09776_03 | C6: 0.0665 | D6: MDCC | E6: 29.03.2026 | F6: 93044 | G6: 0 | H6: =50-5 -> 45 | I6: =F6+G6+H6 -> 93089 | J6: 99387 | K6: 29.03.2027 | M6: 6829 | N6: 50 | P6: =688-683 -> 5
A7: 3 | B7: 09777_03 | C7: 0.0665 | D7: MDCC | E7: 29.03.2026 | F7: 75226 | G7: 0 | H7: =41-4 -> 37 | I7: =F7+G7+H7 -> 75263 | J7: 80355 | K7: 29.03.2027 | M7: 5521 | N7: 41 | P7: =557-553 -> 4
A8: 4 | B8: 09774_03 | C8: 0.0665 | D8: MDCC | E8: 29.03.2026 | F8: 2304166 | G8: 0 | H8: =1259-126 -> 1133 | I8: =F8+G8+H8 -> 2305299 | J8: 2461257 | K8: 29.03.2027 | M8: 169091 | N8: 1259 | P8: =17035-16909 -> 126
A9: 5 | B9: 09775_03 | C9: 0.0665 | D9: MDCC | E9: 29.03.2026 | F9: 9895 | G9: 0 | H9: =5-1 -> 4 | I9: =F9+G9+H9 -> 9899 | J9: 10570 | K9: 29.03.2027 | M9: 727 | N9: 5 | P9: =74-73 -> 1
A10: 6 | B10: 12547_03 | C10: 0.0665 | D10: MDCC | E10: 26.03.2026 | F10: 8535 | G10: 0 | H10: =9-1 -> 8 | I10: =F10+G10+H10 -> 8543 | J10: 9117 | K10: 26.03.2027 | M10: 621 | N10: 9 | P10: =63-62 -> 1
A11: 7 | B11: 14547_03 | C11: 0.0665 | D11: MDCC | E11: 30.03.2026 | F11: 129555 | G11: 0 | H11: =47-5 -> 42 | I11: =F11+G11+H11 -> 129597 | J11: 138388 | K11: 30.03.2027 | M11: 9533 | N11: 47 | P11: =959-954 -> 5
A12: 8 | B12: 14591_03 | C12: 0.075 | D12: MDCC | E12: 24.04.2025 | F12: 109637 | G12: 0 | H12: =7876-788 -> 7088 | I12: =F12+G12+H12 -> 116725 | J12: 118094 | K12: 24.04.2026 | M12: 522 | N12: 7876 | P12: =840-52 -> 788
A13: 9 | B13: 16/2002/508/163125 | C13: 0.0685 | D13: Model | E13: 14.03.2026 | F13: 135818 | G13: 0 | H13: 459 | I13: =F13+G13+H13 -> 136277 | J13: 145363 | K13: 14.03.2027 | M13: 9719 | N13: 0
F14: =SUM(F5:F13) -> 2902630 | G14: =SUM(G5:G13) -> 0 | H14: =SUM(H5:H13) -> 8996 | I14: =SUM(I5:I13) -> 2911626 | J14: =SUM(J5:J13) -> 3101791 | M14: =SUM(M5:M13) -> 205065 | N14: =SUM(N5:N13) -> 9487 | O14: =SUM(M14:N14) -> 214552
B15: Repair Fund
A16: =+A13+1 -> 10 | B16: 300937_04 | C16: 0.0725 | D16: Model | E16: 24.08.2024 | F16: 173865.5 | G16: 7649 | H16: 13521 | I16: =F16+G16+H16 -> 195035.5 | J16: 200734 | K16: 24.08.2026 | M16: 13521 | N16: 0
F17: =SUM(F16) -> 173865.5 | G17: =SUM(G16) -> 7649 | H17: =SUM(H16) -> 13521 | I17: =SUM(I16) -> 195035.5 | J17: =SUM(J16) -> 200734 | M17: =SUM(M16) -> 13521 | N17: =SUM(N16) -> 0 | O17: =SUM(M17:N17) -> 13521
B18: General Fund
A19: =+A16+1 -> 11 | B19: 300936-04 | C19: 0.0725 | D19: Model | E19: 24.08.2024 | F19: 173865.5 | G19: 7649 | H19: 13521 | I19: =F19+G19+H19 -> 195035.5 | J19: 200734 | K19: 24.08.2026 | M19: 13521 | N19: 0
F20: =SUM(F19) -> 173865.5 | G20: =SUM(G19) -> 7649 | H20: =SUM(H19) -> 13521 | I20: =SUM(I19) -> 195035.5 | J20: =SUM(J19) -> 200734 | M20: =SUM(M19) -> 13521 | N20: =SUM(N19) -> 0 | O20: =SUM(M20:N20) -> 13521
B21: Reserve Fund
A22: =+A19+1 -> 12 | B22: 01266_03 | C22: 0.0665 | D22: MDCC | E22: 26.03.2026 | F22: 47300 | G22: 0 | H22: =51-5 -> 46 | I22: =F22+G22+H22 -> 47346 | J22: 50525 | K22: 26.03.2027 | M22: 3444 | N22: 51 | Q22: =350-345 -> 5
A23: 13 | B23: 19877_00 | C23: 0.0665 | D23: MDCC | E23: 30.03.2026 | F23: 52000 | G23: 0 | H23: =18-2 -> 16 | I23: =F23+G23+H23 -> 52016 | J23: 55545 | K23: 30.03.2027 | M23: 0 | N23: 18
F24: =SUM(F22:F23) -> 99300 | G24: =SUM(G22:G23) -> 0 | H24: =SUM(H22:H23) -> 62 | I24: =SUM(I22:I23) -> 99362 | J24: =SUM(J22:J23) -> 106070 | M24: =SUM(M22:M23) -> 3444 | N24: =SUM(N22:N23) -> 69 | O24: =SUM(M24:N24) -> 3513
B25: Common Amenity Fund
A26: =+A23+1 -> 14 | B26: 16/2002/5080/163126 | C26: 0.0685 | D26: Model | E26: 14.03.2026 | F26: 17444 | G26: 0 | H26: 59 | I26: =F26+G26+H26 -> 17503 | J26: 18670 | K26: 14.03.2027 | M26: 1248 | N26: 0 | P26: =+M26-1189 -> 59
A27: =+A26+1 -> 15 | B27: 006605500001608_01 | C27: 0.0665 | D27: MDCC | E27: 24.03.2026 | F27: 87084 | G27: 0 | H27: =126-13 -> 113 | I27: =F27+G27+H27 -> 87197 | J27: 93021 | K27: 24.03.2027 | M27: 6305 | N27: 126 | P27: =643-630 -> 13
A28: =+A27+1 -> 16 | B28: 006605300019242_01 | C28: 0.0665 | D28: MDCC | E28: 29.03.2026 | F28: 1607 | G28: 0 | H28: 0 | I28: =F28+G28+H28 -> 1607 | J28: 1717 | K28: 29.03.2027 | M28: 119 | N28: 0
A29: =+A28+1 -> 17 | B29: 17799_03 | C29: 0.0665 | D29: MDCC | E29: 29.03.2026 | F29: 67732 | G29: 0 | H29: =37-4 -> 33 | I29: =F29+G29+H29 -> 67765 | J29: 72350 | K29: 29.03.2027 | M29: 4971 | N29: 37 | P29: =502-498 -> 4
F30: =SUM(F26:F29) -> 173867 | G30: =SUM(G26:G29) -> 0 | H30: =SUM(H26:H29) -> 205 | I30: =SUM(I26:I29) -> 174072 | J30: =SUM(J26:J29) -> 185758 | M30: =SUM(M26:M29) -> 12643 | N30: =SUM(N26:N29) -> 163 | O30: =SUM(M30:N30) -> 12806
B31: Education Fund
A32: 18 | B32: 006605300019241_01 | C32: 0.0665 | D32: MDCC | E32: 29.03.2026 | F32: 2925 | G32: 0 | H32: 1 | I32: =F32+G32+H32 -> 2926 | J32: 3124 | K32: 29.03.2027 | M32: 215 | N32: 1
A33: 19 | B33: 16/2002/5080/163127 | C33: 0.0685 | D33: Model | E33: 14.03.2026 | F33: 14953 | G33: 0 | H33: 51 | I33: =F33+G33+H33 -> 15004 | J33: 16004 | K33: 14.03.2027 | M33: 1071 | N33: 0 | P33: =+M33-1020 -> 51
F34: =SUM(F32:F33) -> 17878 | G34: =SUM(G32:G33) -> 0 | H34: =SUM(H32:H33) -> 52 | I34: =SUM(I32:I33) -> 17930 | J34: =SUM(J32:J33) -> 19128 | M34: =SUM(M32:M33) -> 1286 | N34: =SUM(N32:N33) -> 1 | O34: =SUM(M34:N34) -> 1287
B35: Share Capital
A36: 20 | B36: 17436_3 | C36: 0.075 | D36: MDCC | E36: 28.04.2025 | F36: 8250 | G36: 0 | H36: =584-59 -> 525 | I36: =F36+G36+H36 -> 8775 | J36: 8886 | K36: 28.04.2026 | M36: 49 | N36: 584 | P36: 64 | Q36: =+P36-5 -> 59
F37: =SUM(F36) -> 8250 | G37: =SUM(G36) -> 0 | H37: =SUM(H36) -> 525 | I37: =SUM(I36) -> 8775 | J37: =SUM(J36) -> 8886 | M37: =SUM(M36) -> 49 | N37: =SUM(N36) -> 584 | O37: =SUM(M37:N37) -> 633
B38: Major Repair Fund
A39: 21 | B39: 19874_00 | C39: 0.0665 | D39: MDCC | E39: 30.03.2026 | F39: 270000 | G39: 0 | H39: =98-10 -> 88 | I39: =F39+G39+H39 -> 270088 | J39: 288408 | K39: 30.03.2027 | M39: 0 | N39: 98
F40: =SUM(F39) -> 270000 | G40: =SUM(G39) -> 0 | H40: =SUM(H39) -> 88 | I40: =SUM(I39) -> 270088 | J40: =SUM(J39) -> 288408 | M40: =SUM(M39) -> 0 | N40: =SUM(N39) -> 98 | O40: =SUM(M40:N40) -> 98
...

Sheet Sch II
A1: MINJAL CO-OPERATIVE HOUSING SOCIETY LTD
A3: Schedule 2: Details of Fixed Assets as on 31 March 2026
A4: Particulars | B4: Rate % | C4: Opening W.D.V. as on 01.04.2024 | D4: Additions during the year before 30.09.2024 | E4: Additions during the year after 30.09.2024 | F4: Gross Block (at cost) as on 31.03.2025 | G4: Depreciation for the year | H4: Closing W.D.V. as on 31.03.2025
A5: Land and Building at cost | B5: 0 | C5: 1997350 | D5: 0 | E5: 0 | F5: =SUM(C5:E5) -> 1997350 | G5: =F5*B5 -> 0 | H5: =F5-G5 -> 1997350
A6: Furniture and Fixture | B6: 0.1 | C6: 659.94 | D6: 0 | E6: 0 | F6: =SUM(C6:E6) -> 659.94 | G6: =ROUND(F6*B6,0) -> 66 | H6: =F6-G6 -> 593.94
A7: Water Pump | B7: 0.15 | C7: 19206 | D7: 0 | E7: 0 | F7: =SUM(C7:E7) -> 19206 | G7: =ROUND(F7*B7,0) -> 2881 | H7: =F7-G7 -> 16325
A8: CCTV System | B8: 0.15 | C8: 13492 | D8: 0 | E8: 0 | F8: =SUM(C8:E8) -> 13492 | G8: =ROUND(F8*B8,0) -> 2024 | H8: =F8-G8 -> 11468
A9: Total | C9: =SUM(C5:C8) -> 2030707.9 | D9: =SUM(D5:D8) -> 0 | E9: =SUM(E5:E8) -> 0 | F9: =SUM(F5:F8) -> 2030707.9 | G9: =SUM(G5:G8) -> 4971 | H9: =SUM(H5:H8) -> 2025736.9

Sheet Sch III to V
A2: MINJAL CO-OPERATIVE HOUSING SOCIETY LTD
A4: Sch III - Member's Receivable as on 31 March 2026 | H4: Sch IV - Current Liabilities and Provisions
A5: Sr. | B5: Flat | C5: Name | D5: FY 25-26 | H5: FY 2024-25 | I5: Particulars | J5: FY 2025-26
A6: 1 | B6: 08 | C6: Mr. Jagdish J Sharma | D6: 4480 | H6: 1900 | I6: Electricity Charges | J6: 1680
A7: 2 | B7: 09 | C7: Mr. Jagdish Jomdar Sharma | D7: 2128 | H7: 1500 | I7: Professional Fees | J7: 1500
A8: Total | D8: =SUM(D6:D7) -> 6608 | H8: 0 | I8: Sweeper | J8: 2000
H9: 0 | I9: Pumpman | J9: 1100
A10: Sch V - Advances from Members as on 31 March 2026 | H10: 8263 | I10: BMC | J10: 0
A11: Sr. | B11: Flat | C11: Name | D11: FY 25-26 | H11: 2000 | I11: Audit Fee | J11: 2000
A12: 1 | B12: 02 | C12: Ms. Gladys Sequeira | D12: 6089 | H12: 7238 | I12: Water Charges Payable | J12: =Workings!E11+Workings!F11 -> 6915
A13: 2 | B13: 03 | C13: Mr. Ambrose A. D'Souza | D13: 20 | H13: =SUM(H6:H12) -> 20901 | I13: Total | J13: =SUM(J6:J12) -> 15195
A14: 3 | B14: 04 | C14: Mr. Charles Pinto | D14: 4792
A15: 4 | B15: 05 | C15: Mr. Teofilo Carvalho | D15: 19344
A16: 5 | B16: 07 | C16: Mr. Anthony Miranda | D16: 3197
A17: 6 | B17: 12 | C17: Mrs. Tania Ashley Albuquerque | D17: 3434
A18: 7 | B18: 14 | C18: Mr. Arun Jerome D''Silva | D18: 802
A19: 8 | B19: 15 | C19: Ms. Cecil D'Cunha | D19: 29
A20: Total | D20: =SUM(D12:D19) -> 37707

Sheet BRS
B2: MINJAL CO-OPERATIVE HOUSING SOCIETY LTD
B4: Mumbai District Bank Reconciliation Statement as on 31st March 2026
D5: Amount
B6: Bank balance as per system (Book Balance) | D6: 297391.19
B8: Add: | C8: Chq issued but not presented in bank | D8: 0
B10: Bank balance as per Passbook | D10: =SUM(D6:D8) -> 297391.19
B13: Model Bank Reconciliation Statement as on 31st March 2026
D14: Amount
B15: Bank balance as per system (Book Balance) | D15: 598161.16
B17: Less: | C17: Cheque presented but not updated in the system | D17: =G17 -> 0
B20: Bank balance as per Passbook | D20: =D15-D17 -> 598161.16

Sheet Workings
B2: Note: Workings Page is not the be printed
B4: Water Charges: | E4: PNH5140001 | F4: PNH5141005
B5: 45670 | C5: 45758 | D5: =C5-B5 -> 88 | E5: 3370 | F5: 4796
B6: 45748 | C6: 45758 | D6: =C6-B6+1 -> 11 | E6: =ROUND(E5*D6/D5,0) -> 421 | F6: =ROUND(D6*F5/D5,0) -> 600
B7: =C6 -> 45758 | C7: 45849 | D7: =C7-B7 -> 91 | E7: 3427 | F7: 4803
B8: =C7 -> 45849 | C8: 45943 | D8: =C8-B8 -> 94 | E8: 3546 | F8: 4845
B9: =C8 -> 45943 | C9: 46035 | D9: =C9-B9 -> 92 | E9: 3471 | F9: 4752
D10: =SUM(D6:D9) -> 288 | E10: =SUM(E6:E9) -> 10865 | F10: =SUM(F6:F9) -> 15000
B11: =C9 -> 46035 | C11: 46112 | D11: =C11-B11 -> 77 | E11: =ROUND(E10*D11/D10,0) -> 2905 | F11: =ROUND(D11*F10/D10,0) -> 4010 | G11: Provision
D12: =D10+D11 -> 365 | E12: =E10+E11 -> 13770 | F12: =F10+F11 -> 19010
B15: Pest Control Expenses
B16: 46054 | C16: 46418 | D16: =+C16-B16+1 -> 365 | E16: 4500
B17: 46113 | C17: =+C16 -> 46418 | D17: =+C17-B17+1 -> 306 | E17: =ROUND(E16*D17/D16,0) -> 3773 | G17: Prepaid
B19: Insurance Expenses
B20: 45936 | C20: 46300 | D20: =+C20-B20+1 -> 365 | E20: 9525
B21: 46113 | C21: =+C20 -> 46300 | D21: =+C21-B21+1 -> 188 | E21: =ROUND(E20*D21/D20,0) -> 4906 | G21: Prepaid
