Workbook

Sheet BS
A1: DAVE DOLL CO-OPERATIVE HOUSING SOCIETY LTD
A2: =IE!A2 -> (Regd. No. : BOM / WP / HSG / TC / 9214 / 1995-96)
A3: D'Monte Lane, C.S.T. No. 520/521/522, Orlem, Malad(West), Mumbai, Maharashtra - 400064
A4: Balance Sheet as at March 31, 2026
H5: =IE!H5 -> (Amt. in Rs.)
A6: 45747 | B6: LIABILITIES | D6: 46112 | E6: =A6 -> 45747 | F6: ASSETS | H6: =D6 -> 46112
B7: Authorised Share Capital | F7: Cash and Bank Balances:
A8: 100000 | B8: ( 2000 Share of ₹ 50/- each ) | D8: 100000 | E8: 3586 | F8: Cash in Hand | G8: 1625
E9: 41438.92 | F9: Citizen Credit Co-op Bank | G9: 155828.57
B10: Issues, Subscribed and Paid Up Share Capital | E10: 5059.9 | F10: MDCC Bank | G10: 4400.9
A11: 9000 | B11: ( 180 Shares of ₹ 50/- each ) | D11: 9000 | E11: 166102.52 | F11: Saraswat Co-op. Bank | G11: 171206.52
E12: 39353 | F12: Citizen Credit Co-op Bank (Repair Fund) | G12: 40482 | H12: =SUM(G8:G12) -> 373542.99
B13: Reserves and Surplus:
B14: (i) General Reserve Fund | F14: Investments:
A15: 63364 | B15: Bal as per last balance sheet | C15: =SUM(A15:A18) -> 34256 | E15: 13000 | F15: 13 Shares of MDCC Bank of @ Rs.1000/- | G15: 13000
A16: 200 | B16: Add: Additions during the year | C16: 0 | E16: 193740 | F16: Fixed Deposits - Schedule A | G16: ='FD-Sch'!E17 -> 233259
A17: =IE!A52 -> 9631 | B17: Add: 25% of Surplus transferred | C17: =IE!D52 -> 0 | E17: 18256 | F17: Accrued Interest on Fixed Deposits | G17: 15897 | H17: =SUM(G15:G17) -> 262156
A18: -38939 | B18: Less: Major Repair Expenses | C18: 0 | D18: =SUM(C15:C18) -> 34256
B19: (ii) Sinking Fund | F19: Sundry Debtors :
A20: 296266 | B20: As per last balance sheet | C20: =SUM(A20:A22) -> 329855 | E20: 11947 | F20: Member's Receivables - Schedule B | H20: =Members!E6 -> 0
A21: 21600 | B21: Add: Additions during the year | C21: 21600
A22: =-IE!E26 -> 11989 | B22: Add: Interest earned during the year | C22: =-IE!G26 -> 15160 | D22: =SUM(C20:C22) -> 366615
B23: (iii) Repair Fund | F23: Fixed Assets:
A24: 304498 | B24: Bal as per last balance sheet | C24: =SUM(A24:A26) -> 0 | F24: (i) Furniture and Fixture
A25: 56520 | B25: Add: Additions during the year | C25: 56520 | E25: 7816 | F25: As per last balance sheet | G25: 7034
A26: -361018 | B26: Less: Major Repair Expenses | C26: 0 | D26: =SUM(C24:C26) -> 56520 | E26: -782 | F26: Less: Depreciation @ 10% | G26: =-ROUND(G25*10%,0) -> -703 | H26: =SUM(G25:G26) -> 6331
B27: (iv) Lift Repair Fund | F27: (ii) Water Pump
A28: 163800 | B28: Bal as per last balance sheet | C28: =SUM(A28:A30) -> 155433 | E28: 375 | F28: As per last balance sheet | G28: 319
A29: 25200 | B29: Add: Additions during the year | C29: 25200 | E29: -56 | F29: Less: Depreciation @ 15% | G29: =-ROUND(G28*15%,0) -> -48 | H29: =SUM(G28:G29) -> 271
A30: -33567 | B30: Less: Expenses incurred during the year | C30: 0 | D30: =SUM(C28:C30) -> 180633
B31: (v) Major Repair Fund | F31: (iii) CCTV
A32: 62079 | B32: Bal as per last balance sheet | C32: =SUM(A32:A34) -> 0 | E32: 24258 | F32: As per last balance sheet | G32: 20619
A33: 64800 | B33: Add: Additions during the year | C33: 64800 | E33: -3639 | F33: Less: Depreciation @ 15% | G33: =-ROUND(G32*15%,0) -> -3093 | H33: =SUM(G32:G33) -> 17526
A34: -126879 | B34: Less: Expenses incurred during the year | C34: -10000 | D34: =SUM(C32:C34) -> 54800
B35: (vi) Conveyance Fund | F35: Other Current Assets:
A36: 319604 | B36: Bal as per last balance sheet | C36: =SUM(A36:A37) -> 166102 | E36: 1590 | F36: Deposit with Adani Electricity | G36: 1590
A37: -153502 | B37: Less: PY expenses taken to IE now adj | C37: 0 | D37: =SUM(C36:C37) -> 166102 | E37: 0 | F37: Advance Payment to Vendors | G37: 0 | H37: =SUM(G36:G37) -> 1590
B38: (vii) Education and Training Fund
A39: 882 | B39: Bal as per last balance sheet | C39: =SUM(A39:A40) -> 882 | F39: Prepaid Expenses:
A40: 0 | B40: Less: Expenses incurred during the year | C40: 0 | D40: =SUM(C39:C40) -> 882 | E40: 6183 | F40: Prepaid Lift Maintenance | G40: 6638
...

Sheet IE
A1: =BS!A1 -> DAVE DOLL CO-OPERATIVE HOUSING SOCIETY LTD
A2: (Regd. No. : BOM / WP / HSG / TC / 9214 / 1995-96)
A3: =BS!A3 -> D'Monte Lane, C.S.T. No. 520/521/522, Orlem, Malad(West), Mumbai, Maharashtra - 400064
A4: Income and Expenditure Account for the year ended March 31, 2026
H5: (Amt. in Rs.)
A6: =BS!A6 -> 45747 | B6: EXPENDITURE | D6: =BS!D6 -> 46112 | E6: =A6 -> 45747 | F6: INCOME | H6: =D6 -> 46112
B7: To Property Tax: | F7: By Maintenance Income:
A8: 59012 | B8: Property Tax | D8: 81134 | E8: 59016 | F8: Municipal Tax | G8: =75612+5532 -> 81144
E9: 87264 | F9: Maintenance Charges | G9: 87264
B10: To Electricity Charges: | E10: 47088 | F10: Electricity Charges | G10: 47088
A11: 40371.68 | B11: Common Area Electricity Charges | D11: 50176.35 | E11: 41760 | F11: Water Charges | G11: 41760
B12: To Water Expenses: | E12: 10800 | F12: Insurance Charges | G12: 10800
A13: 35082 | B13: Water Expenses | C13: 26476 | E13: 6344 | F13: Late Payment Interest | G13: 5114
A14: 0 | B14: Water Tanker Expenses | C14: 0 | E14: 2205 | F14: Non Occupancy Charges | G14: =2695+163 -> 2858
A15: 0 | B15: Water Tank Cleaning Charges | C15: 2600 | D15: =SUM(C13:C15) -> 29076 | E15: 14000 | F15: Parking Charges | G15: =6000+8400+1000 -> 15400
B16: To Salary Expenses: | E16: 25200 | F16: Lift Repair Fund | G16: 25200
A17: 30000 | B17: Salary Expenses | C17: 32900 | E17: 21600 | F17: Sinking Fund | G17: 21600
A18: 2500 | B18: Bonus | C18: 0 | D18: =SUM(C17:C18) -> 32900 | E18: 56520 | F18: Repair Fund | G18: 56520
B19: To Repair and Maintenance: | E19: 64800 | F19: Major Repair | G19: 64800 | H19: =SUM(G8:G19) -> 459548
A20: 33567 | B20: Lift Maintenance | C20: 15475
A21: -33567 | B21: Less: Trfd to Lift Repair Fund | C21: 0
A22: 5700 | B22: Electrical Repair | C22: 2380
A23: 14304 | B23: Other Repair Maintenance | C23: 14280 | F23: By Interest Income:
A24: 3680 | B24: Plumbing Repairs | C24: 0 | E24: 14023 | F24: Interest on Savings Deposit | G24: 8592
A25: 0 | B25: Major Repair | C25: 10000 | E25: 11989 | F25: Interest on Fixed Deposits | G25: 15160
A26: 0 | B26: Less: trf to Major Repairs | C26: -10000 | E26: -11989 | F26: Less: Transferred to Sinking Fund | G26: -15160 | H26: =SUM(G24:G26) -> 8592
A27: 5937 | B27: Pest Control Expenses | C27: 7715 | D27: =SUM(C20:C27) -> 39850
B28: To Service Charges:
A29: 12592 | B29: Accounting Charges | C29: 12592
A30: 19808 | B30: Insurance Expense | C30: 19500
A31: 826 | B31: Subscription Federation | C31: 0
A32: 2000 | B32: Audit Fees | C32: 2500
A33: 4500 | B33: Professional Fees | C33: 1500 | D33: =SUM(C29:C33) -> 36092
B34: To Office Charges:
A35: 1374 | B35: Printing and Stationery | C35: 5642
A36: 4477 | B36: Depreciation on Fixed Assets | C36: 3844
A37: 0 | B37: Meeting Expenses | C37: 1200
A38: 1270 | B38: Office Expenses | C38: 300
A39: 472 | B39: Bank Charges | C39: 177
A40: 70 | B40: Income Tax Expenses | C40: 0
...

Sheet FD-Sch
A1: =BS!A1 -> DAVE DOLL CO-OPERATIVE HOUSING SOCIETY LTD
A2: SCHEDULE - A
A3: Details of Fixed Deposits as at March 31, 2026
L4: (Amt. in Rs.)
A5: Sr. | B5: Certificate No. | C5: Bank | D5: Date of Issue | E5: Amount Deposited | F5: Accrued Int for FY 23-24 | G5: Accrued Int for FY 24-25 | H5: Accrued Int for FY 25-26 | I5: Total Amt Invested | J5: ROI | K5: Maturity Value | L5: Maturity Date
B6: Sinking Fund
A7: 1 | B7: TD0000405493_02 | C7: SCB | D7: 22.06.2025 | E7: 24247 | F7: 0 | G7: 0 | H7: 1265 | I7: =SUM(E7:H7) -> 25512 | J7: 0.066 | K7: 29508 | L7: 22.06.2028
A8: 2 | B8: TD0000405492_03 | C8: SCB | D8: 07.07.2025 | E8: 20310 | F8: 0 | G8: 0 | H8: 1061 | I8: =SUM(E8:H8) -> 21371 | J8: 0.07 | K8: 23334 | L8: 07.07.2027
A9: 3 | B9: TD0000405491_02 | C9: SCB | D9: 14.06.2024 | E9: 16128 | F9: 0 | G9: =919 -> 919 | H9: 1225 | I9: =SUM(E9:H9) -> 18272 | J9: 0.07 | K9: 18636 | L9: 14.07.2026
A10: 4 | B10: TD1000040719_01 | C10: SCB | D10: 22.06.2024 | E10: 25765 | F10: 0 | G10: 1428 | H10: 1954 | I10: =SUM(E10:H10) -> 29147 | J10: 0.07 | K10: 31728 | L10: 22.06.2027
A11: 5 | B11: TD1000053155_01 | C11: SCB | D11: 06.07.2025 | E11: 27684 | F11: 0 | G11: 0 | H11: 1452 | I11: =SUM(E11:H11) -> 29136 | J11: 0.07 | K11: 31806 | L11: 06.07.2027
A12: 6 | B12: TD1000376662_02 | C12: SCB | D12: 28.06.2025 | E12: 26033 | F12: 0 | G12: 0 | H12: 1411 | I12: =SUM(E12:H12) -> 27444 | J12: 0.07 | K12: 28064 | L12: 28.07.2026
A13: 7 | B13: TD1000692312_02 | C13: SCB | D13: 07.03.2026 | E13: 27092 | F13: 0 | G13: 0 | H13: 118 | I13: =SUM(E13:H13) -> 27210 | J13: 0.065 | K13: 32874 | L13: 07.03.2029
A14: 8 | B14: TD1001139004 | C14: SCB | D14: 22.03.2024 | E14: 22000 | F14: 21 | G14: 1606 | H14: 1723 | I14: =SUM(E14:H14) -> 25350 | J14: 0.07 | K14: 27092 | L14: 07.03.2026
A15: 9 | B15: TD1001586949 | C15: SCB | D15: 29.03.2025 | E15: 22000 | F15: 0 | G15: 13 | H15: 1698 | I15: =SUM(E15:H15) -> 23711 | J15: 0.075 | K15: 24290 | L15: 29.07.2026
A16: 10 | B16: 101043021006026 CCB SF | C16: CCB | D16: 30.03.2026 | E16: 22000 | F16: 0 | G16: 0 | H16: 3 | I16: =SUM(E16:H16) -> 22003 | J16: 0.056 | K16: 22611 | L16: 27.09.2026
A17: Grant Total | E17: =SUM(E7:E16) -> 233259 | F17: =SUM(F7:F16) -> 21 | G17: =SUM(G7:G16) -> 3966 | H17: =SUM(H7:H16) -> 11910 | I17: =SUM(I7:I16) -> 249156 | K17: =SUM(K7:K16) -> 269943

Sheet Members
B1: DAVE DOLL CO-OPERATIVE HOUSING SOCIETY LTD.
B2: Schedule B: Member's Receivable as on 31 March 2026
B4: Sr. No. | C4: Flat No. | D4: Name of the Member | E4: Amount
E5: 0
B6: Total | E6: =SUM(E5:E5) -> 0
B8: Schedule C: Member's Advances as on 31 March 2026
B10: Sr. No. | C10: Flat No. | D10: Name of the Member | E10: Amount
B11: 1 | C11: 12 | D11: Mr. Ralph D'Souza | E11: 58
B12: Total | E12: =SUM(E11:E11) -> 58
B16: DAVE DOLL CO-OPERATIVE HOUSING SOCIETY LTD
C17: Schedule D: Vendor's Payable as on March 31, 2026
C18: FY 2024-25 | D18: Vendor Name | E18: FY 2025-26
C19: 4190 | D19: Adani Electricity | E19: 0
C20: 59160 | D20: BMC - Water Expenses | E20: 6527
C21: 1000 | D21: Pumpman | E21: 0
C22: 1500 | D22: Sweeper | E22: 0
C23: 9796 | D23: AGM Constructions | E23: 9796
C24: 4000 | D24: Audit Fees | E24: 4000
C25: 2210 | D25: US Elevators | E25: 2210
C26: 0 | D26: Electricity | E26: 4190
C27: 0 | D27: Water chargegse | E27: 5463
C28: 3000 | D28: Professional Fees | E28: 3000
C29: =SUM(C19:C28) -> 84856 | D29: Total | E29: =SUM(E19:E28) -> 35186

Sheet Vendors
A1: DAVE DOLL CO-OPERATIVE HOUSING SOCIETY LTD
B2: Schedule D: Vendor's Payable as on March 31, 2026
B3: FY 2024-25 | C3: Vendor Name | D3: FY 2025-26
B4: 4190 | C4: Adani Electricity | D4: 0
B5: 59160 | C5: BMC - Water Expenses | D5: 6527
B6: 1000 | C6: Pumpman | D6: 0
B7: 1500 | C7: Sweeper | D7: 0
B8: 9796 | C8: AGM Constructions | D8: 9796
B9: 4000 | C9: Audit Fees | D9: 4000
B10: 2210 | C10: US Elevators | D10: 2210
B11: 0 | C11: Electricity | D11: 4190
B12: 0 | C12: Water chargegse | D12: 5463
B13: 3000 | C13: Professional Fees | D13: 3000
B14: =SUM(B4:B13) -> 84856 | C14: Total | D14: =SUM(D4:D13) -> 35186

Sheet BRS
B1: DAVE DOLL CO-OPERATIVE HOUSING SOCIETY LIMITED
B2: Citizen Credit Co-op Bank Reconciliation Statement as of March 31, 2026
C3: Particulars | D3: Amount
C4: Balance as per System (Book Balance) | D4: 155828.57
C6: Balance as per Bank Passbook | D6: =D4 -> 155828.57
B9: Citizen Credit Repair Fund Reconciliation Statement as of March 31, 2026
C10: Particulars | D10: Amount
C11: Balance as per System (Book Balance) | D11: 40482
C13: Balance as per Bank Passbook | D13: =D11 -> 40482
B16: Mumbai District Co-op Bank Reconciliation Statement as of March 31, 2026
C17: Particulars | D17: Amount
C18: Balance as per System (Book Balance) | D18: 4400.9
C20: Balance as per Bank Passbook | D20: =D18 -> 4400.9
B23: Saraswat Bank Reconciliation Statement as of March 31, 2026
C24: Particulars | D24: Amount
C25: Balance as per System (Book Balance) | D25: 171206.52
C28: Balance as per Bank Passbook | D28: =D25 -> 171206.52

Sheet Workings
B1: Note: Workings Page is not the be printed
B3: Water Charges: | E3: PNH5140001
B4: 44937 | C4: 45027 | D4: =+C4-B4 -> 90 | E4: 7137
B5: =+B4 -> 44937 | C5: 45016 | D5: =+C5-B5 -> 79 | E5: 6344
B6: 45017 | C6: 45027 | D6: =D4-D5 -> 11 | E6: =E4-E5 -> 793
B7: 45028 | C7: 45382 | D7: =+C7-B7 -> 354 | E7: =ROUND(D7*E6/D6,0) -> 25520
B8: 45017 | C8: 45382 | D8: =SUM(D6:D7) -> 365 | E8: =SUM(E6:E7) -> 26313
B10: 46035 | C10: 46112 | D10: =+C10-B10 -> 77 | E10: =ROUND((G10/H10)*D10,0) -> 5463 | F10: Provision for FY 25-26 | G10: 6527 | H10: 92 | I10: days | J10: bill received from 13.10.25 to 13.01.26
B13: Lift AMC
B14: 45901 | C14: 46265 | D14: 12 | E14: 15930
B15: 46113 | C15: =C14 -> 46265 | D15: 5 | E15: =ROUND((E14*D15)/D14,0) -> 6638 | F15: Prepaid
E16: =E14-E15 -> 9292 | F16: Trfd to Lift Repair Fund
B18: Pest Control Expenses
B19: 45744 | C19: 46108 | D19: =C19-B19+1 -> 365 | E19: 7800
B20: 45748 | C20: 46108 | D20: =C20-B20+1 -> 361 | E20: =ROUND((E19*D20)/D19,0) -> 7715 | F20: Prepaid
B23: Insurance Expenses
B24: 45817 | C24: 46181 | D24: =+C24-B24+1 -> 365 | E24: 19500
B25: 46113 | C25: =C24 -> 46181 | D25: =+C25-B25+1 -> 69 | E25: =ROUND(E24*D25/D24,0) -> 3686 | F25: Prepaid
