Workbook

Sheet BS 
A1: PRATHAMESH HARMONY "B" WING CO-OP. HOUSING SOCIETY LTD.
A2: (Regd. No. MUM/WP/HSG/TC/15332/2012-13)
A3: BALANCE SHEET AS ON 31ST MARCH 2026
H4: (Amt in Rs.)
A5: Previous Year 2024-25 | B5: Liabilities | D5: Current Year 2025-26 | E5: =A5 -> Previous Year 2024-25 | F5: Assets | H5: =D5 -> Current Year 2025-26
B6: Authorised Share Capital | F6: Cash & Bank Balances
A7: 100000 | B7: (2000 Shares of Rs.50/- each) | D7: 100000 | E7: 6030 | F7: Cash in Hand | G7: 2850
E8: 21412 | F8: Mumbai District Central Co-op. Bank | G8: 21412 | I8: MDCC account dormant
B9: Issued, Subscribed and Paid Up Share Capital | E9: 241182.94 | F9: Citizencredit Co-Op Bank Ltd | G9: =BRS!D6 -> 112753.34 | H9: =SUM(G7:G9) -> 137015.34
A10: 9000 | B10: (180 Shares of Rs.50/- each) | D10: 9000
F11: Investments
B12: Reserve and Other Funds | E12: 1857802 | F12: Fixed Deposit - ( As per Schedule I ) | G12: ='Sch I FD'!C44 -> 1887491
B13: (i) General Reserve Fund | E13: 34561 | F13: Accrued Interest - FD | G13: ='Sch I FD'!F45 -> 91548 | H13: =SUM(G12:G13) -> 1979039
A14: 368126.46 | B14: Bal as per last Balance Sheet | C14: =SUM(A14:A17) -> 139617.46
A15: 14761 | B15: Add: Int. During the year | C15: =-'IE '!G22 -> 15952 | F15: Deposits
A16: -252270 | B16: Less: Spent During the year | C16: ='Sch Receivable & Payable'!F49 -> 0 | E16: 11638.87 | F16: Security Deposit - Adani Electricity | H16: =11167.72+471.15 -> 11638.87
A17: ='IE '!A32 -> 9000 | B17: Add: 1/4 th Trfd from I & Exp A/c. | C17: ='IE '!C32 -> 0 | D17: =SUM(C14:C17) -> 155569.46
F18: Sundry Debtors, Loans & Advances
B19: (ii) Sinking Fund | E19: 10700.66 | F19: Receivables from Adani | G19: 10700.66
A20: 292715 | B20: Bal as per last Balance Sheet | C20: =SUM(A20:A22) -> 340852 | E20: 45566 | F20: TDS Receivable | G20: 58986
A21: 29808 | B21: Additional During the year | C21: 29808 | E21: 232381 | F21: Members Dues-(As per Schedule II ) | G21: ='Sch Receivable & Payable'!F11 -> 86394
A22: 18329 | B22: Add: Int. During the year | C22: =-'IE '!G25 -> 18704 | D22: =SUM(C20:C22) -> 389364 | E22: 86303 | F22: Advance Payment to Vendors (Sch VI) | G22: ='Sch Receivable & Payable'!F33 -> 85500 | H22: =SUM(G19:G22) -> 241580.66
B23: (iii) Repair Fund
A24: 1159188 | B24: Bal as per last Balance Sheet | C24: =SUM(A24:A27) -> 593562 | F24: Fixed Asset
A25: 89640 | B25: Add: Additional During the year | C25: 89640 | E25: 17867760 | F25: (As per Schedule IV) | H25: ='Sch IV Fixed Assets'!H16 -> 17858257
A26: -698000 | B26: Less: Spent During the year | C26: ='Sch Receivable & Payable'!F47 -> 0
A27: 42734 | B27: Less: Int. During the year | C27: =-'IE '!G23 -> 40276 | D27: =SUM(C24:C27) -> 723478 | F27: Other Assets
B28: (iv) Major Repair Fund | F28: Prepaid Expenses
A29: 922861.52 | B29: Bal as per last Balance Sheet | C29: =SUM(A29:A31) -> 783825.52 | E29: 3333 | F29: Lift Maintenance | G29: 3333
A30: 46814 | B30: Add: Int. During the year | C30: =-'IE '!G24 -> 57142 | E30: 6833 | F30: Pest Control Expenses | G30: 0 | H30: =SUM(G29:G30) -> 3333
A31: -185850 | B31: Less: Spent During the year | C31: ='Sch Receivable & Payable'!F48 -> 0 | D31: =SUM(C29:C31) -> 840967.52
B32: (v) Education & Training Fund
A33: 20777 | B33: Bal as per last Balance Sheet | C33: =SUM(A33:A36) -> 23963
A34: 2160 | B34: Add: Contribution from Members | C34: 2160
A35: 0 | B35: Less: Training Costs incurred | C35: -1770
A36: 1026 | B36: Add: Arrs. collected from Members | C36: =-'IE '!G26 -> 1409 | D36: =SUM(C33:C36) -> 25762
B38: Members Contribution towards
A39: 17803000 | B39: Towards Land and Building | D39: 17803000
B41: Current Liabilities & Provisions
A42: 9748 | B42: Advance from Members - (Sch III ) | C42: ='Sch Receivable & Payable'!F18 -> 1021
...

Sheet IE 
A1: PRATHAMESH HARMONY "B" WING CO-OP. HOUSING SOCIETY LTD.
A2: (Regd. No. MUM/WP/HSG/TC/15332/2012-13)
A3: Income & Expenditure Account for the year ended March 31, 2026
H4: (Amt. In Rs.)
A5: Previous Year 2024-25 | B5: Expenditures | D5: Current Year 2025-26 | E5: =A5 -> Previous Year 2024-25 | F5: Income | H5: =D5 -> Current Year 2025-26
B6: To Property Expenses | F6: By Members Contribution Towards
A7: 366242 | B7: Municipal Tax | C7: 485016 | E7: 332784 | F7: Municipal Taxes | G7: =414880+41050 -> 455930
A8: 182570 | B8: Electricity Expenses | C8: 126690 | E8: 237600 | F8: Electricity Charges | G8: 237600
A9: 84256 | B9: Water Expenses | C9: 75765 | D9: =SUM(C7:C9) -> 687471 | E9: 86400 | F9: Water Charges | G9: 86400
B10: To Lift Maintenance | E10: 172800 | F10: Service Charges | G10: 172800
A11: 48334 | B11: Lift AMC | D11: 40000 | E11: 21600 | F11: Lift Maintenance Charges | G11: 21600
E12: 18000 | F12: Non Occupancy Charges | G12: =15900 -> 15900
A13: 1217914 | B13: To Repair & Maintenance (As per Sch. VII) | C13: =SUM('Sch Receivable & Payable'!F39:F46) -> 266289 | E13: 85600 | F13: Parking Charges | G13: =21300+19600+36000+200 -> 77100
A14: -1136120 | B14: Less: Trfd to Major Repair Fund | C14: =SUM('Sch Receivable & Payable'!F47:F49) -> 0 | D14: =SUM(C13:C14) -> 266289 | E14: 43793 | F14: Late Payment Expenses | G14: 21806
B15: To Service Charges | E15: 9100 | F15: Penalty & Fines | G15: =6100+3500 -> 9600
A16: 133680 | B16: Security Expenses | C16: 99984 | E16: 1500 | F16: Shifting Charges | G16: 0
A17: 11189 | B17: Depreciation | C17: ='Sch IV Fixed Assets'!G16 -> 9502.5 | E17: 3715 | F17: Other Charges | G17: 0 | H17: =SUM(G7:G17) -> 1098736
A18: 2588.26 | B18: Bank Charges | C18: 849.6
A19: 0 | B19: Water Tanker Cleaning Exp | C19: 9350 | F19: By Interest Income
A20: 2077 | B20: Pest Control Charges | C20: 6833 | D20: =SUM(C16:C20) -> 126519.1 | E20: 10742 | F20: Saving Bank Interest | H20: 7338
B21: To Office Expenses | E21: 124205 | F21: Interest Income - Fixed Deposit | G21: 134082
A22: 834 | B22: Festival Expenses | C22: 0 | E22: -14761 | F22: Less: Trf to Reserve Fund | G22: -15952
A23: 12592 | B23: Accounting Charges | C23: 12592 | E23: -42734 | F23: Less: Trf to Repair Fund | G23: -40276
A24: 5383 | B24: Printing and Stationary | C24: 2231 | E24: -46814 | F24: Less: Trf to Major Repair Fund | G24: -57142
A25: 2450 | B25: Meeting Expenses | C25: 820 | E25: -18329 | F25: Less: Trf to Sinking Fund | G25: -18704
A26: 9184 | B26: Miscellaneous Expenses | C26: 874 | E26: -1026 | F26: Less: Trf to Education Fund | G26: -1409 | H26: =SUM(G20:G26) -> 599
A27: 0 | B27: Legal & Professional Fees | C27: 3000
A28: 42500 | B28: Salary Expenses & Bonus | C28: 72209 | E28: 0 | F28: Scrap Sale | G28: 3300
A29: 2500 | B29: Audit Fees | C29: 2500 | E29: 0 | F29: Interest Income - Security Deposit | G29: 0 | H29: =SUM(G28:G29) -> 3300
A30: 0 | B30: Income Tax Expense | C30: 13420 | D30: =SUM(C22:C30) -> 107646
A32: 9000 | B32: To 1/4 th Trfd to Gen. Reserve Fund
A33: =E34-SUM(A7:A32) -> 27001.74 | B33: To Excess of Income over Expenditure | F33: To Excess of Expenditure over Income | H33: =D34-SUM(H7:H32) -> 117952.1
A34: =SUM(A6:A33) -> 1024175 | B34: Total | D34: =SUM(D7:D33) -> 1227925.1 | E34: =SUM(E7:E32) -> 1024175 | F34: Total | H34: =SUM(H7:H33) -> 1227925.1
A36: As per my report of even date
E37: For Prathamesh Harmony " B " Wing Co-op. Housing Society Ltd.
A41: Shri. Bharat C. Boridkar
A42: Govt. Certified Panel Auditor | E42: (Chairman Hon. Secretary Hon. Treasurer)
A43: [Panel No.: Mumbai-4/C1/1011404]
A44: 46277
I46: =D34-H34 -> 0
...

Sheet Sch I FD
A1: PRATHAMESH HARMONY "B" WING CO-OP. HOUSING SOCIETY LTD.
A2: Schedule I -Details of Fixed Deposits as on 31st March 2026
A4: Certificate No. | B4: Date | C4: Amount Invested | D4: Accrued Int. 23-24 | E4: Accrued Int. 24-25 | F4: Accrued Int. 25-26 | G4: Total | H4: Maturity Date | I4: Maturity Value | J4: Interest % | K4: Bank | M4: ren int | N4: rent tds | O4: accd int | P4: accd td | Q4: net int | R4: net tds | T4: .
A5: Sinking Fund | Q5: =+M5+O5 -> 0 | R5: =+N5+P5 -> 0
A6: 209010000304626 R04 | B6: 29.11.2025 | C6: 50000 | D6: 0 | E6: 0 | F6: 0 | G6: =SUM(C6:F6) -> 50000 | H6: 29.11.2026 | I6: 50000 | J6: 0.071 | K6: Citizen Bank | L6: . | O6: 3406 | P6: 342 | Q6: =+M6+O6 -> 3406 | R6: =+N6+P6 -> 342
A7: 310849_02 | B7: 17.02.2025 | C7: 61451 | D7: 0 | E7: 487 | F7: =4602-462 -> 4140 | G7: =SUM(C7:F7) -> 66078 | H7: 17.02.2027 | I7: 70948 | J7: 0.0725 | K7: Citizen Bank | L7: Ok | O7: 4602 | P7: 462 | Q7: =+M7+O7 -> 4602 | R7: =+N7+P7 -> 462
A8: 310850_02 | B8: 17.02.2025 | C8: 61451 | D8: 0 | E8: 487 | F8: =4602-462 -> 4140 | G8: =SUM(C8:F8) -> 66078 | H8: 17.02.2027 | I8: 70948 | J8: 0.0725 | K8: Citizen Bank | L8: Ok | O8: 4602 | P8: 462 | Q8: =+M8+O8 -> 4602 | R8: =+N8+P8 -> 462
A9: 2090100003032195_03 | B9: 03.08.2025 | C9: 31825 | D9: 0 | E9: 0 | F9: =1327-133 -> 1194 | G9: =SUM(C9:F9) -> 33019 | H9: 03.08.2026 | I9: 33846 | J9: 0.0635 | K9: Citizen Bank | L9: Ok | M9: 729 | N9: 73 | O9: =2056-M9 -> 1327 | P9: =206-N9 -> 133 | Q9: =+M9+O9 -> 2056 | R9: =+N9+P9 -> 206
A10: 2090100003032357_03 | B10: 30.03.2025 | C10: 60530 | D10: 0 | E10: 0 | F10: =6+3 -> 9 | G10: =SUM(C10:F10) -> 60539 | H10: 30.03.2026 | I10: 60931 | J10: 0.071 | K10: Citizen Bank | L10: . | M10: 4032 | N10: 403 | O10: =4038-M10 -> 6 | P10: =400-N10 -> -3 | Q10: =+M10+O10 -> 4038 | R10: =+N10+P10 -> 400
A11: Total :- | C11: =SUM(C6:C10) -> 265257 | D11: =SUM(D6:D10) -> 0 | E11: =SUM(E6:E10) -> 974 | F11: =SUM(F6:F10) -> 9483 | G11: =SUM(G6:G10) -> 275714 | I11: =SUM(I6:I10) -> 286673 | Q11: =+M11+O11 -> 0 | R11: =+N11+P11 -> 0
Q12: =+M12+O12 -> 0 | R12: =+N12+P12 -> 0
A13: Repair Fund | Q13: =+M13+O13 -> 0 | R13: =+N13+P13 -> 0
A14: 2090100003031820_03 | B14: 16.09.2025 | C14: 68384 | D14: 0 | E14: 0 | F14: =2339-235 -> 2104 | G14: =SUM(C14:F14) -> 70488 | J14: 0.071 | K14: Citizen Bank | L14: . | M14: 2107 | N14: 211 | O14: =4446-M14 -> 2339 | P14: =446-N14 -> 235 | Q14: =+M14+O14 -> 4446 | R14: =+N14+P14 -> 446
A15: 2090100000304618 R04 | B15: 31.10.2025 | C15: 100000 | D15: 0 | E15: 0 | F15: 0 | G15: =SUM(C15:F15) -> 100000 | H15: 31.10.2026 | I15: 100000 | J15: 0.071 | K15: Citizen Bank | L15: . | O15: 6747 | P15: 676 | Q15: =+M15+O15 -> 6747 | R15: =+N15+P15 -> 676
A16: 2090100000304619 R04 | B16: 31.10.2025 | C16: 100000 | D16: 0 | E16: 0 | F16: 0 | G16: =SUM(C16:F16) -> 100000 | H16: 31.10.2026 | I16: 100000 | J16: 0.071 | K16: Citizen Bank | L16: . | O16: 6747 | P16: 676 | Q16: =+M16+O16 -> 6747 | R16: =+N16+P16 -> 676
A17: 2090100000304620 R04 | B17: 31.10.2025 | C17: 100000 | D17: 0 | E17: 0 | F17: 0 | G17: =SUM(C17:F17) -> 100000 | H17: 31.10.2026 | I17: 100000 | J17: 0.071 | K17: Citizen Bank | L17: . | O17: 6747 | P17: 676 | Q17: =+M17+O17 -> 6747 | R17: =+N17+P17 -> 676
A18: 2090100000304621 R04 | B18: 31.10.2025 | C18: 150000 | D18: 0 | E18: 0 | F18: 0 | G18: =SUM(C18:F18) -> 150000 | H18: 31.10.2026 | I18: 150000 | J18: 0.071 | K18: Citizen Bank | L18: Ok | O18: 10119 | P18: 1012 | Q18: =+M18+O18 -> 10119 | R18: =+N18+P18 -> 1012
A19: 2090100003032358_03 | B19: 30.03.2025 | C19: 81989 | D19: 0 | E19: 0 | F19: =10+2 -> 12 | G19: =SUM(C19:F19) -> 82001 | H19: 30.03.2026 | I19: 82533 | J19: 0.071 | K19: Citizen Bank | L19: Ok | M19: 5460 | N19: 546 | O19: 10 | P19: -2 | Q19: =+M19+O19 -> 5470 | R19: =+N19+P19 -> 544
A20: Total :- | C20: =SUM(C14:C19) -> 600373 | D20: =SUM(D14:D19) -> 0 | E20: =SUM(E14:E19) -> 0 | F20: =SUM(F14:F19) -> 2116 | G20: =SUM(G14:G19) -> 602489 | I20: =SUM(I14:I19) -> 532533 | Q20: =+M20+O20 -> 0 | R20: =+N20+P20 -> 0
Q21: =+M21+O21 -> 0 | R21: =+N21+P21 -> 0
A22: Reserve Fund | Q22: =+M22+O22 -> 0 | R22: =+N22+P22 -> 0
A23: 209010000304625 R04 | B23: 29.11.2025 | C23: 50000 | D23: 0 | E23: 0 | F23: 0 | G23: =SUM(C23:F23) -> 50000 | H23: 29.11.2026 | I23: 50000 | J23: 0.071 | K23: Citizen Bank | L23: . | O23: 3406 | P23: 342 | Q23: =+M23+O23 -> 3406 | R23: =+N23+P23 -> 342
A24: 2090100000310851_1 | B24: 17.02.2025 | C24: 47921 | D24: 0 | E24: 380 | F24: =3588-360 -> 3228 | G24: =SUM(C24:F24) -> 51529 | H24: 17.02.2027 | I24: 55327 | J24: 0.0725 | K24: Citizen Bank | L24: Ok | O24: 3588 | P24: 360 | Q24: =+M24+O24 -> 3588 | R24: =+N24+P24 -> 360
A25: 101043101000181-1 | B25: 19.12.2024 | C25: 34434 | D25: 0 | E25: 644 | F25: =2643-266 -> 2377 | G25: =SUM(C25:F25) -> 37455 | H25: 19.12.2026 | I25: 39834 | J25: 0.0735 | K25: Citizen Bank | L25: Ok | O25: 2643 | P25: 266 | Q25: =+M25+O25 -> 2643 | R25: =+N25+P25 -> 266
A26: 3032382_03 | B26: 28.04.2025 | C26: 62920 | D26: 0 | E26: 0 | F26: =3976-399 -> 3577 | G26: =SUM(C26:F26) -> 66497 | H26: 28.04.2026 | I26: 67230 | J26: 0.0685 | K26: Citizen Bank | L26: Ok | M26: 326 | N26: 33 | O26: =4302-M26 -> 3976 | P26: =432-N26 -> 399 | Q26: =+M26+O26 -> 4302 | R26: =+N26+P26 -> 432
A27: 3032383_03 | B27: 28.04.2025 | C27: 29445 | D27: 0 | E27: 0 | F27: =1860-189 -> 1671 | G27: =SUM(C27:F27) -> 31116 | H27: 28.04.2026 | I27: 31462 | J27: 0.0685 | K27: Citizen Bank | L27: Ok | M27: 153 | N27: 15 | O27: =2013-M27 -> 1860 | P27: =204-N27 -> 189 | Q27: =+M27+O27 -> 2013 | R27: =+N27+P27 -> 204
A28: Total :- | C28: =SUM(C23:C27) -> 224720 | D28: =SUM(D23:D27) -> 0 | E28: =SUM(E23:E27) -> 1024 | F28: =SUM(F23:F27) -> 10853 | G28: =SUM(G23:G27) -> 236597 | I28: =SUM(I23:I27) -> 243853 | Q28: =+M28+O28 -> 0 | R28: =+N28+P28 -> 0
Q29: =+M29+O29 -> 0 | R29: =+N29+P29 -> 0
A30: Major Repair Fund | Q30: =+M30+O30 -> 0 | R30: =+N30+P30 -> 0
A31: 2090100000310834_1 | B31: 01.10.2024 | C31: 419081 | D31: 0 | E31: 13752 | F31: =32156-3217 -> 28939 | G31: =SUM(C31:F31) -> 461772 | H31: 01.10.2026 | I31: 483846 | J31: 0.0725 | K31: Citizen Bank | L31: Ok | O31: 32156 | P31: 3217 | Q31: =+M31+O31 -> 32156 | R31: =+N31+P31 -> 3217
A32: 2090100003032196_03 | B32: 03.08.2025 | C32: 159170 | D32: 0 | E32: 0 | F32: =6635-656 -> 5979 | G32: =SUM(C32:F32) -> 165149 | H32: 03.08.2026 | I32: 169277 | J32: 0.0635 | K32: Citizen Bank | L32: Ok | M32: 3650 | N32: 365 | O32: =10285-M32 -> 6635 | P32: =1021-N32 -> 656 | Q32: =+M32+O32 -> 10285 | R32: =+N32+P32 -> 1021
A33: 101043101000194-1 | B33: 19.12.2024 | C33: 191526 | D33: 0 | E33: 3590 | F33: =14701-1472 -> 13229 | G33: =SUM(C33:F33) -> 208345 | H33: 19.12.2026 | I33: 221559 | J33: 0.0735 | K33: Citizen Bank | L33: Ok | O33: 14701 | P33: 1472 | Q33: =+M33+O33 -> 14701 | R33: =+N33+P33 -> 1472
A34: Total :- | C34: =SUM(C31:C33) -> 769777 | D34: =SUM(D31:D33) -> 0 | E34: =SUM(E31:E33) -> 17342 | F34: =SUM(F31:F33) -> 48147 | G34: =SUM(G31:G33) -> 835266 | I34: =SUM(I31:I33) -> 874682 | Q34: =+M34+O34 -> 0 | R34: =+N34+P34 -> 0
Q35: =+M35+O35 -> 0 | R35: =+N35+P35 -> 0
A36: Education & Training Fund | Q36: =+M36+O36 -> 0 | R36: =+N36+P36 -> 0
A37: 101043101000173-1 | B37: 19.12.2024 | C37: 18364 | D37: 0 | E37: 343 | F37: =1409-143 -> 1266 | G37: =SUM(C37:F37) -> 19973 | H37: 19.12.2026 | I37: 21244 | J37: 0.0735 | K37: Citizen Bank | L37: Ok | O37: 1409 | P37: 143 | Q37: =+M37+O37 -> 1409 | R37: =+N37+P37 -> 143
A38: Total :- | C38: =SUM(C37) -> 18364 | D38: =SUM(D37) -> 0 | E38: =SUM(E37) -> 343 | F38: =SUM(F37) -> 1266 | G38: =SUM(G37) -> 19973 | I38: =SUM(I37) -> 21244 | Q38: =+M38+O38 -> 0 | R38: =+N38+P38 -> 0
Q39: =+M39+O39 -> 0 | R39: =+N39+P39 -> 0
A40: Share Capital Fund | Q40: =+M40+O40 -> 0 | R40: =+N40+P40 -> 0
A41: 2090100000301240_1 | B41: 29.11.2025 | C41: 9000 | D41: 0 | E41: 0 | F41: 0 | G41: =SUM(C41:F41) -> 9000 | H41: 29.11.2026 | I41: 9000 | J41: 0.071 | K41: Citizen Bank | L41: Ok | M41: 0 | O41: 599 | P41: 61 | Q41: =+M41+O41 -> 599 | R41: =+N41+P41 -> 61
...

Sheet Sch Receivable & Payable
A1: PRATHAMESH HARMONY "B" WING CO-OP. HOUSING SOCIETY LTD.
A3: Schedule II - Members Dues as on 31.03.2026
A5: Sr.No | B5: Block | C5: Flat | D5: FY 2024-25 | E5: Name of the Member | F5: FY 2025-26
A6: 1 | B6: B | C6: 101 | D6: 120596 | E6: Mr.Wilson D'Silva | F6: 35424
A7: 2 | B7: B | C7: 201 | D7: 0 | E7: Mr. Ravi Nair | F7: 5736
A8: 3 | B8: B | C8: 502 | D8: 56227 | E8: Mr.Aycod Raja Nadar & Other | F8: 45228
A9: 4 | B9: B | C9: 602 | D9: 0 | E9: Mr. Edward D'Costa | F9: 6
A10: 5 | B10: B | C10: 801 | D10: 55558 | E10: Mr.Mustaq and Sajida Patel | F10: 0
D11: =SUM(D6:D10) -> 232381 | E11: Total | F11: =SUM(F6:F10) -> 86394
A13: Schedule III - Advance from Members as on 31.03.2026
A15: Sr.No | B15: Block | C15: Flat | D15: =D5 -> FY 2024-25 | E15: Name of the Member | F15: =F5 -> FY 2025-26
A16: 1 | B16: B | C16: 202 | D16: 9733 | E16: Mrs.Anuradha Shetty | F16: 1015
A17: 2 | B17: B | C17: 602 | D17: 15 | E17: Mr.Edward D'Costa & Mrs.Marleta S'Costa | F17: 6
D18: =SUM(D16) -> 9733 | E18: Total | F18: =SUM(F16:F17) -> 1021
A20: Schedule V - Payables as of 31.03.2026
A22: Sr.No | B22: =+D15 -> FY 2024-25 | D22: Particulars | F22: =F15 -> FY 2025-26
A23: 1 | B23: 18390 | D23: Adani | F23: 1080
A24: 2 | B24: 414765 | D24: BMC | F24: 85149
A25: 3 | B25: 22700 | D25: VNF Total Solution | F25: 22700
B26: =B23+B24 -> 433155 | D26: Total | F26: =SUM(F23:F25) -> 108929
A28: Schedule VI - Advance to Vendors as of 31.03.2026
A30: Sr.No | B30: =B22 -> FY 2024-25 | D30: Particulars | F30: =F22 -> FY 2025-26
A31: 1 | B31: 803 | D31: BMC | F31: 0
A32: 2 | B32: 85500 | D32: Shanmugam Jeyaram | F32: 85500
B33: =SUM(B31:C32) -> 86303 | D33: Total | F33: =SUM(F28:F32) -> 85500
C36: Schedule VII - Repair & Maintenace for FY 2025-26
B38: Sr.No | C38: =B22 -> FY 2024-25 | E38: R & M Head | F38: =F22 -> FY 2025-26
B39: 1 | C39: 11601 | E39: Electrical | F39: 11640
B40: 2 | C40: 55180 | E40: Others | F40: =133974+1485 -> 135459
B41: 3 | C41: 7013 | E41: Plumbing | F41: 20590
B42: 4 | C42: 0 | E42: Lift Repairs | F42: 83500
B43: 4 | C43: 0 | E43: Garden Maintenance | F43: 1200
B44: 4 | C44: 0 | E44: CCTV Repairs | F44: 1500
B45: 5 | C45: 8000 | E45: Fire Fighting | F45: 12400
B46: 6 | C46: 1136120 | E46: Major Repairs | F46: 0
B47: 7 | C47: -698000 | E47: Less: Trf to Repair Fund | F47: 0
B48: 8 | C48: -185850 | E48: Less: Trf to Major Repair Fund | F48: 0
B49: 9 | C49: -252270 | E49: Less: Trf to Reserve Fund | F49: 0
C50: =SUM(C39:D49) -> 81794 | E50: Total | F50: =SUM(F39:F49) -> 266289

Sheet Sch IV Fixed Assets
A1: PRATHAMESH HARMONY "B" WING CO-OP. HOUSING SOCIETY LTD.
A3: SCHEDULE IV : FIXED ASSETS
A5: Particulars | B5: Rate % | C5: Opening W.D.V. as on 01.04.2025 | D5: Additions during the year On or before 30.09.2025 | E5: Additions during the year after 30.09.2025 | F5: Gross Block (at cost) as on 31.03.2026 | G5: Depreciation for the year | H5: Closing W.D.V. as on 31.03.2026
A6: Land and Building at cost | B6: 0 | C6: 17803000 | F6: =C6+D6+E6 -> 17803000 | G6: 0 | H6: =F6-G6 -> 17803000
A7: CCTV | B7: 0.15 | C7: 15724.3 | D7: 0 | E7: 0 | F7: =C7+D7+E7 -> 15724.3 | G7: =ROUND(((C7+D7)*B7)+((E7*B7)/2),0)+0.3 -> 2359.3 | H7: =F7-G7 -> 13365
A8: Cupboard | B8: 0.1 | C8: 1673 | D8: 0 | E8: 0 | F8: =C8+D8+E8 -> 1673 | G8: =ROUND(((C8+D8)*B8)+((E8*B8)/2),0) -> 167 | H8: =F8-G8 -> 1506
A9: Furniture & Fixture | B9: 0.1 | C9: 2880.8 | D9: 0 | E9: 0 | F9: =C9+D9+E9 -> 2880.8 | G9: =ROUND(((C9+D9)*B9)+((E9*B9)/2),0)-0.2 -> 287.8 | H9: =F9-G9 -> 2593
A10: Table | B10: 0.1 | C10: 693 | D10: 0 | E10: 0 | F10: =C10+D10+E10 -> 693 | G10: =ROUND(((C10+D10)*B10)+((E10*B10)/2),0) -> 69 | H10: =F10-G10 -> 624
A11: Fire Fighting System | B11: 0.15 | C11: 6221.9 | D11: 0 | E11: 0 | F11: =C11+D11+E11 -> 6221.9 | G11: =ROUND(((C11+D11)*B11)+((E11*B11)/2),0)-0.1 -> 932.9 | H11: =F11-G11 -> 5289
A12: Borewell Account | B12: 0.15 | C12: 1873.3 | D12: 0 | E12: 0 | F12: =C12+D12+E12 -> 1873.3 | G12: =ROUND(((C12+D12)*B12)+((E12*B12)/2),0)+0.3 -> 281.3 | H12: =F12-G12 -> 1592
A13: Intercom System | B13: 0.15 | C13: 6162.6 | D13: 0 | E13: 0 | F13: =C13+D13+E13 -> 6162.6 | G13: =ROUND(((C13+D13)*B13)+((E13*B13)/2),0)-0.4 -> 923.6 | H13: =F13-G13 -> 5239
A14: Water Pump | B14: 0.15 | C14: 29320 | D14: 0 | E14: 0 | F14: =C14+D14+E14 -> 29320 | G14: =ROUND(((C14+D14)*B14)+((E14*B14)/2),0) -> 4398 | H14: =F14-G14 -> 24922
A15: Computer Account | B15: 0.4 | C15: 210.6 | D15: 0 | E15: 0 | F15: =C15+D15+E15 -> 210.6 | G15: =ROUND(((C15+D15)*B15)+((E15*B15)/2),0)-0.4 -> 83.6 | H15: =F15-G15 -> 127
A16: Total | C16: =SUM(C6:C15) -> 17867760 | D16: =SUM(D7) -> 0 | E16: =SUM(E6:E15) -> 0 | F16: =SUM(F6:F15) -> 17867760 | G16: =SUM(G6:G15) -> 9502.5 | H16: =SUM(H6:H15) -> 17858257

Sheet xx
A1: PRATHAMESH HARMONY "B" CO-OP. HOUSING SOCIETY LTD.
A2: (Regn. No.MUM/WP/HSG/TC/15332/2012-13)
A4: Balance Sheet as at March 31, 2023
H5: (Amt. In Rs.)
A6: Previous Year 2021-22 | B6: LIABILITIES | D6: Current Year 2022-23 | E6: Previous Year 2021-22 | F6: ASSETS | H6: Current Year 2022-23
B7: Authorised Share Capital | F7: Cash & Bank Balance
A8: 1,00,000.00 | B8: (2000 Shares of Rs.50/- each) | D8: 1,00,000.00 | E8: 1458 | F8: Cash in Hand | G8: 3253
E9: 18115 | F9: Mumbai District Central Co-op. Bank | G9: 19996
B10: Issued, Subscribed and Paid Up | E10: 151805.28 | F10: Citizencredit Co-Op Bank Ltd | G10: 371693.28 | H10: =SUM(G8:G10) -> 394942.28
A11: 9000 | B11: (180 Shares of Rs.50/- each) | D11: 9000
F12: Investment
B13: Reserve Fund | E13: 1700752 | F13: Fixed Deposit - ( As per Schedule I ) | G13: ='Sch I FD'!C44 -> 1887491
A14: 119852.46 | B14: As per last Balance Sheet | C14: =SUM(A14:A19) -> 206325.46 | E14: 45382 | F14: Accrued Interest - FD | G14: =SUM('Sch I FD'!D44:D44) -> 0 | H14: =SUM(G13:G14) -> 1887491
A15: 200 | B15: Add: Entrance Fees | C15: 100
A16: 1000 | B16: Add: Share Transfer Fees | C16: 500 | F16: Deposits
A17: 25000 | B17: Add: Transfer Premium | C17: 25000 | E17: 10255 | F17: Security Deposit - Adani Electricity | H17: 11167.72
A18: 4042 | B18: Add: Int. During the year | C18: =-xxx!G24 -> 8872
A19: 56231 | B19: Add: 1/4 th Trfd from I & Exp A/c. | C19: =xxx!D40 -> 50692 | D19: =SUM(C14:C19) -> 291489.46 | F19: Sundry Debtors, Loans & Advances
E20: 10700.66 | F20: Receivables from Adani | G20: 10700.66
B21: Sinking Fund | E21: 11172 | F21: TDS Receivable | G21: 19450
A22: 168968 | B22: As per last Balance Sheet | C22: =SUM(A22:A24) -> 206397 | E22: 178153 | F22: Members Dues-(As per Schedule II ) | G22: 246651 | H22: =SUM(G20:G22) -> 276801.66
A23: 29808 | B23: Additional During the year | C23: 29808
A24: 7621 | B24: Add: Int. During the year | C24: =-xxx!G27 -> 10796 | D24: =SUM(C22:C24) -> 247001 | F24: Fixed Asset
E25: 17907736 | F25: (As per Schedule IV) | H25: ='Sch IV Fixed Assets'!H16 -> 17858257
B26: Repair Fund
A27: 799393 | B27: As per last Balance Sheet | C27: =SUM(A27:A29) -> 911836 | F27: Prepaid Expenses
A28: 89640 | B28: Add: Additional During the year | C28: 89640 | E28: 1657 | F28: Lift Maintenance | G28: 1667
A29: 22803 | B29: Add: Int. During the year | C29: =-xxx!G25 -> 29171 | D29: =SUM(C27:C29) -> 1030647 | E29: 10704 | F29: Pest Control | G29: 3241 | H29: =SUM(G28:G29) -> 4908
B31: Major Repair Fund
A32: 562301 | B32: As per last Balance Sheet | C32: =SUM(A32:A35) -> 841478
A33: 360000 | B33: Add: Additional During the year | C33: 360000
A34: 33455 | B34: Add: Int. During the year | C34: =-xxx!G26 -> 41170
A35: -114278 | B35: Less: Repair & Maintenance Exp. | C35: 0 | D35: =SUM(C32:C35) -> 1242648
B37: Education & Training Fund
A38: 13194 | B38: As per last Balance Sheet | C38: =SUM(A38:A40) -> 15354
A39: 2160 | B39: Add: Contribution from Members | C39: 2160
A40: 0 | B40: Add: Int. During the year | C40: =-xxx!G28 -> 238 | D40: =SUM(C38:C40) -> 17752
B42: Members Contribution towards
A43: 17803000 | B43: Towards Land and Building | D43: 17803000
B45: Current Liabilities & Provisions
...

Sheet xxx
A1: PRATHAMESH HARMONY "B" CO-OP. HOUSING SOCIETY LTD.
A2: (Regn. No.MUM/WP/HSG/TC/15332/2012-13)
A4: Income & Expenditure Account for the year ended March 31, 2023
H5: (Amt. In Rs.)
A6: Previous Year 2021-22 | B6: Expenditure | D6: Current Year 2022-23 | E6: Previous Year 2021-22 | F6: Income | H6: Current Year 2022-23
B7: To Property Expenses | F7: By Members Contribution Towards
A8: 346622 | B8: Municipal Tax | C8: 327872 | E8: 325092 | F8: Municipal Taxes | G8: 325092
A9: 98000 | B9: Electricity Expenses | C9: 130060 | E9: 237600 | F9: Electricity Charges | G9: 237600
A10: 92183 | B10: Water Expenses | C10: 104088 | D10: =SUM(C8:C10) -> 562020 | E10: 86400 | F10: Water Charges | G10: 86400
E11: 172800 | F11: Service Charges | G11: 172800
B12: To Lift Maintenance | E12: 21600 | F12: Lift Maintenance Charges | G12: 21600
A13: 10069 | B13: Lift AMC | D13: 19990 | E13: 27000 | F13: Non Occupancy Charges | G13: =18600+900 -> 19500
E14: 71900 | F14: Parking Charges | G14: =25200+18400+18000+2700 -> 64300
A15: 114278 | B15: To Repair & Maintenance (As per Sch. VI) | C15: =xxxx!C8 -> 83499 | E15: 32804 | F15: Late Payment Expenses | G15: 36837
A16: -114278 | B16: Less: Trfd to Major Repair Fund | C16: 0 | D16: =SUM(C15:C16) -> 83499 | E16: 5500 | F16: Penalty & Fines | G16: =4500+2500 -> 7000
E17: 6000 | F17: Shifting Charges | G17: 3000
B18: To Service Charges | E18: 0 | F18: Legal Fees | G18: 500
A19: 113000 | B19: Security Expenses | C19: 108000 | E19: 0 | F19: Terrace Rent | G19: 6500 | H19: =SUM(G8:G19) -> 981129
A20: 18490 | B20: Depreciation | C20: ='Sch IV Fixed Assets'!G16 -> 9502.5
A21: 188.8 | B21: Bank Charges | C21: 0 | F21: By Interest Income
A22: 5500 | B22: Water Tanker Cleaning Exp | C22: 0 | E22: 6385 | F22: Saving Bank Interest | H22: =8930+1881 -> 10811
A23: 6000 | B23: Water Tanker Expenses | C23: 0 | E23: 68295 | F23: Interest Income - Fixed Deposit | G23: 90637
A24: 2998 | B24: Pest Control Charges | C24: 7463 | D24: =SUM(C19:C24) -> 124965.5 | E24: -4042 | F24: Less: Trf to Reserve Fund | G24: -8872
E25: -22803 | F25: Less: Trf to Repair Fund | G25: -29171
B26: To Office Expenses | E26: -33455 | F26: Less: Trf to Major Repair Fund | G26: -41170
A27: 3250 | B27: Festival Expenses | C27: 770 | E27: -7621 | F27: Less: Trf to Sinking Fund | G27: -10796
A28: 10368 | B28: Accounting Charges | C28: 11448 | E28: 0 | F28: Less: Trf to Education Fund | G28: -238 | H28: =SUM(G23:G28) -> 390
A29: 2769 | B29: Printing and Stationary | C29: 1750
A30: 929 | B30: Meeting Expenses | C30: 4410 | E30: 18 | F30: Interest Income - Recurring Deposit | H30: 0
A31: 2061 | B31: Miscellaneous Expenses | C31: 0 | E31: 0 | F31: Interest Income - Security Deposit | H31: 912.72
A32: 1500 | B32: Legal & Professional Fees | C32: =500+1500 -> 2000
A33: 2120 | B33: Covid-19 Expenses | C33: 0
A34: 41000 | B34: Salary Expenses | C34: =36000+500 -> 36500
A35: 9000 | B35: Gas Expenses | C35: 0
A36: 2500 | B36: Audit Fees | C36: 2500
A37: 0 | B37: Income Tax Expense | C37: 1400
A38: 0 | B38: Conveyance Expense | C38: 150 | D38: =SUM(C27:C38) -> 60928
A40: =ROUND((E42-SUM(A7:A36))*0.25,) -> 56231 | B40: To 1/4 th Trfd to Reserve Fund | D40: =ROUND((H42-SUM(D7:D36))*0.25,) -> 50692
A41: =E42-SUM(A7:A40) -> 168694.2 | B41: To Excess of Expenditure over Income | D41: =H42-SUM(D7:D40) -> 91148.22
A42: =SUM(A7:A41) -> 993473 | B42: Total | D42: =SUM(D7:D41) -> 993242.72 | E42: =SUM(E7:E41) -> 993473 | F42: Total | H42: =SUM(H7:H41) -> 993242.72
...

Sheet xxxx
A1: Repair & Maintenace for FY 2022-23
A2: FY 2021-22 | B2: R & M Head | C2: FY 2021-22
A3: 7619 | B3: Electrical | C3: 9050
A4: 42508 | B4: Others | C4: =12385+568 -> 12953
A5: 15855 | B5: Plumbing | C5: 20843
A6: 0 | B6: Lift Repairs | C6: =12500+25000 -> 37500
A7: 48296 | B7: Fire Fighting | C7: 3153
A8: =SUM(A3:A7) -> 114278 | B8: Total | C8: =SUM(C3:C7) -> 83499

Sheet FD Int Working
A1: Prathamesh Harmony B Wing CHS Ltd - Income - Non Members > Interest Income - Fixed Deposit ( 306002 ) <br>Transactions From 01-04-2022 to 31-03-2023
A2: Journal No. | B2: Posted Date | C2: Comments | D2: Debit | E2: Credit | F2: Fund
A3: NE-2022-0000001 | B3: 30-06-2022 | C3: Being int recd on FD 304618 R03 | E3: 1122 | F3: RMF
A4: NE-2022-0000003 | B4: 30-06-2022 | C4: being int recd on FD 304619 R03 | E4: 1122 | F4: RMF | L4: RMF | M4: =SUMIF($F$3:$F$63,L4,$E$3:$E$63) -> 29171
A5: NE-2022-0000005 | B5: 30-06-2022 | C5: Being int recd on FD 304620 R03 | E5: 1122 | F5: RMF | L5: SF | M5: =SUMIF($F$3:$F$63,L5,$E$3:$E$63) -> 10796
A6: NE-2022-0000007 | B6: 30-06-2022 | C6: being int recd on FD 304621 R03 | E6: 1683 | F6: RMF | L6: MRF | M6: =SUMIF($F$3:$F$63,L6,$E$3:$E$63) -> 41170
A7: NE-2022-0000009 | B7: 30-06-2022 | C7: being int recd on FD 304625 R03 | E7: 561 | F7: GF | L7: GF | M7: =SUMIF($F$3:$F$63,L7,$E$3:$E$63) -> 8872
A8: NE-2022-0000011 | B8: 30-06-2022 | C8: being int recd on FD 304626 R03 | E8: 561 | F8: SF | L8: ETF | M8: =SUMIF($F$3:$F$63,L8,$E$3:$E$63) -> 238
A9: NE-2022-0000013 | B9: 30-06-2022 | C9: being int recd on FD 301240 R03 SC | E9: 93 | F9: SC | L9: SC | M9: =SUMIF($F$3:$F$63,L9,$E$3:$E$63) -> 390
A10: JE-2022-0000039 | B10: 04-08-2022 | C10: Being FD 2196 renewed and FD 2196 made CCB - PF | E10: 2003 | F10: MRF | M10: =SUM(M4:M9) -> 90637
A11: JE-2022-0000044 | B11: 04-08-2022 | C11: Being FD 2195 renewed and FD 2195 made CCB - SF | E11: 401 | F11: SF
A12: JE-2022-0000036 | B12: 17-09-2022 | C12: Being FD 1820 renewed and FD 1820 made CCB - RMF | E12: 530 | F12: RMF
A13: JE-2022-0000037 | B13: 17-09-2022 | C13: Being FD 1821 renewed and FD 1821 made CCB - PF | E13: 1590 | F13: MRF
A14: JE-2022-0000040 | B14: 23-09-2022 | C14: Being FD 2225 renewed and FD 2225 made CCB - PF | E14: 3452 | F14: MRF
A15: JE-2022-0000007 | B15: 30-09-2022 | C15: Being Int recd on FD 304618 | E15: 1134 | F15: RMF
A16: JE-2022-0000008 | B16: 30-09-2022 | C16: Being Int recd on FD 304619 | E16: 1134 | F16: RMF
A17: JE-2022-0000009 | B17: 30-09-2022 | C17: Being Int recd on FD 304620 | E17: 1134 | F17: RMF
A18: JE-2022-0000010 | B18: 30-09-2022 | C18: Being Int recd on FD 304621 | E18: 1701 | F18: RMF
A19: JE-2022-0000011 | B19: 30-09-2022 | C19: Being Int recd on FD 304625 | E19: 567 | F19: GF
A20: JE-2022-0000012 | B20: 30-09-2022 | C20: Being Int recd on FD 304626 | E20: 567 | F20: SF
A21: JE-2022-0000013 | B21: 30-09-2022 | C21: Being Int recd on FD 301240 SC | E21: 94 | F21: SC
A22: JE-2022-0000029 | B22: 01-10-2022 | C22: Being FD 310834 renewed and FD 310834 made CCB - PF | E22: 9447 | F22: MRF
... A63: JE-2022-0000073 | B63: 31-03-2023 | C63: Being int recd on FD 304621 CCB - RMF | E63: 1602 | F63: RMF
A64: Balance : | B64: ₹90,637.00(Credit) | E64: ₹90,637.00

Sheet Workings
A2: Water Expenses
B3: 45631 | C3: 45721 | D3: =+C3-B3 -> 90 | E3: 16490
B4: 45722 | C4: 45747 | D4: =+C4-B4+1 -> 26 | E4: =ROUND(E3*D4/D3,) -> 4764 | F4: Provision | J4: Income Tax Provision
J5: Interest on saving | K5: ='IE '!G20 -> 0
J6: Interest on IT refund | K6: 0
A7: Lift AMC Expenses | J7: Interest on FD/RD | K7: ='IE '!G21 -> 134082
B8: 45413 | C8: 45566 | D8: 6 | E8: 20000 | J8: 80P2D Benefit | K8: =-K7 -> -134082
B9: 45597 | C9: 45748 | D9: 6 | E9: 20000 | J9: Total | K9: =SUM(K5:K8) -> 0
B10: 45748 | C10: =+C9 -> 45748 | D10: 1 | E10: =+E9*D10/D9 -> 3333.3333 | F10: Prepaid | J10: 0 To 10000 | K10: =ROUND(K9*L10,0) -> 0 | L10: 0.1
J11: 10001 To 20000 | L11: 0.2
J12: 20001 Or more | L12: 0.3
A13: Pest Control | J13: Education Cess | K13: =ROUND(K10*L13,0) -> 0 | L13: 0.04
B14: 45705 | C14: 46070 | D14: =+C14-B14 -> 365 | E14: 6930 | J14: Total Tax | K14: =SUM(K10:K13) -> 0
B15: 45748 | C15: 46070 | D15: =+C15-B15 -> 322 | E15: =ROUND(E14*D15/D14,) -> 6114 | F15: Prepaid | J15: Rounded Off | K15: 1120

Sheet BRS
A1: Prathamesh Harmony CHS
A3: Citizen Credit Bank Reconciliation Statement as on 31.03.2026
D4: Amount
A6: Balance as per system (Book Balance) | D6: 112753.34
A7: Add | B7: Cheque deposited but not cleared in Adda | D7: 0
A8: Less | B8: Cheque issued but not cleared in Adda (As per BRS) | D8: 0
A9: Add | B9: Amount in Adda but not reconciled in Adda
A11: Balance as per passbook | D11: =D6+D7-D8+D9 -> 112753.34
A13: MDCC Bank Reconciliation Statement as on 31.03.2026
D14: Amount
A16: Balance as per system (Book Balance) | D16: 21412
A17: Add | B17: Cheque deposited but not cleared in Adda | D17: 0
A18: Less | B18: Cheque issued but not cleared in Adda | D18: 0
A19: Add | B19: Amount in Adda but not reconciled in Adda | D19: 0
A21: Balance as per passbook | D21: =D16+D17-D18+D19 -> 21412

Sheet Sheet1
B2: The FY 2025-26 audit report workbook is built on last year's template, with the same eleven sheets, layout and print areas. Every formula recalculates clean, and the figures tie to the accounts you sent: Balance Sheet ₹2,02,30,863.87 on both sides, and the I&E balancing at ₹12,27,925.10.
B4: The headline change: the Society is in deficit of ₹1,17,952.10 this year, against a surplus of ₹27,001.74 last year. The Independent Auditor's Report opinion paragraph has been switched to "Excess of Expenditure over Income" accordingly, and no 1/4th transfer to General Reserve has been made.
B6: Main findings I've written into General Remarks (Part C), now 13 points:
B8: Section 70 shortfall of ₹1,65,101.98. Funds total ₹21,44,140.98 against investments of ₹19,79,039. Sinking Fund is short ₹1,13,650, Repair Fund ₹1,20,989, Education Fund ₹5,789; Reserve Fund is over-invested by ₹81,027.54. Last year the position was almost square (surplus ₹1,543), so this is a real deterioration.
B9: Repairs of ₹2,66,289 charged wholly to revenue with no appropriation from the Repair Fund (₹7,23,478) or Major Repair Fund (₹8,40,967.52) — last year ₹11,36,120 was met out of those funds. This is the principal cause of the deficit.
B10: Income tax of ₹13,420 provided although the Society's own Workings tab computes NIL after 80P(2)(d); the amount happens to equal the TDS deducted. That working also misses the ₹7,338 savings-bank interest, because it is keyed into column H of the I&E instead of column G. TDS receivable has built up to ₹58,986.
B11: Municipal tax under-recovery of ₹29,086 (₹4,85,016 charged vs ₹4,55,930 recovered).
B12: MDCC account dormant — ₹21,412 unchanged for two years, noted as dormant in the accounts file itself.
B13: Schedule comparative errors in the accounts file: Schedule V previous-year total ₹4,33,155 omits VNF's ₹22,700, and Schedule III previous-year total ₹9,733 omits ₹15. Neither agrees with the 2024-25 audited Balance Sheet. The xx, xxx, xxxx tabs are 2022-23 statements that now pull current-year schedule figures, and there's a live external link at BS!A70.
B14: The signature block on the Balance Sheet and I&E names "(Shankar D. Gawde), Panel No. 14428, Grp B" — not you. That must be corrected before signing.
B16: Improvements worth noting: cash on hand down to ₹2,850 (within Bye-Law 144), members' dues down from ₹2,32,381 to ₹86,394, and ₹1,770 actually spent from the Education & Training Fund.
B18: What I could not fill in. The accounts file carries no non-financial data, so AGM date, MC meeting dates and count, committee members' names, and the appointment/acceptance letter dates are placeholders. Every provisional cell is shaded yellow, and a new "Pending Inputs" sheet lists each one with its cell reference. I've provisionally dated the report 17-09-2026 and carried classification "B" forward — both are your call. I also cleared the Meeting sheet, which held eight attendees from an entirely different society, and stripped the SANA Apartment CHS content from the lower half of Audit-Remarks.
... B22: I ran out of tool calls before presenting the file — say the word and I'll hand over /mnt/user-data/outputs/Prathamesh-Harmony-CHS-2025-26.xlsx, and I can also convert it back to .xls or export a paginated PDF set if you want it in the same format as last year's.
