Workbook

Sheet BS
A1: KITTY PARK CO-OP. HOUSING SOCIETY LTD.
A2: (Regd.No.MUM/W-P/HSG/(TC)/ 11731/2002-2003)
A3: ADD : CTS No. 556C, Village Valnai, Orlem, Malad (W), Mumbai – 400 064.
A4: BALANCE SHEET AS AT 31ST MARCH 2026
H5: (Amt. in Rs.)
A6: Previous Year 2024-25 | B6: LIABILITIES | D6: Current Year 2025-26 | E6: =A6 -> Previous Year 2024-25 | F6: ASSETS | H6: =D6 -> Current Year 2025-26
B8: Authorised Share Capital | F8: Cash & Bank Balance :
A9: 10000 | B9: (200 Shares of Rs.50/- each) | D9: 10000 | E9: 4 | F9: Cash in hand | G9: 2814
E10: 95191.48 | F10: Mumbai District Central Co-op. Bank | G10: =BRS!D16 -> 98142.48
B11: Issued, Subscribed and Paid Up Share Capital | E11: 316931.85 | F11: Saraswat Co-op. Bank | G11: =BRS!D4 -> 88348.63 | H11: =SUM(G9:G11) -> 189305.11
A12: 6500 | B12: (130 Shares of Rs.50/- each ) | D12: 6500
F13: Investment In Fixed Deposit - (As per Sch. I )
B14: Reserve Fund & Other Funds | E14: 1430092 | F14: FDRs with Banks | G14: =FD!D42 -> 1318170
B15: (i) General Reserve Fund | E15: 93181 | F15: Accrued Interest on Fixed Deposits | G15: =FD!E42+FD!F42 -> 64651 | H15: =SUM(G14:G15) -> 1382821
A16: 269938 | B16: As per last Balance Sheet | C16: =SUM(A16:A18) -> 310812
A17: 21522 | B17: Add: 25% surplus trfd | C17: 0 | F17: Other Investment :
A18: 19352 | B18: Add: Interest on FD | C18: ='FD Interest Working'!D58 -> 19964 | D18: =SUM(C16:C18) -> 330776 | E18: 1000 | F18: Share with MDCC | H18: 1000
B19: (ii) Sinking Fund
A20: 137603 | B20: As per last Balance Sheet | C20: =SUM(A20:A22) -> 150488 | F20: Deposits & Advances :
A21: 2520 | B21: Add: Additions during the year | C21: 2520 | E21: 5365 | F21: With Tata Power | H21: 5365
A22: 10365 | B22: Add: Interest on FD | C22: ='FD Interest Working'!D60 -> 11206 | D22: =SUM(C20:C22) -> 164214
B23: (iii) Repair Fund | E23: 29459 | F23: Dues from Members - ( As per Schedule II ) | H23: ='SCH-II-III-IV-V'!D5 -> 20965
A24: 489871 | B24: As per last Balance Sheet | C24: =SUM(A24:A26) -> 538462
A25: 7440 | B25: Add: Additions during the year | C25: 7440 | E25: 66500 | F25: Advance to Ventors - (As per Schedule - V ) | H25: ='Vendor Prov n Advance'!D31 -> 259403.75
A26: 41151 | B26: Add: Interest on FD | C26: ='FD Interest Working'!D56 -> 41764 | D26: =SUM(C24:C26) -> 587666
B27: (iv) Major Repair Fund
A28: 473977 | B28: As per last Balance Sheet | C28: =SUM(A28:A31) -> 0 | F28: Fixed Assets :
A29: 31200 | B29: Add: Additions during the year | C29: 31200 | E29: 11031100 | F29: (i) Land & Building | H29: =E29 -> 11031100
A30: 0 | B30: Add: Interest recd on FD | C30: ='FD Interest Working'!D57 -> 32376
A31: -505177 | B31: Less: Expenses incurred during year | C31: 0 | D31: =SUM(C28:C31) -> 63576 | E31: 2714 | F31: (i) LED Monitor | G31: 2307
B32: (v) Painting and Repair Fund | E32: -407 | F32: Less: Depreciation @ 15% | G32: =-ROUND(G31*15%,0) -> -346 | H32: =SUM(G31:G32) -> 1961
A33: 715000 | B33: Members contribution during the year | C33: =SUM(A33:A36) -> 347977
A34: 36300 | B34: Add: Interest on FD | C34: 0 | E34: 493 | F34: (ii) Furniture & Fixtures | G34: 444
A35: 0 | B35: Add: Additions during the year | C35: 195000 | E35: -49 | F35: Less: Depreciation @ 10% | G35: =-ROUND(G34*10%,0) -> -44 | H35: =SUM(G34:G35) -> 400
A36: -403323 | B36: Less: Expenses incurred during year | C36: -234625 | D36: =SUM(C33:C36) -> 308352
A37: 13986 | B37: (vi) Education Training Fund | C37: =SUM(A37:A39) -> 16621 | E37: 5076 | F37: (iii) Water Pump Account | G37: 4315
A38: 1560 | B38: Add: Additions during the year | C38: 1560 | E38: -761 | F38: Less: Depreciation @ 15% | G38: =-ROUND(G37*15%,0) -> -647 | H38: =SUM(G37:G38) -> 3668
A39: 1075 | B39: Add: Interest recd on FD | C39: ='FD Interest Working'!D55 -> 1092 | D39: =SUM(C37:C39) -> 19273
E40: 18777 | F40: (iv) CCTV | G40: 15960
B41: Members Contribution towards : | E41: -2817 | F41: Less: Depreciation @ 15% | G41: =-ROUND(G40*15%,0) -> -2394 | H41: =SUM(G40:G41) -> 13566
...

Sheet IE
A1: KITTY PARK CO-OP. HOUSING SOCIETY LTD.
A2: (Regn.No.MUM/W-P/HSG/(TC)/11731/2002-2003)
A3: ADD : CTS No. 556C, Village Valnai, Orlem, Malad (W), Mumbai – 400 064.
A4: INCOME & EXPENDITURE ACCOUNT FOR THE YEAR ENDED 31ST MARCH 2026
H5: (Amt. in Rs.)
A6: 2024-2025 | B6: Expenditure | D6: 2025-2026 | E6: =A6 -> 2024-2025 | F6: Income | H6: =D6 -> 2025-2026
B7: To Salary Expenses : | F7: By Maintenance Income Contribution :
A8: 50500 | B8: Salary Expenses | C8: 43200 | E8: 55068 | F8: Electricity Charges | G8: 55068
A9: 4200 | B9: Bonus | C9: 4800 | D9: =SUM(C8:C9) -> 48000 | E9: 28548 | F9: Water Charges | G9: 28548
E10: 0 | F10: Lift Repair Charges | G10: 65000
A11: 102856 | B11: To Property Tax - Members | D11: 118050 | E11: 5724 | F11: Non Occupancy Charges | G11: =7791+4626 -> 12417
A12: 58184 | B12: To Electricity Expenses | D12: 63958 | E12: 6960 | F12: Parking Charges | G12: 7410
E13: 5249 | F13: Late Payment Interest | G13: 5297
B14: To Water Expenses : | E14: 192504 | F14: Maintenance Charges | G14: 192504 | H14: =SUM(G8:G14) -> 366244
A15: 32915 | B15: Water Expenses | C15: 31915 | D15: =SUM(C15) -> 31915
B16: To Lift Expenses: | F16: By Property Tax Contribution :
A17: 10000 | B17: Lift AMC Expenses | C17: 10000 | E17: 99936 | F17: Property Tax | G17: =109792+5060 -> 114852
A18: 0 | B18: Lift Repair & Maintenance | C18: 143500 | D18: =C17+C18 -> 153500 | E18: 2964 | F18: Common Area P. Tax | G18: 3172 | H18: =SUM(G17:G18) -> 118024
B19: To Repair & Maintenance :
A20: 0 | B20: Repair & Maintenance expense | C20: 1650 | F20: By Interest Income
A21: 6840 | B21: Electrical Repair Maintenance | C21: 5785 | E21: 15420 | F21: Interest Income - Savings Deposit | H21: 6095
A22: 32705 | B22: Other Repair Maintenance | C22: 58285
A23: 11300 | B23: Garden Maintenance expense | C23: 7200 | E23: 108834 | F23: By Interest on Fixed Deposits : | G23: ='FD Interest Working'!D47 -> 107013
A24: 0 | B24: Fighting System Repairs and Maintenance | C24: 20650 | F24: Less: Transfer to:
A25: 0 | B25: CCTV AMC | C25: 1390 | E25: -10365 | F25: Sinking Fund | G25: =-'FD Interest Working'!D60 -> -11206
A26: 2500 | B26: CCTV Repair | C26: 0 | D26: =SUM(C20:C26) -> 94960 | E26: -41151 | F26: Repair Fund | G26: =-'FD Interest Working'!D56 -> -41764
B27: To Service Charges : | E27: -36300 | F27: Painting & Repair Fund | G27: =-'FD Interest Working'!D57 -> -32376
A28: 9096 | B28: Accounting Charges | C28: 9096 | E28: -19352 | F28: Reserve Fund | G28: =-'FD Interest Working'!D58 -> -19964
A29: 4500 | B29: Professional Fees | C29: 4900 | E29: -1075 | F29: Education Fund | G29: =-'FD Interest Working'!D55 -> -1092 | H29: =SUM(G23:G29) -> 611
A30: 1500 | B30: Audit Fees | C30: 2500
A31: 826 | B31: Subscription Federation Fees | C31: 826 | D31: =SUM(C28:C31) -> 17322 | E31: 214 | F31: Interest on IT Refund | H31: 0
B32: To Office Expenses :
A33: 83 | B33: Printing and Stationary | C33: 0 | F33: By Other Income :
A34: 0 | B34: Interest on TDS | C34: 226 | E34: 0 | F34: Sale Of Scrap | G34: 255
A35: 0 | B35: Income Tax Expenses | C35: 2208 | E35: 5000 | F35: Shifting Charges | G35: 5000 | H35: =+G34+G35 -> 5255
A36: 52.83 | B36: Bank Charges | C36: 140.47
A37: 0 | B37: Conveyance Charges | C37: 100
A38: 0 | B38: Miscellaneous Expenses | C38: 150
A39: 4034 | B39: Depreciation on Fixed Assets | C39: 3431 | D39: =SUM(C33:C39) -> 6255.47
A41: 21522 | B41: To Trfd to Reserve Fund ( 25% ) | D41: 0 | E41: 0 | F41: Excess of Expenditure over the Income | H41: =D43-SUM(H8:H39) -> 37731.47
...

Sheet FD
B1: =+IE!A1 -> KITTY PARK CO-OP. HOUSING SOCIETY LTD.
B2: Details of Fixed Deposits as on 31st March 2026
A3: Sr. | B3: Certificate No. | C3: Date | D3: Amount Invested | E3: Accrued Int. 2024-25 | F3: Accrued Int. 2025-26 | G3: Accrued Int. Total | H3: Total Deposit Amount | I3: Maturity Date | J3: Maturity Value | K3: Interest % | L3: Bank
B4: Sinking Fund
A5: 1 | B5: TD0000414292_2 | C5: 29.06.2025 | D5: 3850 | E5: 0 | F5: =208-21 -> 187 | G5: =SUM(E5:F5) -> 187 | H5: =D5+G5 -> 4037 | I5: 29.09.2026 | J5: 4199 | K5: 7 | L5: SCB
A6: 2 | B6: TD0000414298_2 | C6: 29.06.2025 | D6: 47652 | E6: 0 | F6: =2569-258 -> 2311 | G6: =SUM(E6:F6) -> 2311 | H6: =D6+G6 -> 49963 | I6: 29.09.2026 | J6: 51970 | K6: 7 | L6: SCB
A7: 3 | B7: TD0000414288_2 | C7: 05.05.2024 | D7: 4549 | E7: =295-30 -> 265 | F7: =345-34 -> 311 | G7: =SUM(E7:F7) -> 576 | H7: =D7+G7 -> 5125 | I7: 05.05.2026 | J7: 5226 | K7: 7 | L7: SCB
A8: 4 | B8: 1303641_3 | C8: 16.03.2026 | D8: 6083 | E8: 0 | F8: 17 | G8: =SUM(E8:F8) -> 17 | H8: =D8+G8 -> 6100 | I8: 16.03.2027 | J8: 6498 | K8: 6.65 | L8: MDCC
A9: 5 | B9: 1303640_4 | C9: 16.03.2026 | D9: 65616 | E9: 0 | F9: 191 | G9: =SUM(E9:F9) -> 191 | H9: =D9+G9 -> 65807 | I9: 16.03.2027 | J9: 70090 | K9: 6.65 | L9: MDCC
A10: 6 | B10: 1303637_4 | C10: 16.03.2026 | D10: 5276 | E10: 0 | F10: 15 | G10: =SUM(E10:F10) -> 15 | H10: =D10+G10 -> 5291 | I10: 16.03.2027 | J10: 5636 | K10: 6.65 | L10: MDCC
A11: 7 | B11: 1303636_3 | C11: 22.03.2026 | D11: 4618 | E11: 0 | F11: 8 | G11: =SUM(E11:F11) -> 8 | H11: =D11+G11 -> 4626 | I11: 22.03.2027 | J11: 4933 | K11: 6.65 | L11: MDCC
A12: 8 | B12: 1303638_4 | C12: 29.03.2026 | D12: 4987 | E12: 0 | F12: 2 | G12: =SUM(E12:F12) -> 2 | H12: =D12+G12 -> 4989 | I12: 29.03.2027 | J12: 5327 | K12: 6.65 | L12: MDCC
A13: 9 | B13: TD1001143055_01 | C13: 30.06.2025 | D13: 11534 | E13: 0 | F13: =620-61 -> 559 | G13: =SUM(E13:F13) -> 559 | H13: =D13+G13 -> 12093 | I13: 30.09.2026 | J13: 12579 | K13: 7 | L13: SCB
D14: =SUM(D5:D13) -> 154165 | E14: =SUM(E5:E13) -> 265 | F14: =SUM(F5:F13) -> 3601 | G14: =SUM(G5:G13) -> 3866 | H14: =SUM(H5:H13) -> 158031 | J14: =SUM(J5:J13) -> 166458
B16: Share Capital
A17: 10 | B17: 1303639_4 | C17: 16.09.2025 | D17: 7043 | E17: 0 | F17: 261 | G17: =SUM(E17:F17) -> 261 | H17: =D17+G17 -> 7304 | I17: 16.09.2026 | J17: 7534 | K17: 6.8 | L17: MDCC
A18: 11 | B18: TD0000400894_2 | C18: 05.05.2024 | D18: 1745 | E18: 0 | F18: 0 | G18: =F18+E18 -> 0 | H18: =D18+G18 -> 1745 | I18: 05.05.2026 | J18: 1745 | K18: 7 | L18: SCB
D19: =SUM(D17:D18) -> 8788 | E19: {=E17:E18} -> 0 | F19: {=F17:F18} -> 261 | G19: =SUM(G17:G18) -> 261 | H19: =SUM(H17:H18) -> 9049 | J19: =SUM(J17:J18) -> 9279
B20: Repair Fund | E20: 0 | F20: 0
A21: 12 | B21: TD0000414295_2 | C21: 29.06.2025 | D21: 582381 | E21: 0 | F21: =31392-3315 -> 28077 | G21: =SUM(E21:F21) -> 28077 | H21: =D21+G21 -> 610458 | I21: 29.09.2026 | J21: 635134 | K21: 7 | L21: SCB
D22: =SUM(D21) -> 582381 | E22: =SUM(E21) -> 0 | F22: =SUM(F21) -> 28077 | G22: =SUM(G21) -> 28077 | H22: =SUM(H21) -> 610458 | J22: =SUM(J21) -> 635134
B24: Major Repair Fund
A25: 13 | B25: TD0000414294_2 | C25: 29.06.2025 | D25: 40476 | E25: 0 | F25: =2183-217 -> 1966 | G25: =SUM(E25:F25) -> 1966 | H25: =D25+G25 -> 42442 | I25: 29.09.2026 | J25: 44144 | K25: 7 | L25: SCB
A26: 14 | B26: TD0000414296_2 | C26: 29.06.2025 | D26: 11364 | E26: 0 | F26: =613-63 -> 550 | G26: =SUM(E26:F26) -> 550 | H26: =D26+G26 -> 11914 | I26: 29.09.2026 | J26: 12394 | K26: 7 | L26: SCB
A27: 16 | B27: TD0000414300_2 | C27: 29.03.2024 | D27: 152740 | E27: 0 | F27: =8233-876 -> 7357 | G27: =SUM(E27:F27) -> 7357 | H27: =D27+G27 -> 160097 | I27: 29.09.2026 | J27: 166575 | K27: 7 | L27: SCB
A28: 17 | B28: TD1001143106_01 | C28: 30.06.2025 | D28: 78272 | E28: 0 | F28: =4205-419 -> 3786 | G28: =SUM(E28:F28) -> 3786 | H28: =D28+G28 -> 82058 | I28: 30.09.2026 | J28: 85365 | K28: 7 | L28: SCB
D29: =SUM(D25:D28) -> 282852 | E29: =SUM(E25:E28) -> 0 | F29: =SUM(F25:F28) -> 13659 | G29: =SUM(G25:G28) -> 13659 | H29: =SUM(H25:H28) -> 296511 | J29: =SUM(J25:J28) -> 308478
B31: General Reserve Fund
A32: 18 | B32: TD0000414290_2 | C32: 05.05.2024 | D32: 78729 | E32: =5099-510 -> 4589 | F32: =5901-1901 -> 4000 | G32: =SUM(E32:F32) -> 8589 | H32: =D32+G32 -> 87318 | I32: 05.05.2026 | J32: 90439 | K32: 7 | L32: SCB
A33: 19 | B33: TD0000414299_2 | C33: 29.06.2025 | D33: 40469 | E33: 0 | F33: =2182-218 -> 1964 | G33: =SUM(E33:F33) -> 1964 | H33: =D33+G33 -> 42433 | I33: 29.09.2026 | J33: 44136 | K33: 7 | L33: SCB
A34: 20 | B34: TD0000414303_2 | C34: 29.06.2025 | D34: 112740 | E34: 0 | F34: =6077-647 -> 5430 | G34: =SUM(E34:F34) -> 5430 | H34: =D34+G34 -> 118170 | I34: 29.09.2026 | J34: 122952 | K34: 7 | L34: SCB
A35: 21 | B35: TD1001143025_01 | C35: 30.06.2025 | D35: 42845 | E35: 0 | F35: =2302-231 -> 2071 | G35: =SUM(E35:F35) -> 2071 | H35: =D35+G35 -> 44916 | I35: 30.09.2026 | J35: 46727 | K35: 7 | L35: SCB
D36: =SUM(D32:D35) -> 274783 | E36: =SUM(E32:E35) -> 4589 | F36: =SUM(F32:F35) -> 13465 | G36: =SUM(G32:G35) -> 18054 | H36: =SUM(H32:H35) -> 292837 | J36: =SUM(J32:J35) -> 304254
B38: Education & Training Fund
A39: 22 | B39: TD1001143122_01 | C39: 30.06.2025 | D39: 15201 | E39: 0 | F39: =817-83 -> 734 | G39: =SUM(E39:F39) -> 734 | H39: =D39+G39 -> 15935 | I39: 30.09.2026 | J39: 16578 | K39: 7 | L39: SCB
D40: =SUM(D39:D39) -> 15201 | E40: =SUM(E39:E39) -> 0 | F40: =SUM(F39:F39) -> 734 | G40: =SUM(G39:G39) -> 734 | H40: =SUM(H39:H39) -> 15935 | J40: =SUM(J39:J39) -> 16578
B42: GRAND TOTAL | D42: =D14+D19+D22+D29+D36+D40 -> 1318170 | E42: =E14+E19+E22+E29+E36+E40 -> 4854 | F42: =F14+F19+F22+F29+F36+F40 -> 59797 | G42: =G14+G19+G22+G29+G36+G40 -> 64651 | H42: =H14+H19+H22+H29+H36+H40 -> 1382821 | J42: =J14+J19+J22+J29+J36+J40 -> 1440181

Sheet SCH-II-III-IV-V
A1: Kitty Park Co-op. Housing Society Ltd.
A2: Schedule - II: Member's Dues as at 31st March 2026
A3: Sr.No | B3: Flat | C3: Name of the Member | D3: Amount (Rs.)
A4: 1 | B4: 103 | C4: Mr. Jha | D4: 20965
A5: Total | D5: =SUM(D4:D4) -> 20965
A8: Schedule - III: Advance Members as at 31st March 2026
A9: Sr.No | B9: Flat No. | C9: Name of the Member | D9: Amount (Rs.)
A10: 1 | B10: 201 | C10: Mr. John Cota | D10: 7704
A11: 2 | B11: 401 | C11: Mr. Francis Ramos | D11: 62530
A12: 3 | B12: 602 | C12: Mr. Anthony Fernandes | D12: 8093
A13: Total | D13: =SUM(D10:D12) -> 78327
A15: Kitty Park Co-op. Housing Society Ltd.
A16: Sch-IV: Payables and Provisions as of 31.03.2026
A17: Sl.No | B17: FY 2024-25 | C17: Vendor | D17: FY 2025-26
A18: 1 | B18: 600 | C18: Gardener | D18: 600
A19: 2 | B19: 1800 | C19: Pumpman | D19: 1800
A20: 3 | B20: 1800 | C20: Sweeper | D20: 1800
A21: 4 | B21: 1200 | C21: Washing of staircase | D21: 1200
A22: 5 | B22: 7145 | C22: MCGM - Water Expenses | D22: 7198
A23: 6 | B23: 5048 | C23: Tata Power | D23: 5236
A24: 7 | B24: 1500 | C24: Audit Fees | D24: 2000
A25: 8 | B25: 0 | C25: Provision Water Exp | D25: 7884
A26: 9 | B26: 4500 | C26: Professional Fees | D26: 4500
A27: 10 | B27: 235125 | C27: Leakhalt Associates | D27: 0
A28: 11 | B28: 9000 | C28: Mukesh Plumber | D28: 0
A29: 12 | B29: 7500 | C29: TDS Payable | D29: 3246
... A31: 14 | B31: 0 | C31: RK Interprises | D31: 1350
B32: =SUM(B18:B31) -> 276718 | C32: Total | D32: =SUM(D18:D31) -> 36814
A35: Schedule - V : Advance to Vendors as of 31.03.2026
A36: Sr.no | B36: Date | C36: Vendor | D36: Amount (Rs.)
A37: 1 | B37: 25.05.2022 | C37: Shankar Durgad | D37: 25000
A38: 2 | B38: 05.06.2023 | C38: Shankar Durgad | D38: 15000
A39: 3 | B39: 28.06.2023 | C39: Shankar Durgad | D39: 25000
A40: 4 | B40: 16.09.2023 | C40: Bharat Boridkar | D40: 1500
A41: 5 | B41: 12.04.2025 | C41: Irene Rosario | D41: 774
A42: 6 | B42: 13.03.2026 | C42: Kreative Welt | D42: 81629.75
A43: 7 | B43: 11.09.2025 | C43: Leakhalt Associates | D43: 2500
A44: 8 | B44: 31.03.2026 | C44: R.K. ENTERPRISES | D44: 108000
A45: Total | D45: =SUM(D37:D44) -> 259403.75

Sheet Vendor Prov n Advance
A1: Kitty Park Co-op. Housing Society Ltd.
A2: Sch-IV: Payables and Provisions as of 31.03.2026
A3: Sl.No | B3: FY 2024-25 | C3: Vendor | D3: FY 2025-26
A4: 1 | B4: 600 | C4: Gardener | D4: 600
A5: 2 | B5: 1800 | C5: Pumpman | D5: 1800
A6: 3 | B6: 1800 | C6: Sweeper | D6: 1800
A7: 4 | B7: 1200 | C7: Washing of staircase | D7: 1200
A8: 5 | B8: 7145 | C8: MCGM - Water Expenses | D8: 7198
A9: 6 | B9: 5048 | C9: Tata Power | D9: 5236
A10: 7 | B10: 1500 | C10: Audit Fees | D10: 2000
A11: 8 | B11: 0 | C11: Provision Water Exp | D11: 7884
A12: 9 | B12: 4500 | C12: Professional Fees | D12: 4500
A13: 10 | B13: 235125 | C13: Leakhalt Associates | D13: 0
A14: 11 | B14: 9000 | C14: Mukesh Plumber | D14: 0
A15: 12 | B15: 7500 | C15: TDS Payable | D15: 3246
... A17: 14 | B17: 0 | C17: RK Interprises | D17: 1350
B18: =SUM(B4:B17) -> 276718 | C18: Total | D18: =SUM(D4:D17) -> 36814
A21: Schedule - V : Advance to Vendors as of 31.03.2026
A22: Sr.no | B22: Date | C22: Vendor | D22: Amount (Rs.)
A23: 1 | B23: 25.05.2022 | C23: Shankar Durgad | D23: 25000
A24: 2 | B24: 05.06.2023 | C24: Shankar Durgad | D24: 15000
A25: 3 | B25: 28.06.2023 | C25: Shankar Durgad | D25: 25000
A26: 4 | B26: 16.09.2023 | C26: Bharat Boridkar | D26: 1500
A27: 5 | B27: 12.04.2025 | C27: Irene Rosario | D27: 774
A28: 6 | B28: 13.03.2026 | C28: Kreative Welt | D28: 81629.75
A29: 7 | B29: 11.09.2025 | C29: Leakhalt Associates | D29: 2500
A30: 8 | B30: 31.03.2026 | C30: R.K. ENTERPRISES | D30: 108000
A31: Total | D31: =SUM(D23:D30) -> 259403.75

Sheet BRS
A1: KITTY PARK CHS LTD
A2: Saraswat Bank Reconciliation Statement as on 31.03.2026
D3: Amount
B4: Balance as per System (Book Balance) | D4: 88348.63 | F4: Date | G4: Flat/Vendor | H4: Cheque # | I4: Dr | J4: Cr | K4: Cleared On
F5: 13.03.26 | G5: Kreative Welt | H5: 202675 | I5: 0 | J5: 13469 | K5: 06.04.26
A6: Add: | B6: Cheque issued but not presented (Outflow) | D6: =J7 -> 120389 | F6: 31.03.26 | G6: RK Enterprises | H6: 202676 | I6: 0 | J6: 106920 | K6: 04.04.25
I7: =SUM(I5:I6) -> 0 | J7: =SUM(J5:J6) -> 120389
A8: Less: | B8: Cheque deposited but not cleared (Inflow) | D8: =I7 -> 0
B10: Balance as per Bank Passbook | D10: =D4+D6-D8 -> 208737.63
A13: KITTY PARK CHS LTD
A14: MDCC Bank Reconciliation Statement as on 31.03.2026
D15: Amount
B16: Balance as per System (Book Balance) | D16: 98142.48
B18: Balance as per Bank Passbook | D18: =D16 -> 98142.48

Sheet FD Interest Working
A1: Kitty Park C.H.S. Ltd - Income - Non Members > Interest Income - Fixed Deposit ( 306002 ) <br>Transactions From 01-04-2024 to 31-03-2025
A2: Journal No. | B2: Posted Date | C2: Comments | D2: Credit | F2: Bank | G2: Fund
A3: JE-2025-0000024 | B3: 29-06-2025 | C3: Being FD 414298 renewed and remade SCB - SF | D3: 848 | F3: SCB | G3: SF
A4: JE-2025-0000040 | B4: 29-06-2025 | C4: Being FD 414297 renewed and remade SCB - mrf | D4: 4101 | F4: SCB | G4: MRF
A5: JE-2025-0000030 | B5: 29-06-2025 | C5: Being FD TD0000414303 renewed and remade SCB - GF | D5: 2008 | F5: SCB | G5: GF
A6: JE-2025-0000028 | B6: 29-06-2025 | C6: Being FD TD0000414300 renewed and remade SCB - MRF | D6: 2721 | F6: SCB | G6: MRF
A7: JE-2025-0000026 | B7: 29-06-2025 | C7: Being FD TD0000414299 renewed and remade SCB - RES | D7: 721 | F7: SCB | G7: GF
A8: JE-2025-0000021 | B8: 29-06-2025 | C8: Being FD TD0000414296 renewed and remade SCB - MRF | D8: 203 | F8: SCB | G8: MRF
A9: JE-2025-0000019 | B9: 29-06-2025 | C9: Being FD TD0000414295 renewed and remade SCB - RF | D9: 10372 | F9: SCB | G9: RF
A10: JE-2025-0000017 | B10: 29-06-2025 | C10: Being FD TD0000414294 renewed and remade SCB - MRF | D10: 720 | F10: SCB | G10: MRF
A11: JE-2025-0000015 | B11: 29-06-2025 | C11: Being FD TD0000414292 renewed and remade SCB - SF | D11: 69 | F11: SCB | G11: SF
A12: JE-2025-0000002 | B12: 30-06-2025 | C12: Being Int recd on FD TD0000400894 - SC SCB | D12: 30 | F12: SCB | G12: SCF
A13: JE-2025-0000038 | B13: 30-06-2025 | C13: Being FD TD1001143122 renewed and remade SCB - ETF | D13: 275 | F13: SCB | G13: ETF
A14: JE-2025-0000036 | B14: 30-06-2025 | C14: Being FD 1143106 renewed and remade SCB - MRF | D14: 1421 | F14: SCB | G14: MRF
... A35: JE-2025-0000035 | B35: 31-03-2026 | C35: Being int accu on FD TD1001143055 - SF - SCB | D35: 620 | F35: SCB | G35: SF
A36: JE-2025-0000033 | B36: 31-03-2026 | C36: Being int accu on FD TD1001143025 - GF - SCB | D36: 2302 | F36: SCB | G36: GF | T36: Journal No. | U36: Posted Date | V36: Comments | W36: Credit
A37: JE-2025-0000031 | B37: 31-03-2026 | C37: Being int accu on FD TD0000414303 - GF - SCB | D37: 6077 | F37: SCB | G37: GF
A38: JE-2025-0000029 | B38: 31-03-2026 | C38: Being int accu on FD 414300 - MRF - SCB | D38: 8233 | F38: SCB | G38: MRF
A39: JE-2025-0000027 | B39: 31-03-2026 | C39: Being int accu on FD TD0000414299 - RES - SCB | D39: 2182 | F39: SCB | G39: GF
A40: JE-2025-0000025 | B40: 31-03-2026 | C40: Being int accu on FD TD0000414298- SF - SCB | D40: 2569 | F40: SCB | G40: SF
A41: JE-2025-0000022 | B41: 31-03-2026 | C41: Being int accu on FD TD0000414296 - MRF - SCB | D41: 613 | F41: SCB | G41: MRF
A42: JE-2025-0000020 | B42: 31-03-2026 | C42: Being int accu on FD TD0000414295 - RF - SCB | D42: 31392 | F42: SCB | G42: RF
A43: JE-2025-0000018 | B43: 31-03-2026 | C43: Being int accu on FD TD0000414294 - MRF - SCB | D43: 2183 | F43: SCB | G43: MRF
A44: JE-2025-0000016 | B44: 31-03-2026 | C44: Being int accu on FD TD0000414292 - SF - SCB | D44: 208 | F44: SCB | G44: SF
A45: JE-2025-0000014 | B45: 31-03-2026 | C45: Being int accu on FD 414290 - GF - SCB | D45: 5901 | F45: SCB | G45: GF
A46: JE-2025-0000013 | B46: 31-03-2026 | C46: Being int accu on FD 414288 - SF - SCB | D46: 345 | F46: SCB | G46: SF
D47: =SUM(D3:D46) -> 107013
D49: System | G49: Bank
D50: 6828 | F50: MDCC | G50: 6828
D51: 100185 | F51: SCB | G51: 100185
D52: =SUBTOTAL(9,D50:D51) -> 107013 | G52: =SUM(G50:G51) -> 107013
D55: 1092 | G55: ETF
D56: 41764 | G56: RF
D57: 32376 | G57: MRF
D58: 19964 | G58: GF
D59: 611 | G59: SC
D60: 11206 | G60: SF
D61: =SUBTOTAL(9,D55:D60) -> 107013

Sheet Working
A1: Water
A2: Period | C2: Days | D2: Amount
A3: 45936 | B3: 46028 | C3: =B3-A3 -> 92 | D3: 7884
A4: 46028 | B4: 46112 | C4: =B4-A4 -> 84 | D4: =ROUND((C4*D3)/C3,0) -> 7198 | E4: provision
A7: CCTV AMC
A8: Period | C8: Days | D8: Amount
A9: 45910 | B9: 46275 | C9: =B9-A9 -> 365 | D9: 2500
A10: 46113 | B10: 46275 | C10: =B10-A10 -> 162 | D10: =ROUND((C10*D9)/C9,0) -> 1110 | E10: Prepaid

Sheet Cash Book
A1: Kitty Park C.H.S. Ltd
A2: Cash in hand - All Transactions ( 01-04-2019 to 31-03-2020 )
A4: Posted Date | B4: Voucher No | C4: Account | D4: Instr No | E4: Comment | F4: Receipts | G4: Payments
A5: 43556 | B5: 338 | C5: Salary Expenses,Salary Expenses,Salary Expenses | D5: N.A. | E5: Being salaries paid - March 2019 | F5: 0 | G5: 3000
A6: 43556 | B6: 339 | C6: Other Repair Maintenance | D6: N.A. | E6: Being Labour charges paid | F6: 0 | G6: 450
A7: 43556 | B7: 460 | C7: Other Repair Maintenance | D7: N.A. | E7: Paid to Narayan Electricals - Bin for society | F7: 0 | G7: 290 | H7: 31.03.20
A8: 43556 | B8: 461 | C8: Electrical Repair Maintenance | D8: N.A. | E8: LED light for Staircase by Smitha | F8: 0 | G8: 179 | H8: 31.03.20
A9: 43556 | B9: 0 | C9: Sale of Scrap | D9: N.A. | E9: Sale of Scrap - Old metal gates | F9: 3700 | G9: 0
A10: 43586 | B10: 352 | C10: Salary Expenses,Garden Maintenance Expenses | D10: N.A. | E10: Being salary paid for April 2019 | F10: 0 | G10: 1000
A11: 43586 | B11: 354 | C11: Salary Expenses | D11: N.A. | E11: Being salary paid for April 2019 | F11: 0 | G11: 1000
A12: 43586 | B12: 356 | C12: Salary Expenses | D12: N.A. | E12: Being salary paid for April 2019 | F12: 0 | G12: 1125
A13: 43617 | B13: 353 | C13: Salary Expenses,Garden Maintenance Expenses | D13: N.A. | E13: Being salary paid for May 2019 | F13: 0 | G13: 900
A14: 43617 | B14: 355 | C14: Salary Expenses | D14: N.A. | E14: Being salary paid for May 2019 | F14: 0 | G14: 1000
A15: 43617 | B15: 357 | C15: Salary Expenses | D15: N.A. | E15: Being salary paid for May 2019 | F15: 0 | G15: 1500
A16: 43623 | B16: 0 | D16: 15431 | E16: Being Cash withdrawn | F16: 3000 | G16: 0
A17: 43647 | B17: 359 | C17: Salary Expenses | D17: N.A. | E17: Being salary paid for June 2019 | F17: 0 | G17: 600
A18: 43647 | B18: 360 | C18: Salary Expenses | D18: N.A. | E18: Being salary paid for June 2019 | F18: 0 | G18: 1500
A19: 43647 | B19: 361 | C19: Salary Expenses | D19: N.A. | E19: Being salary paid for June 2019 | F19: 0 | G19: 1000
A20: 43647 | B20: 362 | C20: Other Repair Maintenance | D20: N.A. | E20: Being paid for staircase washing | F20: 0 | G20: 200
A21: 43649 | B21: 0 | D21: 15435 | E21: Being Cash withdrawn | F21: 7000 | G21: 0
A22: 43668 | B22: 0 | D22: 15439 | E22: Being Cash withdrawn | F22: 6000 | G22: 0
A23: 43669 | B23: 358 | C23: Garden Maintenance Expenses | D23: N.A. | E23: Being paid for cutting of tree | F23: 0 | G23: 6000
A24: 43680 | B24: 363 | C24: Salary Expenses | D24: N.A. | E24: Being salary paid for July 2019 | F24: 0 | G24: 600
A25: 43680 | B25: 364 | C25: Salary Expenses | D25: N.A. | E25: Being salary paid for July 2019 | F25: 0 | G25: 1500
A26: 43680 | B26: 365 | C26: Salary Expenses | D26: N.A. | E26: Being salary paid for July 2019 | F26: 0 | G26: 1000
A27: 43687 | B27: 370 | C27: Electrical Repair Maintenance | D27: N.A. | E27: Being paid for electrical repairs | F27: 0 | G27: 1295
A28: 43690 | B28: 0 | D28: 35067 | E28: Being Cash withdrawn | F28: 3000 | G28: 0
A29: 43710 | B29: 366 | C29: Salary Expenses | D29: N.A. | E29: Being salary paid for August 2019 | F29: 0 | G29: 600
A30: 43710 | B30: 367 | C30: Salary Expenses | D30: N.A. | E30: Being salary paid for August 2019 | F30: 0 | G30: 1000
A31: 43710 | B31: 368 | C31: Salary Expenses | D31: N.A. | E31: Being salary paid for August 2019 | F31: 0 | G31: 1500
A32: 43710 | B32: 369 | C32: Electrical Repair Maintenance | D32: N.A. | E32: Being paid for Lift Repair & Maintenance | F32: 0 | G32: 140
A33: 43721 | B33: 0 | D33: 35069 | E33: Being Cash Withdrawn | F33: 3000 | G33: 0
A34: 43732 | B34: 0 | D34: 35070 | E34: Being Cash Withdrawn | F34: 2000 | G34: 0
A35: 43739 | B35: 371 | C35: Salary Expenses | D35: N.A. | E35: Being salary paid for September 2019 | F35: 0 | G35: 600
A36: 43739 | B36: 372 | C36: Salary Expenses | D36: N.A. | E36: Being salary paid for September 2019 | F36: 0 | G36: 1000
A37: 43739 | B37: 373 | C37: Salary Expenses | D37: N.A. | E37: Being salary paid for September 2019 | F37: 0 | G37: 1500
A38: 43739 | B38: 374 | C38: Other Repair Maintenance | D38: N.A. | E38: Being paid for Name plate change | F38: 0 | G38: 600
A39: 43739 | B39: 375 | C39: Postage & Courier | D39: N.A. | E39: Being courier exp paid | F39: 0 | G39: 35
A40: 43739 | B40: 376 | C40: Other Repair Maintenance | D40: N.A. | E40: Being cleaning expenses paid | F40: 0 | G40: 200
A41: 43767 | B41: 0 | D41: 35074 | E41: Being Cash withdrawn | F41: 3000 | G41: 0
...
