Workbook

Sheet BS
A1: MANIKA CO-OPERATIVE HOUSING SOCIETY LTD.
A2: (REDG. NO. MUM / WK-E/HSG/TC/14068/2008 Dtd. 04.02.2008
A3: CTS. NO. 556, & 558, MAHAKALI CAVES ROAD, KONDIVITA, ANDHERI (EAST), MUMBAI - 400093.
A4: Balance Sheet as at March 31, 2026
A5: March 31, 2025 | B5: LIABILITIES | D5: March 31, 2026 | E5: =A5 -> March 31, 2025 | F5: ASSETS | H5: =D5 -> March 31, 2026
B6: Authorised Share Capital | F6: Cash and Bank Balance :
A7: 100000 | B7: ( 2,000 share of Rs. 50 each ) | D7: 100000 | E7: 4541 | F7: Cash Book | G7: 1245
E8: 246675.31 | F8: MDCC Bank | G8: =BRS!C5 -> 163170.31 | H8: =G7+G8 -> 164415.31
A9: 12500 | B9: Issued, Subscribed & Paid-up Share Capital | D9: 12500
B10: ( 250 shares of Rs. 50 each ) | F10: Investments :
B11: Reserve and Other Funds | E11: 100 | F11: 1 Share with Mumabi Housing Fed. | G11: 100
B12: (i) General Reserve Fund | E12: 1000 | F12: 1 Shares with MDCC Bank | G12: 1000
A13: 36250 | B13: Opening Balance | C13: =36250+26800+2900+33923 -> 99873 | E13: 2448326 | F13: Fixed Deposits with Banks (Sch 1) | G13: ='Sch 1 - FD'!D50 -> 2976958
A14: 26800 | B14: Add: Members Contributions | C14: =77700+2100 -> 79800 | E14: 88866 | F14: Accrued Interset | G14: ='Sch 1 - FD'!E50+'Sch 1 - FD'!F50 -> 125124 | H14: =SUM(G11:G14) -> 3103182
A15: 2900 | B15: Add: Interest earned | C15: =-IE!G23 -> 7965
A16: 33923 | B16: Add: 25% Surplus Trf to Reserve Fund | C16: =IE!C44 -> 3714 | D16: =SUM(C13:C16) -> 191352 | F16: Sundry Debtors :
B17: (ii) Common Amenity Fund | E17: 4443748 | F17: Dues from Members (Sch 3) | H17: ='Sch 3 - Member'!E19 -> 4699511
A18: 225000 | B18: Bal as per Last year | D18: 225000
B19: (iii) Sinking Fund | F19: Other Current Assets :
A20: 1184428 | B20: Opening Balance | C20: =1184428+47064+80627 -> 1312119 | E20: 22283.72 | F20: Deposit with Adani Electricity | G20: 22283.72
A21: 47064 | B21: Add: Members Contributions | C21: 47064 | E21: 17897 | F21: TDS Receivable FY 21-22 | G21: 17897
A22: 80627 | B22: Add: Interest earned | C22: =-IE!G21 -> 100671 | D22: =SUM(C20:C22) -> 1459854 | E22: 9902 | F22: TDS Receivable FY 22-23 | G22: 9902
B23: (iv) Repair Fund | E23: 12775 | F23: TDS Receivable FY 23-24 | G23: =40574-17897-9902 -> 12775
A24: 1790597 | B24: Opening Balance | C24: =1790597+141252+85345 -> 2017194 | E24: 16895 | F24: TDS Receivable FY 24-25 | G24: =57469-G23-G22-G21 -> 16895
A25: 141252 | B25: Add: Members Contributions | C25: 141252 | E25: 0 | F25: TDS Receivable FY 25-26 | G25: 20508
A26: 85345 | B26: Add: Interest earned | C26: =-IE!G22 -> 96046 | D26: =SUM(C24:C26) -> 2254492 | E26: 234938 | F26: Advance to Vendors (Sch 5) | G26: ='Sch 4 - Payables & Advance'!C23 -> 394996 | H26: =SUM(G20:G26) -> 495256.72
B27: (v) Education & Training Fund
A28: 0 | B28: Opening Balance | C28: =5880 -> 5880 | E28: 92657 | F28: Fixed Assets (Sch 2) | H28: ='Sch 2 - FA'!I12 -> 76054
A29: 5880 | B29: Add: Members Contributions | C29: 5880
A30: 0 | B30: Add: Interest earned | C30: =-IE!G24 -> 172 | D30: =SUM(C28:C30) -> 11932 | F30: Other Items :
B31: Current Liabilities & Provisions: | F31: Prepaid Expenses
A32: 390700 | B32: Municipal Taxes Refundable | C32: 390700 | E32: 11155 | F32: (i) Building Insurance Charges | G32: 11070 | H32: =SUM(G32) -> 11070
A33: 15518 | B33: TDS Payable | C33: 14486
A34: 626608 | B34: Payables/Provisions (Sch 4) | C34: ='Sch 4 - Payables & Advance'!C13 -> 574608 | D34: =SUM(C32:C34) -> 979794
B36: Members' Payables:
A37: 104678 | B37: Advance from Members (Sch 3) | C37: ='Sch 3 - Member'!E36 -> 124900
A38: 0 | B38: Unidentified Credit | C38: ='Sch 3 - Member'!E64 -> 5000
A39: 70000 | B39: Refundable Deposits (Sch 3) | C39: ='Sch 3 - Member'!E59 -> 105000 | D39: =SUM(C37:C39) -> 234900
B41: Unrealised Interest for S01/02
A42: 2213418 | B42: Op. Balance as per Last year | C42: =SUM(A42:A43) -> 2596476
...

Sheet IE
A1: MANIKA CO-OPERATIVE HOUSING SOCIETY LTD
A2: (REDG. NO. MUM / WK-E/HSG/TC/14068/2008 Dtd. 04.02.2008
A3: CTS. NO. 556, & 558, MAHAKALI CAVES ROAD, KONDIVITA, ANDHERI (EAST), MUMBAI - 400093.
A4: Income and Expenditure Account for the year ended March 31, 2026
A5: March 31, 2025 | B5: Expenditures | D5: March 31, 2026 | E5: =A5 -> March 31, 2025 | F5: Incomes | H5: =D5 -> March 31, 2026
B6: To Property Related Expenses: | F6: By Members' Contributions:
A7: 3884 | B7: Property Taxes | C7: 5042 | E7: 205212 | F7: Common Electricity Charges | G7: 205212
A8: 194392 | B8: Water Expenses | C8: 267596 | E8: 4116 | F8: Property Tax (Common Area) | G8: 4116
A9: 209390 | B9: Electricity Expenses | C9: 213700 | E9: 1321236 | F9: Service Charges | G9: 1321236
A10: 30795 | B10: Insurance Expenses | C10: 31166 | D10: =SUM(C7:C10) -> 517504 | E10: 354000 | F10: Water Charges | G10: 354000
B11: To Repairs and Maintenance: | E11: 70500 | F11: Parking Charges | G11: =71100+400 -> 71500
A12: 26660 | B12: Lift Maintenance Expenses | C12: 79123 | E12: 56680 | F12: Non-Occupancy Charges | G12: =60320+1560 -> 61880
A13: 15000 | B13: Garden Maintenance Expenses | C13: 12000 | E13: 4580 | F13: Other Charges | G13: 4080
A14: 10070 | B14: Electrical Maintenance | C14: 9730 | E14: 39120 | F14: Insurance Charges | G14: 39120
A15: 400000 | B15: Major Repair - Lift | C15: 0 | E15: 442374 | F15: Late Payment Charges | G15: 452770
A16: 111360 | B16: Other Repair Maintenance | C16: 49150 | E16: -383058 | F16: Less: Members Unrealised Interest | G16: -396833 | H16: =SUM(G7:G16) -> 2117081
A17: 19380 | B17: Plumbing Repair Maintenance | C17: 17950
A18: 34500 | B18: Water Pump Repair Charges | C18: 51350 | F18: By Interest Income:
A19: 0 | B19: Water Tank Cleaning Expenses | C19: 8000 | D19: =SUM(C12:C19) -> 227303 | E19: 8729 | F19: Interest on Savings Account | G19: 5638
B20: To Services Purchased: | E20: 168872 | F20: Interest on Fixed Deposits | G20: 205033
A21: 579500 | B21: Security Expenses | C21: 579600 | E21: -80627 | F21: Less: Trf to Sinking Fund | G21: -100671
A22: 210750 | B22: Staff Salaries/Bonus | C22: 227250 | E22: -85345 | F22: Less: Trf to Repair Fund | G22: -96046
A23: 23200 | B23: Pest Control Expenses | C23: 24500 | E23: -2900 | F23: Less: Trf to Reserve Fund | G23: -7965
A24: 7205 | B24: Housekeeping Consumables | C24: 7086 | E24: 0 | F24: Less: Trf to Education Fund | G24: -172 | H24: =SUM(G19:G24) -> 5817
A25: 51000 | B25: Accounting Expenses | C25: 56100 | D25: =SUM(C21:C25) -> 894536
B26: To Administrative Expenses | F26: By Other Member Income
A27: 10606 | B27: Festival Expense | C27: 17114 | E27: 30000 | F27: Shifting Charges | G27: 70000
A28: 1610 | B28: Meeting/Function Expenses | C28: 3715 | E28: 3000 | F28: Penalty | G28: 0 | H28: =SUM(G27:G28) -> 70000
A29: 22789 | B29: Interest & Penalty on TDS | C29: 360
A30: 3200 | B30: Staff Welfare | C30: 0 | F30: By Other Income:
A31: 1200 | B31: Misc. Expenses | C31: 2017 | E31: 314 | F31: Sale of Scrap | H31: 4000
A32: 22245 | B32: Depreciation on Fixed Assets | C32: ='Sch 2 - FA'!H12 -> 16603
A33: 11901 | B33: Conveyance Expenses | C33: 25037
A34: 12629 | B34: Printing & Stationery | C34: 15590
A35: 0 | B35: Telephone and Internet Expense | C35: 6899
A36: 461 | B36: Postage and Courier | C36: 950
A37: 0 | B37: Professional and Legal Fees | C37: =440500+7500 -> 448000
A38: 910 | B38: Income Tax Expenses | C38: 587
A39: 5000 | B39: Audit Fees | C39: 5000
A40: 826 | B40: Federation Subscription Fees | C40: 826
...

Sheet Sch 1 - FD
A1: MANIKA CO-OPERATIVE HOUSING SOCIETY LTD
A3: Schedule 1: Details of Fixed Assets as at 31 March 2026
J4: (Amt. in Rs.)
A5: Sr. | B5: Certificate No. | C5: Deposit Date | D5: Principal | E5: Accd. Int. FY 2024-25 | F5: Accd. Int. FY 2025-26 | G5: Total Value Invested | H5: Maturity Date | I5: Maturity Amount | J5: ROI | K5: Bank
B6: Sinking Fund
A7: 1 | B7: 1212_04 | C7: 28.05.2025 | D7: 121524 | E7: 0 | F7: 7068 | G7: =SUM(D7:F7) -> 128592 | H7: 28.05.2026 | I7: 130898 | J7: 0.075 | K7: MDCC
A8: 2 | B8: 1181_04 | C8: 11.04.2025 | D8: 98134 | E8: 0 | F8: 6774 | G8: =SUM(D8:F8) -> 104908 | H8: 11.04.2026 | I8: 105911 | J8: 0.077 | K8: MDCC
A9: 3 | B9: 1211_04 | C9: 28.05.2025 | D9: 77515 | E9: 0 | F9: 4507 | G9: =SUM(D9:F9) -> 82022 | H9: 28.05.2026 | I9: 83494 | J9: 0.075 | K9: MDCC
A10: 4 | B10: 1210_04 | C10: 18.05.2025 | D10: 83528 | E10: 0 | F10: 5020 | G10: =SUM(D10:F10) -> 88548 | H10: 18.05.2026 | I10: 89971 | J10: 0.075 | K10: MDCC
A11: 5 | B11: 0992_04 | C11: 09.09.2025 | D11: 91490 | E11: 0 | F11: 3168 | G11: =SUM(D11:F11) -> 94658 | H11: 09.09.2026 | I11: 97872 | J11: 0.068 | K11: MDCC
A12: 6 | B12: 0864_04 | C12: 30.03.2026 | D12: 127102 | E12: 0 | F12: 41 | G12: =SUM(D12:F12) -> 127143 | H12: 30.03.2027 | I12: 135767 | J12: 0.0665 | K12: MDCC
A13: 7 | B13: 1813_04 | C13: 27.03.2026 | D13: 119032 | E13: 0 | F13: 97 | G13: =SUM(D13:F13) -> 119129 | H13: 27.03.2027 | I13: 127147 | J13: 0.0665 | K13: MDCC
A14: 8 | B14: 1151_04 | C14: 27.03.2026 | D14: 72553 | E14: 0 | F14: 59 | G14: =SUM(D14:F14) -> 72612 | H14: 27.03.2027 | I14: 77499 | J14: 0.0665 | K14: MDCC
A15: 9 | B15: 1312_04 | C15: 12.03.2026 | D15: 67200 | E15: 0 | F15: 220 | G15: =SUM(D15:F15) -> 67420 | H15: 12.03.2026 | I15: 71781 | J15: 0.0665 | K15: MDCC
A16: 10 | B16: 1178_04 | C16: 31.03.2026 | D16: 77480 | E16: 0 | F16: 0 | G16: =SUM(D16:F16) -> 77480 | H16: 31.03.2027 | I16: 82762 | J16: 0.0665 | K16: MDCC
A17: 11 | B17: 1577 | C17: 16.07.2024 | D17: 100000 | E17: =5598-560 -> 5038 | F17: 7518 | G17: =SUM(D17:F17) -> 112556 | H17: 16.07.2026 | I17: 116593 | J17: 0.0775 | K17: MDCC
A18: 12 | B18: 1574 | C18: 26.06.2024 | D18: 100000 | E18: =6025-603 -> 5422 | F18: 7547 | G18: =SUM(D18:F18) -> 112969 | H18: 26.06.2026 | I18: 116593 | J18: 0.0775 | K18: MDCC
A19: 13 | B19: 1570 | C19: 14.06.2024 | D19: 100000 | E19: =6295-629 -> 5666 | F19: 7563 | G19: =SUM(D19:F19) -> 113229 | H19: 14.06.2026 | I19: 116593 | J19: 0.0775 | K19: MDCC
A20: 14 | B20: 1645 | C20: 12.11.2025 | D20: 100000 | E20: 0 | F20: 2371 | G20: =SUM(D20:F20) -> 102371 | H20: 12.11.2026 | I20: 106975 | J20: 0.068 | K20: MDCC
A21: 15 | B21: 1653 | C21: 11.12.2025 | D21: 100000 | E21: 0 | F21: 1886 | G21: =SUM(D21:F21) -> 101886 | H21: 11.12.2026 | I21: 106975 | J21: 0.068 | K21: MDCC
A22: 16 | B22: 1638 | C22: 14.10.2025 | D22: 8000 | E22: 0 | F22: 227 | G22: =SUM(D22:F22) -> 8227 | H22: 14.10.2026 | I22: 8558 | J22: 0.068 | K22: MDCC
A23: 17 | B23: 2655 | C23: 12.11.2025 | D23: 4000 | E23: 0 | F23: 93 | G23: =SUM(D23:F23) -> 4093 | H23: 12.11.2026 | I23: 4279 | J23: 0.068 | K23: MDCC
A24: 18 | B24: 1643 | C24: 12.11.2025 | D24: 12000 | E24: 0 | F24: 283 | G24: =SUM(D24:F24) -> 12283 | H24: 12.11.2026 | I24: 12837 | J24: 0.068 | K24: MDCC
A25: 19 | B25: 1657 | C25: 14.01.2026 | D25: 20000 | E25: 0 | F25: 257 | G25: =SUM(D25:F25) -> 20257 | H25: 14.01.2027 | I25: 21364 | J25: 0.068 | K25: MDCC
D26: =SUM(D7:D25) -> 1479558 | E26: =SUM(E7:E25) -> 16126 | F26: =SUM(F7:F25) -> 54699 | G26: =SUM(G7:G25) -> 1550383 | I26: =SUM(I7:I25) -> 1613869
B28: Reserve Fund
A29: 20 | B29: 2491_01 | C29: 16.02.2026 | D29: 109002 | E29: 0 | F29: =862-86 -> 776 | G29: =SUM(D29:F29) -> 109778 | H29: 16.05.2027 | I29: 118369 | J29: 0.077 | K29: MDCC
D30: =SUM(D29) -> 109002 | E30: =SUM(E29) -> 0 | F30: =SUM(F29) -> 776 | G30: =SUM(D30:F30) -> 109778 | I30: =SUM(I29) -> 118369
B32: Repair Fund
A33: 21 | B33: 1867_04 | C33: 28.05.2025 | D33: 363746 | E33: 0 | F33: =23511-2351 -> 21160 | G33: =SUM(D33:F33) -> 384906 | H33: 28.05.2026 | I33: 391804 | J33: 0.075 | K33: MDCC
A34: 22 | B34: 0785_04 | C34: 09.10.2025 | D34: 191696 | E34: 0 | F34: 0 | G34: =SUM(D34:F34) -> 191696 | H34: 09.10.2026 | I34: 191696 | J34: 0.068 | K34: MDCC
A35: 23 | B35: 2012_04 | C35: 12.03.2026 | D35: 201682 | E35: 0 | F35: =735-74 -> 661 | G35: =SUM(D35:F35) -> 202343 | H35: 12.03.2027 | I35: 215432 | J35: 0.0665 | K35: MDCC
A36: 24 | B36: 1868_04 | C36: 28.05.2025 | D36: 232654 | E36: 0 | F36: =15038-1504 -> 13534 | G36: =SUM(D36:F36) -> 246188 | H36: 28.05.2026 | I36: 250600 | J36: 0.075 | K36: MDCC
A37: 25 | B37: 1860_04 | C37: 23.05.2025 | D37: 250120 | E37: 0 | F37: =16435-1643 -> 14792 | G37: =SUM(D37:F37) -> 264912 | H37: 23.05.2026 | I37: 269413 | J37: 0.075 | K37: MDCC
A38: 26 | B38: 2656 | C38: 12.11.2025 | D38: 100000 | E38: 0 | F38: =2634-263 -> 2371 | G38: =SUM(D38:F38) -> 102371 | H38: 12.11.2026 | I38: 106975 | J38: 0.068 | K38: MDCC
A39: 27 | B39: 2644 | C39: 14.10.2025 | D39: 24000 | E39: 0 | F39: =765-76 -> 689 | G39: =SUM(D39:F39) -> 24689 | H39: 14.10.2026 | I39: 25674 | J39: 0.068 | K39: MDCC
D40: =SUM(D33:D39) -> 1363898 | E40: =SUM(E33:E39) -> 0 | F40: =SUM(F33:F39) -> 53207 | G40: =SUM(G33:G39) -> 1417105 | I40: =SUM(I33:I39) -> 1451594
B42: Education & Training Fund
A43: 28 | B43: 2677 | C43: 14.01.2026 | D43: 12000 | E43: 0 | F43: =172-17 -> 155 | G43: =SUM(D43:F43) -> 12155 | H43: 14.01.2027 | I43: 12818 | J43: 0.0665 | K43: MDCC
D44: =SUM(D43) -> 12000 | E44: =SUM(E43) -> 0 | F44: =SUM(F43) -> 155 | G44: =SUM(D44:F44) -> 12155 | I44: =SUM(I43) -> 12818
...

Sheet Sch 2 - FA
B1: MANIKA CO-OPERATIVE HOUSING SOCIETY LTD
B3: Schedule 2 - Fixed Assets Details as on 31 March 2026
B5: Assets | C5: Gross Block | G5: Depreciation | I5: Net Block
C6: Cost as at 01.04.2025 | D6: Additions on or before 30.09.2025 | E6: Additions after 30.09.2025 | F6: Cost as at 31.03.2026 | G6: Rate of Dep (%) | H6: For the Year
B7: Furniture | C7: 18039 | D7: 0 | E7: 0 | F7: =SUM(C7:E7) -> 18039 | G7: 0.1 | H7: =ROUND((C7+D7+E7/2)*G7,) -> 1804 | I7: =F7-H7 -> 16235
B8: Water Pump | C8: 15879 | D8: 0 | E8: 0 | F8: =SUM(C8:E8) -> 15879 | G8: 0.15 | H8: =ROUND((C8+D8+E8/2)*G8,) -> 2382 | I8: =F8-H8 -> 13497
B9: CCTV | C9: 37508 | D9: 0 | E9: 0 | F9: =SUM(C9:E9) -> 37508 | G9: 0.15 | H9: =ROUND((C9+D9+E9/2)*G9,) -> 5626 | I9: =F9-H9 -> 31882
B10: Sound System | C10: 6803 | D10: 0 | E10: 0 | F10: =SUM(C10:E10) -> 6803 | G10: 0.15 | H10: =ROUND((C10+D10+E10/2)*G10,) -> 1020 | I10: =F10-H10 -> 5783
B11: Laptop | C11: 14428 | D11: 0 | E11: 0 | F11: =SUM(C11:E11) -> 14428 | G11: 0.4 | H11: =ROUND((C11+D11+E11/2)*G11,) -> 5771 | I11: =F11-H11 -> 8657
B12: Total | C12: =SUM(C7:C11) -> 92657 | D12: =SUM(D7:D11) -> 0 | E12: =SUM(E7:E11) -> 0 | F12: =SUM(F7:F11) -> 92657 | H12: =SUM(H7:H11) -> 16603 | I12: =SUM(I7:I11) -> 76054

Sheet Sch 3 - Member
A1: MANIKA CO-OPERATIVE HOUSING SOCIETY LTD.
A2: Schedule 3:
A3: Members' Receivables as at 31.03.2026
A4: Sr. | B4: Wing | C4: Flat | D4: Name of Member | E4: Amount (Rs.)
A5: 1 | B5: A | C5: 8 | D5: MRS. ROSA B. GEORGE & MR. BOBAN GEORGE | E5: 11494
A6: 2 | B6: A | C6: 102 | D6: MR. GURPREET SINGH SAINI & MR. RASHPAL SINGH SAINI | E6: 4111
A7: 3 | B7: A | C7: 602 | D7: MRS. SHUSHILA RAMNARAYAN MISHRA & MR. RAMNARAYAN R. MISHRA | E7: 4584
A8: 4 | B8: B | C8: 102 | D8: MR. HASNAIN HASMAT KHAN | E8: 8094
A9: 5 | B9: B | C9: 201 | D9: MR. GIRDHARILAL PATHAK | E9: 8170
A10: 6 | B10: B | C10: 202 | D10: MR. SANTOSH GANPAT AMBULGE | E10: 36657
A11: 7 | B11: B | C11: 601 | D11: MR. JASBIR SINGH KAPOOR & MR. GURJIT SINGH KAPOOR | E11: 81
A12: 8 | B12: C | C12: 3 | D12: MRS. AMIRTA RAJARAM YADAV, MRS. VIMALADEVI U. YADAV & MRS. GEETA L . YADAV | E12: 28173
A13: 9 | B13: C | C13: 101 | D13: MRS. RASULBI HASMATH KHAN | E13: 25121
A14: 10 | B14: C | C14: 202 | D14: MR. BHARAT B. SINGH | E14: 7831
A15: 11 | B15: Shop | C15: 01 & 02 | D15: MR. CHITTRESEN SHARMA | E15: 4496906
A16: 12 | B16: Shop | C16: 3 | D16: MR. KAMALPRASAD GUPTA | E16: 7829
A17: 13 | B17: Shop | C17: 4 | D17: MRS. NOORBANO JIBRAIL SHAIKH & MR. JABRAIL BABADIN SHAIKH | E17: 55395
A18: 14 | B18: Shop | C18: 5 | D18: MR. JIBRAIL BABADIN SHAIKH & MRS. NOORBANO JABRAIL SHAIKH | E18: 5065
A19: Total | E19: =SUM(E5:E18) -> 4699511
A21: Members' Advances as at 31.03.2026
A22: Sr. | B22: Wing | C22: Flat | D22: Name of Member | E22: Amount (Rs.)
A23: 1 | B23: A | C23: 101 | D23: MR. ALOKE CHATTERJEE & MRS. PRITI CHATTERJEE | E23: 3924
A24: 2 | B24: A | C24: 301 | D24: MR. MELROY GAVIN NICHOLAS REGO & MRS. NITIKA MELROY REGO | E24: 22445
A25: 3 | B25: A | C25: 401 | D25: MRS. KALAVATHI D. SHETTY & MR. DAYANAND K. SHETTY | E25: 4781
A26: 4 | B26: A | C26: 502 | D26: MRS. LYDIA FERNANDES & MR. JOAQUIM A. FERNANDES | E26: 15090
A27: 5 | B27: A | C27: 601 | D27: MR. RAJESH BALDEV MANDHYAN | E27: 4428
A28: 6 | B28: B | C28: 4 | D28: MS. SWARAJI RAMUGRAH SINGH | E28: 15076
A29: 7 | B29: B | C29: 301 | D29: MISS. CELESTE GERALD KURSHINGAL | E29: 5000
A30: 8 | B30: B | C30: 401 | D30: MRS. PARUL M. MEHTA & MR. MEHOOL I. MEHTA | E30: 14099
A31: 9 | B31: B | C31: 501 | D31: MR. PRAVIN TRIVEDI | E31: 8622
A32: 10 | B32: B | C32: 502 | D32: MRS. LOVEY RAMOS | E32: 19684
A33: 11 | B33: C | C33: 1 | D33: MR. RAMNARAYAN H. YADAV & MR. SABAJEET H. YADAV | E33: 1
A34: 12 | B34: C | C34: 301 | D34: MRS. ROSHNI EDWARD ANTHONY | E34: 23
A35: 13 | B35: C | C35: 302 | D35: MR. VASANT A. PAWALE | E35: 11727
A36: Total | E36: =SUM(E23:E35) -> 124900
A38: Members' Refundable Deposits as at 31.03.2026
A39: Sr. | B39: Wing | C39: Flat | D39: Name of Member | E39: Amount (Rs.)
A40: 1 | B40: A | C40: 008 | D40: MRS. ROSA B. GEORGE & MR. BOBAN GEORGE | E40: 5000
A41: =+A40+1 -> 2 | B41: A | C41: 301 | D41: MR. MELROY GAVIN NICHOLAS REGO & MRS. NITIKA MELROY REGO | E41: 5000
A42: 2 | B42: A | C42: 302 | D42: MR. JEROME ALMEIDA | E42: 5000
...

Sheet Sch 4 - Payables & Advance
A1: MANIKA CO-OPERATIVE HOUSING SOCIETY LTD
A2: Schedule 4:
A3: Vendor Payables/Provisions as at 31.03.2026
A5: Sr. | B5: Vendor Name | C5: Amount | D5: Remark
A6: 1 | B6: Adani Electricity | C6: 14050 | D6: March-2024
A7: 2 | B7: Water Charges Payable -BMC | C7: =17928+69048 -> 86976 | D7: Period: 04.01.2023 to 31.03.2024
A8: 3 | B8: National Enterprise - Security | C8: 47040 | D8: March-2024
A9: 4 | B9: Audit Fees Payable | C9: 5000 | D9: FY 2023-24
A10: 5 | B10: Advocate Dattatray Solankar | C10: 17500 | D10: March-2024
A11: 6 | B11: Major Repair - Lift | C11: 400000
A12: 7 | B12: Income Tax | C12: =2045+500+910+587 -> 4042
B13: Total | C13: =SUM(C6:C12) -> 574608
A16: Schedule 5:
A17: Advances to Vendors at 31.03.2026
A19: Sr. | B19: Particulars | C19: Amount | D19: Remark
A20: 1 | B20: BMC | C20: 17952 | D20: Loan EMI
A21: 2 | B21: Irene Rosario - TDS | C21: 805
A22: 3 | B22: Microtech Elevators | C22: 376239
B23: Total | C23: =SUM(C20:C22) -> 394996

Sheet BRS
A1: MANIKA CO-OPERATIVE HOUSING SOCIETY LTD
A3: MDCC Bank Reconciliation Statement as at 31.03.2026
A4: Particulars | C4: Amount | E4: Sr. | F4: Date | G4: Deposit | H4: Issued | I4: Remarks | J4: Instr No. | K4: Cleared on
A5: Balance as per books | C5: 163170.31 | E5: 1 | F5: 30.03.2026 | G5: 4277 | H5: 0 | I5: Flat C 101 Maintenance | J5: MIK013145884 | K5: 02.04.2026
E6: 2 | F6: 30.03.2026 | G6: 0 | H6: 9500 | I6: Darsana Kakda | J6: 028775 | K6: 13.04.2026
A7: Add: | B7: Cheques Issued but not presented | C7: =H7 -> 9500 | G7: =SUM(G5:G6) -> 4277 | H7: =SUM(H5:H6) -> 9500
A9: Less: | B9: Cheques deposited but not presented | C9: =G7 -> 4277
A11: Balance as per Bank Statement | C11: =C5+C7-C9 -> 168393.31
B18: Previous years TDS Receivables are still shown as Receivables in Current year, Society has to take necessary steps to resolve the same.
B20: The dues from members should be recovered regularly and if necessary initiate legal action under New Ammendment section 154 B-29 of the MCS Act, 1960, the members should confirm their debts from time to time.

Sheet Working
A2: 1 | B2: Water expense | M2: 2 | N2: Provision for Income Tax | U2: Notes
C3: Period | E3: No of Days | F3: Water Connection | N3: Income from Savings A/c. | P3: =IE!G19 -> 5638 | T3: 1 | U3: Insurance bill required - Prepaid
F4: KE@0047152 | G4: KE@0047140 | H4: KE@0047139 | I4: KE@0047176 | J4: KE@0047164 | K4: Total | N4: Other Income | P4: 0 | T4: 2 | U4: March 2025 bills paid in April 2025 (vouchers)
C5: 45294 | D5: 45385 | E5: =D5-C5+1 -> 92 | F5: 15105 | G5: 17952 | H5: 19198 | I5: 1020 | J5: 1948 | K5: =SUM(F5:J5) -> 55223 | N5: Income from Fixed Deposit | P5: =IE!G20 -> 205033 | T5: 3 | U5: Audit report for FY 2023-24
B6: Less: Last year | C6: =C5 -> 45294 | D6: 45382 | E6: =D6-C6+1 -> 89 | F6: 16329 | G6: 18259 | H6: 19537 | I6: 983 | J6: 1877 | K6: =SUM(F6:J6) -> 56985 | N6: Dividend | P6: 0 | T6: 4 | U6: Water to check
C7: 45383 | D7: =D5 -> 45385 | E7: =D7-C7+1 -> 3 | F7: =F5-F6 -> -1224 | G7: =G5-G6 -> -307 | H7: =H5-H6 -> -339 | I7: =I5-I6 -> 37 | J7: =J5-J6 -> 71 | K7: =SUM(F7:J7) -> -1762 | N7: Less: 80P2d benefit | P7: =-P5 -> -205033
C8: =D5 -> 45385 | D8: 45476 | E8: =D8-C8 -> 91 | F8: 15239 | G8: 17928 | H8: 19281 | I8: 1020 | J8: 1948 | K8: =SUM(F8:J8) -> 55416 | N8: Total Taxable Income | P8: =SUM(P3:P7) -> 5638
C9: =D8 -> 45476 | D9: 45569 | E9: =D9-C9 -> 93 | F9: 14207 | G9: 17078 | H9: 16883 | I9: 1020 | J9: 2055 | K9: =SUM(F9:J9) -> 51243 | N9: Liability 10% | P9: =P8*10% -> 563.8
C10: =D9 -> 45569 | D10: 45663 | E10: =D10-C10 -> 94 | F10: 6742 | G10: 14768 | H10: 14916 | I10: 1020 | J10: 2055 | K10: =SUM(F10:J10) -> 39501 | N10: Education cess 4% | O10: 0.04 | P10: =ROUND(P9*O10,0) -> 23
C11: =C7 -> 45383 | D11: =D10 -> 45663 | E11: =SUM(E7:E10) -> 281 | F11: =SUM(F7:F10) -> 34964 | G11: =SUM(G7:G10) -> 49467 | H11: =SUM(H7:H10) -> 50741 | I11: =SUM(I7:I10) -> 3097 | J11: =SUM(J7:J10) -> 6129 | K11: =SUM(F11:J11) -> 144398 | N11: Total Tax | P11: =P9+P10 -> 586.8
B12: Add: Provison | C12: =D11 -> 45663 | D12: 45747 | E12: =D12-C12 -> 84 | F12: =ROUND(13887/88*E12,0) -> 13256 | G12: =ROUND(17721/88*E12,0) -> 16916 | H12: =ROUND(17663/88*E12,0) -> 16860 | I12: =ROUND(1120/88*E12,0) -> 1069 | J12: =ROUND(2008/88*E12,0) -> 1917 | K12: =SUM(F12:J12) -> 50018 | L12: =K12+F10+G10+H10 -> 86444 | N12: Say | P12: 910
C13: =C11 -> 45383 | D13: =D12 -> 45747 | E13: =E11+E12 -> 365 | F13: =F11+F12 -> 48220 | G13: =G11+G12 -> 66383 | H13: =H11+H12 -> 67601 | I13: =I11+I12 -> 4166 | J13: =J11+J12 -> 8046 | K13: =K11+K12 -> 194416
A18: 2 | B18: Insurance | C18: 45513 | D18: 45878 | E18: =D18-C18 -> 365 | F18: 31080
B19: Prepaid | C19: 45748 | D19: =D18 -> 45878 | E19: =D19-C19+1 -> 131 | F19: =ROUND(E19*F18/E18,0) -> 11155
C20: =C18 -> 45513 | D20: 45747 | E20: =E18-E19 -> 234 | F20: =F18-F19 -> 19925
B27: Shop 1/2 Unrealized Late Payment Interest
B28: Sl.No | C28: Posted Date | D28: Invoice No | E28: Amount
B29: 1 | C29: 01-04-24 | D29: 2425049 | E29: 31997
B30: 2 | C30: 01-05-24 | D30: 2425097 | E30: 31075
B31: 3 | C31: 01-06-24 | D31: 2425149 | E31: 32190
B32: 4 | C32: 01-07-24 | D32: 2425202 | E32: 31265
B33: 5 | C33: 01-08-24 | D33: 2425251 | E33: 32384
B34: 6 | C34: 01-09-24 | D34: 2425301 | E34: 32481
B35: 7 | C35: 01-10-24 | D35: 2425350 | E35: 31550
B36: 8 | C36: 01-11-24 | D36: 2425399 | E36: 32675
B37: 9 | C37: 01-12-24 | D37: 2425448 | E37: 31740
B38: 10 | C38: 01-01-25 | D38: 2425497 | E38: 32869
B39: 11 | C39: 01-02-25 | D39: 2425546 | E39: 32966
B40: 12 | C40: 01-03-25 | D40: 2425601 | E40: 29866
B41: Total | E41: =SUM(E29:E40) -> 383058
