Workbook

Sheet BS
A1: HELENA VILLA CO-OPERATIVE HOUSING SOCIETY LIMITED
A2: (Regd. No MUM/WP/HSG/TC/12195 DATED 19-09-2003)
A3: BALANCE SHEET AS ON 31ST MARCH 2026
H4: (Amt. in Rs.)
A5: Previous Year | B5: LIABILITIES | D5: Current Year | E5: Previous Year | F5: ASSETS | H5: Current Year
A6: 2024-25 | D6: 2025-26 | E6: =A6 -> 2024-25 | H6: =D6 -> 2025-26
B7: Authorised Share Capital | F7: Cash & Bank Balance
A8: 1500000 | B8: (30000 Shares of Rs. 50 each) | D8: =30000*50 -> 1500000 | E8: 413 | F8: Cash in hand | G8: 385
E9: 44950.15 | F9: Citizen Credit Bank | G9: =BRS!B4 -> 245299.35
B10: Issued, Subscribed and Paid Up Share Capital | E10: 2453 | F10: MDCC Bank | G10: =BRS!B15 -> 6544 | H10: =SUM(G8:G10) -> 252228.35
A11: 3500 | B11: (70 shares of Rs. 50/- each ) | D11: 3500
F12: Deposits
A13: 705712 | B13: Gen. Reserve and Surplus Fund - (Sch III) | D13: ='Sch III - R&S'!D34 -> 789872 | E13: 1894.88 | F13: Security Deposit with Adani | H13: 1894.88
B15: New Water Pipeline Fund | F15: Investments
A16: 4814 | B16: As per last Balance Sheet | C16: =A16+A17 -> 4092 | E16: 1000 | F16: Share with MDCC | G16: 1000
A17: -722 | B17: Less: Depreciation 15% | C17: -614 | D17: =SUM(C16:C17) -> 3478 | E17: 100 | F17: 1 share of MDHF | G17: 100
E18: 894741 | F18: Fixed Deposits - (Sch I) | G18: ='Sch I - FD'!C30 -> 678952
B19: Lift Upgradation Fund | E19: 63658 | F19: Accrued Interest - (Sch I) | G19: ='Sch I - FD'!D30+'Sch I - FD'!E30+'Sch I - FD'!F30 -> 87056 | H19: =SUM(G16:G19) -> 767108
A20: 137492 | B20: As per last Balance Sheet | C20: =A20+A21 -> 116868
A21: -20624 | B21: Less: Depreciation 15% | C21: -17530 | D21: =SUM(C20:C21) -> 99338 | E21: 157834 | F21: Fixed Assets - (Sch II) | H21: ='Sch II - FA'!H10 -> 134344
B23: Current Liabilities & Provisions : | F23: Other Current Assets:
A24: 2000 | B24: Audit Fees | C24: 2000 | E24: 4402 | F24: TDS Receivables | H24: 4402
A25: 9003 | B25: BMC (Water Charges) | C25: 0
A26: 3730 | B26: Electricity Charges | C26: 3361.59
A27: 5326 | B27: Professional Fees | C27: 1500 | F27: Prepaid Expenses:
A28: 0 | B28: Income tax | C28: 0 | E28: 967 | F28: Pest Control | G28: =Workings!E20 -> 967
A29: 2602 | B29: Water Charges | C29: 2602 | D29: =SUM(C24:C29) -> 9463.59 | E29: 20355 | F29: Lift AMC | G29: =Workings!E9 -> 21240 | L29: =+H39-1202767.23 -> 0
E30: 5841 | F30: CCTV AMC | G30: =Workings!E15 -> 5841
A31: 73203 | B31: Advance from Members - (Sch IV) | D31: ='Sch IV - Mem. Adv'!D6 -> 40487 | E31: 3894 | F31: Intercom AMC | G31: 7788
E32: 6954 | F32: Building Insurance Charges | G32: =Workings!E25 -> 6954 | H32: =SUM(G28:G32) -> 42790
A33: 80300 | B33: Retention Sejal Construction | D33: 0
B35: Income & Expenditure Account
A36: 227732.5 | B36: As per last Balance Sheet | C36: =SUM(A36:A38) -> 203121.03
A37: 1160 | B37: Add: Prov of FY 23-24 Income tax w/back
A38: =-IE!E38 -> -25771.47 | B38: Add: Excess of Income over Expenditure | C38: =IE!D39 -> 53507.61 | D38: =C36+C37+C38 -> 256628.64
A39: =SUM(A11:A38) -> 1209457 | B39: Total | D39: =SUM(D10:D38) -> 1202767.2 | E39: =SUM(E7:E38) -> 1209457 | F39: Total | H39: =SUM(H8:H38) -> 1202767.2 | I39: =A39-E39 -> 0 | J39: =D39-H39 -> 0
A41: As per my report of even date | I41: =A39-E39 -> 0
E42: FOR HELENA VILLA CO-OPERATIVE HOUSING SOCIETY LTD
I44: =A39-E39 -> 0 | J44: =D39-H39 -> 0
A46: Shri. Bharat C. Boridkar
...

Sheet IE
A1: HELENA VILLA CO-OPERATIVE HOUSING SOCIETY LIMITED
A2: (Regd. No MUM/WP/HSG/TC/12195 DATED 19-09-2003)
A3: INCOME & EXPENDITURE ACCOUNT FOR THE YEAR ENDED 31ST MARCH 2026
H4: (Amt. in Rs.)
A5: Previous Year | B5: EXPENDITURE | D5: Current Year | E5: Previous Year | F5: INCOME | H5: Current Year
A6: 2024-25 | D6: 2025-26 | E6: =A6 -> 2024-25 | H6: =D6 -> 2025-26
F7: Members Contribution Towards
A8: 154710 | B8: Property Tax | D8: 214284 | E8: 0 | F8: Common Electricity Charges | G8: 45024
E9: 0 | F9: Water Charges | G9: 35952
A10: 36258 | B10: Water Expenses | D10: 35981 | E10: 150384 | F10: Property Tax | G10: =193827+14481 -> 208308
E11: 4368 | F11: Garage Tax | G11: =5628+420 -> 6048
A12: 23593 | B12: Building Insurance | D12: 23720 | E12: 423360 | F12: Maintenance Charges | G12: 421344
E13: 4800 | F13: Parking Charges | G13: 4600
A14: 44898.57 | B14: Electricity Charges | D14: 45888.69 | E14: 36 | F14: Late Payment Interest | G14: 99
E15: 15000 | F15: Non Occupancy Charges | G15: 16402
A16: 62545 | B16: Repair & Maintenance - (Sch V) | D16: ='Sch V -R&M'!C13 -> 86152.2 | F16: Insurance Charges | G16: 23940 | H16: =SUM(G8:G16) -> 761717
B18: Service Charges | F18: Interest Income
A19: 2000 | B19: Audit Fees | C19: 2000 | E19: 3927 | F19: Interest on Saving A/C | G19: 5805
A20: 25452 | B20: Salaries | C20: 13026 | E20: 65206 | F20: Interest on Fixed Deposits | G20: 56590
A21: 7514 | B21: Bonus | C21: 0 | E21: -32 | F21: Less: Trfd to Painting Fund | G21: -532
A22: 271071.5 | B22: Security Charges | C22: 289000 | E22: -23958 | F22: Less: Trfd to Sinking Fund | G22: -9780
A23: 1652 | B23: Subscription Charges | C23: 826 | E23: 0 | F23: Interest on Security Deposit | G23: 0
A24: 0 | B24: House Keeping Expenses | C24: 13810.5 | E24: 180 | F24: Interest on IT refund | G24: 0 | H24: =SUM(G19:G24) -> 52083
A25: 5589 | B25: Depreciation | C25: ='Sch II - FA'!G13 -> 5346
A26: 18000 | B26: Accounting Charges | C26: 19800
A27: 3000 | B27: Professional Fees | C27: =3000-3000+1500 -> 1500 | F27: Other Income
A28: 0 | B28: Miscellaneous Expense | C28: 0 | E28: 0 | F28: Sale of Scrap | G28: 400
A29: 5460 | B29: Office Expenses | C29: 500 | E29: 0 | F29: Miscellaneous Income | G29: 826 | H29: =SUM(G28:G29) -> 1226
A30: 35.4 | B30: Bank Charges | C30: 0
A31: 1277 | B31: Printing and Stationery | C31: 896
A32: 187 | B32: Income tax Expense | C32: 0
A33: 5800 | B33: Pest Control Expense | C33: =5800+967-967 -> 5800
A34: 0 | B34: Meeting Expenses | C34: 146
A35: 0 | B35: Conveyance Charges | C35: 1100
A36: 0 | B36: Festival Expenses (Festival 1) | C36: 1742 | D36: =SUM(C19:C36) -> 355492.5
E38: =A40-SUM(E10:E35) -> 25771.47 | F38: By Excess of Expenditure over Income
B39: By Excess of Income over Expenditure | D39: =H40-SUM(D7:D36) -> 53507.61
A40: =SUM(A7:A36) -> 669042.47 | B40: Total | D40: =SUM(D7:D39) -> 815026 | E40: =SUM(E7:E39) -> 669042.47 | F40: Total | H40: =SUM(H10:H39) -> 815026 | J40: =A40-E40 -> 0
A42: As per my report of even date | I42: =A40-E40 -> 0
E43: FOR HELENA VILLA CO-OPERATIVE HOUSING SOCIETY LTD
...

Sheet Sch I - FD
A1: HELENA VILLA CO-OPERATIVE HOUSING SOCIETY LIMITED
A2: (Regd. No MUM/WP/HSG/TC/12195 DATED 19-09-2003)
J3: (Amt in Rs.)
A4: FDR No. | B4: Date | C4: Amount Invested | D4: Accrued Int. 2023-24 | E4: Accrued Int. 2024-25 | F4: Accrued Int. 2025-26 | G4: Total | H4: Maturity Date | I4: Maturity Value | J4: Interest % | K4: Bank
A5: Sinking Fund
A6: 15320 | B6: 22.03.2026 | C6: 9756 | D6: 0 | E6: 0 | F6: 18 | G6: =SUM(C6+D6+E6+F6) -> 9774 | H6: 22.03.2028 | I6: 11154 | J6: 6.75 | K6: MDCC
A7: 3542476_R14 | B7: 17.03.2026 | C7: 43992 | D7: 0 | E7: 0 | F7: 103 | G7: =SUM(C7+D7+E7+F7) -> 44095 | H7: 17.03.2027 | I7: 44004 | J7: 6.1 | K7: CCB
A8: 15752 | B8: 20.03.2025 | C8: 6844 | D8: 0 | E8: 17 | F8: 542 | G8: =SUM(C8+D8+E8+F8) -> 7403 | H8: 20.06.2026 | I8: 7529 | J8: 7.7 | K8: MDCC
A9: 16212 | B9: 30.03.2026 | C9: 6636 | D9: 0 | E9: 0 | F9: 2 | G9: =SUM(C9+D9+E9+F9) -> 6638 | H9: 30.03.2028 | I9: 7587 | J9: 6.75 | K9: MDCC | M9: MDCC | N9: CCB
A10: Total | C10: =SUM(C6:C9) -> 67228 | D10: =SUM(D6:D9) -> 0 | E10: =SUM(E6:E9) -> 17 | F10: =SUM(F6:F9) -> 665 | G10: =SUM(G6:G9) -> 67910 | I10: =SUM(I6:I9) -> 70274 | M10: =+G10-G7 -> 23815 | N10: =+G7 -> 44095
M11: 0 | N11: 635842
A12: General Fund | M12: 0 | N12: 58756
A13: 1003921 | B13: 12.02.2024 | C13: 100000 | D13: =982-71 -> 911 | E13: =7497-750 -> 6747 | F13: 8020 | G13: =SUM(C13+D13+E13+F13) -> 115678 | H13: 12.11.2026 | I13: 121846 | J13: 7.25 | K13: CCB | M13: 3500
A14: 1003938 | B14: 12.02.2024 | C14: 100000 | D14: =982-71 -> 911 | E14: =7497-750 -> 6747 | F14: 8020 | G14: =SUM(C14+D14+E14+F14) -> 115678 | H14: 12.11.2026 | I14: 121846 | J14: 7.25 | K14: CCB | M14: =SUM(M10:M13) -> 27315 | N14: =SUM(N10:N13) -> 738693
A15: 1003941 | B15: 12.02.2024 | C15: 100000 | D15: =982-71 -> 911 | E15: =7497-750 -> 6747 | F15: 8020 | G15: =SUM(C15+D15+E15+F15) -> 115678 | H15: 12.11.2026 | I15: 121846 | J15: 7.25 | K15: CCB
A16: 1003957 | B16: 12.02.2024 | C16: 100000 | D16: =982-71 -> 911 | E16: =7497-750 -> 6747 | F16: 8020 | G16: =SUM(C16+D16+E16+F16) -> 115678 | H16: 12.11.2026 | I16: 121846 | J16: 7.25 | K16: CCB
A17: 1003962 | B17: 12.02.2024 | C17: 100000 | D17: =982-71 -> 911 | E17: =7497-750 -> 6747 | F17: 8020 | G17: =SUM(C17+D17+E17+F17) -> 115678 | H17: 12.11.2026 | I17: 121846 | J17: 7.25 | K17: CCB
A18: 1004194 | B18: 18.03.2024 | C18: 50000 | D18: =129-10 -> 119 | E18: =3723-374 -> 3349 | F18: 3984 | G18: =SUM(C18+D18+E18+F18) -> 57452 | H18: 18.12.2026 | I18: 60923 | J18: 7.25 | K18: CCB
A19: Total | C19: =SUM(C13:C18) -> 550000 | D19: =SUM(D13:D18) -> 4674 | E19: =SUM(E13:E18) -> 37084 | F19: =SUM(F13:F18) -> 44084 | G19: =SUM(G13:G18) -> 635842 | I19: =SUM(I13:I18) -> 670153
A21: Painting Fund
A22: 1008237 | B22: 30.03.2026 | C22: 28224 | D22: 0 | E22: 0 | F22: 5 | G22: =SUM(C22+D22+E22+F22) -> 28229 | H22: 30.03.2028 | I22: 31794 | J22: 6 | K22: CCB
A23: 1007566 | B23: 20.12.2025 | C23: 30000 | D23: 0 | E23: 0 | F23: 527 | G23: =SUM(C23+D23+E23+F23) -> 30527 | H23: 20.12.2028 | I23: 36134 | J23: 6.25 | K23: CCB
A24: Total | C24: =SUM(C22:C23) -> 58224 | D24: =SUM(D22:D23) -> 0 | E24: =SUM(E22:E23) -> 0 | F24: =SUM(F22:F23) -> 532 | G24: =SUM(G22:G23) -> 58756 | H24: =SUM(H22:H23) -> 0 | I24: =SUM(I22:I23) -> 67928
A26: Share Capital
A27: 7650 | B27: 20.03.2025 | C27: 3500 | D27: 0 | E27: 0 | F27: 0 | G27: =SUM(C27+D27+E27) -> 3500 | H27: 20.06.2026 | I27: 3500 | J27: 7.7 | K27: MDCC
A28: Total | C28: =SUM(C27) -> 3500 | D28: =SUM(D27) -> 0 | E28: =SUM(E27) -> 0 | F28: 0 | G28: =SUM(G27) -> 3500 | I28: =SUM(I27) -> 3500
A30: Grand Total | C30: =+C10+C19+C28+C24 -> 678952 | D30: =+D10+D19+D28+D24 -> 4674 | E30: =+E10+E19+E28+E24 -> 37101 | F30: =+F10+F19+F28+F24 -> 45281 | G30: =+G10+G19+G28+G24 -> 766008 | I30: =+I10+I19+I28+I24 -> 811855

Sheet Sch II - FA
A1: HELENA VILLA CO-OPERATIVE HOUSING SOCIETY LIMITED
A2: (Regd. No MUM/WP/HSG/TC/12195 DATED 19-09-2003)
A3: Particulars | B3: Rate % | C3: Opening W.D.V. as on 01.04.2025 | D3: Additions during the year before 30.09.2025 | E3: Additions during the year after 30.09.2025 | F3: Gross Block (at cost) as on 31.03.2026 | G3: Depreciation for the year | H3: Closing W.D.V. as on 31.03.2026
A4: Letter Box | B4: 0.1 | C4: 3200 | D4: 0 | E4: 0 | F4: =C4+D4+E4 -> 3200 | G4: =ROUND(((D4+C4)*B4)+(E4*B4)/2,0) -> 320 | H4: =F4-G4 -> 2880
A5: Cupboard | B5: 0.1 | C5: 497 | D5: 0 | E5: 0 | F5: =C5+D5+E5 -> 497 | G5: =ROUND(((D5+C5)*B5)+(E5*B5)/2,0) -> 50 | H5: =F5-G5 -> 447
A6: Intercom | B6: 0.15 | C6: 5709 | D6: 0 | E6: 0 | F6: =C6+D6+E6 -> 5709 | G6: =ROUND(((D6+C6)*B6)+(E6*B6)/2,0) -> 856 | H6: =F6-G6 -> 4853
A7: Camera in Lobby | B7: 0.15 | C7: 27468 | F7: =C7+D7+E7 -> 27468 | G7: =ROUND(((D7+C7)*B7)+(E7*B7)/2,0) -> 4120 | H7: =F7-G7 -> 23348
A8: Water pipe Enlargement | B8: 0.15 | C8: 4092 | D8: 0 | E8: 0 | F8: =C8+D8+E8 -> 4092 | G8: =ROUND(((D8+C8)*B8)+(E8*B8)/2,0) -> 614 | H8: =F8-G8 -> 3478
A9: Lift | B9: 0.15 | C9: 116868 | D9: 0 | E9: 0 | F9: =C9+D9+E9 -> 116868 | G9: =ROUND(((D9+C9)*B9)+(E9*B9)/2,0) -> 17530 | H9: =F9-G9 -> 99338
A10: Total | C10: =SUM(C4:C9) -> 157834 | D10: =SUM(D4:D9) -> 0 | E10: =SUM(E4:E9) -> 0 | F10: =SUM(F4:F9) -> 157834 | G10: =SUM(G4:G9) -> 23490 | H10: =SUM(H4:H9) -> 134344
E11: Less trfd to fund | G11: =-G8 -> -614
E12: Less trfd to fund | G12: =-G9 -> -17530
E13: Total Depreciation for FY 25-26 | G13: =G10+G11+G12 -> 5346

Sheet Sch III - R&S
A1: HELENA VILLA CO-OPERATIVE HOUSING SOCIETY LIMITED | B1: HELENA VILLA CO-OPERATIVE HOUSING SOCIETY LIMITED
A2: (Regd. No MUM/WP/HSG/TC/12195 DATED 19-09-2003) | B2: Schedule - III Reserve and Surplus Fund as on 31st March 2026
B3: FY 2024-25 | C3: General Fund | D3: FY 2025-26
B4: 300545 | C4: As per Last year Balance Sheet | D4: =B8 -> 300545
B5: 0 | C5: Add: Addition during the year
B6: 0 | C6: Add: Entr fees & Share trf Fees | D6: 600
B7: 0 | C7: Add: 25% of Surplus
B8: =SUM(B4:B7) -> 300545 | C8: Total (a) | D8: =SUM(D4:D7) -> 301145
C10: Sinking Fund
B11: 304569 | C11: As per last year Balance Sheet | D11: =B14 -> 335163
B12: 6636 | C12: Add: Addition during the year | D12: 6636
B13: 23958 | C13: Add: Interest on FD earned/accrued | D13: 9780
B14: =SUM(B10:B13) -> 335163 | C14: Total (b) | D14: =SUM(D11:D13) -> 351579
C16: Repair & Maintenance Fund
B17: 0 | C17: As per last Balance Sheet | D17: =B20 -> 36708
B18: 36708 | C18: Add: Addition during the year | D18: 36708
B19: 0 | C19: Less: Major Repair Expense | D19: 0
B20: =SUM(B17:B19) -> 36708 | C20: Total (c) | D20: =SUM(D17:D19) -> 73416
C22: Repairs & Painting Fund
B23: 0 | C23: As per last Balance Sheet | D23: =B27 -> 28256
B24: 28224 | C24: Add: Addition during the year | D24: 28224
B25: 32 | C25: Add: Interest on FD earned/accrued | D25: 532
B26: 0 | C26: Less: Major Repair Expense
B27: =SUM(B22:B26) -> 28256 | C27: Total (d) | D27: =SUM(D23:D26) -> 57012
C29: Education & Training Fund
B30: 3360 | C30: As per last Balance Sheet | D30: =B32 -> 5040
B31: 1680 | C31: Add: Addition during the year | D31: 1680
B32: =SUM(B28:B31) -> 5040 | C32: Total (e) | D32: =SUM(D30:D31) -> 6720
B34: =B8+B14+B20+B27+B32 -> 705712 | C34: Total (a+b+c+d+e) | D34: =D8+D14+D20+D27+D32 -> 789872
B37: Schedule IV -Members Advance as on 31st March 2024
B39: Flat No. | C39: Member's Name | D39: Amount (Rs.)
B40: 102 | C40: MR. ERIC LEWIS & MR.MAXIE LEWIS | D40: 949
B41: 301 | C41: MR. PAUL J. D'SOUZA & MRS. VIRGINIA M. D'SOUZA | D41: 42
B42: 501 | C42: MR. MALCOLM J. FERNANDES | D42: 7952
B43: 702 | C43: MR. JIBU VARGHESE THETHAYIL | D43: 16962
B44: Total | D44: =SUM(D40:D43) -> 25905
B47: Schedule V - Repair and Maintenance Expenses
B49: FY 22-23 | C49: Particulars | D49: FY 23-24
B50: 23200 | C50: R&M - Others | D50: =179666-91632 -> 88034
B51: 2465 | C51: R&M - Electrical | D51: 54220
...

Sheet Sch IV - Mem. Adv
A1: HELENA VILLA CO-OPERATIVE HOUSING SOCIETY LIMITED
A2: (Regd. No MUM/WP/HSG/TC/12195 DATED 19-09-2003)
A3: Sl.No | B3: Flat No. | C3: Member's Names | D3: Amount
A4: 1 | B4: 102 | C4: MR. ERIC LEWIS & MR.MAXIE LEWIS | D4: 3196
A5: 4 | B5: 702 | C5: MR. JIBU VARGHESE THETHAYIL | D5: 37291
A6: Total | D6: =SUM(D4:D5) -> 40487
B11: =+A1 -> HELENA VILLA CO-OPERATIVE HOUSING SOCIETY LIMITED
B12: Schedule V - Repair and Maintenance Expense
B13: FY 24-25 | C13: Particulars | D13: FY 25-26
B14: 700 | C14: R&M - Others | D14: 8819
B15: 6050 | C15: R&M - Electrical | D15: 3600
B16: 7060 | C16: R&M - Water Pump
B17: 4500 | C17: R&M - Garden | D17: 6000
B18: 26255 | C18: AMC - Lift | D18: =28320+20355-21240 -> 27435
B19: 5192 | C19: AMC - Intercom | D19: 1298
B20: 7788 | C20: AMC - CCTV | D20: 7788
B21: 5000 | C21: Water Tank Cleaning Charges | D21: 5500
C22: R&M - Fire Fighting System | D22: 25712.2
B23: =SUM(B14:B21) -> 62545 | C23: Total | D23: =SUM(D14:D22) -> 86152.2

Sheet Sch V -R&M
A1: Helena Villa Chs Ltd
A2: Schedule V - Repair and Maintenance Expense
A3: FY 24-25 | B3: Particulars | C3: FY 25-26
A4: 700 | B4: R&M - Others | C4: 8819
A5: 6050 | B5: R&M - Electrical | C5: 3600
A6: 7060 | B6: R&M - Water Pump
A7: 4500 | B7: R&M - Garden | C7: 6000
A8: 26255 | B8: AMC - Lift | C8: =28320+20355-21240 -> 27435
A9: 5192 | B9: AMC - Intercom | C9: 1298
A10: 7788 | B10: AMC - CCTV | C10: 7788
A11: 5000 | B11: Water Tank Cleaning Charges | C11: 5500
B12: R&M - Fire Fighting System | C12: 25712.2
A13: =SUM(A4:A11) -> 62545 | B13: Total | C13: =SUM(C4:C12) -> 86152.2

Sheet BRS
A1: Helena Villa CHS Ltd.
A2: Citizen Credit Bank reconciliation statement as on 31st March 2026
B3: Amount
A4: Balance as per System | B4: 245299.35
A7: Balance as per Pass Book | B7: =B4 -> 245299.35
A12: Helena Villa CHS Ltd.
A13: MDCC Bank reconciliation statement as on 31st March 2026
B14: Amount
A15: Balance as per System | B15: 6544
A17: Balance as per Pass Book | B17: =B15 -> 6544

Sheet Workings
A1: Not for printing
A2: Water | B2: Period | D2: Days | E2: Amount
B3: 45996 | C3: 46086 | D3: =C3-B3 -> 90 | E3: 9008
B4: 46086 | C4: 46112 | D4: =C4-B4 -> 26 | E4: =ROUND(E3*D4/D3,0) -> 2602 | F4: Prov
A7: Lift AMC | B7: Period | D7: Months | E7: Amount
B8: 46023 | C8: 46387 | D8: 12 | E8: 28320
B9: 46113 | C9: 46387 | D9: 9 | E9: =ROUND(E8*D9/D8,0) -> 21240 | F9: Prepaid
A13: CCTV AMC | B13: Period | D13: Months | E13: Amount
B14: 46023 | C14: 46357 | D14: 12 | E14: 7788
B15: 46113 | C15: 46357 | D15: 9 | E15: =ROUND(E14*D15/D14,0) -> 5841 | F15: Prepaid
A18: Pest Control | B18: Period | D18: Months | E18: Amount
B19: 45809 | C19: 46173 | D19: 12 | E19: 5800
B20: 46113 | C20: 46143 | D20: 2 | E20: =ROUND(E19*D20/D19,0) -> 967 | F20: Prepaid
A23: Insurance | B23: Period | D23: Days | E23: Amount
B24: 45855 | C24: 46219 | D24: =C24-B24+1 -> 365 | E24: =21921+1799 -> 23720
B25: 46113 | C25: 46219 | D25: =C25-B25+1 -> 107 | E25: =ROUND(E24*D25/D24,0) -> 6954 | F25: Prepaid
A27: Intercom | B27: Period | D27: Days | E27: Amount
B28: 46023 | C28: 46357 | D28: 12 | E28: 5192
B29: 46113 | C29: 46357 | D29: 9 | E29: =ROUND(E28*D29/D28,0) -> 3894

Sheet FD Interest Working Sheet
A1: Journal No. | B1: Posted Date | C1: Comments | D1: Credit | E1: Fund | F1: Bank
A2: JE-2025-0000013 | B2: 30-06-2025 | C2: Being int recd on FD 7650 - SC MDCC | D2: 67 | E2: SCF | F2: MDCC
A3: JE-2025-0000011 | B3: 30-09-2025 | C3: Being int recd on FD 7650 - SC MDCC | D3: 67 | E3: SCF | F3: MDCC
A4: JE-2025-0000040 | B4: 18-10-2025 | C4: Being FD 15318 redeemed and recd in bank SF MDCC | D4: 6310 | E4: SF | F4: MDCC | I4: MDCC
A5: JE-2025-0000061 | B5: 20-12-2025 | C5: Being FD 1004019 renewed and remade CCB - GF | D5: 1225 | E5: GF | F5: CCB
A6: JE-2025-0000012 | B6: 31-12-2025 | C6: Being int recd on FD 7650 - SC MDCC | D6: 67 | E6: SCF | F6: MDCC
A7: JE-2025-0000032 | B7: 17-03-2026 | C7: Being FD 3542476 renewed and remade CCB - SF | D7: 2805 | E7: SF | F7: CCB | I7: CCB
A8: JE-2025-0000036 | B8: 22-03-2026 | C8: Being FD 15320 renewed and remade MDCC - SF | D8: 701 | E8: SF | F8: MDCC
A9: JE-2025-0000039 | B9: 31-03-2026 | C9: Being int accu on FD 16212 - SF - MDCC | D9: 2 | E9: SF | F9: MDCC
A10: JE-2025-0000038 | B10: 31-03-2026 | C10: Being int accu on FD 15752 - SF - MDCC | D10: 542 | E10: SF | F10: MDCC
A11: JE-2025-0000037 | B11: 31-03-2026 | C11: Being int accu on FD 15320 - SF - MDCC | D11: 18 | E11: SF | F11: MDCC
A12: JE-2025-0000035 | B12: 31-03-2026 | C12: Being int accu on FD 1007566 - PF - CCB | D12: 527 | E12: PF | F12: CCB
A13: JE-2025-0000034 | B13: 31-03-2026 | C13: Being int accu on FD 1008237 - PF - CCB | D13: 5 | E13: PF | F13: CCB
A14: JE-2025-0000033 | B14: 31-03-2026 | C14: Being int accu on FD 3542476 - SF - CCB | D14: 103 | E14: SF | F14: CCB
A15: JE-2025-0000030 | B15: 31-03-2026 | C15: Being int accu on FD 1003962 - GF - CCB | D15: 8020 | E15: GF | F15: CCB
A16: JE-2025-0000029 | B16: 31-03-2026 | C16: Being int accu on FD 1003921 - GF - CCB | D16: 8020 | E16: GF | F16: CCB
A17: JE-2025-0000028 | B17: 31-03-2026 | C17: Being int accu on FD 1003957 - GF - CCB | D17: 8020 | E17: GF | F17: CCB
A18: JE-2025-0000027 | B18: 31-03-2026 | C18: Being int accu on FD 1003941 - GF - CCB | D18: 8020 | E18: GF | F18: CCB
A19: JE-2025-0000026 | B19: 31-03-2026 | C19: Being int accu on FD 1003938 - GF - CCB | D19: 8020 | E19: GF | F19: CCB
... A21: JE-2025-0000018 | B21: 31-03-2026 | C21: Being interest recd on fixed 00660120007650 - MDCC | D21: 67 | E21: SCF | F21: MDCC
A22: Balance : | D22: =SUM(D2:D21) -> 56590
D26: 10481 | E26: SF
D27: 532 | E27: PF
D28: 45309 | E28: GF
D29: 268 | E29: SC
D30: =SUM(D26:D29) -> 56590
D33: As per bank
D34: 7841 | E34: MDCC
D35: 48749 | E35: CCB
D36: =SUM(D34:D35) -> 56590
