Workbook

Sheet BS
A1: KENT - HEIGHTS CO-OPERATIVE HOUSING SOCIETY LTD.
A2: =IE!A2 -> (Regd. No. MUM / WP / HSG / 11721 / 2002-2003)
A3: =IE!A3 -> Add : Narsing Lane, Vardhaman Nagar, Goraswadi , Malad (West), Mumbai - 400064.
A4: Balance Sheet As at 31.03.2026
H5: (Amt. in Rs.)
A6: 2024-2025 | B6: Liabilities | D6: 2025-2026 | E6: =A6 -> 2024-2025 | F6: Assets | H6: =D6 -> 2025-2026
F7: Cash In Hand / Banks :
B8: Authorised Share Capital | E8: 13895 | F8: Cash in Hand | G8: 7701
A9: 16030500 | B9: (3,20,610 shares of Rs 50/- each) | D9: =50*320610 -> 16030500 | E9: 52982.29 | F9: Cosmos A/c - 023204201220212 | G9: =BRS!B19 -> 0
E10: 4616 | F10: MDCC Bank A/c | G10: =BRS!B12 -> 4760
B11: Issued, Subscribed & Paid Up Share Capital | E11: 1158211.9 | F11: Canara Bank A/c. 110059785323 | G11: =BRS!B4 -> 890014.17 | H11: =SUM(G8:G12) -> 902475.17
A12: 22750 | B12: (455 Shares of Rs 50/- each) | D12: 22750
F13: Investments
B14: Reserve & Other Funds (As per Schedule - A ) | E14: 1000 | F14: Shares of MDCC Bank | G14: 1000
A15: 7751959 | B15: General Reserve Fund | C15: ='Reserves & Provision'!H8 -> 8052398 | E15: 15506994 | F15: Fixed Deposits with Bk - (Schedule - F ) | G15: ='Sch - F FDR'!C23 -> 11315043
A16: 7990970 | B16: Sinking Fund | C16: ='Reserves & Provision'!H7 -> 8662034 | E16: 553474 | F16: Accrued Interest on FD | G16: ='Sch - F FDR'!I23 -> 354744 | H16: =SUM(G14:G16) -> 11670787
A17: 2739568 | B17: Repair and Maintenance Fund | C17: ='Reserves & Provision'!H6 -> 3264005
A18: 118670 | B18: Education Training Fund | C18: ='Reserves & Provision'!H9 -> 129590 | D18: =SUM(C15:C18) -> 20108027 | F18: Current Assets ,Loans & Advances :
E19: 2126253 | F19: Member Receivables (Schedule - C ) | G19: ='Members Rec & Adv'!F21 -> 2708282
A20: 112852000 | B20: Contribution for Land and Building | D20: 112852000 | E20: 7600 | F20: Deposit with BMC | G20: 7600
E21: 1885977 | F21: Advance to Vendor | G21: 0
B22: Current liabilities : | E22: 105373 | F22: TDS Receivables on Bank Interest | G22: 82343
A23: 1295618 | B23: Payables/ Provisions (As per Schedule-B) | C23: ='Reserves & Provision'!D22+'Reserves & Provision'!D35 -> 890694 | E23: 215000 | F23: Advance Taxes Paid | G23: 231800 | H23: =SUM(G19:G23) -> 3030025
A24: 14313 | B24: TDS Payable | C24: 26369
A25: 18835 | B25: Retention - Devang Patel | C25: 18835 | E25: 114661910 | F25: Fixed Assets (As per Schedule - G ) | H25: ='Sch - G FA'!I15 -> 118569311
A26: 18835 | B26: Retention - Astrix Solutions | C26: 18835
A27: 0 | B27: Retention - Vaibhav Enterprises | C27: =42256+91829 -> 134085
A28: 200000 | B28: EMD from Hetcon LLP/Vaibhav | C28: 0 | D28: =SUM(C23:C28) -> 1088818 | F28: Prepaid Expenses :
E29: 457975 | F29: Lift AMC | G29: 472986
B30: Members Payable : | E30: 38905 | F30: Insurance Charges | G30: 38905
A31: 2451073 | B31: Advance Members (As per Schedule - D) | C31: ='Members Rec & Adv'!D33 -> 8252 | E31: 10529 | F31: Intercom | G31: 3000
A32: 1100000 | B32: Refundable Deposit (As per Schedule - E) | C32: ='Members Rec & Adv'!D49 -> 1400000 | D32: =SUM(C31:C32) -> 1408252 | E32: 3944 | F32: Fire Fighting Equipments | G32: 0 | H32: =SUM(G29:G32) -> 514891
A34: 6756 | B34: Property tax payable to member | D34: 0
B36: Income & Expenditure A/c.:
A37: 87689.17 | B37: Balance as per last year | C37: =SUM(A37:A41) -> 223292.17
A38: 0 | B38: Add: Property Tax Payable write Off | C38: 6756
A39: -364491 | B39: Less: FY 22-23 prepaid exps of lift | C39: 0
A40: 0 | B40: Less: Deficit during the year | C40: =-IE!H55 -> -1022406
A41: 500094 | B41: Add: Surplus during the year | C41: =IE!D56 -> 0 | D41: =SUM(C37:C41) -> -792357.83
A42: =SUM(A11:A41) -> 1.3680464e+08 | B42: Total | D42: =SUM(D11:D41) -> 1.3468749e+08 | E42: =SUM(E7:E38) -> 1.3680464e+08 | F42: Total | H42: =SUM(H7:H38) -> 1.3468749e+08 | I42: =A42-E42 -> 0 | J42: =D42-H42 -> 0
...

Sheet IE
A1: KENT - HEIGHTS CO-OPERATIVE HOUSING SOCIETY LTD.
A2: (Regd. No. MUM / WP / HSG / 11721 / 2002-2003)
A3: Add : Narsing Lane, Vardhaman Nagar, Goraswadi , Malad (West), Mumbai - 400064.
A4: Income & Expenditure Statement for the period 01-04-2025 to 31-03-2026
H5: (Amt. in Rs.)
A6: 31.03.2025 | B6: Expenditure | D6: 31.03.2026 | E6: =A6 -> 31.03.2025 | F6: Income | H6: =D6 -> 31.03.2026
F7: By Contribution from Members towards:-
A8: 340 | B8: To Property Tax (BMC) | D8: 43053 | E8: 3017560 | F8: General Maintenance | G8: 3126760
A9: 0 | B9: To Common Area Electricity Exp. | D9: 73780 | E9: 9723 | F9: Contribution for Electricity Charges | G9: 0
A10: 0 | B10: To Water Charges | D10: 79252 | E10: 7173 | F10: Contribution for Water Charges | G10: 0
E11: 24000 | F11: Grill Charges | G11: 6000
B12: To AMC Expenses | E12: 28970 | F12: Non Occupancy Charges | G12: =32166+1109 -> 33275
A13: 771693 | B13: Lift AMC Expenses | C13: 789673 | E13: 45000 | F13: Shifting Charges | G13: 45000
A14: 10471 | B14: Intercom | C14: 13529 | E14: 27000 | F14: Fines / Penalty | G14: 12000
A15: 47150 | B15: Fire Fighting System | C15: 3944 | E15: 504000 | F15: Parking Charges | G15: =189000+272800+7600 -> 469400
A16: 3667 | B16: CCTV | C16: 0 | D16: =SUM(C13:C16) -> 807146 | E16: 457800 | F16: Other charges | G16: 30000
E17: 0 | F17: Legal Charges | G17: 24000
B18: To Repair & Maintenance | E18: 96462 | F18: Late Payment Interest | G18: 128043 | H18: =SUM(G8:G18) -> 3874478
A19: 110440 | B19: Electrical Repairs Maintenance | C19: 46154
A20: 213402 | B20: Other Repairs Maintenance | C20: 17897
A21: 147277 | B21: Plumbing | C21: 82116 | F21: By Interest Income
A22: 2926652 | B22: Major Repair Expenses | C22: 6158426 | E22: 1800 | F22: Interest Income Savings Account | H22: 383
A23: -2229992 | B23: Less: Expenses trfd to Fund/Income | C23: =-2359188-3760112 -> -6119300 | E23: 1053741 | F23: Interest Income Fixed Deposits | G23: 810492
A24: -696660 | B24: Less: Member's Receivable | C24: =-(C22-C23)*0 -> 0 | F24: Less: Trfd to Respective Funds
A25: 3500 | B25: Water Tank Cleaning | C25: 12500 | E25: -501316 | F25: a. Sinking Fund | G25: =-SUM('Sch - F FDR'!G6,'Sch - F FDR'!G19) -> -506688
A26: 28391 | B26: Water Pump Repairs Charges | C26: 34790 | D26: =SUM(C19:C26) -> 232583 | E26: -148234 | F26: b. Repair & Maintenance fund | G26: =-SUM('Sch - F FDR'!G13:G14,'Sch - F FDR'!G16) -> -29965
E27: -404191 | F27: c. General Reserve Fund | G27: =-SUM('Sch - F FDR'!G7:G12,'Sch - F FDR'!G15,'Sch - F FDR'!G17,'Sch - F FDR'!G20:G22) -> -273839 | H27: =SUM(G23:G27) -> 0
B28: Deemed Conveyance Expenses | C28: 1125000
A29: 0 | B29: Less: Expenses trfd to Fund/Income | C29: -1092000 | D29: =C28+C29 -> 33000 | F29: By Other Income
E30: 0 | F30: Deemed Conveyance | G30: 1092000
B31: To Service Charges | E31: 0 | F31: Less: Expense Incurred during the Year | G31: -1092000
A32: 931157 | B32: Salary / Security Expenses | C32: =224754+525084+45000 -> 794838 | E32: 274900 | F32: Sale of Scrap | G32: 33700
A33: 210711 | B33: House Keeping Expenses | C33: 270394 | E33: 37100 | F33: Misc. Income | G33: 24000 | H33: =SUM(G30:G33) -> 57700
A34: 39777 | B34: Insurance Expenses | C34: 39777
A35: 826 | B35: Subscription Federation | C35: 826 | D35: =SUM(C32:C35) -> 1105835
B37: To Office Expenses
A38: 66000 | B38: Accounting Charges | C38: 66000
A39: 9100 | B39: Audit Fees | C39: 10000
A40: 11686 | B40: Printing and Stationary | C40: 12208
A41: 289917 | B41: Depreciation on Fixed Assets | C41: ='Sch - G FA'!H15 -> 971160
...

Sheet Sch - F FDR
A1: KENT - HEIGHTS CO-OPERATIVE HOUSING SOCIETY LTD.
A2: SCHEDULE - F
A3: Details of Fixed Deposits with Banks as on 31.03.2026
A4: Sr. No. | B4: FD No | C4: Principal Amount | D4: Date | E4: Fund | F4: Interest Accrued 24-25 | G4: Interest Accrued 25-26 | H4: TDS | I4: Net Interest Accrued | J4: Net Investment Value | K4: Maturity Date | L4: Maturity Value | M4: Rate of Interest
B5: Canara Bank
A6: 1 | B6: 140057802073/11 | C6: 7341359 | D6: 25.09.2024 | E6: Sinking | F6: 235819 | G6: =120984+131624+1465 -> 254073 | H6: =12098+13163+146 -> 25407 | I6: =F6+G6-H6 -> 464485 | J6: =C6+I6 -> 7805844 | K6: 26.09.2025 | L6: 7858784 | M6: 0.0685 | N6: 140057802073/16
A7: 2 | B7: 140057802073/12 | C7: 1118030 | D7: 25.09.2024 | E7: Reserve | F7: 35913 | G7: =18425+20045+223 -> 38693 | H7: =1843+2004+22 -> 3869 | I7: =F7+G7-H7 -> 70737 | J7: =C7+I7 -> 1188767 | K7: 26.09.2025 | L7: 1196830 | M7: 0.0685 | N7: 140057802073/17
A8: 3 | B8: 140057802073/13 | C8: 1118030 | D8: 25.09.2024 | E8: Reserve | F8: 35913 | G8: =18425+20045+223 -> 38693 | H8: =1843+2004+22 -> 3869 | I8: =F8+G8-H8 -> 70737 | J8: =C8+I8 -> 1188767 | K8: 26.09.2025 | L8: 1196830 | M8: 0.0685 | N8: 140057802073/18
A9: 4 | B9: 140057802073/14 | C9: 1118030 | D9: 25.09.2024 | E9: Reserve | F9: 35913 | G9: =18425+20045+223 -> 38693 | H9: =1843+2004+22 -> 3869 | I9: =F9+G9-H9 -> 70737 | J9: =C9+I9 -> 1188767 | K9: 26.09.2025 | L9: 1196830 | M9: 0.0685 | N9: 140057802073/19
A10: 4 | B10: 140057802073/19 | C10: 1188767 | D10: 26.09.2025 | E10: Reserve | G10: 5292 | H10: 529 | I10: =F10+G10-H10 -> 4763 | J10: =C10+I10 -> 1193530 | K10: 26.11.2025 | N10: MATURED
A11: 5 | B11: 140057802073/15 | C11: 1118030 | D11: 25.09.2024 | E11: Reserve | F11: 35913 | G11: -9501 | I11: =F11+G11-H11 -> 26412 | J11: =C11+I11 -> 1144442 | K11: 26.09.2025 | L11: 1196830 | M11: 0.0685 | N11: PREMATURED
A12: 6 | B12: 140100289855/4 | C12: 1064505 | D12: 02.06.2024 | E12: Reserve | F12: 55518 | G12: 12936 | H12: 1294 | I12: =F12+G12-H12 -> 67160 | J12: =C12+I12 -> 1131665 | K12: 02.06.2025 | L12: 1139318 | M12: 0.0685 | N12: 140100289855/7
A13: 7 | B13: 140100289855/5 | C13: 1064505 | D13: 02.06.2024 | E13: R&M | F13: 55518 | G13: 12936 | H13: 1294 | I13: =F13+G13-H13 -> 67160 | J13: =C13+I13 -> 1131665 | K13: 02.06.2025 | L13: 1139318 | M13: 0.0685 | N13: 140100289855/8
A14: 8 | B14: 140100289855/6 | C14: 1064505 | D14: 02.06.2024 | E14: R&M | F14: 55518 | G14: 12936 | H14: 1294 | I14: =F14+G14-H14 -> 67160 | J14: =C14+I14 -> 1131665 | K14: 02.06.2025 | L14: 1139318 | M14: 0.0685 | N14: 140100289855/9
A15: 7 | B15: 140100289855/7 | C15: 1131665 | D15: 02.06.2025 | E15: Reserve | G15: 1953 | H15: 195 | I15: =F15+G15-H15 -> 1758 | J15: =C15+I15 -> 1133423 | K15: 02.06.2025 | L15: 1139318 | M15: 0.0685 | N15: PREMATURED
A16: 8 | B16: 140100289855/8 | C16: 1131665 | D16: 02.06.2025 | E16: R&M | G16: 4093 | H16: 409 | I16: =F16+G16-H16 -> 3684 | J16: =C16+I16 -> 1135349 | K16: 02.06.2025 | L16: 1139318 | M16: 0.0685 | N16: PREMATURED
A17: 9 | B17: 140205412160/3 | C17: 500000 | D17: 04.01.2025 | E17: Reserve | F17: 7449 | G17: =285+8694-3444 -> 5535 | H17: =29+869 -> 898 | I17: =F17+G17-H17 -> 12086 | J17: =C17+I17 -> 512086 | K17: 04.01.2026 | L17: 535140 | M17: 0.0685 | N17: PREMATURED BUT CHECK PROPERLY
A19: 1 | B19: 140057802073/16 | C19: 7805844 | D19: 26.09.2025 | E19: Sinking | F19: 0 | G19: =121966+123681+6968 -> 252615 | H19: =12197+12368+697 -> 25262 | I19: =F19+G19-H19 -> 227353 | J19: =C19+I19 -> 8033197 | K19: 26.09.2026 | L19: 0
A20: 2 | B20: 140057802073/17 | C20: 1188767 | D20: 26.09.2025 | E20: Reserve | F20: 0 | G20: =18574+18836+1061 -> 38471 | H20: =1857+1884+106 -> 3847 | I20: =F20+G20-H20 -> 34624 | J20: =C20+I20 -> 1223391 | K20: 26.09.2026 | L20: 0
A21: 3 | B21: 140057802073/18 | C21: 1188767 | D21: 26.09.2025 | E21: Reserve | F21: 0 | G21: =18574+18836+1061 -> 38471 | H21: =1857+1884+106 -> 3847 | I21: =F21+G21-H21 -> 34624 | J21: =C21+I21 -> 1223391 | K21: 26.09.2026 | L21: 0
A22: 4 | B22: 140100289855/9 | C22: 1131665 | D22: 02.06.2025 | E22: Reserve | F22: 0 | G22: =19097+19387+19681+6438 -> 64603 | H22: =1910+1938+1969+643 -> 6460 | I22: =F22+G22-H22 -> 58143 | J22: =C22+I22 -> 1189808 | K22: 02.06.2026 | L22: 0
B23: Grand-total | C23: =SUM(C19:C22) -> 11315043 | E23: =SUM(E19:E22) -> 0 | F23: =SUM(F19:F22) -> 0 | G23: =SUM(G6:G22) -> 810492 | H23: =SUM(H6:H22) -> 82343 | I23: =SUM(I19:I22) -> 354744 | J23: =SUM(J19:J22) -> 11669787 | L23: =SUM(L19:L22) -> 0

Sheet Members Rec & Adv
A1: ='Sch - G FA'!B1 -> KENT - HEIGHTS CO-OPERATIVE HOUSING SOCIETY LTD.
A2: SCHEDULE - C
A3: Receivable from Members as on 31-03-2026
A4: Sl.No | B4: Flat No. | C4: Name of the Members | D4: Principal | E4: Interest | F4: Total
A5: 1 | B5: 101 | C5: Mrs Mittal Furia Mr. Bhavya Furia & Mr. Dhiraj Furia | D5: 21096 | E5: 0 | F5: =D5+E5 -> 21096
A6: 2 | B6: 201 | C6: Mr. Dushyant G. Shah | D6: 7924 | E6: 0 | F6: =D6+E6 -> 7924
A7: 3 | B7: 204 | C7: Mr. Sameer J. , Mr. Jitendra R. , Mrs. Pramila J. & Mrs. Sapna S. Sangani | D7: 63296 | E7: 0 | F7: =D7+E7 -> 63296
A8: 4 | B8: 901 | C8: Mr. Dilip B. & Mrs. Truti D. Mehta | D8: 140717 | E8: 16373 | F8: =D8+E8 -> 157090
A9: 5 | B9: 1001 | C9: Mitaben J. & Jitendra S. Sanghvi | D9: 54949 | E9: 0 | F9: =D9+E9 -> 54949
A10: 6 | B10: 1002 | C10: Mr. Jitendra S. & Mrs. Meeta J. Sanghvi | D10: 51349 | E10: 0 | F10: =D10+E10 -> 51349
A11: 7 | B11: 1102 | C11: Pritesh Rajendraprasad Joshi (HUF) Karta Pritesh Rajendaprasad Joshi & Mrs. Chhaya Pritesh Joshi | D11: 22468 | E11: 0 | F11: =D11+E11 -> 22468
A12: 8 | B12: 1303 | C12: Shailesh M . & Mrs. Shruti S. Parekh | D12: 12404 | E12: 0 | F12: =D12+E12 -> 12404
A13: 9 | B13: 1401 | C13: Mr. Dinesh B. & Mrs. Meena D. Agarawal | D13: 5000 | E13: 0 | F13: =D13+E13 -> 5000
A14: 10 | B14: 1701 | C14: Mr. Jinendra T. Kothari | D14: 400778 | E14: 61204 | F14: =D14+E14 -> 461982
A15: 11 | B15: 1901 | C15: Manjulaben L. Patel | D15: 19434 | E15: 0 | F15: =D15+E15 -> 19434
A16: 12 | B16: 1902 | C16: Manjulaben L. Patel | D16: 19434 | E16: 0 | F16: =D16+E16 -> 19434
... A19: 15 | B19: 2304 | C19: Mr. Narendra Pravinchandra Shah & Mr. Karan Narendra Shah | D19: 22631 | E19: 3261 | F19: =D19+E19 -> 25892
C20: Major repair receivables for 4 Instalment | D20: ='Major Rep. Chgs'!K94 -> 1731747 | E20: 0 | F20: =D20+E20 -> 1731747
C21: Total | D21: =SUM(D5:D20) -> 2627444 | E21: =SUM(E5:E20) -> 80838 | F21: =SUM(F5:F20) -> 2708282
A23: SCHEDULE - D
A24: Advance Maintenance from Members As on 31.03.2026
A25: Sr.No | B25: Flat No. | C25: Name of the Member | D25: Amount
A26: 1 | B26: 0502 | C26: Mr. Navin M. & Smt. Hasumati N. , Sumit N. & Neha S. Sanghvi | D26: 7
A27: 2 | B27: 0601 | C27: Mr. Jayesh C. Shah | D27: 730
A28: 3 | B28: 0603 | C28: Sonal S. Shah & Sunil G. Shah | D28: 257
A29: 4 | B29: 1801 | C29: Laxmi R. Marri | D29: 899
A30: 5 | B30: 1802 | C30: Mr. Ramdas V. Marri | D30: 899
A31: 6 | B31: 2303 | C31: Deepa Shailesh Adhiya | D31: 10
A32: 7 | B32: Utility '0301 | C32: Mr. Tejas Bharatkumar Shah & Mrs. Dhruti Tejas Shah | D32: ='Major Rep. Chgs'!K95 -> 5450
C33: Total | D33: =SUM(D26:D32) -> 8252
A35: SCHEDULE - E
A36: Refundable Deposit- Member as on 31.03.2026
A37: Sr.No | B37: Flat No. | C37: Name of the Members | D37: Amount(Rs.)
A38: 1 | B38: 204 | C38: Mr. Sameer J. | D38: 50000
A39: 2 | B39: 401 | C39: Mr. Hitesh K. & Shilpa H. | D39: 50000
A40: 3 | B40: 501 | C40: Mr. Rajesh S. & Smt. Parul Patel | D40: 50000
A41: 4 | B41: 503 | C41: Vidya V. & Vasudeo V. Prabhu | D41: 200000
A42: 5 | B42: 504 | C42: Mr. Vasudev B. Prabhu | D42: 200000
A43: 6 | B43: 1001 | C43: Mitaben J. & Jitendra S. Sanghvi | D43: 100000
A44: 7 | B44: 1003 | C44: Mr. Yogesh Hansraj Harkani | D44: =50000+150000 -> 200000
...

Sheet Reserves & Provision
B1: ='Sch - G FA'!B1 -> KENT - HEIGHTS CO-OPERATIVE HOUSING SOCIETY LTD.
B2: Schedule - A
B3: Reserves & Surplus as on 31.03.2026
B4: Fund | C4: Opening balance 01.04.2025 | D4: Additions during the year | G4: Utilization during the year | H4: Closing Balance as on 31.03.2026
D5: Members contribution | E5: Interest Recd | F5: 25% surplus
B6: Repair Fund | C6: 2739568 | D6: 494472 | E6: =-IE!G26 -> 29965 | F6: 0 | G6: 0 | H6: =+C6+D6+E6+F6+-G6 -> 3264005
B7: Sinking Fund | C7: 7990970 | D7: 164376 | E7: =-IE!G25 -> 506688 | F7: 0 | G7: 0 | H7: =+C7+D7+E7+F7+-G7 -> 8662034
B8: General Reserve | C8: 7751959 | D8: =200+400+1000+25000 -> 26600 | E8: =-IE!G27 -> 273839 | F8: =IE!D55 -> 0 | G8: 0 | H8: =+C8+D8+E8+F8+-G8 -> 8052398
B9: Education & Training Fund | C9: 118670 | D9: =10920 -> 10920 | E9: 0 | F9: 0 | G9: 0 | H9: =+C9+D9+E9+F9+-G9 -> 129590
B10: Total | C10: =SUM(C6:C9) -> 18601167 | D10: =SUM(D6:D9) -> 696368 | E10: =SUM(E6:E9) -> 810492 | F10: =SUM(F6:F9) -> 0 | G10: =SUM(G6:G9) -> 0 | H10: =SUM(H6:H9) -> 20108027
B13: Schedule - B
B14: Payables/ Provisions as on 31.03.2026
B15: Vendor | D15: Amount (Rs.)
B16: Adani Electricity Mumbai Ltd | D16: 11560
B17: Astrix Solutions | D17: 4472
B18: Brihanmumbai Municipal Corporation | D18: 307070
B19: Devang Arvind Patel | D19: 4472
B20: MADHU PANDEY | D20: 33660
B21: Shri Siddharth Plastic | D21: 7802
B22: Total (A) | D22: =SUM(D16:D21) -> 369036
B24: Provisions
B25: Vendor | D25: Amount (Rs.)
B26: Audit Fees | D26: 9100
B27: Electricity Expenses | D27: 76400
B28: Manager Salary | D28: 18710
B29: House Keeping Expenses | D29: 13097
B30: Plumbing Maint Expenses | D30: 6000
B31: Water Expenses | D31: 125125
B32: Electrician Salary | D32: 4500
B33: Subscription Federation | D33: 826
B34: Income Tax | D34: 267900
B35: Total (B) | D35: =SUM(D26:D34) -> 521658
B37: Total ( A + B ) | D37: =+D22+D35 -> 890694

Sheet Sch - G FA
B1: =IE!A1 -> KENT - HEIGHTS CO-OPERATIVE HOUSING SOCIETY LTD.
B2: SCHEDULE - G
B3: Fixed Assets Details as at 31st March 2026
B4: Particulars | C4: Rate % | D4: Opening W.D.V. as on 01.04.2025 | E4: Additions during the year before 30.09.2025 | F4: Additions during the year after 30.09.2025 | G4: Gross Block (at cost) as on 31.03.2026 | H4: Depreciation for the year | I4: Closing W.D.V. as on 31.03.2026 | J4: Closing W.D.V. as on 31.03.2022
B5: Land & Building | C5: 0 | D5: 112852000 | E5: 0 | F5: 0 | G5: =D5+E5+F5 -> 112852000 | H5: =ROUND(((E5+D5)*C5)+(F5*C5)/2,0) -> 0 | I5: =G5-H5 -> 112852000
B6: Lift | C6: 0.15 | D6: 821828 | E6: =1340400+1340400+259600 -> 2940400 | F6: =259600+64900 -> 324500 | G6: =D6+E6+F6 -> 4086728 | H6: =ROUND(((E6+D6)*C6)+(F6*C6)/2,0) -> 588672 | I6: =G6-H6 -> 3498056
B7: Furniture & Fixture | C7: 0.1 | D7: 99552 | E7: 0 | F7: 0 | G7: =D7+E7+F7 -> 99552 | H7: =ROUND(((E7+D7)*C7)+(F7*C7)/2,0) -> 9955 | I7: =G7-H7 -> 89597
B8: Fire Fighting Eqpts | C8: 0.15 | D8: 34191 | E8: 0 | F8: 0 | G8: =D8+E8+F8 -> 34191 | H8: =ROUND(((E8+D8)*C8)+(F8*C8)/2,0) -> 5129 | I8: =G8-H8 -> 29062
B9: CCTV Installations | C9: 0.15 | D9: 372885 | E9: =18000 -> 18000 | F9: 16900 | G9: =D9+E9+F9 -> 407785 | H9: =ROUND(((E9+D9)*C9)+(F9*C9)/2,0) -> 59900 | I9: =G9-H9 -> 347885
B10: Pipeline & Water Pump | C10: 0.15 | D10: 373457 | E10: =22500+1083582+393980 -> 1500062 | F10: 35307 | G10: =D10+E10+F10 -> 1908826 | H10: =ROUND(((E10+D10)*C10)+(F10*C10)/2,0) -> 283676 | I10: =G10-H10 -> 1625150
B11: Intercom | C11: 0.15 | D11: 17989 | E11: 0 | F11: 26400 | G11: =D11+E11+F11 -> 44389 | H11: =ROUND(((E11+D11)*C11)+(F11*C11)/2,0) -> 4678 | I11: =G11-H11 -> 39711
B12: Computer & Printer | C12: 0.4 | D12: 12401 | E12: 0 | F12: 0 | G12: =D12+E12+F12 -> 12401 | H12: =ROUND(((E12+D12)*C12)+(F12*C12)/2,0) -> 4960 | I12: =G12-H12 -> 7441
B13: Electric Installation | C13: 0.15 | D13: 33577 | E13: 16992 | F13: 0 | G13: =D13+E13+F13 -> 50569 | H13: =ROUND(((E13+D13)*C13)+(F13*C13)/2,0) -> 7585 | I13: =G13-H13 -> 42984
B14: Sound System | C14: 0.15 | D14: 44030 | E14: 0 | F14: 0 | G14: =D14+E14+F14 -> 44030 | H14: =ROUND(((E14+D14)*C14)+(F14*C14)/2,0) -> 6605 | I14: =G14-H14 -> 37425
B15: Total | D15: =SUM(D5:D14) -> 114661910 | E15: =SUM(E5:E14) -> 4475454 | F15: =SUM(F5:F14) -> 403107 | G15: =SUM(G5:G14) -> 119540471 | H15: =SUM(H5:H14) -> 971160 | I15: =SUM(I5:I14) -> 118569311

Sheet BRS
A1: Kent Heights CHS Ltd.
A2: Canara Bank Reconciliation as of 31.03.2026 | D2: Date | E2: Amount | F2: Instru. No. | G2: Remarks
B3: Amount | D3: 13.03.2026 | E3: 41783 | F3: 00257 | G3: Flat 1703 - Mainatenance
A4: Balance as per System (Book Balance) | B4: 890014.17 | D4: 31.03.2026 | E4: 20470 | F4: 866372 | G4: Flat 0903 - Mainatenance
D5: 31.03.2026 | E5: 21613 | F5: 866372 | G5: Flat 0904 - Mainatenance
A6: Less: Cheques deposited but not cleared | B6: =E6 -> 83866 | E6: =SUM(E3:E5) -> 83866
A8: Balance as per Passbook | B8: =B4-B6 -> 806148.17
A10: MDCC Bank Reconciliation as of 31.03.2026
B11: Amount
A12: Balance as per System (Book Balance) | B12: 4760
A14: Balance as per Passbook | B14: =B12 -> 4760
A17: Cosmos Bank Reconciliation as of 31.05.2025
B18: Amount
A19: Balance as per System (Book Balance) | B19: 0
A21: Balance as per Passbook | B21: =B19 -> 0 | C21: A/c closed

Sheet Workings
A1: Not to print
A3: Lift AMC | L3: Income Tax Provision
A4: Period | B4: From | C4: To | D4: Days/Month | E4: Amount | L4: Income from Savings A/c. | O4: =IE!H22 -> 383
B5: 46023 | C5: 46387 | D5: =C5-B5+1 -> 365 | E5: 292597 | L5: Income from Fixed Deposit | O5: =IE!G23 -> 810492
B6: 46113 | C6: 46387 | D6: =C6-B6+1 -> 275 | E6: =ROUND(E5*D6/D5,0) -> 220450 | F6: prepaid | L6: Interest on IT Refund | O6: 0
L7: Sale of scrap & Promotional | O7: =IE!G32+IE!G33 -> 57700
B8: 45928 | C8: 46292 | D8: =C8-B8+1 -> 365 | E8: 176988 | L8: Gross Taxable Income | O8: =SUM(O4:O7) -> 868575
B9: 46113 | C9: 46292 | D9: =C9-B9+1 -> 180 | E9: =ROUND(E8*D9/D8,0) -> 87282 | F9: prepaid | K9: Less: | L9: Deduction U/S 80P | O9: 0
L10: Net Taxable Income | O10: =O8-O9 -> 868575
B11: 45928 | C11: 46292 | D11: =C11-B11+1 -> 365 | E11: 335099 | L11: 0-10000 | N11: 0.1 | O11: 1000
B12: 46113 | C12: 46292 | D12: =C12-B12+1 -> 180 | E12: =ROUND(E11*D12/D11,0) -> 165254 | F12: prepaid | L12: 10000-20000 | N12: 0.2 | O12: 2000
L13: 20000 or More | N13: 0.3 | O13: =(O10-20000)*N13 -> 254572.5
L14: Tax | O14: =SUM(O11:O13) -> 257572.5
A15: Water | K15: Add | L15: Education cess | N15: 0.04 | O15: =ROUND(O14*N15,0) -> 10303
A16: Period | B16: From | C16: To | D16: Days/Month | E16: Amount | L16: Total Tax | O16: =SUM(O14:O15) -> 267875.5
A17: PN0004387 | B17: 45677 | C17: 46042 | D17: =C17-B17+1 -> 366 | E17: =25918+25918+24459+23836 -> 100131 | L17: Say | O17: =ROUND(O16,-2) -> 267900
B18: 46042 | C18: 46112 | D18: =C18-B18+1 -> 71 | E18: =ROUND(E17*D18/D17,0) -> 19424 | F18: provision
A20: PN0056740 | B20: 45677 | C20: 46042 | D20: =C20-B20+1 -> 366 | E20: =143052+143052+130864+127911 -> 544879
B21: 46042 | C21: 46112 | D21: =C21-B21+1 -> 71 | E21: =ROUND(E20*D21/D20,0) -> 105701 | F21: provision
A24: Insurance | B24: From | C24: To | D24: Days/Month | E24: Amount | Q24: Expense Short fall | R24: Amount
B25: 46105 | C25: 46469 | D25: =C25-B25+1 -> 365 | E25: 39777 | Q25: Property Tax (BMC) | R25: 43053
B26: 46113 | C26: 46469 | D26: =C26-B26+1 -> 357 | E26: =ROUND(E25*D26/D25,0) -> 38905 | F26: prepaid | Q26: Common Area Electricity Exp. | R26: 73780
Q27: Water Charges | R27: 79252
A28: Intercom | B28: From | C28: To | D28: Days/Month | E28: Amount | Q28: Depreciation | R28: =-IE!I41 -> 0
B29: 46023 | C29: 46203 | D29: =C29-B29+1 -> 181 | E29: 6000 | Q29: Festival | R29: =-IE!I50 -> 0
B30: 46113 | C30: 46203 | D30: =C30-B30+1 -> 91 | E30: =ROUND(E29*D30/D29,0) -> 3017 | F30: prepaid | G30: ??? | H30: OCT 25 TO DEC 25 NOT PAID | Q30: Income Tax | R30: =-IE!I52 -> 0
Q31: Total | R31: =SUM(R25:R30) -> 196085
A32: Fire AMC | B32: From | C32: To | D32: Days/Month | E32: Amount
B33: 45809 | C33: 46173 | D33: =C33-B33+1 -> 365 | E33: 0 | G33: ???? | H33: NOT PAID | R33: 203 | S33: to check for major repair
B34: 45748 | C34: 45808 | D34: =C34-B34+1 -> 61 | E34: =ROUND(E33*D34/D33,0) -> 0 | F34: prepaid | R34: 1201 | S34: to check for major repair
R35: 1702 | S35: to check for major repair
R36: 2204 | S36: to check for major repair

Sheet Major Rep. Chgs
A1: Kent Heights CHS LTD - Major Repair Charges Collection Summary
A2: Sl. No | B2: Block | C2: Unit | D2: Name | E2: Invoiced till 01-04-2025 | F2: Invoiced after 01-04-2025 | G2: Billed till 31.03.2026 | H2: Per Qtr | I2: Actual to be collected for 4 inst. (Incl. Prov.) | J2: Total Receipt | K2: Actual Receivables
A3: 1 | B3: Utility | C3: 0101 | D3: Mrs Mittal Furia Mr. Bhavya Furia & Mr. Dhiraj Furia | E3: 43600 | F3: 21800 | G3: =E3+F3 -> 65400 | H3: =I3/4 -> 26202 | I3: 104808 | J3: 104808 | K3: =I3-J3 -> 0
A4: 2 | B4: Utility | C4: 0102 | D4: Rajeshri Associates | E4: 43600 | F4: 21800 | G4: =E4+F4 -> 65400 | H4: =I4/4 -> 26202 | I4: 104808 | J4: 104808 | K4: =I4-J4 -> 0
A5: 3 | B5: Utility | C5: 0103A | D5: Mr. Jayesh Thakorbhai Mistry & Thakorbhai N. Mistry | E5: 22864 | F5: 11432 | G5: =E5+F5 -> 34296 | H5: =I5/4 -> 13737 | I5: 54948 | J5: 54948 | K5: =I5-J5 -> 0
A6: 4 | B6: Utility | C6: 0103B | D6: Devang P. Mehta | E6: 23048 | F6: 11524 | G6: =E6+F6 -> 34572 | H6: =I6/4 -> 13854 | I6: 55416 | J6: 55416 | K6: =I6-J6 -> 0
A7: 5 | B7: Utility | C7: 0104 | D7: Mr. Bhavesh & Mr. Manish D. Meghani | E7: 54616 | F7: 27308 | G7: =E7+F7 -> 81924 | H7: =I7/4 -> 32823 | I7: 131292 | J7: 0 | K7: =I7-J7 -> 131292
A8: 6 | B8: Utility | C8: 0201 | D8: Mr. Dushyant G. Shah | E8: 43600 | F8: 21800 | G8: =E8+F8 -> 65400 | H8: =I8/4 -> 26202 | I8: 104808 | J8: 26202 | K8: =I8-J8 -> 78606
A9: 7 | B9: Utility | C9: 0202 | D9: Mr. Paresh Mavjibhai Patel | E9: 43600 | F9: 21800 | G9: =E9+F9 -> 65400 | H9: =I9/4 -> 26202 | I9: 104808 | J9: 104808 | K9: =I9-J9 -> 0
A10: 8 | B10: Utility | C10: 0203 | D10: Mr. Pritesh A. Gandhi, Mrs. Hina P. Gandhi & Mrs. Ansuya A. Gandhi | E10: 43600 | F10: 21800 | G10: =E10+F10 -> 65400 | H10: =I10/4 -> 26202 | I10: 104808 | J10: 78606 | K10: =I10-J10 -> 26202
A11: 9 | B11: Utility | C11: 0204 | D11: Mr. Sameer J. , Mr. Jitendra R. , Mrs. Pramila J. & Mrs. Sapna S. Sangani | E11: 54616 | F11: 27308 | G11: =E11+F11 -> 81924 | H11: =I11/4 -> 32823 | I11: 131292 | J11: 32823 | K11: =I11-J11 -> 98469
A12: 10 | B12: Utility | C12: 0301 | D12: Mr. Tejas Bharatkumar Shah & Mrs. Dhruti Tejas Shah | E12: 43600 | F12: 21800 | G12: =E12+F12 -> 65400 | H12: =I12/4 -> 26202 | I12: 104808 | J12: 110258 | K12: =(I12-J12)*0 -> 0 | L12: Paid excess
A13: 11 | B13: Utility | C13: 0302 | D13: MRS. VINDYA U. GADIYAR | E13: 43600 | F13: 21800 | G13: =E13+F13 -> 65400 | H13: =I13/4 -> 26202 | I13: 104808 | J13: 104808 | K13: =I13-J13 -> 0
A14: 12 | B14: Utility | C14: 0303 | D14: Mr. Vipul Amrutlal Patel & Mrs. Chetna Vipul Patel | E14: 43600 | F14: 21800 | G14: =E14+F14 -> 65400 | H14: =I14/4 -> 26202 | I14: 104808 | J14: 104808 | K14: =I14-J14 -> 0
A15: 13 | B15: Utility | C15: 0304 | D15: Mr. Mahsukhbhai Shah & Mr. Rajesh M. Shah | E15: 54616 | F15: 27308 | G15: =E15+F15 -> 81924 | H15: =I15/4 -> 32823 | I15: 131292 | J15: 131292 | K15: =I15-J15 -> 0
A16: 14 | B16: Utility | C16: 0401 | D16: Mr. Hitesh K. & Shilpa H. | E16: 43600 | F16: 21800 | G16: =E16+F16 -> 65400 | H16: =I16/4 -> 26202 | I16: 104808 | J16: 104808 | K16: =I16-J16 -> 0
A17: 15 | B17: Utility | C17: 0402 | D17: Bhupat L. & Smt. Aruna B. Patel | E17: 43600 | F17: 21800 | G17: =E17+F17 -> 65400 | H17: =I17/4 -> 26202 | I17: 104808 | J17: 104808 | K17: =I17-J17 -> 0
A18: 16 | B18: Utility | C18: 0403 | D18: Mrs. Tanvi R Panchamia & Mr. Rishabh R Panchamia | E18: 43600 | F18: 21800 | G18: =E18+F18 -> 65400 | H18: =I18/4 -> 26202 | I18: 104808 | J18: 104808 | K18: =I18-J18 -> 0
A19: 17 | B19: Utility | C19: 0404 | D19: Mr. Rajesh Ramachandra Kamath & Mrs. Anitha Rajesh Kamath | E19: 54616 | F19: 27308 | G19: =E19+F19 -> 81924 | H19: =I19/4 -> 32823 | I19: 131292 | J19: 131292 | K19: =I19-J19 -> 0
A20: 18 | B20: Utility | C20: 0501 | D20: Mr. Rajesh S. & Smt. Parul Patel | E20: 43600 | F20: 21800 | G20: =E20+F20 -> 65400 | H20: =I20/4 -> 26202 | I20: 104808 | J20: 104808 | K20: =I20-J20 -> 0
A21: 19 | B21: Utility | C21: 0502 | D21: Mr. Navin M. & Smt. Hasumati N. , Sumit N. & Neha S. Sanghvi | E21: 43600 | F21: 21800 | G21: =E21+F21 -> 65400 | H21: =I21/4 -> 26202 | I21: 104808 | J21: 104808 | K21: =I21-J21 -> 0
A22: 20 | B22: Utility | C22: 0503 | D22: MRS. VIDYA VASUDEV PRABHU & MR. VASUDEV BABURAO PRABHU | E22: 43600 | F22: 21800 | G22: =E22+F22 -> 65400 | H22: =I22/4 -> 26202 | I22: 104808 | J22: 104808 | K22: =I22-J22 -> 0
A23: 21 | B23: Utility | C23: 0504 | D23: MR. VASUDEV BABURAO PRABHU | E23: 54616 | F23: 27308 | G23: =E23+F23 -> 81924 | H23: =I23/4 -> 32823 | I23: 131292 | J23: 131292 | K23: =I23-J23 -> 0
A24: 22 | B24: Utility | C24: 0601 | D24: Mr. Jayesh C. Shah | E24: 43600 | F24: 21800 | G24: =E24+F24 -> 65400 | H24: =I24/4 -> 26202 | I24: 104808 | J24: 104808 | K24: =I24-J24 -> 0
... A31: 29 | B31: Utility | C31: 0704 | D31: Mr. Ajay Jamnadas Padia | E31: 54616 | F31: 27308 | G31: =E31+F31 -> 81924 | H31: =I31/4 -> 32823 | I31: 131292 | J31: 131292 | K31: =I31-J31 -> 0
A32: 30 | B32: Utility | C32: 0801 | D32: Mr. Yogeshchandra S. & Mrs. Kusum Y. Shah | E32: 44184 | F32: 22092 | G32: =E32+F32 -> 66276 | H32: =I32/4 -> 26555 | I32: =(212436/2)+2 -> 106220 | J32: 20000 | K32: =I32-J32 -> 86220
A33: 31 | B33: Utility | C33: 0802 | D33: Shah | E33: 44184 | F33: 22092 | G33: =E33+F33 -> 66276 | H33: =I33/4 -> 26555 | I33: =(212436/2)+2 -> 106220 | J33: 0 | K33: =I33-J33 -> 106220
A34: 32 | B34: Utility | C34: 0803 | D34: Mr. Ramesh Bhuralal Patel & Heena R. Patel | E34: 43600 | F34: 21800 | G34: =E34+F34 -> 65400 | H34: =I34/4 -> 26202 | I34: 104808 | J34: 104808 | K34: =I34-J34 -> 0
A35: 33 | B35: Utility | C35: 0901 | D35: Mr. Dilip B. & Mrs. Truti D. Mehta | E35: 43600 | F35: 21800 | G35: =E35+F35 -> 65400 | H35: =I35/4 -> 26202 | I35: 104808 | J35: 26202 | K35: =I35-J35 -> 78606
A36: 34 | B36: Utility | C36: 0902 | D36: Induben M. Parekh & Pintu M. Parekh | E36: 43600 | F36: 21800 | G36: =E36+F36 -> 65400 | H36: =I36/4 -> 26202 | I36: 104808 | J36: 104808 | K36: =I36-J36 -> 0
A37: 35 | B37: Utility | C37: 0903 | D37: Priyank J. Doshi & Nayana J. Doshi | E37: 43600 | F37: 21800 | G37: =E37+F37 -> 65400 | H37: =I37/4 -> 26202 | I37: 104808 | J37: 104808 | K37: =I37-J37 -> 0
A38: 36 | B38: Utility | C38: 0904 | D38: Mr. Jitendra A. & Mrs. Nayana J. Doshi | E38: 54616 | F38: 27308 | G38: =E38+F38 -> 81924 | H38: =I38/4 -> 32823 | I38: 131292 | J38: 131292 | K38: =I38-J38 -> 0
A39: 37 | B39: Utility | C39: 1001 | D39: Mitaben J. & Jitendra S. Sanghvi | E39: 43600 | F39: 21800 | G39: =E39+F39 -> 65400 | H39: =I39/4 -> 26202 | I39: 104808 | J39: 54500 | K39: =I39-J39 -> 50308
A40: 38 | B40: Utility | C40: 1002 | D40: Mr. Jitendra S. & Mrs. Meeta J. Sanghvi | E40: 43600 | F40: 21800 | G40: =E40+F40 -> 65400 | H40: =I40/4 -> 26202 | I40: 104808 | J40: 54500 | K40: =I40-J40 -> 50308
A41: 39 | B41: Utility | C41: 1003 | D41: Mr. Yogesh Hansraj Harkani | E41: 43600 | F41: 21800 | G41: =E41+F41 -> 65400 | H41: =I41/4 -> 26202 | I41: 104808 | J41: 104808 | K41: =I41-J41 -> 0
A42: 40 | B42: Utility | C42: 1004 | D42: Mr. Haresh N. & Mrs. Harsha N. Modi | E42: 54616 | F42: 27308 | G42: =E42+F42 -> 81924 | H42: =I42/4 -> 32823 | I42: 131292 | J42: 131292 | K42: =I42-J42 -> 0
A43: 41 | B43: Utility | C43: 1101 | D43: Mr. Eknath Gopal Krishna Hegde & Mrs. Bhakti Eknath Hegde | E43: 43600 | F43: 21800 | G43: =E43+F43 -> 65400 | H43: =I43/4 -> 26202 | I43: 104808 | J43: 104808 | K43: =I43-J43 -> 0
A44: 42 | B44: Utility | C44: 1102 | D44: Pritesh Rajendraprasad Joshi (HUF) Karta Pritesh Rajendaprasad Joshi & Mrs. Chhaya Pritesh Joshi | E44: 43600 | F44: 21800 | G44: =E44+F44 -> 65400 | H44: =I44/4 -> 26202 | I44: 104808 | J44: 104808 | K44: =I44-J44 -> 0
A45: 43 | B45: Utility | C45: 1103 | D45: Daksha R. Vora & Rajnikant V. Vora | E45: 43600 | F45: 21800 | G45: =E45+F45 -> 65400 | H45: =I45/4 -> 26202 | I45: 104808 | J45: 104808 | K45: =I45-J45 -> 0
A46: 44 | B46: Utility | C46: 1104 | D46: Mr. Rajnikant Vachhraj Vora | E46: 54616 | F46: 27308 | G46: =E46+F46 -> 81924 | H46: =I46/4 -> 32823 | I46: 131292 | J46: 131292 | K46: =I46-J46 -> 0
...
