Workbook

Sheet BS
A1: Cherry Blossom Co-op. Housing Society Ltd.
A2: ( Regd No.: BOM/W-P/HSG/TC/6681/91-92 )
A3: Plot No. 157/2, D'Monte Lane, Valnai, Orlem, Malad (West), Mumbai - 400064
A4: Balance Sheet as at 31st March 2026
H5: (Amt. in Rs.)
A6: FY 2024-25 | B6: Liabilities | D6: FY 2025-26 | E6: =A6 -> FY 2024-25 | F6: Assets | H6: =D6 -> FY 2025-26
B7: AUTHORISED SHARE CAPITAL | F7: Cash & Bank Balances:
A8: 100000 | B8: (2,000 Shares of Rs.50/- Each ) | D8: 100000 | E8: 1640 | F8: Cash Balance | G8: 4405
E9: 207148.75 | F9: Citizen Credit Co-op. Bank | G9: =BRS!D4 -> 96127.95
B10: Issued, Subscribed and Paid up Share Capital | E10: 11113.85 | F10: MDCC Bank 00061006000497 | G10: =BRS!D17 -> 12886.85 | H10: =SUM(G8:G10) -> 113419.8
A11: 5000 | B11: ( 200 Shares of Rs. 50/- Each ) | D11: =SUM(A11:A12) -> 10000
A12: 5000 | B12: Add: (100 Shares of Rs. 50/- Each) | D12: 0 | F12: Investments :
E13: 100 | F13: 1 Share of MDHF | H13: 100
B14: General Reserve & Other Funds: | E14: 2128540 | F14: Fixed Deposits (As per Sch - I) | G14: ='FD-Sch I'!D53 -> 2399205
B15: (i) General Reserve Fund: | E15: 31172 | F15: SF Accrued Interest | G15: ='FD-Sch I'!F26+'FD-Sch I'!E26 -> 46017
A16: 42896 | B16: Bal as per last balance sheet | C16: =SUM(A16:A18) -> 43296 | E16: 26338 | F16: RF Accrued Interest | G16: ='FD-Sch I'!F38 -> 22226
A17: 400 | B17: Add: Additions during the year | C17: 100 | E17: 492 | F17: ETF Accrued Interest | G17: ='FD-Sch I'!F45 -> 248
A18: 0 | B18: Add: 25% of Surplus during the year | C18: =IE!D35 -> 0 | D18: =SUM(C16:C18) -> 43396 | E18: 4797 | F18: OFD Accrued Interest | G18: ='FD-Sch I'!F51 -> 2067 | H18: =SUM(G14:G18) -> 2469763
B20: (ii) Sinking Fund | F20: Deposit :
A21: 1209446 | B21: Bal as per last balance sheet | C21: =SUM(A21:A24) -> 1329307 | E21: 6184.72 | F21: Adani Electricity | H21: 6184.72
A22: 37584 | B22: Add: Additions during the year | C22: 37584
A23: 82277 | B23: Add: Accrued / Interest Earned | C23: 96672 | D23: =SUM(C21:C23) -> 1463563 | E23: 100000 | F23: Advance to Vendors (Schedule - III ) | H23: ='Sch-III,IV,V'!C8 -> 100000
B25: (iii) Repair Fund | E25: 15586 | F25: TDS Receivable on Bank Interest | H25: 29052
A26: 50445 | B26: Bal as per last balance sheet | D26: 50445
E27: 3044199 | F27: Fixed Assets (As per Schedule - II ) | H27: ='FA-Sch II'!H12 -> 3037031
B28: (iv) Major Repair Fund
A29: 927976 | B29: Bal as per last balance sheet | C29: =SUM(A29:A31) -> 1011748 | F29: Prepaid Expenses :
A30: 83772 | B30: Add: Additions during the year | C30: 83772 | D30: =SUM(C29:C30) -> 1095520 | E30: 16999 | F30: Building Insurance Charges | H30: 16632
B32: (v) Education & Traing Fund
A33: 7371 | B33: Bal as per last balance sheet | C33: =SUM(A33:A35) -> 10147
A34: 2400 | B34: Add: Additions during the year | C34: 2400
A35: 376 | B35: Add: Accrued / Interest Earned | C35: 634 | D35: =C33+C34+C35 -> 13181
A37: 70000 | B37: (vi) Common Amenities Fund | D37: 70000 | F37: Income & Expenditure A/c : | H37: 0
E38: -276480.12 | F38: Bal as per last balance sheet | G38: 29452.68
A39: 600000 | B39: (vii) Deemed Conveyance Fund | C39: 600000 | E39: -4400 | F39: Add: CN towards P.tax from FY 22 -25 | G39: 64368
A40: -600000 | B40: Less: Paid to Adv. Kadam | C40: -600000 | D40: =C39+C40 -> 0 | E40: 310332.8 | F40: Less: Excess of Income over Expenditure for the year | G40: =IE!H35 -> 3492.8 | H40: =SUM(G38:G40) -> 97313.48
B42: Members Contribution towards :
A43: 2995875 | B43: Land & Building | D43: 2995875
B45: Current Liabilities
A46: 42082 | B46: Advance From Members (Sch-IV) | C46: ='Sch-III,IV,V'!K17 -> 54467
...

Sheet IE
A1: Cherry Blossom Co-op. Housing Society Ltd.
A2: ( Regd No.: BOM/W-P/HSG/TC/6681/91-92 )
A3: Plot No. 157/2, D'Monte Lane, Valnai, Orlem, Malad (West), Mumbai - 400064
A4: Income & Expenditure Statement for the year ended 31st March 2026
H5: (Amt. in Rs.)
A6: FY 24-25 | B6: Expenditure | D6: FY 25-26 | E6: =A6 -> FY 24-25 | F6: Income | H6: =D6 -> FY 25-26
F7: By Maintenance Collection from members :
A8: 113072 | B8: To Property Tax | D8: 103232 | E8: 59688 | F8: Maintenance Charges | G8: =54204+5484 -> 59688
A9: 38163 | B9: To Property Tax - RG Area | D9: 0 | E9: 129228 | F9: Property Tax | G9: =134068+2880+13148 -> 150096
A10: 18249 | B10: To Building Insurance Charges | D10: 18222 | E10: 30720 | F10: Water Charges | G10: 30720
A11: 32400 | B11: To Water Expenses | D11: 32375 | E11: 55200 | F11: Electricity Charges | G11: 55200
A12: 0 | B12: To Water Tank Cleaning Expense | D12: 4000 | E12: 20229 | F12: Non Occupancy Charges | G12: 18871
A13: 43452 | B13: To Electricity Expenses | D13: 43846 | E13: 19500 | F13: Parking Charges | G13: =14200+200 -> 14400
E14: 180000 | F14: Service Charges | G14: 180000
B15: To Repairs & Maintenance : | E15: 73 | F15: Late Payment Interest | G15: 277
A16: 13350 | B16: Other Repair Maintenance | C16: 35399 | E16: 3564 | F16: Building Insurance | G16: 3564
A17: 3040 | B17: Electrical Expenses | C17: 2955 | E17: 40500 | F17: Legal charges | G17: 24000 | H17: =SUM(G8:G17) -> 536816
A18: 1900 | B18: Water Pump AMC | C18: 0 | D18: =SUM(C16:C18) -> 38354
F19: Other Income
B20: To Administrative Expenses : | E20: 0 | F20: Miscellaneous Income | H20: 3000
A21: 178600 | B21: Salary | C21: =147900+2200 -> 150100
A22: 148500 | B22: Security Expense | C22: 155760 | F22: By Interest received from Banks:
A23: 24000 | B23: Accounting Charges | C23: 26400 | E23: 8239 | F23: Interest on Savings Deposit | H23: 7585
A24: 70.8 | B24: Bank Charges | C24: 424.8
A25: 826 | B25: Membership & Subscription | C25: 826 | E25: 155781 | F25: Interest on Fixed Deposits | G25: 168134
A26: 853200 | B26: Deemed Conveyance | C26: 0 | E26: -82277 | F26: Less: Transferred to SF FD | G26: -96672
A27: -600000 | B27: Less: Trfd to Liability | C27: 0 | E27: 0 | F27: Less: Transferred to RF FD | G27: 0
A28: 14425 | B28: Meeting Expenses | C28: 30871 | E28: -376 | F28: Less: Transferred to ETF FD | G28: -634
A29: 0 | B29: Office Expense | C29: =1070+1100 -> 2170 | E29: 0 | F29: Less: Transferred to MRF FD | G29: 0 | H29: =G25+G26+G27+G29+G28 -> 70828
A30: 13589 | B30: Printing & Stationery | C30: 5873
A31: 2100 | B31: Audit Fees | C31: 2100
A32: 23500 | B32: Legal & Professional Charges | C32: 0 | E32: 458 | F32: By Interest Income from IT Refund | H32: 0
A33: 8423 | B33: Depreciation on Fixed Assets | C33: ='FA-Sch II'!G12 -> 7168 | D33: =SUM(C21:C33) -> 381692.8
A35: 0 | E35: 310332.8 | F35: By Excess of Expenditure over Income | H35: =D37-SUM(H7:H34) -> 3492.8
A36: 0
A37: =SUM(A7:A33) -> 930859.8 | B37: Total | D37: =SUM(D7:D36) -> 621721.8 | E37: =SUM(E7:E36) -> 930859.8 | F37: Total | H37: =SUM(H7:H36) -> 621721.8 | I37: =A37-E37 -> 0 | J37: =D37-H37 -> 0
A38: =A37-E37 -> 0
A39: As per my report of even date | E39: For Cherry Blossom Co-op. Housing Society Ltd.
A44: =BS!A57 -> ( Shankar D. Gawde )
A45: =BS!A58 -> Government Certified Auditor | E45: Chairman Secretary Treasurer
...

Sheet FD-Sch I
A1: Cherry Blossom Co-op. Hsg. Soc. Ltd
A2: Schedule I - Fixed Deposits with Banks as of 31.03.2026
A3: Sr. No. | B3: Certificate No. | C3: Date | D3: Amount Invested | E3: Accrued in FY 24-25 | F3: Accrued in FY 25-26 | G3: Total | H3: Maturity Date | I3: Maturity Value | J3: Rate (%) | K3: Bank
B4: Sinking Fund FD's
A5: 1 | B5: 1353281 | C5: 10.04.2025 | D5: 42050 | E5: 0 | F5: =3017-302 -> 2715 | G5: =D5+E5+F5 -> 44765 | H5: 10.04.2027 | I5: 48501 | J5: 7.2 | K5: MDCC
A6: 2 | B6: 1414197 | C6: 21.02.2026 | D6: 43196 | E6: 0 | F6: =305-31 -> 274 | G6: =D6+E6+F6 -> 43470 | H6: 21.02.2028 | I6: 49384 | J6: 6.75 | K6: MDCC
A7: 3 | B7: 1453438 | C7: 03.11.2025 | D7: 43795 | E7: 0 | F7: =1227-123 -> 1104 | G7: =D7+E7+F7 -> 44899 | H7: 03.11.2026 | I7: 46850 | J7: 6.8 | K7: MDCC
A8: 4 | B8: 1453439 | C8: 30.10.2025 | D8: 61872 | E8: 0 | F8: =1786-178 -> 1608 | G8: =D8+E8+F8 -> 63480 | H8: 30.10.2026 | I8: 66188 | J8: 6.8 | K8: MDCC
A9: 5 | B9: 1453440 | C9: 30.10.2025 | D9: 91942 | E9: 0 | F9: =2655-266 -> 2389 | G9: =D9+E9+F9 -> 94331 | H9: 30.10.2026 | I9: 98355 | J9: 6.8 | K9: MDCC
A10: 6 | B10: 1453441 | C10: 03.11.2025 | D10: 42348 | E10: 0 | F10: =1185-119 -> 1066 | G10: =D10+E10+F10 -> 43414 | H10: 03.11.2026 | I10: 45302 | J10: 6.8 | K10: MDCC
A11: 7 | B11: 1453443 | C11: 14.02.2026 | D11: 135352 | E11: 0 | F11: =1119-112 -> 1007 | G11: =D11+E11+F11 -> 136359 | H11: 14.02.2027 | I11: 144580 | J11: 6.65 | K11: MDCC
A12: 8 | B12: 1453444 | C12: 14.02.2026 | D12: 187856 | E12: 0 | F12: =1554-155 -> 1399 | G12: =D12+E12+F12 -> 189255 | H12: 14.02.2027 | I12: 200663 | J12: 6.65 | K12: MDCC
A13: 9 | B13: 1453445 | C13: 14.02.2026 | D13: 146834 | E13: 0 | F13: =1214-121 -> 1093 | G13: =D13+E13+F13 -> 147927 | H13: 14.02.2027 | I13: 156845 | J13: 6.65 | K13: MDCC
A14: 10 | B14: 1453446 | C14: 31.03.2026 | D14: 61626 | E14: 0 | F14: 0 | G14: =D14+E14+F14 -> 61626 | H14: 31.03.2027 | I14: 65827 | J14: 6.65 | K14: MDCC
A15: 11 | B15: 1453449 | C15: 20.03.2026 | D15: 57557 | E15: 0 | F15: =125-13 -> 112 | G15: =D15+E15+F15 -> 57669 | H15: 20.03.2027 | I15: 61481 | J15: 6.65 | K15: MDCC
A16: 12 | B16: 1453451 | C16: 03.05.2025 | D16: 46723 | E16: 0 | F16: =3270-328 -> 2942 | G16: =D16+E16+F16 -> 49665 | H16: 03.05.2026 | I16: 50327 | J16: 7.5 | K16: MDCC
A17: 13 | B17: 1453453 | C17: 15.05.2025 | D17: 49764 | E17: 0 | F17: =3355-335 -> 3020 | G17: =D17+E17+F17 -> 52784 | H17: 15.05.2026 | I17: 53603 | J17: 7.5 | K17: MDCC
A18: 14 | B18: 1453768 | C18: 17.02.2026 | D18: 40265 | E18: 0 | F18: =311-31 -> 280 | G18: =D18+E18+F18 -> 40545 | H18: 17.02.2027 | I18: 43010 | J18: 6.65 | K18: MDCC | T18: 28 | U18: =273-S18 -> 273
A19: 15 | B19: 1503320 | C19: 16.12.2025 | D19: 37584 | E19: 0 | F19: =752-75 -> 677 | G19: =D19+E19+F19 -> 38261 | H19: 16.12.2026 | I19: 40206 | J19: 6.8 | K19: MDCC
A20: 16 | B20: 310243_R03 | C20: 09.10.2024 | D20: 45007 | E20: =1521-152 -> 1369 | F20: 3333 | G20: =D20+E20+F20 -> 49709 | H20: 09.10.2027 | I20: 55423 | J20: 7 | K20: Citizen
A21: 17 | B21: 310244_R03 | C21: 09.10.2024 | D21: 45007 | E21: =1521-152 -> 1369 | F21: 3333 | G21: =D21+E21+F21 -> 49709 | H21: 09.10.2027 | I21: 55423 | J21: 7 | K21: Citizen | T21: =280-28 -> 252
A22: 18 | B22: 310245_R03 | C22: 09.10.2024 | D22: 45007 | E22: =1521-152 -> 1369 | F22: 3333 | G22: =D22+E22+F22 -> 49709 | H22: 09.10.2027 | I22: 55423 | J22: 7 | K22: Citizen
A23: 19 | B23: 310246_R03 | C23: 09.10.2024 | D23: 45007 | E23: =1521-152 -> 1369 | F23: 3333 | G23: =D23+E23+F23 -> 49709 | H23: 09.10.2027 | I23: 55423 | J23: 7 | K23: Citizen
A24: 20 | B24: 310247_R03 | C24: 09.10.2024 | D24: 54010 | E24: =1826-183 -> 1643 | F24: 3999 | G24: =D24+E24+F24 -> 59652 | H24: 09.10.2027 | I24: 66510 | J24: 7 | K24: Citizen
A25: 21 | B25: 310248_R03 | C25: 09.10.2024 | D25: 18001 | E25: =609-61 -> 548 | F25: 1333 | G25: =D25+E25+F25 -> 19882 | H25: 09.10.2027 | I25: 22167 | J25: 7 | K25: Citizen
B26: TOTAL | D26: =SUM(D5:D25) -> 1340803 | E26: =SUM(E5:E25) -> 7667 | F26: =SUM(F5:F25) -> 38350 | G26: =SUM(G5:G25) -> 1386820 | I26: =SUM(I5:I25) -> 1481491
B27: . | U27: =191-19 -> 172
B28: Repair Fund FD's
A29: 22 | B29: 1353283 | C29: 10.04.2025 | D29: 93743 | E29: 0 | F29: =6729-673 -> 6056 | G29: =D29+E29+F29 -> 99799 | H29: 10.04.2027 | I29: 108124 | J29: 7.2 | K29: MDCC
A30: 23 | B30: 1453442 | C30: 30.10.2025 | D30: 138222 | E30: 0 | F30: =3991-399 -> 3592 | G30: =D30+E30+F30 -> 141814 | H30: 30.10.2026 | I30: 147864 | J30: 6.8 | K30: MDCC
A31: 24 | B31: 1453447 | C31: 14.02.2026 | D31: 37172 | E31: 0 | F31: =306-31 -> 275 | G31: =D31+E31+F31 -> 37447 | H31: 14.02.2027 | I31: 39706 | J31: 7.2 | K31: MDCC
A32: 25 | B32: 1453448 | C32: 31.03.2026 | D32: 137007 | E32: 0 | F32: 0 | G32: =D32+E32+F32 -> 137007 | H32: 31.03.2026 | I32: 146348 | J32: 6.65 | K32: MDCC
A33: 26 | B33: 1453450 | C33: 20.03.2026 | D33: 128290 | E33: 0 | F33: =280-28 -> 252 | G33: =D33+E33+F33 -> 128542 | H33: 20.03.2027 | I33: 137036 | J33: 6.65 | K33: MDCC
A34: 27 | B34: 1453452 | C34: 15.05.2025 | D34: 110917 | E34: 0 | F34: =7479-748 -> 6731 | G34: =D34+E34+F34 -> 117648 | H34: 15.05.2026 | I34: 119473 | J34: 7.5 | K34: MDCC
A35: 28 | B35: 1453769 | C35: 20.02.2026 | D35: 89747 | E35: 0 | F35: =644-64 -> 580 | G35: =D35+E35+F35 -> 90327 | H35: 20.02.2027 | I35: 95866 | J35: 6.65 | K35: MDCC
A36: 29 | B36: 1503318 | C36: 16.12.2025 | D36: 83772 | E36: 0 | F36: =1676-168 -> 1508 | G36: =D36+E36+F36 -> 85280 | H36: 16.12.2026 | I36: 89615 | J36: 6.8 | K36: MDCC | S36: =P36-Q36 -> 0
A37: 30 | B37: 1002026_R1 | C37: 07.09.2025 | D37: 91809 | E37: 0 | F37: =5780-2548 -> 3232 | G37: =D37+E37+F37 -> 95041 | H37: 07.03.2027 | I37: 100416 | J37: 6.25 | K37: Citizen
B38: TOTAL | D38: =SUM(D29:D37) -> 910679 | E38: =SUM(E29:E37) -> 0 | F38: =SUM(F29:F37) -> 22226 | G38: =SUM(G29:G37) -> 932905 | I38: =SUM(I29:I37) -> 984448
B39: .
B40: Education Fund FD's
...

Sheet FA-Sch II
A1: Cherry Blossom Co-op. Hsg. Soc. Ltd
A2: Details of Fixed Assets as on 31st March 2026
A3: Schedule - II
A4: Particulars | B4: Rate % | C4: Opening W.D.V. as on 01.04.2025 | D4: Additions during the year before 30.09.2025 | E4: Additions during the year after 30.09.2025 | F4: Gross Block (at cost) as on 31.03.2026 | G4: Depreciation for the year | H4: Closing W.D.V. as on 31.03.2026
A5: Land & Building | C5: 2995875 | D5: 0 | E5: 0 | F5: =C5+D5+E5 -> 2995875 | G5: =ROUND(((D5+C5)*B5)+(E5*B5)/2,0) -> 0 | H5: =F5-G5 -> 2995875
A7: CCTV | B7: 0.15 | C7: 30019 | D7: 0 | E7: 0 | F7: =C7+D7+E7 -> 30019 | G7: =ROUND(((D7+C7)*B7)+(E7*B7)/2,0) -> 4503 | H7: =F7-G7 -> 25516
A9: Furniture & Fixtures | B9: 0.1 | C9: 1602 | D9: 0 | E9: 0 | F9: =C9+D9+E9 -> 1602 | G9: =ROUND(((D9+C9)*B9)+(E9*B9)/2,0) -> 160 | H9: =F9-G9 -> 1442
A11: Water Pump Account | B11: 0.15 | C11: 16703 | D11: 0 | E11: 0 | F11: =C11+D11+E11 -> 16703 | G11: =ROUND(((D11+C11)*B11)+(E11*B11)/2,0) -> 2505 | H11: =F11-G11 -> 14198
A12: Total | C12: =SUM(C5:C11) -> 3044199 | D12: =SUM(D5:D11) -> 0 | E12: =SUM(E5:E11) -> 0 | F12: =SUM(F5:F11) -> 3044199 | G12: =SUM(G5:G11) -> 7168 | H12: =SUM(H5:H11) -> 3037031

Sheet Sch-III,IV,V
A1: Cherry Blossom Co-op. Hsg. Soc. Ltd.
A2: ( F.Y. 2025-26)
A4: Schedule - III | G4: Schedule - IV
A5: Advance to Vendors | G5: Advance from Members
A6: Sr.no. | B6: Vendor Name | C6: Amount (Rs.) | G6: Sl.No | H6: Block | I6: Unit | J6: Name of the Member | K6: Amount (Rs.)
A7: 1 | B7: P. Vaz (Advocate) | C7: 100000 | G7: 1 | H7: A | I7: 04 | J7: MR. PIOUS RODRIGUES & MRS. THERESA RODRIGUES | K7: 36
A8: Total | C8: =SUM(C7:C7) -> 100000 | G8: 2 | H8: A | I8: 06 | J8: MRS. LYDIA AUSTIN GOMES | K8: 4134
G9: 3 | H9: A | I9: 09 | J9: MRS. LEENA D'SA | K9: 968
G10: 4 | H10: B | I10: 02 | J10: MRS. VANESSA LOBO | K10: 1599
A11: Schedule - V | G11: 5 | H11: B | I11: 03 | J11: MR. AJAY JAYSUKHLAL PANCHAL | K11: =1004+1972 -> 2976
A12: Provision & Payables | G12: 6 | H12: B | I12: 07 | J12: FLOSSY MACHADO | K12: 6637
A13: Sr.no. | B13: Account Head | C13: Amount (Rs.) | G13: 7 | H13: B | I13: 08 | J13: MRS. CAROLINE SONIA D'SOUZA & MRS. THERESA MARGARET D'SOUZA | K13: 8417
A14: 1 | B14: Water Expenses | C14: =Sheet!E8 -> 7297 | G14: 8 | H14: B | I14: 13 | J14: MR. PRAVIN G. PARDESHI & MRS. MAMTA PRAVIN PARDESHI | K14: 8500
A15: 2 | B15: Audit Fees | C15: 2100 | G15: 9 | H15: B | I15: 14 | J15: MR. SANJEEV VASANT DALI | K15: 7548
A16: 3 | B16: Subscription Charges | C16: 826 | G16: 10 | H16: B | I16: 15 | J16: MRS. DORIS LAWRENCE D'SOUZA | K16: 13652
A17: 4 | B17: Professional Fee | C17: 1500 | G17: Total | K17: =SUM(K7:K16) -> 54467
A18: 5 | B18: Adani Electricity | C18: 3410
A19: 6 | B19: BMC | C19: 8105
A20: 7 | B20: Majithiya Services | C20: 12980
A21: 8 | B21: Sweeper | C21: 2200
A22: Total | C22: =SUM(C14:C21) -> 38418

Sheet BRS
B1: Cherry Blossom CHS LTD
B2: Citizen Bank Reconciliation Statement as on 31.03.2026
D3: Amount
C4: Balance as per System (Book Balance) | D4: 96127.95
B6: Less: | C6: Amount Debited by Bank but not entered in the system (Issued) | D6: 0
B8: Add: | C8: Amount credited in Bank but not entered in the system (Deposit) | D8: 0
C10: Balance as per Bank Passbook | D10: =D4-D6+D8 -> 96127.95
B14: Cherry Blossom CHS LTD
B15: MDCC Bank Reconciliation Statement as on 31.03.2026
D16: Amount
C17: Balance as per System (Book Balance) | D17: 12886.85
B19: Less: | C19: Amount Debited by Bank but not entered in the system (Issued) | D19: 0
B21: Add: | C21: Amount credited in Bank but not entered in the system (Deposit) | D21: 0
C23: Balance as per Bank Passbook | D23: =D17-D19+D21 -> 12886.85

Sheet Sheet
A1: Water expenses
A2: PNH5880008 | B2: 45665 | C2: 45755 | D2: =C2-B2 -> 90 | E2: 8041
B3: 45748 | C3: 45755 | D3: =C3-B3+1 -> 8 | E3: =ROUND(D3*E2/D2,0) -> 715
B4: =C3 -> 45755 | C4: 45846 | D4: =C4-B4 -> 91 | E4: 8339
B5: =C4 -> 45846 | C5: 45938 | D5: =C5-B5 -> 92 | E5: 8024
B6: =C5 -> 45938 | C6: 46030 | D6: =C6-B6 -> 92 | E6: 8105
D7: =SUM(D3:D6) -> 283 | E7: =SUM(E3:E6) -> 25183
B8: =C6 -> 46030 | C8: 46112 | D8: =C8-B8 -> 82 | E8: =ROUND(D8*E7/D7,0) -> 7297 | F8: provision
D9: =D7+D8 -> 365 | E9: =E7+E8 -> 32480
A11: Insurance
B12: 46088 | C12: 46452 | D12: =C12-B12+1 -> 365 | E12: 17855
B13: 46113 | C13: 46452 | D13: =C13-B13+1 -> 340 | E13: =ROUND(E12*D13/D12,0) -> 16632 | F13: prepaid

Sheet FD Interest Working

Sheet Working
C1: Period | E1: Days/months | F1: Amount
A2: 1 | B2: Water Expense | C2: 44573 | D2: 44664 | E2: 91 | F2: 6797
C3: 44573 | D3: 44651 | E3: =19+28+31 -> 78 | F3: =E3*F2/E2 -> 5826 | G3: PY
C4: 44652 | D4: 44664 | E4: =D4-C4+1 -> 13 | F4: =F2-F3 -> 971
C5: =D2 -> 44664 | D5: 44755 | E5: =D5-C5 -> 91 | F5: 6945
C6: =D5 -> 44755 | D6: 44847 | E6: =D6-C6 -> 92 | F6: 8841
C7: =D6 -> 44847 | D7: 44939 | E7: =D7-C7 -> 92 | F7: 7898
C8: 44652 | D8: 44939 | E8: =SUM(E4:E7) -> 288 | F8: =SUM(F4:F7) -> 24655
C9: =D8 -> 44939 | D9: 45016 | E9: =D9-C9 -> 77 | F9: =ROUND(E9*F8/E8,0) -> 6592 | G9: Provision
C10: =C8 -> 44652 | D10: =D9 -> 45016 | E10: =E8+E9 -> 365 | F10: =F8+F9 -> 31247
A12: 2 | B12: CCTV AMC | C12: 44896 | D12: 45260 | E12: =D12-C12+1 -> 365 | F12: 7275
C13: 45017 | D13: =D12 -> 45260 | E13: =D13-C13+1 -> 244 | F13: =ROUND(E13*F12/E12,0) -> 4863 | G13: Prepaid
C14: =C12 -> 44896 | D14: 45016 | E14: =E12-E13 -> 121 | F14: =F12-F13 -> 2412
A16: 3 | B16: Insurance | C16: 44991 | D16: 45356 | E16: =D16-C16 -> 365 | F16: 18249
C17: 45017 | D17: =D16 -> 45356 | E17: =D17-C17 -> 339 | F17: =ROUND(E17*F16/E16,0) -> 16949 | G17: Prepaid
C18: =C16 -> 44991 | D18: 45016 | E18: =E16-E17 -> 26 | F18: =F16-F17 -> 1300
C19: 44652 | D19: 44990 | E19: =D19-C19 -> 338 | F19: 14770
E20: =SUM(E18:E19) -> 364 | F20: =SUM(F18:F19) -> 16070
